Workbook

Sheet 名称
A1: 货号 | B1: 产品名称 | C1: 外箱 | D1: 车间
A2: 47329 | B2: 收割车 | C2: 2 | D2: A
A3: 47399 | B3: 洒水车 | C3: 4 | D3: B
A4: 47550 | B4: 回力车 | C4: 4 | D4: B
A5: 47615 | B5: 跳舞的玉米 | C5: 6 | D5: B
A6: 47640 | B6: 半挂车 | C6: 2 | D6: B
A7: 47669 | B7: 动物车 | C7: 4 | D7: 印尼
A8: 47674 | B8: JD LNS圆轮拖拉机 | C8: 2 | D8: 印尼
A9: 35189AZ | B9: 吹气车 | C9: 2 | D9: A
A10: 35189B | B10: 吹气车 | C10: 2 | D10: A
A11: 35189C | B11: 吹气车 | C11: 2 | D11: A
A12: 35206B | B12: 猪马牛羊车（单支装） | C12: 2 | D12: A
A13: 35802J | B13: 挖土机 | C13: 2 | D13: 印尼
A14: 46644B | B14: 发光车 | C14: 2 | D14: A
A15: 46656EU1 | B15: 6"拖拉机 | C15: 4 | D15: B
A16: 46670C | B16: 46656/46748 混装 | C16: 4 | D16: B
A17: 46670TSC | B17: 46656/46748 混装 | C17: 4 | D17: B
A18: 46720J | B18: 木材运输车 | C18: 4 | D18: 印尼
A19: 47101J | B19: 1:16收割机 | C19: 1 | D19: 印尼
A20: 47280A | B20: 童车 | C20: 1 | D20: B
... A46: Y2049G1 | B46: 锁匙 | C46: 36 | D46: B
A47: 46088 | B47: 吹气三轮车 | C47: 1 | D47: A
A48: E73647BZR | B48: 手镯和球 | C48: 12 | D48: B
A49: 43379 | B49: 手镯和球 | C49: 12 | D49: B
A50: T72465ML3 | B50: 贪婪的老奶奶 | C50: 6 | D50: B
A51: T72465ADR2 | B51: 贪婪的老奶奶 | C51: 6 | D51: B
A52: L27870B | B52: 杯子 | C52: 18 | D52: B
A53: T72465ASC1 | B53: 贪婪的老奶奶 | C53: 6 | D53: B
A54: T72465RO | B54: 贪婪的老奶奶 | C54: 6 | D54: B
A55: T72465BZR2 | B55: 贪婪的老奶奶 | C55: 6 | D55: B
A56: 47391J | B56: 1:16收割机 | C56: 1 | D56: 印尼
A57: Y2341C | B57: 杯子 | C57: 18 | D57: 印尼
A58: E73855A1 | B58: 马里奥能量蘑菇吸塑混装 | C58: 6 | D58: 印尼
A59: E73906 | B59: 马里奥和他的蘑菇 | C59: 6 | D59: 印尼
A60: E73907 | B60: 能量蘑菇 | C60: 6 | D60: 印尼
A61: E73856 | B61: 宝箱马里奥 | C61: 4 | D61: 印尼
... A92: E73858 | B92: 浮水马里奥 | C92: 3 | D92: 印尼
A93: L21106 | B93: 盲盒公仔(塑胶毛绒) | C93: 6 | D93: 河源 | E93: 6PCS一PDQ，1PDQ 一箱
A94: L21011 | B94: 11寸大毛绒 | C94: 2 | D94: 河源
A95: L19200 | D95: 河源
...

Sheet 总接单
A1: 产品名称
A2: 接单日期 | B2: 国家 | C2: PO | D2: CUSTOMER PO | E2: 货号 | F2: 数量 | G2: 客PO走货期 | H2: FA586-1 | I2: FA586-2 | J2: EVA Foam Ball EVA泡沫球 | K2: Battery 电池 | L2: PCBA 印刷电路板组件 | M2: Power Adapter 电源适配器 | N2: Variable Speed Fan 变速风机性能 | O2: FA590-1 | P2: FA594-1 | Q2: FA595-1 | R2: FA560-2 | S2: FA596-1 | T2: FA000-1 | U2: 单价USD | V2: 金额USD | W2: 金额HKD | X2: 车间
A3: 46109 | B3: 美国 | C3: 2640 | E3: FA586-1 | F3: 10002 | G3: 46213 | H3: =F3 -> 10002 | U3: 25.2 | V3: =SUM(H3:O3)*U3 -> 252050.4 | W3: =V3*7.75 -> 1953390.6 | X3: 兴信B
A4: 46109 | B4: 美国 | C4: 2640 | E4: FA586-1 | F4: 2670 | G4: 46223 | H4: =F4 -> 2670 | U4: 25.2 | V4: =SUM(H4:O4)*U4 -> 67284 | W4: =V4*7.75 -> 521451 | X4: 兴信B
A5: 46109 | B5: 美国 | C5: 2640 | E5: FA586-1 | F5: 22332 | G5: 46223 | H5: =F5 -> 22332 | U5: 25.2 | V5: =SUM(H5:O5)*U5 -> 562766.4 | W5: =V5*7.75 -> 4361439.6 | X5: 兴信B
A6: 46109 | B6: 美国 | C6: 2640 | E6: FA586-1 | F6: 10002 | G6: 46251 | H6: =F6 -> 10002 | U6: 25.2 | V6: =SUM(H6:O6)*U6 -> 252050.4 | W6: =V6*7.75 -> 1953390.6 | X6: 兴信B
A7: 46128 | B7: 美国 | C7: PO-000000116 | E7: FA586-2 | F7: 15000 | G7: 46258 | I7: =F7 -> 15000 | U7: 25.2 | V7: =SUM(H7:O7)*U7 -> 378000 | W7: =V7*7.75 -> 2929500 | X7: 印尼RRM
A8: 46128 | B8: 美国 | C8: PO-000000116 | E8: FA586-2 | F8: 15000 | G8: 46265 | I8: =F8 -> 15000 | U8: 25.2 | V8: =SUM(H8:O8)*U8 -> 378000 | W8: =V8*7.75 -> 2929500 | X8: 印尼RRM
A9: 46128 | B9: 美国 | C9: PO-000000116 | E9: FA586-2 | F9: 10002 | G9: 46272 | I9: =F9 -> 10002 | U9: 25.2 | V9: =SUM(H9:O9)*U9 -> 252050.4 | W9: =V9*7.75 -> 1953390.6 | X9: 印尼RRM
A10: 46156 | B10: 美国 | C10: 2640 | E10: FA590-1 | F10: 5000 | G10: 46216 | O10: 5000 | U10: 10.68 | V10: =SUM(H10:O10)*U10 -> 53400 | W10: =V10*7.75 -> 413850 | X10: 兴信B
A11: 46156 | B11: 美国 | C11: 2640 | E11: FA590-1 | F11: 10000 | G11: 46244 | O11: 10000 | U11: 10.68 | V11: =SUM(H11:O11)*U11 -> 106800 | W11: =V11*7.75 -> 827700 | X11: 兴信B
A12: 46156 | B12: 美国 | C12: PO-000000274 | E12: FA590-1 | F12: =5000 -> 5000 | G12: 46230 | O12: =F12 -> 5000 | U12: 10.68 | V12: =SUM(H12:O12)*U12 -> 53400 | W12: =V12*7.75 -> 413850 | X12: 兴信B
A13: 46156 | B13: 美国 | C13: PO-000000274 | E13: FA586-1 | F13: 15000 | G13: 46230 | H13: 15000 | U13: 25.2 | V13: =SUM(H13:O13)*U13 -> 378000 | W13: =V13*7.75 -> 2929500 | X13: 兴信B
A14: 46156 | B14: 美国 | C14: PO-000000274 | E14: FA590-1 | F14: 15000 | G14: 46237 | O14: 15000 | U14: 10.68 | V14: =SUM(H14:O14)*U14 -> 160200 | W14: =V14*7.75 -> 1241550 | X14: 兴信B
A15: 46157 | B15: 亚马逊 | C15: PO-000000686 | E15: FA586-1 | F15: =15000-600 -> 14400 | G15: 46216 | H15: =F15 -> 14400 | U15: 25.2 | V15: =SUM(H15:O15)*U15 -> 362880 | W15: =V15*7.75 -> 2812320 | X15: 兴信B
A16: 46157 | B16: 亚马逊 | C16: PO-000000686 | E16: FA586-1 | F16: 600 | G16: 46216 | H16: =F16 -> 600 | U16: 25.2 | V16: =SUM(H16:O16)*U16 -> 15120 | W16: =V16*7.75 -> 117180 | X16: 兴信B
A17: 46157 | B17: 亚马逊 | C17: PO-000000686 | E17: FA590-1 | F17: 5000 | G17: 46216 | O17: 5000 | U17: 10.68 | V17: =SUM(H17:O17)*U17 -> 53400 | W17: =V17*7.75 -> 413850 | X17: 兴信B
A18: 46157 | B18: 亚马逊 | C18: PO-000000686 | E18: FA586-1 | F18: =15000-7500 -> 7500 | G18: 46237 | H18: =F18 -> 7500 | U18: 25.2 | V18: =SUM(H18:O18)*U18 -> 189000 | W18: =V18*7.75 -> 1464750 | X18: 兴信B
A19: 46157 | B19: 亚马逊 | C19: PO-000000686 | E19: FA586-1 | F19: 7500 | G19: 46237 | H19: =F19 -> 7500 | U19: 25.2 | V19: =SUM(H19:O19)*U19 -> 189000 | W19: =V19*7.75 -> 1464750 | X19: 兴信B
A20: 46109 | B20: 美国 | C20: MA | E20: EVA Foam Ball EVA泡沫球 | F20: =10000*20 -> 200000 | G20: 46272 | J20: 10000 | U20: 0 | V20: =SUM(H20:O20)*U20 -> 0 | W20: =V20*7.75 -> 0 | X20: 印尼RRM
A21: 46109 | B21: 美国 | C21: MA | E21: Battery 电池 | F21: =10000 -> 10000 | G21: 46272 | K21: 10000 | U21: 0 | V21: =SUM(H21:O21)*U21 -> 0 | W21: =V21*7.75 -> 0 | X21: 印尼RRM
A22: 46109 | B22: 美国 | C22: MA | E22: PCBA 印刷电路板组件 | F22: =10000 -> 10000 | G22: 46272 | L22: 10000 | U22: 0 | V22: =SUM(H22:O22)*U22 -> 0 | W22: =V22*7.75 -> 0 | X22: 印尼RRM
A23: 46109 | B23: 美国 | C23: MA | E23: Power Adapter 电源适配器 | F23: =10000 -> 10000 | G23: 46272 | M23: 10000 | U23: 0 | V23: =SUM(H23:O23)*U23 -> 0 | W23: =V23*7.75 -> 0 | X23: 印尼RRM
A24: 46109 | B24: 美国 | C24: MA | E24: Variable Speed Fan 变速风机性能 | F24: =10000 -> 10000 | G24: 46272 | N24: 10000 | U24: 0 | V24: =SUM(H24:N24)*U24 -> 0 | W24: =V24*7.75 -> 0 | X24: 印尼RRM
A25: 46175 | B25: 美国 | C25: PO-000001251 | E25: FA594-1 | F25: 75 | G25: 46262 | P25: 75 | U25: 2.7 | V25: =SUM(H25:T25)*U25 -> 202.5 | W25: =V25*7.75 -> 1569.38 | X25: 兴信B
A26: 46175 | B26: 美国 | C26: PO-000001251 | E26: FA595-1 | F26: 250 | G26: 46262 | Q26: 250 | U26: 2.42 | V26: =SUM(H26:T26)*U26 -> 605 | W26: =V26*7.75 -> 4688.75 | X26: 兴信B
A27: 46175 | B27: 美国 | C27: PO-000001251 | E27: FA596-1 | F27: 500 | G27: 46262 | S27: 500 | U27: 12.65 | V27: =SUM(H27:T27)*U27 -> 6325 | W27: =V27*7.75 -> 49018.75 | X27: 兴信B
A28: 46175 | B28: 美国 | C28: PO-000001251 | E28: FA000-1 | F28: 200 | G28: 46262 | T28: 200 | U28: 2.3 | V28: =SUM(H28:T28)*U28 -> 460 | W28: =V28*7.75 -> 3565 | X28: 兴信B
A29: 46185 | B29: 美国 | C29: PO-000001476 | E29: FA560-2 | F29: 3000 | G29: 46262 | R29: =F29 -> 3000 | U29: 2.74 | V29: =SUM(H29:T29)*U29 -> 8220 | W29: =V29*7.75 -> 63705 | X29: 兴信B
A30: 46188 | B30: 美国 | C30: MA | E30: FA560-2 | F30: 3000 | G30: 46262 | R30: 3000 | U30: 0 | V30: =SUM(H30:T30)*U30 -> 0 | W30: =V30*7.75 -> 0 | X30: 兴信B
V31: =SUM(H31:T31)*U31 -> 0 | W31: =V31*7.75 -> 0
V32: =SUM(H32:N32)*U32 -> 0 | W32: =V32*7.75 -> 0
F33: =SUM(F3:F32) -> 417033 | G33: =F33-SUM(H33:M33) -> 247025 | H33: =SUM(H3:H32) -> 90006 | I33: =SUM(I3:I32) -> 40002 | J33: =SUM(J3:J32) -> 10000 | K33: =SUM(K3:K32) -> 10000 | L33: =SUM(L3:L32) -> 10000 | M33: =SUM(M3:M32) -> 10000 | N33: =SUM(N3:N32) -> 10000 | O33: =SUM(O3:O32) -> 40000 | ... T33: =SUM(T3:T32) -> 200 | U33: =SUM(H33:M33) -> 170008 | V33: =SUM(V3:V32) -> 3719214.1 | W33: =SUM(W3:W32) -> 28823909
F34: =F33-总排期!H20-已走货!J18 -> 97504
D36: 美国
A37: 总接单： | B37: =B38+B39 -> 28823909 | C37: 总接单： | D37: =SUMIF(B:B,D36,W:W) -> 22551059
A38: 兴信B | B38: =SUMIF(X:X,A38,W:W) -> 21011519 | C38: 总排期： | D38: =SUMIF(总排期!C:C,D36,总排期!AA:AA) -> 11129878
A39: 印尼RRM | B39: =SUMIF(X:X,A39,W:W) -> 7812390.6 | C39: 已走货： | D39: =SUMIF(已走货!C:C,D36,已走货!Z:Z) -> 11421181
A40: 总排期： | B40: =总排期!AA20 -> 12594628 | D40: =D37-D38-D39 -> 0
A41: 已走货： | B41: =已走货!Z15 -> 16229281
...

Sheet 总排期
A1: 接单期 | B1: 提交化学测试 | C1: 国家 | D1: 第三客户名称 | E1: PO | F1: 货号 | G1: 产品名称 | H1: 数量 | I1: 外箱 | J1: 总箱数 | K1: 客PO走货期 | L1: RR走货期 | M1: 验货期 | N1: 实际验货期 | O1: 日期码 | P1: 箱唛资料 | Q1: 预配船期 | R1: 年报测试 | S1: 客贴纸 | T1: 印尼回复上拉时间 | U1: 印尼回复完成时间 | V1: 箱唛状态 | W1: 外箱条码 | X1: 备注 | Y1: 单价USD | Z1: 金额USD | AA1: 金额HKD | AB1: 发票号 | AC1: 船期 | AD1: 是否入系统 | AE1: 车间 | AF1: 混装比例 | AG1: 预计物料上印尼时间 | AH1: 物料到印尼时间 | AI1: 包材上料时间 | AJ1: 塑胶件上料时间 | AK1: 纸吉 | AL1: 五金上料时间 | AM1: 贴纸 | AN1: 仓库复来料时间 | AO1: 接单周期 | AP1: 印尼周期
A2: 46156 | C2: 美国 | D2: Fat Brain | E2: PO-000000274 | F2: FA590-1 | G2: 扩展包 | H2: 15000 | I2: 4 | J2: =H2/I2 -> 3750 | K2: 46237 | L2: 46237 | M2: =L2-3 -> 46234 | N2: 2026/8/8pass | O2: E1226AV | P2: 箱唛6/24放 | Q2: 待定 | W2: 10810074279137 | Y2: 10.68 | Z2: =H2*Y2 -> 160200 | AA2: =Z2*7.75 -> 1241550 | AE2: 兴信B | AO2: =L2-A2 -> 81 | AP2: =L2-AI2 -> 46237
A3: 46157 | C3: 亚马逊 | D3: Fat Brain | E3: PO-000000686 | F3: FA586-1 | G3: 管道吹风球 | H3: 7500 | I3: 3 | J3: =H3/I3 -> 2500 | K3: 46237 | L3: 46237 | M3: =L3-3 -> 46234 | N3: 2026/8/8pass | O3: E1326AV | P3: 箱唛6/24放 | Q3: 普通货代，待释放SO | S3: 7/30已给亚马逊贴纸 | W3: 10810074278994 | X3: 美版适配器 | Y3: 25.2 | Z3: =H3*Y3 -> 189000 | AA3: =Z3*7.75 -> 1464750 | AE3: 兴信B | AO3: =L3-A3 -> 80 | AP3: =L3-AI3 -> 46237
A4: 46109 | C4: 美国 | D4: Fat Brain | E4: 2640 | F4: FA586-1 | G4: 管道吹风球 | H4: 10002 | I4: 3 | J4: =H4/I4 -> 3334 | K4: 46251 | L4: 46251 | M4: =L4-3 -> 46248 | N4: 46253 | O4: C2626AV | P4: 箱唛6/24放 | Q4: 待定 | S4: 7/3已给SGS贴纸 | W4: 10810074278994 | X4: 美版适配器 | Y4: 25.2 | Z4: =H4*Y4 -> 252050.4 | AA4: =Z4*7.75 -> 1953390.6 | AE4: 兴信B | AO4: =L4-A4 -> 142 | AP4: =L4-AI4 -> 46251
A5: 46128 | C5: 美国 | D5: Fat Brain | E5: PO-000000116 | F5: FA586-2 | G5: 管道吹风球 | H5: 15000 | I5: 3 | J5: =H5/I5 -> 5000 | K5: 46258 | L5: 46258 | M5: =L5-3 -> 46255 | O5: D1526AV | P5: 箱唛6/24放 | S5: 7/3已给SGS贴纸 | W5: 10810074278994 | X5: 美版适配器 | Y5: 25.2 | Z5: =H5*Y5 -> 378000 | AA5: =Z5*7.75 -> 2929500 | AE5: 印尼RRM | AO5: =L5-A5 -> 130 | AP5: =L5-AI5 -> 46258
A6: 46128 | C6: 美国 | D6: Fat Brain | E6: PO-000000116 | F6: FA586-2 | G6: 管道吹风球 | H6: 15000 | I6: 3 | J6: =H6/I6 -> 5000 | K6: 46265 | L6: 46265 | M6: =L6-3 -> 46262 | O6: D1526AV | P6: 箱唛6/24放 | S6: 7/3已给SGS贴纸 | W6: 10810074278994 | X6: 美版适配器 | Y6: 25.2 | Z6: =H6*Y6 -> 378000 | AA6: =Z6*7.75 -> 2929500 | AE6: 印尼RRM | AO6: =L6-A6 -> 137 | AP6: =L6-AI6 -> 46265
A7: 46128 | C7: 美国 | D7: Fat Brain | E7: PO-000000116 | F7: FA586-2 | G7: 管道吹风球 | H7: 10002 | I7: 3 | J7: =H7/I7 -> 3334 | K7: 46272 | L7: 46272 | M7: =L7-3 -> 46269 | O7: D1526AV | P7: 箱唛6/24放 | S7: 7/3已给SGS贴纸 | W7: 10810074278994 | X7: 美版适配器 | Y7: 25.2 | Z7: =H7*Y7 -> 252050.4 | AA7: =Z7*7.75 -> 1953390.6 | AE7: 印尼RRM | AO7: =L7-A7 -> 144 | AP7: =L7-AI7 -> 46272
A8: 46109 | C8: 美国 | D8: Fat Brain | E8: MA | G8: EVA Foam Ball EVA泡沫球 | H8: =10000*20 -> 200000 | K8: 46272 | Y8: 0 | Z8: =H8*Y8 -> 0 | AA8: =I8*Z8 -> 0 | AE8: 印尼RRM | AO8: =L8-A8 -> -46109 | AP8: =L8-AI8 -> 0
A9: 46109 | C9: 美国 | D9: Fat Brain | E9: MA | G9: Battery 电池 | H9: =10000 -> 10000 | K9: 46272 | Y9: 0 | Z9: =H9*Y9 -> 0 | AA9: =I9*Z9 -> 0 | AE9: 印尼RRM | AO9: =L9-A9 -> -46109 | AP9: =L9-AI9 -> 0
A10: 46109 | C10: 美国 | D10: Fat Brain | E10: MA | G10: PCBA 印刷电路板组件 | H10: =10000 -> 10000 | K10: 46272 | Y10: 0 | Z10: =H10*Y10 -> 0 | AA10: =I10*Z10 -> 0 | AE10: 印尼RRM | AO10: =L10-A10 -> -46109 | AP10: =L10-AI10 -> 0
A11: 46109 | C11: 美国 | D11: Fat Brain | E11: MA | G11: Power Adapter 电源适配器 | H11: =10000 -> 10000 | K11: 46272 | X11: 美版适配器 | Y11: 0 | Z11: =H11*Y11 -> 0 | AA11: =I11*Z11 -> 0 | AE11: 印尼RRM | AO11: =L11-A11 -> -46109 | AP11: =L11-AI11 -> 0
A12: 46109 | C12: 美国 | D12: Fat Brain | E12: MA | G12: Variable Speed Fan 变速风机性能 | H12: =10000 -> 10000 | K12: 46272 | Y12: 0 | Z12: =H12*Y12 -> 0 | AA12: =Z12*7.75 -> 0 | AE12: 印尼RRM | AO12: =L12-A12 -> -46109 | AP12: =L12-AI12 -> 0
A13: 46175 | C13: 美国 | D13: Fat Brain | E13: PO-000001251 | F13: FA594-1 | G13: 电池 | H13: 75 | I13: 120 | J13: 1 | K13: 46262 | Y13: 2.7 | Z13: =H13*Y13 -> 202.5 | AA13: =Z13*7.75 -> 1569.38 | AE13: 兴信B | AO13: =L13-A13 -> -46175 | AP13: =L13-AI13 -> 0
A14: 46175 | C14: 美国 | D14: Fat Brain | E14: PO-000001251 | F14: FA595-1 | G14: 美规适配器 | H14: 250 | I14: 100 | J14: 3 | K14: 46262 | Y14: 2.42 | Z14: =H14*Y14 -> 605 | AA14: =Z14*7.75 -> 4688.75 | AE14: 兴信B | AO14: =L14-A14 -> -46175 | AP14: =L14-AI14 -> 0
A15: 46175 | C15: 美国 | D15: Fat Brain | E15: PO-000001251 | F15: FA596-1 | G15: 管道吹风球主机 | H15: 500 | I15: 6 | J15: 84 | K15: 46262 | Y15: 12.65 | Z15: =H15*Y15 -> 6325 | AA15: =Z15*7.75 -> 49018.75 | AE15: 兴信B | AO15: =L15-A15 -> -46175 | AP15: =L15-AI15 -> 0
A16: 46175 | C16: 美国 | D16: Fat Brain | E16: PO-000001251 | F16: FA000-1 | G16: 主机版彩盒 | H16: 200 | I16: 20 | J16: =H16/I16 -> 10 | K16: 46262 | Y16: 2.3 | Z16: =H16*Y16 -> 460 | AA16: =Z16*7.75 -> 3565 | AE16: 兴信B | AO16: =L16-A16 -> -46175 | AP16: =L16-AI16 -> 0
A17: 46185 | C17: 美国 | D17: Fat Brain | E17: PO-000001476 | F17: FA560-2 | G17: 彩色EVA球混装 | H17: 3000 | I17: 12 | J17: =H17/I17 -> 250 | K17: 46262 | O17: F1026AV | P17: 箱唛8/15已放 | W17: 10810074279526 | Y17: 2.74 | Z17: =H17*Y17 -> 8220 | AA17: =Z17*7.75 -> 63705 | AE17: 兴信B | AO17: =L17-A17 -> -46185 | AP17: =L17-AI17 -> 0
A18: 46188 | C18: 美国 | D18: Fat Brain | E18: MA | F18: FA560-2 | G18: 彩色EVA球混装 | H18: =6000-3000 -> 3000 | I18: 12 | J18: =H18/I18 -> 250 | K18: 46262 | X18: 转PO-000001476,3000套 | Y18: 0 | Z18: =H18*Y18 -> 0 | AA18: =Z18*7.75 -> 0 | AE18: 兴信B
Z19: =H19*Y19 -> 0 | AA19: =Z19*7.75 -> 0 | AO19: =L19-A19 -> 0 | AP19: =L19-AI19 -> 0
G20: 合计 | H20: =SUM(H2:H19) -> 319529 | Z20: =SUM(Z2:Z19) -> 1625113.3 | AA20: =SUM(AA2:AA19) -> 12594628

Sheet 已走货
A1: 接单期 | B1: 提交化学测试 | C1: 国家 | D1: 第三客户名称 | E1: PO | F1: 货号 | G1: 产品名称 | H1: 数量 | I1: 外箱 | J1: 总箱数 | K1: PO走货期 | L1: 验货期 | M1: 实际验货期 | N1: 日期码 | O1: 箱唛资料 | P1: Spot check | Q1: 年报测试 | R1: 客贴纸 | S1: 印尼回复上拉时间 | T1: 印尼回复完成时间 | U1: 箱唛状态 | V1: 外箱条码 | W1: 备注 | X1: 单价USD | Y1: 金额USD | Z1: 金额HKD | AA1: 发票号 | AB1: 船期 | AC1: 是否入系统 | AD1: 车间 | AE1: 混装比例 | AF1: 预计物料上印尼时间 | AG1: 物料到印尼时间 | AH1: 包材上料时间 | AI1: 塑胶件上料时间 | AJ1: 纸吉 | AK1: 五金上料时间 | AL1: 贴纸 | AM1: 仓库复来料时间 | AN1: 接单周期 | AO1: 印尼周期
A2: 46157 | C2: 亚马逊 | D2: Fat Brain | E2: PO-000000686 | F2: FA586-1 | G2: 管道吹风球 | H2: 600 | I2: 3 | J2: =H2/I2 -> 200 | K2: 46216 | L2: 46213 | M2: 2026/7/13pass | N2: E1326AV | O2: 箱唛6/24放 | R2: 7/4已给亚马逊外箱贴纸 | V2: 10810074278994 | W2: 美版适配器 | X2: 25.2 | Y2: =H2*X2 -> 15120 | Z2: =Y2*7.75 -> 117180 | AA2: FB00013 | AD2: 兴信B
A3: 46157 | C3: 亚马逊 | D3: Fat Brain | E3: PO-000000686 | F3: FA590-1 | G3: 扩展包 | H3: 5000 | I3: 4 | J3: =H3/I3 -> 1250 | K3: 46216 | L3: 46213 | M3: 2026/7/13pass | N3: E1326AV | O3: 箱唛6/24放 | R3: 7/4已给亚马逊外箱贴纸 | V3: 10810074279137 | X3: 10.68 | Y3: =H3*X3 -> 53400 | Z3: =Y3*7.75 -> 413850 | AA3: FB00013 | AD3: 兴信B | AN3: =K3-A3 -> 59 | AO3: =K3-AH3 -> 46216
A4: 46156 | C4: 美国 | D4: Fat Brain | E4: 2640 | F4: FA590-1 | G4: 扩展包 | H4: 5000 | I4: 4 | J4: =H4/I4 -> 1250 | K4: 46216 | L4: 46216 | M4: 2026/7/7pass | N4: C2626AV | O4: 箱唛6/24放 | V4: 10810074279137 | X4: 10.68 | Y4: =H4*X4 -> 53400 | Z4: =Y4*7.75 -> 413850 | AA4: FB00015 | AD4: 兴信B | AN4: =K4-A4 -> 60 | AO4: =K4-AH4 -> 46216
A5: 46109 | C5: 美国 | D5: Fat Brain | E5: 2640 | F5: FA586-1 | G5: 管道吹风球 | H5: 10002 | I5: 3 | J5: =H5/I5 -> 3334 | K5: 46216 | L5: 46213 | M5: 2026/7/7pass | N5: C2626AV | O5: 箱唛6/24放 | R5: 7/3已给SGS贴纸 | V5: 10810074278994 | W5: 美版适配器 | X5: 25.2 | Y5: =H5*X5 -> 252050.4 | Z5: =Y5*7.75 -> 1953390.6 | AA5: FB00015 | AD5: 兴信B | AN5: =K5-A5 -> 107 | AO5: =K5-AH5 -> 46216
A6: 46109 | C6: 美国 | D6: Fat Brain | E6: 2640 | F6: FA586-1 | G6: 管道吹风球 | H6: 22332 | I6: 3 | J6: =H6/I6 -> 7444 | K6: 46223 | L6: 46223 | M6: 2026/7/21pass | N6: C2626AV | O6: 箱唛6/24放 | R6: 7/3已给SGS贴纸 | V6: 10810074278994 | W6: 美版适配器 | X6: 25.2 | Y6: =H6*X6 -> 562766.4 | Z6: =Y6*7.75 -> 4361439.6 | AA6: FB00015 | AD6: 兴信B | AN6: =K6-A6 -> 114 | AO6: =K6-AH6 -> 46223
A7: 46157 | C7: 亚马逊 | D7: Fat Brain | E7: PO-000000686 | F7: FA586-1 | G7: 管道吹风球 | H7: =15000-600 -> 14400 | I7: 3 | J7: =H7/I7 -> 4800 | K7: 46216 | L7: 46216 | M7: =L7-3 -> 46213 | N7: E1326AV | O7: 箱唛6/24放 | R7: 7/4已给亚马逊外箱贴纸 | V7: 10810074278994 | W7: 美版适配器 | X7: 25.2 | Y7: =H7*X7 -> 362880 | Z7: =Y7*7.75 -> 2812320 | AA7: FB00016 | AD7: 兴信B | AO7: =L7-A7 -> 59 | AP7: =L7-AI7 -> 46216
A8: 46109 | C8: 美国 | D8: Fat Brain | E8: 2640 | F8: FA586-1 | G8: 管道吹风球 | H8: 2670 | I8: 3 | J8: =H8/I8 -> 890 | K8: 46223 | L8: 46223 | M8: 46220 | N8: C2626AV | O8: 箱唛6/24放 | R8: 7/3已给SGS贴纸 | V8: 10810074278994 | W8: 美版适配器 | X8: 25.2 | Y8: =H8*X8 -> 67284 | Z8: =Y8*7.75 -> 521451 | AA8: FB00017 | AD8: 兴信B
A9: 46156 | C9: 美国 | D9: Fat Brain | E9: PO-000000274 | F9: FA590-1 | G9: 扩展包 | H9: 5000 | I9: 4 | J9: =H9/I9 -> 1250 | K9: 46230 | L9: 46230 | M9: =L9-3 -> 46227 | N9: E1226AV | O9: 箱唛6/24放 | V9: 10810074279137 | X9: 10.68 | Y9: =H9*X9 -> 53400 | Z9: =Y9*7.75 -> 413850 | AA9: FB00018 | AD9: 兴信B
A10: 46156 | C10: 美国 | D10: Fat Brain | E10: PO-000000274 | F10: FA586-1 | G10: 管道吹风球 | H10: 15000 | I10: 3 | J10: =H10/I10 -> 5000 | K10: 46230 | L10: 46230 | M10: =L10-3 -> 46227 | N10: E1226AV | O10: 箱唛6/24放 | R10: 7/3已给SGS贴纸 | V10: 10810074278994 | W10: 美版适配器 | X10: 25.2 | Y10: =H10*X10 -> 378000 | Z10: =Y10*7.75 -> 2929500 | AA10: FB00018 | AD10: 兴信B
A11: 46157 | C11: 亚马逊 | D11: Fat Brain | E11: PO-000000686 | F11: FA586-1 | G11: 管道吹风球 | H11: =15000-7500 -> 7500 | I11: 3 | J11: =H11/I11 -> 2500 | K11: 46237 | L11: 46237 | M11: 2026/8/8pass | N11: E1326AV | O11: 箱唛6/24放 | P11: 走亚马逊7500pcs船期：2026/8/10 | R11: 7/30已给亚马逊贴纸 | V11: 10810074278994 | W11: 美版适配器 | X11: 25.2 | Y11: =H11*X11 -> 189000 | Z11: =Y11*7.75 -> 1464750 | AA11: FB00022 | AD11: 兴信B
A12: 46156 | C12: 美国 | D12: Fat Brain | E12: 2640 | F12: FA590-1 | G12: 扩展包 | H12: 10000 | I12: 4 | J12: =H12/I12 -> 2500 | K12: 46244 | L12: 46244 | M12: 2026/8/8pass | N12: C2626AV | O12: 箱唛6/24放 | V12: 10810074279137 | X12: 10.68 | Y12: =H12*X12 -> 106800 | Z12: =Y12*7.75 -> 827700 | AA12: FB00023 | AD12: 兴信B
Y14: =H14*X14 -> 0 | Z14: =Y14*7.75 -> 0 | AN14: =K14-A14 -> 0 | AO14: =K14-AH14 -> 0
G15: 合计 | H15: =SUM(H2:H14) -> 97504 | Y15: =SUM(Y2:Y14) -> 2094100.8 | Z15: =SUM(Z2:Z14) -> 16229281

Sheet 取消单
A1: 接单期 | B1: 提交化学测试 | C1: 国家 | D1: 第三客户名称 | E1: PO | F1: 货号 | G1: 产品名称 | H1: 数量 | I1: 外箱 | J1: 总箱数 | K1: 客PO走货期 | L1: RR走货期 | M1: 验货期 | N1: 实际验货期 | O1: 日期码 | P1: 箱唛资料 | Q1: Spot check | R1: 年报测试 | S1: 客贴纸 | T1: 印尼回复上拉时间 | U1: 印尼回复完成时间 | V1: 箱唛状态 | W1: 外箱条码 | X1: 备注 | Y1: 单价USD | Z1: 金额USD | AA1: 金额HKD | AB1: 发票号 | AC1: 船期 | AD1: 是否入系统 | AE1: 车间 | AF1: 混装比例 | AG1: 预计物料上印尼时间 | AH1: 物料到印尼时间 | AI1: 包材上料时间 | AJ1: 塑胶件上料时间 | AK1: 纸吉 | AL1: 五金上料时间 | AM1: 贴纸 | AN1: 仓库复来料时间 | AO1: 接单周期 | AP1: 印尼周期
A2: 46109 | B2: =IF(TODAY()>=A2,IF(R2="","未",""),"") -> 未 | C2: 美国 | D2: Fat Brain | E2: MA | G2: EVA Foam Ball EVA泡沫球 | H2: =15000*20-15000*20 -> 0 | L2: 46230 | M2: =L2-3 -> 46227 | X2: 转PO-000000274:15000pcs | Z2: =H2*Y2 -> 0 | AA2: =Z2*7.75 -> 0 | AE2: B | AO2: =L2-A2 -> 121 | AP2: =L2-AI2 -> 46230
A3: 46109 | B3: =IF(TODAY()>=A3,IF(R3="","未",""),"") -> 未 | C3: 美国 | D3: Fat Brain | E3: MA | G3: Battery 电池 | H3: =15000-15000 -> 0 | L3: 46230 | M3: =L3-3 -> 46227 | X3: 转PO-000000274:15000pcs | Z3: =H3*Y3 -> 0 | AA3: =Z3*7.75 -> 0 | AE3: B | AO3: =L3-A3 -> 121 | AP3: =L3-AI3 -> 46230
A4: 46109 | B4: =IF(TODAY()>=A4,IF(R4="","未",""),"") -> 未 | C4: 美国 | D4: Fat Brain | E4: MA | G4: PCBA 印刷电路板组件 | H4: =15000-15000 -> 0 | L4: 46230 | M4: =L4-3 -> 46227 | X4: 转PO-000000274:15000pcs | Z4: =H4*Y4 -> 0 | AA4: =Z4*7.75 -> 0 | AE4: B | AO4: =L4-A4 -> 121 | AP4: =L4-AI4 -> 46230
A5: 46109 | B5: =IF(TODAY()>=A5,IF(R5="","未",""),"") -> 未 | C5: 美国 | D5: Fat Brain | E5: MA | G5: Power Adapter 电源适配器 | H5: =15000-15000 -> 0 | L5: 46230 | M5: =L5-3 -> 46227 | X5: 美版适配器 转PO-000000274:15000pcs | Z5: =H5*Y5 -> 0 | AA5: =Z5*7.75 -> 0 | AE5: B | AO5: =L5-A5 -> 121 | AP5: =L5-AI5 -> 46230
A6: 46109 | B6: =IF(TODAY()>=A6,IF(R6="","未",""),"") -> 未 | C6: 美国 | D6: Fat Brain | E6: MA | G6: Variable Speed Fan 变速风机性能 | H6: =15000-15000 -> 0 | L6: 46230 | M6: =L6-3 -> 46227 | X6: 转PO-000000274:15000pcs | Z6: =H6*Y6 -> 0 | AA6: =Z6*7.75 -> 0 | AE6: B | AO6: =L6-A6 -> 121 | AP6: =L6-AI6 -> 46230
A7: 46109 | B7: =IF(TODAY()>=A7,IF(R7="","未",""),"") -> 未 | C7: 亚马逊 | D7: Fat Brain | E7: MA | G7: EVA Foam Ball EVA泡沫球 | H7: =14998*20-5004*20-9994*20 -> 0 | L7: 46213 | M7: =L7-3 -> 46210 | X7: 转PO单2640:5004pcs 转PO-000000686:9994pcs | Z7: =H7*Y7 -> 0 | AA7: =Z7*7.75 -> 0 | AE7: B | AO7: =L7-A7 -> 104 | AP7: =L7-AI7 -> 46213
A8: 46109 | B8: =IF(TODAY()>=A8,IF(R8="","未",""),"") -> 未 | C8: 亚马逊 | D8: Fat Brain | E8: MA | G8: Battery 电池 | H8: =14998-5004-9994 -> 0 | L8: 46213 | M8: =L8-3 -> 46210 | X8: 转PO单2640:5004pcs 转PO-000000686:9994pcs | Z8: =H8*Y8 -> 0 | AA8: =Z8*7.75 -> 0 | AE8: B | AO8: =L8-A8 -> 104 | AP8: =L8-AI8 -> 46213
A9: 46109 | B9: =IF(TODAY()>=A9,IF(R9="","未",""),"") -> 未 | C9: 亚马逊 | D9: Fat Brain | E9: MA | G9: PCBA 印刷电路板组件 | H9: =14998-5004-9994 -> 0 | L9: 46213 | M9: =L9-3 -> 46210 | X9: 转PO单2640:5004pcs 转PO-000000686:9994pcs | Z9: =H9*Y9 -> 0 | AA9: =Z9*7.75 -> 0 | AE9: B | AO9: =L9-A9 -> 104 | AP9: =L9-AI9 -> 46213
A10: 46109 | B10: =IF(TODAY()>=A10,IF(R10="","未",""),"") -> 未 | C10: 亚马逊 | D10: Fat Brain | E10: MA | G10: Power Adapter 电源适配器 | H10: =14998-5004-9994 -> 0 | L10: 46213 | M10: =L10-3 -> 46210 | X10: 美版适配器 转PO单2640:5004pcs 转PO-000000686:9994pcs | Z10: =H10*Y10 -> 0 | AA10: =Z10*7.75 -> 0 | AE10: B | AO10: =L10-A10 -> 104 | AP10: =L10-AI10 -> 46213
A11: 46109 | B11: =IF(TODAY()>=A11,IF(R11="","未",""),"") -> 未 | C11: 亚马逊 | D11: Fat Brain | E11: MA | G11: Variable Speed Fan 变速风机性能 | H11: =14998-5004-9994 -> 0 | L11: 46213 | M11: =L11-3 -> 46210 | X11: 转PO单2640:5004pcs 转PO-000000686:9994pcs | Z11: =H11*Y11 -> 0 | AA11: =Z11*7.75 -> 0 | AE11: B | AO11: =L11-A11 -> 104 | AP11: =L11-AI11 -> 46213
A12: 46109 | B12: =IF(TODAY()>=A12,IF(R12="","未",""),"") -> 未 | C12: 加拿大 | D12: Fat Brain | E12: MA | G12: EVA Foam Ball EVA泡沫球 | H12: =10000*20-10000*20 -> 0 | L12: 46260 | M12: =L12-2 -> 46258 | X12: 转PO-000000686:10000pcs | Z12: =H12*Y12 -> 0 | AA12: =Z12*7.75 -> 0 | AE12: 印尼 | AO12: =L12-A12 -> 151 | AP12: =L12-AI12 -> 46260
A13: 46109 | B13: =IF(TODAY()>=A13,IF(R13="","未",""),"") -> 未 | C13: 加拿大 | D13: Fat Brain | E13: MA | G13: Battery 电池 | H13: =10000-10000 -> 0 | L13: 46260 | M13: =L13-2 -> 46258 | X13: 转PO-000000686:10000pcs | Z13: =H13*Y13 -> 0 | AA13: =Z13*7.75 -> 0 | AE13: 印尼 | AO13: =L13-A13 -> 151 | AP13: =L13-AI13 -> 46260
A14: 46109 | B14: =IF(TODAY()>=A14,IF(R14="","未",""),"") -> 未 | C14: 加拿大 | D14: Fat Brain | E14: MA | G14: PCBA 印刷电路板组件 | H14: =10000-10000 -> 0 | L14: 46260 | M14: =L14-2 -> 46258 | X14: 转PO-000000686:10000pcs | Z14: =H14*Y14 -> 0 | AA14: =Z14*7.75 -> 0 | AE14: 印尼 | AO14: =L14-A14 -> 151 | AP14: =L14-AI14 -> 46260
A15: 46109 | B15: =IF(TODAY()>=A15,IF(R15="","未",""),"") -> 未 | C15: 加拿大 | D15: Fat Brain | E15: MA | G15: Power Adapter 电源适配器 | H15: =10000-10000 -> 0 | L15: 46260 | M15: =L15-2 -> 46258 | X15: 转PO-000000686:10000pcs 美版适配器 | Z15: =H15*Y15 -> 0 | AA15: =Z15*7.75 -> 0 | AE15: 印尼 | AO15: =L15-A15 -> 151 | AP15: =L15-AI15 -> 46260
A16: 46109 | B16: =IF(TODAY()>=A16,IF(R16="","未",""),"") -> 未 | C16: 加拿大 | D16: Fat Brain | E16: MA | G16: Variable Speed Fan 变速风机性能 | H16: =10000-10000 -> 0 | L16: 46260 | M16: =L16-2 -> 46258 | X16: 转PO-000000686:10000pcs | Z16: =H16*Y16 -> 0 | AA16: =Z16*7.75 -> 0 | AE16: 印尼 | AO16: =L16-A16 -> 151 | AP16: =L16-AI16 -> 46260
A17: 46109 | B17: =IF(TODAY()>=A17,IF(R17="","未",""),"") -> 未 | C17: 美国 | D17: Fat Brain | E17: MA | G17: EVA Foam Ball EVA泡沫球 | H17: =25000*20-25000*20 -> 0 | L17: 46251 | M17: =L17-3 -> 46248 | X17: 转TOMT排期24992PCS | Z17: =H17*Y17 -> 0 | AA17: =Z17*7.75 -> 0 | AE17: 印尼 | AO17: =L17-A17 -> 142 | AP17: =L17-AI17 -> 46251
A18: 46109 | B18: =IF(TODAY()>=A18,IF(R18="","未",""),"") -> 未 | C18: 美国 | D18: Fat Brain | E18: MA | G18: Battery 电池 | H18: =25000-25000 -> 0 | L18: 46251 | M18: =L18-3 -> 46248 | X18: 转TOMT排期24992PCS | Z18: =H18*Y18 -> 0 | AA18: =Z18*7.75 -> 0 | AE18: 印尼 | AO18: =L18-A18 -> 142 | AP18: =L18-AI18 -> 46251
A19: 46109 | B19: =IF(TODAY()>=A19,IF(R19="","未",""),"") -> 未 | C19: 美国 | D19: Fat Brain | E19: MA | G19: PCBA 印刷电路板组件 | H19: =25000-25000 -> 0 | L19: 46251 | M19: =L19-3 -> 46248 | X19: 转TOMT排期24992PCS | Z19: =H19*Y19 -> 0 | AA19: =Z19*7.75 -> 0 | AE19: 印尼 | AO19: =L19-A19 -> 142 | AP19: =L19-AI19 -> 46251
A20: 46109 | B20: =IF(TODAY()>=A20,IF(R20="","未",""),"") -> 未 | C20: 美国 | D20: Fat Brain | E20: MA | G20: Power Adapter 电源适配器 | H20: =25000-25000 -> 0 | L20: 46251 | M20: =L20-3 -> 46248 | X20: 转TOMT排期24992PCS | Z20: =H20*Y20 -> 0 | AA20: =Z20*7.75 -> 0 | AE20: 印尼 | AO20: =L20-A20 -> 142 | AP20: =L20-AI20 -> 46251
A21: 46109 | B21: =IF(TODAY()>=A21,IF(R21="","未",""),"") -> 未 | C21: 美国 | D21: Fat Brain | E21: MA | G21: Variable Speed Fan 变速风机性能 | H21: =25000-25000 -> 0 | L21: 46251 | M21: =L21-3 -> 46248 | X21: 转TOMT排期24992PCS | Z21: =H21*Y21 -> 0 | AA21: =Z21*7.75 -> 0 | AE21: 印尼 | AO21: =L21-A21 -> 142 | AP21: =L21-AI21 -> 46251
A22: 46142 | B22: =IF(TODAY()>=A22,IF(R22="","未",""),"") -> 未 | C22: 美国 | D22: Fat Brain | E22: MA | F22: 拓展包 | G22: EVA Foam Ball EVA泡沫球 | H22: =5000*10-5000*10 -> 0 | L22: 46213 | M22: =L22-3 -> 46210 | X22: 转PO单2640:5000pcs | Z22: =H22*Y22 -> 0 | AA22: =Z22*7.75 -> 0 | AE22: B | AO22: =L22-A22 -> 71 | AP22: =L22-AI22 -> 46213
A23: 46142 | B23: =IF(TODAY()>=A23,IF(R23="","未",""),"") -> 未 | C23: 亚马逊 | D23: Fat Brain | E23: MA | F23: 拓展包 | G23: EVA Foam Ball EVA泡沫球 | H23: =5000*10-5000*10 -> 0 | L23: 46213 | M23: =L23-3 -> 46210 | X23: 转PO-000000686:5000pcs | Z23: =H23*Y23 -> 0 | AA23: =Z23*7.75 -> 0 | AE23: B | AO23: =L23-A23 -> 71 | AP23: =L23-AI23 -> 46213
A24: 46142 | B24: =IF(TODAY()>=A24,IF(R24="","未",""),"") -> 未 | C24: 美国 | D24: Fat Brain | E24: MA | F24: 拓展包 | G24: EVA Foam Ball EVA泡沫球 | H24: =5000*10-5000*10 -> 0 | L24: 46230 | M24: =L24-3 -> 46227 | X24: 转PO-000000274:5000pcs | Z24: =H24*Y24 -> 0 | AA24: =Z24*7.75 -> 0 | AE24: B | AO24: =L24-A24 -> 88 | AP24: =L24-AI24 -> 46230
A25: 46142 | B25: =IF(TODAY()>=A25,IF(R25="","未",""),"") -> 未 | C25: 美国 | D25: Fat Brain | E25: MA | F25: 拓展包 | G25: EVA Foam Ball EVA泡沫球 | H25: =15000*10-15000*10 -> 0 | L25: 46237 | M25: =L25-3 -> 46234 | X25: 转PO-000000274:15000pcs | Z25: =H25*Y25 -> 0 | AA25: =Z25*7.75 -> 0 | AE25: B | AO25: =L25-A25 -> 95 | AP25: =L25-AI25 -> 46237
A26: 46142 | B26: =IF(TODAY()>=A26,IF(R26="","未",""),"") -> 未 | C26: 美国 | D26: Fat Brain | E26: MA | F26: 拓展包 | G26: EVA Foam Ball EVA泡沫球 | H26: =10000*10-10000*10 -> 0 | L26: 46244 | M26: =L26-3 -> 46241 | X26: 转PO单2640:10000pcs | Z26: =H26*Y26 -> 0 | AA26: =Z26*7.75 -> 0 | AE26: B | AO26: =L26-A26 -> 102 | AP26: =L26-AI26 -> 46244
Z27: =H27*Y27 -> 0 | AA27: =Z27*7.75 -> 0 | AO27: =L27-A27 -> 0 | AP27: =L27-AI27 -> 0
Z28: =H28*Y28 -> 0 | AA28: =Z28*7.75 -> 0 | AO28: =L28-A28 -> 0 | AP28: =L28-AI28 -> 0
Z29: =H29*Y29 -> 0 | AA29: =Z29*7.75 -> 0 | AO29: =L29-A29 -> 0 | AP29: =L29-AI29 -> 0
Z30: =H30*Y30 -> 0 | AA30: =Z30*7.75 -> 0 | AO30: =L30-A30 -> 0 | AP30: =L30-AI30 -> 0
Z31: =H31*Y31 -> 0 | AA31: =Z31*7.75 -> 0 | AO31: =L31-A31 -> 0 | AP31: =L31-AI31 -> 0
G32: 合计 | H32: =SUM(H2:H31) -> 0 | Z32: =SUM(Z2:Z31) -> 0 | AA32: =SUM(AA2:AA31) -> 0
