Workbook

Sheet Summary
A1: VENDOR QUOTE FORM
A2: ASSORTMENT PRICE
A4: FROM | B4: : | C4: ROYAL REGENT PRODUCTS INDUSTRIES LIMITED | M4: PREPARED BY : | N4: Charles
A5: CUSTOMER | B5: : | C5: SPIN MASTER TOYS FAR EAST LTD
A6: MATERIAL NO | B6: : | C6: 1097236 | M6: REVISION : | N6: V2
A7: MATERIAL GROUP | B7: :
A8: DESCRIPTION | B8: : | C8: 29090/ T.94703-0001/ PWP LPP - 6.88 Movie Plush Refresh - GML | M8: DATE : | N8: 46096
A10: ASSORTMENT MATRIX:
A11: IND. SKU TOY# | B11: Description | E11: Qty ( per carton ) | F11: Revision | J11: EX FTY (US$) | K11: FOB ID FCL (US$) | L11: FOB ID LCL1 (US$) | M11: FOB ID LCL2 (US$) | N11: FOB ID LCL3 (US$)
A12: =C6 -> 1097236 | B12: =Rocky!C7 -> 29090/ T.94703-0001/ PWP LPP - 6.88 Movie Plush Refresh - GML--Rocky | E12: 2 | J12: =Rocky!L179 -> 2.1259875 | K12: =Rocky!L181 -> 2.1503512 | L12: =Rocky!L185 -> 2.2408449 | M12: =Rocky!L186 -> 2.2028326 | N12: =Rocky!L187 -> 2.1920989
A13: =C6 -> 1097236 | B13: =Skye!C7 -> 29090/ T.94703-0001/ PWP LPP - 6.88 Movie Plush Refresh - GML--Skye | E13: 2 | J13: =Skye!L179 -> 2.278025 | K13: =Skye!L181 -> 2.3023887 | L13: =Skye!L185 -> 2.3928824 | M13: =Skye!L186 -> 2.3548701 | N13: =Skye!L187 -> 2.3441364
A14: =C6 -> 1097236 | B14: =Marshall!C7 -> 29090/ T.94703-0001/ PWP LPP - 6.88 Movie Plush Refresh - GML--Marshall | E14: 2 | J14: =Marshall!L179 -> 2.1801856 | K14: =Marshall!L181 -> 2.2045493 | L14: =Marshall!L185 -> 2.295043 | M14: =Marshall!L186 -> 2.2570307 | N14: =Marshall!L187 -> 2.246297
A15: =C6 -> 1097236 | B15: =Rex!C7 -> 29090/ T.94703-0001/ PWP LPP - 6.88 Movie Plush Refresh - GML--Rex | E15: 2 | J15: =Rex!L179 -> 2.418661 | K15: =Rex!L181 -> 2.4430247 | L15: =Rex!L185 -> 2.5335184 | M15: =Rex!L186 -> 2.495506 | N15: =Rex!L187 -> 2.4847723
A16: =C6 -> 1097236 | B16: =Chase!C7 -> 29090/ T.94703-0001/ PWP LPP - 6.88 Movie Plush Refresh - GML--Chase | E16: 2 | J16: =Chase!L179 -> 2.0808071 | K16: =Chase!L181 -> 2.1051708 | L16: =Chase!L185 -> 2.1956645 | M16: =Chase!L186 -> 2.1576522 | N16: =Chase!L187 -> 2.1469185
A17: =C6 -> 1097236 | B17: =Rubble!C7 -> 29090/ T.94703-0001/ PWP LPP - 6.88 Movie Plush Refresh - GML--Rubble | E17: 2 | J17: =Rubble!L179 -> 2.1542613 | K17: =Rubble!L181 -> 2.178625 | L17: =Rubble!L185 -> 2.2691187 | M17: =Rubble!L186 -> 2.2311064 | N17: =Rubble!L187 -> 2.2203727
A18: =C12 -> 0
A20: REMARKS: EXCHANGE RATE US$1 = HK$7.75 | D20: Case Pack = | E20: =SUM(E12:E19) -> 12 | G20: =I22+1 -> 16369 | H20: to | I20: =Rocky!I168 -> 19248 | J20: =ROUND(SUMPRODUCT($E$12:$E$19,J12:J19)/$E$20,4) -> 2.2063 | K20: =ROUND(SUMPRODUCT($E$12:$E$19,K12:K19)/$E$20,4) -> 2.2307 | L20: =ROUND(SUMPRODUCT($E$12:$E$19,L12:L19)/$E$20,4) -> 2.3212 | M20: =ROUND(SUMPRODUCT($E$12:$E$19,M12:M19)/$E$20,4) -> 2.2832 | N20: =ROUND(SUMPRODUCT($E$12:$E$19,N12:N19)/$E$20,4) -> 2.2724 | O20: (LCL 3)
F21: ( pcs per shipment ) | K21: =K20-J20 -> 0.0244 | L21: =L20-J20 -> 0.1149 | M21: =M20-J20 -> 0.0769 | N21: =N20-J20 -> 0.0661
A22: Unit Cost per CBM for INDONESIA FCL : | D22: =(K21/(E52/E45)) -> 16.607077 | F22: Qty fm | G22: =H24+1 -> 8665 | H22: to | I22: =Rocky!I167 -> 16368 | M22: =M20 -> 2.2832 | O22: (LCL 2)
A23: Unit Cost per CBM for INDONESIA LCL (50%to 75% loaded container) : | D23: =(N21/(E52/E45)) -> 44.988845 | F23: ( pcs per shipment ) | M23: =M21 -> 0.0769
A24: No. of pieces in 40' container : | D24: =((55/E52)*E45) -> 37433.986 | G24: Qty under | H24: =Rocky!I166 -> 8664 | L24: =L20 -> 2.3212 | O24: (LCL 1)
F25: ( pcs per shipment ) | L25: =L21 -> 0.1149
A26: DESIGNATED VENDOR COMPONENT(S) :
A27: PART | C27: VENDOR | D27: COST (US$) | J27: PRODUCT COST + CONSIGNED PARTS + SHIPPING COST
J28: PROJECT(S) WITH TOOLING(S)?
J30: VENDOR FOB INDONESIA FCL: | N30: =K20 -> 2.2307
J31: Consigned parts No | K31: Description | L31: Usage | M31: Unit Cost | N31: TOTAL
A34: Verified By: | D34: Approved By:
J38: TOTAL FOB INDONESIA FCL | N38: =SUM(N30:N37) -> 2.2307
A40: SMTFE Engineer: | D40: Director of Procurement / Ronnen Harary | N40: 0
J41: Total Cost | N41: =SUM(N38:N40) -> 2.2307
A42: Date: | D42: Date: | J42: (Consign Part usage per SKU. Plesase refer to the consign parts usage contents)
A44: Shipping cost to US & TN
A45: Item | D45: pcs/carton | E45: =E20 -> 12
C46: OR | L46: OR
A47: Carton Dimension (inch) : | D47: Carton Dimension (cm) : | J47: Retail Package Dimension (inch) | M47: Retail Package Dimension (cm)
A48: Width - L | B48: 18.5 | C48: inch | D48: Width - L | E48: =B48*2.54 -> 46.99 | F48: cm | J48: Width - L | L48: Inch | M48: Width - L | N48: =K48*2.54 -> 0 | O48: cm
A49: Depth -W | B49: 8.54 | C49: inch | D49: Depth-W | E49: =B49*2.54 -> 21.6916 | F49: cm | J49: Depth-W | L49: Inch | M49: Depth-W | N49: =K49*2.54 -> 0 | O49: cm
A50: Height | B50: 6.81 | C50: inch | D50: Height | E50: =B50*2.54 -> 17.2974 | F50: cm | J50: Height | L50: Inch | M50: Height | N50: =K50*2.54 -> 0 | O50: cm
A51: Weight | C51: lb | D51: Weight | E51: =+B51 -> 0 | F51: lb | J51: Weight | L51: lb | M51: Weight | N51: =+K51 -> 0 | O51: lb
...

Sheet Rocky
A1: VENDOR QUOTE FORM
A2: INDIVIDUAL COST BREAKDOWN
A3: From (Vendor) : | C3: ROYAL REGENT PRODUCTS INDUSTRIES LIMITED | M3: PREPARED BY : | N3: =Summary!N4 -> Charles
A4: To CUSTOMER : | C4: SPIN MASTER TOYS FAR EAST LTD | M4: REVISION : | N4: =Summary!N6 -> V2
A5: MATERIAL NO ; | C5: =Summary!C6 -> 1097236 | M5: DATE : | N5: =Summary!N8 -> 46096
A6: MATERIAL GROUP : | C6: =Summary!C7 -> 0
A7: DESCRIPTION : | C7: 29090/ T.94703-0001/ PWP LPP - 6.88 Movie Plush Refresh - GML--Rocky
B9: In-Housed Molding | C9: Parts (each row below represents a single mold) | D9: Mold No. | E9: Part No. | F9: Cav/UP | I9: Material | J9: Resin price (US$/kg) | K9: Wt. per toy (g) | L9: US$ per toy | N9: Molding Cost (US$/pc) | O9: Cycle time (sec) | P9: Machine size (Ton) | Q9: Molding Labour Rate (US$/hr)
M10: =IF(F10="","",F10/H10)
L11: =+J11*K11/1000 -> 0 | M11: =IF(F11="","",F11/H11) | N11: 0
M12: =IF(F12="","",F12/H12)
M13: =IF(F13="","",F13/H13)
M14: =IF(F14="","",F14/H14)
L15: =+J15*K15/1000 -> 0 | M15: =IF(F15="","",F15/H15) | N15: 0
M16: =IF(F16="","",F16/H16)
L17: =+J17*K17/1000 -> 0 | M17: =IF(F17="","",F17/H17) | N17: 0
J18: Total Wt. | K18: =SUM(K10:K17) -> 0 | N18: =SUM(N10:N17) -> 0
L19: Sub-total: | M19: =SUM(L10:L18) -> 0
N20: =M19/P98 -> 0
B21: Purchased Part | C21: Description | J21: Unit price (US$/pc) | K21: Usage per toy | L21: US$ per toy
C22: Fabric Cost
C23: 58" 320G 1.5MM White Crystal Super Soft, Digital Positioning Print | D23: 58"320G 1.5MM白色水晶超柔，数码定位印 | J23: =14/6.8*1.06 -> 2.1823529 | K23: 0.11625958 | L23: =K23*J23 -> 0.25371944
C24: 58" 320G 1.5MM White Crystal Super Soft + Bottom-to-Bottom Bonding | D24: 58"320G 1.5MM白色水晶超柔+底对底贴合 | J24: =19.8/6.8*1.06 -> 3.0864706 | K24: 0.0019567784 | L24: =K24*J24 -> 0.0060395391
C25: 58" 220G Black Edge Lurex Fabric | D25: 58" 220G黑色边纶布 | J25: =6.2/6.8*1.06 -> 0.96647059 | K25: 0.00090312851 | L25: =K25*J25 -> 0.00087284714
C26: 36" 2MM Green Jifu Fabric | D26: 36"2MM绿色戟绒布 | J26: =9.2/6.8*1.06 -> 1.4341176 | K26: 0.0045156425 | L26: =K26*J26 -> 0.0064759626
C27: 36" 2MM Gray-Blue Jifu Fabric | D27: 36"2MM灰蓝色戟绒布 | J27: =9.2/6.8*1.06 -> 1.4341176 | K27: 0.0019352754 | L27: =K27*J27 -> 0.0027754126
C28: 58" 180G White Edge Lurex Fabric | D28: 58"180G白色边伦布 | J28: =5/6.8*1.06 -> 0.77941176 | K28: 0.0024083427 | L28: =K28*J28 -> 0.0018770906
L29: =K29*J29 -> 0
L30: =K30*J30 -> 0
L31: =K31*J31 -> 0
L32: =K32*J32 -> 0
M36: =SUM(L23:L36) -> 0.27176029 | N36: =M36/P98 -> 0.39547879
C37: Metal Parts Cost
L38: =J38*K38 -> 0
L39: =J39*K39 -> 0
L40: =J40*K40 -> 0
L41: =J41*K41 -> 0
L42: =J42*K42 -> 0
L43: =J43*K43 -> 0
L44: =J44*K44 -> 0
...

Sheet Skye
A1: VENDOR QUOTE FORM
A2: INDIVIDUAL COST BREAKDOWN
A3: From (Vendor) : | C3: ROYAL REGENT PRODUCTS INDUSTRIES LIMITED | M3: PREPARED BY : | N3: =Summary!N4 -> Charles
A4: To CUSTOMER : | C4: SPIN MASTER TOYS FAR EAST LTD | M4: REVISION : | N4: =Summary!N6 -> V2
A5: MATERIAL NO ; | C5: =Summary!C6 -> 1097236 | M5: DATE : | N5: =Summary!N8 -> 46096
A6: MATERIAL GROUP : | C6: =Summary!C7 -> 0
A7: DESCRIPTION : | C7: 29090/ T.94703-0001/ PWP LPP - 6.88 Movie Plush Refresh - GML--Skye
B9: In-Housed Molding | C9: Parts (each row below represents a single mold) | D9: Mold No. | E9: Part No. | F9: Cav/UP | I9: Material | J9: Resin price (US$/kg) | K9: Wt. per toy (g) | L9: US$ per toy | N9: Molding Cost (US$/pc) | O9: Cycle time (sec) | P9: Machine size (Ton) | Q9: Molding Labour Rate (US$/hr)
M10: =IF(F10="","",F10/H10)
L11: =+J11*K11/1000 -> 0 | M11: =IF(F11="","",F11/H11) | N11: 0
M12: =IF(F12="","",F12/H12)
M13: =IF(F13="","",F13/H13)
M14: =IF(F14="","",F14/H14)
L15: =+J15*K15/1000 -> 0 | M15: =IF(F15="","",F15/H15) | N15: 0
M16: =IF(F16="","",F16/H16)
L17: =+J17*K17/1000 -> 0 | M17: =IF(F17="","",F17/H17) | N17: 0
J18: Total Wt. | K18: =SUM(K10:K17) -> 0 | N18: =SUM(N10:N17) -> 0
L19: Sub-total: | M19: =SUM(L10:L18) -> 0
N20: =M19/P98 -> 0
B21: Purchased Part | C21: Description | J21: Unit price (US$/pc) | K21: Usage per toy | L21: US$ per toy
C22: Fabric Cost
C23: 58" 320G 1.5MM White Crystal Super Soft, Digital Positioning Print | D23: 58"320G 1.5MM白色水晶超柔，数码定位印 | J23: =14/6.8*1.06 -> 2.1823529 | K23: 0.13110558 | L23: =K23*J23 -> 0.28611864
C24: 63" 950G 20MM Orange Rabbit Fur | D24: 63"950G 20MM橙色兔毛 | J24: =25/6.8*1.06 -> 3.8970588 | K24: 0.0081281566 | L24: =K24*J24 -> 0.031675904
C25: 58" 220G Black Edge Lumber | D25: 58" 220G黑色边纶布 | J25: =6.2/6.8*1.06 -> 0.96647059 | K25: 0.00090312851 | L25: =K25*J25 -> 0.00087284714
C26: 58" 2MM Rose Red Velvet Fabric | D26: 36"2MM玫红色戟绒布 | J26: =9.2/6.8*1.06 -> 1.4341176 | K26: 0.0042145997 | L26: =K26*J26 -> 0.0060442318
C27: 58" 2MM Yellow Velvet Fabric | D27: 36"2MM黄色戟绒布 | J27: =9.2/6.8*1.06 -> 1.4341176 | K27: 0.0011611652 | L27: =K27*J27 -> 0.0016652475
C28: 58" 180G White Edge Lumber | D28: 58"180G白色边伦布 | J28: =5/6.8*1.06 -> 0.77941176 | K28: 0.0019352754 | L28: =K28*J28 -> 0.0015083764
L29: =K29*J29 -> 0
L30: =K30*J30 -> 0
L31: =K31*J31 -> 0
L32: =K32*J32 -> 0
M36: =SUM(L23:L36) -> 0.32788525 | N36: =M36/P98 -> 0.44112531
C37: Metal Parts Cost
L38: =J38*K38 -> 0
L39: =J39*K39 -> 0
L40: =J40*K40 -> 0
L41: =J41*K41 -> 0
L42: =J42*K42 -> 0
L43: =J43*K43 -> 0
L44: =J44*K44 -> 0
...

Sheet Marshall
A1: VENDOR QUOTE FORM
A2: INDIVIDUAL COST BREAKDOWN
A3: From (Vendor) : | C3: ROYAL REGENT PRODUCTS INDUSTRIES LIMITED | M3: PREPARED BY : | N3: =Summary!N4 -> Charles
A4: To CUSTOMER : | C4: SPIN MASTER TOYS FAR EAST LTD | M4: REVISION : | N4: =Summary!N6 -> V2
A5: MATERIAL NO ; | C5: =Summary!C6 -> 1097236 | M5: DATE : | N5: =Summary!N8 -> 46096
A6: MATERIAL GROUP : | C6: =Summary!C7 -> 0
A7: DESCRIPTION : | C7: 29090/ T.94703-0001/ PWP LPP - 6.88 Movie Plush Refresh - GML--Marshall
B9: In-Housed Molding | C9: Parts (each row below represents a single mold) | D9: Mold No. | E9: Part No. | F9: Cav/UP | I9: Material | J9: Resin price (US$/kg) | K9: Wt. per toy (g) | L9: US$ per toy | N9: Molding Cost (US$/pc) | O9: Cycle time (sec) | P9: Machine size (Ton) | Q9: Molding Labour Rate (US$/hr)
M10: =IF(F10="","",F10/H10)
L11: =+J11*K11/1000 -> 0 | M11: =IF(F11="","",F11/H11) | N11: 0
M12: =IF(F12="","",F12/H12)
M13: =IF(F13="","",F13/H13)
M14: =IF(F14="","",F14/H14)
L15: =+J15*K15/1000 -> 0 | M15: =IF(F15="","",F15/H15) | N15: 0
M16: =IF(F16="","",F16/H16)
L17: =+J17*K17/1000 -> 0 | M17: =IF(F17="","",F17/H17) | N17: 0
J18: Total Wt. | K18: =SUM(K10:K17) -> 0 | N18: =SUM(N10:N17) -> 0
L19: Sub-total: | M19: =SUM(L10:L18) -> 0
N20: =M19/P98 -> 0
B21: Purchased Part | C21: Description | J21: Unit price (US$/pc) | K21: Usage per toy | L21: US$ per toy
C22: Fabric Cost
C23: 58" 320G 1.5MM white crystal ultra-soft, digital positioning printing | D23: 58"320G 1.5MM白色水晶超柔，数码定位印 | J23: =14/6.8*1.06 -> 2.1823529 | K23: 0.12876019 | L23: =K23*J23 -> 0.28100018
C24: 58" 220G Black Edge Lumber | D24: 58" 220G黑色边纶布 | J24: =6.2/6.8*1.06 -> 0.96647059 | K24: 0.0010625041 | L24: =K24*J24 -> 0.001026879
C25: 58" 2MM red velvet fabric | D25: 36"2MM红色戟绒布 | J25: =9.2/6.8*1.06 -> 1.4341176 | K25: 0.018578644 | L25: =K25*J25 -> 0.026643961
C26: 58" 2MM white velvet fabric | D26: 36"2MM白色戟绒布 | J26: =9.2/6.8*1.06 -> 1.4341176 | K26: 0.001806257 | L26: =K26*J26 -> 0.0025903851
C27: 58" 180G White Edge Lumber | D27: 58"180G白色边伦布 | J27: =5/6.8*1.06 -> 0.77941176 | K27: 0.0024083427 | L27: =K27*J27 -> 0.0018770906
L28: =K28*J28 -> 0
L29: =K29*J29 -> 0
L30: =K30*J30 -> 0
L31: =K31*J31 -> 0
L32: =K32*J32 -> 0
M36: =SUM(L23:L36) -> 0.3131385 | N36: =M36/P98 -> 0.42981294
C37: Metal Parts Cost
L38: =J38*K38 -> 0
L39: =J39*K39 -> 0
L40: =J40*K40 -> 0
L41: =J41*K41 -> 0
L42: =J42*K42 -> 0
L43: =J43*K43 -> 0
L44: =J44*K44 -> 0
...

Sheet Rex
A1: VENDOR QUOTE FORM
A2: INDIVIDUAL COST BREAKDOWN
A3: From (Vendor) : | C3: ROYAL REGENT PRODUCTS INDUSTRIES LIMITED | M3: PREPARED BY : | N3: =Summary!N4 -> Charles
A4: To CUSTOMER : | C4: SPIN MASTER TOYS FAR EAST LTD | M4: REVISION : | N4: =Summary!N6 -> V2
A5: MATERIAL NO ; | C5: =Summary!C6 -> 1097236 | M5: DATE : | N5: =Summary!N8 -> 46096
A6: MATERIAL GROUP : | C6: =Summary!C7 -> 0
A7: DESCRIPTION : | C7: 29090/ T.94703-0001/ PWP LPP - 6.88 Movie Plush Refresh - GML--Rex
B9: In-Housed Molding | C9: Parts (each row below represents a single mold) | D9: Mold No. | E9: Part No. | F9: Cav/UP | I9: Material | J9: Resin price (US$/kg) | K9: Wt. per toy (g) | L9: US$ per toy | N9: Molding Cost (US$/pc) | O9: Cycle time (sec) | P9: Machine size (Ton) | Q9: Molding Labour Rate (US$/hr)
M10: =IF(F10="","",F10/H10)
L11: =+J11*K11/1000 -> 0 | M11: =IF(F11="","",F11/H11) | N11: 0
M12: =IF(F12="","",F12/H12)
M13: =IF(F13="","",F13/H13)
M14: =IF(F14="","",F14/H14)
L15: =+J15*K15/1000 -> 0 | M15: =IF(F15="","",F15/H15) | N15: 0
M16: =IF(F16="","",F16/H16)
L17: =+J17*K17/1000 -> 0 | M17: =IF(F17="","",F17/H17) | N17: 0
J18: Total Wt. | K18: =SUM(K10:K17) -> 0 | N18: =SUM(N10:N17) -> 0
L19: Sub-total: | M19: =SUM(L10:L18) -> 0
N20: =M19/P98 -> 0
B21: Purchased Part | C21: Description | J21: Unit price (US$/pc) | K21: Usage per toy | L21: US$ per toy
C22: Fabric Cost
C23: 58" 320G 1.5MM White Crystal Super Soft + Digital Positioning Print | D23: 58"320G 1.5MM白色水晶超柔+数码定位印 | J23: =14/6.8*1.06 -> 2.1823529 | K23: 0.14776912 | L23: =K23*J23 -> 0.32248438
C24: 58" 220G Black Edge Lurex Fabric | D24: 58" 220G黑色边纶布 | J24: =6.2/6.8*1.06 -> 0.96647059 | K24: 0.00090312851 | L24: =K24*J24 -> 0.00087284714
C25: 36" 2MM Black Jifu Fabric | D25: 36"2MM黑色戟绒布 | J25: =9.2/6.8*1.06 -> 1.4341176 | K25: 0.0053724568 | L25: =K25*J25 -> 0.007704735
C26: 36" 2MM Black Jifu Fabric | D26: 36"2MM黑色戟绒布 | J26: =9.2/6.8*1.06 -> 1.4341176 | K26: 0.010235456 | L26: =K26*J26 -> 0.014678849
C27: 36" 2MM White Jifu + Digital Positioning Print | D27: 36"2MM白色戟绒+数码定位印 | J27: =17.1/6.8*1.06 -> 2.6655882 | K27: 0.0090312851 | L27: =K27*J27 -> 0.024073687
C28: 58" 180G White Edge Lurex Fabric | D28: 58"180G白色边伦布 | J28: =5/6.8*1.06 -> 0.77941176 | K28: 0.001806257 | L28: =K28*J28 -> 0.001407818
L29: =K29*J29 -> 0
L30: =K30*J30 -> 0
L31: =K31*J31 -> 0
L32: =K32*J32 -> 0
M36: =SUM(L23:L36) -> 0.37122231 | N36: =M36/P98 -> 0.47191487
C37: Metal Parts Cost
L38: =J38*K38 -> 0
L39: =J39*K39 -> 0
L40: =J40*K40 -> 0
L41: =J41*K41 -> 0
L42: =J42*K42 -> 0
L43: =J43*K43 -> 0
L44: =J44*K44 -> 0
...

Sheet Chase
A1: VENDOR QUOTE FORM
A2: INDIVIDUAL COST BREAKDOWN
A3: From (Vendor) : | C3: ROYAL REGENT PRODUCTS INDUSTRIES LIMITED | M3: PREPARED BY : | N3: =Summary!N4 -> Charles
A4: To CUSTOMER : | C4: SPIN MASTER TOYS FAR EAST LTD | M4: REVISION : | N4: =Summary!N6 -> V2
A5: MATERIAL NO ; | C5: =Summary!C6 -> 1097236 | M5: DATE : | N5: =Summary!N8 -> 46096
A6: MATERIAL GROUP : | C6: =Summary!C7 -> 0
A7: DESCRIPTION : | C7: 29090/ T.94703-0001/ PWP LPP - 6.88 Movie Plush Refresh - GML--Chase
B9: In-Housed Molding | C9: Parts (each row below represents a single mold) | D9: Mold No. | E9: Part No. | F9: Cav/UP | I9: Material | J9: Resin price (US$/kg) | K9: Wt. per toy (g) | L9: US$ per toy | N9: Molding Cost (US$/pc) | O9: Cycle time (sec) | P9: Machine size (Ton) | Q9: Molding Labour Rate (US$/hr)
M10: =IF(F10="","",F10/H10)
L11: =+J11*K11/1000 -> 0 | M11: =IF(F11="","",F11/H11) | N11: 0
M12: =IF(F12="","",F12/H12)
M13: =IF(F13="","",F13/H13)
M14: =IF(F14="","",F14/H14)
L15: =+J15*K15/1000 -> 0 | M15: =IF(F15="","",F15/H15) | N15: 0
M16: =IF(F16="","",F16/H16)
L17: =+J17*K17/1000 -> 0 | M17: =IF(F17="","",F17/H17) | N17: 0
J18: Total Wt. | K18: =SUM(K10:K17) -> 0 | N18: =SUM(N10:N17) -> 0
L19: Sub-total: | M19: =SUM(L10:L18) -> 0
N20: =M19/P98 -> 0
B21: Purchased Part | C21: Description | J21: Unit price (US$/pc) | K21: Usage per toy | L21: US$ per toy
C22: Fabric Cost
C23: 58" 320G 1.5MM White Crystal Super Soft, Digital Positioning Print | D23: 58"320G 1.5MM白色水晶超柔，数码定位印 | J23: =14/6.8*1.06 -> 2.1823529 | K23: 0.11218825 | L23: =K23*J23 -> 0.24483436
C24: 58" 220G black edge linen fabric | D24: 58" 220G黑色边纶布 | J24: =6.2/6.8*1.06 -> 0.96647059 | K24: 0.00090312851 | L24: =K24*J24 -> 0.00087284714
C25: 36" 2MM black jinvelvet fabric | D25: 36"2MM黑色戟绒布 | J25: =9.2/6.8*1.06 -> 1.4341176 | K25: 0.0038903997 | L25: =K25*J25 -> 0.0055792909
C26: 36" 2MM dark brown jinvelvet fabric | D26: 36"2MM深棕色戟绒布 | J26: =9.2/6.8*1.06 -> 1.4341176 | K26: 0.0019066046 | L26: =K26*J26 -> 0.0027342953
C27: 58" 180G white edge linen fabric | D27: 58"180G白色边伦布 | J27: =5/6.8*1.06 -> 0.77941176 | K27: 0.0020642937 | L27: =K27*J27 -> 0.0016089348
L28: =K28*J28 -> 0
L29: =K29*J29 -> 0
L30: =K30*J30 -> 0
L31: =K31*J31 -> 0
L32: =K32*J32 -> 0
M36: =SUM(L23:L36) -> 0.25562973 | N36: =M36/P98 -> 0.38094716
C37: Metal Parts Cost
L38: =J38*K38 -> 0
L39: =J39*K39 -> 0
L40: =J40*K40 -> 0
L41: =J41*K41 -> 0
L42: =J42*K42 -> 0
L43: =J43*K43 -> 0
L44: =J44*K44 -> 0
...

Sheet Rubble
A1: VENDOR QUOTE FORM
A2: INDIVIDUAL COST BREAKDOWN
A3: From (Vendor) : | C3: ROYAL REGENT PRODUCTS INDUSTRIES LIMITED | M3: PREPARED BY : | N3: =Summary!N4 -> Charles
A4: To CUSTOMER : | C4: SPIN MASTER TOYS FAR EAST LTD | M4: REVISION : | N4: =Summary!N6 -> V2
A5: MATERIAL NO ; | C5: =Summary!C6 -> 1097236 | M5: DATE : | N5: =Summary!N8 -> 46096
A6: MATERIAL GROUP : | C6: =Summary!C7 -> 0
A7: DESCRIPTION : | C7: 29090/ T.94703-0001/ PWP LPP - 6.88 Movie Plush Refresh - GML--Rubble
B9: In-Housed Molding | C9: Parts (each row below represents a single mold) | D9: Mold No. | E9: Part No. | F9: Cav/UP | I9: Material | J9: Resin price (US$/kg) | K9: Wt. per toy (g) | L9: US$ per toy | N9: Molding Cost (US$/pc) | O9: Cycle time (sec) | P9: Machine size (Ton) | Q9: Molding Labour Rate (US$/hr)
M10: =IF(F10="","",F10/H10)
L11: =+J11*K11/1000 -> 0 | M11: =IF(F11="","",F11/H11) | N11: 0
M12: =IF(F12="","",F12/H12)
M13: =IF(F13="","",F13/H13)
M14: =IF(F14="","",F14/H14)
L15: =+J15*K15/1000 -> 0 | M15: =IF(F15="","",F15/H15) | N15: 0
M16: =IF(F16="","",F16/H16)
L17: =+J17*K17/1000 -> 0 | M17: =IF(F17="","",F17/H17) | N17: 0
J18: Total Wt. | K18: =SUM(K10:K17) -> 0 | N18: =SUM(N10:N17) -> 0
L19: Sub-total: | M19: =SUM(L10:L18) -> 0
N20: =M19/P98 -> 0
B21: Purchased Part | C21: Description | J21: Unit price (US$/pc) | K21: Usage per toy | L21: US$ per toy
C22: Fabric Cost
C23: 58" 320G 1.5MM White Crystal Ultra Soft, Digital Positioning Printing | D23: 58"320G 1.5MM白色水晶超柔，数码定位印 | J23: =14/6.8*1.06 -> 2.1823529 | K23: 0.12443706 | L23: =K23*J23 -> 0.27156558
C24: 58" 220G Black Edge Lumber | D24: 58" 220G黑色边纶布 | J24: =6.2/6.8*1.06 -> 0.96647059 | K24: 0.00082102592 | L24: =K24*J24 -> 0.0007934974
C25: 58" 2MM Yellow Velvet Fabric | D25: 36"2MM黄色戟绒布 | J25: =9.2/6.8*1.06 -> 1.4341176 | K25: 0.0049261555 | L25: =K25*J25 -> 0.0070646865
C26: 58" 2MM Brownish Yellow Velvet | D26: 36"2MM焦黄色戟绒布 | J26: =9.2/6.8*1.06 -> 1.4341176 | K26: 0.0010034761 | L26: =K26*J26 -> 0.0014391028
C27: 58" 180G White Edge Lumber | D27: 58"180G白色边伦布 | J27: =5/6.8*1.06 -> 0.77941176 | K27: 0.0031198985 | L27: =K27*J27 -> 0.0024316856
L28: =K28*J28 -> 0
L29: =K29*J29 -> 0
L30: =K30*J30 -> 0
L31: =K31*J31 -> 0
L32: =K32*J32 -> 0
M36: =SUM(L23:L36) -> 0.28329455 | N36: =M36/P98 -> 0.40545831
C37: Metal Parts Cost
L38: =J38*K38 -> 0
L39: =J39*K39 -> 0
L40: =J40*K40 -> 0
L41: =J41*K41 -> 0
L42: =J42*K42 -> 0
L43: =J43*K43 -> 0
L44: =J44*K44 -> 0
...
