Workbook

Sheet 77425包装MA 
A1: 迷你衣柜装MA明细
A2: 放MA日期 | B2: PO号码 | C2: MA订单号码 | D2: 货号 | E2: 数量 | F2: 名称 | G2: 版本号 | H2: 彩盒 1L | I2: 说明书 5L | K2: 彩盒 3L | L2: 中文说明书 | N2: 备注
A3: 44930 | B3: 77200 77361 Dino Strike S4, S5 & 77349 Fashion S2 包材放订 | C3: 1000012977 | D3: 77425 | E3: 20000 | F3: Color box | G3: A | H3: 20000
A4: 44930 | B4: 77200 77361 Dino Strike S4, S5 & 77349 Fashion S2 包材放订 | C4: 1000012978 | D4: 77425 | E4: 20000 | F4: Instruction Book | G4: A | I4: 20000
A5: 44991 | B5: 77200 77361 Dino Strike S4, S5 & 77349 Fashion S2 包材放订 | C5: 1000013388 | D5: 77425 | E5: 5000 | F5: Color box | G5: A | K5: 5000
D6: 77425 | E6: 订单备料 | L6: 3000
A7: 45023 | B7: 77200 77361 Dino Strike S4, S5 & 77349 Fashion S2 包材放订 | C7: 1000013765 | D7: 77425 | E7: 10000 | F7: Color box | G7: A | H7: 10000
A8: 45023 | B8: 77200 77361 Dino Strike S4, S5 & 77349 Fashion S2 包材放订 | C8: 1000013766 | D8: 77425 | E8: 20000 | F8: Instruction Book | G8: A | I8: 20000
A9: 45034 | B9: 77200 77361 Dino Strike S4, S5 & 77349 Fashion S2 包材放订 | C9: 1000013938 | D9: 77425 | E9: 10000 | F9: Color box | G9: A | H9: 10000
A10: 45034 | B10: 77200 77361 Dino Strike S4, S5 & 77349 Fashion S2 包材放订 | C10: 1000013939 | D10: 77425 | E10: 10000 | F10: Instruction Book | G10: A | I10: 10000
A11: 45043 | B11: 77200 77361 Dino Strike S4, S5 & 77349 Fashion S2 包材放订 | C11: 1000014135 | D11: 77425 | E11: 20000 | F11: Color box | G11: A | H11: 20000
A12: 45043 | B12: 77200 77361 Dino Strike S4, S5 & 77349 Fashion S2 包材放订 | C12: 1000014136 | D12: 77425 | E12: 10000 | F12: Color box | G12: A | K12: 10000
A13: 45043 | B13: 77200 77361 Dino Strike S4, S5 & 77349 Fashion S2 包材放订 | C13: 1000014137 | D13: 77425 | E13: 25000 | F13: Instruction Book | G13: A | I13: 25000
A14: 45111 | B14: 77200 77361 Dino Strike S4, S5 & 77349 Fashion S2 包材放订 | C14: 1000015246 | D14: 77425 | E14: 20000 | F14: Color box | G14: A | H14: 20000
A15: 45111 | B15: 77200 77361 Dino Strike S4, S5 & 77349 Fashion S2 包材放订 | C15: 1000015247 | D15: 77425 | E15: 15000 | F15: Instruction Book | G15: A | I15: 15000
A16: 45111 | B16: 77200 77361 Dino Strike S4, S5 & 77349 Fashion S2 包材放订 | C16: 1000015248 | D16: 77425 | E16: 5000 | F16: Color box | G16: A | K16: 5000
A17: 45128 | B17: 77200 77361 Dino Strike S4, S5 & 77349 Fashion S2 包材放订 | C17: 1000015524 | D17: 77425 | E17: 10000 | F17: Instruction Book | G17: A | I17: 10000
A18: 45142 | B18: 77200 77361 Dino Strike S4, S5 & 77349 Fashion S2 包材放订 | C18: 1000015842 | D18: 77425 | E18: 15000 | F18: Color box | G18: A | H18: 15000
A19: 45142 | B19: 77200 77361 Dino Strike S4, S5 & 77349 Fashion S2 包材放订 | C19: 1000015843 | D19: 77425 | E19: 10000 | F19: Instruction Book | G19: A | I19: 10000
A20: 45475 | B20: 77200 77361 Dino Strike S4, S5 & 77349 Fashion S2 包材放订 | C20: 1000021482 | D20: 77425 | E20: 2000 | F20: Color box | G20: A | K20: 2000
A21: 45490 | B21: 77200 77361 Dino Strike S4, S5 & 77349 Fashion S2 包材放订 | C21: 1000021895 | D21: 77425 | E21: 5000 | F21: Instruction Book | G21: A | I21: 5000
A22: 45559 | B22: 77200 77361 Dino Strike S4, S5 & 77349 Fashion S2 包材放订 | C22: 1000023322 | D22: 77425 | E22: 3436 | F22: Color box | G22: A | H22: 3436
A23: 45559 | B23: 77200 77361 Dino Strike S4, S5 & 77349 Fashion S2 包材放订 | C23: 1000023323 | D23: 77425 | E23: 2456 | F23: Instruction Book | G23: A | I23: 2456 | N23: 最后一次放订，按照实际订单数量采购
N24: 最后一次放订，按照实际订单数量采购
A27: 包材合计 | H27: =SUM(H3:H26) -> 98436 | I27: =SUM(I3:I26) -> 117456 | J27: =SUM(J3:J26) -> 0 | K27: =SUM(K3:K26) -> 22000 | L27: =SUM(L3:L26) -> 3000
A29: 接单汇总数 | H29: ='77425明细 '!AK20+H32 -> 95060 | I29: ='77425明细 '!AL20+I32 -> 115160 | K29: ='77425明细 '!AM20+K32 -> 22020 | L29: ='77425明细 '!AN20+L32 -> 3000
A31: 欠数 | H31: =H27-H29 -> 3376 | I31: =I27-I29 -> 2296 | J31: =J27-J29 -> 0 | K31: =K27-K29 -> -20 | L31: =L27-L29 -> 0
F32: 2024年删除数 | H32: 93316 | I32: 113416 | J32: 0 | K32: 22020 | L32: 3000

Sheet 77425明细 
A1: 香港接单日期 | B1: 第三方客户名称 | C1: 走货国家 | D1: ZURU PO NO# | E1: 第三方客户 PO NO# | F1: SKU | G1: ITEM# | H1: 货品名称 | I1: PO数量(只) | J1: 内箱装箱数量(只) | K1: 外箱装箱数量(只) | L1: 总箱数 | M1: 计划出货期 | N1: 计划验货期 | O1: 第三方客户公证行验货 | P1: 验货结果 | Q1: S/O(截仓期) | R1: 箱唛 (收到日期) | S1: 外箱贴纸 | T1: 贴纸资料 (收到日期及订购日期) | U1: 备注 | V1: ZURU跟单组员 | W1: 单价USD | X1: 金额USD | Y1: 发票号 | Z1: 系统货号 | AA1: 是否入系统 | AB1: 下单情况 | AC1: 生产情况 | AD1: 已回数量 | AE1: 欠数 | AF1: HN回复完成时间 | AG1: 贴纸 | AH1: 纸箱 | AI1: 77425 有香味 | AJ1: 77425 无香味 | AK1: 彩盒 A/B版 MA 1L | AL1: 说明书 5L A/B版本 | AM1: 彩盒 MA 3L | AN1: 中文版说明书
A2: 45614 | B2: Amazon Mexico, S. DE R.L. DE CV | C2: 墨西哥 | D2: 4500151559 | E2: 64SP3ZYY | F2: 4500151559-20 | G2: 77425-S001 | H2: 迷你衣柜 | I2: 24 | J2: 0 | K2: 4 | L2: =I2/K2 -> 6 | M2: 45649 | N2: 45645 | P2: PASS | R2: 空白外箱加印ZURU Logo+MADE IN CHINA+SSCC LABEL(客供贴纸），无shipping mark,日期使用ZURU 标准版本 | S2: 有 | T2: 欠 | U2: 日期码格式：ZURU INC(BVI) 标准格式 日期：按实际生产日期 Packaging Info: 77425: MA 1L+进口商贴纸+SSCC贴纸 Remark: Amazon FOB订单，出口Mexico，外箱最长边不能超过25" （超过了，case pack只能为1），不符合要求的大货，一律不接受。 1.空白外箱加印ZURU Logo+MADE IN CHINA+SSCC LABEL(客供贴纸），无shipping mark,日期使用ZURU 标准版本。SSCC Label显示的是客人自己的item#，SSCC Lab el 贴在外箱正面的正中间，贴一面即可，跟单订购，贴纸离外箱距必须至少3cm,每一张SSCC Label都是唯一且有不同流水及条码的，没有损耗，绝对不可贴错，否 则贴错或损坏一张会导致全部都错，千万要注意！ 2. 日期码使用ZURU标准版 3. 客户PO备注在remark处 5.77425: 3PCS AAA Batteries (Not included) | V2: Zoe Luo | W2: 8.2879 | X2: =I2*W2 -> 198.9096 | Y2: 88897-1.6 | Z2: 77425-S001 | AA2: 已入 | AB2: 系统出单 | AD2: 24 | AE2: =AD2-I2 -> 0 | AG2: OK | AI2: =I2 -> 24 | AK2: =I2 -> 24 | AL2: =I2 -> 24
A3: 45631 | D3: ZMPO24913 | G3: 77425-S001 | H3: 迷你衣柜 | I3: 60 | J3: 0 | K3: 4 | L3: =I3/K3 -> 15 | M3: 45649 | N3: 45645 | R3: 周转箱 | S3: 无 | T3: 无 | U3: Remark:大货最新ZURU Logo版本/请用大货标准箱装箱4PCS/箱共15箱/箱唛请参照邮件附件 备注：收到样品订单后尽快安排 ，注意样板品质质量要求要高于大货品质要求 ，送货时必须要附带送货单(没有送货单和QC检验合格报告的仓库一律拒绝收货)，请知悉，谢谢！ | V3: Angus | Y3: 94902-4.30 | Z3: 77425-S001 | AA3: 已入 | AB3: 系统出单 | AD3: 60 | AE3: =AD3-I3 -> 0 | AI3: =I3 -> 60 | AK3: =I3 -> 60 | AL3: =I3 -> 60
A4: 45702 | B4: TJX UK | C4: 英国 | D4: 4500157680 | E4: TJX UK: PO#50047489 | F4: 4500157680-50 | G4: 77425-S001 | H4: 迷你衣柜 | I4: 548 | J4: 0 | K4: 4 | L4: =I4/K4 -> 137 | M4: 45741 | N4: 45737 | P4: PASS | R4: 45712 | S4: 无 | T4: 45707 | U4: 日期码格式：ZURU INC(BVI) 标准格式 日期：按实际生产日期 Packaging Info: TJX UK: PO#50047540(71101)---TJX UK: PO#50047545(71101)---TJX UK: PO#50047483(71101)---TJX UK: PO#50047488(71101)---TJX UK: PO#50047489(77425) SLOB ITEM消耗库存： 77425: MA1L (1L warning) 最新UPC包装 Remark: 1. 出往UK的产品+包装务必打上UKCA logo ，否则客人会退货且当地会有罚款； 2. 订单必须经过ZURU QC验货并且通过后方可出货； 3. 订单每行对应客人不同的PO， 箱唛也有不同，做货的时候请分开堆放； 4. 包装条码请按包装备注上的对应的警示语语种包装，出德国的订单(订单备注为TJX Europe-DE)需要确保有英语+德语+荷兰语+波兰语警示语； 5. 订单每行对应客人不同的PO，即同款item的价格贴纸都不相同，请注意收到贴纸后不要弄混!（客人PO号请参考PO最后一栏remark）； 6. 客供价格贴纸位置为产品正面右上角，不能遮住产品信息，大货生产前，请把贴纸位置先发给跟单确认 7. 涉及到相关款式会有闪粉的或者微塑料的，请统一默认出无闪粉或者不含微塑料版本; 8. 外箱封箱必须是工字型封箱方式； | V4: Sandy Shao | W4: 7.6428 | X4: =W4*I4 -> 4188.2544 | Y4: 94634-3.25 | Z4: 77425-S001 | AA4: 已入 | AB4: 系统出单 | AD4: 548 | AE4: =AD4-I4 -> 0 | AG4: 无 | AI4: =I4 -> 548 | AK4: =I4 -> 548 | AL4: =I4 -> 548
A5: 45702 | B5: TJX UK c/o TJX Distribution Ltd & C | C5: 德国 | D5: 4500157675 | E5: TJX Europe-DE: PO#55047520 | F5: 4500157675-60 | G5: 77425-S001 | H5: 迷你衣柜 | I5: 548 | J5: 0 | K5: 4 | L5: =I5/K5 -> 137 | M5: 45741 | N5: 45737 | P5: PASS | R5: 45712 | S5: 无 | T5: 45707 | U5: 日期码格式：ZURU INC(BVI) 标准格式 日期：按实际生产日期 Packaging Info: TJX Europe-DE: PO#55047501(71101)---TJX Europe-DE: PO#55047502(71101)---TJX Europe-DE: PO#55047504(71101)---TJX Europe-DE: PO#55047514(71101)--- TJX Europe-DE: PO#55047516(71101)---TJX Europe-DE: PO#55047520(77425) SLOB ITEM 消耗库存： 77425: MA1L (1L warning) 最新UPC包装+1张贴纸（含德语<(>&<)>荷兰语<(>&<)>波兰语警告语） Remark: 1. 出往UK的产品+包装务必打上UKCA logo ，否则客人会退货且当地会有罚款； 2. 订单必须经过ZURU QC验货并且通过后方可出货； 3. 订单每行对应客人不同的PO， 箱唛也有不同，做货的时候请分开堆放； 4. 包装条码请按包装备注上的对应的警示语语种包装，出德国的订单(订单备注为TJX Europe-DE)需要确保有英语+德语+荷兰语+波兰语警示语； 5. 订单每行对应客人不同的PO，即同款item的价格贴纸都不相同，请注意收到贴纸后不要弄混!（客人PO号请参考PO最后一栏remark）； 6. 客供价格贴纸位置为产品正面右上角，不能遮住产品信息，大货生产前，请把贴纸位置先发给跟单确认 7. 涉及到相关款式会有闪粉的或者微塑料的，请统一默认出无闪粉或者不含微塑料版本; 8. 外箱封箱必须是工字型封箱方式； | V5: Sandy Shao | W5: 7.339 | X5: =W5*I5 -> 4021.772 | Y5: 94645-3.26 | Z5: 77425-S001 | AA5: 已入 | AB5: 系统出单 | AD5: 548 | AE5: =AD5-I5 -> 0 | AG5: OK | AI5: =I5 -> 548 | AK5: =I5 -> 548 | AL5: =I5 -> 548
A6: 45756 | B6: Amazon Mexico, S. DE R.L. DE CV | C6: 墨西哥 | D6: 4500163057 | E6: 5K7XXSZF | F6: 4500163057-50 | G6: 77425-S001 | H6: 迷你衣柜 | I6: 92 | J6: 0 | K6: 4 | L6: =I6/K6 -> 23 | M6: 45812 | N6: =M6-4 -> 45808 | P6: PASS | R6: 空白外箱加印ZURU Logo+MADE IN CHINA+SSCC LABEL(客供贴纸），无shipping mark,日期使用ZURU 标准版本。SSCC Label显示的是客人自己的item#，SSCC Lab | S6: 有 | T6: 欠 | U6: 日期码格式：ZURU INC(BVI) 标准格式 日期：按实际生产日期 5. 77425：MA 1L UPC包装+MA 多语说明书+进口商贴纸+SSCC label Remark: 1. Amazon FOB订单，出口Mexico，外箱最长边不能超过25" （超过了，case pack只能为1），不符合要求的大货，一律不接受。 2. 空白外箱加印ZURU Logo+MADE IN CHINA+SSCC LABEL(客供贴纸），无shipping mark,日期使用ZURU 标准版本。SSCC Label显示的是客人自己的item#，SSCC Lab el 贴在外箱正面的正中间，贴一面即可，跟单订购，贴纸离外箱距必须至少3cm,每一张SSCC Label都是唯一且有不同流水及条码的，没有损耗，绝对不可贴错，否 则贴错或损坏一张会导致全部都错，千万要注意！ 3. 日期码使用ZURU标准版 4. 9543D:2PCS AAA BATTERIES(NOT INCLUDED) 5. 77425: 3PCS AAA BATTERIES(NOT INCLUDED) | V6: Ever Li | W6: 8.1164 | X6: =W6*I6 -> 746.7088 | Y6: 95288-6.10 | Z6: 77425-S001 | AA6: 已入 | AB6: 系统出单 | AD6: 92 | AE6: =AD6-I6 -> 0 | AG6: OK | AI6: =I6 -> 92 | AK6: =I6 -> 92 | AL6: =I6 -> 92
A7: 45756 | B7: Amazon Mexico, S. DE R.L. DE CV | C7: 墨西哥 | D7: 4500163057 | E7: 34P65IJU | F7: 4500163057-80 | G7: 774225-S001 | H7: 迷你衣柜 | I7: 64 | J7: 0 | K7: 4 | L7: =I7/K7 -> 16 | M7: 45812 | N7: =M7-4 -> 45808 | P7: PASS | R7: 空白外箱加印ZURU Logo+MADE IN CHINA+SSCC LABEL(客供贴纸），无shipping mark,日期使用ZURU 标准版本。SSCC Label显示的是客人自己的item#，SSCC Lab | S7: 有 | T7: 欠 | U7: 日期码格式：ZURU INC(BVI) 标准格式 日期：按实际生产日期 5. 77425：MA 1L UPC包装+MA 多语说明书+进口商贴纸+SSCC label Remark: 1. Amazon FOB订单，出口Mexico，外箱最长边不能超过25" （超过了，case pack只能为1），不符合要求的大货，一律不接受。 2. 空白外箱加印ZURU Logo+MADE IN CHINA+SSCC LABEL(客供贴纸），无shipping mark,日期使用ZURU 标准版本。SSCC Label显示的是客人自己的item#，SSCC Lab el 贴在外箱正面的正中间，贴一面即可，跟单订购，贴纸离外箱距必须至少3cm,每一张SSCC Label都是唯一且有不同流水及条码的，没有损耗，绝对不可贴错，否 则贴错或损坏一张会导致全部都错，千万要注意！ 3. 日期码使用ZURU标准版 4. 9543D:2PCS AAA BATTERIES(NOT INCLUDED) 5. 77425: 3PCS AAA BATTERIES(NOT INCLUDED) | V7: Ever Li | W7: 8.1164 | X7: =W7*I7 -> 519.4496 | Y7: 95288-6.10 | Z7: 77425-S001 | AA7: 已入 | AB7: 系统出单 | AD7: 64 | AE7: =AD7-I7 -> 0 | AG7: OK | AI7: =I7 -> 64 | AK7: =I7 -> 64 | AL7: =I7 -> 64
A8: 45818 | B8: ZURU LLC | C8: 美国 | D8: 4500169495 | E8: B0BS8LM6R6 | F8: 4500169495-120 | G8: 77425-S001-MTS | H8: 迷你衣柜 | I8: 212 | J8: 0 | K8: 4 | L8: =I8/K8 -> 53 | M8: 45855 | N8: 45852 | P8: PASS | R8: 45818 | S8: 无 | T8: 无 | U8: 日期码格式：ZURU INC(BVI) 标准格式 日期：按实际生产日期 Packaging Info: #77425 MA 1L UPC版本 Remark: 1.Amazon domestic 订单。出口美国。外箱最长边不能超过25" （超过了，case pack只能为1），不符合要求的大货，一律不接受。 2.无第三方验货/测试要求。 3.日期码使用ZURU标准版本。 4.邮包盒要印刷日期码。 | V8: Kelly Shen/Mia Pan/P | W8: 4.4908 | X8: =W8*I8 -> 952.0496 | Y8: ZB01104R1-8.6 | Z8: 77425-S001 | AA8: 已入 | AB8: 系统出单 | AD8: 212 | AE8: =AD8-I8 -> 0 | AG8: 无 | AI8: =I8 -> 212 | AK8: =I8 -> 212 | AL8: =I8 -> 212
A9: 45744 | B9: YOYO LLC | C9: 吉尔吉斯斯坦 | D9: 4500161685 | F9: 4500161685-10 | G9: 77425-S001 | H9: 迷你衣柜 | I9: 100 | J9: 0 | K9: 4 | L9: =I9/K9 -> 25 | M9: 45880 | N9: 45876 | P9: PASS | R9: 45784 | S9: 无 | T9: 45856 | U9: 日期码格式：ZURU INC(BVI) 标准格式 日期：按实际生产日期 Packaging Info: 1L MA UPC 包装+ 进口商贴纸 ， MA PDQ /说明书/指南（如有） Remark: 标准配比 | V9: Ann | W9: 7.1871 | X9: =W9*I9 -> 718.71 | Y9: 96119-8.22 | Z9: 77425-S001 | AA9: 已入 | AB9: 系统出单 | AD9: 100 | AE9: =AD9-I9 -> 0 | AG9: OK | AI9: =I9 -> 100 | AK9: =I9 -> 100 | AL9: =I9 -> 100
A10: 45840 | B10: TJX UK | C10: 英国 | D10: 4500172515 | E10: TJX UK PO#50687573 | F10: 4500172515-60 | G10: 77425-S001 | H10: 迷你衣柜 | I10: 96 | J10: 0 | K10: 4 | L10: =I10/K10 -> 24 | M10: 45880 | N10: 45876 | P10: PASS | R10: 45840 | S10: 无 | T10: 45861 | U10: 日期码格式：ZURU INC(BVI) 标准格式 日期：按实际生产日期 Packaging Info: 77425 MA1L (1L warning) 最新UPC包装+1张客供价格贴纸 Remark: 1. 出往UK的产品+包装务必打上UKCA logo ，否则客人会退货且当地会有罚款； 2. 订单必须经过ZURU QC验货并且通过后方可出货； 3. 订单每行对应客人不同的PO， 箱唛也有不同，做货的时候请分开堆放； 4. 包装条码请按包装备注上的对应的警示语语种包装，出德国的订单(订单备注为TJX Europe-DE)需要确保有英语+德语+荷兰语+波兰语警示语； 5. 订单每行对应客人不同的PO，即同款item的价格贴纸都不相同，请注意收到贴纸后不要弄混!（客人PO号请参考PO最后一栏remark）； 6. 客供价格贴纸位置为产品正面右上角，不能遮住产品信息，大货生产前，请把贴纸位置先发给跟单确认 7. 涉及到相关款式会有闪粉的或者微塑料的，请统一默认出无闪粉或者不含微塑料版本; 8. 外箱封箱必须是工字型封箱方式； | V10: Sandy Shao | W10: 7.4847 | X10: =W10*I10 -> 718.5312 | Y10: 96093-8.19 | Z10: 77425-S001 | AA10: 已入 | AB10: 系统出单 | AD10: 96 | AE10: =AD10-I10 -> 0 | AG10: OK | AI10: =I10 -> 96 | AK10: =I10 -> 96 | AL10: =I10 -> 96
G20: 接单汇总 | I20: =SUM(I2:I19) -> 1744 | AI20: =SUM(AI2:AI19) -> 1744 | AJ20: =SUM(AJ2:AJ19) -> 0 | AK20: =SUM(AK2:AK19) -> 1744 | AL20: =SUM(AL2:AL19) -> 1744 | AM20: =SUM(AM2:AM19) -> 0 | AN20: =SUM(AN2:AN19) -> 0 | AO20: =SUM(AO2:AO19) -> 0 | AP20: =SUM(AP2:AP19) -> 0 | ... AX20: =SUM(AX2:AX19) -> 0 | AZ20: =SUM(AZ2:AZ19) -> 0 | BA20: =SUM(BA2:BA19) -> 0 | BB20: =SUM(BB2:BB19) -> 0 | BC20: =SUM(BC2:BC19) -> 0 | BD20: =SUM(BD2:BD19) -> 0 | BE20: =SUM(BE2:BE19) -> 0 | BF20: =SUM(BF2:BF19) -> 0 | BG20: =SUM(BG2:BG19) -> 0 | ... BJ20: =SUM(BJ2:BJ19) -> 0

Sheet 77485 S3 明细
A1: 香港接单日期 | B1: 第三方客户名称 | C1: 走货国家 | D1: ZURU PO NO# | E1: 第三方客户 PO NO# | F1: SKU | G1: ITEM# | H1: 货品名称 | I1: PO数量(只) | J1: 内箱装箱数量(只) | K1: 外箱装箱数量(只) | L1: 总箱数 | M1: 计划出货期 | N1: 计划验货期 | O1: 第三方客户公证行验货 | P1: 验货结果 | Q1: S/O(截仓期) | R1: 箱唛 (收到日期) | S1: 外箱贴纸 | T1: 贴纸资料 (收到日期及订购日期) | U1: 样板 | V1: 备注 | W1: ZURU跟单组员 | X1: 单价USD | Y1: 金额USD | Z1: 是否收到客版包装资料 | AA1: 发票号 | AB1: 系统货号 | AC1: 是否入系统 | AD1: 下单情况 | AE1: 生产情况 | AF1: 已回数量 | AG1: 欠数 | AH1: HN回复完成时间 | AI1: 贴纸 | AJ1: 纸箱 | AK1: 77485 有香味 | AL1: 77485 无香味 | AM1: MA 1L A/B收缩膜 | AN1: MA 1L 收缩膜 无条码 | AO1: MA 3L 收缩膜 无条码 | AP1: MA 3L 收缩膜 | AQ1: 客版收缩膜 | AR1: MA 5L 收藏指南 | AS1: MA 5L B版收藏指南 | AT1: 客版收藏指南 | AU1: WM 客版收藏指南 | AV1: 客版 1L 8pcs GQ1-S001 | AW1: 1L 21pcs GQ2-S001 | AX1: 3L 21pcs GQ2-S001 | AY1: 1L 12PCS GQ3-S001 | AZ1: 1L B 12PCS GQ3-S001 | BA1: 3L 12PCS GQ3-S001 | BB1: 1L 12PCS GQ4-S001 | BC1: 1L 13PCS GQ6-S001 | BD1: 13PCS GQ6-S001 3L | BE1: 25PCS GQ7-S001 | BF1: 25PCS GQ7-S001 3L | BG1: 客版 SK-S001 不含底座 | BH1: 客版 1L SK-S001 不含底座 | BI1: 3L SK-S002 含底座 60pcs | BJ1: 3L SK1-S001 30pcs | BK1: MSLD104展示架 | BL1: 客版不含鞋子 收缩膜 | BM1: 客版不含鞋子 收藏指南 | BN1: 77486 圆筒 | BO1: 77486 3L彩纸 | BP1: 77486 TJX版本 彩纸 | BQ1: 77486 贴纸 | BR1: 77601 圆筒 | BS1: 776016 3L彩纸 | BT1: 77601 贴纸 | BU1: 合计数量 | BV1: 累计数量 | BW1: MA 数量 | BX1: 820000 | BY1: 300000 | BZ1: 300000 | CA1: 200000 | CB1: =400000+500000+300000 -> 1200000 | CC1: GQ2/GQ7 | CD1: 累计数量 | CE1: MA 数量 | CF1: 2000 | CG1: 13970 | CH1: 11700 | CI1: =22330+10000 -> 32330
A2: 45604 | B2: THE ENTERTAINER | C2: 英国 | D2: 4500150141 | E2: 4500150141-2 | F2: 4500150141-80 | G2: 77485GQ6-S001 | H2: 3代迷你小手袋 | I2: 3120 | J2: 0 | K2: 52 | L2: =I2/K2 -> 60 | M2: 45657 | N2: 45653 | P2: PASS | R2: 45610 | S2: 无 | T2: 客户EAN条码贴一张覆盖ZURU 原条码，条码贴翻订单4500148687 | V2: 日期码格式：ZURU INC(BVI) 标准格式 日期：按实际生产日期 Packaging Info: 77485GQ6：MA最新1L配套包装+客户EAN条码贴一张覆盖ZURU 原条码，条码贴翻订单4500148687。 Remark: *MA版本按工厂现有最新库存即可，订单出英国，请注意检查产品及包装应带UKCA图标，包装显示ZURU UK LTD信息，QC同事请查核，如有问题与跟单确认。 *生产日期按实际（法定工作日），按ZURU标准格式即可 ，但是请知悉包装日期码需要早于或者等于外箱日期码 ，不能晚于外箱日期码 *请注意所有订单都需要经过ZURU QC验货并且通过后方可出货 *条码以订单显示为准 ，请安排生产前先核对 ，有问题请提出。 *所有产品按符合欧洲标准走货，需要是不含微塑料版本 。 *涉及到硼的，如可选择情况下应使用低硼版本 （slime 类别低硼一般低于300ppm)，无选择的应与跟单复核再安排 。 | W2: Sherry Lu | X2: 1.8967 | Y2: =I2*X2 -> 5917.704 | AA2: 88877-1.4 | AB2: 77485GQ6-S001 | AC2: 已入 | AD2: 系统出单 | AF2: =52+3068 -> 3120 | AG2: =AF2-I2 -> 0 | AI2: OK | AK2: =I2 -> 3120 | AM2: =I2 -> 3120 | AS2: =I2 -> 3120 | BC2: =AK2/13 -> 240 | BU2: =AK2+AL2 -> 3120 | BV2: =2188428+BU2 -> 2191548 | CA2: =SUM(BX$1:CB$1)-BV2 -> 628452 | CC2: =AW2+AX2+BE2+BF2 -> 0 | CD2: =46986.5714285714+CC2 -> 46986.571 | CH2: =$CF$1+$CG$1+$CH$1+$CI$1-CD2 -> 13013.429
A3: 45586 | B3: ROSS PROCUREMENT.INC | C3: 美国 | D3: 4500148421 | E3: 60190475 | F3: 4500148421-20 | G3: 77486-S001 | H3: 3代迷你小手袋 圆筒装 | I3: 3000 | J3: 0 | K3: 12 | L3: =I3/K3 -> 250 | M3: 45653 | N3: 45649 | P3: PASS | R3: 通用模板 | S3: 无 | T3: 欠客供价格贴纸 | V3: 日期码格式： 标准格式 日期：按实际生产日期 Packaging Info: URU MA UPC 收缩膜+客版铜版纸+PVC桶 + 客供价格贴纸，出口美国 , 优先使用MA 1L 最新版本 。 Remark: 1.ZURU MA UPC 收缩膜+客版铜版纸+PVC桶 + 客供价格贴纸，出口美国 , 优先使用MA 1L 最新版本 。 2.价格贴纸位于包装正面右下角，不挡住重要信息即可，可适当调整 ，价格贴纸由跟单提供。 3.标准日期码格式，产品和包装必须有日期码 。 4.同个产品同个货期不可出现不同的包装。 5. PVC 桶中球不能出现完全相同的ASSORTMENT ， 即同一个PVC 中球里的ASSORTMENT 需要不同。 以免消费者失望。 6.PVC 桶上加上 MINI BRANDS 的LOGO 贴纸 （ ZURU 统一要求的） 7.收缩膜可使用标版带UPC条码MA，无需白色贴纸覆盖。 | W3: Sophia Zhou | X3: 4.0635 | Y3: =I3*X3 -> 12190.5 | AA3: 88928-1.7 | AB3: 77486-S001 | AC3: 已入 | AD3: 系统出单 | AF3: =2988+12 -> 3000 | AG3: =AF3-I3 -> 0 | AI3: OK | AK3: =I3*2 -> 6000 | AM3: =I3*2 -> 6000 | AS3: =I3*2 -> 6000 | BN3: =I3 -> 3000 | BO3: =I3 -> 3000 | BQ3: =I3 -> 3000 | BU3: =AK3+AL3 -> 6000 | BV3: =BV2+BU3 -> 2197548 | CA3: =SUM(BX$1:CB$1)-BV3 -> 622452 | CC3: =AW3+AX3+BE3+BF3 -> 0 | CD3: =CD2+CC3 -> 46986.571 | CH3: =$CF$1+$CG$1+$CH$1+$CI$1-CD3 -> 13013.429
A4: 45615 | B4: COMERCIALIZADORA MEXICO AMERICANA S | C4: 墨西哥 | D4: 4500151611 | E4: 5251213810 | F4: 4500151611-80 | G4: 77485GQ7-S001 | H4: 3代迷你小手袋 | I4: 15700 | J4: 0 | K4: 50 | L4: =I4/K4 -> 314 | M4: 45650 | N4: 45652 | O4: 客版日期码要求：LOT+ZURU标准日期码格式。东莞生产的格式：LOTDGYYYYMMDD, DG是东莞拼音首字母， YYYYMMDD是实际的年月日，例如(LOTDG20240920) | P4: PASS | R4: 45631 | S4: 无 | T4: 进口商贴纸翻单PO4500120342 | V4: 日期码格式：LOTDGYYYYMMDD 日期：按实际生产日期 Packaging Info: 77485GQ7: 3L MA EAN 收缩膜+新UPC条码贴纸+进口商贴纸+MA 5L 收藏指南+MA 3L PDQ+箱唛；进口商贴纸翻单PO4500120342，条码贴纸不翻单 Remark: 1. 客版日期码要求：LOT+ZURU标准日期码格式。东莞生产的格式：LOTDGYYYYMMDD, DG是东莞拼音首字母， YYYYMMDD是实际的年月日，例如(LOTDG20240920) 3. 此单有第三方监柜，至少多备一套完整的物料用于监柜，请多备料。 4. WM墨西哥防霉的新要求:货物必须在出货主箱和集装箱中按要求放置干燥剂，干燥剂指定品牌干霸 77485GQ7： 需要在每箱放入6小包干燥剂，每包干燥剂重量2g 如走柜货等loading plan 确认后再通知集装箱干燥剂数量 | W4: Ever Li | X4: 1.9784 | Y4: =X4*I4 -> 31060.88 | AA4: 88845-1.2 | AB4: 77485GQ7-S001-3L-1 | AC4: 已入 | AD4: 系统出单 | AF4: =15700 -> 15700 | AG4: =AF4-I4 -> 0 | AI4: OK | AK4: =I4 -> 15700 | AP4: =I4 -> 15700 | AS4: =I4 -> 15700 | BF4: =I4/25 -> 628 | BU4: =AK4+AL4 -> 15700 | BV4: =BV3+BU4 -> 2213248 | CA4: =SUM(BX$1:CB$1)-BV4 -> 606752 | CC4: =AW4+AX4+BE4+BF4 -> 628 | CD4: =CD3+CC4 -> 47614.571 | CH4: =$CF$1+$CG$1+$CH$1+$CI$1-CD4 -> 12385.429
A5: 45644 | B5: WALGREEN CO. | C5: 美国 | D5: MPO03152 | G5: 77485-S001 | H5: 3代迷你小手袋 | I5: 42616 | J5: 0 | K5: 24 | L5: =I5/K5 -> 1775.6667 | M5: 45667 | N5: 45663 | O5: 此MPO订单替换原手工单MPOWAL034 | P5: PASS | R5: 周转箱 | S5: 无 | T5: WIC贴纸（WIC # 795592） | V5: Remark:1.此MPO订单替换原手工单MPOWAL034 2.订单要求参考MPOWAL034 3.分三批送货 第-批 77485-8528pcs 77555-8528pcs(已送货)第二批77485-25584pcs77555-25584pcs(已送货)第三批 77485-8504pcs77555-8504pcs(待安排送货) | W5: Cara Li | X5: 1.8043 | Y5: =X5*I5 -> 76892.049 | AA5: 94402-2.27 94410-2.28 | AB5: 77485-S001 | AC5: 已入 | AD5: 消耗取消单 | AF5: =34112+8520 -> 42632 | AG5: =AF5-I5 -> 16 | AI5: OK | AK5: =I5 -> 42616 | AM5: =I5 -> 42616 | AS5: =I5 -> 42616 | BU5: =AK5+AL5 -> 42616 | BV5: =BV4+BU5 -> 2255864 | CA5: =SUM(BX$1:CB$1)-BV5 -> 564136 | CC5: =AW5+AX5+BE5+BF5 -> 0 | CD5: =CD4+CC5 -> 47614.571 | CH5: =$CF$1+$CG$1+$CH$1+$CI$1-CD5 -> 12385.429
A6: 45573 | B6: Ansaldo Chile | C6: 智利 | D6: 4500146540 | F6: 4500146540-40 | G6: 77485GQ7-S001 | H6: 3代迷你小手袋 | I6: 3200 | J6: 0 | K6: 50 | L6: =I6/K6 -> 64 | M6: 45659 | N6: 45654 | P6: PASS | R6: 45580 | S6: 无 | T6: 进口商贴纸翻单PO4500146361 | V6: 日期码格式：ZURU INC(BVI) 标准格式 日期：按实际生产日期 Packaging Info: 77485GQ7:MA 1L包装+进口商贴纸+箱唛,进口商贴纸翻单PO4500146361 Remark: | W6: Ava Liang | X6: 1.9961 | Y6: =X6*I6 -> 6387.52 | AA6: 88980-1.10 | AB6: 77485GQ7-S001 | AC6: 已入 | AD6: 系统出单 | AF6: 3200 | AG6: =AF6-I6 -> 0 | AI6: OK | AK6: =I6 -> 3200 | AM6: =I6 -> 3200 | AS6: =I6 -> 3200 | BE6: =I6/25 -> 128 | BU6: =AK6+AL6 -> 3200 | BV6: =BV5+BU6 -> 2259064 | CA6: =SUM(BX$1:CB$1)-BV6 -> 560936 | CC6: =AW6+AX6+BE6+BF6 -> 128 | CD6: =CD5+CC6 -> 47742.571 | CH6: =$CF$1+$CG$1+$CH$1+$CI$1-CD6 -> 12257.429
A7: 45621 | B7: London Supply Group SA | C7: 乌拉圭 | D7: 4500152280 | F7: 4500152280-60 | G7: 77485GQ7-S001 | H7: 3代迷你小手袋 | I7: 250 | J7: 0 | K7: 50 | L7: =I7/K7 -> 5 | M7: 45660 | N7: 45656 | P7: PASS | R7: 45623 | S7: 无 | T7: 无 | V7: 日期码格式：ZURU INC(BVI) 标准格式 日期：按实际生产日期 Tracking Code: Packaging Info: 77485GQ7:MA 1L包装+箱唛，无进口商贴纸 Remark: | W7: Ava Liang | X7: 2.0019 | Y7: =X7*I7 -> 500.475 | AA7: 88896-1.6 | AB7: 77485GQ7-S001 | AC7: 已入 | AD7: 系统出单 | AF7: 250 | AG7: =AF7-I7 -> 0 | AI7: 无 | AK7: =I7 -> 250 | AM7: =I7 -> 250 | AS7: =I7 -> 250 | BE7: =I7/25 -> 10 | BU7: =AK7+AL7 -> 250 | BV7: =BV6+BU7 -> 2259314 | CA7: =SUM(BX$1:CB$1)-BV7 -> 560686 | CC7: =AW7+AX7+BE7+BF7 -> 10 | CD7: =CD6+CC7 -> 47752.571 | CH7: =$CF$1+$CG$1+$CH$1+$CI$1-CD7 -> 12247.429
A8: 45615 | B8: VM INTERNATIONAL | C8: 美国 | D8: 4500151779 | F8: 4500151779-70 | G8: 77485GQ6-S003 | H8: 3代迷你小手袋 | I8: 1092 | J8: 0 | K8: 13 | L8: =I8/K8 -> 84 | M8: 45666 | N8: 45296 | O8: 2025/1/6 第三方验货 | P8: PASS | Q8: 1/12 出货 | R8: 45638 | S8: 无 | T8: 无 | V8: 日期码格式：ZURU INC(BVI) 标准格式 日期：按实际生产日期 Packaging Info: 1.ZURU 标准日期码格式， 2.无第三方测试和验货，ZURU 内部QC验货即可出货 Remark: 3. 优先 MA 1L UPC包装; 4. 纸箱印ZURU LOGO，出口美国； | W8: Iris Yuan | X8: 1.9068 | Y8: =I8*X8 -> 2082.2256 | AA8: 94112-1.18 | AB8: 77485GQ6-S003 | AC8: 已入 | AD8: 系统出单 | AF8: 1092 | AG8: =AF8-I8 -> 0 | AI8: 无 | AK8: =I8 -> 1092 | AM8: =I8 -> 1092 | AS8: =I8 -> 1092 | BC8: =I8/13 -> 84 | BU8: =AK8+AL8 -> 1092 | BV8: =BV7+BU8 -> 2260406 | CA8: =SUM(BX$1:CB$1)-BV8 -> 559594 | CC8: =AW8+AX8+BE8+BF8 -> 0 | CD8: =CD7+CC8 -> 47752.571 | CH8: =$CF$1+$CG$1+$CH$1+$CI$1-CD8 -> 12247.429
A9: 45621 | B9: WAL-MART STORES INC. USA | C9: 美国 | D9: 4500152202 | E9: 0877286348 ELWOOD | F9: 4500152202-10 | G9: 77485SLB-S004 | H9: 3代迷你小手袋 | I9: 3456 | J9: 0 | K9: 1152 | L9: =I9/K9 -> 3 | M9: 45300 | N9: 45296 | O9: 2025/1/6 自检 | P9: PASS | R9: 45621 | S9: 无 | T9: 12/20 RFID贴纸 艾利贴纸（不干胶贴纸）和一张普通贴纸（A4纸） | V9: 日期码格式：ZURU DGYYYYMMDD CHINA(日期避开周末和法定节假日即可） 日期：按实际生产日期 Tracking Code: Packaging Info: 77485SLB-S004 1.包装要求： MA 1L收缩膜+ 客版 收藏指南B版+MA 纸袋+客版 1L PDQ，翻单：4500128976 每pcs产品上要贴1张RFID贴纸，贴纸由ZURU提供，贴纸位置请严格按照我们签回的签板； Remark: 77485SLB-S004 1.包装要求： MA 1L收缩膜+ 客版 收藏指南B版+MA 纸袋+客版 1L PDQ，翻单：4500128976 每pcs产品上要贴1张RFID贴纸，贴纸由ZURU提供，贴纸位置请严格按照我们签回的签板； 2. 外箱印刷带条码的RFID箱唛：RFID紫色色带+WM Dept.图标+RFID图标+ITF-14条码，四面右下角印刷ZURU logo, ITFF条码只印刷在正唛一面，在加印的时候确保 条形码能扫描出来，外箱侧面任一角落加印："MADE IN CHINA" 字样； 3. 每个slip sheet上面贴一张艾利贴纸（不干胶贴纸）和一张普通贴纸（A4纸），slip sheet打印的普通贴纸的尺寸不能比艾利贴纸小，普通贴纸内容见附件； 4. 在产品上和包装上要有日期码、以及要有MADE IN CHINA和ZURU字样； 5. 产品如有扎带口要剪平，不能刮手。 6. 此单需要验货，请多备料 7. 此单以slip sheet出货，77485：1152pcs/96CTN/Slip Sheet | W9: Maggie Xie | X9: 2182.1336 | Y9: 6546.4008 | AA9: 94397-2.27 | AB9: 77485SLB-S004 | AC9: 已入 | AD9: 系统出单 | AF9: 3456 | AG9: =AF9-I9 -> 0 | AK9: =I9 -> 3456 | AM9: =I9 -> 3456 | AU9: 3456 | AZ9: =I9/12 -> 288 | BU9: =AK9+AL9 -> 3456 | BV9: =BV8+BU9 -> 2263862 | CA9: =SUM(BX$1:CB$1)-BV9 -> 556138 | CC9: =AW9+AX9+BE9+BF9 -> 0 | CD9: =CD8+CC9 -> 47752.571 | CH9: =$CF$1+$CG$1+$CH$1+$CI$1-CD9 -> 12247.429
A10: 45621 | B10: WAL-MART STORES INC. USA | C10: 美国 | D10: 4500152202 | E10: 0877286379 RIDGEVILLE SC | F10: 4500152202-20 | G10: 77485SLB-S004 | H10: 3代迷你小手袋 | I10: 3456 | J10: 0 | K10: 1152 | L10: =I10/K10 -> 3 | M10: 45300 | N10: 45296 | O10: 2025/1/6 自检 | P10: PASS | R10: 45621 | S10: 无 | T10: 12/20 RFID贴纸 艾利贴纸（不干胶贴纸）和一张普通贴纸（A4纸） | V10: 日期码格式：ZURU DGYYYYMMDD CHINA(日期避开周末和法定节假日即可） 日期：按实际生产日期 Tracking Code: Packaging Info: 77485SLB-S004 1.包装要求： MA 1L收缩膜+ 客版 收藏指南B版+MA 纸袋+客版 1L PDQ，翻单：4500128976 每pcs产品上要贴1张RFID贴纸，贴纸由ZURU提供，贴纸位置请严格按照我们签回的签板； Remark: 77485SLB-S004 1.包装要求： MA 1L收缩膜+ 客版 收藏指南B版+MA 纸袋+客版 1L PDQ，翻单：4500128976 每pcs产品上要贴1张RFID贴纸，贴纸由ZURU提供，贴纸位置请严格按照我们签回的签板； 2. 外箱印刷带条码的RFID箱唛：RFID紫色色带+WM Dept.图标+RFID图标+ITF-14条码，四面右下角印刷ZURU logo, ITFF条码只印刷在正唛一面，在加印的时候确保 条形码能扫描出来，外箱侧面任一角落加印："MADE IN CHINA" 字样； 3. 每个slip sheet上面贴一张艾利贴纸（不干胶贴纸）和一张普通贴纸（A4纸），slip sheet打印的普通贴纸的尺寸不能比艾利贴纸小，普通贴纸内容见附件； 4. 在产品上和包装上要有日期码、以及要有MADE IN CHINA和ZURU字样； 5. 产品如有扎带口要剪平，不能刮手。 6. 此单需要验货，请多备料 7. 此单以slip sheet出货，77485：1152pcs/96CTN/Slip Sheet | W10: Maggie Xie | X10: 2182.1336 | Y10: 6546.4008 | AA10: 94397-2.27 | AB10: 77485SLB-S004 | AC10: 已入 | AD10: 系统出单 | AG10: =AF10-I10 -> -3456 | AK10: =I10 -> 3456 | AM10: =I10 -> 3456 | AU10: 3456 | AZ10: =I10/12 -> 288 | BU10: =AK10+AL10 -> 3456 | BV10: =BV9+BU10 -> 2267318 | CA10: =SUM(BX$1:CB$1)-BV10 -> 552682 | CC10: =AW10+AX10+BE10+BF10 -> 0 | CD10: =CD9+CC10 -> 47752.571 | CH10: =$CF$1+$CG$1+$CH$1+$CI$1-CD10 -> 12247.429
A11: 45621 | B11: WAL-MART STORES INC. USA | C11: 美国 | D11: 4500152202 | E11: 0877286391 EASTVALE | F11: 4500152202-30 | G11: 77485SLB-S004 | H11: 3代迷你小手袋 | I11: 5760 | J11: 0 | K11: 1152 | L11: =I11/K11 -> 5 | M11: 45300 | N11: 45296 | O11: 2025/1/6 自检 | P11: PASS | R11: 45621 | S11: 无 | T11: 12/20 RFID贴纸 艾利贴纸（不干胶贴纸）和一张普通贴纸（A4纸） | V11: 日期码格式：ZURU DGYYYYMMDD CHINA(日期避开周末和法定节假日即可） 日期：按实际生产日期 Tracking Code: Packaging Info: 77485SLB-S004 1.包装要求： MA 1L收缩膜+ 客版 收藏指南B版+MA 纸袋+客版 1L PDQ，翻单：4500128976 每pcs产品上要贴1张RFID贴纸，贴纸由ZURU提供，贴纸位置请严格按照我们签回的签板； Remark: 77485SLB-S004 1.包装要求： MA 1L收缩膜+ 客版 收藏指南B版+MA 纸袋+客版 1L PDQ，翻单：4500128976 每pcs产品上要贴1张RFID贴纸，贴纸由ZURU提供，贴纸位置请严格按照我们签回的签板； 2. 外箱印刷带条码的RFID箱唛：RFID紫色色带+WM Dept.图标+RFID图标+ITF-14条码，四面右下角印刷ZURU logo, ITFF条码只印刷在正唛一面，在加印的时候确保 条形码能扫描出来，外箱侧面任一角落加印："MADE IN CHINA" 字样； 3. 每个slip sheet上面贴一张艾利贴纸（不干胶贴纸）和一张普通贴纸（A4纸），slip sheet打印的普通贴纸的尺寸不能比艾利贴纸小，普通贴纸内容见附件； 4. 在产品上和包装上要有日期码、以及要有MADE IN CHINA和ZURU字样； 5. 产品如有扎带口要剪平，不能刮手。 6. 此单需要验货，请多备料 7. 此单以slip sheet出货，77485：1152pcs/96CTN/Slip Sheet | W11: Maggie Xie | X11: 2182.1336 | Y11: 10910.668 | AA11: 94052-1.15 | AB11: 77485SLB-S004 | AC11: 已入 | AD11: 系统出单 | AF11: 5760 | AG11: =AF11-I11 -> 0 | AK11: =I11 -> 5760 | AM11: =I11 -> 5760 | AU11: 5760 | AZ11: =I11/12 -> 480 | BU11: =AK11+AL11 -> 5760 | BV11: =BV10+BU11 -> 2273078 | CA11: =SUM(BX$1:CB$1)-BV11 -> 546922 | CC11: =AW11+AX11+BE11+BF11 -> 0 | CD11: =CD10+CC11 -> 47752.571 | CH11: =$CF$1+$CG$1+$CH$1+$CI$1-CD11 -> 12247.429
A12: 45621 | B12: WAL-MART STORES INC. USA | C12: 美国 | D12: 4500152202 | E12: 0877286395 STATESBORO | F12: 4500152202-40 | G12: 77485SLB-S004 | H12: 3代迷你小手袋 | I12: 1152 | J12: 0 | K12: 1152 | L12: =I12/K12 -> 1 | M12: 45300 | N12: 45296 | O12: 2025/1/6 自检 | P12: PASS | R12: 45621 | S12: 无 | T12: 12/20 RFID贴纸 艾利贴纸（不干胶贴纸）和一张普通贴纸（A4纸） | V12: 日期码格式：ZURU DGYYYYMMDD CHINA(日期避开周末和法定节假日即可） 日期：按实际生产日期 Tracking Code: Packaging Info: 77485SLB-S004 1.包装要求： MA 1L收缩膜+ 客版 收藏指南B版+MA 纸袋+客版 1L PDQ，翻单：4500128976 每pcs产品上要贴1张RFID贴纸，贴纸由ZURU提供，贴纸位置请严格按照我们签回的签板； Remark: 77485SLB-S004 1.包装要求： MA 1L收缩膜+ 客版 收藏指南B版+MA 纸袋+客版 1L PDQ，翻单：4500128976 每pcs产品上要贴1张RFID贴纸，贴纸由ZURU提供，贴纸位置请严格按照我们签回的签板； 2. 外箱印刷带条码的RFID箱唛：RFID紫色色带+WM Dept.图标+RFID图标+ITF-14条码，四面右下角印刷ZURU logo, ITFF条码只印刷在正唛一面，在加印的时候确保 条形码能扫描出来，外箱侧面任一角落加印："MADE IN CHINA" 字样； 3. 每个slip sheet上面贴一张艾利贴纸（不干胶贴纸）和一张普通贴纸（A4纸），slip sheet打印的普通贴纸的尺寸不能比艾利贴纸小，普通贴纸内容见附件； 4. 在产品上和包装上要有日期码、以及要有MADE IN CHINA和ZURU字样； 5. 产品如有扎带口要剪平，不能刮手。 6. 此单需要验货，请多备料 7. 此单以slip sheet出货，77485：1152pcs/96CTN/Slip Sheet | W12: Maggie Xie | X12: 2182.1336 | Y12: 2182.1336 | AA12: 94052-1.15 | AB12: 77485SLB-S004 | AC12: 已入 | AD12: 系统出单 | AF12: 1152 | AG12: =AF12-I12 -> 0 | AK12: =I12 -> 1152 | AM12: =I12 -> 1152 | AU12: 1152 | AZ12: =I12/12 -> 96 | BU12: =AK12+AL12 -> 1152 | BV12: =BV11+BU12 -> 2274230 | CA12: =SUM(BX$1:CB$1)-BV12 -> 545770 | CC12: =AW12+AX12+BE12+BF12 -> 0 | CD12: =CD11+CC12 -> 47752.571 | CH12: =$CF$1+$CG$1+$CH$1+$CI$1-CD12 -> 12247.429
A13: 45621 | B13: WAL-MART STORES INC. USA | C13: 美国 | D13: 4500152202 | E13: 0877286401 SUFFOLK | F13: 4500152202-50 | G13: 77485SLB-S004 | H13: 3代迷你小手袋 | I13: 4608 | J13: 0 | K13: 1152 | L13: =I13/K13 -> 4 | M13: 45300 | N13: 45296 | O13: 2025/1/6 自检 | P13: PASS | R13: 45621 | S13: 无 | T13: 12/20 RFID贴纸 艾利贴纸（不干胶贴纸）和一张普通贴纸（A4纸） | V13: 日期码格式：ZURU DGYYYYMMDD CHINA(日期避开周末和法定节假日即可） 日期：按实际生产日期 Tracking Code: Packaging Info: 77485SLB-S004 1.包装要求： MA 1L收缩膜+ 客版 收藏指南B版+MA 纸袋+客版 1L PDQ，翻单：4500128976 每pcs产品上要贴1张RFID贴纸，贴纸由ZURU提供，贴纸位置请严格按照我们签回的签板； Remark: 77485SLB-S004 1.包装要求： MA 1L收缩膜+ 客版 收藏指南B版+MA 纸袋+客版 1L PDQ，翻单：4500128976 每pcs产品上要贴1张RFID贴纸，贴纸由ZURU提供，贴纸位置请严格按照我们签回的签板； 2. 外箱印刷带条码的RFID箱唛：RFID紫色色带+WM Dept.图标+RFID图标+ITF-14条码，四面右下角印刷ZURU logo, ITFF条码只印刷在正唛一面，在加印的时候确保 条形码能扫描出来，外箱侧面任一角落加印："MADE IN CHINA" 字样； 3. 每个slip sheet上面贴一张艾利贴纸（不干胶贴纸）和一张普通贴纸（A4纸），slip sheet打印的普通贴纸的尺寸不能比艾利贴纸小，普通贴纸内容见附件； 4. 在产品上和包装上要有日期码、以及要有MADE IN CHINA和ZURU字样； 5. 产品如有扎带口要剪平，不能刮手。 6. 此单需要验货，请多备料 7. 此单以slip sheet出货，77485：1152pcs/96CTN/Slip Sheet | W13: Maggie Xie | X13: 2182.1336 | Y13: 8728.5344 | AA13: 94018-1.13 | AB13: 77485SLB-S004 | AC13: 已入 | AD13: 系统出单 | AF13: 4608 | AG13: =AF13-I13 -> 0 | AK13: =I13 -> 4608 | AM13: =I13 -> 4608 | AU13: 4608 | AZ13: =I13/12 -> 384 | BU13: =AK13+AL13 -> 4608 | BV13: =BV12+BU13 -> 2278838 | CA13: =SUM(BX$1:CB$1)-BV13 -> 541162 | CC13: =AW13+AX13+BE13+BF13 -> 0 | CD13: =CD12+CC13 -> 47752.571 | CH13: =$CF$1+$CG$1+$CH$1+$CI$1-CD13 -> 12247.429
A14: 45621 | B14: WAL-MART STORES INC. USA | C14: 美国 | D14: 4500152202 | E14: 0877286405 HOUSTON | F14: 4500152202-60 | G14: 77485SLB-S004 | H14: 3代迷你小手袋 | I14: 5760 | J14: 0 | K14: 1152 | L14: =I14/K14 -> 5 | M14: 45300 | N14: 45296 | O14: 2025/1/6 自检 | P14: PASS | R14: 45621 | S14: 无 | T14: 12/20 RFID贴纸 艾利贴纸（不干胶贴纸）和一张普通贴纸（A4纸） | V14: 日期码格式：ZURU DGYYYYMMDD CHINA(日期避开周末和法定节假日即可） 日期：按实际生产日期 Tracking Code: Packaging Info: 77485SLB-S004 1.包装要求： MA 1L收缩膜+ 客版 收藏指南B版+MA 纸袋+客版 1L PDQ，翻单：4500128976 每pcs产品上要贴1张RFID贴纸，贴纸由ZURU提供，贴纸位置请严格按照我们签回的签板； Remark: 77485SLB-S004 1.包装要求： MA 1L收缩膜+ 客版 收藏指南B版+MA 纸袋+客版 1L PDQ，翻单：4500128976 每pcs产品上要贴1张RFID贴纸，贴纸由ZURU提供，贴纸位置请严格按照我们签回的签板； 2. 外箱印刷带条码的RFID箱唛：RFID紫色色带+WM Dept.图标+RFID图标+ITF-14条码，四面右下角印刷ZURU logo, ITFF条码只印刷在正唛一面，在加印的时候确保 条形码能扫描出来，外箱侧面任一角落加印："MADE IN CHINA" 字样； 3. 每个slip sheet上面贴一张艾利贴纸（不干胶贴纸）和一张普通贴纸（A4纸），slip sheet打印的普通贴纸的尺寸不能比艾利贴纸小，普通贴纸内容见附件； 4. 在产品上和包装上要有日期码、以及要有MADE IN CHINA和ZURU字样； 5. 产品如有扎带口要剪平，不能刮手。 6. 此单需要验货，请多备料 7. 此单以slip sheet出货，77485：1152pcs/96CTN/Slip Sheet | W14: Maggie Xie | X14: 2182.1336 | Y14: 10910.668 | AA14: 94397-2.27 | AB14: 77485SLB-S004 | AC14: 已入 | AD14: 系统出单 | AF14: 5760 | AG14: =AF14-I14 -> 0 | AK14: =I14 -> 5760 | AM14: =I14 -> 5760 | AU14: 5760 | AZ14: =I14/12 -> 480 | BU14: =AK14+AL14 -> 5760 | BV14: =BV13+BU14 -> 2284598 | CA14: =SUM(BX$1:CB$1)-BV14 -> 535402 | CC14: =AW14+AX14+BE14+BF14 -> 0 | CD14: =CD13+CC14 -> 47752.571 | CH14: =$CF$1+$CG$1+$CH$1+$CI$1-CD14 -> 12247.429
A15: 45621 | B15: WAL-MART STORES INC. USA | C15: 美国 | D15: 4500152202 | E15: 0877286409 MOBILE | F15: 4500152202-70 | G15: 77485SLB-S004 | H15: 3代迷你小手袋 | I15: 2304 | J15: 0 | K15: 1152 | L15: =I15/K15 -> 2 | M15: 45300 | N15: 45296 | O15: 2025/1/6 自检 | P15: PASS | R15: 45621 | S15: 无 | T15: 12/20 RFID贴纸 艾利贴纸（不干胶贴纸）和一张普通贴纸（A4纸） | V15: 日期码格式：ZURU DGYYYYMMDD CHINA(日期避开周末和法定节假日即可） 日期：按实际生产日期 Tracking Code: Packaging Info: 77485SLB-S004 1.包装要求： MA 1L收缩膜+ 客版 收藏指南B版+MA 纸袋+客版 1L PDQ，翻单：4500128976 每pcs产品上要贴1张RFID贴纸，贴纸由ZURU提供，贴纸位置请严格按照我们签回的签板； Remark: 77485SLB-S004 1.包装要求： MA 1L收缩膜+ 客版 收藏指南B版+MA 纸袋+客版 1L PDQ，翻单：4500128976 每pcs产品上要贴1张RFID贴纸，贴纸由ZURU提供，贴纸位置请严格按照我们签回的签板； 2. 外箱印刷带条码的RFID箱唛：RFID紫色色带+WM Dept.图标+RFID图标+ITF-14条码，四面右下角印刷ZURU logo, ITFF条码只印刷在正唛一面，在加印的时候确保 条形码能扫描出来，外箱侧面任一角落加印："MADE IN CHINA" 字样； 3. 每个slip sheet上面贴一张艾利贴纸（不干胶贴纸）和一张普通贴纸（A4纸），slip sheet打印的普通贴纸的尺寸不能比艾利贴纸小，普通贴纸内容见附件； 4. 在产品上和包装上要有日期码、以及要有MADE IN CHINA和ZURU字样； 5. 产品如有扎带口要剪平，不能刮手。 6. 此单需要验货，请多备料 7. 此单以slip sheet出货，77485：1152pcs/96CTN/Slip Sheet | W15: Maggie Xie | X15: 2182.1336 | Y15: 4364.2672 | AA15: 94052-1.15 | AB15: 77485SLB-S004 | AC15: 已入 | AD15: 系统出单 | AF15: 2304 | AG15: =AF15-I15 -> 0 | AK15: =I15 -> 2304 | AM15: =I15 -> 2304 | AU15: 2304 | AZ15: =I15/12 -> 192 | BU15: =AK15+AL15 -> 2304 | BV15: =BV14+BU15 -> 2286902 | CA15: =SUM(BX$1:CB$1)-BV15 -> 533098 | CC15: =AW15+AX15+BE15+BF15 -> 0 | CD15: =CD14+CC15 -> 47752.571 | CH15: =$CF$1+$CG$1+$CH$1+$CI$1-CD15 -> 12247.429
A16: 45618 | B16: CRG | C16: 哥斯达黎加 | D16: 4500152087 | E16: ZU01-25 | F16: 4500152087-100 | G16: 77485GQ7-S001 | H16: 3代迷你小手袋 | I16: 2000 | J16: 0 | K16: 50 | L16: =I16/K16 -> 40 | M16: 45660 | N16: 45656 | P16: PASS | R16: 45623 | S16: 无 | T16: 45636 | V16: 日期码格式：ZURU INC(BVI) 标准格式 日期：按实际生产日期 Packaging Info: 77485GQ7:MA 1L包装+进口商贴纸+箱唛 Remark: | W16: Ava Liang | X16: 2.0019 | Y16: =X16*I16 -> 4003.8 | AA16: 88961-1.9 | AB16: 77485GQ7-S001 | AC16: 已入 | AD16: 系统出单 | AF16: 2000 | AG16: =AF16-I16 -> 0 | AI16: OK | AK16: =I16 -> 2000 | AM16: =I16 -> 2000 | AS16: =I16 -> 2000 | BE16: =I16/25 -> 80 | BU16: =AK16+AL16 -> 2000 | BV16: =BV15+BU16 -> 2288902 | CA16: =SUM(BX$1:CB$1)-BV16 -> 531098 | CC16: =AW16+AX16+BE16+BF16 -> 80 | CD16: =CD15+CC16 -> 47832.571 | CH16: =$CF$1+$CG$1+$CH$1+$CI$1-CD16 -> 12167.429
A17: 45587 | B17: WALGREEN CO. | C17: 美国 | D17: MPOWAL034 | G17: 77485-S001 | H17: 3代迷你小手袋 | I17: 0 | J17: 0 | K17: 24 | L17: =I17/K17 -> 0 | M17: 45656 | N17: 45652 | R17: 周转箱 | S17: 无 | T17: WIC贴纸（WIC # 795592） | V17: Remark:1. 2% 损耗 2. 送货前必需通知我司安排验货 3.77485：MA 1L包装 + WIC贴纸（WIC # 795592） 4.产品和包装上要有ZURU 标准格式 tracking code DG20241122 4.先安排CRD 11/22的数量，CRD 12/10的数量等通知后再安排 5.11/22完成23452PCS, 11/23抽板测试，抽板后才可以安排送货。所有来料都要测试符合美国联邦法规和州法规后才可以做大货。如因测试问题延期造成罚款需由工厂承担。 6. 装箱方式需另外跟PM确认，用周转箱/周转框，出货前需提供装箱清单 7.收到PO后请寄出每款1个球和全套散件给实验室。大货样77515 12PCS，77555 16PCS,7748516PCS, 待通知后再寄出。 | W17: Cara Li | X17: 1.7942 | Y17: =X17*I17 -> 0 | AB17: 77485-S001 | AC17: 已入 | AD17: 系统出单 | AG17: =AF17-I17 -> 0 | AI17: OK | AK17: =I17 -> 0 | AM17: =I17 -> 0 | AS17: =I17 -> 0 | BU17: =AK17+AL17 -> 0 | BV17: =BV16+BU17 -> 2288902 | CA17: =SUM(BX$1:CB$1)-BV17 -> 531098 | CC17: =AW17+AX17+BE17+BF17 -> 0 | CD17: =CD16+CC17 -> 47832.571 | CH17: =$CF$1+$CG$1+$CH$1+$CI$1-CD17 -> 12167.429
A18: 45604 | B18: Inventive Toys | C18: 俄罗斯联邦 | D18: 4500150836 | F18: 4500150836-20 | G18: 77485GQ6-S001 | H18: 3代迷你小手袋 | I18: 2028 | J18: 0 | K18: 52 | L18: =I18/K18 -> 39 | M18: 45657 | N18: 45653 | O18: 注意 ：外包装 (指: 收缩膜/彩卡/铝箔袋/挂卡/PDQ) /外箱不要打ZURU标准日期码！胶件可以打日期码。 | P18: PASS | R18: 45622 | S18: 无 | T18: 进口商贴纸+EAN条码贴纸 | V18: 日期码格式：外包装/外箱不要打ZURU标准日期码 日期： Packaging Info: 注意 ：外包装 (指: 收缩膜/彩卡/铝箔袋/挂卡/PDQ) /外箱不要打ZURU标准日期码！胶件可以打日期码。 外包装（包括收缩膜/彩卡/PDQ）都不能含Instagram and facebook logo等社交logo; 1L MA 收缩膜 或者彩卡+ 进口商贴纸； MA PDQ + EAN条码贴纸 ， MA指南/说明书（如有）; Remark: 标准配比 ；整单货期2025年1月3 | W18: Ann Zhang | X18: 1.9026 | Y18: =I18*X18 -> 3858.4728 | AA18: 94071-1.16 | AB18: 77485GQ6-S001 | AC18: 已入 | AD18: 系统出单 | AF18: =1976+52 -> 2028 | AG18: =AF18-I18 -> 0 | AI18: OK | AK18: =I18 -> 2028 | AM18: =I18 -> 2028 | AS18: =I18 -> 2028 | BC18: =AK18/13 -> 156 | BU18: =AK18+AL18 -> 2028 | BV18: =BV17+BU18 -> 2290930 | CA18: =SUM(BX$1:CB$1)-BV18 -> 529070 | CC18: =AW18+AX18+BE18+BF18 -> 0 | CD18: =CD17+CC18 -> 47832.571 | CH18: =$CF$1+$CG$1+$CH$1+$CI$1-CD18 -> 12167.429
A19: 45614 | B19: BURLINGTON COAT FACTORY | C19: 美国 | D19: 4500151472 | E19: 客户PO#383017 506 | F19: 4500151472-50 | G19: 77486-S001 | H19: 3代迷你小手袋 圆筒装 | I19: 1800 | J19: 0 | K19: 12 | L19: =I19/K19 -> 150 | M19: 45663 | N19: 45659 | P19: PASS | R19: 45614 | S19: 有 | T19: 45638 | V19: 日期码格式：ZURU INC(BVI) 标准格式 日期：按实际生产日期 Packaging Info: 1，ZURU MA （首选1L）UPC版本+客供价格贴纸+外箱贴纸，出口美国 有PVC桶的价格贴纸贴在PVC桶上面 Remark: 2，产品和包装上印刷ZURU 标准日期码； 3，纸箱中间靠上沿印刷ZURU LOGO，见箱唛资料 4、外箱UCC 条码贴纸，尺寸: 4*6inch，贴在其中一面正唛右下角，贴纸距离外箱底部3.5cm, 侧边距离3.5cm。外箱贴纸由跟单提供电子版, 工厂自行安排，不可用 封箱胶覆盖贴纸条码，贴纸需要可以扫描且无损坏. 5，每个产品有一个价格贴纸， 价格贴纸覆盖UPC条码上 （若UPC 条码太大，可以露出ITEM#, 覆盖条码即可），若价格贴纸覆盖UPC 会挡住文字/图案，在产品背面 找空白处粘贴价格贴纸即可。贴的时候要是会覆盖包装上重要的信息和图案，需要告知跟单。 | W19: Jessi Xu | X19: 4.1259 | Y19: =I19*X19 -> 7426.62 | AA19: 88988-1.11 | AB19: 77486-S001 | AC19: 已入 | AD19: 系统出单 | AF19: 1800 | AG19: =AF19-I19 -> 0 | AI19: OK | AK19: =I19*2 -> 3600 | AM19: =I19*2 -> 3600 | AS19: =I19*2 -> 3600 | BN19: =I19 -> 1800 | BO19: =I19 -> 1800 | BQ19: =I19 -> 1800 | BU19: =AK19+AL19 -> 3600 | BV19: =BV18+BU19 -> 2294530 | CA19: =SUM(BX$1:CB$1)-BV19 -> 525470 | CC19: =AW19+AX19+BE19+BF19 -> 0 | CD19: =CD18+CC19 -> 47832.571 | CH19: =$CF$1+$CG$1+$CH$1+$CI$1-CD19 -> 12167.429
A20: 45614 | B20: BURLINGTON COAT FACTORY | C20: 美国 | D20: 4500151472 | E20: 客户PO#383019 406 | F20: 4500151472-100 | G20: 77486-S001 | H20: 3代迷你小手袋 圆筒装 | I20: 3600 | J20: 0 | K20: 12 | L20: =I20/K20 -> 300 | M20: 45663 | N20: 45659 | P20: PASS | R20: 45614 | S20: 有 | T20: 45638 | V20: 日期码格式：ZURU INC(BVI) 标准格式 日期：按实际生产日期 Packaging Info: 1，ZURU MA （首选1L）UPC版本+客供价格贴纸+外箱贴纸，出口美国 有PVC桶的价格贴纸贴在PVC桶上面 Remark: 2，产品和包装上印刷ZURU 标准日期码； 3，纸箱中间靠上沿印刷ZURU LOGO，见箱唛资料 4、外箱UCC 条码贴纸，尺寸: 4*6inch，贴在其中一面正唛右下角，贴纸距离外箱底部3.5cm, 侧边距离3.5cm。外箱贴纸由跟单提供电子版, 工厂自行安排，不可用 封箱胶覆盖贴纸条码，贴纸需要可以扫描且无损坏. 5，每个产品有一个价格贴纸， 价格贴纸覆盖UPC条码上 （若UPC 条码太大，可以露出ITEM#, 覆盖条码即可），若价格贴纸覆盖UPC 会挡住文字/图案，在产品背面 找空白处粘贴价格贴纸即可。贴的时候要是会覆盖包装上重要的信息和图案，需要告知跟单。 | W20: Jessi Xu | X20: 4.1024 | Y20: =I20*X20 -> 14768.64 | AA20: 88981-1.10 | AB20: 77486-S001 | AC20: 已入 | AD20: 系统出单 | AF20: 3600 | AG20: =AF20-I20 -> 0 | AI20: OK | AK20: =I20*2 -> 7200 | AM20: =I20*2 -> 7200 | AS20: =I20*2 -> 7200 | BN20: =I20 -> 3600 | BO20: =I20 -> 3600 | BQ20: =I20 -> 3600 | BU20: =AK20+AL20 -> 7200 | BV20: =BV19+BU20 -> 2301730 | CA20: =SUM(BX$1:CB$1)-BV20 -> 518270 | CC20: =AW20+AX20+BE20+BF20 -> 0 | CD20: =CD19+CC20 -> 47832.571 | CH20: =$CF$1+$CG$1+$CH$1+$CI$1-CD20 -> 12167.429
A21: 45603 | B21: DD’S DISCOUNTS | C21: 美国 | D21: 4500150308 | E21: 70054030 | F21: 4500150308-10 | G21: 77486-S001 | H21: 3代迷你小手袋 圆筒装 | I21: 600 | J21: 0 | K21: 12 | L21: =I21/K21 -> 50 | M21: 45670 | N21: 45666 | P21: PASS | R21: 45610 | S21: 无 | T21: 欠客供价格贴纸 | V21: 日期码格式： 标准格式 日期：按实际生产日期 Packaging Info: 1.ZURU MA UPC 收缩膜+客版铜版纸+PVC桶 + 客供价格贴纸，出口美国 , 优先使用MA 1L 最新版本 。 Remark: 1.ZURU MA UPC 收缩膜+客版铜版纸+PVC桶 + 客供价格贴纸，出口美国 , 优先使用MA 1L 最新版本 。 2.价格贴纸位于包装正面右下角，不挡住重要信息即可，可适当调整 ，价格贴纸由跟单提供。 3.标准日期码格式，产品和包装必须有日期码 。 4.同个产品同个货期不可出现不同的包装。 5. PVC 桶中球不能出现完全相同的ASSORTMENT ， 即同一个PVC 中球里的ASSORTMENT 需要不同。 以免消费者失望。 6.PVC 桶上加上 MINI BRANDS 的LOGO 贴纸 （ ZURU 统一要求的） 7.收缩膜可使用标版带UPC条码MA，无需白色贴纸覆盖。 8. #77516 收缩膜用3L+空白贴纸 | W21: Taylor Liao | X21: 4.1259 | Y21: =I21*X21 -> 2475.54 | AA21: 94145-1.21 | AB21: 77486-S001 | AC21: 已入 | AD21: 系统出单 | AF21: 600 | AG21: =AF21-I21 -> 0 | AI21: OK | AK21: =I21*2 -> 1200 | AM21: =I21*2 -> 1200 | AS21: =I21*2 -> 1200 | BN21: =I21 -> 600 | BO21: =I21 -> 600 | BQ21: =I21 -> 600 | BU21: =AK21+AL21 -> 1200 | BV21: =BV20+BU21 -> 2302930 | CA21: =SUM(BX$1:CB$1)-BV21 -> 517070 | CC21: =AW21+AX21+BE21+BF21 -> 0 | CD21: =CD20+CC21 -> 47832.571 | CH21: =$CF$1+$CG$1+$CH$1+$CI$1-CD21 -> 12167.429
A22: 45637 | B22: WAL-MART STORES INC. USA | C22: 美国 | D22: 4500153681 | E22: 0881410086 STATESBORO | F22: 4500153681-10 | G22: 77485SLB-S004 | H22: 3代迷你小手袋 | I22: 1152 | J22: 0 | K22: 1152 | L22: =I22/K22 -> 1 | M22: 45671 | N22: 45667 | O22: 2025/1/14第三方验货 | P22: PASS | R22: 外箱印刷带条码的RFID箱唛：RFID紫色色带+WM Dept.图标+RFID图标+ITF-14条码，四面右下角印刷ZURU logo, ITFF条码只印刷在正唛一面，在加印的时候确保 条形码能扫描出来，外箱侧面任一角落加印："MADE IN CHINA" 字样； | S22: 无 | T22: 12/20 寄出RFID贴纸 | V22: 日期码格式：ZURU DGYYYYMMDD CHINA(日期避开周末和法定节假日即可） 日期：按实际生产日期 Packaging Info: 77485SLB-S004 1.包装要求： MA 1L收缩膜+ 客版 收藏指南B版+MA 纸袋+客版 1L PDQ，翻单：4500128976 每pcs产品上要贴1张RFID贴纸，贴纸由ZURU提供，贴纸位置请严格按照我们签回的签板； Remark: 77485SLB-S004 1.包装要求： MA 1L收缩膜+ 客版 收藏指南B版+MA 纸袋+客版 1L PDQ，翻单：4500128976 每pcs产品上要贴1张RFID贴纸，贴纸由ZURU提供，贴纸位置请严格按照我们签回的签板； 2. 外箱印刷带条码的RFID箱唛：RFID紫色色带+WM Dept.图标+RFID图标+ITF-14条码，四面右下角印刷ZURU logo, ITFF条码只印刷在正唛一面，在加印的时候确保 条形码能扫描出来，外箱侧面任一角落加印："MADE IN CHINA" 字样； 3. 每个slip sheet上面贴一张艾利贴纸（不干胶贴纸）和一张普通贴纸（A4纸），slip sheet打印的普通贴纸的尺寸不能比艾利贴纸小，普通贴纸内容见附件； 4. 在产品上和包装上要有日期码、以及要有MADE IN CHINA和ZURU字样； 5. 产品如有扎带口要剪平，不能刮手。 6. 此单需要验货，请多备料 7. 此单以slip sheet出货，77485：1152pcs/96CTN/Slip Sheet | W22: Maggie Xie | X22: 2206.6131 | Y22: 4364.2672 | AA22: 94124-1.20 | AB22: 77485SLB-S004 | AC22: 已入 | AD22: 系统出单 | AF22: 1152 | AG22: =AF22-I22 -> 0 | AK22: =I22 -> 1152 | AM22: =I22 -> 1152 | AU22: =I22 -> 1152 | AZ22: =I22/12 -> 96 | BU22: =AK22+AL22 -> 1152 | BV22: =BV21+BU22 -> 2304082 | CA22: =SUM(BX$1:CB$1)-BV22 -> 515918 | CC22: =AW22+AX22+BE22+BF22 -> 0 | CD22: =CD21+CC22 -> 47832.571 | CH22: =$CF$1+$CG$1+$CH$1+$CI$1-CD22 -> 12167.429
A23: 45637 | B23: WAL-MART STORES INC. USA | C23: 美国 | D23: 4500153681 | E23: 0881410104 ELWOOD | F23: 4500153681-20 | G23: 77485SLB-S004 | H23: 3代迷你小手袋 | I23: 3456 | J23: 0 | K23: 1152 | L23: =I23/K23 -> 3 | M23: 45671 | N23: 45667 | O23: 2025/1/14第三方验货 | P23: PASS | R23: 外箱印刷带条码的RFID箱唛：RFID紫色色带+WM Dept.图标+RFID图标+ITF-14条码，四面右下角印刷ZURU logo, ITFF条码只印刷在正唛一面，在加印的时候确保 条形码能扫描出来，外箱侧面任一角落加印："MADE IN CHINA" 字样； | S23: 无 | T23: 12/20 寄出RFID贴纸 | V23: 日期码格式：ZURU DGYYYYMMDD CHINA(日期避开周末和法定节假日即可） 日期：按实际生产日期 Packaging Info: 77485SLB-S004 1.包装要求： MA 1L收缩膜+ 客版 收藏指南B版+MA 纸袋+客版 1L PDQ，翻单：4500128976 每pcs产品上要贴1张RFID贴纸，贴纸由ZURU提供，贴纸位置请严格按照我们签回的签板； Remark: 77485SLB-S004 1.包装要求： MA 1L收缩膜+ 客版 收藏指南B版+MA 纸袋+客版 1L PDQ，翻单：4500128976 每pcs产品上要贴1张RFID贴纸，贴纸由ZURU提供，贴纸位置请严格按照我们签回的签板； 2. 外箱印刷带条码的RFID箱唛：RFID紫色色带+WM Dept.图标+RFID图标+ITF-14条码，四面右下角印刷ZURU logo, ITFF条码只印刷在正唛一面，在加印的时候确保 条形码能扫描出来，外箱侧面任一角落加印："MADE IN CHINA" 字样； 3. 每个slip sheet上面贴一张艾利贴纸（不干胶贴纸）和一张普通贴纸（A4纸），slip sheet打印的普通贴纸的尺寸不能比艾利贴纸小，普通贴纸内容见附件； 4. 在产品上和包装上要有日期码、以及要有MADE IN CHINA和ZURU字样； 5. 产品如有扎带口要剪平，不能刮手。 6. 此单需要验货，请多备料 7. 此单以slip sheet出货，77485：1152pcs/96CTN/Slip Sheet | W23: Maggie Xie | X23: 2206.6131 | Y23: 4364.2672 | AA23: 94051-1.15 | AB23: 77485SLB-S004 | AC23: 已入 | AD23: 系统出单 | AF23: 3456 | AG23: =AF23-I23 -> 0 | AK23: =I23 -> 3456 | AM23: =I23 -> 3456 | AU23: =I23 -> 3456 | AZ23: =I23/12 -> 288 | BU23: =AK23+AL23 -> 3456 | BV23: =BV22+BU23 -> 2307538 | CA23: =SUM(BX$1:CB$1)-BV23 -> 512462 | CC23: =AW23+AX23+BE23+BF23 -> 0 | CD23: =CD22+CC23 -> 47832.571 | CH23: =$CF$1+$CG$1+$CH$1+$CI$1-CD23 -> 12167.429
A24: 45637 | B24: WAL-MART STORES INC. USA | C24: 美国 | D24: 4500153681 | E24: 0881410110 EASTVALE | F24: 4500153681-30 | G24: 77485SLB-S004 | H24: 3代迷你小手袋 | I24: 1152 | J24: 0 | K24: 1152 | L24: =I24/K24 -> 1 | M24: 45671 | N24: 45667 | O24: 2025/1/14第三方验货 | P24: PASS | R24: 外箱印刷带条码的RFID箱唛：RFID紫色色带+WM Dept.图标+RFID图标+ITF-14条码，四面右下角印刷ZURU logo, ITFF条码只印刷在正唛一面，在加印的时候确保 条形码能扫描出来，外箱侧面任一角落加印："MADE IN CHINA" 字样； | S24: 无 | T24: 12/20 寄出RFID贴纸 | V24: 日期码格式：ZURU DGYYYYMMDD CHINA(日期避开周末和法定节假日即可） 日期：按实际生产日期 Packaging Info: 77485SLB-S004 1.包装要求： MA 1L收缩膜+ 客版 收藏指南B版+MA 纸袋+客版 1L PDQ，翻单：4500128976 每pcs产品上要贴1张RFID贴纸，贴纸由ZURU提供，贴纸位置请严格按照我们签回的签板； Remark: 77485SLB-S004 1.包装要求： MA 1L收缩膜+ 客版 收藏指南B版+MA 纸袋+客版 1L PDQ，翻单：4500128976 每pcs产品上要贴1张RFID贴纸，贴纸由ZURU提供，贴纸位置请严格按照我们签回的签板； 2. 外箱印刷带条码的RFID箱唛：RFID紫色色带+WM Dept.图标+RFID图标+ITF-14条码，四面右下角印刷ZURU logo, ITFF条码只印刷在正唛一面，在加印的时候确保 条形码能扫描出来，外箱侧面任一角落加印："MADE IN CHINA" 字样； 3. 每个slip sheet上面贴一张艾利贴纸（不干胶贴纸）和一张普通贴纸（A4纸），slip sheet打印的普通贴纸的尺寸不能比艾利贴纸小，普通贴纸内容见附件； 4. 在产品上和包装上要有日期码、以及要有MADE IN CHINA和ZURU字样； 5. 产品如有扎带口要剪平，不能刮手。 6. 此单需要验货，请多备料 7. 此单以slip sheet出货，77485：1152pcs/96CTN/Slip Sheet | W24: Maggie Xie | X24: 2206.6131 | Y24: 4364.2672 | AA24: 94124-1.20 | AB24: 77485SLB-S004 | AC24: 已入 | AD24: 系统出单 | AF24: 1152 | AG24: =AF24-I24 -> 0 | AK24: =I24 -> 1152 | AM24: =I24 -> 1152 | AU24: =I24 -> 1152 | AZ24: =I24/12 -> 96 | BU24: =AK24+AL24 -> 1152 | BV24: =BV23+BU24 -> 2308690 | CA24: =SUM(BX$1:CB$1)-BV24 -> 511310 | CC24: =AW24+AX24+BE24+BF24 -> 0 | CD24: =CD23+CC24 -> 47832.571 | CH24: =$CF$1+$CG$1+$CH$1+$CI$1-CD24 -> 12167.429
A25: 45637 | B25: WAL-MART STORES INC. USA | C25: 美国 | D25: 4500153681 | E25: 0881410111 HOUSTON | F25: 4500153681-40 | G25: 77485SLB-S004 | H25: 3代迷你小手袋 | I25: 2304 | J25: 0 | K25: 1152 | L25: =I25/K25 -> 2 | M25: 45671 | N25: 45667 | O25: 2025/1/14第三方验货 | P25: PASS | R25: 外箱印刷带条码的RFID箱唛：RFID紫色色带+WM Dept.图标+RFID图标+ITF-14条码，四面右下角印刷ZURU logo, ITFF条码只印刷在正唛一面，在加印的时候确保 条形码能扫描出来，外箱侧面任一角落加印："MADE IN CHINA" 字样； | S25: 无 | T25: 12/20 寄出RFID贴纸 | V25: 日期码格式：ZURU DGYYYYMMDD CHINA(日期避开周末和法定节假日即可） 日期：按实际生产日期 Packaging Info: 77485SLB-S004 1.包装要求： MA 1L收缩膜+ 客版 收藏指南B版+MA 纸袋+客版 1L PDQ，翻单：4500128976 每pcs产品上要贴1张RFID贴纸，贴纸由ZURU提供，贴纸位置请严格按照我们签回的签板； Remark: 77485SLB-S004 1.包装要求： MA 1L收缩膜+ 客版 收藏指南B版+MA 纸袋+客版 1L PDQ，翻单：4500128976 每pcs产品上要贴1张RFID贴纸，贴纸由ZURU提供，贴纸位置请严格按照我们签回的签板； 2. 外箱印刷带条码的RFID箱唛：RFID紫色色带+WM Dept.图标+RFID图标+ITF-14条码，四面右下角印刷ZURU logo, ITFF条码只印刷在正唛一面，在加印的时候确保 条形码能扫描出来，外箱侧面任一角落加印："MADE IN CHINA" 字样； 3. 每个slip sheet上面贴一张艾利贴纸（不干胶贴纸）和一张普通贴纸（A4纸），slip sheet打印的普通贴纸的尺寸不能比艾利贴纸小，普通贴纸内容见附件； 4. 在产品上和包装上要有日期码、以及要有MADE IN CHINA和ZURU字样； 5. 产品如有扎带口要剪平，不能刮手。 6. 此单需要验货，请多备料 7. 此单以slip sheet出货，77485：1152pcs/96CTN/Slip Sheet | W25: Maggie Xie | X25: 2206.6131 | Y25: 4364.2672 | AA25: 94124-1.20 | AB25: 77485SLB-S004 | AC25: 已入 | AD25: 系统出单 | AF25: 2304 | AG25: =AF25-I25 -> 0 | AK25: =I25 -> 2304 | AM25: =I25 -> 2304 | AU25: =I25 -> 2304 | AZ25: =I25/12 -> 192 | BU25: =AK25+AL25 -> 2304 | BV25: =BV24+BU25 -> 2310994 | CA25: =SUM(BX$1:CB$1)-BV25 -> 509006 | CC25: =AW25+AX25+BE25+BF25 -> 0 | CD25: =CD24+CC25 -> 47832.571 | CH25: =$CF$1+$CG$1+$CH$1+$CI$1-CD25 -> 12167.429
A26: 45637 | B26: WAL-MART STORES INC. USA | C26: 美国 | D26: 4500153681 | E26: 0881410114 SUFFOLK | F26: 4500153681-50 | G26: 77485SLB-S004 | H26: 3代迷你小手袋 | I26: 2304 | J26: 0 | K26: 1152 | L26: =I26/K26 -> 2 | M26: 45671 | N26: 45667 | O26: 2025/1/14第三方验货 | P26: PASS | R26: 外箱印刷带条码的RFID箱唛：RFID紫色色带+WM Dept.图标+RFID图标+ITF-14条码，四面右下角印刷ZURU logo, ITFF条码只印刷在正唛一面，在加印的时候确保 条形码能扫描出来，外箱侧面任一角落加印："MADE IN CHINA" 字样； | S26: 无 | T26: 12/20 寄出RFID贴纸 | V26: 日期码格式：ZURU DGYYYYMMDD CHINA(日期避开周末和法定节假日即可） 日期：按实际生产日期 Packaging Info: 77485SLB-S004 1.包装要求： MA 1L收缩膜+ 客版 收藏指南B版+MA 纸袋+客版 1L PDQ，翻单：4500128976 每pcs产品上要贴1张RFID贴纸，贴纸由ZURU提供，贴纸位置请严格按照我们签回的签板； Remark: 77485SLB-S004 1.包装要求： MA 1L收缩膜+ 客版 收藏指南B版+MA 纸袋+客版 1L PDQ，翻单：4500128976 每pcs产品上要贴1张RFID贴纸，贴纸由ZURU提供，贴纸位置请严格按照我们签回的签板； 2. 外箱印刷带条码的RFID箱唛：RFID紫色色带+WM Dept.图标+RFID图标+ITF-14条码，四面右下角印刷ZURU logo, ITFF条码只印刷在正唛一面，在加印的时候确保 条形码能扫描出来，外箱侧面任一角落加印："MADE IN CHINA" 字样； 3. 每个slip sheet上面贴一张艾利贴纸（不干胶贴纸）和一张普通贴纸（A4纸），slip sheet打印的普通贴纸的尺寸不能比艾利贴纸小，普通贴纸内容见附件； 4. 在产品上和包装上要有日期码、以及要有MADE IN CHINA和ZURU字样； 5. 产品如有扎带口要剪平，不能刮手。 6. 此单需要验货，请多备料 7. 此单以slip sheet出货，77485：1152pcs/96CTN/Slip Sheet | W26: Maggie Xie | X26: 2206.6131 | Y26: 4364.2672 | AA26: 94124-1.20 | AB26: 77485SLB-S004 | AC26: 已入 | AD26: 系统出单 | AG26: =AF26-I26 -> -2304 | AK26: =I26 -> 2304 | AM26: =I26 -> 2304 | AU26: =I26 -> 2304 | AZ26: =I26/12 -> 192 | BU26: =AK26+AL26 -> 2304 | BV26: =BV25+BU26 -> 2313298 | CA26: =SUM(BX$1:CB$1)-BV26 -> 506702 | CC26: =AW26+AX26+BE26+BF26 -> 0 | CD26: =CD25+CC26 -> 47832.571 | CH26: =$CF$1+$CG$1+$CH$1+$CI$1-CD26 -> 12167.429
A27: 45637 | B27: WAL-MART STORES INC. USA | C27: 美国 | D27: 4500153681 | E27: 0881410121 MOBILE | F27: 4500153681-60 | G27: 77485SLB-S004 | H27: 3代迷你小手袋 | I27: 3456 | J27: 0 | K27: 1152 | L27: =I27/K27 -> 3 | M27: 45671 | N27: 45667 | O27: 2025/1/14第三方验货 | P27: PASS | R27: 外箱印刷带条码的RFID箱唛：RFID紫色色带+WM Dept.图标+RFID图标+ITF-14条码，四面右下角印刷ZURU logo, ITFF条码只印刷在正唛一面，在加印的时候确保 条形码能扫描出来，外箱侧面任一角落加印："MADE IN CHINA" 字样； | S27: 无 | T27: 12/20 寄出RFID贴纸 | V27: 日期码格式：ZURU DGYYYYMMDD CHINA(日期避开周末和法定节假日即可） 日期：按实际生产日期 Packaging Info: 77485SLB-S004 1.包装要求： MA 1L收缩膜+ 客版 收藏指南B版+MA 纸袋+客版 1L PDQ，翻单：4500128976 每pcs产品上要贴1张RFID贴纸，贴纸由ZURU提供，贴纸位置请严格按照我们签回的签板； Remark: 77485SLB-S004 1.包装要求： MA 1L收缩膜+ 客版 收藏指南B版+MA 纸袋+客版 1L PDQ，翻单：4500128976 每pcs产品上要贴1张RFID贴纸，贴纸由ZURU提供，贴纸位置请严格按照我们签回的签板； 2. 外箱印刷带条码的RFID箱唛：RFID紫色色带+WM Dept.图标+RFID图标+ITF-14条码，四面右下角印刷ZURU logo, ITFF条码只印刷在正唛一面，在加印的时候确保 条形码能扫描出来，外箱侧面任一角落加印："MADE IN CHINA" 字样； 3. 每个slip sheet上面贴一张艾利贴纸（不干胶贴纸）和一张普通贴纸（A4纸），slip sheet打印的普通贴纸的尺寸不能比艾利贴纸小，普通贴纸内容见附件； 4. 在产品上和包装上要有日期码、以及要有MADE IN CHINA和ZURU字样； 5. 产品如有扎带口要剪平，不能刮手。 6. 此单需要验货，请多备料 7. 此单以slip sheet出货，77485：1152pcs/96CTN/Slip Sheet | W27: Maggie Xie | X27: 2206.6131 | Y27: 4364.2672 | AA27: 94084-1.17 | AB27: 77485SLB-S004 | AC27: 已入 | AD27: 系统出单 | AF27: 3456 | AG27: =AF27-I27 -> 0 | AK27: =I27 -> 3456 | AM27: =I27 -> 3456 | AU27: =I27 -> 3456 | AZ27: =I27/12 -> 288 | BU27: =AK27+AL27 -> 3456 | BV27: =BV26+BU27 -> 2316754 | CA27: =SUM(BX$1:CB$1)-BV27 -> 503246 | CC27: =AW27+AX27+BE27+BF27 -> 0 | CD27: =CD26+CC27 -> 47832.571 | CH27: =$CF$1+$CG$1+$CH$1+$CI$1-CD27 -> 12167.429
A28: 45637 | B28: WAL-MART STORES INC. USA | C28: 美国 | D28: 4500153681 | E28: 0881410134 RIDGEVILLE SC | F28: 4500153681-70 | G28: 77485SLB-S004 | H28: 3代迷你小手袋 | I28: 1152 | J28: 0 | K28: 1152 | L28: =I28/K28 -> 1 | M28: 45671 | N28: 45667 | P28: PASS | R28: 外箱印刷带条码的RFID箱唛：RFID紫色色带+WM Dept.图标+RFID图标+ITF-14条码，四面右下角印刷ZURU logo, ITFF条码只印刷在正唛一面，在加印的时候确保 条形码能扫描出来，外箱侧面任一角落加印："MADE IN CHINA" 字样； | S28: 无 | T28: 12/20 寄出RFID贴纸 | V28: 日期码格式：ZURU DGYYYYMMDD CHINA(日期避开周末和法定节假日即可） 日期：按实际生产日期 Packaging Info: 77485SLB-S004 1.包装要求： MA 1L收缩膜+ 客版 收藏指南B版+MA 纸袋+客版 1L PDQ，翻单：4500128976 每pcs产品上要贴1张RFID贴纸，贴纸由ZURU提供，贴纸位置请严格按照我们签回的签板； Remark: 77485SLB-S004 1.包装要求： MA 1L收缩膜+ 客版 收藏指南B版+MA 纸袋+客版 1L PDQ，翻单：4500128976 每pcs产品上要贴1张RFID贴纸，贴纸由ZURU提供，贴纸位置请严格按照我们签回的签板； 2. 外箱印刷带条码的RFID箱唛：RFID紫色色带+WM Dept.图标+RFID图标+ITF-14条码，四面右下角印刷ZURU logo, ITFF条码只印刷在正唛一面，在加印的时候确保 条形码能扫描出来，外箱侧面任一角落加印："MADE IN CHINA" 字样； 3. 每个slip sheet上面贴一张艾利贴纸（不干胶贴纸）和一张普通贴纸（A4纸），slip sheet打印的普通贴纸的尺寸不能比艾利贴纸小，普通贴纸内容见附件； 4. 在产品上和包装上要有日期码、以及要有MADE IN CHINA和ZURU字样； 5. 产品如有扎带口要剪平，不能刮手。 6. 此单需要验货，请多备料 7. 此单以slip sheet出货，77485：1152pcs/96CTN/Slip Sheet | W28: Maggie Xie | X28: 2206.6131 | Y28: 4364.2672 | AA28: 94124-1.20 | AB28: 77485SLB-S004 | AC28: 已入 | AD28: 系统出单 | AF28: 1152 | AG28: =AF28-I28 -> 0 | AK28: =I28 -> 1152 | AM28: =I28 -> 1152 | AU28: =I28 -> 1152 | AZ28: =I28/12 -> 96 | BU28: =AK28+AL28 -> 1152 | BV28: =BV27+BU28 -> 2317906 | CA28: =SUM(BX$1:CB$1)-BV28 -> 502094 | CC28: =AW28+AX28+BE28+BF28 -> 0 | CD28: =CD27+CC28 -> 47832.571 | CH28: =$CF$1+$CG$1+$CH$1+$CI$1-CD28 -> 12167.429
A29: 45586 | B29: TJX COMPANIES, INC | C29: 美国 | D29: 4500147801 | E29: TJ MAXX DC#891-120PCS , DC#894-96PCS, DC#896-96PCS, DC#897-192PCS , DC#898-96PCS | F29: 4500147801-40 | G29: 77486-S001 | H29: 3代迷你小手袋 圆筒装 | I29: 600 | J29: 0 | K29: 12 | L29: =I29/K29 -> 50 | M29: 45677 | N29: 45673 | P29: PASS | R29: 45600 | S29: 无 | T29: 欠客供价格贴纸+空白贴纸 | V29: 日期码格式：ZURU INC(BVI) 标准格式 日期：按实际生产日期 Packaging Info: MA UPC包装+价格贴纸，价格贴纸客供。#77486 球的收缩膜用无条码版本或者加空白贴纸覆盖条码信息。 Remark: 1. 产品和包装上印刷tracking code信息，格式为ZURU常规格式。 2. 分5个DC出货，每款产品每个DC的箱唛资料不同。具体分DC数量，请参考后面行项目备注。 3. ZURU QC验货。 | W29: Emily Wu | X29: 4.1259 | Y29: =I29*X29 -> 2475.54 | AA29: 94280-2.18 | AB29: 77486-S001 | AC29: 已入 | AD29: 系统出单 | AF29: 600 | AG29: =AF29-I29 -> 0 | AI29: OK | AK29: =I29*2 -> 1200 | AM29: =I29*2 -> 1200 | AS29: =I29*2 -> 1200 | BN29: =I29 -> 600 | BO29: =I29 -> 600 | BQ29: =I29 -> 600 | BU29: =AK29+AL29 -> 1200 | BV29: =BV28+BU29 -> 2319106 | CA29: =SUM(BX$1:CB$1)-BV29 -> 500894 | CC29: =AW29+AX29+BE29+BF29 -> 0 | CD29: =CD28+CC29 -> 47832.571 | CH29: =$CF$1+$CG$1+$CH$1+$CI$1-CD29 -> 12167.429
A30: 45586 | B30: TJX COMPANIES, INC | C30: 美国 | D30: 4500147799 | E30: Marshalls DC#881-120PCS , DC#884-96PCS, DC#886-132PCS , DC#887-120PCS , DC#888-132PCS | F30: 4500147799-40 | G30: 77486-S001 | H30: 3代迷你小手袋 圆筒装 | I30: 600 | J30: 0 | K30: 12 | L30: =I30/K30 -> 50 | M30: 45677 | N30: 45673 | P30: PASS | R30: 45600 | S30: 无 | T30: 欠客供价格贴纸+空白贴纸 | V30: 日期码格式：ZURU INC(BVI) 标准格式 日期：按实际生产日期 Packaging Info: MA UPC包装+价格贴纸，价格贴纸客供。#77486 球的收缩膜用无条码版本或者加空白贴纸覆盖条码信息。 Remark: 1. 产品和包装上印刷tracking code信息，格式为ZURU常规格式。 2. 分5个DC出货，每款产品每个DC的箱唛资料不同。具体分DC数量，请参考后面行项目备注。 3. ZURU QC验货。 | W30: Emily Wu | X30: 4.087 | Y30: =I30*X30 -> 2452.2 | AA30: 94278-2.18 | AB30: 77486-S001 | AC30: 已入 | AD30: 系统出单 | AG30: =AF30-I30 -> -600 | AI30: OK | AK30: =I30*2 -> 1200 | AM30: =I30*2 -> 1200 | AS30: =I30*2 -> 1200 | BN30: =I30 -> 600 | BO30: =I30 -> 600 | BQ30: =I30 -> 600 | BU30: =AK30+AL30 -> 1200 | BV30: =BV29+BU30 -> 2320306 | CA30: =SUM(BX$1:CB$1)-BV30 -> 499694 | CC30: =AW30+AX30+BE30+BF30 -> 0 | CD30: =CD29+CC30 -> 47832.571 | CH30: =$CF$1+$CG$1+$CH$1+$CI$1-CD30 -> 12167.429
A31: 45603 | B31: ROSS PROCUREMENT.INC | C31: 美国 | D31: 4500150464 | E31: 60190494 | F31: 4500150464-30 | G31: 77486-S001 | H31: 3代迷你小手袋 圆筒装 | I31: 2400 | J31: 0 | K31: 12 | L31: =I31/K31 -> 200 | M31: 45672 | N31: 45668 | P31: pass | R31: 45610 | S31: 无 | T31: 欠客供价格贴纸 | V31: 日期码格式：ZURU INC(BVI) 标准格式 日期：按实际生产日期 Packaging Info: 1.ZURU MA UPC 收缩膜+客版铜版纸+PVC桶 + 客供价格贴纸，出口美国 , 优先使用MA 1L 最新版本 。 Remark: 1.ZURU MA UPC 收缩膜+客版铜版纸+PVC桶 + 客供价格贴纸，出口美国 , 优先使用MA 1L 最新版本 。 2.价格贴纸位于包装正面右下角，不挡住重要信息即可，可适当调整 ，价格贴纸由跟单提供。 3.标准日期码格式，产品和包装必须有日期码 。 4.同个产品同个货期不可出现不同的包装。 5. PVC 桶中球不能出现完全相同的ASSORTMENT ， 即同一个PVC 中球里的ASSORTMENT 需要不同。 以免消费者失望。 6.PVC 桶上加上 MINI BRANDS 的LOGO 贴纸 （ ZURU 统一要求的） 7.收缩膜可使用标版带UPC条码MA，无需白色贴纸覆盖。 | W31: Sophia Zhou | X31: 4.1142 | Y31: =I31*X31 -> 9874.08 | AA31: 94486-3.7 | AB31: 77486-S001 | AC31: 已入 | AD31: 系统出单 | AF31: =2388+12 -> 2400 | AG31: =AF31-I31 -> 0 | AI31: OK | AK31: =I31*2 -> 4800 | AM31: =I31*2 -> 4800 | AS31: =I31*2 -> 4800 | BN31: =I31 -> 2400 | BO31: =I31 -> 2400 | BQ31: =I31 -> 2400 | BU31: =AK31+AL31 -> 4800 | BV31: =BV30+BU31 -> 2325106 | CA31: =SUM(BX$1:CB$1)-BV31 -> 494894 | CC31: =AW31+AX31+BE31+BF31 -> 0 | CD31: =CD30+CC31 -> 47832.571 | CH31: =$CF$1+$CG$1+$CH$1+$CI$1-CD31 -> 12167.429
A32: 45632 | B32: Cladellas 2000 S.L | C32: 西班牙 | D32: 4500153372 | F32: 4500153372-60 | G32: 77485GQ7-S001 | H32: 3代迷你小手袋 | I32: 1000 | J32: 0 | K32: 50 | L32: =I32/K32 -> 20 | M32: 45672 | N32: 45668 | P32: pass | Q32: 1/15 出货 | R32: 45638 | S32: 无 | T32: 45638 | V32: 日期码格式：ZURU INC(BVI) 标准格式 日期：按实际生产日期 Packaging Info: 6.77485GQ7：最新MA 3L EAN 版本包装+一张客户警语贴纸（含环保标）+MA 5L 收藏指南+MA 3L PDQ； Remark: 产品均符合EU微塑料法规要求：不含有微塑料，不含有闪粉； 此单需要在年前出货，请注意安排装柜人员； | W32: Sherry Chen | X32: 2.0019 | Y32: =I32*X32 -> 2001.9 | AA32: 94203-2.10 | AB32: 77485GQ7-S001-3L-1 | AC32: 已入 | AD32: 系统出单 | AF32: 1000 | AG32: =AF32-I32 -> 0 | AI32: OK | AK32: =I32 -> 1000 | AP32: =I32 -> 1000 | AS32: =I32 -> 1000 | BF32: =I32/25 -> 40 | BU32: =AK32+AL32 -> 1000 | BV32: =BV31+BU32 -> 2326106 | CA32: =SUM(BX$1:CB$1)-BV32 -> 493894 | CC32: =AW32+AX32+BE32+BF32 -> 40 | CD32: =CD31+CC32 -> 47872.571 | CH32: =$CF$1+$CG$1+$CH$1+$CI$1-CD32 -> 12127.429
A33: 45632 | B33: MILLS FLEET FARM | C33: 美国 | D33: MPO03108 | G33: 77485-S001 | H33: 3代迷你小手袋 | I33: 640 | J33: 0 | K33: 24 | L33: =I33/K33 -> 26.666667 | M33: 45674 | N33: 45670 | P33: pass | Q33: 子件于2025年1月21日送到库有混装 | R33: 周转箱 | S33: 无 | T33: 无 | V33: Remark:1.包装:ZURU MA 1L UPC最新包装;出口美国2.日期跟踪码:产品外包装及产品本身都必须有日期跟踪码，并且确保两者的日期跟踪码要一致;2URU标准格式日期码(请自行调整具体年月日生产期,但不能为周末)该单是多工厂混装，为了统一，日期可以统一打2025年1月16日 3.按照Zuru MA 标板配比 4.子件于2025年1月21日送到库有混装,产品包菠上需做好标识,以便组装厂识别组装时避免重复字,送货到库有厂时送货单请备注上:客供子件给Mils Fleet Farm p4500153457 #MSLD121-S001混装用。 | W33: Mila Yao | X33: 1.8342 | Y33: =X33*I33 -> 1173.888 | AA33: 94409-2.28 | AB33: 77485-S001 | AC33: 已入 | AD33: 系统出单 | AF33: 640 | AG33: =AF33-I33 -> 0 | AI33: 无 | AK33: =I33 -> 640 | AM33: =I33 -> 640 | AS33: =I33 -> 640 | BU33: =AK33+AL33 -> 640 | BV33: =BV32+BU33 -> 2326746 | CA33: =SUM(BX$1:CB$1)-BV33 -> 493254 | CC33: =AW33+AX33+BE33+BF33 -> 0 | CD33: =CD32+CC33 -> 47872.571 | CH33: =$CF$1+$CG$1+$CH$1+$CI$1-CD33 -> 12127.429
A34: 45639 | B34: CORPORACION FAVORITA C.A. | C34: 厄瓜多尔 | D34: 4500153836 | E34: 24-1067174JEC | F34: 4500153836-20 | G34: 77485GQ7-S001 | H34: 3代迷你小手袋 | I34: 4600 | J34: 0 | K34: 50 | L34: =I34/K34 -> 92 | M34: 45677 | N34: 45673 | P34: pass | R34: 45639 | S34: 无 | T34: 45643 | V34: 日期码格式：LOTE 格式：例如2025-01 日期： Packaging Info: 77485GQ7：MA 5L 收藏指南+MA 3L 包装+UPC 贴纸+MA 3L PDQ 包装+进口商贴纸+箱唛 Remark: 客户有LOTE 格式：例如2025-01. ，外箱箱唛，产品批号需要与进口商贴纸保持一致。 | W34: Zoe Luo | X34: 1.9961 | Y34: =I34*X34 -> 9182.06 | AA34: 94144-1.21 | AB34: 77485GQ7-S001-3L-1 | AC34: 已入 | AD34: 系统出单 | AF34: =2100+2500 -> 4600 | AG34: =AF34-I34 -> 0 | AI34: OK | AK34: =I34 -> 4600 | AP34: =I34 -> 4600 | AS34: =I34 -> 4600 | BF34: =I34/25 -> 184 | BU34: =AK34+AL34 -> 4600 | BV34: =BV33+BU34 -> 2331346 | CA34: =SUM(BX$1:CB$1)-BV34 -> 488654 | CC34: =AW34+AX34+BE34+BF34 -> 184 | CD34: =CD33+CC34 -> 48056.571 | CH34: =$CF$1+$CG$1+$CH$1+$CI$1-CD34 -> 11943.429
A35: 45639 | B35: CENTRO CUESTA NACIONAL | C35: 多米尼加共和国 | D35: 4500153864 | F35: 4500153864-80 | G35: 77485GQ7-S001 | H35: 3代迷你小手袋 | I35: 750 | J35: 0 | K35: 50 | L35: =I35/K35 -> 15 | M35: 45677 | N35: 45673 | P35: pass | R35: 45639 | S35: 无 | T35: 45644 | V35: 日期码格式：2025-01 日期： Packaging Info: 77485GQ7：MA 5L 收藏指南+MA 3L 包装+UPC 贴纸+MA 3L PDQ 包装+箱唛 Remark: | W35: Zoe Luo | X35: 2.0019 | Y35: =I35*X35 -> 1501.425 | AA35: 94113-1.18 | AB35: 77485GQ7-S001-3L-1 | AC35: 已入 | AD35: 系统出单 | AF35: 750 | AG35: =AF35-I35 -> 0 | AI35: OK | AK35: =I35 -> 750 | AP35: =I35 -> 750 | AS35: =I35 -> 750 | BF35: =I35/25 -> 30 | BU35: =AK35+AL35 -> 750 | BV35: =BV34+BU35 -> 2332096 | CA35: =SUM(BX$1:CB$1)-BV35 -> 487904 | CC35: =AW35+AX35+BE35+BF35 -> 30 | CD35: =CD34+CC35 -> 48086.571 | CH35: =$CF$1+$CG$1+$CH$1+$CI$1-CD35 -> 11913.429
A36: 45624 | B36: WALGREEN CO. | C36: 美国 | D36: 4500152749 | E36: 4550103326 | F36: 4500152749-10 | G36: 77485GQ4-S002 | H36: 3代迷你小手袋 | I36: 2226 | J36: 0 | K36: 6 | L36: =I36/K36 -> 371 | M36: 45695 | N36: 45691 | P36: pass | R36: 45624 | S36: 无 | T36: WIC贴纸（WIC#744431） | V36: 日期码格式：ZURU INC(BVI) 标准格式:DG20250207 日期：02-07-2025 Tracking Code: Packaging Info: Remark: 客版1L PDQ +MA 1L包装 + WIC贴纸（WIC#744431）+ MA 收藏指南 + PDQ折页 （同PO 4500142744） 产品和包装上面要有ZURU 标准格式TRACKING CODE， DG20250207 | W36: Cara Li | X36: 1.9361 | Y36: =I36*X36 -> 4309.7586 | AA36: 94189-2.8 | AB36: 待定 | AC36: 已入 | AD36: 系统出单 | AF36: 2226 | AG36: =AF36-I36 -> 0 | AI36: OK | AK36: =I36 -> 2226 | AM36: =I36 -> 2226 | AS36: =I36 -> 2226 | BB36: =I36/6 -> 371 | BU36: =AK36+AL36 -> 2226 | BV36: =BV35+BU36 -> 2334322 | CA36: =SUM(BX$1:CB$1)-BV36 -> 485678 | CC36: =AW36+AX36+BE36+BF36 -> 0 | CD36: =CD35+CC36 -> 48086.571 | CH36: =$CF$1+$CG$1+$CH$1+$CI$1-CD36 -> 11913.429
A37: 45624 | B37: WALGREEN CO. | C37: 美国 | D37: 4500152749 | E37: 4550102988 | F37: 4500152749-20 | G37: 77485GQ4-S002 | H37: 3代迷你小手袋 | I37: 708 | J37: 0 | K37: 6 | L37: =I37/K37 -> 118 | M37: 45695 | N37: 45691 | P37: pass | R37: 45624 | S37: 无 | T37: WIC贴纸（WIC#744431） | V37: 日期码格式：ZURU INC(BVI) 标准格式:DG20250207 日期：02-07-2025 Tracking Code: Packaging Info: Remark: 客版1L PDQ +MA 1L包装 + WIC贴纸（WIC#744431）+ MA 收藏指南 + PDQ折页 （同PO 4500142744） 产品和包装上面要有ZURU 标准格式TRACKING CODE， DG20250207 | W37: Cara Li | X37: 1.9361 | Y37: =I37*X37 -> 1370.7588 | AA37: 94189-2.8 | AB37: 待定 | AC37: 已入 | AD37: 系统出单 | AF37: 708 | AG37: =AF37-I37 -> 0 | AK37: =I37 -> 708 | AM37: =I37 -> 708 | AS37: =I37 -> 708 | BB37: =I37/6 -> 118 | BU37: =AK37+AL37 -> 708 | BV37: =BV36+BU37 -> 2335030 | CA37: =SUM(BX$1:CB$1)-BV37 -> 484970 | CC37: =AW37+AX37+BE37+BF37 -> 0 | CD37: =CD36+CC37 -> 48086.571 | CH37: =$CF$1+$CG$1+$CH$1+$CI$1-CD37 -> 11913.429
A38: 45624 | B38: WALGREEN CO. | C38: 美国 | D38: 4500152749 | E38: 4550103356 | F38: 4500152749-30 | G38: 77485GQ4-S002 | H38: 3代迷你小手袋 | I38: 942 | J38: 0 | K38: 6 | L38: =I38/K38 -> 157 | M38: 45695 | N38: 45691 | P38: pass | R38: 45624 | S38: 无 | T38: WIC贴纸（WIC#744431） | V38: 日期码格式：ZURU INC(BVI) 标准格式:DG20250207 日期：02-07-2025 Tracking Code: Packaging Info: Remark: 客版1L PDQ +MA 1L包装 + WIC贴纸（WIC#744431）+ MA 收藏指南 + PDQ折页 （同PO 4500142744） 产品和包装上面要有ZURU 标准格式TRACKING CODE， DG20250207 | W38: Cara Li | X38: 1.9361 | Y38: =I38*X38 -> 1823.8062 | AA38: 94189-2.8 | AB38: 待定 | AC38: 已入 | AD38: 系统出单 | AF38: 942 | AG38: =AF38-I38 -> 0 | AK38: =I38 -> 942 | AM38: =I38 -> 942 | AS38: =I38 -> 942 | BB38: =I38/6 -> 157 | BU38: =AK38+AL38 -> 942 | BV38: =BV37+BU38 -> 2335972 | CA38: =SUM(BX$1:CB$1)-BV38 -> 484028 | CC38: =AW38+AX38+BE38+BF38 -> 0 | CD38: =CD37+CC38 -> 48086.571 | CH38: =$CF$1+$CG$1+$CH$1+$CI$1-CD38 -> 11913.429
A39: 45624 | B39: WALGREEN CO. | C39: 美国 | D39: 4500152749 | E39: 4550102986 | F39: 4500152749-40 | G39: 77485GQ4-S002 | H39: 3代迷你小手袋 | I39: 1416 | J39: 0 | K39: 6 | L39: =I39/K39 -> 236 | M39: 45695 | N39: 45691 | P39: pass | R39: 45624 | S39: 无 | T39: WIC贴纸（WIC#744431） | V39: 日期码格式：ZURU INC(BVI) 标准格式:DG20250207 日期：02-07-2025 Tracking Code: Packaging Info: Remark: 客版1L PDQ +MA 1L包装 + WIC贴纸（WIC#744431）+ MA 收藏指南 + PDQ折页 （同PO 4500142744） 产品和包装上面要有ZURU 标准格式TRACKING CODE， DG20250207 | W39: Cara Li | X39: 1.9361 | Y39: =I39*X39 -> 2741.5176 | AA39: 94189-2.8 | AB39: 待定 | AC39: 已入 | AD39: 系统出单 | AF39: 1416 | AG39: =AF39-I39 -> 0 | AK39: =I39 -> 1416 | AM39: =I39 -> 1416 | AS39: =I39 -> 1416 | BB39: =I39/6 -> 236 | BU39: =AK39+AL39 -> 1416 | BV39: =BV38+BU39 -> 2337388 | CA39: =SUM(BX$1:CB$1)-BV39 -> 482612 | CC39: =AW39+AX39+BE39+BF39 -> 0 | CD39: =CD38+CC39 -> 48086.571 | CH39: =$CF$1+$CG$1+$CH$1+$CI$1-CD39 -> 11913.429
