Workbook

Sheet 名称
A1: ITEM
A2: 1025130 | B2: 新款四角星（OMTS)
A3: 1124135 | B3: 复仇者联盟游戏机
A4: 1124138 | B4: 转盘游戏机-EN
A5: 1125103 | B5: 红色比卡超-EN
A6: 1125115 | B6: 新点读笔地图
A7: 1125130 | B7: 新款四角星（OMTS)
A8: 1125151 | B8: 绿波比卡超 EN
A9: 1125155 | B9: PTE 比卡超圆形游戏机
A10: 1224138 | B10: 转盘游戏机-ES
A11: 1425130 | B11: 新款四角星（OMTS)
A12: 1522113 | B12: 圆形灯-SL
A13: 3021070 | B13: 橙色超级男仔小精灵-SE
... A25: 4724113 | B25: 圆形灯
A26: 1121118- US | B26: 金属色比卡超-EN
A27: 1123103- US-TAR | B27: 红色比卡超-EN-US
A28: 1124138- UK | B28: 转盘游戏机
A29: 1125103- US-MIL | B29: 红色比卡超-EN-US
A30: 1125106- US-MIL | B30: 紫波比卡超-EN-US
A31: 1125110- US-MIL | B31: 四角星抢答器 EN US
A32: 1125117- US-MIL | B32: 比卡超手表 EN-US
A33: 1125118- US-MIL | B33: 金属色比卡超-EN-US
A34: 1125124- US-MIL | B34: 白色比卡超 EN-US
A35: 1125130- US | B35: 新款四角星（OMTS)
A36: 1125151- US-MIL | B36: 绿波比卡超 EN-US
A37: 1125155- UK | B37: PTE 比卡超圆形游戏机
... A39: 1125159- UK | B39: 新款五角星-UK

Sheet 总接单
A1: 产品名称 | I1: 四角星 | L1: 游戏机 | P1: 圆形灯 | Q1: 魔镜 | R1: 小精灵 | T1: 五角星 | X1: 比卡超精灵球 | AF1: 地图 | AI1: 新点读笔地图 | AJ1: 速度头 | AK1: 蓝精灵 | AL1: 超级精灵球 | AM1: 米奇老鼠头 | AN1: 足球
A2: 接单日期 | B2: 国家 | C2: PO号 | D2: CUSTOMER PO | E2: ITEM | F2: 产品名称 | G2: 数量 | H2: 验货期 | I2: 四角星抢答器 | J2: 涡轮四角星 | K2: 新款四角星（OMTS) | L2: PTE 比卡超圆形游戏机 | M2: 城市游戏机 | N2: 复仇者联盟游戏机 | O2: 转盘游戏机 | P2: 圆形灯 | Q2: 魔镜 | R2: 橙色超级男仔小精灵（四方彩盒版本） | S2: 橙色超级男仔小精灵（六边彩盒版本） | T2: 五角星 | U2: 小孩五角星 | V2: 新款五角星 | W2: 米奇五角星 | X2: 比卡超手表 | Y2: 绿波比卡超 | Z2: 金属色比卡超 | AA2: 红色比卡超 | AB2: 紫波比卡超 | AC2: 金属色比卡超 | AD2: 灰红波比卡超 | AE2: 白色比卡超 | AF2: 平板地图 | AG2: 世界地图 | AH2: 动物地图 | AI2: 新点读笔地图 | AJ2: 速度头 | AK2: 蓝精灵 | AL2: 超级精灵球 | AM2: 迪士尼米奇头 | AN2: 足球 | AO2: 单价USD | AP2: 金额USD | AQ2: 金额HKD
A3: 45943 | B3: 德国 | D3: PO-25101302 | E3: 1825103 | F3: 红色比卡超-DE | G3: 6000 | H3: 46023 | AA3: =G3 -> 6000 | AO3: 2.119 | AP3: =SUM(I3:AN3)*AO3 -> 12714 | AQ3: =AP3*7.75 -> 98533.5
A4: 45943 | B4: 德国 | D4: PO-25101302 | E4: 1825155 | F4: PTE 比卡超圆形游戏机-DE | G4: 5004 | H4: 46023 | L4: =G4 -> 5004 | AO4: 4.516 | AP4: =SUM(I4:AN4)*AO4 -> 22598.06 | AQ4: =AP4*7.75 -> 175134.97
A5: 45954 | B5: 法国 | D5: PO-25101601 | E5: 1025103 | F5: 红色比卡超 | G5: 4002 | H5: 46007 | AA5: =G5 -> 4002 | AO5: 2.119 | AP5: =SUM(I5:AN5)*AO5 -> 8480.24 | AQ5: =AP5*7.75 -> 65721.86
A6: 45954 | B6: 法国 | D6: PO-25101601 | E6: 1025117 | F6: 比卡超手表 | G6: 3000 | H6: 46007 | X6: =G6 -> 3000 | AO6: 2.656 | AP6: =SUM(I6:AN6)*AO6 -> 7968 | AQ6: =AP6*7.75 -> 61752
A7: 45954 | B7: 法国 | D7: PO-25101601 | E7: 1025155 | F7: PTE 圆型游戏机 | G7: 8004 | H7: 46007 | L7: =G7 -> 8004 | AO7: 4.516 | AP7: =SUM(I7:AN7)*AO7 -> 36146.06 | AQ7: =AP7*7.75 -> 280131.97
A8: 45954 | B8: 波兰 | D8: PO-25102401 | E8: 1426107 | F8: 足球 | G8: 15 | H8: 46034 | AN8: =G8 -> 15 | AO8: 0 | AP8: =SUM(I8:AN8)*AO8 -> 0 | AQ8: =AP8*7.75 -> 0
A9: 45954 | B9: 波兰 | D9: PO-25102401 | E9: 1426107 | F9: 足球 | G9: 8520 | H9: 46041 | AN9: =G9 -> 8520 | AO9: 3.912 | AP9: =SUM(I9:AN9)*AO9 -> 33330.24 | AQ9: =AP9*7.75 -> 258309.36
A10: 45968 | B10: 希腊 | D10: PO-25110501 | E10: 1324138 | F10: 转盘游戏机 GR | G10: 5004 | H10: 46021 | O10: =G10 -> 5004 | AO10: 3.865 | AP10: =SUM(I10:AN10)*AO10 -> 19340.46 | AQ10: =AP10*7.75 -> 149888.57
A11: 45968 | B11: 希腊 | D11: PO-25110502 | E11: 1325107 | F11: 足球 GR | G11: 6000 | H11: 46021 | AN11: =G11 -> 6000 | AO11: 3.912 | AP11: =SUM(I11:AN11)*AO11 -> 23472 | AQ11: =AP11*7.75 -> 181908
A12: 45968 | B12: 希腊 | D12: PO-25110502 | E12: 1325107 | F12: 足球 GR | G12: 6 | H12: 46021 | AN12: =G12 -> 6 | AO12: 0 | AP12: =SUM(I12:AN12)*AO12 -> 0 | AQ12: =AP12*7.75 -> 0
A13: 45968 | B13: 希腊 | D13: PO-25110502 | E13: 1325107 | F13: 足球 GR | G13: 10 | H13: 46021 | AN13: =G13 -> 10 | AO13: 0 | AP13: =SUM(I13:AN13)*AO13 -> 0 | AQ13: =AP13*7.75 -> 0
A14: 45972 | B14: 克罗地亚 | D14: PO-25111001 | E14: 4726107 | F14: 足球 CR | G14: 5076 | H14: 45683 | AN14: =G14 -> 5076 | AO14: 3.912 | AP14: =SUM(I14:AN14)*AO14 -> 19857.31 | AQ14: =AP14*7.75 -> 153894.15
A15: 45972 | B15: 克罗地亚 | C15: 样品 | D15: PO-25111001 | E15: 4726107 | F15: 足球 CR | G15: 10 | H15: 45683 | AN15: =G15 -> 10 | AO15: 0 | AP15: =SUM(I15:AN15)*AO15 -> 0 | AQ15: =AP15*7.75 -> 0
A16: 45975 | B16: 罗马尼亚 | D16: PO-25111401 | E16: 3826107 | F16: 足球 RO | G16: 6168 | H16: 46037 | AN16: =G16 -> 6168 | AO16: 3.912 | AP16: =SUM(I16:AN16)*AO16 -> 24129.22 | AQ16: =AP16*7.75 -> 187001.46
A17: 45975 | B17: 罗马尼亚 | D17: PO-25111401 | E17: 3826107 | F17: 足球 RO | G17: 10 | H17: 46045 | AN17: =G17 -> 10 | AO17: 0 | AP17: =SUM(I17:AN17)*AO17 -> 0 | AQ17: =AP17*7.75 -> 0
A18: 45978 | B18: 意大利 | C18: 签办 | D18: PO-25111701 | E18: 3225107 | F18: 足球 IT | G18: 3 | H18: 46021 | AN18: =G18 -> 3 | AO18: 0 | AP18: =SUM(I18:AN18)*AO18 -> 0 | AQ18: =AP18*7.75 -> 0
A19: 45978 | B19: 意大利 | D19: PO-25111701 | E19: 3225107 | F19: 足球 IT | G19: 7200 | H19: 46038 | AN19: =G19 -> 7200 | AO19: 3.912 | AP19: =SUM(I19:AN19)*AO19 -> 28166.4 | AQ19: =AP19*7.75 -> 218289.6
A20: 45978 | B20: 意大利 | D20: PO-25111701 | E20: 3225107 | F20: 足球 IT | G20: 10 | H20: 46038 | AN20: =G20 -> 10 | AO20: 0 | AP20: =SUM(I20:AN20)*AO20 -> 0 | AQ20: =AP20*7.75 -> 0
A21: 45985 | B21: 美国 | D21: PO-25112401 | E21: 1123103- US-TAR | F21: 红色比卡超 EN-US | G21: 12600 | H21: 46034 | AA21: =G21 -> 12600 | AO21: 2.089 | AP21: =SUM(I21:AN21)*AO21 -> 26321.4 | AQ21: =AP21*7.75 -> 203990.85
A22: 45988 | B22: 新西兰 | D22: PO-25112503 | E22: 1126148 | F22: 足球 EN(黑色外壳） | G22: 822 | H22: 46045 | AN22: =G22 -> 822 | AO22: 3.912 | AP22: =SUM(I22:AN22)*AO22 -> 3215.66 | AQ22: =AP22*7.75 -> 24921.37
A23: 45988 | B23: 新西兰 | D23: PO-25112601 | E23: 1126148 | F23: 足球 EN(黑色外壳） | G23: 426 | H23: 46045 | AN23: =G23 -> 426 | AO23: 3.912 | AP23: =SUM(I23:AN23)*AO23 -> 1666.51 | AQ23: =AP23*7.75 -> 12915.45
A24: 45988 | B24: 保加利亚 | D24: PO-25112603 | E24: 3117070 | F24: 橙色超级男仔小精灵 | G24: 2508 | H24: 46045 | R24: =G24 -> 2508 | AO24: 2.77 | AP24: =SUM(I24:AN24)*AO24 -> 6947.16 | AQ24: =AP24*7.75 -> 53840.49
A25: 45988 | B25: 保加利亚 | D25: PO-25112603 | E25: 3124115 | F25: 新点读笔地图-BU/EN | G25: 1500 | H25: 46045 | AI25: =G25 -> 1500 | AO25: 4.132 | AP25: =SUM(I25:AN25)*AO25 -> 6198 | AQ25: =AP25*7.75 -> 48034.5
A26: 45992 | B26: 澳大利亚 | D26: PO-25120101 | E26: 1126148 | F26: 足球 EN(黑色外壳） | G26: 1500 | H26: 46045 | AN26: =G26 -> 1500 | AO26: 3.912 | AP26: =SUM(I26:AN26)*AO26 -> 5868 | AQ26: =AP26*7.75 -> 45477
A27: 45992 | B27: 澳大利亚 | D27: PO-25120101 | E27: 1126148 | F27: 足球 EN(黑色外壳） | G27: 12 | H27: 46045 | AN27: =G27 -> 12 | AO27: 0 | AP27: =SUM(I27:AN27)*AO27 -> 0 | AQ27: =AP27*7.75 -> 0
A28: 45992 | B28: 澳大利亚 | D28: PO-25120101 | E28: 1121118- AU | F28: 金属色比卡超 | G28: 2208 | H28: 46045 | Z28: =G28 -> 2208 | AO28: 2.09 | AP28: =SUM(I28:AN28)*AO28 -> 4614.72 | AQ28: =AP28*7.75 -> 35764.08
A29: 45992 | B29: 澳大利亚 | D29: PO-25120101 | E29: 1121118- AU | F29: 金属色比卡超 | G29: 12 | H29: 46045 | Z29: =G29 -> 12 | AO29: 0 | AP29: =SUM(I29:AN29)*AO29 -> 0 | AQ29: =AP29*7.75 -> 0
A30: 45999 | B30: 巴西 | D30: PO-25120501 | E30: 3325103 | F30: 红色比卡超 | G30: 3000 | H30: 46059 | AA30: =G30 -> 3000 | AO30: 2.176 | AP30: =SUM(I30:AN30)*AO30 -> 6528 | AQ30: =AP30*7.75 -> 50592
A31: 45999 | B31: 巴西 | D31: PO-25120501 | E31: 3325103 | F31: 红色比卡超 | G31: 18 | H31: 46059 | AA31: =G31 -> 18 | AO31: 0 | AP31: =SUM(I31:AN31)*AO31 -> 0 | AQ31: =AP31*7.75 -> 0
A32: 45999 | B32: 巴西 | D32: PO-25120501 | E32: 3325110 | F32: 四角星抢答器 | G32: 3000 | H32: 46059 | I32: =G32 -> 3000 | AO32: 3.361 | AP32: =SUM(I32:AN32)*AO32 -> 10083 | AQ32: =AP32*7.75 -> 78143.25
A33: 45999 | B33: 巴西 | D33: PO-25120501 | E33: 3325110 | F33: 四角星抢答器 | G33: 18 | H33: 46059 | I33: =G33 -> 18 | AO33: 0 | AP33: =SUM(I33:AN33)*AO33 -> 0 | AQ33: =AP33*7.75 -> 0
A34: 46000 | B34: 斯洛文尼亚 | D34: PO-25120803 | E34: 1526103 | F34: 红色比卡超-SL | G34: 3000 | H34: 46091 | AA34: =G34 -> 3000 | AO34: 1.937 | AP34: =SUM(I34:AN34)*AO34 -> 5811 | AQ34: =AP34*7.75 -> 45035.25
A35: 46000 | B35: 斯洛文尼亚 | D35: PO-25120803 | E35: 1526103 | F35: 红色比卡超-SL | G35: 16 | H35: 46091 | AA35: =G35 -> 16 | AO35: 0 | AP35: =SUM(I35:AN35)*AO35 -> 0 | AQ35: =AP35*7.75 -> 0
A36: 46000 | B36: 斯洛文尼亚（克罗地亚） | D36: PO-25120803 | E36: 4726103 | F36: 红色比卡超-CR | G36: 3000 | H36: 46091 | AA36: =G36 -> 3000 | AO36: 1.937 | AP36: =SUM(I36:AN36)*AO36 -> 5811 | AQ36: =AP36*7.75 -> 45035.25
A37: 46000 | B37: 斯洛文尼亚（克罗地亚） | D37: PO-25120803 | E37: 4726103 | F37: 红色比卡超-CR | G37: 16 | H37: 46091 | AA37: =G37 -> 16 | AO37: 0 | AP37: =SUM(I37:AN37)*AO37 -> 0 | AQ37: =AP37*7.75 -> 0
A38: 46001 | B38: 法国 | D38: PO-25121001 | E38: 1025103 | F38: 红色比卡超-FR | G38: 4002 | H38: 46045 | AA38: =G38 -> 4002 | AO38: 2.119 | AP38: =SUM(I38:AN38)*AO38 -> 8480.24 | AQ38: =AP38*7.75 -> 65721.86
A39: 46001 | B39: 法国 | D39: PO-25121002 | E39: 1025155 | F39: PTE 圆型游戏机-FR | G39: 6000 | H39: 46045 | L39: =G39 -> 6000 | AO39: 4.516 | AP39: =SUM(I39:AN39)*AO39 -> 27096 | AQ39: =AP39*7.75 -> 209994
A40: 46001 | B40: 法国 | D40: PO-25121002 | E40: 1025155 | F40: PTE 圆型游戏机-FR | G40: 6 | H40: 46045 | L40: =G40 -> 6 | AO40: 0 | AP40: =SUM(I40:AN40)*AO40 -> 0 | AQ40: =AP40*7.75 -> 0
...

Sheet 总排期
A1: 接单期 | B1: 第三客户名称 | C1: 国家 | D1: 客PO号 | E1: PO | F1: ITEM | G1: 货名 | H1: 数量 | I1: 装箱数 | J1: 总箱数 | K1: 验货期 | L1: 客确认验货期 | M1: 第三方验货期 | N1: 是否安排自检 | O1: 船期SO | P1: 计划走货期 | Q1: 签办进度 | R1: 客贴纸 | S1: 客供物料（IC） | T1: 包装进度 | U1: 箱唛移印资料 | V1: 日期码 | W1: PCBA/MCU/Flash IC | X1: 备注 | Y1: 单价USD | Z1: 金额USD | AA1: 金额HKD | AB1: 发票号 | AC1: 是否入系统 | AD1: 做货车间 | AE1: 生产车间 | AF1: 下单明细 | AG1: 送回数量 | AH1: 欠数 | AI1: 送货日期 | AJ1: 掉期天数 | AK1: 纸箱 | AL1: 贴纸 | AM1: 预计完成时间 | AN1: 彩盒样品寄出时间 | AO1: 说明书样品寄出时间 | AP1: 彩盒打稿OK时间 | AQ1: 说明书打稿OK时间 | AR1: 整体签板 | AS1: 收到包装日期
A2: 45988 | B2: Felyx | C2: 保加利亚 | E2: PO-25112603 | F2: 3124115 | G2: 新点读笔地图-BU/EN | H2: 1500 | I2: 6 | J2: =H2/I2 -> 250 | K2: 46142 | L2: 待确认 | P2: 46142 | S2: 46007 | T2: 翻单25041001 | U2: 打稿中 | V2: 260221BU | W2: World Tour Map: XM25QH128C BU/EN | X2: 中英文版本，不含电池，带有地图，OID笔，手册和纸张插入 | Y2: 4.132 | Z2: =H2*Y2 -> 6198 | AA2: =Z2*7.75 -> 48034.5 | AC2: 已入系统 | AD2: B | AE2: 东莞
A3: 46148 | B3: GP Italy | C3: 意大利 | E3: PO-26050602 | F3: 3222103 | G3: 红色比卡超-IT | H3: 1896 | I3: 6 | J3: =H3/I3 -> 316 | K3: 46213 | L3: 46216 | O3: 46239 | P3: 46209 | S3: 46172 | T3: 翻单25121201 | U3: 6/3确认移印箱唛 | V3: 261821IT | W3: PKM Kanto PCBA: ZPK028A(IT) | X3: 带电，GP意大利包装 | Y3: 1.899 | Z3: =H3*Y3 -> 3600.5 | AA3: =Z3*7.75 -> 27903.88 | AC3: 已入系统 | AD3: B | AE3: 邵阳 | AF3: 系统出单 | AG3: 1896 | AH3: =AG3-H3 -> 0 | AM3: 46201
A4: 46148 | B4: GP Italy | C4: 意大利 | E4: PO-26050602 | F4: 3222110 | G4: 四角星抢答器-IT | H4: 1896 | I4: 6 | J4: =H4/I4 -> 316 | K4: 46213 | L4: 46216 | O4: 46239 | P4: 46209 | S4: 46172 | T4: 翻单25121201 | U4: 6/3确认移印箱唛 | V4: 261821IT | W4: PKM Trivia Flash: ZPT011A(IT) MCU: ZPT001D | X4: 带电，GP意大利包装 | Y4: 3.06 | Z4: =H4*Y4 -> 5801.76 | AA4: =Z4*7.75 -> 44963.64 | AC4: 已入系统 | AD4: B | AE4: 邵阳 | AF4: 系统出单 | AG4: =1806+90 -> 1896 | AH4: =AG4-H4 -> 0 | AM4: 46200
A5: 46148 | B5: GP Italy | C5: 意大利 | E5: PO-26050601 | F5: 3225130 | G5: OMTS新款四角星-IT | H5: 8004 | I5: 6 | J5: =H5/I5 -> 1334 | K5: 46213 | L5: 46216 | O5: 46239 | P5: 46209 | S5: 46172 | T5: 5/27确认文档 | U5: 6/3确认移印箱唛 | V5: 261821IT | W5: Flash: AMSFX032CHX-043 MCU: AM32A070A-046 | X5: 带电，GP意大利包装 | Y5: 3.345 | Z5: =H5*Y5 -> 26773.38 | AA5: =Z5*7.75 -> 207493.7 | AC5: 已入系统 | AD5: B | AE5: 邵阳 | AF5: 系统出单 | AG5: =4584+2520+606+294 -> 8004 | AH5: =AG5-H5 -> 0 | AM5: 46210
A6: 46111 | B6: Gialamas - Greece | C6: 希腊 | E6: PO-26032507 | F6: 1326168 | G6: 涡轮四角星-GR | H6: 4680 | I6: 6 | J6: =H6/I6 -> 780 | K6: 46217 | L6: 46220 | O6: 46230 | P6: 46219 | S6: 46171 | T6: 4/29确认文档 | U6: 6/11确认移印，7/1确认箱唛 | V6: 261821GR | W6: IC Factory part no. Flash: AMSFX128DHX-P06 MCU: AM32A070A-050 | X6: 带电， 希腊包装 | Y6: 3.382 | Z6: =H6*Y6 -> 15827.76 | AA6: =Z6*7.75 -> 122665.14 | AC6: 已入系统 | AD6: B | AE6: 新邵 | AF6: 系统出单 | AG6: =2340+1404+468+468 -> 4680 | AH6: =AG6-H6 -> 0
A7: 46094 | B7: TM Toys -Poland | C7: 波兰 | E7: PO-26031201 | F7: 1426146 | G7: 蓝精灵-PL | H7: 4002 | I7: 6 | J7: =H7/I7 -> 667 | K7: 46220 | L7: 46223 | O7: 46237 | P7: 46219 | S7: ok | T7: 4/10确认文档 | U7: 4/10确认移印，4/30确认箱 | V7: 261821PL | W7: PCBA: ZZT003A(PL) | X7: 波兰版，带电,注意区分箱唛 | Y7: 2.59 | Z7: =H7*Y7 -> 10365.18 | AA7: =Z7*7.75 -> 80330.15 | AC7: 已入系统 | AD7: B | AE7: 新邵 | AF7: 系统出单 | AG7: =3168+102+732 -> 4002 | AH7: =AG7-H7 -> 0 | AM7: 7/14补齐尾数
A8: 46094 | B8: TM Toys -Poland | C8: 波兰(匈牙利） | E8: PO-26031201 | F8: 4526169 | G8: 超级精灵球-HU | H8: 5004 | I8: 6 | J8: =H8/I8 -> 834 | K8: 46220 | L8: 46223 | O8: 46237 | P8: 46219 | S8: 46176 | T8: 5/21确认彩盒，6/22确认说明书 | U8: 4/10确认移印，4/30确认箱 | V8: 261821HU | W8: PCBA: ZPU004A(HU) | X8: 匈牙利版，带电 | Y8: 2.573 | Z8: =H8*Y8 -> 12875.29 | AA8: =Z8*7.75 -> 99783.5 | AC8: 已入系统 | AD8: B | AE8: 东莞
A9: 45999 | B9: Pillowtex - Brazil | C9: 巴西（葡萄牙） | E9: PO-25120501 | F9: 3325110 | G9: 四角星抢答器 BR | H9: 3000 | I9: 6 | J9: 500 | K9: 46223 | L9: 46227 | O9: 46241 | P9: 46192 | S9: 46178 | T9: 1/29收到包装 | U9: 1/21确认箱唛，1/14确认移印 | V9: 260701BR | W9: Flash: ZPT012A(BR) MCU: ZPT001D | X9: 带电，新包装 | Y9: 3.361 | Z9: =H9*Y9 -> 10083 | AA9: =Z9*7.75 -> 78143.25 | AC9: 已入系统 | AD9: 邵阳 | AE9: 邵阳 | AF9: 系统出单 | AG9: 3000 | AH9: =AG9-H9 -> 0 | AM9: 46215
A10: 46115 | B10: GP France_Amazon | C10: 法国 | E10: PO-26040206 | F10: 1026107 | G10: 足球-FR | H10: 540 | I10: 6 | J10: =H10/I10 -> 90 | K10: 46224 | L10: 46225 | O10: 46235 | P10: 46202 | R10: 6/30收到外箱贴纸 | S10: 4/20 | T10: 翻单跟25121003 | U10: 4/30确认箱唛移印 | V10: 261821FR | W10: IC Factory part no.: Flash: ZFZ002E(FR) MCU: ZFZ001A | X10: 带电，法国GP包装，贴亚马逊外箱贴纸 | Y10: 4.765 | Z10: =H10*Y10 -> 2573.1 | AA10: =Z10*7.75 -> 19941.53 | AC10: 已入系统 | AD10: B | AE10: 新邵 | AF10: 系统出单 | AG10: =504+36 -> 540 | AH10: =AG10-H10 -> 0 | AM10: 46197
A11: 46115 | B11: GP France_Amazon | C11: 法国 | E11: PO-26040207 | F11: 1026107 | G11: 足球-FR | H11: 336 | I11: 6 | J11: =H11/I11 -> 56 | K11: 46224 | L11: 46225 | P11: 46223 | R11: 7/21收到 | S11: 4/20 | T11: 翻单跟25121003 | U11: 4/30确认箱唛移印 | V11: 261821FR | W11: IC Factory part no.: Flash: ZFZ002E(FR) MCU: ZFZ001A | X11: 带电，法国GP包装，贴亚马逊外箱贴纸 | Y11: 4.765 | Z11: =H11*Y11 -> 1601.04 | AA11: =Z11*7.75 -> 12408.06 | AC11: 已入系统 | AD11: B | AE11: 新邵 | AF11: 系统出单 | AG11: 336 | AH11: =AG11-H11 -> 0 | AM11: 46203
A12: 46080 | B12: Orbico | C12: 波兰 | E12: PO-26022601 | F12: 1426155 | G12: PTE 圆型游戏机- PL | H12: 9210 | I12: 6 | J12: =H12/I12 -> 1535 | K12: 46227 | L12: 46230 | O12: 46231 | P12: 46219 | T12: 4/2确认包装 | U12: 4/2确认箱唛移印 | V12: 261821PL | W12: Flash: ZPE009A(PL) MCU: ZPE001A | X12: 带电，波兰新包装 | Y12: 4.335 | Z12: =H12*Y12 -> 39925.35 | AA12: =Z12*7.75 -> 309421.46 | AC12: 已入系统 | AD12: B | AE12: 邵阳 | AF12: 系统出单 | AG12: =4104+3612+1356+138 -> 9210 | AH12: =AG12-H12 -> 0 | AM12: 46219
A13: 46080 | B13: Orbico | C13: 波兰 | E13: PO-26022602 | F13: 1426169 | G13: 超级精灵球- PL | H13: 9000 | I13: 6 | J13: =H13/I13 -> 1500 | K13: 46227 | L13: 46230 | O13: 46242 | P13: 46220 | S13: 46196 | T13: 5/21确认彩盒,7/3确认说明书 | U13: 5/25确认箱，5/21确认移印 | V13: 261821PL | W13: PCBA: ZPU003A(PL) | X13: 带电，波兰新包装 | Y13: 2.573 | Z13: =H13*Y13 -> 23157 | AA13: =Z13*7.75 -> 179466.75 | AC13: 已入系统 | AD13: B | AE13: 东莞 | AH13: =AG13-H13 -> -9000
A14: 46164 | B14: CAFFARO - Argentina | C14: 阿根廷 | E14: PO-26052103 | F14: 5226146 | G14: 蓝精灵-LA | H14: 5460 | I14: 4 | J14: =H14/I14 -> 1365 | K14: 46230 | L14: 46230 | O14: 46237 | P14: 46219 | S14: 46197 | T14: 6/10确认文档 | U14: 6/1确认箱唛移印 | V14: 261821ES | W14: PCBA: ZZT010A(LA) | X14: 西班牙语 阿根廷（西班牙）包装，带电（用客指定 Vinnic 电池） | Y14: 2.657 | Z14: =H14*Y14 -> 14507.22 | AA14: =Z14*7.75 -> 112430.96 | AC14: 已入系统 | AD14: B | AE14: 新邵 | AF14: 系统出单 | AG14: =1260+1680+840+1680 -> 5460 | AH14: =AG14-H14 -> 0
A15: 46142 | B15: Talent Show | C15: 克罗地亚 | E15: PO-26042901 | F15: 4726146 | G15: 蓝精灵-CR | H15: 5460 | I15: 6 | J15: =H15/I15 -> 910 | K15: 46231 | L15: 46233 | O15: 46239 | P15: 46220 | S15: 46198 | T15: 4/30确认文档 | U15: 5/6确认箱唛移印 | V15: 261821HR | W15: PCBA: ZZT008A(CR) | X15: 带电，克罗地亚包装 | Y15: 2.59 | Z15: =H15*Y15 -> 14141.4 | AA15: =Z15*7.75 -> 109595.85 | AC15: 已入系统 | AD15: B | AE15: 新邵 | AF15: 系统出单 | AG15: =1056+2112+2292 -> 5460 | AH15: =AG15-H15 -> 0
A16: 46091 | B16: Ultra Pro | C16: 美国 | E16: PO-26030904 | F16: 1126164- US | G16: 迪士尼米奇头-EN-US | H16: 13200 | I16: 6 | J16: =H16/I16 -> 2200 | K16: 46237 | L16: CMA – 8/5 , CIS – 8/6，8/10返验 | O16: 46242 | P16: 46233 | S16: 46206 | T16: 6/3收到包装 | U16: 5/11确认箱唛,6/5确认移印 | V16: DONGGUAN 07/2026 EN | W16: PCBA: ZDG001A(EN) | X16: 带电，喷金属油+闪粉 -外箱增加上下平咭，客ITEM号：10307 | Y16: 2.697 | Z16: =H16*Y16 -> 35600.4 | AA16: =Z16*7.75 -> 275903.1 | AC16: 已入系统 | AD16: B | AE16: 新邵 | AF16: 系统出单 | AG16: =3024+2520+504+2520+3024+1008+600 -> 13200 | AH16: =AG16-H16 -> 0 | AM16: 46237
A17: 46157 | B17: Educa | C17: 西班牙 | E17: PO-26051503 | F17: 1226168 | G17: 涡轮四角星- ES | H17: 10020 | I17: 6 | J17: =H17/I17 -> 1670 | K17: 46237 | L17: Customer Educa 8/4 | O17: 46241 | P17: 46227 | R17: 外箱贴纸 20677-73455 | S17: 46193 | T17: 7/9确认彩盒，7/13确认说明书 | U17: 6/12确认箱唛,6/22确认移印 | V17: 261821ES | W17: Flash: AMSFX128DHS-P09 MCU: AM32A070A-050 | X17: 带电，西班牙包装，客PO:73455 ,包装上增加一第客供贴纸 包装需要备品 2%（彩盒+纸箱） | Y17: 3.45 | Z17: =H17*Y17 -> 34569 | AA17: =Z17*7.75 -> 267909.75 | AC17: 已入系统 | AD17: B | AE17: 新邵 | AF17: 系统出单 | AG17: =6552+1512+504+1008+444 -> 10020 | AH17: =AG17-H17 -> 0 | AM17: 46235
A18: 46098 | B18: Ultra Pro | C18: 加拿大 | E18: PO-26031602 | F18: 1126164-US | G18: 迪士尼米奇头-EN-US | H18: 5280 | I18: 6 | J18: =H18/I18 -> 880 | K18: 46239 | L18: CMA – 8/5 , CIS – 8/6，8/14返验 | O18: 46250 | P18: 46230 | S18: 46210 | T18: 包装跟美国US | U18: 5/8确认箱唛，6/5确认移印 | V18: DONGGUAN 07/2026 EN | W18: Disney Guess PCBA: ZDG001A(EN) | X18: 带电，喷金属油+闪粉 -外箱增加上下平咭，客ITEM号：10307 | Y18: 2.697 | Z18: =H18*Y18 -> 14240.16 | AA18: =Z18*7.75 -> 110361.24 | AC18: 已入系统 | AD18: B | AE18: 新邵 | AF18: 系统出单 | AG18: =360+504+2016+1512+504+90+294 -> 5280 | AH18: =AG18-H18 -> 0 | AM18: 46239
A19: 46169 | B19: Proludis Giocattoli - Italy | C19: 意大利 | E19: PO-26052201 | F19: 3226159 | G19: 新款五角星-IT | H19: 5004 | I19: 6 | J19: =H19/I19 -> 834 | K19: 46252 | L19: 46253 | P19: 46234 | S19: 46177 | T19: 6/3确认文档 | U19: 6/15确认箱唛及移印 | V19: 262171IT | W19: FOF Ultimate Flash: ZFU009A(IT)，MCU: ZFU001A | X19: 带电，意大利包装 | Y19: 3.651 | Z19: =H19*Y19 -> 18269.6 | AA19: =Z19*7.75 -> 141589.4 | AC19: 已入系统 | AD19: B | AE19: 邵阳 | AF19: 系统出单 | AG19: =4152+774+78 -> 5004 | AH19: =AG19-H19 -> 0 | AM19: 预计7/31
A20: 46169 | B20: Proludis Giocattoli - Italy | C20: 意大利 | E20: PO-26052201 | F20: 3226169 | G20: 超级精灵球-IT | H20: 5004 | I20: 6 | J20: =H20/I20 -> 834 | K20: 46240 | L20: 46241 | P20: 46234 | S20: 46203 | T20: 5/4收到包装，7/3确认说明书 | U20: 6/15确认箱唛及移印 | V20: 262171IT | W20: PMK Ultimate PCBA: ZPU005A(IT) | X20: 带电，意大利包装 | Y20: 2.573 | Z20: =H20*Y20 -> 12875.29 | AA20: =Z20*7.75 -> 99783.5 | AC20: 已入系统 | AD20: B | AE20: 东莞 | AH20: =AG20-H20 -> -5004
A21: 46157 | B21: Educa | C21: 西班牙 | E21: PO-26051502 | F21: 1226157 | G21: 城市套装游戏机-ES | H21: 8400 | I21: 4 | J21: =H21/I21 -> 2100 | K21: 46240 | L21: Customer Educa 8/12 | O21: 46247 | P21: 46230 | R21: 外箱贴纸 20668-73434 | S21: 46212 | T21: 6/5确认文档 | U21: 6/12确认箱唛,6/15确认移印 | V21: 261821ES | W21: Flash: AMSFX128DHS-P08 MCU: AM32A070A-051 | X21: 带电，西班牙包装，客PO:73434 包装需要备品 2%（彩盒+纸箱） | Y21: 4.772 | Z21: =H21*Y21 -> 40084.8 | AA21: =Z21*7.75 -> 310657.2 | AC21: 已入系统 | AD21: B | AE21: 新邵 | AF21: 系统出单 | AG21: =336+1004+672+2352+3696+340 -> 8400 | AH21: =AG21-H21 -> 0 | AM21: 46240
A22: 46151 | B22: Toy Partner | C22: 西班牙 | E22: PO-26050701 | F22: 1226169 | G22: 超级精灵球-ES | H22: 6000 | I22: 6 | J22: =H22/I22 -> 1000 | K22: 46241 | L22: 46245 | O22: 46246 | P22: 46231 | S22: 46203 | T22: 5/28确认包装 | U22: 6/16确认箱唛，6/25确认移印 | V22: 262171ES | W22: PCBA: ZPU006A(ES) | X22: 带电，西班牙包装 | Y22: 2.573 | Z22: =H22*Y22 -> 15438 | AA22: =Z22*7.75 -> 119644.5 | AC22: 已入系统 | AD22: B | AE22: 东莞 | AH22: =AG22-H22 -> -6000
A23: 46161 | B23: Dexy | C23: 塞尔维亚 | E23: PO-26051802 | F23: 3026146 | G23: 蓝精灵-SE | H23: 5460 | I23: 6 | J23: =H23/I23 -> 910 | K23: 46241 | L23: 46244 | O23: 46247 | P23: 46239 | S23: 6/25 | T23: 5/19确认文档 | U23: 5/26确认箱唛移印 | V23: 261821SE | W23: PCBA: ZZT007A(SE) | X23: 带电，塞尔维亚包装 | Y23: 2.667 | Z23: =H23*Y23 -> 14561.82 | AA23: =Z23*7.75 -> 112854.11 | AC23: 已入系统 | AD23: B | AE23: 新邵 | AF23: 系统出单 | AG23: =528+294+4224+414 -> 5460 | AH23: =AG23-H23 -> 0 | AM23: 46238
A24: 46136 | B24: GP France | C24: 法国 | E24: PO-26042401 | F24: 1026156 | G24: 迪士尼游戏机-FR | H24: 4800 | I24: 6 | J24: =H24/I24 -> 800 | K24: 46244 | L24: 46248 | P24: 46232 | S24: 46204 | T24: 6/26确认文档 | U24: 6/25确认移印箱唛 | V24: 262171FR | W24: IC Factory part no. Flash: ZDT002A(FR) MCU: ZDT001A | X24: 带电，GP法国包装 | Y24: 3.303 | Z24: =H24*Y24 -> 15854.4 | AA24: =Z24*7.75 -> 122871.6 | AC24: 已入系统 | AD24: B | AE24: 东莞 | AH24: =AG24-H24 -> -4800
A25: 46163 | B25: Asmodee - CZ | C25: 捷克共和国 | E25: PO-26052004 | F25: 3526107 | G25: 足球-CZ | H25: 5040 | I25: 6 | J25: =H25/I25 -> 840 | K25: 46244 | L25: 46251 | P25: 46251 | S25: 46198 | T25: 5/22确认包装 | U25: 7/16确认箱唛移印 | V25: 262171CZ | W25: Flash: ZFZ007C(CZ) MCU: ZFZ001A | X25: 带电，捷克包装 | Y25: 4.029 | Z25: =H25*Y25 -> 20306.16 | AA25: =Z25*7.75 -> 157372.74 | AC25: 已入系统 | AD25: B | AE25: 新邵 | AF25: 系统出单 | AG25: =252+2520+2016+252 -> 5040 | AH25: =AG25-H25 -> 0 | AM25: 46243
A26: 46151 | B26: Toy Partner | C26: 西班牙（葡萄牙语） | E26: PO-26050702 | F26: 3326103 | G26: 红色比卡超-PO | H26: 3000 | I26: 6 | J26: =H26/I26 -> 500 | K26: 46244 | L26: 46245 | O26: 46246 | P26: 46231 | S26: 46207 | T26: 7/9确认包装 | U26: 6/16确认箱唛，6/25确认移印 | V26: 262171PO | W26: PCBA: ZPK041A(PO) | X26: 带电，（无隔电片） 葡萄牙语版包装 | Y26: 1.899 | Z26: =H26*Y26 -> 5697 | AA26: =Z26*7.75 -> 44151.75 | AC26: 已入系统 | AD26: B | AE26: 邵阳 | AF26: 系统出单 | AG26: =2988+12 -> 3000 | AH26: =AG26-H26 -> 0 | AM26: 46248
A27: 46091 | B27: Ultra Pro | C27: 美国 | E27: PO-26030905 | F27: 1126156- US | G27: 迪士尼游戏机-EN-US | H27: 12360 | I27: 6 | J27: =H27/I27 -> 2060 | K27: 46246 | L27: CMA – 8/13 , CIS – 8/14 | O27: 46249 | P27: 46233 | S27: 46205 | T27: 6/3收到包装 | U27: 5/11确认箱唛,6/5确认移印 | V27: DONGGUAN 07/2026 EN | W27: Flash: ZDT001A(EN) MCU: ZDT001A | X27: 带电，美国US包装 -外箱增加上下平咭 客ITEM:10308 | Y27: 3.317 | Z27: =H27*Y27 -> 40998.12 | AA27: =Z27*7.75 -> 317735.43 | AC27: 已入系统 | AD27: B | AE27: 新邵 | AF27: 系统出单 | AG27: =504+2016+1512+2016+2520+3024+768 -> 12360 | AH27: =AG27-H27 -> 0
A28: 46098 | B28: Ultra Pro | C28: 加拿大 | E28: PO-26031602 | F28: 1126156-US | G28: 迪士尼游戏机-EN-US | H28: 4980 | I28: 6 | J28: =H28/I28 -> 830 | K28: 46246 | L28: CMA – 8/13 , CIS – 8/17 | O28: 46250 | P28: 46233 | S28: 46205 | T28: 包装跟美国US | U28: 5/8确认箱唛，6/5确认移印 | V28: DONGGUAN 07/2026 EN | W28: Disney Trivia Flash: ZDT001A(EN) MCU: ZDT001A | X28: 带电，美国US包装 -外箱增加上下平咭 客ITEM:10308 | Y28: 3.317 | Z28: =H28*Y28 -> 16518.66 | AA28: =Z28*7.75 -> 128019.62 | AC28: 已入系统 | AD28: B | AE28: 新邵 | AF28: 系统出单 | AG28: =504+2016+504+1008+948 -> 4980 | AH28: =AG28-H28 -> 0
A29: 46121 | B29: Sunman - Romania | C29: 罗马尼亚 | E29: PO-26040802 | F29: 3826164 | G29: 迪士尼米奇头-RO | H29: 5400 | I29: 6 | J29: =H29/I29 -> 900 | K29: 46248 | L29: 46251 | P29: 46234 | S29: 46210 | T29: 7/3确认彩盒，7/10确认说明书 | U29: 6/17确认箱唛，移印待确认 | V29: 262171RO | W29: IC Factory part no. PCBA: ZDG004A(RO) | X29: 带电，喷金属油+闪粉，罗马尼亚包装 | Y29: 2.683 | Z29: =H29*Y29 -> 14488.2 | AA29: =Z29*7.75 -> 112283.55 | AC29: 已入系统 | AD29: B | AE29: 新邵 | AF29: 系统出单 | AG29: =1944+1008+1368+1080 -> 5400 | AH29: =AG29-H29 -> 0 | AM29: 46248
A30: 46111 | B30: Gialamas - Greece | C30: 希腊 | E30: PO-26032603 | F30: 1326103 | G30: 红色比卡超-GR | H30: 4500 | I30: 6 | J30: =H30/I30 -> 750 | K30: 46251 | L30: 46254 | P30: 46240 | S30: 46218 | T30: 7/8确认包装 | U30: 6/11确认移印，7/1确认箱唛 | V30: 262171GR | W30: Pokemon Kanto GR PCBA - ZPK040A(GR) | X30: 带电，无隔电片， 希腊包装 | Y30: 1.899 | Z30: =H30*Y30 -> 8545.5 | AA30: =Z30*7.75 -> 66227.63 | AC30: 已入系统 | AD30: B | AE30: 邵阳 | AF30: 系统出单 | AG30: =4470+30 -> 4500 | AH30: =AG30-H30 -> 0
A31: 46164 | B31: Golden Bear | C31: 英国 | E31: PO-26052202 | F31: 1125155- UK | G31: PTE 圆型游戏机-EN-UK | H31: 7002 | I31: 6 | J31: =H31/I31 -> 1167 | K31: =P31 -> 46251 | L31: 46252 | P31: 46251 | T31: 6/15确认彩盒，拼图更新2026，6/24确认说明书 | U31: 6/25确认移印箱唛 | V31: 262171EN | W31: Flash: ZPE001A(EN) MCU: ZPE001A | X31: 英国版-有盖版彩盒，带电池， x 4C双面游戏板(50CM)，包装需要使用FSC纸张（内卡/彩盒/说明书/拼图），请注意：外箱封一条长胶带密封纸箱。補回120pcs遊戲版給美國客戶 | Y31: 4.335 | Z31: =H31*Y31 -> 30353.67 | AA31: =Z31*7.75 -> 235240.94 | AC31: 已入系统 | AD31: B | AE31: 邵阳 | AF31: 系统出单 | AG31: =2520+3480+954+48 -> 7002 | AH31: =AG31-H31 -> 0
A32: 46151 | B32: Toy Partner | C32: 西班牙 | E32: PO-26050703 | F32: 1226156 | G32: 迪士尼游戏机-ES | H32: 4980 | I32: 6 | J32: =H32/I32 -> 830 | K32: 46251 | L32: 46254 | P32: 46248 | S32: 46210 | T32: 6/23确认文档 | U32: 6/22确认箱唛，6/25确认移印 | V32: 262171ES | W32: IC Factory part no. Flash: ZDT004A(ES) MCU: ZDT001A | X32: 带电，西班牙包装 | Y32: 3.303 | Z32: =H32*Y32 -> 16448.94 | AA32: =Z32*7.75 -> 127479.29 | AC32: 已入系统 | AD32: B | AE32: 新邵 | AF32: 系统出单 | AH32: =AG32-H32 -> -4980
A33: 46111 | B33: Gialamas - Greece | C33: 希腊 | E33: PO-26032603 | F33: 1326110 | G33: 四角星抢答器-GR | H33: 6300 | I33: 6 | J33: =H33/I33 -> 1050 | K33: 46251 | L33: 46254 | P33: 46240 | S33: 46213 | T33: 6/25确认文档 | U33: 6/11确认移印，7/1确认箱唛 | V33: 262171GR | W33: Pokemon Trainer Trivia GR Flash - ZPT013A(GR) MCU: ZPT001D | X33: 带电， 希腊包装,留意面壳LGOG移印跟彩盒LOGO一样 | Y33: 3.06 | Z33: =H33*Y33 -> 19278 | AA33: =Z33*7.75 -> 149404.5 | AC33: 已入系统 | AD33: B | AE33: 邵阳 | AF33: 系统出单 | AG33: =4572 -> 4572 | AH33: =AG33-H33 -> -1728
A34: 46121 | B34: Sunman - Turkey | C34: 土耳其 | E34: PO-26040801 | F34: 3626146 | G34: 蓝精灵-TU | H34: 8010 | I34: 6 | J34: =H34/I34 -> 1335 | K34: 46252 | L34: 46255 | P34: 46234 | S34: 46203 | T34: 4/9确认文档 | U34: 5/14确认移印，5/8箱唛确认 | V34: 261821TU | W34: Magic Tim PCBA: ZZT012A(TU) | X34: 带电，土耳其包装 | Y34: 2.59 | Z34: =H34*Y34 -> 20745.9 | AA34: =Z34*7.75 -> 160780.73 | AC34: 已入系统 | AD34: B | AE34: 新邵 | AF34: 系统出单 | AG34: =4752+1584+1056+528+90 -> 8010 | AH34: =AG34-H34 -> 0 | AM34: 46235
A35: 46169 | B35: Proludis Giocattoli - Italy | C35: 意大利 | E35: PO-26052201 | F35: 3226164 | G35: 迪士尼米奇头-IT | H35: 3000 | I35: 6 | J35: =H35/I35 -> 500 | K35: 46251 | L35: 46253 | P35: 46234 | S35: 46213 | T35: 7/14确认包装 | U35: 6/15确认箱唛及移印 | V35: 262171IT | W35: Disney Guess PCBA: ZDG005A(IT) | X35: 带电，喷金属油+闪粉，意大利包装 | Y35: 2.683 | Z35: =H35*Y35 -> 8049 | AA35: =Z35*7.75 -> 62379.75 | AC35: 已入系统 | AD35: B | AE35: 新邵 | AF35: 系统出单 | AG35: =2520+450+30 -> 3000 | AH35: =AG35-H35 -> 0 | AM35: 46244
A36: 46111 | B36: Gialamas - Greece | C36: 希腊 | E36: PO-26032603 | F36: 1326164 | G36: 迪士尼米奇头-GR | H36: 5280 | I36: 6 | J36: =H36/I36 -> 880 | K36: 46253 | L36: 46254 | P36: 46240 | S36: 46218 | T36: 7/6确认彩盒，7/10确认说明书 | U36: 6/11确认移印，7/1确认箱唛 | V36: 262171GR | W36: Disney Guess GR PCBA - ZDG002A(GR) | X36: 带电， 希腊包装，喷金属油+闪粉 | Y36: 2.64 | Z36: =H36*Y36 -> 13939.2 | AA36: =Z36*7.75 -> 108028.8 | AC36: 已入系统 | AD36: B | AE36: 新邵 | AF36: 系统出单 | AH36: =AG36-H36 -> -5280
A37: 46121 | B37: Sunman - Turkey | C37: 土耳其 | E37: PO-26040801 | F37: 3626164 | G37: 迪士尼米奇头-TU | H37: 5280 | I37: 6 | J37: =H37/I37 -> 880 | K37: 46254 | L37: 46255 | P37: 46234 | S37: 46218 | T37: 7/6确认彩盒，7/13确认说明书 | U37: 移印待确认，5/8箱唛确认 | V37: 261821TU | W37: Disney Guess PCBA : ZDG003A(TU) | X37: 带电，喷金属油+闪粉，土耳其包装 | Y37: 2.64 | Z37: =H37*Y37 -> 13939.2 | AA37: =Z37*7.75 -> 108028.8 | AC37: 已入系统 | AD37: B | AE37: 新邵 | AF37: 系统出单 | AG37: =1008+1008+504 -> 2520 | AH37: =AG37-H37 -> -2760
A38: 46189 | B38: Flat River | C38: 美国 | E38: PO-26061101 | F38: 1125103- US-MIL | G38: 红色比卡超EN-US | H38: 1758 | I38: 6 | J38: =H38/I38 -> 293 | K38: 46254 | L38: 46258 | P38: 46251 | S38: 46208 | T38: 7/15确认包装 | U38: 7/24确认箱唛，7/13确认移印，7/27确认邮包盒唛头 | V38: DONGGUAN 08/2026 EN | W38: PKM Kanto: ZPK001B(EN) | X38: 带电，无隔电片， 新包装（彩盒+邮包盒） | Y38: 2.122 | Z38: =H38*Y38 -> 3730.48 | AA38: =Z38*7.75 -> 28911.22 | AC38: 已入系统 | AD38: B | AE38: 邵阳 | AF38: 系统出单 | AG38: 1758 | AH38: =AG38-H38 -> 0
A39: 46189 | B39: Flat River | C39: 美国 | E39: PO-26061101 | F39: 1125106- US-MIL | G39: 紫波比卡超EN-US | H39: 1650 | I39: 6 | J39: =H39/I39 -> 275 | K39: 46254 | L39: 46258 | P39: 46251 | S39: 46208 | T39: 7/15确认包装 | U39: 7/24确认箱唛，7/13确认移印，7/27确认邮包盒唛头 | V39: DONGGUAN 08/2026 EN | W39: PKM Ash: ZPK013A(EN) | X39: 带电，无隔电片， 新包装（彩盒+邮包盒） | Y39: 2.163 | Z39: =H39*Y39 -> 3568.95 | AA39: =Z39*7.75 -> 27659.36 | AC39: 已入系统 | AD39: B | AE39: 邵阳 | AF39: 系统出单 | AG39: 1650 | AH39: =AG39-H39 -> 0
A40: 46189 | B40: Flat River | C40: 美国 | E40: PO-26061101 | F40: 1125117- US-MIL | G40: 比卡超手表 EN-US | H40: 2202 | I40: 6 | J40: =H40/I40 -> 367 | K40: 46254 | L40: 46258 | P40: 46251 | S40: 46208 | T40: 说明书翻单26031303，彩盒7/15更新 | U40: 7/24确认箱唛，7/13确认移印，7/27确认邮包盒唛头 | V40: DONGGUAN 08/2026 EN | W40: PKM Mission:ZPD001A(EN) | X40: 不带电， 新包装（彩盒+邮包盒） | Y40: 2.913 | Z40: =H40*Y40 -> 6414.43 | AA40: =Z40*7.75 -> 49711.83 | AC40: 已入系统 | AD40: B | AE40: 邵阳 | AF40: 系统出单 | AH40: =AG40-H40 -> -2202
...

Sheet 样办排期
A1: 接单期 | B1: 第三客户名称 | C1: 国家 | D1: 客PO号 | E1: PO | F1: ITEM | G1: 货名 | H1: 数量 | I1: 装箱数 | J1: 总箱数 | K1: 交办日期 | L1: 验货期 | M1: 第三方验货期 | N1: 是否安排自检 | O1: 船期SO | P1: 计划走货期 | Q1: 样办回来日期 | R1: 样办寄出日期 | S1: 欠数 | T1: 签回日期 | U1: 客贴纸 | V1: 客供物料（IC） | W1: 包装进度 | X1: 箱唛移印资料 | Y1: 日期码 | Z1: PCBA/MCU/Flash IC | AA1: 备注 | AB1: 单价USD | AC1: 金额USD | AD1: 金额HKD | AE1: 发票号 | AF1: 是否入系统 | AG1: 做货车间 | AH1: 生产车间 | AI1: 下单明细 | AJ1: 电子交期 | AK1: 塑胶交期 | AL1: 包装交期 | AM1: 送回数量 | AN1: 欠数 | AO1: 送货日期 | AP1: 掉期天数 | AQ1: 纸箱 | AR1: 贴纸 | AS1: 样板交期 | AT1: 彩盒样品寄出时间 | AU1: 说明书样品寄出时间 | AV1: 彩盒打稿OK时间 | AW1: 说明书打稿OK时间 | AX1: 整体签板 | AY1: 收到包装日期
A2: 46083 | B2: Modell & Hobby | C2: 匈牙利 | D2: 签办 | E2: PO-26022701 | F2: 4526168 | G2: 涡轮四角星-HU | H2: 5 | K2: =L2-14 -> #N/A | L2: =VLOOKUP($F2,总排期!$F:$U,6,0) -> #N/A | P2: =VLOOKUP($F2,总排期!$F:$U,11,0) -> #N/A | R2: 7/11寄出5PCS | T2: 46218 | V2: =VLOOKUP($F2,总排期!$F:$U,14,0) -> #N/A | W2: =VLOOKUP($F2,总排期!$F:$U,15,0) -> #N/A | X2: =VLOOKUP($F2,总排期!$F:$U,16,0) -> #N/A | Y2: 261821HU | Z2: Flash: AMSFX128DHS-P03 MCU: AM32A070A-050 | AA2: 带电，匈牙利包装 | AB2: 0 | AC2: =H2*AB2 -> 0 | AD2: =AC2*7.75 -> 0 | AF2: 已入系统 | AG2: B | AH2: 新邵 | AI2: 系统出单 | AJ2: OK | AL2: OK | AM2: 6 | AN2: =AM2-H2 -> 1 | AS2: 46210
A3: 46148 | B3: GP Italy | C3: 意大利 | D3: 大货办+签办 | E3: PO-26050601 | F3: 3225130 | G3: OMTS新款四角星-IT | H3: 6 | K3: =L3-14 -> 46199 | L3: =VLOOKUP($F3,总排期!$F:$U,6,0) -> 46213 | P3: =VLOOKUP($F3,总排期!$F:$U,11,0) -> 46209 | Q3: 46211 | R3: 7/8寄出2PCS,7/20补寄4PCS | T3: 46214 | V3: =VLOOKUP($F3,总排期!$F:$U,14,0) -> 46172 | W3: =VLOOKUP($F3,总排期!$F:$U,15,0) -> 5/27确认文档 | X3: =VLOOKUP($F3,总排期!$F:$U,16,0) -> 6/3确认移印箱唛 | Y3: 261821IT | Z3: Flash: AMSFX032CHX-043 MCU: AM32A070A-046 | AA3: 带电，GP意大利包装 | AB3: 0 | AC3: =H3*AB3 -> 0 | AD3: =AC3*7.75 -> 0 | AF3: 已入系统 | AG3: B | AH3: 邵阳 | AI3: 系统出单 | AJ3: OK | AL3: OK | AM3: 6 | AN3: =AM3-H3 -> 0 | AS3: 46209
A4: 46111 | B4: Gialamas - Greece | C4: 希腊 | D4: 签办 | E4: PO-26032507 | F4: 1326168 | G4: 涡轮四角星-GR | H4: 6 | K4: =L4-14 -> 46203 | L4: =VLOOKUP($F4,总排期!$F:$U,6,0) -> 46217 | P4: =VLOOKUP($F4,总排期!$F:$U,11,0) -> 46219 | Q4: 46211 | R4: 7/8寄出3PCS,其余质量问题 | T4: 46214 | V4: =VLOOKUP($F4,总排期!$F:$U,14,0) -> 46171 | W4: =VLOOKUP($F4,总排期!$F:$U,15,0) -> 4/29确认文档 | X4: =VLOOKUP($F4,总排期!$F:$U,16,0) -> 6/11确认移印，7/1确认箱唛 | Y4: 261821GR | Z4: IC Factory part no. Flash: AMSFX128DHX-P06 MCU: AM32A070A-050 | AA4: 带电， 希腊包装 | AB4: 0 | AC4: =H4*AB4 -> 0 | AD4: =AC4*7.75 -> 0 | AF4: 已入系统 | AG4: B | AH4: 新邵 | AI4: 系统出单 | AJ4: OK | AL4: OK | AM4: 6 | AN4: =AM4-H4 -> 0 | AS4: 46210
A5: 46106 | B5: Apollo - Slovenia | C5: 斯洛文尼亚 | D5: 签办 | E5: PO-26032503 | F5: 1526146 | G5: 蓝精灵-SL | H5: 15 | K5: =L5-14 -> #N/A | L5: =VLOOKUP($F5,总排期!$F:$U,6,0) -> #N/A | P5: =VLOOKUP($F5,总排期!$F:$U,11,0) -> #N/A | R5: 7/11寄出5PCS,7/15寄出10PCS | T5: 46218 | V5: =VLOOKUP($F5,总排期!$F:$U,14,0) -> #N/A | W5: =VLOOKUP($F5,总排期!$F:$U,15,0) -> #N/A | X5: =VLOOKUP($F5,总排期!$F:$U,16,0) -> #N/A | Y5: 261821SL | Z5: IC Factory part no. ZZT009A(SL) | AA5: 带电，跟PO-26032504拼柜走货 | AB5: 0 | AC5: =H5*AB5 -> 0 | AD5: =AC5*7.75 -> 0 | AF5: 已入系统 | AG5: B | AH5: 新邵 | AI5: 系统出单 | AJ5: OK | AL5: OK | AM5: 16 | AN5: =AM5-H5 -> 1 | AS5: 46211
A6: 46094 | B6: TM Toys -Poland | C6: 波兰(匈牙利） | D6: 签办 | E6: PO-26031201 | F6: 4526169 | G6: 超级精灵球-HU | H6: 16 | K6: =L6-14 -> 46206 | L6: =VLOOKUP($F6,总排期!$F:$U,6,0) -> 46220 | P6: =VLOOKUP($F6,总排期!$F:$U,11,0) -> 46219 | Q6: 46211 | R6: 46211 | T6: 46223 | V6: =VLOOKUP($F6,总排期!$F:$U,14,0) -> 46176 | W6: =VLOOKUP($F6,总排期!$F:$U,15,0) -> 5/21确认彩盒，6/22确认说明书 | X6: =VLOOKUP($F6,总排期!$F:$U,16,0) -> 4/10确认移印，4/30确认箱 | Y6: 261821HU | Z6: PCBA: ZPU004A(HU) | AA6: 匈牙利版，带电 | AB6: 0 | AC6: =H6*AB6 -> 0 | AD6: =AC6*7.75 -> 0 | AF6: 已入系统 | AG6: B | AH6: 东莞 | AN6: =AM6-H6 -> -16
A7: 46163 | B7: Ultra Pro | C7: 美国 | D7: 签办 | E7: PO-26052001 | F7: 1126155-US | G7: PTE 圆型游戏机-EN-US | H7: 28 | K7: =L7-14 -> #N/A | L7: =VLOOKUP($F7,总排期!$F:$U,6,0) -> #N/A | P7: =VLOOKUP($F7,总排期!$F:$U,11,0) -> #N/A | R7: 7/15寄出28PCS | T7: 46223 | V7: =VLOOKUP($F7,总排期!$F:$U,14,0) -> #N/A | W7: =VLOOKUP($F7,总排期!$F:$U,15,0) -> #N/A | X7: =VLOOKUP($F7,总排期!$F:$U,16,0) -> #N/A | Y7: DONGGUAN 07/2026 EN | Z7: Flash - ZPE001A(EN) MCU - ZPE001A | AA7: 带电，缩小版包装（无翻盖）。外箱增加上下平咭 | AB7: 0 | AC7: =H7*AB7 -> 0 | AD7: =AC7*7.75 -> 0 | AF7: 已入系统 | AG7: B | AH7: 邵阳 | AI7: 系统出单 | AJ7: OK | AL7: 46210 | AN7: =AM7-H7 -> -28
A8: 45999 | B8: Pillowtex - Brazil | C8: 巴西（葡萄牙） | D8: 签办 | E8: PO-25120501 | F8: 3325110 | G8: 四角星抢答器 BR | H8: 6 | K8: =L8-14 -> 46209 | L8: =VLOOKUP($F8,总排期!$F:$U,6,0) -> 46223 | P8: =VLOOKUP($F8,总排期!$F:$U,11,0) -> 46192 | Q8: 46213 | R8: 7/10寄出 | T8: 46224 | V8: =VLOOKUP($F8,总排期!$F:$U,14,0) -> 46178 | W8: =VLOOKUP($F8,总排期!$F:$U,15,0) -> 1/29收到包装 | X8: =VLOOKUP($F8,总排期!$F:$U,16,0) -> 1/21确认箱唛，1/14确认移印 | Y8: 260701BR | Z8: Flash: ZPT012A(BR) MCU: ZPT001D | AA8: 带电，新包装 | AB8: 0 | AC8: =H8*AB8 -> 0 | AD8: =AC8*7.75 -> 0 | AF8: 已入系统 | AG8: B | AH8: 邵阳 | AI8: 系统出单 | AJ8: OK | AL8: OK | AM8: 6 | AN8: =AM8-H8 -> 0 | AS8: 46211
A9: 46083 | B9: Modell & Hobby | C9: 匈牙利 | D9: 签办 | E9: PO-26022701 | F9: 4526146 | G9: 蓝精灵-HU | H9: 6 | K9: =L9-14 -> #N/A | L9: =VLOOKUP($F9,总排期!$F:$U,6,0) -> #N/A | P9: =VLOOKUP($F9,总排期!$F:$U,11,0) -> #N/A | R9: 7/15寄出4PCS | T9: 46223 | V9: =VLOOKUP($F9,总排期!$F:$U,14,0) -> #N/A | W9: =VLOOKUP($F9,总排期!$F:$U,15,0) -> #N/A | X9: =VLOOKUP($F9,总排期!$F:$U,16,0) -> #N/A | Y9: 261821HU | Z9: PCBA: ZZT005A(HU) | AA9: 带电，匈牙利包装 | AB9: 0 | AC9: =H9*AB9 -> 0 | AD9: =AC9*7.75 -> 0 | AF9: 已入系统 | AG9: B | AH9: 新邵 | AI9: 系统出单 | AJ9: OK | AL9: OK | AM9: 6 | AN9: =AM9-H9 -> 0 | AS9: 46213
A10: 46161 | B10: Talent Show | C10: 克罗地亚 | D10: 签办 | E10: PO-26051803 | F10: 4724113 | G10: 圆形灯-CR | H10: 3 | K10: =L10-14 -> #N/A | L10: =VLOOKUP($F10,总排期!$F:$U,6,0) -> #N/A | P10: =VLOOKUP($F10,总排期!$F:$U,11,0) -> #N/A | R10: 7/20寄出 | T10: 46225 | V10: =VLOOKUP($F10,总排期!$F:$U,14,0) -> #N/A | W10: =VLOOKUP($F10,总排期!$F:$U,15,0) -> #N/A | X10: =VLOOKUP($F10,总排期!$F:$U,16,0) -> #N/A | Y10: 261821HR | Z10: CR Flash: AMSFX032BHX-011 MCU: AM32A070A-021 | AA10: 不带电，克罗地亚包装 | AB10: 0 | AC10: =H10*AB10 -> 0 | AD10: =AC10*7.75 -> 0 | AF10: 已入系统 | AG10: B | AH10: 邵阳 | AI10: 系统出单 | AJ10: OK | AL10: 46210 | AM10: 3 | AN10: =AM10-H10 -> 0
A11: 46080 | B11: Orbico | C11: 波兰 | D11: 签办 | E11: PO-26022601 | F11: 1426155 | G11: PTE 圆型游戏机- PL | H11: 7 | K11: =L11-14 -> 46213 | L11: =VLOOKUP($F11,总排期!$F:$U,6,0) -> 46227 | P11: =VLOOKUP($F11,总排期!$F:$U,11,0) -> 46219 | R11: 7/17寄出15PCS退回，7/21寄出7PCS | T11: 46227 | V11: =VLOOKUP($F11,总排期!$F:$U,14,0) -> 0 | W11: =VLOOKUP($F11,总排期!$F:$U,15,0) -> 4/2确认包装 | X11: =VLOOKUP($F11,总排期!$F:$U,16,0) -> 4/2确认箱唛移印 | Y11: 261821PL | Z11: Flash: ZPE009A(PL) MCU: ZPE001A | AA11: 带电，波兰新包装 | AB11: 0 | AC11: =H11*AB11 -> 0 | AD11: =AC11*7.75 -> 0 | AF11: 已入系统 | AG11: B | AH11: 邵阳 | AI11: 系统出单 | AJ11: OK | AL11: 46214 | AM11: 18 | AN11: =AM11-H11 -> 11 | AS11: 46210
A12: 46080 | B12: Orbico | C12: 波兰 | D12: 签办 | E12: PO-26022602 | F12: 1426169 | G12: 超级精灵球- PL | H12: 15 | K12: =L12-14 -> 46213 | L12: =VLOOKUP($F12,总排期!$F:$U,6,0) -> 46227 | P12: =VLOOKUP($F12,总排期!$F:$U,11,0) -> 46220 | R12: 7/22寄出 | T12: 46230 | V12: =VLOOKUP($F12,总排期!$F:$U,14,0) -> 46196 | W12: =VLOOKUP($F12,总排期!$F:$U,15,0) -> 5/21确认彩盒,7/3确认说明书 | X12: =VLOOKUP($F12,总排期!$F:$U,16,0) -> 5/25确认箱，5/21确认移印 | Y12: 261821PL | Z12: PCBA: ZPU003A(PL) | AA12: 带电，波兰新包装 | AB12: 0 | AC12: =H12*AB12 -> 0 | AD12: =AC12*7.75 -> 0 | AF12: 已入系统 | AG12: B | AH12: 东莞 | AN12: =AM12-H12 -> -15
A13: 46164 | B13: CAFFARO - Argentina | C13: 阿根廷 | D13: 大货办+签办 | E13: PO-26052103 | F13: 5226146 | G13: 蓝精灵-LA | H13: 8 | K13: =L13-14 -> 46216 | L13: =VLOOKUP($F13,总排期!$F:$U,6,0) -> 46230 | P13: =VLOOKUP($F13,总排期!$F:$U,11,0) -> 46219 | R13: 7/21寄出5PCS，7/29寄出3PCS | T13: 46227 | V13: =VLOOKUP($F13,总排期!$F:$U,14,0) -> 46197 | W13: =VLOOKUP($F13,总排期!$F:$U,15,0) -> 6/10确认文档 | X13: =VLOOKUP($F13,总排期!$F:$U,16,0) -> 6/1确认箱唛移印 | Y13: 261821ES | Z13: PCBA: ZZT010A(LA) | AA13: 西班牙语 阿根廷（西班牙）包装，带电（用客指定 Vinnic 电池） | AB13: 0 | AC13: =H13*AB13 -> 0 | AD13: =AC13*7.75 -> 0 | AF13: 已入系统 | AG13: B | AH13: 新邵 | AI13: 系统出单 | AJ13: 7月7号已交5535 | AL13: OK | AM13: 12 | AN13: =AM13-H13 -> 4
A14: 46142 | B14: Talent Show | C14: 克罗地亚 | D14: 大货办+签办 | E14: PO-26042901 | F14: 4726146 | G14: 蓝精灵-CR | H14: 4 | K14: =L14-14 -> 46217 | L14: =VLOOKUP($F14,总排期!$F:$U,6,0) -> 46231 | P14: =VLOOKUP($F14,总排期!$F:$U,11,0) -> 46220 | R14: 7/15寄出4PCS | T14: 46223 | V14: =VLOOKUP($F14,总排期!$F:$U,14,0) -> 46198 | W14: =VLOOKUP($F14,总排期!$F:$U,15,0) -> 4/30确认文档 | X14: =VLOOKUP($F14,总排期!$F:$U,16,0) -> 5/6确认箱唛移印 | Y14: 261821HR | Z14: PCBA: ZZT008A(CR) | AA14: 带电，克罗地亚包装 | AB14: 0 | AC14: =H14*AB14 -> 0 | AD14: =AC14*7.75 -> 0 | AF14: 已入系统 | AG14: B | AH14: 新邵 | AI14: 系统出单 | AJ14: 7月10号交 | AL14: OK | AM14: 4 | AN14: =AM14-H14 -> 0
A15: 46169 | B15: Proludis Giocattoli - Italy | C15: 意大利 | D15: 大货办+签办 | E15: PO-26052201 | F15: 3226159 | G15: 新款五角星-IT | H15: 8 | K15: =L15-14 -> 46238 | L15: =VLOOKUP($F15,总排期!$F:$U,6,0) -> 46252 | P15: =VLOOKUP($F15,总排期!$F:$U,11,0) -> 46234 | R15: 7/30寄出2PCS，8/5补6PCS | T15: 46238 | V15: =VLOOKUP($F15,总排期!$F:$U,14,0) -> 46177 | W15: =VLOOKUP($F15,总排期!$F:$U,15,0) -> 6/3确认文档 | X15: =VLOOKUP($F15,总排期!$F:$U,16,0) -> 6/15确认箱唛及移印 | Y15: 262171IT | Z15: FOF Ultimate Flash: ZFU009A(IT)，MCU: ZFU001A | AA15: 带电，意大利包装 | AB15: 0 | AC15: =H15*AB15 -> 0 | AD15: =AC15*7.75 -> 0 | AF15: 已入系统 | AG15: B | AH15: 邵阳 | AI15: 系统出单 | AM15: 8 | AN15: =AM15-H15 -> 0
A16: 46121 | B16: Sunman - Turkey | C16: 土耳其 | D16: 大货办+签办 | E16: PO-26040801 | F16: 3626146 | G16: 蓝精灵-TU | H16: 6 | K16: =L16-14 -> 46238 | L16: =VLOOKUP($F16,总排期!$F:$U,6,0) -> 46252 | P16: =VLOOKUP($F16,总排期!$F:$U,11,0) -> 46234 | R16: 7/28寄出3PCS，8/5补3PCS | T16: 46238 | V16: =VLOOKUP($F16,总排期!$F:$U,14,0) -> 46203 | W16: =VLOOKUP($F16,总排期!$F:$U,15,0) -> 4/9确认文档 | X16: =VLOOKUP($F16,总排期!$F:$U,16,0) -> 5/14确认移印，5/8箱唛确认 | Y16: 261821TU | Z16: Magic Tim PCBA: ZZT012A(TU) | AA16: 带电，土耳其包装 | AB16: 0 | AC16: =H16*AB16 -> 0 | AD16: =AC16*7.75 -> 0 | AF16: 已入系统 | AG16: B | AH16: 新邵 | AI16: 系统出单 | AM16: 12 | AN16: =AM16-H16 -> 6
A17: 46091 | B17: Ultra Pro | C17: 美国 | D17: 签办 | E17: PO-26030904 | F17: 1126164- US | G17: 迪士尼米奇头-EN-US | H17: 12 | K17: =L17-14 -> 46223 | L17: =VLOOKUP($F17,总排期!$F:$U,6,0) -> 46237 | P17: =VLOOKUP($F17,总排期!$F:$U,11,0) -> 46233 | R17: 签办工程已安排，大货办需要2箱 | T17: 46227 | V17: =VLOOKUP($F17,总排期!$F:$U,14,0) -> 46206 | W17: =VLOOKUP($F17,总排期!$F:$U,15,0) -> 6/3收到包装 | X17: =VLOOKUP($F17,总排期!$F:$U,16,0) -> 5/11确认箱唛,6/5确认移印 | Y17: DONGGUAN 07/2026 EN | Z17: PCBA: ZDG001A(EN) | AA17: 带电，喷金属油+闪粉 -外箱增加上下平咭，客ITEM号：10307 | AB17: 0 | AC17: =H17*AB17 -> 0 | AD17: =AC17*7.75 -> 0 | AF17: 已入系统 | AG17: B | AH17: 新邵 | AN17: =AM17-H17 -> -12
A18: 46157 | B18: Educa | C18: 西班牙 | D18: 大货办+签办 | E18: PO-26051503 | F18: 1226168 | G18: 涡轮四角星- ES | H18: 12 | K18: =L18-14 -> 46223 | L18: =VLOOKUP($F18,总排期!$F:$U,6,0) -> 46237 | P18: =VLOOKUP($F18,总排期!$F:$U,11,0) -> 46227 | R18: 需大货办2箱，要有正箱，签办7/27寄出4PCS | T18: 46233 | V18: =VLOOKUP($F18,总排期!$F:$U,14,0) -> 46193 | W18: =VLOOKUP($F18,总排期!$F:$U,15,0) -> 7/9确认彩盒，7/13确认说明书 | X18: =VLOOKUP($F18,总排期!$F:$U,16,0) -> 6/12确认箱唛,6/22确认移印 | Y18: 261821ES | Z18: Flash: AMSFX128DHS-P09 MCU: AM32A070A-050 | AA18: 带电，西班牙包装，客PO:73455 ,包装上增加一第客供贴纸 包装需要备品 2% | AB18: 0 | AC18: =H18*AB18 -> 0 | AD18: =AC18*7.75 -> 0 | AF18: 已入系统 | AG18: B | AH18: 新邵 | AI18: 系统出单 | AJ18: 7月16号开始交 | AM18: 18 | AN18: =AM18-H18 -> 6
A19: 46169 | B19: Proludis Giocattoli - Italy | C19: 意大利 | D19: 大货办+签办 | E19: PO-26052201 | F19: 3226169 | G19: 超级精灵球-IT | H19: 12 | K19: =L19-14 -> 46226 | L19: =VLOOKUP($F19,总排期!$F:$U,6,0) -> 46240 | P19: =VLOOKUP($F19,总排期!$F:$U,11,0) -> 46234 | R19: 8/1寄出 | T19: 46240 | V19: =VLOOKUP($F19,总排期!$F:$U,14,0) -> 46203 | W19: =VLOOKUP($F19,总排期!$F:$U,15,0) -> 5/4收到包装，7/3确认说明书 | X19: =VLOOKUP($F19,总排期!$F:$U,16,0) -> 6/15确认箱唛及移印 | Y19: 262171IT | Z19: PMK Ultimate PCBA: ZPU005A(IT) | AA19: 带电，意大利包装 | AB19: 0 | AC19: =H19*AB19 -> 0 | AD19: =AC19*7.75 -> 0 | AF19: 已入系统 | AG19: B | AH19: 东莞 | AN19: =AM19-H19 -> -12
A20: 46151 | B20: Toy Partner | C20: 西班牙 | D20: 大货办+签办 | E20: PO-26050701 | F20: 1226169 | G20: 超级精灵球-ES | H20: 12 | K20: =L20-14 -> 46227 | L20: =VLOOKUP($F20,总排期!$F:$U,6,0) -> 46241 | P20: =VLOOKUP($F20,总排期!$F:$U,11,0) -> 46231 | R20: 7/25 寄出 | T20: 46233 | V20: =VLOOKUP($F20,总排期!$F:$U,14,0) -> 46203 | W20: =VLOOKUP($F20,总排期!$F:$U,15,0) -> 5/28确认包装 | X20: =VLOOKUP($F20,总排期!$F:$U,16,0) -> 6/16确认箱唛，6/25确认移印 | Y20: 262171ES | Z20: PCBA: ZPU006A(ES) | AA20: 带电，西班牙包装 | AB20: 0 | AC20: =H20*AB20 -> 0 | AD20: =AC20*7.75 -> 0 | AF20: 已入系统 | AG20: B | AH20: 东莞 | AN20: =AM20-H20 -> -12
A21: 46161 | B21: Dexy | C21: 塞尔维亚 | D21: 大货办 | E21: PO-26051802 | F21: 3026146 | G21: 蓝精灵-SE | H21: 6 | K21: =L21-14 -> 46227 | L21: =VLOOKUP($F21,总排期!$F:$U,6,0) -> 46241 | P21: =VLOOKUP($F21,总排期!$F:$U,11,0) -> 46239 | R21: 7/25 寄出3PCS | T21: 46233 | V21: =VLOOKUP($F21,总排期!$F:$U,14,0) -> 6/25 | W21: =VLOOKUP($F21,总排期!$F:$U,15,0) -> 5/19确认文档 | X21: =VLOOKUP($F21,总排期!$F:$U,16,0) -> 5/26确认箱唛移印 | Y21: 261821SE | Z21: PCBA: ZZT007A(SE) | AA21: 带电，塞尔维亚包装 | AB21: 0 | AC21: =H21*AB21 -> 0 | AD21: =AC21*7.75 -> 0 | AF21: 已入系统 | AG21: B | AH21: 新邵 | AI21: 系统出单 | AJ21: 已交2240 | AM21: 6 | AN21: =AM21-H21 -> 0
A22: 46157 | B22: Educa | C22: 西班牙 | D22: 大货办+签办 | E22: PO-26051502 | F22: 1226157 | G22: 城市套装游戏机-ES | H22: 8 | K22: =L22-14 -> 46226 | L22: =VLOOKUP($F22,总排期!$F:$U,6,0) -> 46240 | P22: =VLOOKUP($F22,总排期!$F:$U,11,0) -> 46230 | R22: 需大货办2箱,8/7寄出，签办7/27寄出4PCS | T22: 46233 | V22: =VLOOKUP($F22,总排期!$F:$U,14,0) -> 46212 | W22: =VLOOKUP($F22,总排期!$F:$U,15,0) -> 6/5确认文档 | X22: =VLOOKUP($F22,总排期!$F:$U,16,0) -> 6/12确认箱唛,6/15确认移印 | Y22: 261821ES | Z22: Flash: AMSFX128DHS-P08 MCU: AM32A070A-051 | AA22: 带电，西班牙包装，客PO:73434 包装需要备品 2% | AB22: 0 | AC22: =H22*AB22 -> 0 | AD22: =AC22*7.75 -> 0 | AF22: 已入系统 | AG22: B | AH22: 新邵 | AN22: =AM22-H22 -> -8
A23: 46164 | B23: Golden Bear | C23: 英国 | E23: PO-26052202 | F23: 1125155- UK | G23: PTE 圆型游戏机-EN-UK | H23: 8 | I23: 6 | J23: =H23/I23 -> 1 | K23: =L23-14 -> 46237 | L23: =VLOOKUP($F23,总排期!$F:$U,6,0) -> 46251 | P23: 46251 | R23: 东莞寄2套，湖南8/1寄 6PCS | T23: 46240 | V23: =VLOOKUP($F23,总排期!$F:$U,14,0) -> 0 | W23: =VLOOKUP($F23,总排期!$F:$U,15,0) -> 6/15确认彩盒，拼图更新2026，6/24确认说明书 | X23: =VLOOKUP($F23,总排期!$F:$U,16,0) -> 6/25确认移印箱唛 | Y23: 262171EN | Z23: Flash: ZPE001A(EN) MCU: ZPE001A | AA23: 英国版-有盖版彩盒，带电池， x 4C双面游戏板(50CM)，包装需要使用FSC纸张（内卡/彩盒/说明书/拼图），请注意：外箱封一条长胶带密封纸箱。補回120pcs遊戲版給美國客戶 | AC23: 已入系统 | AD23: B | AE23: 邵阳 | AF23: 系统出单 | AG23: B | AH23: 邵阳 | AM23: 8 | AN23: =AM23-H23 -> 0
A24: 46091 | B24: Ultra Pro | C24: 美国 | D24: 签办 | E24: PO-26030905 | F24: 1126156- US | G24: 迪士尼游戏机-EN-US | H24: 18 | K24: =L24-14 -> 46232 | L24: =VLOOKUP($F24,总排期!$F:$U,6,0) -> 46246 | P24: =VLOOKUP($F24,总排期!$F:$U,11,0) -> 46233 | R24: 签办工程已安排，大货办需要3箱 | T24: 46223 | V24: =VLOOKUP($F24,总排期!$F:$U,14,0) -> 46205 | W24: =VLOOKUP($F24,总排期!$F:$U,15,0) -> 6/3收到包装 | X24: =VLOOKUP($F24,总排期!$F:$U,16,0) -> 5/11确认箱唛,6/5确认移印 | Y24: DONGGUAN 06/2026 EN | Z24: Flash: ZDT001A(EN) MCU: ZDT001A | AA24: 带电，美国US包装 -外箱增加上下平咭 客ITEM:10308 | AB24: 0 | AC24: =H24*AB24 -> 0 | AD24: =AC24*7.75 -> 0 | AG24: B | AH24: 新邵 | AN24: =AM24-H24 -> -18
A25: 46136 | B25: GP France | C25: 法国 | D25: 大货办+签办 | E25: PO-26042401 | F25: 1026156 | G25: 迪士尼游戏机-FR | H25: 12 | K25: =L25-14 -> 46230 | L25: =VLOOKUP($F25,总排期!$F:$U,6,0) -> 46244 | P25: =VLOOKUP($F25,总排期!$F:$U,11,0) -> 46232 | R25: 8/6 寄出 | T25: 46244 | V25: =VLOOKUP($F25,总排期!$F:$U,14,0) -> 46204 | W25: =VLOOKUP($F25,总排期!$F:$U,15,0) -> 6/26确认文档 | X25: =VLOOKUP($F25,总排期!$F:$U,16,0) -> 6/25确认移印箱唛 | Y25: 262171FR | Z25: IC Factory part no. Flash: ZDT002A(FR) MCU: ZDT001A | AA25: 带电，GP法国包装 | AB25: 0 | AC25: =H25*AB25 -> 0 | AD25: =AC25*7.75 -> 0 | AG25: B | AH25: 东莞 | AN25: =AM25-H25 -> -12
A26: 46163 | B26: Asmodee - CZ | C26: 捷克共和国 | D26: 签办 | E26: PO-26052004 | F26: 3526107 | G26: 足球-CZ | H26: 3 | K26: =L26-14 -> 46230 | L26: =VLOOKUP($F26,总排期!$F:$U,6,0) -> 46244 | P26: =VLOOKUP($F26,总排期!$F:$U,11,0) -> 46251 | R26: 8/6 寄出 | T26: 46244 | V26: =VLOOKUP($F26,总排期!$F:$U,14,0) -> 46198 | W26: =VLOOKUP($F26,总排期!$F:$U,15,0) -> 5/22确认包装 | X26: =VLOOKUP($F26,总排期!$F:$U,16,0) -> 7/16确认箱唛移印 | Y26: 262171CZ | Z26: Flash: ZFZ007C(CZ) MCU: ZFZ001A | AA26: 带电，捷克包装 | AB26: 0 | AC26: =H26*AB26 -> 0 | AD26: =AC26*7.75 -> 0 | AF26: 已入系统 | AG26: B | AH26: 新邵 | AI26: 系统出单 | AN26: =AM26-H26 -> -3
A27: 260 | B27: Toy Partner | C27: 西班牙（葡萄牙语） | D27: 大货办+签办 | E27: PO-26050702 | F27: 3326103 | G27: 红色比卡超-PO | H27: 8 | K27: =L27-14 -> 46230 | L27: =VLOOKUP($F27,总排期!$F:$U,6,0) -> 46244 | P27: =VLOOKUP($F27,总排期!$F:$U,11,0) -> 46231 | R27: 湖南8/5寄4PCS，8/13寄4PCS | T27: 46244 | V27: =VLOOKUP($F27,总排期!$F:$U,14,0) -> 46207 | W27: =VLOOKUP($F27,总排期!$F:$U,15,0) -> 7/9确认包装 | X27: =VLOOKUP($F27,总排期!$F:$U,16,0) -> 6/16确认箱唛，6/25确认移印 | Y27: 262171PO | Z27: PCBA: ZPK041A(PO) | AA27: 带电，（无隔电片） （葡萄牙语版包装） | AB27: 0 | AC27: =H27*AB27 -> 0 | AD27: =AC27*7.75 -> 0 | AF27: 已入系统 | AG27: B | AH27: 邵阳 | AI27: 系统出单 | AM27: 4 | AN27: =AM27-H27 -> -4
A28: 46169 | B28: Proludis Giocattoli - Italy | C28: 意大利 | D28: 大货办+签办 | E28: PO-26052201 | F28: 3226164 | G28: 迪士尼米奇头-IT | H28: 10 | K28: =L28-14 -> 46237 | L28: =VLOOKUP($F28,总排期!$F:$U,6,0) -> 46251 | P28: =VLOOKUP($F28,总排期!$F:$U,11,0) -> 46234 | R28: 8/8寄出 4PCS | S28: 欠6PCS | T28: 46251 | V28: =VLOOKUP($F28,总排期!$F:$U,14,0) -> 46213 | W28: =VLOOKUP($F28,总排期!$F:$U,15,0) -> 7/14确认包装 | X28: =VLOOKUP($F28,总排期!$F:$U,16,0) -> 6/15确认箱唛及移印 | Y28: 262171IT | Z28: Disney Guess PCBA: ZDG005A(IT) | AA28: 带电，意大利包装 | AB28: 0 | AC28: =H28*AB28 -> 0 | AD28: =AC28*7.75 -> 0 | AF28: 已入系统 | AG28: B | AH28: 新邵 | AN28: =AM28-H28 -> -10
A29: 46121 | B29: Sunman - Romania | C29: 罗马尼亚 | D29: 大货办+签办 | E29: PO-26040802 | F29: 3826164 | G29: 迪士尼米奇头-RO | H29: 12 | K29: =L29-14 -> 46234 | L29: =VLOOKUP($F29,总排期!$F:$U,6,0) -> 46248 | P29: =VLOOKUP($F29,总排期!$F:$U,11,0) -> 46234 | R29: 8/12寄出 5PCS，8/15寄6PCS,，客人退回4PCS | T29: 46251 | V29: =VLOOKUP($F29,总排期!$F:$U,14,0) -> 46210 | W29: =VLOOKUP($F29,总排期!$F:$U,15,0) -> 7/3确认彩盒，7/10确认说明书 | X29: =VLOOKUP($F29,总排期!$F:$U,16,0) -> 6/17确认箱唛，移印待确认 | Y29: 262171RO | Z29: IC Factory part no. PCBA: ZDG004A(RO) | AA29: 带电，罗马尼亚包装 | AB29: 0 | AC29: =H29*AB29 -> 0 | AD29: =AC29*7.75 -> 0 | AF29: 已入系统 | AG29: B | AH29: 新邵 | AN29: =AM29-H29 -> -12
A30: 46111 | B30: Gialamas - Greece | C30: 希腊 | D30: 大货办+签办 | E30: PO-26032603 | F30: 1326103 | G30: 红色比卡超-GR | H30: 12 | K30: =L30-14 -> 46237 | L30: =VLOOKUP($F30,总排期!$F:$U,6,0) -> 46251 | P30: =VLOOKUP($F30,总排期!$F:$U,11,0) -> 46240 | R30: 8/10寄出 5PCS 8/14寄出6PCS | T30: 46251 | V30: =VLOOKUP($F30,总排期!$F:$U,14,0) -> 46218 | W30: =VLOOKUP($F30,总排期!$F:$U,15,0) -> 7/8确认包装 | X30: =VLOOKUP($F30,总排期!$F:$U,16,0) -> 6/11确认移印，7/1确认箱唛 | Y30: 262171GR | Z30: Pokemon Kanto GR PCBA - ZPK040A(GR) | AA30: 带电，无隔电片， 希腊包装 | AB30: 0 | AC30: =H30*AB30 -> 0 | AD30: =AC30*7.75 -> 0 | AF30: 已入系统 | AG30: B | AH30: 邵阳 | AI30: 系统出单 | AM30: 6 | AN30: =AM30-H30 -> -6
A31: 46111 | B31: Gialamas - Greece | C31: 希腊 | D31: 大货办+签办 | E31: PO-26032603 | F31: 1326164 | G31: 迪士尼米奇头-GR | H31: 12 | K31: =L31-14 -> 46239 | L31: =VLOOKUP($F31,总排期!$F:$U,6,0) -> 46253 | P31: =VLOOKUP($F31,总排期!$F:$U,11,0) -> 46240 | R31: 8/12寄出 5PCS | S31: 欠6PCS | T31: 46251 | V31: =VLOOKUP($F31,总排期!$F:$U,14,0) -> 46218 | W31: =VLOOKUP($F31,总排期!$F:$U,15,0) -> 7/6确认彩盒，7/10确认说明书 | X31: =VLOOKUP($F31,总排期!$F:$U,16,0) -> 6/11确认移印，7/1确认箱唛 | Y31: 262171GR | Z31: Disney Guess GR PCBA - ZDG002A(GR) | AA31: 带电， 希腊包装，喷金属油+闪粉 | AB31: 0 | AC31: =H31*AB31 -> 0 | AD31: =AC31*7.75 -> 0 | AF31: 已入系统 | AG31: B | AH31: 新邵 | AN31: =AM31-H31 -> -12
A32: 46111 | B32: Gialamas - Greece | C32: 希腊 | D32: 签办 | E32: PO-26032603 | F32: 1326110 | G32: 四角星抢答器-GR | H32: 12 | K32: =L32-14 -> 46237 | L32: =VLOOKUP($F32,总排期!$F:$U,6,0) -> 46251 | P32: =VLOOKUP($F32,总排期!$F:$U,11,0) -> 46240 | R32: 8/16寄出 | V32: =VLOOKUP($F32,总排期!$F:$U,14,0) -> 46213 | W32: =VLOOKUP($F32,总排期!$F:$U,15,0) -> 6/25确认文档 | X32: =VLOOKUP($F32,总排期!$F:$U,16,0) -> 6/11确认移印，7/1确认箱唛 | Y32: 262171GR | Z32: Pokemon Trainer Trivia GR Flash - ZPT013A(GR) MCU: ZPT001D | AA32: 带电， 希腊包装,留意面壳LGOG移印跟彩盒LOGO一样 | AB32: 0 | AC32: =H32*AB32 -> 0 | AD32: =AC32*7.75 -> 0 | AF32: 已入系统 | AG32: B | AH32: 邵阳 | AN32: =AM32-H32 -> -12
A33: 46121 | B33: Sunman - Turkey | C33: 土耳其 | D33: 大货办+签办 | E33: PO-26040801 | F33: 3626164 | G33: 迪士尼米奇头-TU | H33: 6 | K33: =L33-14 -> 46240 | L33: =VLOOKUP($F33,总排期!$F:$U,6,0) -> 46254 | P33: =VLOOKUP($F33,总排期!$F:$U,11,0) -> 46234 | R33: 8/1寄出4PCS测试办，8/11寄测试办2PCS | T33: 46251 | V33: =VLOOKUP($F33,总排期!$F:$U,14,0) -> 46218 | W33: =VLOOKUP($F33,总排期!$F:$U,15,0) -> 7/6确认彩盒，7/13确认说明书 | X33: =VLOOKUP($F33,总排期!$F:$U,16,0) -> 移印待确认，5/8箱唛确认 | Y33: 261821TU | Z33: Disney Guess PCBA : ZDG003A(TU) | AA33: 带电，喷金属油+闪粉，土耳其包装 | AB33: 0 | AC33: =H33*AB33 -> 0 | AD33: =AC33*7.75 -> 0 | AF33: 已入系统 | AG33: B | AH33: 新邵 | AN33: =AM33-H33 -> -6
A34: 46151 | B34: Toy Partner | C34: 西班牙 | D34: 大货办+签办 | E34: PO-26050703 | F34: 1226156 | G34: 迪士尼游戏机-ES | H34: 12 | K34: =L34-14 -> 46237 | L34: =VLOOKUP($F34,总排期!$F:$U,6,0) -> 46251 | P34: =VLOOKUP($F34,总排期!$F:$U,11,0) -> 46248 | R34: 8/14寄出 | V34: =VLOOKUP($F34,总排期!$F:$U,14,0) -> 46210 | W34: =VLOOKUP($F34,总排期!$F:$U,15,0) -> 6/23确认文档 | X34: =VLOOKUP($F34,总排期!$F:$U,16,0) -> 6/22确认箱唛，6/25确认移印 | Y34: 262171ES | Z34: IC Factory part no. Flash: ZDT004A(ES) MCU: ZDT001A | AA34: 带电，西班牙包装 | AB34: 0 | AC34: =H34*AB34 -> 0 | AD34: =AC34*7.75 -> 0 | AG34: B | AH34: 新邵 | AN34: =AM34-H34 -> -12
A35: 46148 | B35: GP Italy | C35: 意大利 | D35: 大货办+签办 | E35: PO-26050501 | F35: 3226156 | G35: 迪士尼游戏机-IT | H35: 12 | K35: =L35-14 -> #VALUE! | L35: =VLOOKUP($F35,总排期!$F:$U,6,0) -> 待复 | P35: =VLOOKUP($F35,总排期!$F:$U,11,0) -> 46249 | V35: =VLOOKUP($F35,总排期!$F:$U,14,0) -> 46213 | W35: =VLOOKUP($F35,总排期!$F:$U,15,0) -> 欠 | X35: =VLOOKUP($F35,总排期!$F:$U,16,0) -> 6/3确认移印箱唛 | Y35: 262171IT | Z35: Flash: ZDT003A(IT) MCU: ZDT001A | AA35: 带电，GP意大利包装 | AB35: 0 | AC35: =H35*AB35 -> 0 | AD35: =AC35*7.75 -> 0 | AG35: B | AH35: 新邵 | AN35: =AM35-H35 -> -12
A36: 46189 | B36: Flat River | C36: 美国 | D36: 大货办+签办 | E36: PO-26061101 | F36: 1125103- US-MIL | G36: 红色比卡超EN-US | H36: 6 | K36: =L36-14 -> 46240 | L36: =VLOOKUP($F36,总排期!$F:$U,6,0) -> 46254 | P36: =VLOOKUP($F36,总排期!$F:$U,11,0) -> 46251 | V36: =VLOOKUP($F36,总排期!$F:$U,14,0) -> 46208 | W36: =VLOOKUP($F36,总排期!$F:$U,15,0) -> 7/15确认包装 | X36: =VLOOKUP($F36,总排期!$F:$U,16,0) -> 7/24确认箱唛，7/13确认移印，7/27确认邮包盒唛头 | Z36: PKM Kanto: ZPK001B(EN) | AA36: 带电，无隔电片， 新包装（彩盒+邮包盒） | AB36: 0 | AC36: =H36*AB36 -> 0 | AD36: =AC36*7.75 -> 0 | AF36: 已入系统 | AG36: B | AH36: 邵阳 | AI36: 系统出单 | AN36: =AM36-H36 -> -6
A37: 46189 | B37: Flat River | C37: 美国 | D37: 大货办+签办 | E37: PO-26061101 | F37: 1125106- US-MIL | G37: 紫波比卡超EN-US | H37: 6 | K37: =L37-14 -> 46240 | L37: =VLOOKUP($F37,总排期!$F:$U,6,0) -> 46254 | P37: =VLOOKUP($F37,总排期!$F:$U,11,0) -> 46251 | V37: =VLOOKUP($F37,总排期!$F:$U,14,0) -> 46208 | W37: =VLOOKUP($F37,总排期!$F:$U,15,0) -> 7/15确认包装 | X37: =VLOOKUP($F37,总排期!$F:$U,16,0) -> 7/24确认箱唛，7/13确认移印，7/27确认邮包盒唛头 | Z37: PKM Ash: ZPK013A(EN) | AA37: 带电，无隔电片， 新包装（彩盒+邮包盒） | AB37: 0 | AC37: =H37*AB37 -> 0 | AD37: =AC37*7.75 -> 0 | AF37: 已入系统 | AG37: B | AH37: 邵阳 | AI37: 系统出单 | AN37: =AM37-H37 -> -6
A38: 46189 | B38: Flat River | C38: 美国 | D38: 大货办+签办 | E38: PO-26061101 | F38: 1125117- US-MIL | G38: 比卡超手表 EN-US | H38: 6 | K38: =L38-14 -> 46240 | L38: =VLOOKUP($F38,总排期!$F:$U,6,0) -> 46254 | P38: =VLOOKUP($F38,总排期!$F:$U,11,0) -> 46251 | V38: =VLOOKUP($F38,总排期!$F:$U,14,0) -> 46208 | W38: =VLOOKUP($F38,总排期!$F:$U,15,0) -> 说明书翻单26031303，彩盒7/15更新 | X38: =VLOOKUP($F38,总排期!$F:$U,16,0) -> 7/24确认箱唛，7/13确认移印，7/27确认邮包盒唛头 | Z38: PKM Mission:ZPD001A(EN) | AA38: 不带电， 新包装（彩盒+邮包盒） | AB38: 0 | AC38: =H38*AB38 -> 0 | AD38: =AC38*7.75 -> 0 | AF38: 已入系统 | AG38: B | AH38: 邵阳 | AI38: 系统出单 | AN38: =AM38-H38 -> -6
A39: 46189 | B39: Flat River | C39: 美国 | D39: 大货办+签办 | E39: PO-26061101 | F39: 1125118- US-MIL | G39: 金属色比卡超 EN-US | H39: 6 | K39: =L39-14 -> 46240 | L39: =VLOOKUP($F39,总排期!$F:$U,6,0) -> 46254 | P39: =VLOOKUP($F39,总排期!$F:$U,11,0) -> 46251 | V39: =VLOOKUP($F39,总排期!$F:$U,14,0) -> 46208 | W39: =VLOOKUP($F39,总排期!$F:$U,15,0) -> 7/15确认包装 | X39: =VLOOKUP($F39,总排期!$F:$U,16,0) -> 7/24确认箱唛，7/13确认移印，7/27确认邮包盒唛头 | Z39: PKM Legacy: ZPK017A(EN) | AA39: 带电，无隔电片， 新包装（彩盒+邮包盒） | AB39: 0 | AC39: =H39*AB39 -> 0 | AD39: =AC39*7.75 -> 0 | AF39: 已入系统 | AG39: B | AH39: 邵阳 | AI39: 系统出单 | AN39: =AM39-H39 -> -6
A40: 46189 | B40: Flat River | C40: 美国 | D40: 大货办+签办 | E40: PO-26061101 | F40: 1125155- US-MIL | G40: PTE 圆型游戏机EN-US | H40: 6 | K40: =L40-14 -> 46240 | L40: =VLOOKUP($F40,总排期!$F:$U,6,0) -> 46254 | P40: =VLOOKUP($F40,总排期!$F:$U,11,0) -> 46251 | V40: =VLOOKUP($F40,总排期!$F:$U,14,0) -> 46208 | W40: =VLOOKUP($F40,总排期!$F:$U,15,0) -> 7/15确认包装 | X40: =VLOOKUP($F40,总排期!$F:$U,16,0) -> 7/24确认箱唛，7/13确认移印，7/27确认邮包盒唛头 | Z40: PKM Expert: MCU: ZPE001A + Flash: ZPE001A(EN) | AA40: 带电， 新包装（彩盒+邮包盒） | AB40: 0 | AC40: =H40*AB40 -> 0 | AD40: =AC40*7.75 -> 0 | AF40: 已入系统 | AG40: B | AH40: 邵阳 | AI40: 系统出单 | AN40: =AM40-H40 -> -6
...

Sheet 已走货
A1: 接单期 | B1: 第三客户名称 | C1: 国家 | D1: 第三方PO | E1: Cust. PO NO. | F1: ITEM | G1: 货名 | H1: 数量 | I1: 装箱数 | J1: 总箱数 | K1: 出货期 | L1: 验货期 | M1: 第三方验货期 | N1: 是否安排自检 | O1: 船期SO | P1: 计划走货期 | Q1: 追客新资料期 | R1: 客贴纸 | S1: 客供物料（IC） | T1: 包装核对 | U1: 箱唛资料 | V1: 日期码 | W1: PCBA/MCU/Flash IC | X1: 备注 | Y1: 单价(USD) | Z1: 金额USD | AA1: 金额HKD | AB1: 发票号 | AC1: 是否入系统 | AD1: 做货车间 | AE1: 生产车间 | AF1: 下单明细 | AG1: 送回数量 | AH1: 欠数 | AI1: 纸箱 | AJ1: 贴纸 | AK1: 预计完成时间 | AL1: 彩盒样品寄出时间 | AM1: 说明书样品寄出时间 | AN1: 彩盒打稿OK时间 | AO1: 说明书打稿OK时间 | AP1: 整体签板 | AQ1: 收到包装日期
A2: 45943 | B2: Asmodee Germany | C2: 德国 | E2: PO-25101302 | F2: 1825103 | G2: 红色比卡超 DE | H2: 6000 | I2: 6 | J2: 1000 | K2: 46027 | L2: OK | P2: 46023 | S2: 45962 | T2: 翻单25050602 | U2: 10/24确认箱唛移印 | V2: 253601DE | W2: PCBA: ZPK009A(DE) | X2: 带电,带隔电片 | Y2: 2.119 | Z2: 12714 | AA2: 98533.5 | AB2: FH20220282 | AC2: 已入系统 | AD2: B | AE2: 邵阳 | AF2: 系统出单 | AG2: 6000 | AH2: 0
A3: 45943 | B3: Asmodee Germany | C3: 德国 | E3: PO-25101302 | F3: 1825155 | G3: PTE 比卡超圆形游戏机 DE | H3: 5004 | I3: 6 | J3: 834 | K3: 46027 | L3: OK | P3: 46023 | S3: 45954 | T3: 翻单25050602 | U3: 10/24确认箱唛移印 | V3: 253601DE | W3: MCU: ZPE001A Flash: ZPE003A(DE) | X3: 带电 | Y3: 4.516 | Z3: 22598.06 | AA3: 175134.97 | AB3: FH20220282 | AC3: 已入系统 | AD3: B | AE3: 邵阳 | AF3: 系统出单 | AG3: 5004 | AH3: 0
A4: 45954 | B4: GP France | C4: 法国 | E4: PO-25101601 | F4: 1025103 | G4: 红色比卡超 | H4: 4002 | I4: 6 | J4: 667 | K4: 46009 | L4: OK | P4: 46010 | S4: 45975 | T4: 翻单25041905彩盒/说明书新档案11/20确认 | U4: 11/13确认箱唛移印 | V4: 253601FR | W4: IC Factory part no. PCBA: ZPK004A(FR) | X4: 带电池，包装上印有Triman标志，包装：GP法国pkg + I/S（带法国标志），带隔电片 | Y4: 2.119 | Z4: 8480.24 | AA4: 65721.86 | AB4: FH20220283 | AC4: 已入系统 | AD4: B | AE4: 邵阳 | AF4: 系统出单 | AG4: 4002 | AH4: 0
A5: 45954 | B5: GP France | C5: 法国 | E5: PO-25101601 | F5: 1025117 | G5: 比卡超手表 | H5: 3000 | I5: 6 | J5: 500 | K5: 46009 | L5: OK | P5: 46010 | S5: 45975 | T5: 翻单25041905地图/彩盒及说明书新档案11/20确认 | U5: 11/13确认箱唛移印 | V5: 253601FR | W5: IC Factory part no.: PCBA: ZPD002A(FR | X5: 不带电池，包装上印有Triman标志，包装：GP法国pkg + I/S（带法国标志） | Y5: 2.656 | Z5: 7968 | AA5: 61752 | AB5: FH20220283 | AC5: 已入系统 | AD5: B | AE5: 邵阳 | AF5: 系统出单 | AG5: 3000 | AH5: 0
A6: 45954 | B6: GP France | C6: 法国 | E6: PO-25101601 | F6: 1025155 | G6: PTE 圆型游戏机 | H6: 8004 | I6: 6 | J6: 1334 | K6: 46009 | L6: OK | P6: 46010 | S6: 45975 | T6: 翻单25041905彩盒及拼图/说明书新档案11/20确认 | U6: 11/13确认箱唛移印 | V6: 253601FR | W6: IC Factory part no. MCU: ZPE001A Flash: ZPE002A(FR) | X6: 带电池，包装上印有Triman标志，包装：GP法国pkg + I/S（带法国标志） | Y6: 4.516 | Z6: 36146.06 | AA6: 280131.97 | AB6: FH20220283 | AC6: 已入系统 | AD6: B | AE6: 邵阳 | AF6: 系统出单 | AG6: 8004 | AH6: 0
A7: 45985 | B7: Target | C7: 美国 | E7: PO-25112401 | F7: 1123103- US-TAR | G7: 红色比卡超 EN-US | H7: 12600 | I7: 6 | J7: 2100 | K7: 46030 | L7: 46030 | P7: 46037 | S7: 45996 | T7: 翻单25052901 | U7: 12/11确认箱唛移印 | V7: DONGGUAN 01/2026 EN | W7: PCBA:ZPK001B(EN) | X7: 没有隔电片，带电，額外的貼紙(可移贴纸(2pcs)+ 胶袋包装)，MIC:带针咪头，有Try Me功能，外箱增加上下平咭 | Y7: 2.089 | Z7: 26321.4 | AA7: 203990.85 | AB7: FH20220284 | AC7: 已入系统 | AD7: B | AE7: 邵阳 | AF7: 系统出单 | AG7: 12600 | AH7: 0 | AJ7: OK
A8: 45968 | B8: GP Greece | C8: 希腊 | E8: PO-25110501 | F8: 1324138 | G8: 转盘游戏机 GR | H8: 5004 | I8: 6 | J8: 834 | K8: 46035 | L8: 46035 | P8: 46028 | S8: 45978 | T8: 翻单24062313 | U8: 11/20确认箱唛移印 | V8: 260061GR | W8: MCU: AM32A070A-042 Flash: AMSFX032CHX-031 | X8: 带电，包装希腊GP版 | Y8: 3.865 | Z8: 19340.46 | AA8: 149888.57 | AB8: FH20220285 | AC8: 已入系统 | AD8: B | AE8: 邵阳 | AF8: 系统出单 | AG8: 5004 | AH8: 0
A9: 45968 | B9: GP Greece | C9: 希腊 | E9: PO-25110502 | F9: 1325107 | G9: 足球 GR | H9: 6000 | I9: 6 | J9: 1000 | K9: 46035 | L9: 46035 | P9: 46028 | S9: 45978 | T9: 包装11/17确认 | U9: 移印工程跟进，11/20确认箱唛 | V9: 260061GR | W9: Flash: ZFZ014A(GE) MCU: ZFZ001A | X9: 带电，包装希腊GP版 | Y9: 3.912 | Z9: 23472 | AA9: 181908 | AB9: FH20220285 | AC9: 已入系统 | AD9: B | AE9: 东莞
A10: 45972 | B10: Talent Show | C10: 克罗地亚 | E10: PO-25111001 | F10: 4726107 | G10: 足球 CR | H10: 5076 | I10: 6 | J10: =H10/I10 -> 846 | K10: 46045 | L10: ok | P10: 45690 | S10: 46009 | T10: 12/30确认 | U10: 11/20确认箱唛移印 | V10: 260221HR | W10: Flash: ZFZ005C(CR) MCU: ZFZ001A | X10: 带电，克罗地亚包装 | Y10: 3.912 | Z10: =H10*Y10 -> 19857.31 | AA10: =Z10*7.75 -> 153894.15 | AB10: FH20220286 | AC10: 已入系统 | AD10: B | AE10: 东莞
A11: 45954 | C11: 波兰 | E11: PO-25102401 | F11: 1426107 | G11: 足球 PL | H11: 8520 | I11: 6 | J11: =H11/I11 -> 1420 | K11: 46048 | L11: 46052 | P11: 46048 | S11: 46016 | T11: 1/7确认 | U11: 12/1确认箱唛移印 | V11: 260221PL | W11: Flash: ZFZ004C(PL) MCU: ZFZ001B | X11: 波兰版包装 -带电（ 3个2AA电池）,主纸箱有特殊的点线（只封一条胶纸，胶纸不能超过虚线） | Y11: 3.912 | Z11: =H11*Y11 -> 33330.24 | AA11: =Z11*7.75 -> 258309.36 | AB11: FH20220287 | AC11: 已入系统 | AD11: B | AE11: 东莞
A12: 46001 | B12: GP France | C12: 法国 | E12: PO-25121001 | F12: 1025103 | G12: 红色比卡超-FR | H12: 4002 | I12: 6 | J12: 667 | K12: 46045 | L12: 46049 | P12: 46052 | S12: 46020 | T12: 翻单25101601 | U12: 12/18确认移印箱唛 | V12: 260221FR | W12: PCBA: ZPK004A(FR) | X12: 带电池，包装上印有Triman标志，包装：GP法国pkg + I/S（带法国标志），带隔电片 | Y12: 2.119 | Z12: 8480.24 | AA12: 65721.86 | AB12: FH20220288 | AC12: 已入系统 | AD12: B | AE12: 邵阳 | AF12: 系统出单 | AG12: 4002 | AH12: 0 | AK12: 46036
A13: 46001 | B13: GP France | C13: 法国 | E13: PO-25121002 | F13: 1025155 | G13: PTE 圆型游戏机-FR | H13: 6000 | I13: 6 | J13: 1000 | K13: 46045 | L13: 46049 | P13: 46052 | S13: 46014 | T13: 翻单25101601 | U13: 12/18确认移印箱唛 | V13: 260221FR | W13: MCU: ZPE001A Flash: ZPE002A(FR) | X13: 带电池，包装上印有Triman标志，包装：GP法国pkg + I/S（带法国标志） | Y13: 4.516 | Z13: 27096 | AA13: 209994 | AB13: FH20220288 | AC13: 已入系统 | AD13: B | AE13: 邵阳 | AF13: 系统出单 | AG13: 6000 | AH13: 0 | AK13: 46042
A14: 46001 | B14: GP France | C14: 法国 | E14: PO-25121004 | F14: 1025155 | G14: PTE 圆型游戏机-FR | H14: 2004 | I14: 6 | J14: 334 | K14: 46045 | L14: 46049 | P14: 46052 | S14: 46014 | T14: 翻单25101601 | U14: 12/18确认移印箱唛 | V14: 260221FR | W14: MCU: ZPE001A Flash: ZPE002A(FR) | X14: 带电池，包装上印有Triman标志，包装：GP法国pkg + I/S（带法国标志） | Y14: 4.516 | Z14: 9050.06 | AA14: 70137.97 | AB14: FH20220288 | AC14: 已入系统 | AD14: B | AE14: 邵阳 | AF14: 系统出单 | AG14: 2004 | AH14: 0 | AK14: 46044
A15: 46001 | B15: GP France | C15: 法国 | E15: PO-25121003 | F15: 1026107 | G15: 足球-FR | H15: 6000 | I15: 6 | J15: 1000 | K15: 46045 | L15: 46049 | P15: 46052 | S15: 46008 | T15: 12/30确认 | U15: 12/18确认移印箱唛 | V15: 260221FR | W15: Flash: ZFZ002E(FR) MCU: MCU: ZFZ001A | X15: 带电池，包装上印有Triman标志，包装：GP法国pkg + I/S（带法国标志） | Y15: 3.912 | Z15: 23472 | AA15: 181908 | AB15: FH20220288 | AC15: 已入系统 | AD15: B | AE15: 东莞
