Workbook

Sheet 名称
A1: 货号 | B1: 产品名称 | C1: 外箱 | D1: 车间
A2: 47329 | B2: 收割车 | C2: 2 | D2: A
A3: 47399 | B3: 洒水车 | C3: 4 | D3: B
A4: 47550 | B4: 回力车 | C4: 4 | D4: B
A5: 47615 | B5: 跳舞的玉米 | C5: 6 | D5: B
A6: 47640 | B6: 半挂车 | C6: 2 | D6: B
A7: 47669 | B7: 动物车 | C7: 4 | D7: 印尼
A8: 47674 | B8: JD LNS圆轮拖拉机 | C8: 2 | D8: 印尼
A9: 35189AZ | B9: 吹气车 | C9: 2 | D9: A
A10: 35189B | B10: 吹气车 | C10: 2 | D10: A
A11: 35189C | B11: 吹气车 | C11: 2 | D11: A
A12: 35206B | B12: 猪马牛羊车（单支装） | C12: 2 | D12: A
A13: 35802J | B13: 挖土机 | C13: 2 | D13: 印尼
A14: 46644B | B14: 发光车 | C14: 2 | D14: A
A15: 46656EU1 | B15: 6"拖拉机 | C15: 4 | D15: B
A16: 46670C | B16: 46656/46748 混装 | C16: 4 | D16: B
A17: 46670TSC | B17: 46656/46748 混装 | C17: 4 | D17: B
A18: 46720J | B18: 木材运输车 | C18: 4 | D18: 印尼
A19: 47101J | B19: 1:16收割机 | C19: 1 | D19: 印尼
A20: 47280A | B20: 童车 | C20: 1 | D20: B
... A46: Y2049G1 | B46: 锁匙 | C46: 36 | D46: B
A47: 46088 | B47: 吹气三轮车 | C47: 1 | D47: A
A48: E73647BZR | B48: 手镯和球 | C48: 12 | D48: B
A49: 43379 | B49: 手镯和球 | C49: 12 | D49: B
A50: T72465ML3 | B50: 贪婪的老奶奶 | C50: 6 | D50: B
A51: T72465ADR2 | B51: 贪婪的老奶奶 | C51: 6 | D51: B
A52: L27870B | B52: 杯子 | C52: 18 | D52: B
A53: T72465ASC1 | B53: 贪婪的老奶奶 | C53: 6 | D53: B
A54: T72465RO | B54: 贪婪的老奶奶 | C54: 6 | D54: B
A55: T72465BZR2 | B55: 贪婪的老奶奶 | C55: 6 | D55: B
A56: 47391J | B56: 1:16收割机 | C56: 1 | D56: 印尼
A57: Y2341C | B57: 杯子 | C57: 18 | D57: 印尼
A58: E73855A1 | B58: 马里奥能量蘑菇吸塑混装 | C58: 6 | D58: 印尼
A59: E73906 | B59: 马里奥和他的蘑菇 | C59: 6 | D59: 印尼
A60: E73907 | B60: 能量蘑菇 | C60: 6 | D60: 印尼
A61: E73856 | B61: 宝箱马里奥 | C61: 4 | D61: 印尼
... A86: 096283(E73907) | B86: 能量蘑菇 | C86: 6 | D86: 印尼

Sheet 总接单
A1: 产品名称 | BQ1: E73956/E73956US/E73855A1/E73855US
A2: 接单日期 | B2: 国家 | C2: TOMY PO | D2: CUSTOMER PO | E2: 货号 | F2: 数量 | G2: PO走货期 | H2: 35189AZ/B | I2: 47280 47280A | J2: L27870TG/B/L27870C | K2: Y2341G | L2: Y2049L/Y2049G1//Y2049G2/Y2049L1 | M2: 47329/TSC1 | N2: E73251 | O2: E73252 | P2: E73253 | Q2: E73254/C | R2: 46656A | S2: 46670 | T2: 37651F | U2: 46644B | V2: 46088 | W2: 35206B | X2: T20121/FR | Y2: 47399/TSC | Z2: E73410 | AA2: 46696 | AB2: 47464 | AC2: 47424 | AD2: 47425 | AE2: P4608805 | AF2: P4608815 | AG2: P4608814 | AH2: P4608813 | AI2: L61157 | AJ2: 47465 | AK2: POB23-00600 配件 | AL2: L18207 | AM2: E73647/43379 | AN2: P4608802 | AO2: 37964 | AP2: 47615 | AQ2: 47640/TSC | AR2: 47550 | AS2: 47639 | AT2: 47600 | AU2: E73697 | AV2: 46720J | AW2: E73622A/E73622AZ | AX2: E73622AWM | AY2: E73635A | AZ2: E73623A1 | BA2: E73636A | BB2: 47669/47669TSC | BC2: 47674DG/47674TSC | BD2: 47674 | BE2: 47682 | BF2: T73785EN | BG2: E73814C | BH2: 47600J | BI2: 47602J | BJ2: 47367J | BK2: 47101J | BL2: 35802J | BM2: E73860C/E73860PL | BN2: 47465J1 | BO2: 47391J | BP2: Y2341C | BQ2: E73906/E73906US | BR2: E73907/E73907A/E73907US | BS2: E73856 | BT2: E73857 | BU2: 47722A | BV2: 47723A | BW2: 47711A | BX2: 47713A | BY2: 47714A | BZ2: E73705A | CA2: 47716A | CB2: 47712A | CC2: E74041BULK | CE2: 单价USD | CF2: 金额USD | CG2: 金额HKD | CH2: 车间
A3: 45950 | C3: MA | E3: E73860PL | F3: 8100 | CF3: =SUM(H3:CD3)*CE3 -> 0 | CG3: =CF3*7.75 -> 0 | CH3: 印尼
CF4: =SUM(H4:CD4)*CE4 -> 0 | CG4: =CF4*7.75 -> 0 | CH4: 印尼
F5: =SUM(F3:F4) -> 8100 | G5: =F5-CE5-#REF! -> #REF! | H5: =SUM(H3:H4) -> 0 | I5: =SUM(I3:I4) -> 0 | J5: =SUM(J3:J4) -> 0 | K5: =SUM(K3:K4) -> 0 | L5: =SUM(L3:L4) -> 0 | M5: =SUM(M3:M4) -> 0 | N5: =SUM(N3:N4) -> 0 | O5: =SUM(O3:O4) -> 0 | ... CD5: =SUM(CD3:CD4) -> 0 | CE5: =SUM(H5:CD5) -> 0 | CF5: =SUM(CF3:CF4) -> 0 | CG5: =SUM(CG3:CG4) -> 0
F6: =F5-总排期!J4-已走货!J3 -> 0 | G6: =#REF!+#REF!+#REF!+#REF!+F3+#REF!-G5 -> #REF!
D8: 美国
A9: 总接单： | B9: =CG5 -> 0 | C9: 总接单： | D9: =SUMIF(B:B,D8,CG:CG) -> 0
A10: 总排期： | B10: =总排期!AA4 -> 0 | C10: 总排期： | D10: =SUMIF(总排期!C:C,D8,总排期!AA:AA) -> 0
A11: 已走货： | B11: =已走货!AA3 -> 0 | C11: 已走货： | D11: =SUMIF(已走货!C:C,D8,已走货!AA:AA) -> 0
B12: =B9-B10-B11 -> 0 | D12: =D9-D10-D11 -> 0
A15: 以下标注内容区分识别备注：
A16: 类型 | B16: 内容
A17: 黄色填充 | B17: 新加单或更改
A18: 粉色填充 | B18: 扣单/转单
A19: 蓝色字体 | B19: 已经完成订单
A20: 粉色字体 | B20: 已经出货
A21: 红色字体 | B21: 取消单

Sheet 总排期
A1: 接单期 | B1: 提交化学测试 | C1: 国家 | D1: 第三客户名称 | E1: 客跟单 | F1: PO | G1: CUSTOMER PO | H1: 货号 | I1: 产品名称 | J1: 数量 | K1: 外箱 | L1: 总箱数 | M1: PO走货期 | N1: 验货期 | O1: 实际验货期 | P1: 日期码 | Q1: 箱唛资料 | R1: Spot check | S1: 年报测试 | T1: 客贴纸 | U1: 印尼回复上拉时间 | V1: 印尼回复完成时间 | W1: 箱唛状态 | X1: 备注 | Y1: 单价USD | Z1: 金额USD | AA1: 金额HKD | AB1: 发票号 | AC1: 船期 | AD1: 是否入系统 | AE1: 车间 | AF1: 混装比例 | AG1: 预计物料上印尼时间 | AH1: 物料到印尼时间 | AI1: 包材上料时间 | AJ1: 塑胶件上料时间 | AK1: 纸吉 | AL1: 五金上料时间 | AM1: 贴纸 | AN1: 仓库复来料时间 | AO1: 接单周期 | AP1: 印尼周期
A2: 45950 | B2: =IF(TODAY()>=A2,IF(R2="","未",""),"") -> 未 | F2: 4500142654 | H2: E73860PL | I2: =VLOOKUP(H2,名称!A:C,2,0) -> 泡泡壶 | J2: 8100 | K2: =VLOOKUP(H2,名称!A:D,3,0) -> 4 | L2: =J2/K2 -> 2025 | M2: 46021 | N2: =M2-2 -> 46019 | P2: L0225RR02 | X2: 印尼龙昌下单 | Z2: =J2*Y2 -> 0 | AA2: =Z2*7.75 -> 0 | AE2: =VLOOKUP(H2,名称!A:D,4,0) -> 印尼 | AH2: 46000 | AI2: 45974 | AL2: 45967 | AN2: 45973 | AO2: =M2-A2 -> 71 | AP2: =M2-AI2 -> 47
Z3: =J3*Y3 -> 0 | AA3: =Z3*7.75 -> 0 | AE3: =VLOOKUP(H3,名称!A:D,4,0) -> #N/A | AO3: =M3-A3 -> 0 | AP3: =M3-AI3 -> 0
I4: 合计 | J4: =SUM(J2:J3) -> 8100 | Z4: =SUM(Z2:Z3) -> 0 | AA4: =SUM(AA2:AA3) -> 0

Sheet 已走货
A1: 接单期 | B1: 提交化学测试 | C1: 国家 | D1: 客名 | E1: 客跟单 | F1: TOMY PO | G1: CUSTOMER PO | H1: 货号 | I1: 产品名称 | J1: 数量 | K1: 外箱 | L1: 总箱数 | M1: PO走货期 | N1: 验货期 | O1: 实际验货期 | P1: 印尼回复上拉时间 | Q1: 印尼回复完成时间 | R1: Spot check | S1: 年报测试 | T1: 客贴纸 | U1: 日期码 | V1: 箱唛资料 | W1: 箱唛状态 | X1: 备注 | Y1: 单价USD | Z1: 金额USD | AA1: 金额HKD | AB1: 发票号 | AC1: 出货日期 | AD1: 是否入系统 | AE1: 车间 | AF1: 混装比例 | AG1: 预计物料上印尼时间 | AH1: 物料到印尼时间 | AI1: 包材上料时间 | AJ1: 塑胶件上料时间 | AK1: 纸吉 | AL1: 五金上料时间 | AM1: 贴纸 | AN1: 仓库复来料时间 | AO1: 接单周期 | AP1: 印尼周期
Z2: =J2*Y2 -> 0 | AA2: =Z2*7.75 -> 0 | AO2: =M2-A2 -> 0 | AP2: =M2-AI2 -> 0
I3: 合计 | J3: =SUM(J2:J2) -> 0 | Z3: =SUM(Z2:Z2) -> 0 | AA3: =SUM(AA2:AA2) -> 0

Sheet 取消单
A1: 接单期 | B1: 提交化学测试 | C1: 国家 | D1: 客名 | E1: 客跟单 | F1: TOMY PO | G1: CUSTOMER PO | H1: 货号 | I1: 产品名称 | J1: 数量 | K1: 外箱 | L1: 总箱数 | M1: PO走货期 | N1: 验货期 | O1: 实际验货期 | P1: 印尼回复上拉时间 | Q1: 印尼回复完成时间 | R1: Spot check | S1: 年报测试 | T1: 客贴纸 | U1: 日期码 | V1: 箱唛资料 | W1: 箱唛状态 | X1: 备注 | Y1: 单价USD | Z1: 金额USD | AA1: 金额HKD | AB1: 发票号 | AC1: 出货日期 | AD1: 是否入系统 | AE1: 车间 | AF1: 混装比例 | AG1: 预计物料上印尼时间 | AH1: 物料到印尼时间 | AI1: 包材上料时间 | AJ1: 塑胶件上料时间 | AK1: 纸吉 | AL1: 五金上料时间 | AM1: 贴纸 | AN1: 仓库复来料时间 | AO1: 接单周期 | AP1: 印尼周期
A2: 45679 | C2: 美国 | E2: Nancy | F2: 10094612 | G2: 202502170028 | H2: 47682 | I2: JD LNS 履带拖拉机 | J2: 0 | K2: 2 | L2: =J2/K2 -> 0 | M2: 45756 | N2: =M2-7 -> 45749 | X2: 取消单 | Y2: 5.49 | Z2: =J2*Y2 -> 0 | AA2: =Z2*7.75 -> 0 | AE2: 印尼 | AO2: =M2-A2 -> 77 | AP2: =M2-AI2 -> 45756
A3: 45595 | C3: 美国 | E3: Olivia | F3: 10089531 | G3: 202430270058 | H3: E73622A | I3: 布鲁伊家族沐浴玩具 | J3: =10000-10000 -> 0 | K3: 4 | L3: =J3/K3 -> 0 | M3: 45700 | N3: =M3-7 -> 45693 | R3: 2-11 OK | U3: A0325RR02 | V3: 标准唛+TTT | X3: 转10000PCS到PO10094685 | Y3: 2.17 | Z3: =J3*Y3 -> 0 | AA3: =Z3*7.75 -> 0 | AE3: 印尼 | AI3: 45639 | AJ3: 印尼备料 | AO3: =M3-A3 -> 105 | AP3: =M3-AI3 -> 61
A4: 45595 | C4: 美国 | E4: Olivia | F4: 10089531 | G4: 202430270058 | H4: E73635A | I4: 布鲁伊沐浴玩具 | J4: =7800-7800 -> 0 | K4: 6 | L4: =J4/K4 -> 0 | M4: 45700 | N4: =M4-7 -> 45693 | R4: 2-11 OK | U4: A0325RR02 | V4: 标准唛+TTT | X4: 转7800PCS到PO10094685 | Y4: 1.36 | Z4: =J4*Y4 -> 0 | AA4: =Z4*7.75 -> 0 | AE4: 印尼 | AI4: 45639 | AJ4: 印尼备料 | AO4: =M4-A4 -> 105 | AP4: =M4-AI4 -> 61
A5: 45595 | C5: 美国 | E5: Olivia | F5: 10089531 | G5: 202430270058 | H5: E73622AWM | I5: 布鲁伊家族沐浴玩具 | J5: =2000-2000 -> 0 | K5: 2 | L5: =J5/K5 -> 0 | M5: 45700 | N5: =M5-7 -> 45693 | R5: 2-11 OK | U5: A0325RR02 | V5: 标准唛+TTT | X5: 转2000PCS到PO10094685 | Y5: 2.23 | Z5: =J5*Y5 -> 0 | AA5: =Z5*7.75 -> 0 | AE5: 印尼 | AI5: 45646 | AJ5: 印尼备料 | AO5: =M5-A5 -> 105 | AP5: =M5-AI5 -> 54
A6: 45609 | C6: 美国 | E6: Olivia | F6: 10090269 | G6: 202431770039 | H6: E73622A | I6: 布鲁伊家族沐浴玩具 | J6: =10000-10000 -> 0 | K6: 4 | L6: =J6/K6 -> 0 | M6: 45707 | N6: =M6-7 -> 45700 | R6: 2-11 OK | U6: A0325RR02 | V6: 标准唛+TTT | X6: 转10000PCS到PO10094708 | Y6: 2.17 | Z6: =J6*Y6 -> 0 | AA6: =Z6*7.75 -> 0 | AE6: 印尼 | AI6: 45646 | AJ6: 印尼备料 | AO6: =M6-A6 -> 98 | AP6: =M6-AI6 -> 61
A7: 45595 | C7: 美国 | E7: Olivia | F7: 10089531 | G7: 202430270058 | H7: E73635A | I7: 布鲁伊沐浴玩具 | J7: =7800-7800 -> 0 | K7: 6 | L7: =J7/K7 -> 0 | M7: 45707 | N7: =M7-7 -> 45700 | R7: 2-11 OK | U7: A0325RR02 | V7: 标准唛+TTT | X7: 转7800PCS到PO10094685 | Y7: 1.36 | Z7: =J7*Y7 -> 0 | AA7: =Z7*7.75 -> 0 | AE7: 印尼 | AI7: 45639 | AJ7: 印尼备料 | AO7: =M7-A7 -> 112 | AP7: =M7-AI7 -> 68
A8: 45609 | C8: 美国 | E8: Olivia | F8: 10090269 | G8: 202431770039 | H8: E73622AWM | I8: 布鲁伊家族沐浴玩具 | J8: =5000-5000 -> 0 | K8: 2 | L8: =J8/K8 -> 0 | M8: 45707 | N8: =M8-7 -> 45700 | R8: 2-11 OK | U8: B1025RR02 | V8: 标准唛+TTT | X8: 转5000PCS到PO10094708 | Y8: 2.23 | Z8: =J8*Y8 -> 0 | AA8: =Z8*7.75 -> 0 | AE8: 印尼 | AI8: 45646 | AJ8: 印尼备料 | AO8: =M8-A8 -> 98 | AP8: =M8-AI8 -> 61
A9: 45595 | C9: 美国 | E9: Olivia | F9: 10089531 | G9: 202430270058 | H9: E73635A | I9: 布鲁伊沐浴玩具 | J9: =7800-7800 -> 0 | K9: 6 | L9: =J9/K9 -> 0 | M9: 45707 | N9: =M9-7 -> 45700 | R9: 2-11 OK | U9: B1025RR02 | V9: 标准唛+TTT | X9: 转7800PCS到PO10094685 | Y9: 1.36 | Z9: =J9*Y9 -> 0 | AA9: =Z9*7.75 -> 0 | AE9: 印尼 | AI9: 45646 | AJ9: 印尼备料 | AO9: =M9-A9 -> 112 | AP9: =M9-AI9 -> 61
A10: 45681 | C10: 美国 | E10: Janice | F10: 10094685 | G10: 202502370242 | H10: E73635A | I10: 布鲁伊沐浴玩具 | J10: =1212-1212 -> 0 | K10: 6 | L10: =J10/K10 -> 0 | M10: 45714 | N10: =M10-7 -> 45707 | O10: 3-5 OK | R10: 2-11 OK | U10: B1025RR02 | V10: 标准唛+TTT | X10: 从PO10089531转入7800PCS | Y10: 1.36 | Z10: =J10*Y10 -> 0 | AA10: =Z10*7.75 -> 0 | AE10: 印尼 | AI10: 45646 | AJ10: 印尼备料 | AO10: =M10-A10 -> 33 | AP10: =M10-AI10 -> 68
A11: 45661 | F11: MPO | G11: 202500370011 | H11: 47674DG | I11: JD LNS圆轮拖拉机 | J11: =24500-24500 -> 0 | K11: 2 | L11: =J11/K11 -> 0 | M11: 45742 | N11: =M11-7 -> 45735 | T11: 需要JD贴纸 | U11: C1325RR02 | V11: 待定 | Y11: 5.28 | Z11: =J11*Y11 -> 0 | AA11: =Z11*7.75 -> 0 | AE11: 印尼 | AI11: 45679 | AO11: =M11-A11 -> 81 | AP11: =M11-AI11 -> 63
A12: 45661 | F12: MPO | G12: 202500370011 | H12: 47674DG | I12: JD LNS圆轮拖拉机 | J12: =11696-11696 -> 0 | K12: 2 | L12: =J12/K12 -> 0 | M12: 45763 | N12: =M12-7 -> 45756 | T12: 需要JD贴纸 | U12: C1325RR02 | V12: 待定 | Y12: 5.28 | Z12: =J12*Y12 -> 0 | AA12: =Z12*7.75 -> 0 | AE12: 印尼 | AO12: =M12-A12 -> 102 | AP12: =M12-AI12 -> 45763
A13: 45674 | F13: MPO | G13: 202501670214 | H13: 47674 | I13: JD LNS圆轮拖拉机 | J13: =29348+20-26824-1000-762-782 -> 0 | K13: 2 | L13: =J13/K13 -> 0 | M13: 45791 | N13: =M13-7 -> 45784 | T13: 未收到JD贴纸 | U13: D1525RR02 | V13: 待定 | X13: 有Try me贴纸 有说明书 无价格贴纸 | Y13: 4.79 | Z13: =J13*Y13 -> 0 | AA13: =Z13*7.75 -> 0 | AE13: 印尼 | AI13: 45715 | AJ13: 印尼备料 | AO13: =M13-A13 -> 117 | AP13: =M13-AI13 -> 76
A14: 45706 | F14: MPO | G14: 202504871145 | H14: 47669TSC | I14: 动物车 | J14: =18708+28-2040-1716-1804-1836-1672-1604-2384-1728-2684-1268 -> 0 | K14: 4 | L14: =J14/K14 -> 0 | M14: 45791 | N14: =M14-7 -> 45784 | U14: D1525RR02 | V14: 待定 | X14: 需要改双坑纸箱 | Y14: 4.91 | Z14: =J14*Y14 -> 0 | AA14: =Z14*7.75 -> 0 | AE14: 印尼 | AO14: =M14-A14 -> 85 | AP14: =M14-AI14 -> 45791
A15: 45706 | F15: MPO | G15: 202504871145 | H15: 47674TSC | I15: JD LNS圆轮拖拉机 | J15: =10000+42-1346-1042-1092-1006-874-388-1636-772-1644-242 -> 0 | K15: 2 | L15: =J15/K15 -> 0 | M15: 45798 | N15: =M15-7 -> 45791 | T15: 未收到JD贴纸 | U15: D1525RR02 | V15: 待定 | X15: 需要改双坑纸箱 | Y15: 5.28 | Z15: =J15*Y15 -> 0 | AA15: =Z15*7.75 -> 0 | AE15: 印尼 | AJ15: 印尼备料 | AO15: =M15-A15 -> 92 | AP15: =M15-AI15 -> 45798
A16: 45721 | F16: MPO | G16: 202506370040 | H16: 47101J | I16: 1：16收割机 | J16: =1569-129-492-38-43-51-67-24-200-35-12-30-184-240-24 -> 0 | K16: 1 | L16: =J16/K16 -> 0 | M16: 45805 | N16: =M16-7 -> 45798 | U16: E1325RR02 | V16: 待定 | X16: 转129PCS到PO10098301 转492PCS到PO10098300 转38PCS到PO10098316 转43PCS到PO10098303 转51PCS到PO10098304 转67PCS到PO10098305 转24PCS到PO10098308 转200PCS到PO10098423 转35PCS到PO10098425 转12PCS到PO10098426 转30PCS到PO10098428 转184PCS到PO10098429 转240PCS到PO10098430 转24PCS到PO10098435 | Y16: 29.8 | Z16: =J16*Y16 -> 0 | AA16: =Z16*7.75 -> 0 | AE16: 印尼 | AJ16: 45722 | AO16: =M16-A16 -> 84 | AP16: =M16-AI16 -> 45805
A17: 45721 | F17: MPO | G17: 202506370040 | H17: 35802J | I17: 挖土机 | J17: =704-24-126-16-60-58-92-20-20-20-20-60-120-4-64 -> 0 | K17: 2 | L17: =J17/K17 -> 0 | M17: 45805 | N17: =M17-7 -> 45798 | U17: E1325RR02 | V17: 待定 | X17: 转126PCS到PO10098301 转16PCS到PO10098316 转60PCS到PO10098303 转58PCS到PO10098304 转92PCS到PO10098305 转20PCS到PO10098307 转20PCS到PO10098423 转20PCS到PO10098425 转20PCS到PO10098426 转60PCS到PO10098428 转120PCS到PO10098432 转4PCS到PO10098435 转64PCS到PO10098436 | Y17: 11.9 | Z17: =J17*Y17 -> 0 | AA17: =Z17*7.75 -> 0 | AE17: 印尼 | AI17: 45743 | AJ17: 印尼备料 | AO17: =M17-A17 -> 84 | AP17: =M17-AI17 -> 62
A18: 45721 | F18: MPO | G18: 202506370040 | H18: 47600J | I18: 1：16货柜车 | J18: =804-108-126-32-50-58-48-22-6-44-150-52-20-10-60-18 -> 0 | K18: 2 | L18: =J18/K18 -> 0 | M18: 45805 | N18: =M18-7 -> 45798 | U18: E1325RR02 | V18: 待定 | X18: 转108PCS到PO10098301 转126PCS到PO10098300 转32PCS到PO10098316 转50PCS到PO10098303 转58PCS到PO10098304 转48PCS到PO10098305 转22PCS到PO10098307 转6PCS到PO10098308 转44PCS到PO10098310 转150PCS到PO10098423 转52PCS到PO10098425 转20PCS到PO10098428 转10PCS到PO10098446 转60PCS到PO1009832 转18PCS到PO10098435 | Y18: 30.54 | Z18: =J18*Y18 -> 0 | AA18: =Z18*7.75 -> 0 | AE18: 印尼 | AJ18: 45736 | AO18: =M18-A18 -> 84 | AP18: =M18-AI18 -> 45805
A19: 45721 | F19: MPO | G19: 202506370040 | H19: 47669 | I19: 动物车 | J19: =660-32-20-64-80-24-40-272-40-80-8 -> 0 | K19: 4 | L19: =J19/K19 -> 0 | M19: 45805 | N19: =M19-7 -> 45798 | U19: E1325RR02 | V19: 待定 | X19: 转32PCS到PO10098316 转20PCS到PO10098307 转64PCS到PO10098310 转80PCS到PO10098423 转24PCS到PO10098425 转40PCS到PO10098426 转272PCS到PO10098427 转40PCS到PO10098428 转80PCS到PO10098432 转8PCS到PO10098435 | Y19: 4.81 | Z19: =J19*Y19 -> 0 | AA19: =Z19*7.75 -> 0 | AE19: 印尼 | AO19: =M19-A19 -> 84 | AP19: =M19-AI19 -> 45805
A20: 45721 | F20: MPO | G20: 202506370040 | H20: 47674 | I20: JD LNS圆轮拖拉机 | J20: =26824-942-2240-576-412-370-676-72-160-360-2000-840-160-1000-800-4000-4400-300-7092-324-100 -> 0 | K20: 2 | L20: =J20/K20 -> 0 | M20: 45805 | N20: =M20-7 -> 45798 | U20: E1325RR02 | V20: 待定 | X20: 转942PCS到PO10098301 转2240PCS到PO10098300 转576PCS到PO10098316 转412PCS到PO10098303 转370PCS到PO10098304 转676PCS到PO10098305 转72PCS到PO10098307 转160PCS到PO10098308 转360PCS到PO10098310 转2000PCS到PO10098423 转840PCS到PO10098425 转160PCS到PO10098426 转1000PCS到PO10098427 转800PCS到PO10098428 转4000PCS到PO10098429 转4400PCS到PO10098430 转300PCS到PO10098432 转7092PCS到PO10098433 转324PCS到PO10098435 转100PCS到PO10098436 | Y20: 4.79 | Z20: =J20*Y20 -> 0 | AA20: =Z20*7.75 -> 0 | AE20: 印尼 | AJ20: 印尼备料 | AO20: =M20-A20 -> 84 | AP20: =M20-AI20 -> 45805
A21: 45721 | F21: MPO | G21: 202506370040 | H21: 47602J | I21: 1：16翻斗车 | J21: =60-24-36 -> 0 | K21: 4 | L21: =J21/K21 -> 0 | M21: 45812 | N21: =M21-7 -> 45805 | U21: E1325RR02 | V21: 待定 | X21: 转24PCS到PO10098308 再转36pcs到10098428 | Y21: 14 | Z21: =J21*Y21 -> 0 | AA21: =Z21*7.75 -> 0 | AE21: 印尼 | AJ21: 45736 | AO21: =M21-A21 -> 91 | AP21: =M21-AI21 -> 45812
A22: 45721 | F22: MPO | G22: 202506370040 | H22: 47367J | I22: 1:16拖车厢 | J22: =830-112-50-54-58-48-32-106-120-98-48-30-44-30 -> 0 | K22: 2 | L22: =J22/K22 -> 0 | M22: 45812 | N22: =M22-7 -> 45805 | U22: E1325RR02 | V22: 待定 | X22: 转112PCS到PO10098301 转50PCS到PO10098316 转54PCS到PO10098303 转58PCS到PO10098304 转48PCS到PO10098305 转32PCS到PO10098308 转106PCS到PO10098310 转120PCS到PO10098423 转98PCS到PO10098425 转48PCS到PO10098426 转30PCS到PO10098428 转44PCS到PO10098435 转30PCS到PO10098436 | Y22: 22.9 | Z22: =J22*Y22 -> 0 | AA22: =Z22*7.75 -> 0 | AE22: 印尼 | AJ22: 45736 | AO22: =M22-A22 -> 91 | AP22: =M22-AI22 -> 45812
A23: 45721 | F23: MPO | G23: 202506370041 | H23: 47101J | I23: =VLOOKUP(H23,名称!A:C,2,0) -> 1:16收割机 | J23: =250-250 -> 0 | K23: =VLOOKUP(H23,名称!A:D,3,0) -> 1 | L23: =J23/K23 -> 0 | M23: 45805 | N23: 45818 | O23: 45798 | R23: 45798 | U23: E1325RR02 | V23: 待定 | Y23: 29.8 | Z23: =J23*Y23 -> 0 | AA23: =Z23*7.75 -> 0 | AE23: 印尼 | AJ23: 45756 | AM23: 45722 | AO23: =M23-A23 -> 84 | AP23: =M23-AI23 -> 45805
A24: 45721 | F24: MPO | G24: 202506370041 | H24: 47600J | I24: =VLOOKUP(H24,名称!A:C,2,0) -> 1:16货柜车 | J24: =360-360 -> 0 | K24: =VLOOKUP(H24,名称!A:D,3,0) -> 2 | L24: =J24/K24 -> 0 | M24: 45805 | N24: 45818 | O24: 45773 | R24: 45775 | U24: E1325RR02 | V24: 待定 | Y24: 30.54 | Z24: =J24*Y24 -> 0 | AA24: =Z24*7.75 -> 0 | AE24: 印尼 | AJ24: 45750 | AM24: 45736 | AO24: =M24-A24 -> 84 | AP24: =M24-AI24 -> 45805
A25: 45721 | F25: MPO | G25: 202506370041 | H25: 35802J | I25: =VLOOKUP(H25,名称!A:C,2,0) -> 挖土机 | J25: =200-200 -> 0 | K25: =VLOOKUP(H25,名称!A:D,3,0) -> 2 | L25: =J25/K25 -> 0 | M25: 45805 | N25: 45818 | P25: 45807 | Q25: 45807 | U25: E1325RR02 | V25: 待定 | Y25: 11.9 | Z25: =J25*Y25 -> 0 | AA25: =Z25*7.75 -> 0 | AE25: 印尼 | AJ25: 45743 | AM25: 印尼备料 | AO25: =M25-A25 -> 84 | AP25: =M25-AI25 -> 45805
A26: 45721 | F26: MPO | G26: 202506370041 | H26: 47367J | I26: =VLOOKUP(H26,名称!A:C,2,0) -> 1:16拖车厢 | J26: =580-580 -> 0 | K26: =VLOOKUP(H26,名称!A:D,3,0) -> 2 | L26: =J26/K26 -> 0 | M26: 45812 | N26: 45818 | P26: 45786 | Q26: 45787 | U26: E1325RR02 | V26: 待定 | Y26: 22.9 | Z26: =J26*Y26 -> 0 | AA26: =Z26*7.75 -> 0 | AE26: 印尼 | AJ26: 45757 | AM26: 45736 | AO26: =M26-A26 -> 91 | AP26: =M26-AI26 -> 45812
A27: 45721 | F27: MPO | G27: 202506370041 | H27: 47602J | I27: =VLOOKUP(H27,名称!A:C,2,0) -> 1:16翻斗车 | J27: =120-120 -> 0 | K27: =VLOOKUP(H27,名称!A:D,3,0) -> 4 | L27: =J27/K27 -> 0 | M27: 45812 | N27: 45818 | P27: 45756 | Q27: 45756 | U27: E1325RR02 | V27: 待定 | Y27: 14 | Z27: =J27*Y27 -> 0 | AA27: =Z27*7.75 -> 0 | AE27: 印尼 | AJ27: 45750 | AM27: 45736 | AO27: =M27-A27 -> 91 | AP27: =M27-AI27 -> 45812
A28: 45721 | F28: MPO | G28: 202506370042 | H28: 47674 | I28: =VLOOKUP(H28,名称!A:C,2,0) -> JD LNS圆轮拖拉机 | J28: 762 | K28: =VLOOKUP(H28,名称!A:D,3,0) -> 2 | L28: =J28/K28 -> 381 | M28: 45805 | N28: =M28-7 -> 45798 | P28: 45758 | Q28: 45758 | U28: E1325RR02 | V28: 待定 | Y28: 4.79 | Z28: =J28*Y28 -> 3649.98 | AA28: =Z28*7.75 -> 28287.35 | AE28: 印尼 | AJ28: 45743 | AM28: 印尼备料 | AO28: =M28-A28 -> 84 | AP28: =M28-AI28 -> 45805
A29: 45721 | F29: MPO | G29: 202506370041 | H29: 47669 | I29: =VLOOKUP(H29,名称!A:C,2,0) -> 动物车 | J29: =600-600 -> 0 | K29: =VLOOKUP(H29,名称!A:D,3,0) -> 4 | L29: =J29/K29 -> 0 | M29: 45805 | N29: =M29-7 -> 45798 | P29: 45792 | Q29: 45792 | U29: E1325RR02 | V29: 待定 | Y29: 4.81 | Z29: =J29*Y29 -> 0 | AA29: =Z29*7.75 -> 0 | AE29: 印尼 | AJ29: 45749 | AM29: 45750 | AO29: =M29-A29 -> 84 | AP29: =M29-AI29 -> 45805
A30: 45721 | F30: MPO | G30: 202506370041 | H30: 47674 | I30: =VLOOKUP(H30,名称!A:C,2,0) -> JD LNS圆轮拖拉机 | J30: =1000-1000 -> 0 | K30: =VLOOKUP(H30,名称!A:D,3,0) -> 2 | L30: =J30/K30 -> 0 | M30: 45805 | N30: =M30-7 -> 45798 | P30: 45782 | Q30: 45782 | U30: E1325RR02 | V30: 待定 | Y30: 4.79 | Z30: =J30*Y30 -> 0 | AA30: =Z30*7.75 -> 0 | AE30: 印尼 | AJ30: 45743 | AM30: 印尼备料 | AO30: =M30-A30 -> 84 | AP30: =M30-AI30 -> 45805
A31: 45721 | C31: 美国 | D31: TOMY COMPANY, LTD. (TKY-US) | E31: Olivia | F31: MPO | G31: 202506370042 | H31: 47600J | I31: =VLOOKUP(H31,名称!A:C,2,0) -> 1:16货柜车 | J31: =846-846 -> 0 | K31: =VLOOKUP(H31,名称!A:D,3,0) -> 2 | L31: =J31/K31 -> 0 | M31: 45805 | N31: 45818 | P31: 45769 | Q31: 45771 | U31: E1325RR02 | V31: 待定 | Y31: 30.54 | Z31: =J31*Y31 -> 0 | AA31: =Z31*7.75 -> 0 | AE31: 印尼 | AI31: 45749 | AJ31: 45736 | AL31: 45702 | AO31: =M31-A31 -> 84 | AP31: =M31-AI31 -> 56
A32: 45721 | C32: 美国 | D32: TOMY COMPANY, LTD. (TKY-US) | E32: Olivia | F32: MPO | G32: 202506370042 | H32: 47602J | I32: =VLOOKUP(H32,名称!A:C,2,0) -> 1:16翻斗车 | J32: =44-44 -> 0 | K32: =VLOOKUP(H32,名称!A:D,3,0) -> 4 | L32: =J32/K32 -> 0 | M32: 45812 | N32: =M32-2 -> 45810 | P32: 45756 | Q32: 45756 | U32: E1325RR02 | V32: 待定 | Y32: 14 | Z32: =J32*Y32 -> 0 | AA32: =Z32*7.75 -> 0 | AE32: 印尼 | AI32: 45749 | AJ32: 45736 | AL32: 45702 | AO32: =M32-A32 -> 91 | AP32: =M32-AI32 -> 63
A33: 45721 | C33: 美国 | D33: TOMY COMPANY, LTD. (TKY-US) | E33: Olivia | F33: MPO | G33: 202506370042 | H33: 47367J | I33: =VLOOKUP(H33,名称!A:C,2,0) -> 1:16拖车厢 | J33: =802-802 -> 0 | K33: =VLOOKUP(H33,名称!A:D,3,0) -> 2 | L33: =J33/K33 -> 0 | M33: 45812 | N33: =M33-2 -> 45810 | P33: 45782 | Q33: 45784 | U33: E1325RR02 | V33: 待定 | Y33: 22.9 | Z33: =J33*Y33 -> 0 | AA33: =Z33*7.75 -> 0 | AE33: 印尼 | AI33: 45756 | AJ33: 45736 | AL33: 45702 | AO33: =M33-A33 -> 91 | AP33: =M33-AI33 -> 56
A34: 45484 | C34: 美国 | D34: TOMY INTERNATIONAL INC. | E34: Cici | F34: 10082921 | G34: 202419170139 | H34: 47465J1 | I34: =VLOOKUP(H34,名称!A:C,2,0) -> 牵引车 | J34: 500 | K34: 4 | L34: =J34/K34 -> 125 | M34: 45812 | N34: =M34-2 -> 45810 | P34: 45769 | Q34: 45772 | U34: E1325RR02 | V34: 标准唛+TTT | W34: OK | Y34: 10.22 | Z34: =J34*Y34 -> 5110 | AA34: =Z34*7.75 -> 39602.5 | AE34: 印尼 | AG34: 45576 | AH34: 45593 | AI34: 45743 | AJ34: 已上 | AO34: =M34-A34 -> 328 | AP34: =M34-AI34 -> 69
A35: 45743 | C35: 美国 | D35: TOMY COMPANY, LTD. (TKY-US) | E35: Olivia | F35: MPO | G35: 202508070032 | H35: E73622A | I35: =VLOOKUP(H35,名称!A:C,2,0) -> 布鲁伊家族杯子套装 | J35: =21192-4440-3304-4704-6596-2148 -> 0 | K35: =VLOOKUP(H35,名称!A:D,3,0) -> 4 | L35: =J35/K35 -> 0 | M35: 45798 | N35: =M35-2 -> 45796 | P35: 45783 | Q35: 45813 | R35: 4/23寄出 | U35: D1525RR02 | V35: 待定 | Y35: 2.17 | Z35: =J35*Y35 -> 0 | AA35: =Z35*7.75 -> 0 | AE35: 印尼 | AI35: 45756 | AJ35: 印尼备料 | AO35: =M35-A35 -> 55 | AP35: =M35-AI35 -> 42
A36: 45782 | C36: 比利时 | D36: TOMY UK CO LTD | E36: Gary | F36: 10100962 | G36: 4500031036 | H36: T73785EN | I36: =VLOOKUP(H36,名称!A:C,2,0) -> 游戏转盘 | J36: =2502-2502 -> 0 | K36: =VLOOKUP(H36,名称!A:D,3,0) -> 6 | L36: =J36/K36 -> 0 | M36: 45882 | N36: =M36-2 -> 45880 | U36: G1525RR02 | V36: 标准唛+TTT | W36: OK | Y36: 4.58 | Z36: =J36*Y36 -> 0 | AA36: =Z36*7.75 -> 0 | AE36: 印尼 | AN36: 45813 | AO36: =M36-A36 -> 100 | AP36: =M36-AI36 -> 45882
A37: 45782 | C37: 比利时 | D37: TOMY UK CO LTD | E37: Gary | F37: 10100962 | G37: 4500031036 | H37: T73785EN | I37: =VLOOKUP(H37,名称!A:C,2,0) -> 游戏转盘 | J37: =2502-2502 -> 0 | K37: =VLOOKUP(H37,名称!A:D,3,0) -> 6 | L37: =J37/K37 -> 0 | M37: 45896 | N37: =M37-2 -> 45894 | U37: G1525RR02 | V37: 标准唛+TTT | W37: OK | Y37: 4.58 | Z37: =J37*Y37 -> 0 | AA37: =Z37*7.75 -> 0 | AE37: 印尼 | AN37: 45813 | AO37: =M37-A37 -> 114 | AP37: =M37-AI37 -> 45896
A38: 45743 | C38: 美国 | D38: TOMY COMPANY, LTD. (TKY-US) | E38: Olivia | F38: MPO | G38: 202508070032 | H38: E73622A | I38: =VLOOKUP(H38,名称!A:C,2,0) -> 布鲁伊家族杯子套装 | J38: =6200+2148+14992+16-5008-3576-4016-4500-6256 -> 0 | K38: =VLOOKUP(H38,名称!A:D,3,0) -> 4 | L38: =J38/K38 -> 0 | M38: 45812 | N38: =M38-2 -> 45810 | P38: 45783 | Q38: 45813 | R38: 4/23寄出 | T38: 4/24收到JD贴纸 | U38: D1525RR02 | V38: 待定 | Y38: 2.17 | Z38: =J38*Y38 -> 0 | AA38: =Z38*7.75 -> 0 | AE38: 印尼 | AI38: 45764 | AJ38: 印尼备料 | AN38: 45759 | AO38: =M38-A38 -> 69 | AP38: =M38-AI38 -> 48
A39: 45721 | C39: 美国 | D39: TOMY COMPANY, LTD. (TKY-US) | E39: Olivia | F39: MPO | G39: 202506370043 | H39: 47669 | I39: =VLOOKUP(H39,[1]名称!A:C,2,0) -> 动物车 | J39: =800-748-52 -> 0 | K39: =VLOOKUP(H39,[1]名称!A:D,3,0) -> 4 | L39: =J39/K39 -> 0 | M39: 45805 | N39: =M39-2 -> 45803 | P39: 45791 | Q39: 45791 | R39: 5/5寄出 | U39: E1325RR02 | V39: 待定 | Y39: 4.81 | Z39: =J39*Y39 -> 0 | AA39: =Z39*7.75 -> 0 | AE39: 印尼 | AI39: 45749 | AJ39: 45750 | AO39: =M39-A39 -> 84 | AP39: =M39-AI39 -> 56
A40: 45721 | C40: 美国 | D40: TOMY COMPANY, LTD. (TKY-US) | E40: Olivia | F40: MPO | G40: 202506370043 | H40: 47674 | I40: =VLOOKUP(H40,[1]名称!A:C,2,0) -> JD LNS圆轮拖拉机 | J40: =782-736-46 -> 0 | K40: =VLOOKUP(H40,[1]名称!A:D,3,0) -> 2 | L40: =J40/K40 -> 0 | M40: 45805 | N40: =M40-2 -> 45803 | P40: 45758 | Q40: 45758 | R40: 4/23寄出 | U40: E1325RR02 | V40: 待定 | Y40: 4.79 | Z40: =J40*Y40 -> 0 | AA40: =Z40*7.75 -> 0 | AE40: 印尼 | AI40: 45743 | AJ40: 印尼备料 | AL40: 45715 | AO40: =M40-A40 -> 84 | AP40: =M40-AI40 -> 62
...

Sheet Sheet1
A1: 货号 | B1: 接单 | C1: 排期 | D1: 走货 | E1: 相差 | F1: 接单 | G1: 排期 | H1: 走货 | I1: 相差
A2: 47669 | B2: =SUMIF(总接单!E:EF,A2,总接单!F:F) -> 0 | C2: =SUMIF(总排期!H:H,A2,总排期!J:J) -> 0 | D2: =SUMIF(已走货!H:H,A2,已走货!J:J) -> 0 | E2: =B2-C2-D2 -> 0 | F2: =SUMIF(总接单!E:E,A2,总接单!CG:CG) -> 0 | G2: =SUMIF(总排期!H:H,A2,总排期!AA:AA) -> 0 | H2: =SUMIF(已走货!H:H,A2,已走货!AA:AA) -> 0 | I2: =F2-G2-H2 -> 0
A3: 47674 | B3: =SUMIF(总接单!E:EF,A3,总接单!F:F) -> 47682 | C3: =SUMIF(总排期!H:H,A3,总排期!J:J) -> 0 | D3: =SUMIF(已走货!H:H,A3,已走货!J:J) -> 0 | E3: =B3-C3-D3 -> 47682 | F3: =SUMIF(总接单!E:E,A3,总接单!CG:CG) -> 0 | G3: =SUMIF(总排期!H:H,A3,总排期!AA:AA) -> 0 | H3: =SUMIF(已走货!H:H,A3,已走货!AA:AA) -> 0 | I3: =F3-G3-H3 -> 0
A4: 096283(E73907) | B4: =SUMIF(总接单!E:EF,A4,总接单!F:F) -> 0 | C4: =SUMIF(总排期!H:H,A4,总排期!J:J) -> 0 | D4: =SUMIF(已走货!H:H,A4,已走货!J:J) -> 0 | E4: =B4-C4-D4 -> 0 | F4: =SUMIF(总接单!E:E,A4,总接单!CG:CG) -> 0 | G4: =SUMIF(总排期!H:H,A4,总排期!AA:AA) -> 0 | H4: =SUMIF(已走货!H:H,A4,已走货!AA:AA) -> 0 | I4: =F4-G4-H4 -> 0
A5: 35802J | B5: =SUMIF(总接单!E:EF,A5,总接单!F:F) -> 0 | C5: =SUMIF(总排期!H:H,A5,总排期!J:J) -> 0 | D5: =SUMIF(已走货!H:H,A5,已走货!J:J) -> 0 | E5: =B5-C5-D5 -> 0 | F5: =SUMIF(总接单!E:E,A5,总接单!CG:CG) -> 0 | G5: =SUMIF(总排期!H:H,A5,总排期!AA:AA) -> 0 | H5: =SUMIF(已走货!H:H,A5,已走货!AA:AA) -> 0 | I5: =F5-G5-H5 -> 0
A6: 46720J | B6: =SUMIF(总接单!E:EF,A6,总接单!F:F) -> 0 | C6: =SUMIF(总排期!H:H,A6,总排期!J:J) -> 0 | D6: =SUMIF(已走货!H:H,A6,已走货!J:J) -> 0 | E6: =B6-C6-D6 -> 0 | F6: =SUMIF(总接单!E:E,A6,总接单!CG:CG) -> 0 | G6: =SUMIF(总排期!H:H,A6,总排期!AA:AA) -> 0 | H6: =SUMIF(已走货!H:H,A6,已走货!AA:AA) -> 0 | I6: =F6-G6-H6 -> 0
A7: 47101J | B7: =SUMIF(总接单!E:EF,A7,总接单!F:F) -> 0 | C7: =SUMIF(总排期!H:H,A7,总排期!J:J) -> 0 | D7: =SUMIF(已走货!H:H,A7,已走货!J:J) -> 0 | E7: =B7-C7-D7 -> 0 | F7: =SUMIF(总接单!E:E,A7,总接单!CG:CG) -> 0 | G7: =SUMIF(总排期!H:H,A7,总排期!AA:AA) -> 0 | H7: =SUMIF(已走货!H:H,A7,已走货!AA:AA) -> 0 | I7: =F7-G7-H7 -> 0
A8: 47274J | B8: =SUMIF(总接单!E:EF,A8,总接单!F:F) -> 0 | C8: =SUMIF(总排期!H:H,A8,总排期!J:J) -> 0 | D8: =SUMIF(已走货!H:H,A8,已走货!J:J) -> 0 | E8: =B8-C8-D8 -> 0 | F8: =SUMIF(总接单!E:E,A8,总接单!CG:CG) -> 0 | G8: =SUMIF(总排期!H:H,A8,总排期!AA:AA) -> 0 | H8: =SUMIF(已走货!H:H,A8,已走货!AA:AA) -> 0 | I8: =F8-G8-H8 -> 0
A9: 47367J | B9: =SUMIF(总接单!E:EF,A9,总接单!F:F) -> 0 | C9: =SUMIF(总排期!H:H,A9,总排期!J:J) -> 0 | D9: =SUMIF(已走货!H:H,A9,已走货!J:J) -> 0 | E9: =B9-C9-D9 -> 0 | F9: =SUMIF(总接单!E:E,A9,总接单!CG:CG) -> 0 | G9: =SUMIF(总排期!H:H,A9,总排期!AA:AA) -> 0 | H9: =SUMIF(已走货!H:H,A9,已走货!AA:AA) -> 0 | I9: =F9-G9-H9 -> 0
A10: 47391J | B10: =SUMIF(总接单!E:EF,A10,总接单!F:F) -> 0 | C10: =SUMIF(总排期!H:H,A10,总排期!J:J) -> 0 | D10: =SUMIF(已走货!H:H,A10,已走货!J:J) -> 0 | E10: =B10-C10-D10 -> 0 | F10: =SUMIF(总接单!E:E,A10,总接单!CG:CG) -> 0 | G10: =SUMIF(总排期!H:H,A10,总排期!AA:AA) -> 0 | H10: =SUMIF(已走货!H:H,A10,已走货!AA:AA) -> 0 | I10: =F10-G10-H10 -> 0
A11: 47465J1 | B11: =SUMIF(总接单!E:EF,A11,总接单!F:F) -> 0 | C11: =SUMIF(总排期!H:H,A11,总排期!J:J) -> 0 | D11: =SUMIF(已走货!H:H,A11,已走货!J:J) -> 0 | E11: =B11-C11-D11 -> 0 | F11: =SUMIF(总接单!E:E,A11,总接单!CG:CG) -> 0 | G11: =SUMIF(总排期!H:H,A11,总排期!AA:AA) -> 0 | H11: =SUMIF(已走货!H:H,A11,已走货!AA:AA) -> 0 | I11: =F11-G11-H11 -> 0
A12: 47600J | B12: =SUMIF(总接单!E:EF,A12,总接单!F:F) -> 0 | C12: =SUMIF(总排期!H:H,A12,总排期!J:J) -> 0 | D12: =SUMIF(已走货!H:H,A12,已走货!J:J) -> 0 | E12: =B12-C12-D12 -> 0 | F12: =SUMIF(总接单!E:E,A12,总接单!CG:CG) -> 0 | G12: =SUMIF(总排期!H:H,A12,总排期!AA:AA) -> 0 | H12: =SUMIF(已走货!H:H,A12,已走货!AA:AA) -> 0 | I12: =F12-G12-H12 -> 0
A13: 47602J | B13: =SUMIF(总接单!E:EF,A13,总接单!F:F) -> 0 | C13: =SUMIF(总排期!H:H,A13,总排期!J:J) -> 0 | D13: =SUMIF(已走货!H:H,A13,已走货!J:J) -> 0 | E13: =B13-C13-D13 -> 0 | F13: =SUMIF(总接单!E:E,A13,总接单!CG:CG) -> 0 | G13: =SUMIF(总排期!H:H,A13,总排期!AA:AA) -> 0 | H13: =SUMIF(已走货!H:H,A13,已走货!AA:AA) -> 0 | I13: =F13-G13-H13 -> 0
A14: 47669TSC | B14: =SUMIF(总接单!E:EF,A14,总接单!F:F) -> 0 | C14: =SUMIF(总排期!H:H,A14,总排期!J:J) -> 0 | D14: =SUMIF(已走货!H:H,A14,已走货!J:J) -> 0 | E14: =B14-C14-D14 -> 0 | F14: =SUMIF(总接单!E:E,A14,总接单!CG:CG) -> 0 | G14: =SUMIF(总排期!H:H,A14,总排期!AA:AA) -> 0 | H14: =SUMIF(已走货!H:H,A14,已走货!AA:AA) -> 0 | I14: =F14-G14-H14 -> 0
A15: 47674DG | B15: =SUMIF(总接单!E:EF,A15,总接单!F:F) -> 0 | C15: =SUMIF(总排期!H:H,A15,总排期!J:J) -> 0 | D15: =SUMIF(已走货!H:H,A15,已走货!J:J) -> 0 | E15: =B15-C15-D15 -> 0 | F15: =SUMIF(总接单!E:E,A15,总接单!CG:CG) -> 0 | G15: =SUMIF(总排期!H:H,A15,总排期!AA:AA) -> 0 | H15: =SUMIF(已走货!H:H,A15,已走货!AA:AA) -> 0 | I15: =F15-G15-H15 -> 0
... A52: 马里奥身子搪胶件+帽子 | B52: =SUMIF(总接单!E:EF,A52,总接单!F:F) -> 0 | C52: =SUMIF(总排期!H:H,A52,总排期!J:J) -> 0 | D52: =SUMIF(已走货!H:H,A52,已走货!J:J) -> 0 | E52: =B52-C52-D52 -> 0 | F52: =SUMIF(总接单!E:E,A52,总接单!CG:CG) -> 0 | G52: =SUMIF(总排期!H:H,A52,总排期!AA:AA) -> 0 | H52: =SUMIF(已走货!H:H,A52,已走货!AA:AA) -> 0 | I52: =F52-G52-H52 -> 0
