Workbook
Name _CER10: #REF!
Name _CER10: #REF!
Name _CER10: #REF!

Sheet 名称
A1: 货号 | B1: 名称 | C1: 装箱数 | D1: 彩盒UPC条码
A2: T01535 | B2: 恐龙公园 | C2: 12
A3: JW-RV-RPGE | B3: 恐龙游戏盘 | C3: 6
A4: T01453 | B4: 恐龙游戏盘 | C4: 2
A5: T01685 | B5: 手术游戏盘 | C5: 6
A6: T01685-S | B6: 手术游戏盘 | C6: 6
A7: JW-RV-RPGE-3PK | B7: 恐龙游戏盘 | C7: 3
A8: JW-RV-RPGEA | B8: 恐龙游戏盘(邮包盒装) | C8: 6
A9: T01453 | B9: 恐龙游戏盘 | C9: 2
A10: T01685 | B10: 手术游戏盘 | C10: 6
A11: T02444 | B11: 恐龙公园二代 | C11: 12
A12: T02943 | B12: 9.5寸粉红熊公仔（移印） | C12: 2
A13: T02943-2 | B13: 9.5寸粉红熊公仔（移印） | C13: 2
... A29: T03942-DS | B29: 恐龙公园二代--实验室 | C29: 12

Sheet 总接单
A1: 接单期 | B1: 国家 | C1: 客户 | D1: Customer | E1: PO号 | F1: 货号 | G1: 数量 | H1: 出货日期 | I1: JW-RV-RPGE | J1: JW-RV-RPGEA | K1: T01453 | L1: T01535 | M1: T02444 | N1: T03804 | O1: T01685-S | P1: T01685A | Q1: T02428 | V1: T02945-2 | X1: T02943-2 | Y1: T03190 | Z1: T03191 | AA1: T03192 | AB1: T03900-9.5寸漫画系列 | AF1: T03349-3寸可爱系列 | AM1: T03980 | AO1: T03937-DS | AP1: T03938-DS | AQ1: T03939-DS | AR1: T03940-DS | AS1: T03941-DS | AT1: T03942-DS | AX1: 单价USD$ | AY1: 金额USD$ | AZ1: 金额HK$ | BA1: 国家 | BB1: =C1 -> 客户
I2: 恐龙游戏盘 | J2: 恐龙游戏盘 | K2: 恐龙游戏盘 | L2: 恐龙公园 | M2: 恐龙公园S2 | N2: 恐龙公园S2 | O2: 手术游戏盘 | Q2: 涂鸦公仔 | R2: 格力奇公仔 | S2: 绿色油淋公仔 | T2: 粉红熊公仔 | U2: 涂鸦公仔（移印办） | V2: 格力奇公仔（移印办） | W2: 绿色油淋公仔（移印办） | X2: 粉红熊公仔（移印办） | Y2: 弗莱尔 | Z2: 前锋 | AA2: 大心脏 | AB2: 漫画熊 | AC2: 战士熊 | AD2: 小女孩 | AE2: 大眼睛 | AF2: 寿司狗 | AG2: 柯基 | AH2: 爱心柴犬 | AI2: 爱心猫 | AJ2: 仙人掌 | AK2: 鸡尾酒 | AL2: 可爱熊猫 | AM2: 9.5寸绿色淋油公仔 | AN2: 9.5寸涂鸦公仔 | AO2: 一代陆地 | AP2: 一代海洋 | AQ2: 一代天空 | AR2: 二代海滩 | AS2: 二代雨林 | AT2: 二代实验室
A3: 45967 | B3: 越南 | C3: Viet Tinh Anh Joint Stock Company | D3: Viet-TM110225 | E3: PO211348 | F3: T02444 | G3: 1680 | H3: 46021 | M3: =G3 -> 1680 | AX3: 2.1 | AY3: =SUM(I3:AW3)*AX3 -> 3528 | AZ3: =AY3*7.75 -> 27342 | BA3: =B3 -> 越南 | BB3: =C3 -> Viet Tinh Anh Joint Stock Company
A4: 45981 | B4: 乌克兰 | C4: AMIGO & F Ltd | D4: Kuma Paw 0126 | E4: PO211615 | F4: T02943-2 | G4: 800 | H4: 46047 | X4: =G4 -> 800 | AX4: 6.2 | AY4: =SUM(I4:AW4)*AX4 -> 4960 | AZ4: =AY4*7.75 -> 38440 | BA4: =B4 -> 乌克兰 | BB4: =C4 -> AMIGO & F Ltd
A5: 45981 | B5: 乌克兰 | C5: AMIGO & F Ltd | D5: Kuma Paw 0126 | E5: PO211615 | F5: T02945-2 | G5: 800 | H5: 46047 | V5: =G5 -> 800 | AX5: 6.5 | AY5: =SUM(I5:AW5)*AX5 -> 5200 | AZ5: =AY5*7.75 -> 40300 | BA5: =B5 -> 乌克兰 | BB5: =C5 -> AMIGO & F Ltd
A6: 45986 | B6: 美国 | C6: Monster Group LLC | D6: WM Domestic Order | E6: PO211734 | F6: T02943-2 | G6: 2304 | H6: 46047 | X6: =G6 -> 2304 | AX6: 6.2 | AY6: =SUM(I6:AW6)*AX6 -> 14284.8 | AZ6: =AY6*7.75 -> 110707.2 | BA6: =B6 -> 美国 | BB6: =C6 -> Monster Group LLC
A7: 45986 | B7: 美国 | C7: Monster Group LLC | D7: WM Domestic Order | E7: PO211734 | F7: T02945-2 | G7: 2304 | H7: 46047 | V7: =G7 -> 2304 | AX7: 6.5 | AY7: =SUM(I7:AW7)*AX7 -> 14976 | AZ7: =AY7*7.75 -> 116064 | BA7: =B7 -> 美国 | BB7: =C7 -> Monster Group LLC
A8: 45986 | B8: 美国 | C8: Monster Group LLC | D8: WM Domestic Order | E8: PO212369 | F8: T02943-2 | G8: 2500 | H8: 46086 | X8: =G8 -> 2500 | AX8: 6.2 | AY8: =SUM(I8:AW8)*AX8 -> 15500 | AZ8: =AY8*7.75 -> 120125 | BA8: =B8 -> 美国 | BB8: =C8 -> Monster Group LLC
A9: 45986 | B9: 美国 | C9: Monster Group LLC | D9: WM Domestic Order | E9: PO212369 | F9: T02945-2 | G9: 2500 | H9: 46086 | V9: =G9 -> 2500 | AX9: 6.5 | AY9: =SUM(I9:AW9)*AX9 -> 16250 | AZ9: =AY9*7.75 -> 125937.5 | BA9: =B9 -> 美国 | BB9: =C9 -> Monster Group LLC
A10: 45989 | B10: 澳大利亚 | C10: Woolworths Group Limited t/a Big W | D10: 47895690 | E10: PO211747 | F10: JW-RV-RPGE | G10: 1014 | H10: 46040 | I10: =G10 -> 1014 | AX10: 4.5 | AY10: =SUM(I10:AW10)*AX10 -> 4563 | AZ10: =AY10*7.75 -> 35363.25 | BA10: =B10 -> 澳大利亚 | BB10: =C10 -> Woolworths Group Limited t/a Big W
A11: 45989 | B11: 澳大利亚 | C11: Woolworths Group Limited t/a Big W | D11: 47896520 | E11: PO211748 | F11: JW-RV-RPGE | G11: 624 | H11: 46040 | I11: =G11 -> 624 | AX11: 4.5 | AY11: =SUM(I11:AW11)*AX11 -> 2808 | AZ11: =AY11*7.75 -> 21762 | BA11: =B11 -> 澳大利亚 | BB11: =C11 -> Woolworths Group Limited t/a Big W
A12: 45993 | B12: 新加坡 | C12: Sheng Tai Toys Pty Ltd | D12: Shengtai-TM110464 | E12: PO211605 | F12: T02444 | G12: 1200 | H12: 46083 | M12: =G12 -> 1200 | AX12: 2.1 | AY12: =SUM(I12:AW12)*AX12 -> 2520 | AZ12: =AY12*7.75 -> 19530 | BA12: =B12 -> 新加坡 | BB12: =C12 -> Sheng Tai Toys Pty Ltd
A13: 45996 | B13: 香港 | C13: Asia Goal Limited | D13: PO-AG250344 | E13: PO211794 | F13: T02444 | G13: 720 | H13: 46037 | M13: =G13 -> 720 | AX13: 2.1 | AY13: =SUM(I13:AW13)*AX13 -> 1512 | AZ13: =AY13*7.75 -> 11718 | BA13: =B13 -> 香港 | BB13: =C13 -> Asia Goal Limited
A14: 46010 | B14: 美国 | C14: Monster Group LLC | D14: WM Domestic Order | E14: PO212104 | F14: T03190 | G14: 4676 | H14: 46058 | Y14: =G14 -> 4676 | AX14: 6.15 | AY14: =SUM(I14:AW14)*AX14 -> 28757.4 | AZ14: =AY14*7.75 -> 222869.85 | BA14: =B14 -> 美国 | BB14: =C14 -> Monster Group LLC
A15: 46010 | B15: 美国 | C15: Monster Group LLC | D15: WM Domestic Order | E15: PO212104 | F15: T03191 | G15: 4376 | H15: 46058 | Z15: =G15 -> 4376 | AX15: 6.47 | AY15: =SUM(I15:AW15)*AX15 -> 28312.72 | AZ15: =AY15*7.75 -> 219423.58 | BA15: =B15 -> 美国 | BB15: =C15 -> Monster Group LLC
A16: 46010 | B16: 美国 | C16: Monster Group LLC | D16: WM Domestic Order | E16: PO212104 | F16: T03192 | G16: 4476 | H16: 46058 | AA16: =G16 -> 4476 | AX16: 5.59 | AY16: =SUM(I16:AW16)*AX16 -> 25020.84 | AZ16: =AY16*7.75 -> 193911.51 | BA16: =B16 -> 美国 | BB16: =C16 -> Monster Group LLC
A17: 46010 | B17: 澳大利亚 | C17: Woolworths Group Limited t/a Big W | D17: 47905042 | E17: PO212018 | F17: JW-RV-RPGE | G17: 1200 | H17: 46048 | I17: =G17 -> 1200 | AX17: 4.5 | AY17: =SUM(I17:AW17)*AX17 -> 5400 | AZ17: =AY17*7.75 -> 41850 | BA17: =B17 -> 澳大利亚 | BB17: =C17 -> Woolworths Group Limited t/a Big W
A18: 46030 | B18: 中国台湾 | C18: Asia Goal Limited | D18: PO-AG250418 | E18: PO212218 | F18: T02444 | G18: 780 | H18: 46101 | M18: =G18 -> 780 | AX18: 2.1 | AY18: =SUM(I18:AW18)*AX18 -> 1638 | AZ18: =AY18*7.75 -> 12694.5 | BA18: =B18 -> 中国台湾 | BB18: =C18 -> Asia Goal Limited
A19: 46030 | B19: 中国台湾 | C19: Asia Goal Limited | D19: PO-AG250418 | E19: PO212218 | F19: JW-RV-RPGE | G19: 180 | H19: 46101 | I19: =G19 -> 180 | AX19: 4.5 | AY19: =SUM(I19:AW19)*AX19 -> 810 | AZ19: =AY19*7.75 -> 6277.5 | BA19: =B19 -> 中国台湾 | BB19: =C19 -> Asia Goal Limited
A20: 46030 | B20: 中国台湾 | C20: Asia Goal Limited | D20: PO-AG250418 | E20: PO212218 | F20: T01685 | G20: 180 | H20: 46101 | O20: =G20 -> 180 | AM20: =AC20 -> 0 | AO20: =Z20 -> 0 | AP20: =AA20 -> 0 | AQ20: =AB20 -> 0 | AR20: =AC20 -> 0 | AS20: =AD20 -> 0 | AT20: =AE20 -> 0 | AX20: 4.43 | AY20: =SUM(I20:AW20)*AX20 -> 797.4 | AZ20: =AY20*7.75 -> 6179.85 | BA20: =B20 -> 中国台湾 | BB20: =C20 -> Asia Goal Limited
A21: 46038 | B21: 美国 | C21: Meijer LANSING | D21: 218955615 | E21: PO212267 | F21: T01453 | G21: 1000 | H21: 46092 | K21: =G21 -> 1000 | AX21: 4.5 | AY21: =SUM(I21:AW21)*AX21 -> 4500 | AZ21: =AY21*7.75 -> 34875 | BA21: =B21 -> 美国 | BB21: =C21 -> Meijer LANSING
A22: 46038 | B22: 美国 | C22: Meijer LANSING | D22: 218955627 | E22: PO212268 | F22: T01453 | G22: 500 | H22: 46092 | K22: =G22 -> 500 | AX22: 4.5 | AY22: =SUM(I22:AW22)*AX22 -> 2250 | AZ22: =AY22*7.75 -> 17437.5 | BA22: =B22 -> 美国 | BB22: =C22 -> Meijer LANSING
A23: 46049 | B23: 澳大利亚 | C23: Woolworths Group Limited t/a Big W | D23: 47908798 | E23: PO212336 | F23: JW-RV-RPGE | G23: 1200 | H23: 46100 | I23: 1200 | AX23: 4.5 | AY23: =SUM(I23:AW23)*AX23 -> 5400 | AZ23: =AY23*7.75 -> 41850 | BA23: =B23 -> 澳大利亚 | BB23: =C23 -> Woolworths Group Limited t/a Big W
A24: 46051 | B24: 美国 | C24: Meijer LANSING | D24: 219021251 | E24: PO212355 | F24: T01453 | G24: 1000 | H24: 46106 | K24: 1000 | AX24: 4.5 | AY24: =SUM(I24:AW24)*AX24 -> 4500 | AZ24: =AY24*7.75 -> 34875 | BA24: =B24 -> 美国 | BB24: =C24 -> Meijer LANSING
A25: 46051 | B25: 美国 | C25: Meijer LANSING | D25: 219021257 | E25: PO212356 | F25: T01453 | G25: 500 | H25: 46106 | K25: 500 | AX25: 4.5 | AY25: =SUM(I25:AW25)*AX25 -> 2250 | AZ25: =AY25*7.75 -> 17437.5 | BA25: =B25 -> 美国 | BB25: =C25 -> Meijer LANSING
A26: 46062 | B26: 英国 | C26: Smyths Toys HQ UC | D26: 4400542038 | E26: PO212408 | F26: JW-RV-RPGE | G26: 6306 | H26: 46111 | I26: 6306 | AX26: 4.5 | AY26: =SUM(I26:AW26)*AX26 -> 28377 | AZ26: =AY26*7.75 -> 219921.75 | BA26: =B26 -> 英国 | BB26: =C26 -> Smyths Toys HQ UC
A27: 46077 | B27: 美国 | C27: Monster Group LLC | D27: Kuma Paw 9.5 inch for WM Domestic Order | E27: PO212438 | F27: T03204 | G27: 5400 | H27: 46141 | V27: =G27/2 -> 2700 | X27: =G27/2 -> 2700 | AX27: 6.67 | AY27: =SUM(I27:AW27)*AX27 -> 36018 | AZ27: =AY27*7.75 -> 279139.5 | BA27: =B27 -> 美国 | BB27: =C27 -> Monster Group LLC
A28: 46083 | B28: 新西兰 | C28: Kmart Australia & NZ Holding Limited | D28: 21559600 | E28: PO212479 | F28: T02444 | G28: 564 | H28: 46122 | M28: =G28 -> 564 | AX28: 2.1 | AY28: =SUM(I28:AW28)*AX28 -> 1184.4 | AZ28: =AY28*7.75 -> 9179.1 | BA28: =B28 -> 新西兰 | BB28: =C28 -> Kmart Australia & NZ Holding Limited
A29: 46083 | B29: 澳大利亚 | C29: Kmart Australia & NZ Holding Limited | D29: 21559598 | E29: PO212478 | F29: T02444 | G29: 6156 | H29: 46122 | M29: =G29 -> 6156 | AX29: 2.1 | AY29: =SUM(I29:AW29)*AX29 -> 12927.6 | AZ29: =AY29*7.75 -> 100188.9 | BA29: =B29 -> 澳大利亚 | BB29: =C29 -> Kmart Australia & NZ Holding Limited
A30: 46086 | B30: 美国 | C30: Flybar Inc | D30: FB-7504 | E30: PO212516 | F30: JW-RV-RPGEA | G30: 504 | H30: 46127 | K30: 504 | AX30: 4.9 | AY30: =SUM(I30:AW30)*AX30 -> 2469.6 | AZ30: =AY30*7.75 -> 19139.4 | BA30: =B30 -> 美国 | BB30: =C30 -> Flybar Inc
A31: 46102 | B31: 加拿大 | C31: Lachine | D31: 004980 | E31: PO212541 | F31: T03804 | G31: 2964 | H31: 46157 | N31: =G31 -> 2964 | AX31: 2.1 | AY31: =SUM(I31:AW31)*AX31 -> 6224.4 | AZ31: =AY31*7.75 -> 48239.1 | BA31: =B31 -> 加拿大 | BB31: =C31 -> Lachine
A32: 46101 | B32: 澳大利亚 | C32: Kmart Australia & NZ Holding Limited | D32: 21657135 | E32: PO212624 | F32: T02444 | G32: 6288 | H32: 46135 | M32: =G32 -> 6288 | AX32: 2.1 | AY32: =SUM(I32:AW32)*AX32 -> 13204.8 | AZ32: =AY32*7.75 -> 102337.2 | BA32: =B32 -> 澳大利亚 | BB32: =C32 -> Kmart Australia & NZ Holding Limited
A33: 46101 | B33: 澳大利亚 | C33: Kmart Australia & NZ Holding Limited | D33: 21602319 | E33: PO212625 | F33: T02444 | G33: 432 | H33: 46129 | M33: =G33 -> 432 | AX33: 2.1 | AY33: =SUM(I33:AW33)*AX33 -> 907.2 | AZ33: =AY33*7.75 -> 7030.8 | BA33: =B33 -> 澳大利亚 | BB33: =C33 -> Kmart Australia & NZ Holding Limited
A34: 46101 | B34: 澳大利亚 | C34: Target Australia Pty Ltd | D34: 2617376 | E34: PO212775 | F34: T02444 | G34: 1800 | H34: 46135 | M34: =G34 -> 1800 | AX34: 2.1 | AY34: =SUM(I34:AW34)*AX34 -> 3780 | AZ34: =AY34*7.75 -> 29295 | BA34: =B34 -> 澳大利亚 | BB34: =C34 -> Target Australia Pty Ltd
A35: 46101 | B35: 澳大利亚 | C35: Target Australia Pty Ltd | D35: 2617377 | E35: PO213307 | F35: T02444 | G35: 1800 | H35: 46176 | M35: =G35 -> 1800 | AX35: 2.1 | AY35: =SUM(I35:AW35)*AX35 -> 3780 | AZ35: =AY35*7.75 -> 29295 | BA35: =B35 -> 澳大利亚 | BB35: =C35 -> Target Australia Pty Ltd
A36: 46101 | B36: 澳大利亚 | C36: Target Australia Pty Ltd | D36: 2617378 | E36: PO213308 | F36: T02444 | G36: 1200 | H36: 46211 | M36: =G36 -> 1200 | AX36: 2.1 | AY36: =SUM(I36:AW36)*AX36 -> 2520 | AZ36: =AY36*7.75 -> 19530 | BA36: =B36 -> 澳大利亚 | BB36: =C36 -> Target Australia Pty Ltd
A37: 46101 | B37: 澳大利亚 | C37: Target Australia Pty Ltd | D37: 2617379 | E37: PO213309 | F37: T02444 | G37: 1500 | H37: 46245 | M37: =G37 -> 1500 | AX37: 2.1 | AY37: =SUM(I37:AW37)*AX37 -> 3150 | AZ37: =AY37*7.75 -> 24412.5 | BA37: =B37 -> 澳大利亚 | BB37: =C37 -> Target Australia Pty Ltd
A38: 46101 | B38: 澳大利亚 | C38: Target Australia Pty Ltd | D38: 2617380 | E38: PO213310 | F38: T02444 | G38: 1200 | H38: 46267 | M38: =G38 -> 1200 | AX38: 2.1 | AY38: =SUM(I38:AW38)*AX38 -> 2520 | AZ38: =AY38*7.75 -> 19530 | BA38: =B38 -> 澳大利亚 | BB38: =C38 -> Target Australia Pty Ltd
A39: 46114 | B39: 美国 | C39: Flybar Inc | D39: FB-7781 | E39: PO212868 | F39: JW-RV-RPGEA | G39: 1002 | H39: 46160 | J39: =G39 -> 1002 | AX39: 4.9 | AY39: =SUM(I39:AW39)*AX39 -> 4909.8 | AZ39: =AY39*7.75 -> 38050.95 | BA39: =B39 -> 美国 | BB39: =C39 -> Flybar Inc
A40: 46114 | B40: 美国 | C40: Flybar Inc | D40: FB-7782 | E40: PO212869 | F40: JW-RV-RPGEA | G40: 1002 | H40: 46160 | J40: =G40 -> 1002 | AX40: 4.9 | AY40: =SUM(I40:AW40)*AX40 -> 4909.8 | AZ40: =AY40*7.75 -> 38050.95 | BA40: =B40 -> 美国 | BB40: =C40 -> Flybar Inc
...

Sheet 正在做货
A1: 接单期 | B1: 国家 | C1: 客跟单 | D1: 客户 | E1: Customer PO | F1: PO号 | G1: 货号 | H1: 名称 | I1: 数量 | J1: 装箱数 | K1: 总箱数 | L1: 客PO期 | M1: 出货期 | N1: 验货期 | O1: 是否约验货 | P1: 验货结果 | Q1: 船期SO | R1: 吨车/柜货 | S1: 生产车间 | T1: 箱唛资料 | U1: 客贴纸 | V1: 是否寄出签办 | W1: 是否打卡板 | X1: 彩盒UPC条码 | Y1: 彩盒版本 | Z1: 说明书版本 | AA1: 日期码 | AB1: 备注 | AC1: 单价 | AD1: 金额USD | AE1: 金额HKD | AF1: 发票号 | AG1: 走柜/散货 | AH1: 出货日期 | AI1: 是否入系统 | AJ1: 下单情况 | AK1: 贴纸情况 | AL1: 首期扣数
A2: 46101 | B2: 澳大利亚 | C2: Rachel | D2: Target Australia Pty Ltd | E2: 2617379 | F2: PO213309 | G2: T02444 | H2: =VLOOKUP(G2,名称!A:B,2,0) -> 恐龙公园二代 | I2: 1500 | J2: =VLOOKUP(G2,名称!A:C,3,FALSE) -> 12 | K2: =I2/J2 -> 125 | L2: 46247 | M2: 46241 | N2: 46241 | O2: 已约 | P2: pass | Q2: Extra Costs：$6.875 | T2: OK | U2: SSCC贴纸 | X2: 草地套装：0840148226203 海滩滩套装：0840148226210 实验室套装：0840148226227 | Y2: 标准美文版本 （13位数UPC条码） | Z2: 美文版本说明书 | AA2: 46260 | AB2: 普通透明胶带封箱，外箱不需要盖日期码 | AC2: 2.1 | AD2: =AC2*I2 -> 3150 | AE2: =AD2*7.75 -> 24412.5 | AI2: 已入系统 | AK2: SSCC贴纸4/23给到佩玲 | AL2: =IFERROR(VLOOKUP(G2,'已打发票扣数（26年5月开始）'!$A$1:$C$17,3,0)*I2*0.3,"") -> 945
A3: 46101 | B3: 澳大利亚 | C3: Rachel | D3: Target Australia Pty Ltd | E3: 2617380 | F3: PO213310 | G3: T02444 | H3: =VLOOKUP(G3,名称!A:B,2,0) -> 恐龙公园二代 | I3: 1200 | J3: =VLOOKUP(G3,名称!A:C,3,FALSE) -> 12 | K3: =I3/J3 -> 100 | L3: 46274 | M3: =L3-7 -> 46267 | N3: =M3 -> 46267 | Q3: Extra Costs：$5.5 | T3: OK | U3: SSCC贴纸 | X3: 草地套装：0840148226203 海滩滩套装：0840148226210 实验室套装：0840148226227 | Y3: 标准美文版本 （13位数UPC条码） | Z3: 美文版本说明书 | AA3: 46291 | AB3: 普通透明胶带封箱，外箱不需要盖日期码 | AC3: 2.1 | AD3: =AC3*I3 -> 2520 | AE3: =AD3*7.75 -> 19530 | AI3: 已入系统 | AK3: SSCC贴纸4/23给到佩玲 | AL3: =IFERROR(VLOOKUP(G3,'已打发票扣数（26年5月开始）'!$A$1:$C$17,3,0)*I3*0.3,"") -> 756
A4: 46114 | B4: 美国-亚马逊 | C4: Elaine | D4: Flybar Inc | E4: FB-7783 | F4: PO212870 | G4: JW-RV-RPGEA | H4: =VLOOKUP(G4,名称!A:B,2,0) -> 恐龙游戏盘(邮包盒装) | I4: 1002 | J4: =VLOOKUP(G4,名称!A:C,3,FALSE) -> 6 | K4: =I4/J4 -> 167 | L4: 46167 | M4: 46163 | N4: 46163 | O4: 已约 | P4: pass | Q4: Extra Costs：$20.04 船期8/26 | T4: OK | X4: 0840148227217 | Y4: 亚马逊版本 （12位数UPC条码） | Z4: 美文版本说明书 | AA4: 46235 | AB4: 外箱不需要盖日期码 | AC4: 4.9 | AD4: =AC4*I4 -> 4909.8 | AE4: =AD4*7.75 -> 38050.95 | AI4: 已入系统 | AK4: 客追踪贴纸 | AL4: =IFERROR(VLOOKUP(G4,'已打发票扣数（26年5月开始）'!$A$1:$C$17,3,0)*I4*0.3,"") -> 1352.7
A5: 46167 | B5: 美国-亚马逊 | C5: Elaine | D5: Flybar Inc | E5: FB-7937 | F5: PO213850 | G5: T03937-DS | H5: =VLOOKUP(G5,名称!A:B,2,0) -> 恐龙公园一代--陆地 | I5: =408-144 -> 264 | J5: =VLOOKUP(G5,名称!A:C,3,FALSE) -> 12 | K5: =I5/J5 -> 22 | L5: 46232 | M5: =L5-5 -> 46227 | N5: 46232 | O5: 已约 | P5: pass | T5: OK | X5: 0840148231382 | Y5: 沃尔玛版本彩盒 （12位数UPC条码） | Z5: 美文版本说明书 | AA5: / | AB5: 用取消单PO211192返工，条形码上已有日期码，不需要另外打日期，产品上的RFID贴纸要撕掉 | AC5: 2.1 | AD5: =AC5*I5 -> 554.4 | AE5: =AD5*7.75 -> 4296.6 | AK5: 条形码贴纸/客追踪贴纸6/18给到佩玲 | AL5: =(I5*AC5)*0.3 -> 166.32
A6: 46167 | B6: 美国-亚马逊 | C6: Elaine | D6: Flybar Inc | E6: FB-7937 | F6: PO213850 | G6: T03938-DS | H6: =VLOOKUP(G6,名称!A:B,2,0) -> 恐龙公园一代--海洋 | I6: =408-144 -> 264 | J6: =VLOOKUP(G6,名称!A:C,3,FALSE) -> 12 | K6: =I6/J6 -> 22 | L6: 46232 | M6: =L6-5 -> 46227 | N6: 46232 | O6: 已约 | P6: pass | T6: OK | X6: 0840148231399 | Y6: 沃尔玛版本彩盒 （12位数UPC条码） | Z6: 美文版本说明书 | AA6: / | AB6: 用取消单PO211192返工，条形码上已有日期码，不需要另外打日期，产品上的RFID贴纸要撕掉 | AC6: 2.1 | AD6: =AC6*I6 -> 554.4 | AE6: =AD6*7.75 -> 4296.6 | AK6: 条形码贴纸/客追踪贴纸6/18给到佩玲 | AL6: =(I6*AC6)*0.3 -> 166.32
A7: 46167 | B7: 美国-亚马逊 | C7: Elaine | D7: Flybar Inc | E7: FB-7937 | F7: PO213850 | G7: T03939-DS | H7: =VLOOKUP(G7,名称!A:B,2,0) -> 恐龙公园一代--天空 | I7: =408-144 -> 264 | J7: =VLOOKUP(G7,名称!A:C,3,FALSE) -> 12 | K7: =I7/J7 -> 22 | L7: 46232 | M7: =L7-5 -> 46227 | N7: 46232 | O7: 已约 | P7: pass | T7: OK | X7: 0840148231405 | Y7: 沃尔玛版本彩盒 （12位数UPC条码） | Z7: 美文版本说明书 | AA7: / | AB7: 用取消单PO211192返工，条形码上已有日期码，不需要另外打日期，产品上的RFID贴纸要撕掉 | AC7: 2.1 | AD7: =AC7*I7 -> 554.4 | AE7: =AD7*7.75 -> 4296.6 | AK7: 条形码贴纸/客追踪贴纸6/18给到佩玲 | AL7: =(I7*AC7)*0.3 -> 166.32
A8: 46167 | B8: 美国-亚马逊 | C8: Elaine | D8: Flybar Inc | E8: FB-7937 | F8: PO213850 | G8: T03940-DS | H8: =VLOOKUP(G8,名称!A:B,2,0) -> 恐龙公园二代--海滩 | I8: =408-144 -> 264 | J8: =VLOOKUP(G8,名称!A:C,3,FALSE) -> 12 | K8: =I8/J8 -> 22 | L8: 46232 | M8: =L8-5 -> 46227 | N8: 46232 | O8: 已约 | P8: pass | T8: OK | X8: 0840148231412 | Y8: 沃尔玛版本彩盒 （12位数UPC条码） | Z8: 美文版本说明书 | AA8: / | AB8: 条形码上已有日期码，不需要另外打日期 | AC8: 2.1 | AD8: =AC8*I8 -> 554.4 | AE8: =AD8*7.75 -> 4296.6 | AK8: 条形码贴纸/客追踪贴纸6/18给到佩玲 | AL8: =(I8*AC8)*0.3 -> 166.32
A9: 46167 | B9: 美国-亚马逊 | C9: Elaine | D9: Flybar Inc | E9: FB-7937 | F9: PO213850 | G9: T03941-DS | H9: =VLOOKUP(G9,名称!A:B,2,0) -> 恐龙公园二代--雨林 | I9: =408-144 -> 264 | J9: =VLOOKUP(G9,名称!A:C,3,FALSE) -> 12 | K9: =I9/J9 -> 22 | L9: 46232 | M9: =L9-5 -> 46227 | N9: 46232 | O9: 已约 | P9: pass | T9: OK | X9: 0840148231429 | Y9: 沃尔玛版本彩盒 （12位数UPC条码） | Z9: 美文版本说明书 | AA9: / | AB9: 条形码上已有日期码，不需要另外打日期 | AC9: 2.1 | AD9: =AC9*I9 -> 554.4 | AE9: =AD9*7.75 -> 4296.6 | AK9: 条形码贴纸/客追踪贴纸6/18给到佩玲 | AL9: =(I9*AC9)*0.3 -> 166.32
A10: 46167 | B10: 美国-亚马逊 | C10: Elaine | D10: Flybar Inc | E10: FB-7937 | F10: PO213850 | G10: T03942-DS | H10: =VLOOKUP(G10,名称!A:B,2,0) -> 恐龙公园二代--实验室 | I10: =408-144 -> 264 | J10: =VLOOKUP(G10,名称!A:C,3,FALSE) -> 12 | K10: =I10/J10 -> 22 | L10: 46232 | M10: =L10-5 -> 46227 | N10: 46232 | O10: 已约 | P10: pass | T10: OK | X10: 0840148231436 | Y10: 沃尔玛版本彩盒 （12位数UPC条码） | Z10: 美文版本说明书 | AA10: / | AB10: 条形码上已有日期码，不需要另外打日期 | AC10: 2.1 | AD10: =AC10*I10 -> 554.4 | AE10: =AD10*7.75 -> 4296.6 | AK10: 条形码贴纸/客追踪贴纸6/18给到佩玲 | AL10: =(I10*AC10)*0.3 -> 166.32
A11: 46167 | B11: 美国-亚马逊 | C11: Elaine | D11: Flybar Inc | E11: FB-7938 | F11: PO213891 | G11: T03937-DS | H11: =VLOOKUP(G11,名称!A:B,2,0) -> 恐龙公园一代--陆地 | I11: 600 | J11: =VLOOKUP(G11,名称!A:C,3,FALSE) -> 12 | K11: =I11/J11 -> 50 | L11: 46262 | M11: =L11-3 -> 46259 | N11: =L11-3 -> 46259 | Q11: Extra Costs：$468 | T11: OK | X11: 0840148231382 | Y11: 沃尔玛版本彩盒 （12位数UPC条码） | Z11: 美文版本说明书 | AA11: / | AB11: 用取消单PO211192、P0210601返工，条形码上已有日期码，不需要另外打日期，产品上的RFID贴纸要撕掉 | AC11: 2.1 | AD11: =AC11*I11 -> 1260 | AE11: =AD11*7.75 -> 9765 | AK11: 条形码贴纸/客追踪贴纸6/18给到佩玲 | AL11: =(I11*AC11)*0.3 -> 378
A12: 46167 | B12: 美国-亚马逊 | C12: Elaine | D12: Flybar Inc | E12: FB-7938 | F12: PO213891 | G12: T03938-DS | H12: =VLOOKUP(G12,名称!A:B,2,0) -> 恐龙公园一代--海洋 | I12: 600 | J12: =VLOOKUP(G12,名称!A:C,3,FALSE) -> 12 | K12: =I12/J12 -> 50 | L12: 46262 | M12: =L12-3 -> 46259 | N12: =L12-3 -> 46259 | T12: OK | X12: 0840148231399 | Y12: 沃尔玛版本彩盒 （12位数UPC条码） | Z12: 美文版本说明书 | AA12: / | AB12: 用取消单PO211192、P0210601返工，条形码上已有日期码，不需要另外打日期，产品上的RFID贴纸要撕掉 | AC12: 2.1 | AD12: =AC12*I12 -> 1260 | AE12: =AD12*7.75 -> 9765 | AK12: 条形码贴纸/客追踪贴纸6/18给到佩玲 | AL12: =(I12*AC12)*0.3 -> 378
A13: 46167 | B13: 美国-亚马逊 | C13: Elaine | D13: Flybar Inc | E13: FB-7938 | F13: PO213891 | G13: T03939-DS | H13: =VLOOKUP(G13,名称!A:B,2,0) -> 恐龙公园一代--天空 | I13: 600 | J13: =VLOOKUP(G13,名称!A:C,3,FALSE) -> 12 | K13: =I13/J13 -> 50 | L13: 46262 | M13: =L13-3 -> 46259 | N13: =L13-3 -> 46259 | T13: OK | X13: 0840148231405 | Y13: 沃尔玛版本彩盒 （12位数UPC条码） | Z13: 美文版本说明书 | AA13: / | AB13: 用取消单PO211192、P0210601返工，条形码上已有日期码，不需要另外打日期，产品上的RFID贴纸要撕掉 | AC13: 2.1 | AD13: =AC13*I13 -> 1260 | AE13: =AD13*7.75 -> 9765 | AK13: 条形码贴纸/客追踪贴纸6/18给到佩玲 | AL13: =(I13*AC13)*0.3 -> 378
A14: 46167 | B14: 美国-亚马逊 | C14: Elaine | D14: Flybar Inc | E14: FB-7938 | F14: PO213891 | G14: T03940-DS | H14: =VLOOKUP(G14,名称!A:B,2,0) -> 恐龙公园二代--海滩 | I14: 600 | J14: =VLOOKUP(G14,名称!A:C,3,FALSE) -> 12 | K14: =I14/J14 -> 50 | L14: 46262 | M14: =L14-3 -> 46259 | N14: =L14-3 -> 46259 | T14: OK | X14: 0840148231412 | Y14: 沃尔玛版本彩盒 （12位数UPC条码） | Z14: 美文版本说明书 | AA14: / | AB14: 条形码上已有日期码，不需要另外打日期 | AC14: 2.1 | AD14: =AC14*I14 -> 1260 | AE14: =AD14*7.75 -> 9765 | AK14: 条形码贴纸/客追踪贴纸6/18给到佩玲 | AL14: =(I14*AC14)*0.3 -> 378
A15: 46167 | B15: 美国-亚马逊 | C15: Elaine | D15: Flybar Inc | E15: FB-7938 | F15: PO213891 | G15: T03941-DS | H15: =VLOOKUP(G15,名称!A:B,2,0) -> 恐龙公园二代--雨林 | I15: 600 | J15: =VLOOKUP(G15,名称!A:C,3,FALSE) -> 12 | K15: =I15/J15 -> 50 | L15: 46262 | M15: =L15-3 -> 46259 | N15: =L15-3 -> 46259 | T15: OK | X15: 0840148231429 | Y15: 沃尔玛版本彩盒 （12位数UPC条码） | Z15: 美文版本说明书 | AA15: / | AB15: 条形码上已有日期码，不需要另外打日期 | AC15: 2.1 | AD15: =AC15*I15 -> 1260 | AE15: =AD15*7.75 -> 9765 | AK15: 条形码贴纸/客追踪贴纸6/18给到佩玲 | AL15: =(I15*AC15)*0.3 -> 378
A16: 46167 | B16: 美国-亚马逊 | C16: Elaine | D16: Flybar Inc | E16: FB-7938 | F16: PO213891 | G16: T03942-DS | H16: =VLOOKUP(G16,名称!A:B,2,0) -> 恐龙公园二代--实验室 | I16: 600 | J16: =VLOOKUP(G16,名称!A:C,3,FALSE) -> 12 | K16: =I16/J16 -> 50 | L16: 46262 | M16: =L16-3 -> 46259 | N16: =L16-3 -> 46259 | T16: OK | X16: 0840148231436 | Y16: 沃尔玛版本彩盒 （12位数UPC条码） | Z16: 美文版本说明书 | AA16: / | AB16: 条形码上已有日期码，不需要另外打日期 | AC16: 2.1 | AD16: =AC16*I16 -> 1260 | AE16: =AD16*7.75 -> 9765 | AK16: 条形码贴纸/客追踪贴纸6/18给到佩玲 | AL16: =(I16*AC16)*0.3 -> 378
A17: 46195 | B17: 美国-亚马逊 | C17: Elaine | D17: Flybar Inc | E17: FB-8224 | F17: PO214370 | G17: JW-RV-RPGEA | H17: =VLOOKUP(G17,名称!A:B,2,0) -> 恐龙游戏盘(邮包盒装) | I17: 1002 | J17: =VLOOKUP(G17,名称!A:C,3,FALSE) -> 6 | K17: =I17/J17 -> 167 | L17: 46248 | M17: 46247 | N17: 46247 | O17: 已约 | P17: pass | Q17: Extra Costs：$30.06 2026/8/29 | T17: OK | U17: 追踪贴纸 | X17: 0840148227217 | Y17: 亚马逊版本 （12位数UPC条码） | Z17: 美文版本说明书 | AA17: 46235 | AB17: 外箱不需要盖日期码 | AC17: 4.9 | AD17: =AC17*I17 -> 4909.8 | AE17: =AD17*7.75 -> 38050.95 | AI17: 已入系统 | AL17: =IFERROR(VLOOKUP(G17,'已打发票扣数（26年5月开始）'!$A$1:$C$17,3,0)*I17*0.3,"") -> 1352.7
A18: 46195 | B18: 美国-亚马逊 | C18: Elaine | D18: Flybar Inc | E18: FB-8223 | F18: PO214369 | G18: JW-RV-RPGEA | H18: =VLOOKUP(G18,名称!A:B,2,0) -> 恐龙游戏盘(邮包盒装) | I18: 1002 | J18: =VLOOKUP(G18,名称!A:C,3,FALSE) -> 6 | K18: =I18/J18 -> 167 | L18: 46248 | M18: 46247 | N18: 46247 | O18: 已约 | P18: pass | Q18: Extra Costs：$30.06 2026/9/21 | T18: OK | U18: 追踪贴纸 | X18: 0840148227217 | Y18: 亚马逊版本 （12位数UPC条码） | Z18: 美文版本说明书 | AA18: 46235 | AB18: 外箱不需要盖日期码 | AC18: 4.9 | AD18: =AC18*I18 -> 4909.8 | AE18: =AD18*7.75 -> 38050.95 | AI18: 已入系统 | AL18: =IFERROR(VLOOKUP(G18,'已打发票扣数（26年5月开始）'!$A$1:$C$17,3,0)*I18*0.3,"") -> 1352.7
A19: 46195 | B19: 美国-亚马逊 | C19: Elaine | D19: Flybar Inc | E19: FB-8225 | F19: PO214371 | G19: JW-RV-RPGEA | H19: =VLOOKUP(G19,名称!A:B,2,0) -> 恐龙游戏盘(邮包盒装) | I19: 498 | J19: =VLOOKUP(G19,名称!A:C,3,FALSE) -> 6 | K19: =I19/J19 -> 83 | L19: 46248 | M19: 46247 | N19: 46247 | O19: 已约 | P19: pass | Q19: Extra Costs：$24.9 2026/10/21 | T19: OK | U19: 追踪贴纸 | X19: 0840148227217 | Y19: 亚马逊版本 （12位数UPC条码） | Z19: 美文版本说明书 | AA19: 46235 | AB19: 外箱不需要盖日期码 | AC19: 4.9 | AD19: =AC19*I19 -> 2440.2 | AE19: =AD19*7.75 -> 18911.55 | AI19: 已入系统 | AL19: =IFERROR(VLOOKUP(G19,'已打发票扣数（26年5月开始）'!$A$1:$C$17,3,0)*I19*0.3,"") -> 672.3
A20: 46226 | B20: 美国 | C20: Jennifer | D20: Meijer LANSING | E20: 219664389 | F20: PO214790 | G20: T01453 | H20: =VLOOKUP(G20,名称!A:B,2,0) -> 恐龙游戏盘 | I20: 574 | J20: =VLOOKUP(G20,名称!A:C,3,FALSE) -> 2 | K20: =I20/J20 -> 287 | L20: 46269 | M20: =L20-7 -> 46262 | N20: 46262 | T20: OK | X20: 840148207301 | Y20: 标准美文12位条形码 | Z20: 沃尔玛版本说明书 | AA20: RR23726 | AB20: 该订单与沃尔玛订单相似，但外箱箱唛不同请注意不要订错外箱，外箱不用加盖日期码。 | AC20: 4.5 | AD20: =AC20*I20 -> 2583 | AE20: =AD20*7.75 -> 20018.25 | AI20: 已入系统 | AL20: =IFERROR(VLOOKUP(G20,'已打发票扣数（26年5月开始）'!$A$1:$C$17,3,0)*I20*0.3,"") -> 774.9
A21: 46226 | B21: 美国 | C21: Jennifer | D21: Meijer LANSING | E21: 219664388 | F21: PO214789 | G21: T01453 | H21: =VLOOKUP(G21,名称!A:B,2,0) -> 恐龙游戏盘 | I21: 1300 | J21: =VLOOKUP(G21,名称!A:C,3,FALSE) -> 2 | K21: =I21/J21 -> 650 | L21: 46269 | M21: =L21-7 -> 46262 | N21: 46262 | T21: OK | X21: 840148207301 | Y21: 标准美文12位条形码 | Z21: 沃尔玛版本说明书 | AA21: RR23726 | AB21: 该订单与沃尔玛订单相似，但外箱箱唛不同请注意不要订错外箱，外箱不用加盖日期码。 | AC21: 4.5 | AD21: =AC21*I21 -> 5850 | AE21: =AD21*7.75 -> 45337.5 | AI21: 已入系统 | AL21: =IFERROR(VLOOKUP(G21,'已打发票扣数（26年5月开始）'!$A$1:$C$17,3,0)*I21*0.3,"") -> 1755
A22: 46240 | B22: 上海 | C22: Carol | D22: BIG W | E22: 47981637 | F22: PO214938 | G22: JW-RV-RPGE | H22: =VLOOKUP(G22,名称!A:B,2,0) -> 恐龙游戏盘 | I22: 198 | J22: =VLOOKUP(G22,名称!A:C,3,FALSE) -> 6 | K22: =I22/J22 -> 33 | L22: 46280 | M22: =L22-7 -> 46273 | N22: 46273 | Q22: Extra Costs：$300 | T22: OK | X22: 0840148207301 | Y22: 标准美文版本 （13位数UPC条码） | Z22: 美文版本说明书 | AA22: 150926 | AB22: 外箱不需要盖日期码 | AC22: 4.5 | AD22: =AC22*I22 -> 891 | AE22: =AD22*7.75 -> 6905.25 | AI22: 已入系统 | AL22: =IFERROR(VLOOKUP(G22,'已打发票扣数（26年5月开始）'!$A$1:$C$17,3,0)*I22*0.3,"") -> 267.3
A23: 46240 | B23: 上海 | C23: Carol | D23: BIG W | E23: 47981746 | F23: PO214939 | G23: JW-RV-RPGE | H23: =VLOOKUP(G23,名称!A:B,2,0) -> 恐龙游戏盘 | I23: 942 | J23: =VLOOKUP(G23,名称!A:C,3,FALSE) -> 6 | K23: =I23/J23 -> 157 | L23: 46280 | M23: =L23-7 -> 46273 | N23: 46273 | T23: OK | X23: 0840148207301 | Y23: 标准美文版本 （13位数UPC条码） | Z23: 美文版本说明书 | AA23: 150926 | AB23: 外箱不需要盖日期码 | AC23: 4.5 | AD23: =AC23*I23 -> 4239 | AE23: =AD23*7.75 -> 32852.25 | AI23: 已入系统 | AL23: =IFERROR(VLOOKUP(G23,'已打发票扣数（26年5月开始）'!$A$1:$C$17,3,0)*I23*0.3,"") -> 1271.7
A24: 46240 | B24: 上海 | C24: Carol | D24: BIG W | E24: 47982010 | F24: PO214940 | G24: JW-RV-RPGE | H24: =VLOOKUP(G24,名称!A:B,2,0) -> 恐龙游戏盘 | I24: 432 | J24: =VLOOKUP(G24,名称!A:C,3,FALSE) -> 6 | K24: =I24/J24 -> 72 | L24: 46280 | M24: =L24-7 -> 46273 | N24: 46273 | Q24: Extra Costs：$300 | T24: OK | X24: 0840148207301 | Y24: 标准美文版本 （13位数UPC条码） | Z24: 美文版本说明书 | AA24: 150926 | AB24: 外箱不需要盖日期码 | AC24: 4.5 | AD24: =AC24*I24 -> 1944 | AE24: =AD24*7.75 -> 15066 | AI24: 已入系统 | AL24: =IFERROR(VLOOKUP(G24,'已打发票扣数（26年5月开始）'!$A$1:$C$17,3,0)*I24*0.3,"") -> 583.2
A25: 46240 | B25: 上海 | C25: Carol | D25: BIG W | E25: 47982383 | F25: PO214941 | G25: JW-RV-RPGE | H25: =VLOOKUP(G25,名称!A:B,2,0) -> 恐龙游戏盘 | I25: 924 | J25: =VLOOKUP(G25,名称!A:C,3,FALSE) -> 6 | K25: =I25/J25 -> 154 | L25: 46280 | M25: =L25-7 -> 46273 | N25: =M25 -> 46273 | T25: OK | X25: 0840148207301 | Y25: 标准美文版本 （13位数UPC条码） | Z25: 美文版本说明书 | AA25: 150926 | AB25: 外箱不需要盖日期码 | AC25: 4.5 | AD25: =AC25*I25 -> 4158 | AE25: =AD25*7.75 -> 32224.5 | AI25: 已入系统 | AL25: =IFERROR(VLOOKUP(G25,'已打发票扣数（26年5月开始）'!$A$1:$C$17,3,0)*I25*0.3,"") -> 1247.4
A26: 46245 | B26: 上海 | C26: Elaine | D26: WRT | E26: 26-3202009JUS | F26: PO215033 | G26: T01535 | H26: =VLOOKUP(G26,名称!A:B,2,0) -> 恐龙公园 | I26: 132 | J26: =VLOOKUP(G26,名称!A:C,3,FALSE) -> 12 | K26: =I26/J26 -> 11 | L26: 46286 | M26: =L26-7 -> 46279 | N26: =M26 -> 46279 | Q26: Extra Costs：$7.56 | X26: 0840148215733 | Y26: 标准美文版本 （13位数UPC条码） | Z26: 美文版本说明书 | AA26: RR25226 | AB26: 外箱不需要盖日期码 | AC26: 2.1 | AD26: =AC26*I26 -> 277.2 | AE26: =AD26*7.75 -> 2148.3 | AI26: 已入系统 | AL26: =IFERROR(VLOOKUP(G26,'已打发票扣数（26年5月开始）'!$A$1:$C$17,3,0)*I26*0.3,"") -> 83.16
A27: 46245 | B27: 上海 | C27: Elaine | D27: WRT | E27: 26-3202009JUS | F27: PO215033 | G27: T02444 | H27: =VLOOKUP(G27,名称!A:B,2,0) -> 恐龙公园二代 | I27: 120 | J27: =VLOOKUP(G27,名称!A:C,3,FALSE) -> 12 | K27: =I27/J27 -> 10 | L27: 46286 | M27: =L27-7 -> 46279 | N27: =M27 -> 46279 | X27: 0840148221734 | Y27: 标准美文版本 （13位数UPC条码） | Z27: 美文版本说明书 | AA27: RR25226 | AB27: 外箱不需要盖日期码 | AC27: 2.1 | AD27: =AC27*I27 -> 252 | AE27: =AD27*7.75 -> 1953 | AI27: 已入系统 | AL27: =IFERROR(VLOOKUP(G27,'已打发票扣数（26年5月开始）'!$A$1:$C$17,3,0)*I27*0.3,"") -> 75.6
A28: 46245 | B28: 上海 | C28: Elaine | D28: WRT | E28: 26-3202008JDO | F28: PO215031 | G28: T01535 | H28: =VLOOKUP(G28,名称!A:B,2,0) -> 恐龙公园 | I28: 144 | J28: =VLOOKUP(G28,名称!A:C,3,FALSE) -> 12 | K28: =I28/J28 -> 12 | L28: 46286 | M28: =L28-7 -> 46279 | N28: =M28 -> 46279 | Q28: Extra Costs：$8.64 | X28: 0840148215733 | Y28: 标准美文版本 （13位数UPC条码） | Z28: 美文版本说明书 | AA28: RR25226 | AB28: 外箱不需要盖日期码 | AC28: 2.1 | AD28: =AC28*I28 -> 302.4 | AE28: =AD28*7.75 -> 2343.6 | AI28: 已入系统 | AL28: =IFERROR(VLOOKUP(G28,'已打发票扣数（26年5月开始）'!$A$1:$C$17,3,0)*I28*0.3,"") -> 90.72
A29: 46245 | B29: 上海 | C29: Elaine | D29: WRT | E29: 26-3202008JDO | F29: PO215031 | G29: T02444 | H29: =VLOOKUP(G29,名称!A:B,2,0) -> 恐龙公园二代 | I29: 144 | J29: =VLOOKUP(G29,名称!A:C,3,FALSE) -> 12 | K29: =I29/J29 -> 12 | L29: 46286 | M29: =L29-7 -> 46279 | N29: =M29 -> 46279 | X29: 0840148221734 | Y29: 标准美文版本 （13位数UPC条码） | Z29: 美文版本说明书 | AA29: RR25226 | AB29: 外箱不需要盖日期码 | AC29: 2.1 | AD29: =AC29*I29 -> 302.4 | AE29: =AD29*7.75 -> 2343.6 | AI29: 已入系统 | AL29: =IFERROR(VLOOKUP(G29,'已打发票扣数（26年5月开始）'!$A$1:$C$17,3,0)*I29*0.3,"") -> 90.72
A30: 46245 | B30: 上海 | C30: Elaine | D30: WRT | E30: 26-3202007JEC | F30: PO215029 | G30: T01535 | H30: =VLOOKUP(G30,名称!A:B,2,0) -> 恐龙公园 | I30: 504 | J30: =VLOOKUP(G30,名称!A:C,3,FALSE) -> 12 | K30: =I30/J30 -> 42 | L30: 46286 | M30: =L30-7 -> 46279 | N30: =M30 -> 46279 | Q30: Extra Costs：$30.24 | X30: 0840148215733 | Y30: 标准美文版本 （13位数UPC条码） | Z30: 美文版本说明书 | AA30: RR25226 | AB30: 外箱不需要盖日期码 | AC30: 2.1 | AD30: =AC30*I30 -> 1058.4 | AE30: =AD30*7.75 -> 8202.6 | AI30: 已入系统 | AL30: =IFERROR(VLOOKUP(G30,'已打发票扣数（26年5月开始）'!$A$1:$C$17,3,0)*I30*0.3,"") -> 317.52
A31: 46245 | B31: 上海 | C31: Elaine | D31: WRT | E31: 26-3202007JEC | F31: PO215029 | G31: T02444 | H31: =VLOOKUP(G31,名称!A:B,2,0) -> 恐龙公园二代 | I31: 504 | J31: =VLOOKUP(G31,名称!A:C,3,FALSE) -> 12 | K31: =I31/J31 -> 42 | L31: 46286 | M31: =L31-7 -> 46279 | N31: =M31 -> 46279 | X31: 0840148221734 | Y31: 标准美文版本 （13位数UPC条码） | Z31: 美文版本说明书 | AA31: RR25226 | AB31: 外箱不需要盖日期码 | AC31: 2.1 | AD31: =AC31*I31 -> 1058.4 | AE31: =AD31*7.75 -> 8202.6 | AI31: 已入系统 | AL31: =IFERROR(VLOOKUP(G31,'已打发票扣数（26年5月开始）'!$A$1:$C$17,3,0)*I31*0.3,"") -> 317.52
AD32: =AC32*I32 -> 0 | AE32: =AD32*7.75 -> 0 | AL32: =IFERROR(VLOOKUP(G32,'已打发票扣数（26年5月开始）'!$A$1:$C$17,3,0)*I32*0.3,"")
AD33: =AC33*I33 -> 0 | AE33: =AD33*7.75 -> 0 | AL33: =IFERROR(VLOOKUP(G33,'已打发票扣数（26年5月开始）'!$A$1:$C$17,3,0)*I33*0.3,"")
AD34: =AC34*I34 -> 0 | AE34: =AD34*7.75 -> 0 | AL34: =IFERROR(VLOOKUP(G34,'已打发票扣数（26年5月开始）'!$A$1:$C$17,3,0)*I34*0.3,"")
AD35: =AC35*I35 -> 0 | AE35: =AD35*7.75 -> 0 | AL35: =IFERROR(VLOOKUP(G35,'已打发票扣数（26年5月开始）'!$A$1:$C$17,3,0)*I35*0.3,"")
AD36: =AC36*I36 -> 0 | AE36: =AD36*7.75 -> 0 | AL36: =IFERROR(VLOOKUP(G36,'已打发票扣数（26年5月开始）'!$A$1:$C$17,3,0)*I36*0.3,"")
AD37: =AC37*I37 -> 0 | AE37: =AD37*7.75 -> 0 | AL37: =IFERROR(VLOOKUP(G37,'已打发票扣数（26年5月开始）'!$A$1:$C$17,3,0)*I37*0.3,"")
AD38: =AC38*I38 -> 0 | AE38: =AD38*7.75 -> 0 | AL38: =IFERROR(VLOOKUP(G38,'已打发票扣数（26年5月开始）'!$A$1:$C$17,3,0)*I38*0.3,"")
AD39: =AC39*I39 -> 0 | AE39: =AD39*7.75 -> 0 | AL39: =IFERROR(VLOOKUP(G39,'已打发票扣数（26年5月开始）'!$A$1:$C$17,3,0)*I39*0.3,"")
I40: =SUM(I2:I39) -> 17306 | AD40: =SUM(AD2:AD39) -> 56641.8 | AE40: =SUM(AE2:AE39) -> 438973.95

Sheet 已出货
A1: 接单期 | B1: 国家 | C1: 客跟单 | D1: 客户 | E1: Customer | F1: PO号 | G1: 货号 | H1: 名称 | I1: 数量 | J1: 装箱数 | K1: 总箱数 | L1: 客PO期 | M1: 出货期 | N1: 验货期 | O1: 是否验货 | P1: 验货结果 | Q1: 船期SO | R1: 吨车/柜货 | S1: 生产车间 | T1: 箱唛资料 | U1: 客贴纸 | V1: 是否寄出签办 | W1: 是否打卡板 | X1: 彩盒UPC条码 | Y1: 彩盒版本 | Z1: 说明书版本 | AA1: 日期码 | AB1: 备注 | AC1: 单价 | AD1: 金额USD | AE1: 金额HKD | AF1: 发票号 | AG1: 走柜/散货 | AH1: 出货日期 | AI1: 是否入系统 | AJ1: 下单情况 | AK1: 贴纸情况 | AL1: 首期扣数30%
A2: 45967 | B2: 越南 | C2: Elaine | D2: Viet Tinh Anh Joint Stock Company | E2: Viet-TM110225 | F2: PO211348 | G2: T02444 | H2: =VLOOKUP(G2,名称!A:B,2,0) -> 恐龙公园二代 | I2: 1680 | J2: =VLOOKUP(G2,名称!A:C,3,FALSE) -> 12 | K2: =I2/J2 -> 140 | L2: 46021 | M2: 46021 | N2: 46021 | O2: 已约 | Q2: 1/6 extra costs:$300 | R2: 5吨车 | T2: OK | X2: 草地套装：0840148226203 海滩滩套装：0840148226210 实验室套装：0840148226227 | Y2: 标准美文版本 （13位数UPC条码） | Z2: 美文版本说明书 | AA2: RR35925 | AC2: 2.1 | AD2: =AC2*I2 -> 3528 | AE2: =AD2*7.75 -> 27342 | AF2: 83213 | AG2: =VLOOKUP(AF2,'[2]Toy Monster'!$L:$M,2,0) -> RR02车 | AH2: =VLOOKUP(AF2,'[2]Toy Monster'!$L:$T,9,FALSE) -> 46027 | AI2: 已入系统 | AL2: =IFERROR(VLOOKUP(G2,'已打发票扣数（26年5月开始）'!$A$1:$C$17,3,0)*I2*0.3,"") -> 1058.4
A3: 45989 | B3: 澳大利亚 | C3: Rachel | D3: Woolworths Group Limited t/a Big W | E3: 47895690 | F3: PO211747 | G3: JW-RV-RPGE | H3: =VLOOKUP(G3,名称!A:B,2,0) -> 恐龙游戏盘 | I3: 1014 | J3: =VLOOKUP(G3,名称!A:C,3,FALSE) -> 6 | K3: =I3/J3 -> 169 | L3: 46041 | M3: 46036 | N3: 46036 | O3: 已约 | P3: OK | T3: OK | X3: 0840148207301 | Y3: 标准美文版本 （13位数UPC条码） | Z3: 美文版本说明书 | AA3: 090126 | AC3: 4.5 | AD3: =AC3*I3 -> 4563 | AE3: =AD3*7.75 -> 35363.25 | AF3: 83218 | AG3: =VLOOKUP(AF3,'[2]Toy Monster'!$L:$M,2,0) -> RR19车 | AH3: =VLOOKUP(AF3,'[2]Toy Monster'!$L:$T,9,FALSE) -> 46048 | AI3: 已入系统 | AL3: =IFERROR(VLOOKUP(G3,'已打发票扣数（26年5月开始）'!$A$1:$C$17,3,0)*I3*0.3,"") -> 1368.9
A4: 45989 | B4: 澳大利亚 | C4: Rachel | D4: Woolworths Group Limited t/a Big W | E4: 47896520 | F4: PO211748 | G4: JW-RV-RPGE | H4: =VLOOKUP(G4,名称!A:B,2,0) -> 恐龙游戏盘 | I4: 624 | J4: =VLOOKUP(G4,名称!A:C,3,FALSE) -> 6 | K4: =I4/J4 -> 104 | L4: 46041 | M4: 46036 | N4: 46036 | O4: 已约 | P4: OK | Q4: Extra Costs:$200 | T4: OK | X4: 0840148207301 | Y4: 标准美文版本 （13位数UPC条码） | Z4: 美文版本说明书 | AA4: 090126 | AC4: 4.5 | AD4: =AC4*I4 -> 2808 | AE4: =AD4*7.75 -> 21762 | AF4: 83219 | AG4: =VLOOKUP(AF4,'[2]Toy Monster'!$L:$M,2,0) -> RR19车 | AH4: =VLOOKUP(AF4,'[2]Toy Monster'!$L:$T,9,FALSE) -> 46048 | AI4: 已入系统 | AL4: =IFERROR(VLOOKUP(G4,'已打发票扣数（26年5月开始）'!$A$1:$C$17,3,0)*I4*0.3,"") -> 842.4
A5: 46010 | B5: 澳大利亚 | C5: Rachel | D5: Woolworths Group Limited t/a Big W | E5: 47905042 | F5: PO212018 | G5: JW-RV-RPGE | H5: =VLOOKUP(G5,名称!A:B,2,0) -> 恐龙游戏盘 | I5: 1200 | J5: =VLOOKUP(G5,名称!A:C,3,FALSE) -> 6 | K5: =I5/J5 -> 200 | L5: 46041 | M5: 46036 | N5: 46036 | O5: 已约 | P5: OK | T5: OK | X5: 0840148207301 | Y5: 标准美文版本 （13位数UPC条码） | Z5: 美文版本说明书 | AA5: 090126 | AC5: 4.5 | AD5: =AC5*I5 -> 5400 | AE5: =AD5*7.75 -> 41850 | AF5: 83220 | AG5: =VLOOKUP(AF5,'[2]Toy Monster'!$L:$M,2,0) -> RR19车 | AH5: =VLOOKUP(AF5,'[2]Toy Monster'!$L:$T,9,FALSE) -> 46048 | AI5: 已入系统 | AL5: =IFERROR(VLOOKUP(G5,'已打发票扣数（26年5月开始）'!$A$1:$C$17,3,0)*I5*0.3,"") -> 1620
A6: 45996 | B6: 香港 | C6: Elaine | D6: Asia Goal Limited | E6: PO-AG250344 | F6: PO211794 | G6: T02444 | H6: =VLOOKUP(G6,名称!A:B,2,0) -> 恐龙公园二代 | I6: 720 | J6: =VLOOKUP(G6,名称!A:C,3,FALSE) -> 12 | K6: =I6/J6 -> 60 | L6: 46043 | M6: 46043 | N6: 46043 | O6: 已约 | P6: OK | R6: EXW | T6: OK | X6: 草地套装：0840148226203 海滩滩套装：0840148226210 实验室套装：0840148226227 | Y6: 标准美文版本 （13位数UPC条码） | Z6: 美文版本说明书 | AA6: RR35925 | AC6: 2.1 | AD6: =AC6*I6 -> 1512 | AE6: =AD6*7.75 -> 11718 | AF6: 83221 | AG6: =VLOOKUP(AF6,'[2]Toy Monster'!$L:$M,2,0) -> RR27客上车 | AH6: =VLOOKUP(AF6,'[2]Toy Monster'!$L:$T,9,FALSE) -> 46052 | AI6: 已入系统 | AK6: 客贴纸12/29给到佩玲 | AL6: =IFERROR(VLOOKUP(G6,'已打发票扣数（26年5月开始）'!$A$1:$C$17,3,0)*I6*0.3,"") -> 453.6
A7: 45981 | B7: 乌克兰 | C7: Rainbow | D7: AMIGO & F Ltd | E7: Kuma Paw 0126 | F7: PO211615 | G7: T02943 | H7: =VLOOKUP(G7,名称!A:B,2,0) -> 9.5寸粉红熊公仔（移印） | I7: 800 | J7: =VLOOKUP(G7,名称!A:C,3,FALSE) -> 2 | K7: =I7/J7 -> 400 | L7: 46045 | M7: 46036 | N7: 46036 | O7: 已约 | P7: OK | Q7: extra costs:$16 | R7: 20GP | T7: OK | X7: 840148224445 | Y7: 沃尔玛版本彩盒 （12位数UPC条码） | Z7: / | AA7: RR00526 | AC7: 6.2 | AD7: =AC7*I7 -> 4960 | AE7: =AD7*7.75 -> 38440 | AF7: 83222 | AG7: =VLOOKUP(AF7,'[2]Toy Monster'!$L:$M,2,0) -> RR103柜 | AH7: =VLOOKUP(AF7,'[2]Toy Monster'!$L:$T,9,FALSE) -> 46052 | AI7: 已入系统 | AK7: 客贴纸/条形码贴纸 | AL7: =IFERROR(VLOOKUP(G7,'已打发票扣数（26年5月开始）'!$A$1:$C$17,3,0)*I7*0.3,"") -> 1521.6
A8: 45981 | B8: 乌克兰 | C8: Rainbow | D8: AMIGO & F Ltd | E8: Kuma Paw 0126 | F8: PO211615 | G8: T02945 | H8: =VLOOKUP(G8,名称!A:B,2,0) -> 9.5寸格力奇公仔 （移印） | I8: 800 | J8: =VLOOKUP(G8,名称!A:C,3,FALSE) -> 2 | K8: =I8/J8 -> 400 | L8: 46045 | M8: 46036 | N8: 46036 | O8: 已约 | P8: OK | Q8: extra costs:$16 | R8: 20GP | T8: OK | X8: 840148224469 | Y8: 沃尔玛版本彩盒 （12位数UPC条码） | Z8: / | AA8: RR00526 | AC8: 6.5 | AD8: =AC8*I8 -> 5200 | AE8: =AD8*7.75 -> 40300 | AF8: 83222 | AG8: =VLOOKUP(AF8,'[2]Toy Monster'!$L:$M,2,0) -> RR103柜 | AH8: =VLOOKUP(AF8,'[2]Toy Monster'!$L:$T,9,FALSE) -> 46052 | AI8: 已入系统 | AK8: 客贴纸/条形码贴纸 | AL8: =IFERROR(VLOOKUP(G8,'已打发票扣数（26年5月开始）'!$A$1:$C$17,3,0)*I8*0.3,"") -> 1593.6
A9: 45986 | B9: 美国 | C9: Jennifer | D9: Monster Group LLC | E9: WM Domestic Order | F9: PO211734 | G9: T02943 | H9: =VLOOKUP(G9,名称!A:B,2,0) -> 9.5寸粉红熊公仔（移印） | I9: 2304 | J9: =VLOOKUP(G9,名称!A:C,3,FALSE) -> 2 | K9: =I9/J9 -> 1152 | L9: 46037 | M9: 46036 | N9: 46036 | O9: 已约 | P9: OK | Q9: 46053 | R9: 10吨车 | T9: OK | X9: 840148224445 | Y9: 沃尔玛版本彩盒 （12位数UPC条码） | Z9: / | AA9: RR00526 | AB9: 出货后PO号跟改为：212368 | AC9: 6.2 | AD9: =AC9*I9 -> 14284.8 | AE9: =AD9*7.75 -> 110707.2 | AF9: 83223 | AG9: =VLOOKUP(AF9,'[2]Toy Monster'!$L:$M,2,0) -> RR21车 | AH9: =VLOOKUP(AF9,'[2]Toy Monster'!$L:$T,9,FALSE) -> 46059 | AI9: 已入系统 | AK9: RFID贴纸12/10日给到佩玲 | AL9: =IFERROR(VLOOKUP(G9,'已打发票扣数（26年5月开始）'!$A$1:$C$17,3,0)*I9*0.3,"") -> 4382.21
A10: 45986 | B10: 美国 | C10: Jennifer | D10: Monster Group LLC | E10: WM Domestic Order | F10: PO211734 | G10: T02945 | H10: =VLOOKUP(G10,名称!A:B,2,0) -> 9.5寸格力奇公仔 （移印） | I10: 2304 | J10: =VLOOKUP(G10,名称!A:C,3,FALSE) -> 2 | K10: =I10/J10 -> 1152 | L10: 46037 | M10: 46036 | N10: 46036 | O10: 已约 | P10: OK | Q10: 46053 | R10: 10吨车 | T10: OK | X10: 840148224469 | Y10: 沃尔玛版本彩盒 （12位数UPC条码） | Z10: / | AA10: RR00526 | AB10: 出货后PO号跟改为：212368 | AC10: 6.5 | AD10: =AC10*I10 -> 14976 | AE10: =AD10*7.75 -> 116064 | AF10: 83223 | AG10: =VLOOKUP(AF10,'[2]Toy Monster'!$L:$M,2,0) -> RR21车 | AH10: =VLOOKUP(AF10,'[2]Toy Monster'!$L:$T,9,FALSE) -> 46059 | AI10: 已入系统 | AK10: RFID贴纸12/10日给到佩玲 | AL10: =IFERROR(VLOOKUP(G10,'已打发票扣数（26年5月开始）'!$A$1:$C$17,3,0)*I10*0.3,"") -> 4589.57
A11: 46010 | B11: 美国 | C11: Jennifer | D11: Monster Group LLC | E11: WM Domestic Order | F11: PO212104 | G11: T03190 | H11: =VLOOKUP(G11,名称!A:B,2,0) -> FLiar | I11: 4676 | J11: =VLOOKUP(G11,名称!A:C,3,FALSE) -> 2 | K11: =I11/J11 -> 2338 | L11: 46052 | M11: =L11-4 -> 46048 | N11: 46056 | O11: 已约 | P11: OK | Q11: 2/7-2/9 | R11: 40HQ | T11: OK | X11: 840148226241 | Y11: 沃尔玛版本彩盒 （12位数UPC条码） | Z11: / | AA11: RR02126 | AC11: 6.15 | AD11: =AC11*I11 -> 28757.4 | AE11: =AD11*7.75 -> 222869.85 | AF11: 83224 | AG11: =VLOOKUP(AF11,'[2]Toy Monster'!$L:$M,2,0) -> RR131-132柜 | AH11: =VLOOKUP(AF11,'[2]Toy Monster'!$L:$T,9,FALSE) -> 46062 | AI11: 已入系统 | AK11: RFID贴纸12/29给到佩玲 | AL11: =IFERROR(VLOOKUP(G11,'已打发票扣数（26年5月开始）'!$A$1:$C$17,3,0)*I11*0.3,"")
A12: 46010 | B12: 美国 | C12: Jennifer | D12: Monster Group LLC | E12: WM Domestic Order | F12: PO212104 | G12: T03191 | H12: =VLOOKUP(G12,名称!A:B,2,0) -> Striker | I12: 4376 | J12: =VLOOKUP(G12,名称!A:C,3,FALSE) -> 2 | K12: =I12/J12 -> 2188 | L12: 46052 | M12: =L12-4 -> 46048 | N12: 46056 | O12: 已约 | P12: OK | Q12: 2/7-2/9 | R12: 40HQ | T12: OK | X12: 840148226258 | Y12: 沃尔玛版本彩盒 （12位数UPC条码） | Z12: / | AA12: RR02126 | AC12: 6.47 | AD12: =AC12*I12 -> 28312.72 | AE12: =AD12*7.75 -> 219423.58 | AF12: 83224 | AG12: =VLOOKUP(AF12,'[2]Toy Monster'!$L:$M,2,0) -> RR131-132柜 | AH12: =VLOOKUP(AF12,'[2]Toy Monster'!$L:$T,9,FALSE) -> 46062 | AI12: 已入系统 | AK12: RFID贴纸12/29给到佩玲 | AL12: =IFERROR(VLOOKUP(G12,'已打发票扣数（26年5月开始）'!$A$1:$C$17,3,0)*I12*0.3,"")
A13: 46010 | B13: 美国 | C13: Jennifer | D13: Monster Group LLC | E13: WM Domestic Order | F13: PO212104 | G13: T03192 | H13: =VLOOKUP(G13,名称!A:B,2,0) -> Clutch | I13: 4476 | J13: =VLOOKUP(G13,名称!A:C,3,FALSE) -> 2 | K13: =I13/J13 -> 2238 | L13: 46052 | M13: =L13-4 -> 46048 | N13: 46056 | O13: 已约 | P13: OK | Q13: 2/7-2/9 | R13: 40HQ | T13: OK | X13: 840148226265 | Y13: 沃尔玛版本彩盒 （12位数UPC条码） | Z13: / | AA13: RR02126 | AC13: 5.59 | AD13: =AC13*I13 -> 25020.84 | AE13: =AD13*7.75 -> 193911.51 | AF13: 83224 | AG13: =VLOOKUP(AF13,'[2]Toy Monster'!$L:$M,2,0) -> RR131-132柜 | AH13: =VLOOKUP(AF13,'[2]Toy Monster'!$L:$T,9,FALSE) -> 46062 | AI13: 已入系统 | AK13: RFID贴纸12/29给到佩玲 | AL13: =IFERROR(VLOOKUP(G13,'已打发票扣数（26年5月开始）'!$A$1:$C$17,3,0)*I13*0.3,"")
A14: 45993 | B14: 新加坡 | C14: Elaine | D14: Sheng Tai Toys Pty Ltd | E14: Shengtai-TM110464 | F14: PO211605 | G14: T02444 | H14: =VLOOKUP(G14,名称!A:B,2,0) -> 恐龙公园二代 | I14: 1200 | J14: =VLOOKUP(G14,名称!A:C,3,FALSE) -> 12 | K14: =I14/J14 -> 100 | L14: 46087 | M14: 46087 | N14: 46087 | O14: 已约 | P14: OK | Q14: 2026/3/10，Extra Costs:$300 | R14: 20GP | T14: OK | X14: 草地套装：0840148226203 海滩滩套装：0840148226210 实验室套装：0840148226227 | Y14: 标准美文版本 （13位数UPC条码） | Z14: 美文版本说明书 | AA14: RR35925 | AC14: 2.1 | AD14: =AC14*I14 -> 2520 | AE14: =AD14*7.75 -> 19530 | AF14: 83229REV1 | AG14: =VLOOKUP(AF14,'[2]Toy Monster'!$L:$M,2,0) -> RR155柜 | AH14: =VLOOKUP(AF14,'[2]Toy Monster'!$L:$T,9,FALSE) -> 46094 | AI14: 已入系统 | AL14: =IFERROR(VLOOKUP(G14,'已打发票扣数（26年5月开始）'!$A$1:$C$17,3,0)*I14*0.3,"") -> 756
A15: 46049 | B15: 澳大利亚 | C15: Rachel | D15: Woolworths Group Limited t/a Big W | E15: 47908798 | F15: PO212336 | G15: JW-RV-RPGE | H15: =VLOOKUP(G15,名称!A:B,2,0) -> 恐龙游戏盘 | I15: 1200 | J15: =VLOOKUP(G15,名称!A:C,3,FALSE) -> 6 | K15: =I15/J15 -> 200 | L15: 46107 | M15: 46107 | N15: 46107 | O15: 已约 | P15: OK | Q15: 46109 | T15: OK | X15: 0840148207301 | Y15: 标准美文版本 （13位数UPC条码） | Z15: 美文版本说明书 | AA15: 170326 | AB15: 生产彩盒时不要印日期码，日期码由湖南生产大货时打在彩盒上，注意不要漏打！ 包装以及说明书均为美文 | AC15: 4.5 | AD15: =AC15*I15 -> 5400 | AE15: =AD15*7.75 -> 41850 | AF15: 83230 | AG15: =VLOOKUP(AF15,'[2]Toy Monster'!$L:$M,2,0) -> RR80车 | AH15: =VLOOKUP(AF15,'[2]Toy Monster'!$L:$T,9,FALSE) -> 46111 | AI15: 已入系统 | AL15: =IFERROR(VLOOKUP(G15,'已打发票扣数（26年5月开始）'!$A$1:$C$17,3,0)*I15*0.3,"") -> 1620
A16: 46038 | B16: 美国 | C16: Jennifer | D16: Meijer LANSING | E16: 218955615 | F16: PO212267 | G16: T01453 | H16: =VLOOKUP(G16,名称!A:B,2,0) -> 恐龙游戏盘 | I16: 1000 | J16: =VLOOKUP(G16,名称!A:C,3,FALSE) -> 2 | K16: =I16/J16 -> 500 | L16: 46099 | M16: 46099 | N16: =M16 -> 46099 | O16: 已约 | P16: OK | Q16: 46100 | T16: OK | X16: 840148207301 | Y16: 沃尔玛版本彩盒 （12位数UPC条码） | Z16: 沃尔玛版本说明书 | AA16: RR07026 | AB16: 该订单与沃尔玛订单相似，但外箱箱唛不同请注意不要订错外箱，外箱不用加盖日期码。 | AC16: 4.5 | AD16: =AC16*I16 -> 4500 | AE16: =AD16*7.75 -> 34875 | AF16: 83231 | AG16: =VLOOKUP(AF16,'[2]Toy Monster'!$L:$M,2,0) -> RR70车 | AH16: =VLOOKUP(AF16,'[2]Toy Monster'!$L:$T,9,FALSE) -> 46111 | AI16: 已入系统 | AL16: =IFERROR(VLOOKUP(G16,'已打发票扣数（26年5月开始）'!$A$1:$C$17,3,0)*I16*0.3,"") -> 1350
A17: 46038 | B17: 美国 | C17: Jennifer | D17: Meijer LANSING | E17: 218955627 | F17: PO212268 | G17: T01453 | H17: =VLOOKUP(G17,名称!A:B,2,0) -> 恐龙游戏盘 | I17: 500 | J17: =VLOOKUP(G17,名称!A:C,3,FALSE) -> 2 | K17: =I17/J17 -> 250 | L17: 46099 | M17: 46099 | N17: =M17 -> 46099 | O17: 已约 | P17: OK | Q17: 46100 | T17: OK | X17: 840148207301 | Y17: 沃尔玛版本彩盒 （12位数UPC条码） | Z17: 沃尔玛版本说明书 | AA17: RR07026 | AB17: 该订单与沃尔玛订单相似，但外箱箱唛不同请注意不要订错外箱，外箱不用加盖日期码。 | AC17: 4.5 | AD17: =AC17*I17 -> 2250 | AE17: =AD17*7.75 -> 17437.5 | AF17: 83232 | AG17: =VLOOKUP(AF17,'[2]Toy Monster'!$L:$M,2,0) -> RR70车 | AH17: =VLOOKUP(AF17,'[2]Toy Monster'!$L:$T,9,FALSE) -> 46111 | AI17: 已入系统 | AL17: =IFERROR(VLOOKUP(G17,'已打发票扣数（26年5月开始）'!$A$1:$C$17,3,0)*I17*0.3,"") -> 675
A18: 45986 | B18: 美国 | C18: Jennifer | D18: Monster Group LLC | E18: WM Domestic Order | F18: PO212369 | G18: T02943 | H18: =VLOOKUP(G18,名称!A:B,2,0) -> 9.5寸粉红熊公仔（移印） | I18: 2500 | J18: =VLOOKUP(G18,名称!A:C,3,FALSE) -> 2 | K18: =I18/J18 -> 1250 | L18: 46086 | M18: =L18-7 -> 46079 | N18: 46056 | O18: 已约 | P18: OK | Q18: Extra Costs:$350 | R18: 10吨车 | T18: OK | X18: 840148224445 | Y18: 沃尔玛版本彩盒 （12位数UPC条码） | Z18: / | AA18: RR00526 | AB18: 原PO号：PO211734 | AC18: 6.2 | AD18: =AC18*I18 -> 15500 | AE18: =AD18*7.75 -> 120125 | AF18: 83233 | AG18: =VLOOKUP(AF18,'[2]Toy Monster'!$L:$M,2,0) -> RR86-87车 | AH18: =VLOOKUP(AF18,'[2]Toy Monster'!$L:$T,9,FALSE) -> 46112 | AI18: 已入系统 | AK18: RFID贴纸12/10日给到佩玲 | AL18: =IFERROR(VLOOKUP(G18,'已打发票扣数（26年5月开始）'!$A$1:$C$17,3,0)*I18*0.3,"") -> 4755
A19: 45986 | B19: 美国 | C19: Jennifer | D19: Monster Group LLC | E19: WM Domestic Order | F19: PO212369 | G19: T02945 | H19: =VLOOKUP(G19,名称!A:B,2,0) -> 9.5寸格力奇公仔 （移印） | I19: 2500 | J19: =VLOOKUP(G19,名称!A:C,3,FALSE) -> 2 | K19: =I19/J19 -> 1250 | L19: 46086 | M19: =L19-7 -> 46079 | N19: 46056 | O19: 已约 | P19: OK | Q19: Extra Costs:$350 | R19: 10吨车 | T19: OK | X19: 840148224469 | Y19: 沃尔玛版本彩盒 （12位数UPC条码） | Z19: / | AA19: RR00526 | AB19: 原PO号：PO211734 | AC19: 6.5 | AD19: =AC19*I19 -> 16250 | AE19: =AD19*7.75 -> 125937.5 | AF19: 83233 | AG19: =VLOOKUP(AF19,'[2]Toy Monster'!$L:$M,2,0) -> RR86-87车 | AH19: =VLOOKUP(AF19,'[2]Toy Monster'!$L:$T,9,FALSE) -> 46112 | AI19: 已入系统 | AK19: RFID贴纸12/10日给到佩玲 | AL19: =IFERROR(VLOOKUP(G19,'已打发票扣数（26年5月开始）'!$A$1:$C$17,3,0)*I19*0.3,"") -> 4980
A20: 46051 | B20: 美国 | C20: Jennifer | D20: Meijer LANSING | E20: 219021251 | F20: PO212355 | G20: T01453 | H20: =VLOOKUP(G20,名称!A:B,2,0) -> 恐龙游戏盘 | I20: 1000 | J20: =VLOOKUP(G20,名称!A:C,3,FALSE) -> 2 | K20: =I20/J20 -> 500 | L20: 46113 | M20: 46107 | N20: 46107 | O20: 已约 | P20: OK | Q20: 46112 | T20: OK | X20: 840148207301 | Y20: 沃尔玛版本彩盒 （12位数UPC条码） | Z20: 沃尔玛版本说明书 | AA20: RR08426 | AB20: 该订单与沃尔玛订单相似，但外箱箱唛不同请注意不要订错外箱，外箱不用加盖日期码。 | AC20: 4.5 | AD20: =AC20*I20 -> 4500 | AE20: =AD20*7.75 -> 34875 | AF20: 83234 | AG20: =VLOOKUP(AF20,'[2]Toy Monster'!$L:$M,2,0) -> RR82车 | AH20: =VLOOKUP(AF20,'[2]Toy Monster'!$L:$T,9,FALSE) -> 46112 | AI20: 已入系统 | AL20: =IFERROR(VLOOKUP(G20,'已打发票扣数（26年5月开始）'!$A$1:$C$17,3,0)*I20*0.3,"") -> 1350
A21: 46051 | B21: 美国 | C21: Jennifer | D21: Meijer LANSING | E21: 219021257 | F21: PO212356 | G21: T01453 | H21: =VLOOKUP(G21,名称!A:B,2,0) -> 恐龙游戏盘 | I21: 500 | J21: =VLOOKUP(G21,名称!A:C,3,FALSE) -> 2 | K21: =I21/J21 -> 250 | L21: 46113 | M21: 46107 | N21: 46107 | O21: 已约 | P21: OK | Q21: 46112 | T21: OK | X21: 840148207301 | Y21: 沃尔玛版本彩盒 （12位数UPC条码） | Z21: 沃尔玛版本说明书 | AA21: RR08426 | AB21: 该订单与沃尔玛订单相似，但外箱箱唛不同请注意不要订错外箱，外箱不用加盖日期码。 | AC21: 4.5 | AD21: =AC21*I21 -> 2250 | AE21: =AD21*7.75 -> 17437.5 | AF21: 83235 | AG21: =VLOOKUP(AF21,'[2]Toy Monster'!$L:$M,2,0) -> RR82车 | AH21: =VLOOKUP(AF21,'[2]Toy Monster'!$L:$T,9,FALSE) -> 46112 | AI21: 已入系统 | AL21: =IFERROR(VLOOKUP(G21,'已打发票扣数（26年5月开始）'!$A$1:$C$17,3,0)*I21*0.3,"") -> 675
A22: 46062 | B22: 英国 | C22: Rainbow Peng | D22: Smyths Toys HQ UC | E22: 4400542038 | F22: PO212408 | G22: JW-RV-RPGE | H22: =VLOOKUP(G22,名称!A:B,2,0) -> 恐龙游戏盘 | I22: 6306 | J22: =VLOOKUP(G22,名称!A:C,3,FALSE) -> 6 | K22: =I22/J22 -> 1051 | L22: 46118 | M22: 46113 | N22: =M22 -> 46113 | O22: 已约 | P22: OK | Q22: 46120 | R22: 40GP | T22: OK | X22: 0840148207301 | Y22: Smyths客版彩盒 （13位数UPC条码） | Z22: 5国语言客版说明书 | AA22: 042026 | AB22: 生产彩盒时不要印日期码，日期码由湖南生产大货时打在彩盒上，注意不要漏打！ 包装以及说明书均为5国语 | AC22: 4.5 | AD22: =AC22*I22 -> 28377 | AE22: =AD22*7.75 -> 219921.75 | AF22: 83236 | AG22: =VLOOKUP(AF22,'[2]Toy Monster'!$L:$M,2,0) -> RR169柜 | AH22: =VLOOKUP(AF22,'[2]Toy Monster'!$L:$T,9,FALSE) -> 46122 | AI22: 已入系统 | AL22: =IFERROR(VLOOKUP(G22,'已打发票扣数（26年5月开始）'!$A$1:$C$17,3,0)*I22*0.3,"") -> 8513.1
A23: 46083 | B23: 新西兰 | C23: Rachel | D23: Kmart Australia & NZ Holding Limited | E23: 21559600 | F23: PO212479 | G23: T02444 | H23: =VLOOKUP(G23,名称!A:B,2,0) -> 恐龙公园二代 | I23: 564 | J23: =VLOOKUP(G23,名称!A:C,3,FALSE) -> 12 | K23: =I23/J23 -> 47 | L23: 46122 | M23: 46122 | N23: 46122 | O23: 已约 | Q23: 4/11 extra costs:$2.585 | R23: 5吨车 | T23: OK | X23: 草地套装：0840148226203 海滩滩套装：0840148226210 实验室套装：0840148226227 | Y23: 标准美文版本 （13位数UPC条码） | Z23: 美文版本说明书 | AA23: 46138 | AB23: 外箱上面两面都需要工字形ANKO胶带封箱 | AC23: 2.1 | AD23: =AC23*I23 -> 1184.4 | AE23: =AD23*7.75 -> 9179.1 | AF23: 83237 | AG23: =VLOOKUP(AF23,'[2]Toy Monster'!$L:$M,2,0) -> RR94车 | AH23: =VLOOKUP(AF23,'[2]Toy Monster'!$L:$T,9,FALSE) -> 46127 | AI23: 已入系统 | AK23: SSCC贴纸3/30给到佩玲 | AL23: =IFERROR(VLOOKUP(G23,'已打发票扣数（26年5月开始）'!$A$1:$C$17,3,0)*I23*0.3,"") -> 355.32
A24: 46083 | B24: 澳大利亚 | C24: Rachel | D24: Kmart Australia & NZ Holding Limited | E24: 21559598 | F24: PO212478 | G24: T02444 | H24: =VLOOKUP(G24,名称!A:B,2,0) -> 恐龙公园二代 | I24: 6156 | J24: =VLOOKUP(G24,名称!A:C,3,FALSE) -> 12 | K24: =I24/J24 -> 513 | L24: 46122 | M24: 46122 | N24: 46122 | O24: 已约 | Q24: 4/11 extra costs:$28.215 | R24: 5吨车 | T24: OK | X24: 草地套装：0840148226203 海滩滩套装：0840148226210 实验室套装：0840148226227 | Y24: 标准美文版本 （13位数UPC条码） | Z24: 美文版本说明书 | AA24: 46138 | AB24: 外箱上面两面都需要工字形ANKO胶带封箱 | AC24: 2.1 | AD24: =AC24*I24 -> 12927.6 | AE24: =AD24*7.75 -> 100188.9 | AF24: 83238 | AG24: =VLOOKUP(AF24,'[2]Toy Monster'!$L:$M,2,0) -> RR94车 | AH24: =VLOOKUP(AF24,'[2]Toy Monster'!$L:$T,9,FALSE) -> 46127 | AI24: 已入系统 | AK24: SSCC贴纸3/30给到佩玲 | AL24: =IFERROR(VLOOKUP(G24,'已打发票扣数（26年5月开始）'!$A$1:$C$17,3,0)*I24*0.3,"") -> 3878.28
A25: 46030 | B25: 中国台湾 | C25: Elaine | D25: Asia Goal Limited | E25: PO-AG250418 | F25: PO212218 | G25: T02444 | H25: =VLOOKUP(G25,名称!A:B,2,0) -> 恐龙公园二代 | I25: 780 | J25: =VLOOKUP(G25,名称!A:C,3,FALSE) -> 12 | K25: =I25/J25 -> 65 | L25: 46108 | M25: 46107 | N25: 46107 | O25: 已约 | P25: OK | Q25: 46125 | R25: 客自提 | T25: OK | X25: 草地套装：0840148226203 海滩滩套装：0840148226210 实验室套装：0840148226227 | Y25: 标准美文版本 （13位数UPC条码） | Z25: 美文版本说明书 | AA25: RR35925 | AC25: 2.1 | AD25: =AC25*I25 -> 1638 | AE25: =AD25*7.75 -> 12694.5 | AF25: 83239 | AG25: =VLOOKUP(AF25,'[2]Toy Monster'!$L:$M,2,0) -> RR103车 | AH25: =VLOOKUP(AF25,'[2]Toy Monster'!$L:$T,9,FALSE) -> 46127 | AI25: 已入系统 | AK25: 客贴纸2/2日给到佩玲 | AL25: =IFERROR(VLOOKUP(G25,'已打发票扣数（26年5月开始）'!$A$1:$C$17,3,0)*I25*0.3,"") -> 491.4
A26: 46030 | B26: 中国台湾 | C26: Elaine | D26: Asia Goal Limited | E26: PO-AG250418 | F26: PO212218 | G26: JW-RV-RPGE | H26: =VLOOKUP(G26,名称!A:B,2,0) -> 恐龙游戏盘 | I26: 180 | J26: =VLOOKUP(G26,名称!A:C,3,FALSE) -> 6 | K26: =I26/J26 -> 30 | L26: 46108 | M26: 46107 | N26: 46107 | O26: 已约 | P26: OK | Q26: 46125 | R26: 客自提 | T26: OK | X26: 0840148207301 | Y26: 标准美文版本 （13位数UPC条码） | Z26: 美文版本说明书 | AA26: 090126 | AC26: 4.5 | AD26: =AC26*I26 -> 810 | AE26: =AD26*7.75 -> 6277.5 | AF26: 83239 | AG26: =VLOOKUP(AF26,'[2]Toy Monster'!$L:$M,2,0) -> RR103车 | AH26: =VLOOKUP(AF26,'[2]Toy Monster'!$L:$T,9,FALSE) -> 46127 | AI26: 已入系统 | AK26: 客贴纸2/2日给到佩玲 | AL26: =IFERROR(VLOOKUP(G26,'已打发票扣数（26年5月开始）'!$A$1:$C$17,3,0)*I26*0.3,"") -> 243
A27: 46030 | B27: 中国台湾 | C27: Elaine | D27: Asia Goal Limited | E27: PO-AG250418 | F27: PO212218 | G27: T01685 | H27: =VLOOKUP(G27,名称!A:B,2,0) -> 手术游戏盘 | I27: 180 | J27: =VLOOKUP(G27,名称!A:C,3,FALSE) -> 6 | K27: =I27/J27 -> 30 | L27: 46108 | M27: 46107 | N27: 46107 | O27: 已约 | P27: OK | Q27: 4/13 extra costs:$60 | R27: 客自提 | T27: OK | X27: 0840148217751 | Y27: 标准美文版本 （13位数UPC条码） | Z27: 美文版本说明书 | AA27: 03/26 | AC27: 4.43 | AD27: =AC27*I27 -> 797.4 | AE27: =AD27*7.75 -> 6179.85 | AF27: 83239 | AG27: =VLOOKUP(AF27,'[2]Toy Monster'!$L:$M,2,0) -> RR103车 | AH27: =VLOOKUP(AF27,'[2]Toy Monster'!$L:$T,9,FALSE) -> 46127 | AI27: 已入系统 | AK27: 客贴纸2/2日给到佩玲 | AL27: =IFERROR(VLOOKUP(G27,'已打发票扣数（26年5月开始）'!$A$1:$C$17,3,0)*I27*0.3,"") -> 244.08
A28: 46086 | B28: 美国 | C28: Elaine | D28: Flybar Inc | E28: FB-7504 | F28: PO212516 | G28: JW-RV-RPGEA | H28: =VLOOKUP(G28,名称!A:B,2,0) -> 恐龙游戏盘(邮包盒装) | I28: 504 | J28: =VLOOKUP(G28,名称!A:C,3,FALSE) -> 6 | K28: =I28/J28 -> 84 | L28: 46134 | M28: 46122 | N28: 46122 | O28: 已约 | P28: OK | Q28: Extra Costs：$120 | R28: 40GP | T28: OK | X28: 0840148227217 | Y28: 标准美文版本 （12位数UPC条码） | Z28: 美文版本说明书 | AA28: 46113 | AC28: 4.9 | AD28: =AC28*I28 -> 2469.6 | AE28: =AD28*7.75 -> 19139.4 | AF28: 83240 | AG28: =VLOOKUP(AF28,'[2]Toy Monster'!$L:$M,2,0) -> RR201柜 | AH28: =VLOOKUP(AF28,'[2]Toy Monster'!$L:$T,9,FALSE) -> 46141 | AI28: 已入系统 | AK28: 追踪贴纸/条形码贴纸 | AL28: =IFERROR(VLOOKUP(G28,'已打发票扣数（26年5月开始）'!$A$1:$C$17,3,0)*I28*0.3,"") -> 680.4
A29: 46101 | B29: 澳大利亚 | C29: Rachel | D29: Kmart Australia & NZ Holding Limited | E29: 21657135 | F29: PO212624 | G29: T02444 | H29: =VLOOKUP(G29,名称!A:B,2,0) -> 恐龙公园二代 | I29: 6288 | J29: =VLOOKUP(G29,名称!A:C,3,FALSE) -> 12 | K29: =I29/J29 -> 524 | L29: 46142 | M29: 46135 | N29: 46135 | O29: 已约 | P29: OK | Q29: 4/27 Extra Costs：$28.82 | R29: 5吨车 | T29: OK | X29: 草地套装：0840148226203 海滩滩套装：0840148226210 实验室套装：0840148226227 | Y29: 标准美文版本 （13位数UPC条码） | Z29: 美文版本说明书 | AA29: 46138 | AB29: 外箱上下两面都需要工字形ANKO胶带封箱 | AC29: 2.1 | AD29: =AC29*I29 -> 13204.8 | AE29: =AD29*7.75 -> 102337.2 | AF29: 83241 | AG29: =VLOOKUP(AF29,'[2]Toy Monster'!$L:$M,2,0) -> RR128车 | AH29: =VLOOKUP(AF29,'[2]Toy Monster'!$L:$T,9,FALSE) -> 46141 | AI29: 已入系统 | AK29: SSCC贴纸4/2给到佩玲 | AL29: =IFERROR(VLOOKUP(G29,'已打发票扣数（26年5月开始）'!$A$1:$C$17,3,0)*I29*0.3,"") -> 3961.44
A30: 46101 | B30: 澳大利亚 | C30: Rachel | D30: Kmart Australia & NZ Holding Limited | E30: 21602319 | F30: PO212625 | G30: T02444 | H30: =VLOOKUP(G30,名称!A:B,2,0) -> 恐龙公园二代 | I30: 432 | J30: =VLOOKUP(G30,名称!A:C,3,FALSE) -> 12 | K30: =I30/J30 -> 36 | L30: 46136 | M30: 46135 | N30: 46135 | O30: 已约 | P30: OK | Q30: 4/27 Extra Costs：$1.98 | R30: 5吨车 | T30: OK | X30: 草地套装：0840148226203 海滩滩套装：0840148226210 实验室套装：0840148226227 | Y30: 标准美文版本 （13位数UPC条码） | Z30: 美文版本说明书 | AA30: 46138 | AB30: 外箱上下两面都需要工字形ANKO胶带封箱 | AC30: 2.1 | AD30: =AC30*I30 -> 907.2 | AE30: =AD30*7.75 -> 7030.8 | AF30: 83242 | AG30: =VLOOKUP(AF30,'[2]Toy Monster'!$L:$M,2,0) -> RR128车 | AH30: =VLOOKUP(AF30,'[2]Toy Monster'!$L:$T,9,FALSE) -> 46141 | AI30: 已入系统 | AK30: SSCC贴纸4/2给到佩玲 | AL30: =IFERROR(VLOOKUP(G30,'已打发票扣数（26年5月开始）'!$A$1:$C$17,3,0)*I30*0.3,"") -> 272.16
A31: 46077 | B31: 美国 | C31: Jennifer | D31: Monster Group LLC | E31: Kuma Paw 9.5 inch for WM Domestic Order | F31: PO212438 | G31: T03204 | H31: =VLOOKUP(G31,名称!A:B,2,0) -> 9.5寸粉红熊公仔+格力奇熊仔混装 | I31: 5400 | J31: =VLOOKUP(G31,名称!A:C,3,FALSE) -> 2 | K31: =I31/J31 -> 2700 | L31: 46157 | M31: 46153 | N31: 46153 | O31: 已约 | P31: OK | Q31: 46160 | R31: 5吨车 | T31: OK | X31: 840148224445 840148224469 | Y31: 沃尔玛版本彩盒 （12位数UPC条码） | Z31: / | AA31: RR11226 | AB31: 9.5寸粉红色熊仔脚底码货号为：T02943-2，与9.5寸格力奇熊仔混装，配比1:1 | AC31: 6.67 | AD31: =AC31*I31 -> 36018 | AE31: =AD31*7.75 -> 279139.5 | AF31: 83246REV1 | AG31: =VLOOKUP(AF31,'[2]Toy Monster'!$L:$M,2,0) -> RR170-171车 | AH31: =VLOOKUP(AF31,'[2]Toy Monster'!$L:$T,9,FALSE) -> 46161 | AI31: 已入系统 | AK31: RFID贴纸3/16给到佩玲 | AL31: =((896*6.34)+(896*6.64))*0.3 -> 3489.02
A32: 46101 | B32: 澳大利亚 | C32: Rachel | D32: Target Australia Pty Ltd | E32: 2617376 | F32: PO212775 | G32: T02444 | H32: =VLOOKUP(G32,名称!A:B,2,0) -> 恐龙公园二代 | I32: 1800 | J32: =VLOOKUP(G32,名称!A:C,3,FALSE) -> 12 | K32: =I32/J32 -> 150 | L32: 46156 | M32: 46156 | N32: 46156 | O32: 已约 | P32: OK | Q32: 5/23 Extra Costs：$8.25 | R32: 5吨车 | T32: OK | X32: 草地套装：0840148226203 海滩滩套装：0840148226210 实验室套装：0840148226227 | Y32: 标准美文版本 （13位数UPC条码） | Z32: 美文版本说明书 | AA32: 46138 | AB32: 普通透明胶带封箱，外箱不需要盖日期码 | AC32: 2.1 | AD32: =AC32*I32 -> 3780 | AE32: =AD32*7.75 -> 29295 | AF32: 83248 | AG32: =VLOOKUP(AF32,'[2]Toy Monster'!$L:$M,2,0) -> RR187车 | AH32: =VLOOKUP(AF32,'[2]Toy Monster'!$L:$T,9,FALSE) -> 46172 | AI32: 已入系统 | AK32: SSCC贴纸4/23给到佩玲 | AL32: =IFERROR(VLOOKUP(G32,'已打发票扣数（26年5月开始）'!$A$1:$C$17,3,0)*I32*0.3,"") -> 1134
A33: 46114 | B33: 美国 | C33: Elaine | D33: Flybar Inc | E33: FB-7781 | F33: PO212868 | G33: JW-RV-RPGEA | H33: =VLOOKUP(G33,名称!A:B,2,0) -> 恐龙游戏盘(邮包盒装) | I33: 1002 | J33: =VLOOKUP(G33,名称!A:C,3,FALSE) -> 6 | K33: =I33/J33 -> 167 | L33: 46167 | M33: 46163 | N33: 46163 | O33: 已约 | P33: OK | Q33: 5/30 Extra Costs：$20.04 | R33: 40HQ | T33: OK | X33: 0840148227217 | Y33: 亚马逊版本 （12位数UPC条码） | Z33: 美文版本说明书 | AA33: 46174 | AB33: 外箱不需要盖日期码 | AC33: 4.9 | AD33: =AC33*I33 -> 4909.8 | AE33: =AD33*7.75 -> 38050.95 | AF33: 83249 | AG33: =VLOOKUP(AF33,'[2]Toy Monster'!$L:$M,2,0) -> RR293柜 | AH33: =VLOOKUP(AF33,'[2]Toy Monster'!$L:$T,9,FALSE) -> 46172 | AI33: 已入系统 | AK33: 客追踪贴纸 | AL33: =IFERROR(VLOOKUP(G33,'已打发票扣数（26年5月开始）'!$A$1:$C$17,3,0)*I33*0.3,"")+(I33*3.55-I33*1.35) -> 3557.1
A34: 46119 | B34: 加拿大 | C34: Jennifer | D34: Canada Inc./dba Red Planet Group | E34: 005065 | F34: PO212771 | G34: JW-RV-RPGE | H34: =VLOOKUP(G34,名称!A:B,2,0) -> 恐龙游戏盘 | I34: 1800 | J34: =VLOOKUP(G34,名称!A:C,3,FALSE) -> 6 | K34: =I34/J34 -> 300 | L34: 46171 | M34: 46167 | N34: 46167 | O34: 已约 | Q34: 6/2 Extra Costs：$260 | R34: 5吨车 | T34: OK | X34: 0840148207301 | Y34: 客版本英法双语彩盒 (12位数UPC条码) | Z34: 客版英法双语说明书 | AA34: RR14226 | AB34: 外箱不需要盖日期码 | AC34: 4.5 | AD34: =AC34*I34 -> 8100 | AE34: =AD34*7.75 -> 62775 | AF34: 83250 | AG34: =VLOOKUP(AF34,'[2]Toy Monster'!$L:$M,2,0) -> RR172车 | AH34: =VLOOKUP(AF34,'[2]Toy Monster'!$L:$T,9,FALSE) -> 46177 | AI34: 已入系统 | AL34: =IFERROR(VLOOKUP(G34,'已打发票扣数（26年5月开始）'!$A$1:$C$17,3,0)*I34*0.3,"")+(I34*3.55-I34*1.35) -> 6390
A35: 46102 | B35: 加拿大 | C35: Jennifer | D35: Lachine | E35: 004980 | F35: PO212541 | G35: T03804 | H35: =VLOOKUP(G35,名称!A:B,2,0) -> 恐龙公园二代 | I35: 2964 | J35: =VLOOKUP(G35,名称!A:C,3,FALSE) -> 12 | K35: =I35/J35 -> 247 | L35: 46164 | M35: 46167 | N35: 46167 | O35: 已约 | P35: OK | Q35: 6/2 Extra Costs：$660 | R35: 5吨车 | T35: OK | X35: 840148221734 | Y35: 双语版本 （12位数UPC条码） | Z35: 双语版本说明书 | AA35: RR13826 | AB35: 混装只需装实验室和海滩两个场景，外箱不需要打日期码 | AC35: 2.1 | AD35: =AC35*I35 -> 6224.4 | AE35: =AD35*7.75 -> 48239.1 | AF35: 95751 | AG35: =VLOOKUP(AF35,'[2]Toy Monster'!$L:$M,2,0) -> RR172车 | AH35: =VLOOKUP(AF35,'[2]Toy Monster'!$L:$T,9,FALSE) -> 46177 | AI35: 已入系统 | AL35: =IFERROR(VLOOKUP(G35,'已打发票扣数（26年5月开始）'!$A$1:$C$17,3,0)*I35*0.3,"") -> 1867.32
A36: 46121 | B36: 越南 | C36: Elaine | D36: Viet Tinh Anh Joint Stock Company | E36: Viet-TM111631 | F36: PO212874 | G36: T02444 | H36: =VLOOKUP(G36,名称!A:B,2,0) -> 恐龙公园二代 | I36: 1656 | J36: =VLOOKUP(G36,名称!A:C,3,FALSE) -> 12 | K36: =I36/J36 -> 138 | L36: 46175 | M36: 46174 | N36: 46174 | O36: 已约 | P36: OK | Q36: 6/6 Extra Costs：$300 | R36: 5吨车 | T36: OK | X36: 草地套装：0840148226203 海滩滩套装：0840148226210 实验室套装：0840148226227 | Y36: 标准美文版本 （13位数UPC条码） | Z36: 美文版本说明书 | AA36: 46162 | AC36: 2.1 | AD36: =AC36*I36 -> 3477.6 | AE36: =AD36*7.75 -> 26951.4 | AF36: 95752 | AG36: =VLOOKUP(AF36,'[2]Toy Monster'!$L:$M,2,0) -> RR245柜 | AH36: =VLOOKUP(AF36,'[2]Toy Monster'!$L:$T,9,FALSE) -> 46183 | AI36: 已入系统 | AL36: =IFERROR(VLOOKUP(G36,'已打发票扣数（26年5月开始）'!$A$1:$C$17,3,0)*I36*0.3,"") -> 1043.28
A37: 46134 | B37: 韩国 | C37: Elaine | D37: BomNamu Co. Ltd | E37: BNM_TM260403 | F37: PO213297 | G37: T01535 | H37: =VLOOKUP(G37,名称!A:B,2,0) -> 恐龙公园 | I37: 540 | J37: =VLOOKUP(G37,名称!A:C,3,FALSE) -> 12 | K37: =I37/J37 -> 45 | L37: 46181 | M37: =L37-7 -> 46174 | N37: =L37-7 -> 46174 | O37: 已约 | P37: OK | Q37: 6/9 Extra Costs：$609 | R37: 5吨车 | T37: OK | U37: 进口贴纸 | X37: 0840148215733 | Y37: 标准美文版本 （13位数UPC条码） | Z37: 美文版本说明书 | AA37: 46162 | AB37: 用取消单P0210601返工 | AC37: 2.1 | AD37: =AC37*I37 -> 1134 | AE37: =AD37*7.75 -> 8788.5 | AF37: 95753 | AG37: =VLOOKUP(AF37,'[2]Toy Monster'!$L:$M,2,0) -> RR254车 | AH37: =VLOOKUP(AF37,'[2]Toy Monster'!$L:$T,9,FALSE) -> 46183 | AI37: 已入系统 | AK37: PDQ贴纸4/29给到佩玲，条形码贴纸、客贴纸5/11给到佩玲 | AL37: =IFERROR(VLOOKUP(G37,'已打发票扣数（26年5月开始）'!$A$1:$C$17,3,0)*I37*0.3,"") -> 340.2
A38: 46122 | B38: 澳大利亚 | C38: Rachel | D38: Kmart Australia & NZ Holding Limited | E38: 21688246 | F38: PO213048 | G38: T02444 | H38: =VLOOKUP(G38,名称!A:B,2,0) -> 恐龙公园二代 | I38: 1224 | J38: =VLOOKUP(G38,名称!A:C,3,FALSE) -> 12 | K38: =I38/J38 -> 102 | L38: 46174 | M38: 46174 | N38: 46174 | O38: 已约 | P38: OK | Q38: 6/10 Extra Costs：$5.61 | R38: 5吨车 | T38: OK | X38: 草地套装：0840148226203 海滩滩套装：0840148226210 实验室套装：0840148226227 | Y38: 标准美文版本 （13位数UPC条码） | Z38: 美文版本说明书 | AA38: 46138 | AB38: 外箱上下两面都需要工字形ANKO胶带封箱 | AC38: 2.1 | AD38: =AC38*I38 -> 2570.4 | AE38: =AD38*7.75 -> 19920.6 | AF38: 95754 | AG38: =VLOOKUP(AF38,'[2]Toy Monster'!$L:$M,2,0) -> RR256车 | AH38: =VLOOKUP(AF38,'[2]Toy Monster'!$L:$T,9,FALSE) -> 46184 | AI38: 已入系统 | AK38: SSCC贴纸5/20给到佩玲 | AL38: =IFERROR(VLOOKUP(G38,'已打发票扣数（26年5月开始）'!$A$1:$C$17,3,0)*I38*0.3,"") -> 771.12
A39: 46122 | B39: 新西兰 | C39: Rachel | D39: Kmart Australia & NZ Holding Limited | E39: 21688244 | F39: PO213046 | G39: T02444 | H39: =VLOOKUP(G39,名称!A:B,2,0) -> 恐龙公园二代 | I39: 5496 | J39: =VLOOKUP(G39,名称!A:C,3,FALSE) -> 12 | K39: =I39/J39 -> 458 | L39: 46174 | M39: 46174 | N39: 46174 | O39: 已约 | P39: OK | Q39: 6/10 Extra Costs:$25.19 | R39: 5吨车 | T39: OK | X39: 草地套装：0840148226203 海滩滩套装：0840148226210 实验室套装：0840148226227 | Y39: 标准美文版本 （13位数UPC条码） | Z39: 美文版本说明书 | AA39: 46138 | AB39: 外箱上下两面都需要工字形ANKO胶带封箱 | AC39: 2.1 | AD39: =AC39*I39 -> 11541.6 | AE39: =AD39*7.75 -> 89447.4 | AF39: 95755 | AG39: =VLOOKUP(AF39,'[2]Toy Monster'!$L:$M,2,0) -> RR256车 | AH39: =VLOOKUP(AF39,'[2]Toy Monster'!$L:$T,9,FALSE) -> 46184 | AI39: 已入系统 | AK39: SSCC贴纸5/20给到佩玲 | AL39: =IFERROR(VLOOKUP(G39,'已打发票扣数（26年5月开始）'!$A$1:$C$17,3,0)*I39*0.3,"") -> 3462.48
