Workbook

Sheet 名称
A1: 货号 | B1: 产品名称 | C1: 外箱 | D1: 车间
A2: 47329 | B2: 收割车 | C2: 2 | D2: A
A3: 47399 | B3: 洒水车 | C3: 4 | D3: B
A4: 47550 | B4: 回力车 | C4: 4 | D4: B
A5: 47615 | B5: 跳舞的玉米 | C5: 6 | D5: B
A6: 47640 | B6: 半挂车 | C6: 2 | D6: B
A7: 47669 | B7: 动物车 | C7: 4 | D7: KIK
A8: 47674 | B8: JD LNS圆轮拖拉机 | C8: 2 | D8: KIK
A9: 35189AZ | B9: 吹气车 | C9: 2 | D9: A
A10: 35189B | B10: 吹气车 | C10: 2 | D10: A
A11: 35189C | B11: 吹气车 | C11: 2 | D11: A
A12: 35206B | B12: 猪马牛羊车（单支装） | C12: 2 | D12: A
A13: 35802J | B13: 挖土机 | C13: 2 | D13: KIK
A14: 46644B | B14: 发光车 | C14: 2 | D14: A
A15: 46656EU1 | B15: 6"拖拉机 | C15: 4 | D15: B
A16: 46670C | B16: 46656/46748 混装 | C16: 4 | D16: B
A17: 46670TSC | B17: 46656/46748 混装 | C17: 4 | D17: B
A18: 46720J | B18: 木材运输车 | C18: 4 | D18: KIK
A19: 47101J | B19: 1:16收割机 | C19: 1 | D19: KIK
A20: 47280A | B20: 童车 | C20: 1 | D20: B
... A46: Y2049G1 | B46: 锁匙 | C46: 36 | D46: B
A47: 46088 | B47: 吹气三轮车 | C47: 1 | D47: A
A48: E73647BZR | B48: 手镯和球 | C48: 12 | D48: B
A49: 43379 | B49: 手镯和球 | C49: 12 | D49: B
A50: T72465ML3 | B50: 贪婪的老奶奶 | C50: 6 | D50: B
A51: T72465ADR2 | B51: 贪婪的老奶奶 | C51: 6 | D51: B
A52: L27870B | B52: 杯子 | C52: 18 | D52: B
A53: T72465ASC1 | B53: 贪婪的老奶奶 | C53: 6 | D53: B
A54: T72465RO | B54: 贪婪的老奶奶 | C54: 6 | D54: B
A55: T72465BZR2 | B55: 贪婪的老奶奶 | C55: 6 | D55: B
A56: 47391J | B56: 1:16收割机 | C56: 1 | D56: KIK
A57: Y2341C | B57: 杯子 | C57: 18 | D57: KIK
A58: E73855A1 | B58: 马里奥能量蘑菇吸塑混装 | C58: 6 | D58: KIK
A59: E73906 | B59: 马里奥和他的蘑菇 | C59: 6 | D59: KIK
A60: E73907 | B60: 能量蘑菇 | C60: 6 | D60: KIK
A61: E73856 | B61: 宝箱马里奥 | C61: 4 | D61: KIK
... A92: E73858 | B92: 浮水马里奥 | C92: 3 | D92: KIK
A93: L21106 | B93: 盲盒公仔(塑胶毛绒) | C93: 6 | D93: 河源 | E93: 6PCS一PDQ，1PDQ 一箱
A94: L21011 | B94: 11寸大毛绒 | C94: 2 | D94: 河源
A95: L19200 | D95: 河源
...

Sheet 总接单
A1: 产品名称 | AF1: E73956/E73956US/E73855A1/E73855US/E73956A1/E73855A2
A2: 接单日期 | B2: 国家 | C2: TOMY PO | D2: CUSTOMER PO | E2: 货号 | F2: 数量 | G2: PO走货期 | H2: L27870TG/L27870B/L27870C | I2: Y2049L/Y2049G1//Y2049G2/Y2049L1 | J2: 46720J | K2: E73622A/E73622AZ | L2: E73622AWM | M2: E73635A | N2: E74062C | O2: E73917C | P2: E73623A1 | Q2: E73636A | R2: 47669/47669TSC/47669TSCA | S2: 47674DG/47674TSC/47674DG2/47674A/47674TSCA | T2: 47674 | U2: T73785EN | V2: E73814C1 | W2: 47600J | X2: 47602J | Y2: 47367J | Z2: 47101J | AA2: 35802J | AB2: E73860C/E73860PL | AC2: 47465J1 | AD2: 47391J | AE2: Y2341C | AF2: E73906/E73906US | AG2: E73907/E73907A/E73907US/E73907A1 | AH2: E73856/E73856AZ | AI2: E73857 | AJ2: 47722A | AK2: 47723A | AL2: 47711A | AM2: 47713A | AN2: 47714A/47714ATSC | AO2: E73705A | AP2: 47023AZ2 | AQ2: 47716A | AR2: 47712A | AS2: E74041BULK/47274J | AT2: 35765D | AU2: 35766C | AV2: E73858/E73858AZ | AW2: L21106 | AX2: L21011 | AY2: 43452PL | AZ2: 47023A1 | BA2: 47616A | BB2: F5861ML2 | BC2: 47193C | BD2: L21010A7 | BE2: 35874A1J | BF2: 47020A1 | BG2: 46510A1 | BH2: L21015 | BI2: L21014 | BJ2: 47207B | BK2: 47339B | BL2: T12694N | BM2: 46701A1 | BN2: L67988A | BO2: 35874VAZJ | BP2: 068266 | BQ2: 单价USD | BR2: 金额USD | BS2: 金额HKD | BT2: 车间
A3: 45772 | B3: 比利时 | C3: 10100602 | D3: 4500031037 | E3: 47669 | F3: 680 | G3: 46015 | R3: =F3 -> 680 | BQ3: 4.906 | BR3: =SUM(H3:BP3)*BQ3 -> 3336.08 | BS3: =BR3*7.75 -> 25854.62 | BT3: =IFERROR(VLOOKUP(E3,名称!A:D,4,FALSE),"") -> KIK
A4: 45772 | B4: 比利时 | C4: 10100602 | D4: 4500031037 | E4: 47669 | F4: =1500-680 -> 820 | G4: 46078 | R4: =F4 -> 820 | BQ4: 4.906 | BR4: =SUM(H4:BP4)*BQ4 -> 4022.92 | BS4: =BR4*7.75 -> 31177.63 | BT4: =IFERROR(VLOOKUP(E4,名称!A:D,4,FALSE),"") -> KIK
A5: 45850 | B5: 澳大利亚 | C5: 10107306 | D5: 20218498 | E5: E73622A | F5: =4000-2200 -> 1800 | G5: 46036 | K5: =F5 -> 1800 | BQ5: 2.199 | BR5: =SUM(H5:BP5)*BQ5 -> 3958.2 | BS5: =BR5*7.75 -> 30676.05 | BT5: =IFERROR(VLOOKUP(E5,名称!A:D,4,FALSE),"") -> KIK
A6: 45862 | B6: 比利时 | C6: 10107795 | D6: 4500031524 | E6: E73855A1 | F6: 7200 | G6: 46029 | AF6: 4800 | AG6: 2400 | BQ6: 1.377 | BR6: =SUM(H6:BP6)*BQ6 -> 9914.4 | BS6: =BR6*7.75 -> 76836.6 | BT6: =IFERROR(VLOOKUP(E6,名称!A:D,4,FALSE),"") -> KIK
A7: 45862 | B7: 比利时 | C7: 10107795 | D7: 4500031524 | E7: E73855A1 | F7: =2802-600 -> 2202 | G7: 46078 | AF7: =F7/6*4 -> 1468 | AG7: =F7/6*2 -> 734 | BQ7: 1.377 | BR7: =SUM(H7:BP7)*BQ7 -> 3032.15 | BS7: =BR7*7.75 -> 23499.16 | BT7: =IFERROR(VLOOKUP(E7,名称!A:D,4,FALSE),"") -> KIK
A8: 45862 | B8: 比利时 | C8: 10107796 | D8: 4500031525 | E8: E73906 | F8: =3600-396 -> 3204 | G8: 46078 | AF8: =F8 -> 3204 | BQ8: 1.422 | BR8: =SUM(H8:BP8)*BQ8 -> 4556.09 | BS8: =BR8*7.75 -> 35309.7 | BT8: =IFERROR(VLOOKUP(E8,名称!A:D,4,FALSE),"") -> KIK
A9: 45862 | B9: 比利时 | C9: 10107796 | D9: 4500031525 | E9: E73907 | F9: =3600-600-1602 -> 1398 | G9: 46029 | AG9: =F9 -> 1398 | BQ9: 1.287 | BR9: =SUM(H9:BP9)*BQ9 -> 1799.23 | BS9: =BR9*7.75 -> 13944.03 | BT9: =IFERROR(VLOOKUP(E9,名称!A:D,4,FALSE),"") -> KIK
A10: 45862 | B10: 比利时 | C10: 10107796 | D10: 4500031525 | E10: E73907 | F10: 1602 | G10: 46029 | AG10: =F10 -> 1602 | BQ10: 1.287 | BR10: =SUM(H10:BP10)*BQ10 -> 2061.77 | BS10: =BR10*7.75 -> 15978.72 | BT10: =IFERROR(VLOOKUP(E10,名称!A:D,4,FALSE),"") -> KIK
A11: 45862 | B11: 比利时 | C11: 10107797 | D11: 4500031526 | E11: E73856 | F11: =10000-1500-3000-2148 -> 3352 | G11: 46029 | AH11: =F11 -> 3352 | BQ11: 2.205 | BR11: =SUM(H11:BP11)*BQ11 -> 7391.16 | BS11: =BR11*7.75 -> 57281.49 | BT11: =IFERROR(VLOOKUP(E11,名称!A:D,4,FALSE),"") -> KIK
A12: 45862 | B12: 比利时 | C12: 10107797 | D12: 4500031526 | E12: E73856 | F12: 1500 | G12: 46029 | AH12: =F12 -> 1500 | BQ12: 2.205 | BR12: =SUM(H12:BP12)*BQ12 -> 3307.5 | BS12: =BR12*7.75 -> 25633.13 | BT12: =IFERROR(VLOOKUP(E12,名称!A:D,4,FALSE),"") -> KIK
A13: 45862 | B13: 比利时 | C13: 10107797 | D13: 4500031526 | E13: E73856 | F13: =3000-52 -> 2948 | G13: 46029 | AH13: =F13 -> 2948 | BQ13: 2.205 | BR13: =SUM(H13:BP13)*BQ13 -> 6500.34 | BS13: =BR13*7.75 -> 50377.64 | BT13: =IFERROR(VLOOKUP(E13,名称!A:D,4,FALSE),"") -> KIK
A14: 45862 | B14: 比利时 | C14: 10107797 | D14: 4500031526 | E14: E73856 | F14: 52 | G14: 46043 | AH14: =F14 -> 52 | BQ14: 2.158 | BR14: =SUM(H14:BP14)*BQ14 -> 112.22 | BS14: =BR14*7.75 -> 869.71 | BT14: =IFERROR(VLOOKUP(E14,名称!A:D,4,FALSE),"") -> KIK
A15: 45862 | B15: 比利时 | C15: 10107797 | D15: 4500031526 | E15: E73856 | F15: =2148-172 -> 1976 | G15: 46078 | AH15: =F15 -> 1976 | BQ15: 2.205 | BR15: =SUM(H15:BP15)*BQ15 -> 4357.08 | BS15: =BR15*7.75 -> 33767.37 | BT15: =IFERROR(VLOOKUP(E15,名称!A:D,4,FALSE),"") -> KIK
A16: 45862 | B16: 比利时 | C16: 10107797 | D16: 4500031526 | E16: E73856 | F16: 172 | G16: 46057 | AH16: =F16 -> 172 | BQ16: 2.158 | BR16: =SUM(H16:BP16)*BQ16 -> 371.18 | BS16: =BR16*7.75 -> 2876.65 | BT16: =IFERROR(VLOOKUP(E16,名称!A:D,4,FALSE),"") -> KIK
A17: 45862 | B17: 比利时 | C17: 10107798 | D17: 4500031527 | E17: E73857 | F17: =1000-52 -> 948 | G17: 46029 | AI17: =F17 -> 948 | BQ17: 3.362 | BR17: =SUM(H17:BP17)*BQ17 -> 3187.18 | BS17: =BR17*7.75 -> 24700.65 | BT17: =IFERROR(VLOOKUP(E17,名称!A:D,4,FALSE),"") -> KIK
A18: 45862 | B18: 比利时 | C18: 10107798 | D18: 4500031527 | E18: E73857 | F18: 52 | G18: 46043 | AI18: =F18 -> 52 | BQ18: 3.216 | BR18: =SUM(H18:BP18)*BQ18 -> 167.23 | BS18: =BR18*7.75 -> 1296.03 | BT18: =IFERROR(VLOOKUP(E18,名称!A:D,4,FALSE),"") -> KIK
A19: 45862 | B19: 比利时 | C19: 10107798 | D19: 4500031527 | E19: E73857 | F19: =6000-1200-1000 -> 3800 | G19: 46036 | AI19: =F19 -> 3800 | BQ19: 3.362 | BR19: =SUM(H19:BP19)*BQ19 -> 12775.6 | BS19: =BR19*7.75 -> 99010.9 | BT19: =IFERROR(VLOOKUP(E19,名称!A:D,4,FALSE),"") -> KIK
A20: 45862 | B20: 比利时 | C20: 10107798 | D20: 4500031527 | E20: E73857 | F20: 172 | G20: 46057 | AI20: =F20 -> 172 | BQ20: 3.216 | BR20: =SUM(H20:BP20)*BQ20 -> 553.15 | BS20: =BR20*7.75 -> 4286.91 | BT20: =IFERROR(VLOOKUP(E20,名称!A:D,4,FALSE),"") -> KIK
A21: 45862 | B21: 比利时 | C21: 10107798 | D21: 4500031527 | E21: E73857 | F21: =1200-172 -> 1028 | G21: 46078 | AI21: =F21 -> 1028 | BQ21: 3.362 | BR21: =SUM(H21:BP21)*BQ21 -> 3456.14 | BS21: =BR21*7.75 -> 26785.09 | BT21: =IFERROR(VLOOKUP(E21,名称!A:D,4,FALSE),"") -> KIK
A22: 45862 | B22: 比利时 | C22: 10107798 | D22: 4500031527 | E22: E73956 | F22: =5500-500-2-54 -> 4944 | G22: 46029 | AF22: =F22/6*3 -> 2472 | AG22: =F22/6*3 -> 2472 | BQ22: 2.339 | BR22: =SUM(H22:BP22)*BQ22 -> 11564.02 | BS22: =BR22*7.75 -> 89621.16 | BT22: =IFERROR(VLOOKUP(E22,名称!A:D,4,FALSE),"") -> KIK
A23: 45862 | B23: 比利时 | C23: 10107798 | D23: 4500031527 | E23: E73956 | F23: 54 | G23: 46043 | AF23: =F23/6*3 -> 27 | AG23: =F23/6*3 -> 27 | BQ23: 2.299 | BR23: =SUM(H23:BP23)*BQ23 -> 124.15 | BS23: =BR23*7.75 -> 962.16 | BT23: =IFERROR(VLOOKUP(E23,名称!A:D,4,FALSE),"") -> KIK
A24: 45862 | B24: 比利时 | C24: 10107799 | D24: 4500031528 | E24: E73855A1 | F24: =1500+600-600 -> 1500 | G24: 46057 | AF24: =F24/6*4 -> 1000 | AG24: =F24/6*2 -> 500 | BQ24: 1.377 | BR24: =SUM(H24:BP24)*BQ24 -> 2065.5 | BS24: =BR24*7.75 -> 16007.63 | BT24: =IFERROR(VLOOKUP(E24,名称!A:D,4,FALSE),"") -> KIK
A25: 45862 | B25: 比利时 | C25: 10107799 | D25: 4500031528 | E25: E73856 | F25: 1000 | G25: 46057 | AH25: =F25 -> 1000 | BQ25: 2.205 | BR25: =SUM(H25:BP25)*BQ25 -> 2205 | BS25: =BR25*7.75 -> 17088.75 | BT25: =IFERROR(VLOOKUP(E25,名称!A:D,4,FALSE),"") -> KIK
A26: 45862 | B26: 比利时 | C26: 10107799 | D26: 4500031528 | E26: E73857 | F26: 1500 | G26: 46057 | AI26: =F26 -> 1500 | BQ26: 3.362 | BR26: =SUM(H26:BP26)*BQ26 -> 5043 | BS26: =BR26*7.75 -> 39083.25 | BT26: =IFERROR(VLOOKUP(E26,名称!A:D,4,FALSE),"") -> KIK
A27: 45868 | B27: 澳大利亚 | C27: 10108133 | D27: 20218536 | E27: E73623A1 | F27: 3000 | G27: 46036 | P27: =F27 -> 3000 | BQ27: 1.398 | BR27: =SUM(H27:BP27)*BQ27 -> 4194 | BS27: =BR27*7.75 -> 32503.5 | BT27: =IFERROR(VLOOKUP(E27,名称!A:D,4,FALSE),"") -> KIK
A28: 45869 | B28: 美国 | C28: 10108291 | D28: 202520972529 | E28: E73855US | F28: 1002 | G28: 46057 | AF28: =F28/6*4 -> 668 | AG28: =F28/6*2 -> 334 | BQ28: 1.311 | BR28: =SUM(H28:BP28)*BQ28 -> 1313.62 | BS28: =BR28*7.75 -> 10180.56 | BT28: =IFERROR(VLOOKUP(E28,名称!A:D,4,FALSE),"") -> KIK
A29: 45869 | B29: 美国 | C29: 10108291 | D29: 202520972529 | E29: E73856 | F29: =6000-1500-2852+4 -> 1652 | G29: 46015 | AH29: =F29 -> 1652 | BQ29: 2.205 | BR29: =SUM(H29:BP29)*BQ29 -> 3642.66 | BS29: =BR29*7.75 -> 28230.62 | BT29: =IFERROR(VLOOKUP(E29,名称!A:D,4,FALSE),"") -> KIK
A30: 45869 | B30: 美国 | C30: 10108291 | D30: 202520972529 | E30: E73856 | F30: 1500 | G30: 46015 | AH30: =F30 -> 1500 | BQ30: 2.205 | BR30: =SUM(H30:BP30)*BQ30 -> 3307.5 | BS30: =BR30*7.75 -> 25633.13 | BT30: =IFERROR(VLOOKUP(E30,名称!A:D,4,FALSE),"") -> KIK
A31: 45869 | B31: 美国 | C31: 10108291 | D31: 202520972529 | E31: E73856 | F31: 2852 | G31: 46050 | AH31: =F31 -> 2852 | BQ31: 2.205 | BR31: =SUM(H31:BP31)*BQ31 -> 6288.66 | BS31: =BR31*7.75 -> 48737.12 | BT31: =IFERROR(VLOOKUP(E31,名称!A:D,4,FALSE),"") -> KIK
A32: 45869 | B32: 美国 | C32: 10108291 | D32: 202520972529 | E32: E73857 | F32: 2000 | G32: 46029 | AI32: =F32 -> 2000 | BQ32: 3.362 | BR32: =SUM(H32:BP32)*BQ32 -> 6724 | BS32: =BR32*7.75 -> 52111 | BT32: =IFERROR(VLOOKUP(E32,名称!A:D,4,FALSE),"") -> KIK
A33: 45869 | B33: 美国 | C33: 10108291 | D33: 202520972529 | E33: E73857 | F33: 1200 | G33: 46043 | AI33: =F33 -> 1200 | BQ33: 3.362 | BR33: =SUM(H33:BP33)*BQ33 -> 4034.4 | BS33: =BR33*7.75 -> 31266.6 | BT33: =IFERROR(VLOOKUP(E33,名称!A:D,4,FALSE),"") -> KIK
A34: 45869 | B34: 美国 | C34: 10108291 | D34: 202520972529 | E34: E73857 | F34: 4800 | G34: 46043 | AI34: =F34 -> 4800 | BQ34: 3.362 | BR34: =SUM(H34:BP34)*BQ34 -> 16137.6 | BS34: =BR34*7.75 -> 125066.4 | BT34: =IFERROR(VLOOKUP(E34,名称!A:D,4,FALSE),"") -> KIK
A35: 45869 | B35: 美国 | C35: 10108291 | D35: 202520972529 | E35: E73906US | F35: =12000-4500-2898-3204+6 -> 1404 | G35: 46015 | AF35: =F35 -> 1404 | BQ35: 1.413 | BR35: =SUM(H35:BP35)*BQ35 -> 1983.85 | BS35: =BR35*7.75 -> 15374.84 | BT35: =IFERROR(VLOOKUP(E35,名称!A:D,4,FALSE),"") -> KIK
A36: 45869 | B36: 美国 | C36: 10108291 | D36: 202520972529 | E36: E73906US | F36: 4500 | G36: 46029 | AF36: =F36 -> 4500 | BQ36: 1.413 | BR36: =SUM(H36:BP36)*BQ36 -> 6358.5 | BS36: =BR36*7.75 -> 49278.38 | BT36: =IFERROR(VLOOKUP(E36,名称!A:D,4,FALSE),"") -> KIK
A37: 45869 | B37: 美国 | C37: 10108291 | D37: 202520972529 | E37: E73906US | F37: 2898 | G37: 46043 | AF37: =F37 -> 2898 | BQ37: 1.413 | BR37: =SUM(H37:BP37)*BQ37 -> 4094.87 | BS37: =BR37*7.75 -> 31735.24 | BT37: =IFERROR(VLOOKUP(E37,名称!A:D,4,FALSE),"") -> KIK
A38: 45869 | B38: 美国 | C38: 10108291 | D38: 202520972529 | E38: E73906US | F38: 3204 | G38: 46050 | AF38: =F38 -> 3204 | BQ38: 1.413 | BR38: =SUM(H38:BP38)*BQ38 -> 4527.25 | BS38: =BR38*7.75 -> 35086.19 | BT38: =IFERROR(VLOOKUP(E38,名称!A:D,4,FALSE),"") -> KIK
A39: 45869 | B39: 美国 | C39: 10108291 | D39: 202520972529 | E39: E73907US | F39: 3000 | G39: 46092 | AG39: =F39 -> 3000 | BQ39: 1.278 | BR39: =SUM(H39:BP39)*BQ39 -> 3834 | BS39: =BR39*7.75 -> 29713.5 | BT39: =IFERROR(VLOOKUP(E39,名称!A:D,4,FALSE),"") -> KIK
A40: 45869 | B40: 美国 | C40: 10108291 | D40: 202520972529 | E40: E73956US | F40: 6000 | G40: 46057 | AF40: =F40/6*3 -> 3000 | AG40: =F40/6*3 -> 3000 | BQ40: 2.33 | BR40: =SUM(H40:BP40)*BQ40 -> 13980 | BS40: =BR40*7.75 -> 108345 | BT40: =IFERROR(VLOOKUP(E40,名称!A:D,4,FALSE),"") -> KIK
...

Sheet KIK总排期
A1: 接单期 | B1: 提交化学测试 | C1: 国家 | D1: 第三客户名称 | E1: 客跟单 | F1: TOMY PO | G1: CUSTOMER PO | H1: 货号 | I1: 产品名称 | J1: 数量 | K1: 外箱 | L1: 总箱数 | M1: PO走货期 | N1: 验货期 | O1: 实际验货期 | P1: 日期码 | Q1: 箱唛资料 | R1: Spot check | S1: 年报测试 | T1: 客贴纸 | U1: 印尼回复上拉时间 | V1: 印尼回复完成时间 | W1: 箱唛状态 | X1: 备注 | Y1: 单价USD | Z1: 金额USD | AA1: 金额HKD | AB1: 发票号 | AC1: 船期 | AD1: 是否入系统 | AE1: 车间 | AF1: 混装比例 | AG1: 确认采购日期 | AH1: 包材上料时间 | AI1: 塑胶件上料时间 | AJ1: 纸吉 | AK1: PCBA | AL1: 五金 | AM1: 贴纸 | AN1: 仓库复来料时间 | AO1: 接单周期 | AP1: 印尼周期
A2: 45947 | B2: =IF(TODAY()>=A2,IF(R2="","未",""),"") -> 未 | F2: MA | H2: 35802J | I2: =IFERROR(VLOOKUP(H2,名称!A:C,2,0),"") -> 挖土机 | J2: 2500 | K2: =IFERROR(VLOOKUP(H2,名称!A:D,3,0),"") -> 2 | L2: =IFERROR((J2/K2),"") -> 1250 | X2: 内部释放MA | Y2: 0 | Z2: =J2*Y2 -> 0 | AA2: =Z2*7.75 -> 0 | AE2: =IFERROR(VLOOKUP(H2,名称!A:D,4,0),"") -> KIK | AF2: 2025/11/27 | AK2: 45987 | AO2: =M2-A2 -> -45947 | AP2: =M2-AH2 -> 0
A3: 45947 | B3: =IF(TODAY()>=A3,IF(R3="","未",""),"") -> 未 | F3: MA | H3: 47602J | I3: =IFERROR(VLOOKUP(H3,名称!A:C,2,0),"") -> 1:16翻斗车 | J3: 2500 | K3: =IFERROR(VLOOKUP(H3,名称!A:D,3,0),"") -> 4 | L3: =IFERROR((J3/K3),"") -> 625 | X3: 内部释放MA | Y3: 0 | Z3: =J3*Y3 -> 0 | AA3: =Z3*7.75 -> 0 | AE3: =IFERROR(VLOOKUP(H3,名称!A:D,4,0),"") -> KIK | AF3: 45995 | AH3: 46022 | AI3: 45995 | AL3: 45995 | AO3: =M3-A3 -> -45947 | AP3: =M3-AH3 -> -46022
A4: 45951 | B4: =IF(TODAY()>=A4,IF(R4="","未",""),"") -> 未 | F4: MA | H4: E73622A | I4: =IFERROR(VLOOKUP(H4,名称!A:C,2,0),"") -> 布鲁伊家族杯子套装 | J4: =50000-1012-10000-10000+50000-5004-3000-5000-5004-10000-5000 -> 45980 | K4: =IFERROR(VLOOKUP(H4,名称!A:D,3,0),"") -> 4 | L4: =IFERROR((J4/K4),"") -> 11495 | M4: 46120 | N4: =M4-2 -> 46118 | X4: 内部释放MA/塑胶件和喷油 | Y4: 0 | Z4: =J4*Y4 -> 0 | AA4: =Z4*7.75 -> 0 | AE4: =IFERROR(VLOOKUP(H4,名称!A:D,4,0),"") -> KIK | AO4: =M4-A4 -> 169 | AP4: =M4-AH4 -> 46120
A5: 46041 | B5: =IF(TODAY()>=A5,IF(R5="","未",""),"") | C5: 欧美 | F5: MA | H5: E73906 | I5: =IFERROR(VLOOKUP(H5,名称!A:C,2,0),"") -> 马里奥和他的蘑菇 | J5: 22744 | K5: =IFERROR(VLOOKUP(H5,名称!A:D,3,0),"") -> 6 | L5: =IFERROR((J5/K5),"") -> 3790.6667 | M5: 46216 | N5: =M5-2 -> 46214 | R5: 5/25 ok | X5: 内部释放MA/马里奥搪胶喷油 | Y5: 0 | Z5: =J5*Y5 -> 0 | AA5: =Z5*7.75 -> 0 | AE5: =IFERROR(VLOOKUP(H5,名称!A:D,4,0),"") -> KIK | AK5: 无 | AL5: 无 | AO5: =M5-A5 -> 175 | AP5: =M5-AH5 -> 46216
A6: 46044 | B6: =IF(TODAY()>=A6,IF(R6="","未",""),"") | C6: 比利时 | D6: TOMY UK CO LTD | E6: Gary | F6: 10119539 | G6: 4500032198 | H6: L21106 | I6: =IFERROR(VLOOKUP(H6,名称!A:C,2,0),"") -> 盲盒公仔(塑胶毛绒) | J6: 11514 | K6: =IFERROR(VLOOKUP(H6,名称!A:D,3,0),"") -> 6 | L6: =IFERROR((J6/K6),"") -> 1919 | M6: 46190 | N6: =M6-2 -> 46188 | O6: 46184 | P6: D1526RR02 | Q6: 标准唛+TTT+欧盟信息 | R6: 6/5ok | Y6: 3.959 | Z6: =J6*Y6 -> 45583.93 | AA6: =Z6*7.75 -> 353275.46 | AE6: =IFERROR(VLOOKUP(H6,名称!A:D,4,0),"") -> 河源 | AH6: 46135 | AI6: 46129 | AK6: 无 | AL6: 46134 | AN6: 3/23放产 | AO6: =M6-A6 -> 146 | AP6: =M6-AH6 -> 55
A7: 46112 | B7: =IF(TODAY()>=A7,IF(R7="","未",""),"") | C7: 美国 | D7: TOMY INTERNATIONAL INC. | E7: Olivia | F7: 10123756 | G7: 202608570043 | H7: E73857AZ | I7: =IFERROR(VLOOKUP(H7,名称!A:C,2,0),"") -> 管道马里奥 | J7: 5000 | K7: =IFERROR(VLOOKUP(H7,名称!A:D,3,0),"") -> 4 | L7: =IFERROR((J7/K7),"") -> 1250 | M7: 46246 | N7: =M7-2 -> 46244 | O7: 46231 | P7: F1526RR02 | Q7: 标准唛+TTT | R7: 6/9 ok | Y7: 3.354 | Z7: =J7*Y7 -> 16770 | AA7: =Z7*7.75 -> 129967.5 | AE7: =IFERROR(VLOOKUP(H7,名称!A:D,4,0),"") -> KIK | AH7: 彩盒6/16， 吸塑6/24 | AI7: 无 | AK7: 无 | AL7: 无 | AN7: 未放产 | AO7: =M7-A7 -> 134 | AP7: =M7-AH7 -> #VALUE!
A8: 46112 | B8: =IF(TODAY()>=A8,IF(R8="","未",""),"") | C8: 美国 | D8: TOMY INTERNATIONAL INC. | E8: Olivia | F8: 10123756 | G8: 202608570043 | H8: E73856AZ | I8: =IFERROR(VLOOKUP(H8,名称!A:C,2,0),"") -> 宝箱马里奥 | J8: =5000-3000-600 -> 1400 | K8: =IFERROR(VLOOKUP(H8,名称!A:D,3,0),"") -> 4 | L8: =IFERROR((J8/K8),"") -> 350 | M8: 46246 | N8: =M8-2 -> 46244 | O8: 46231 | P8: F1526RR02 | Q8: 标准唛+TTT | R8: 7/7 ok | Y8: 2.15 | Z8: =J8*Y8 -> 3010 | AA8: =Z8*7.75 -> 23327.5 | AE8: =IFERROR(VLOOKUP(H8,名称!A:D,4,0),"") -> KIK | AH8: 46189 | AK8: 无 | AL8: 无 | AN8: 未放产 | AO8: =M8-A8 -> 134 | AP8: =M8-AH8 -> 57
A9: 46098 | B9: =IF(TODAY()>=A9,IF(R9="","未",""),"") | C9: 美国 | D9: TOMY INTERNATIONAL INC. | E9: Olivia | F9: 10119018 | G9: 202601272243 | H9: E73858AZ | I9: =IFERROR(VLOOKUP(H9,名称!A:C,2,0),"") -> 浮水马里奥 | J9: 5001 | K9: =IFERROR(VLOOKUP(H9,名称!A:D,3,0),"") -> 3 | L9: =IFERROR((J9/K9),"") -> 1667 | M9: 46246 | N9: =M9-2 -> 46244 | O9: 46245 | P9: E1526RR02 | Q9: 标准唛+TTT | R9: 7/15 ok | Y9: 2.925 | Z9: =J9*Y9 -> 14627.93 | AA9: =Z9*7.75 -> 113366.46 | AE9: =IFERROR(VLOOKUP(H9,名称!A:D,4,0),"") -> KIK | AH9: 46189 | AI9: 46184 | AK9: 无 | AL9: 46134 | AN9: 未放产 | AO9: =M9-A9 -> 148 | AP9: =M9-AH9 -> 57
A10: 46129 | B10: =IF(TODAY()>=A10,IF(R10="","未",""),"") | C10: 英国 | D10: ARGOS LIMITED | E10: Nancy | F10: 10125316 | G10: 56811 | H10: E73705A | I10: =IFERROR(VLOOKUP(H10,名称!A:C,2,0),"") -> 布鲁伊混装 | J10: 7500 | K10: =IFERROR(VLOOKUP(H10,名称!A:D,3,0),"") -> 4 | L10: =IFERROR((J10/K10),"") -> 1875 | M10: 46239 | N10: =M10-2 -> 46237 | O10: 46237 | P10: G1526RR02 | Q10: 客唛+TTT+欧盟信息 | R10: 6/5ok | X10: 有特殊贴纸 | Y10: 2.115 | Z10: =J10*Y10 -> 15862.5 | AA10: =Z10*7.75 -> 122934.38 | AE10: =IFERROR(VLOOKUP(H10,名称!A:D,4,0),"") -> KIK | AH10: 46149 | AL10: 46149 | AO10: =M10-A10 -> 110 | AP10: =M10-AH10 -> 90
A11: 46135 | B11: =IF(TODAY()>=A11,IF(R11="","未",""),"") | C11: 澳大利亚 | D11: TOMY AUSTRALIA PTY, LTD. | E11: Toby | F11: 10125945 | G11: 20219070 | H11: E73623A1 | I11: =IFERROR(VLOOKUP(H11,名称!A:C,2,0),"") -> 布鲁伊+宾果沐浴玩具混装 | J11: 3000 | K11: =IFERROR(VLOOKUP(H11,名称!A:D,3,0),"") -> 6 | L11: =IFERROR((J11/K11),"") -> 500 | M11: 46239 | N11: =M11-2 -> 46237 | O11: 46237 | P11: G1526RR02 | Q11: 标准唛+TTT | R11: 6/2 ok | Y11: 1.398 | Z11: =J11*Y11 -> 4194 | AA11: =Z11*7.75 -> 32503.5 | AE11: =IFERROR(VLOOKUP(H11,名称!A:D,4,0),"") -> KIK | AH11: 46171 | AI11: 无 | AK11: 无 | AO11: =M11-A11 -> 104 | AP11: =M11-AH11 -> 68
A12: 46135 | B12: =IF(TODAY()>=A12,IF(R12="","未",""),"") | C12: 中国 | D12: TOMY UK CO LTD | E12: Olivia | F12: 10125938 | G12: 4500032691 | H12: E73623A1 | I12: =IFERROR(VLOOKUP(H12,名称!A:C,2,0),"") -> 布鲁伊+宾果沐浴玩具混装 | J12: 504 | K12: =IFERROR(VLOOKUP(H12,名称!A:D,3,0),"") -> 6 | L12: =IFERROR((J12/K12),"") -> 84 | M12: 46253 | N12: =M12-2 -> 46251 | O12: 46237 | P12: G1526RR02 | Q12: 标准唛+TTT+欧盟信息 | R12: 5/20 ok | Y12: 1.398 | Z12: =J12*Y12 -> 704.59 | AA12: =Z12*7.75 -> 5460.57 | AE12: =IFERROR(VLOOKUP(H12,名称!A:D,4,0),"") -> KIK | AH12: 46171 | AI12: 无 | AK12: 无 | AO12: =M12-A12 -> 118 | AP12: =M12-AH12 -> 82
A13: 46135 | B13: =IF(TODAY()>=A13,IF(R13="","未",""),"") | C13: 比利时 | D13: TOMY UK CO LTD | E13: Olivia | F13: 10125936 | G13: 4500032690 | H13: E73623A1 | I13: =IFERROR(VLOOKUP(H13,名称!A:C,2,0),"") -> 布鲁伊+宾果沐浴玩具混装 | J13: 1500 | K13: =IFERROR(VLOOKUP(H13,名称!A:D,3,0),"") -> 6 | L13: =IFERROR((J13/K13),"") -> 250 | M13: 46246 | N13: =M13-2 -> 46244 | O13: 46237 | P13: G1526RR02 | Q13: 标准唛+TTT+欧盟信息 | R13: 5/20 ok | Y13: 1.398 | Z13: =J13*Y13 -> 2097 | AA13: =Z13*7.75 -> 16251.75 | AE13: =IFERROR(VLOOKUP(H13,名称!A:D,4,0),"") -> KIK | AH13: 46171 | AI13: 无 | AK13: 无 | AO13: =M13-A13 -> 111 | AP13: =M13-AH13 -> 75
A14: 46149 | B14: =IF(TODAY()>=A14,IF(R14="","未",""),"") | C14: 比利时 | D14: TOMY UK CO LTD | E14: Olivia | F14: 10126801 | G14: 4500032770 | H14: E73705A | I14: =IFERROR(VLOOKUP(H14,名称!A:C,2,0),"") -> 布鲁伊混装 | J14: 2360 | K14: =IFERROR(VLOOKUP(H14,名称!A:D,3,0),"") -> 4 | L14: =IFERROR((J14/K14),"") -> 590 | M14: 46246 | N14: =M14-2 -> 46244 | O14: 46237 | P14: G1526RR02 | Q14: 标准唛+TTT+欧盟信息 | R14: 5/20 ok | Y14: 2.204 | Z14: =J14*Y14 -> 5201.44 | AA14: =Z14*7.75 -> 40311.16 | AE14: =IFERROR(VLOOKUP(H14,名称!A:D,4,0),"") -> KIK | AH14: 46171 | AL14: 46171 | AN14: 46170 | AO14: =M14-A14 -> 97 | AP14: =M14-AH14 -> 75
A15: 46162 | B15: =IF(TODAY()>=A15,IF(R15="","未",""),"") | C15: 中国 | D15: TOMY UK CO LTD | E15: Warren | F15: 10127804 | G15: 4500032849 | H15: E73705A | I15: =IFERROR(VLOOKUP(H15,名称!A:C,2,0),"") -> 布鲁伊混装 | J15: 480 | K15: =IFERROR(VLOOKUP(H15,名称!A:D,3,0),"") -> 4 | L15: =IFERROR((J15/K15),"") -> 120 | M15: 46253 | N15: =M15-2 -> 46251 | O15: 46237 | P15: G1526RR02 | Q15: 标准唛+TTT+欧盟信息 | R15: 6/2 ok | X15: 从PO10126801转入 | Y15: 2.204 | Z15: =J15*Y15 -> 1057.92 | AA15: =Z15*7.75 -> 8198.88 | AE15: =IFERROR(VLOOKUP(H15,名称!A:D,4,0),"") -> KIK | AH15: 46171 | AL15: 46171 | AO15: =M15-A15 -> 91 | AP15: =M15-AH15 -> 82
A16: 46028 | B16: =IF(TODAY()>=A16,IF(R16="","未",""),"") | C16: 澳大利亚 | D16: TOMY AUSTRALIA PTY, LTD. | E16: Toby | F16: 10118393 | G16: 20218861 | H16: E73622A | I16: =IFERROR(VLOOKUP(H16,名称!A:C,2,0),"") -> 布鲁伊家族杯子套装 | J16: 3000 | K16: =IFERROR(VLOOKUP(H16,名称!A:D,3,0),"") -> 4 | L16: =IFERROR((J16/K16),"") -> 750 | M16: 46288 | N16: =M16-2 -> 46286 | P16: D1526RR02 | Q16: 标准唛+TTT | R16: 5/29ok | S16: 4/1 ok | Y16: 2.199 | Z16: =J16*Y16 -> 6597 | AA16: =Z16*7.75 -> 51126.75 | AE16: =IFERROR(VLOOKUP(H16,名称!A:D,4,0),"") -> KIK | AH16: 46067 | AI16: 无 | AK16: 无 | AL16: 无 | AO16: =M16-A16 -> 260 | AP16: =M16-AH16 -> 221
A17: 46163 | B17: =IF(TODAY()>=A17,IF(R17="","未",""),"") | C17: 美国 | D17: TOMY INTERNATIONAL INC. | E17: Olivia | F17: 10127831 | G17: PO-000000746 | H17: Y2049L1 | I17: =IFERROR(VLOOKUP(H17,名称!A:C,2,0),"") -> 锁匙 | J17: 10008 | K17: =IFERROR(VLOOKUP(H17,名称!A:D,3,0),"") -> 36 | L17: =IFERROR((J17/K17),"") -> 278 | M17: 46246 | N17: =M17-2 -> 46244 | O17: 46245 | P17: G1526RR02 | Q17: 标准唛+TTT | R17: 6/22 ok | Y17: 0.324 | Z17: =J17*Y17 -> 3242.59 | AA17: =Z17*7.75 -> 25130.07 | AE17: =IFERROR(VLOOKUP(H17,名称!A:D,4,0),"") -> KIK | AH17: 46184 | AI17: 无 | AK17: 无 | AL17: 无 | AO17: =M17-A17 -> 83 | AP17: =M17-AH17 -> 62
A18: 46164 | B18: =IF(TODAY()>=A18,IF(R18="","未",""),"") | C18: 美国 | D18: TOMY INTERNATIONAL INC. | E18: Olivia | F18: 10127866 | G18: PO-000000943 | H18: Y2341C | I18: =IFERROR(VLOOKUP(H18,名称!A:C,2,0),"") -> 杯子 | J18: =10008+10008 -> 20016 | K18: =IFERROR(VLOOKUP(H18,名称!A:D,3,0),"") -> 18 | L18: =IFERROR((J18/K18),"") -> 1112 | M18: 46246 | N18: =M18-2 -> 46244 | O18: 46245 | P18: G1526RR02 | Q18: 标准唛+TTT | R18: 6/22ok | Y18: 0.963 | Z18: =J18*Y18 -> 19275.41 | AA18: =Z18*7.75 -> 149384.43 | AE18: =IFERROR(VLOOKUP(H18,名称!A:D,4,0),"") -> KIK | AH18: 46197 | AI18: 无 | AJ18: 46220 | AK18: 无 | AL18: 无 | AO18: =M18-A18 -> 82 | AP18: =M18-AH18 -> 49
A19: 46137 | B19: =IF(TODAY()>=A19,IF(R19="","未",""),"") | C19: 英国 | D19: TOMY UK CO LTD | E19: Warren | F19: 10126125 | G19: 4500032727 | H19: 47674A | I19: =IFERROR(VLOOKUP(H19,名称!A:C,2,0),"") -> JD LNS圆轮拖拉机 | J19: 400 | K19: =IFERROR(VLOOKUP(H19,名称!A:D,3,0),"") -> 2 | L19: =IFERROR((J19/K19),"") -> 200 | M19: 46253 | N19: =M19-2 -> 46251 | O19: 46245 | P19: G1526RR02 | Q19: 标准唛+TTT+欧盟信息 | R19: 5/25 ok | T19: 有JD贴纸 | Y19: 4.792 | Z19: =J19*Y19 -> 1916.8 | AA19: =Z19*7.75 -> 14855.2 | AE19: =IFERROR(VLOOKUP(H19,名称!A:D,4,0),"") -> KIK | AH19: 46189 | AI19: 无 | AK19: 已上 | AL19: 46184 | AN19: 46191 | AO19: =M19-A19 -> 116 | AP19: =M19-AH19 -> 64
A20: 46156 | B20: =IF(TODAY()>=A20,IF(R20="","未",""),"") | C20: 英国 | D20: TOMY UK CO LTD | E20: Nancy | F20: 10127402 | G20: 4500032826 | H20: 47674A | I20: =IFERROR(VLOOKUP(H20,名称!A:C,2,0),"") -> JD LNS圆轮拖拉机 | J20: 400 | K20: =IFERROR(VLOOKUP(H20,名称!A:D,3,0),"") -> 2 | L20: =IFERROR((J20/K20),"") -> 200 | M20: 46253 | N20: =M20-2 -> 46251 | O20: 46245 | P20: G1526RR02 | Q20: 标准唛+TTT+欧盟信息 | R20: 5/25 ok | T20: 有JD贴纸 | Y20: 4.792 | Z20: =J20*Y20 -> 1916.8 | AA20: =Z20*7.75 -> 14855.2 | AE20: =IFERROR(VLOOKUP(H20,名称!A:D,4,0),"") -> KIK | AH20: 46189 | AI20: 无 | AK20: 46197 | AL20: 46184 | AN20: 46191 | AO20: =M20-A20 -> 97 | AP20: =M20-AH20 -> 64
A21: 46179 | B21: =IF(TODAY()>=A21,IF(R21="","未",""),"") | C21: 美国 | D21: TOMY INTERNATIONAL INC. | E21: Olivia | F21: 10129047 | G21: PO-000001294 | H21: E73622AZ | I21: =IFERROR(VLOOKUP(H21,名称!A:C,2,0),"") -> 布鲁伊家族沐浴玩具 | J21: 5004 | K21: 6 | L21: =IFERROR((J21/K21),"") -> 834 | M21: 46253 | N21: =M21-2 -> 46251 | O21: 预计8/19 | P21: G1526RR02 | Q21: 标准唛+TTT | R21: 7/31 ok | Y21: 2.001 | Z21: =J21*Y21 -> 10013 | AA21: =Z21*7.75 -> 77600.75 | AH21: 46197 | AI21: 无 | AK21: 无 | AL21: 无 | AO21: =M21-A21 -> 74 | AP21: =M21-AH21 -> 56
A22: 46205 | B22: =IF(TODAY()>=A22,IF(R22="","未",""),"") | C22: 美国 | D22: NEWTON BUYING CORP. (T.J.MAXX) | E22: Olivia | F22: 10131168 | G22: 80 527344 | H22: E73622A | I22: =IFERROR(VLOOKUP(H22,名称!A:C,2,0),"") -> 布鲁伊家族杯子套装 | J22: 248 | K22: 4 | L22: =IFERROR((J22/K22),"") -> 62 | M22: 2026/8/19周三 | N22: 46251 | O22: 预计8/19 | P22: G1526RR02 | Q22: 客唛7/27确认 | R22: 7/31 ok | T22: 有价钱贴纸 | X22: 使用PO#10129047的物料 | Y22: 2.199 | Z22: =J22*Y22 -> 545.35 | AA22: =Z22*7.75 -> 4226.46 | AE22: =IFERROR(VLOOKUP(H22,名称!A:D,4,0),"") -> KIK | AH22: 46221 | AI22: 无 | AK22: 无 | AL22: 无 | AO22: =M22-A22 -> #VALUE! | AP22: =M22-AH22 -> #VALUE!
A23: 46205 | B23: =IF(TODAY()>=A23,IF(R23="","未",""),"") | C23: 美国 | D23: MARSHALLS OF MA, INC | E23: Olivia | F23: 10131170 | G23: 01 527336 | H23: E73622A | I23: =IFERROR(VLOOKUP(H23,名称!A:C,2,0),"") -> 布鲁伊家族杯子套装 | J23: 1032 | K23: 4 | L23: =IFERROR((J23/K23),"") -> 258 | M23: 2026/8/19周三 | N23: 46251 | O23: 预计8/19 | P23: G1526RR02 | Q23: 客唛7/27确认 | R23: 7/31 ok | T23: 有价钱贴纸 | X23: 使用PO#10129047的物料 | Y23: 2.199 | Z23: =J23*Y23 -> 2269.37 | AA23: =Z23*7.75 -> 17587.62 | AE23: =IFERROR(VLOOKUP(H23,名称!A:D,4,0),"") -> KIK | AH23: 46221 | AI23: 无 | AK23: 无 | AL23: 无 | AO23: =M23-A23 -> #VALUE! | AP23: =M23-AH23 -> #VALUE!
A24: 46205 | B24: =IF(TODAY()>=A24,IF(R24="","未",""),"") | C24: 美国 | D24: MARSHALLS OF MA, INC | E24: Olivia | F24: 10131172 | G24: 04 527336 | H24: E73622A | I24: =IFERROR(VLOOKUP(H24,名称!A:C,2,0),"") -> 布鲁伊家族杯子套装 | J24: 812 | K24: 4 | L24: =IFERROR((J24/K24),"") -> 203 | M24: 2026/8/19周三 | N24: 46251 | O24: 预计8/19 | P24: G1526RR02 | Q24: 客唛7/27确认 | R24: 7/31 ok | T24: 有价钱贴纸 | X24: 使用PO#10129047的物料 | Y24: 2.199 | Z24: =J24*Y24 -> 1785.59 | AA24: =Z24*7.75 -> 13838.32 | AE24: =IFERROR(VLOOKUP(H24,名称!A:D,4,0),"") -> KIK | AH24: 46221 | AI24: 无 | AK24: 无 | AL24: 无 | AO24: =M24-A24 -> #VALUE! | AP24: =M24-AH24 -> #VALUE!
A25: 46205 | B25: =IF(TODAY()>=A25,IF(R25="","未",""),"") | C25: 美国 | D25: MARSHALLS OF MA, INC | E25: Olivia | F25: 10131173 | G25: 06 527336 | H25: E73622A | I25: =IFERROR(VLOOKUP(H25,名称!A:C,2,0),"") -> 布鲁伊家族杯子套装 | J25: 1352 | K25: 4 | L25: =IFERROR((J25/K25),"") -> 338 | M25: 2026/8/19周三 | N25: 46251 | O25: 预计8/19 | P25: G1526RR02 | Q25: 客唛7/27确认 | R25: 7/31 ok | T25: 有价钱贴纸 | X25: 使用PO#10129047的物料 | Y25: 2.199 | Z25: =J25*Y25 -> 2973.05 | AA25: =Z25*7.75 -> 23041.14 | AE25: =IFERROR(VLOOKUP(H25,名称!A:D,4,0),"") -> KIK | AH25: 46221 | AI25: 无 | AK25: 无 | AL25: 无 | AO25: =M25-A25 -> #VALUE! | AP25: =M25-AH25 -> #VALUE!
A26: 46205 | B26: =IF(TODAY()>=A26,IF(R26="","未",""),"") | C26: 美国 | D26: MARSHALLS OF MA, INC | E26: Olivia | F26: 10131174 | G26: 07 527336 | H26: E73622A | I26: =IFERROR(VLOOKUP(H26,名称!A:C,2,0),"") -> 布鲁伊家族杯子套装 | J26: 1120 | K26: 4 | L26: =IFERROR((J26/K26),"") -> 280 | M26: 2026/8/19周三 | N26: 46251 | O26: 预计8/19 | P26: G1526RR02 | Q26: 客唛7/27确认 | R26: 7/31 ok | T26: 有价钱贴纸 | X26: 使用PO#10129047的物料 | Y26: 2.199 | Z26: =J26*Y26 -> 2462.88 | AA26: =Z26*7.75 -> 19087.32 | AE26: =IFERROR(VLOOKUP(H26,名称!A:D,4,0),"") -> KIK | AH26: 46221 | AI26: 无 | AK26: 无 | AL26: 无 | AO26: =M26-A26 -> #VALUE! | AP26: =M26-AH26 -> #VALUE!
A27: 46205 | B27: =IF(TODAY()>=A27,IF(R27="","未",""),"") | C27: 美国 | D27: MARSHALLS OF MA, INC | E27: Olivia | F27: 10131175 | G27: 08 527336 | H27: E73622A | I27: =IFERROR(VLOOKUP(H27,名称!A:C,2,0),"") -> 布鲁伊家族杯子套装 | J27: 484 | K27: 4 | L27: =IFERROR((J27/K27),"") -> 121 | M27: 2026/8/19周三 | N27: 46251 | O27: 预计8/19 | P27: G1526RR02 | Q27: 客唛7/27确认 | R27: 7/31 ok | T27: 有价钱贴纸 | X27: 使用PO#10129047的物料 | Y27: 2.199 | Z27: =J27*Y27 -> 1064.32 | AA27: =Z27*7.75 -> 8248.48 | AE27: =IFERROR(VLOOKUP(H27,名称!A:D,4,0),"") -> KIK | AH27: 46221 | AI27: 无 | AK27: 无 | AL27: 无 | AO27: =M27-A27 -> #VALUE! | AP27: =M27-AH27 -> #VALUE!
A28: 46179 | B28: =IF(TODAY()>=A28,IF(R28="","未",""),"") | C28: 美国 | D28: TOMY INTERNATIONAL INC. | E28: Olivia | F28: 10129074 | G28: PO-000001299 | H28: Y2341C | I28: =IFERROR(VLOOKUP(H28,名称!A:C,2,0),"") -> 杯子 | J28: 10008 | K28: 3 | L28: =IFERROR((J28/K28),"") -> 3336 | M28: 46260 | N28: =M28-2 -> 46258 | P28: G1526RR02 | Q28: 标准唛+TTT | R28: 6/25 ok | Y28: 0.963 | Z28: =J28*Y28 -> 9637.7 | AA28: =Z28*7.75 -> 74692.18 | AE28: =IFERROR(VLOOKUP(H28,名称!A:D,4,0),"") -> KIK | AH28: 46184 | AI28: 无 | AJ28: 46220 | AK28: 无 | AL28: 无 | AO28: =M28-A28 -> 81 | AP28: =M28-AH28 -> 76
A29: 46179 | B29: =IF(TODAY()>=A29,IF(R29="","未",""),"") | C29: 美国 | D29: TOMY INTERNATIONAL INC. | E29: Olivia | F29: 10129047 | G29: PO-000001294 | H29: E73705A | I29: =IFERROR(VLOOKUP(H29,名称!A:C,2,0),"") -> 布鲁伊混装 | J29: 5000 | K29: 4 | L29: =IFERROR((J29/K29),"") -> 1250 | M29: 46260 | N29: =M29-2 -> 46258 | P29: G1526RR02 | Q29: 标准唛+TTT | R29: 7/30 ok | Y29: 2.204 | Z29: =J29*Y29 -> 11020 | AA29: =Z29*7.75 -> 85405 | AH29: 46197 | AL29: 46197 | AO29: =M29-A29 -> 81 | AP29: =M29-AH29 -> 63
A30: 46205 | B30: =IF(TODAY()>=A30,IF(R30="","未",""),"") | C30: 美国 | D30: NEWTON BUYING CORP. (T.J.MAXX) | E30: Olivia | F30: 10131164 | G30: 60 527344 | H30: E73622A | I30: =IFERROR(VLOOKUP(H30,名称!A:C,2,0),"") -> 布鲁伊家族杯子套装 | J30: 648 | K30: 4 | L30: =IFERROR((J30/K30),"") -> 162 | M30: 46260 | N30: =M30-2 -> 46258 | O30: 预计8/26 | P30: G1526RR02 | Q30: 客唛7/27确认 | R30: 7/31 ok | T30: 有价钱贴纸 | Y30: 2.199 | Z30: =J30*Y30 -> 1424.95 | AA30: =Z30*7.75 -> 11043.36 | AE30: =IFERROR(VLOOKUP(H30,名称!A:D,4,0),"") -> KIK | AH30: 46221 | AI30: 无 | AK30: 无 | AL30: 无 | AO30: =M30-A30 -> 55 | AP30: =M30-AH30 -> 39
A31: 46205 | B31: =IF(TODAY()>=A31,IF(R31="","未",""),"") | C31: 美国 | D31: NEWTON BUYING CORP. (T.J.MAXX) | E31: Olivia | F31: 10131166 | G31: 70 527344 | H31: E73622A | I31: =IFERROR(VLOOKUP(H31,名称!A:C,2,0),"") -> 布鲁伊家族杯子套装 | J31: 2288 | K31: 4 | L31: =IFERROR((J31/K31),"") -> 572 | M31: 46260 | N31: =M31-2 -> 46258 | O31: 预计8/26 | P31: G1526RR02 | Q31: 客唛7/27确认 | R31: 7/31 ok | T31: 有价钱贴纸 | Y31: 2.199 | Z31: =J31*Y31 -> 5031.31 | AA31: =Z31*7.75 -> 38992.65 | AE31: =IFERROR(VLOOKUP(H31,名称!A:D,4,0),"") -> KIK | AH31: 46221 | AI31: 无 | AK31: 无 | AL31: 无 | AO31: =M31-A31 -> 55 | AP31: =M31-AH31 -> 39
A32: 46205 | B32: =IF(TODAY()>=A32,IF(R32="","未",""),"") | C32: 美国 | D32: NEWTON BUYING CORP. (T.J.MAXX) | E32: Olivia | F32: 10131161 | G32: 10 527344 | H32: E73622A | I32: =IFERROR(VLOOKUP(H32,名称!A:C,2,0),"") -> 布鲁伊家族杯子套装 | J32: 1232 | K32: 4 | L32: =IFERROR((J32/K32),"") -> 308 | M32: 46260 | N32: =M32-2 -> 46258 | O32: 预计8/26 | P32: G1526RR02 | Q32: 客唛7/27确认 | R32: 7/31 ok | T32: 有价钱贴纸 | Y32: 2.199 | Z32: =J32*Y32 -> 2709.17 | AA32: =Z32*7.75 -> 20996.07 | AE32: =IFERROR(VLOOKUP(H32,名称!A:D,4,0),"") -> KIK | AH32: 46221 | AI32: 无 | AK32: 无 | AL32: 无 | AO32: =M32-A32 -> 55 | AP32: =M32-AH32 -> 39
A33: 46205 | B33: =IF(TODAY()>=A33,IF(R33="","未",""),"") | C33: 美国 | D33: NEWTON BUYING CORP. (T.J.MAXX) | E33: Olivia | F33: 10131163 | G33: 40 527344 | H33: E73622A | I33: =IFERROR(VLOOKUP(H33,名称!A:C,2,0),"") -> 布鲁伊家族杯子套装 | J33: 784 | K33: 4 | L33: =IFERROR((J33/K33),"") -> 196 | M33: 46260 | N33: =M33-2 -> 46258 | O33: 预计8/26 | P33: G1526RR02 | Q33: 客唛7/27确认 | R33: 7/31 ok | T33: 有价钱贴纸 | Y33: 2.199 | Z33: =J33*Y33 -> 1724.02 | AA33: =Z33*7.75 -> 13361.16 | AE33: =IFERROR(VLOOKUP(H33,名称!A:D,4,0),"") -> KIK | AH33: 46221 | AI33: 无 | AK33: 无 | AL33: 无 | AO33: =M33-A33 -> 55 | AP33: =M33-AH33 -> 39
A34: 46176 | B34: =IF(TODAY()>=A34,IF(R34="","未",""),"") | C34: 日本 | D34: TOMY COMPANY, LTD. | E34: Angel | F34: 10128185 | G34: 2.0260522e+19 | H34: 995135(E73857) | I34: =IFERROR(VLOOKUP(H34,名称!A:C,2,0),"") -> 管道马里奥 | J34: 1500 | K34: 4 | L34: =IFERROR((J34/K34),"") -> 375 | M34: 46265 | N34: =M34-2 -> 46263 | P34: G1526 | Q34: 客唛 | R34: 7/31 寄出 | X34: 印尼的旧彩盒可以使用，但是一箱里面不能出现两种彩盒 | Y34: 3.703 | Z34: =J34*Y34 -> 5554.5 | AA34: =Z34*7.75 -> 43047.38 | AE34: =IFERROR(VLOOKUP(H34,名称!A:D,4,0),"") -> KIK | AH34: 46212 | AI34: 无 | AJ34: 纸箱7/17 | AK34: 无 | AL34: 无 | AN34: 46219 | AO34: =M34-A34 -> 89 | AP34: =M34-AH34 -> 53
A35: 46176 | B35: =IF(TODAY()>=A35,IF(R35="","未",""),"") | C35: 日本 | D35: TOMY COMPANY, LTD. | E35: Angel | F35: 10128185 | G35: 2.0260522e+19 | H35: 995135(E73857) | I35: =IFERROR(VLOOKUP(H35,名称!A:C,2,0),"") -> 管道马里奥 | J35: 4500 | K35: 4 | L35: =IFERROR((J35/K35),"") -> 1125 | M35: 46265 | N35: =M35-2 -> 46263 | P35: G1526 | Q35: 客唛 | R35: 7/31 寄出 | X35: 印尼的旧彩盒可以使用，但是一箱里面不能出现两种彩盒 | Y35: 3.703 | Z35: =J35*Y35 -> 16663.5 | AA35: =Z35*7.75 -> 129142.13 | AE35: =IFERROR(VLOOKUP(H35,名称!A:D,4,0),"") -> KIK | AH35: 46212 | AI35: 无 | AJ35: 纸箱7/17 | AK35: 无 | AL35: 无 | AN35: 46219 | AO35: =M35-A35 -> 89 | AP35: =M35-AH35 -> 53
A36: 46136 | B36: =IF(TODAY()>=A36,IF(R36="","未",""),"") | C36: 澳大利亚 | D36: TOMY AUSTRALIA PTY, LTD. | E36: Toby | F36: 10125937 | G36: 20219073 | H36: E73857 | I36: =IFERROR(VLOOKUP(H36,名称!A:C,2,0),"") -> 管道马里奥 | J36: 3000 | K36: =IFERROR(VLOOKUP(H36,名称!A:D,3,0),"") -> 4 | L36: =IFERROR((J36/K36),"") -> 750 | M36: 46267 | N36: =M36-2 -> 46265 | P36: H1426RR02 | Q36: 标准唛+TTT | R36: 6/9 ok | Y36: 3.43 | Z36: =J36*Y36 -> 10290 | AA36: =Z36*7.75 -> 79747.5 | AE36: =IFERROR(VLOOKUP(H36,名称!A:D,4,0),"") -> KIK | AH36: 46163 | AI36: 无 | AK36: 无 | AL36: 无 | AN36: 46163 | AO36: =M36-A36 -> 131 | AP36: =M36-AH36 -> 104
A37: 46136 | B37: =IF(TODAY()>=A37,IF(R37="","未",""),"") | C37: 澳大利亚 | D37: TOMY AUSTRALIA PTY, LTD. | E37: Toby | F37: 10125937 | G37: 20219073 | H37: E73856 | I37: =IFERROR(VLOOKUP(H37,名称!A:C,2,0),"") -> 宝箱马里奥 | J37: 1500 | K37: =IFERROR(VLOOKUP(H37,名称!A:D,3,0),"") -> 4 | L37: =IFERROR((J37/K37),"") -> 375 | M37: 46267 | N37: =M37-2 -> 46265 | P37: H1426RR02 | Q37: 标准唛+TTT | R37: 6/9 ok | Y37: 2.25 | Z37: =J37*Y37 -> 3375 | AA37: =Z37*7.75 -> 26156.25 | AE37: =IFERROR(VLOOKUP(H37,名称!A:D,4,0),"") -> KIK | AH37: 消耗取消单 10115934 | AK37: 无 | AL37: 无 | AN37: 待定/客人预计取消 | AO37: =M37-A37 -> 131 | AP37: =M37-AH37 -> #VALUE!
A38: 46136 | B38: =IF(TODAY()>=A38,IF(R38="","未",""),"") | C38: 澳大利亚 | D38: TOMY AUSTRALIA PTY, LTD. | E38: Toby | F38: 10125937 | G38: 20219073 | H38: E73855A2 | I38: =IFERROR(VLOOKUP(H38,名称!A:C,2,0),"") -> 马里奥能量蘑菇吸塑混装 | J38: 3000 | K38: =IFERROR(VLOOKUP(H38,名称!A:D,3,0),"") -> 6 | L38: =IFERROR((J38/K38),"") -> 500 | M38: 46267 | N38: =M38-2 -> 46265 | P38: H1426RR02 | Q38: 标准唛+TTT | R38: 7/2 ok | X38: 从po10123689/10123756各转入1500PCS | Y38: 1.405 | Z38: =J38*Y38 -> 4215 | AA38: =Z38*7.75 -> 32666.25 | AE38: =IFERROR(VLOOKUP(H38,名称!A:D,4,0),"") -> KIK | AH38: 46134 | AK38: 无 | AL38: 无 | AO38: =M38-A38 -> 131 | AP38: =M38-AH38 -> 133
A39: 46170 | B39: =IF(TODAY()>=A39,IF(R39="","未",""),"") | C39: 美国 | D39: TOMY INTERNATIONAL INC. | E39: Olivia | F39: 10128336 | G39: PO-000001105 | H39: E73856AZ | I39: =IFERROR(VLOOKUP(H39,名称!A:C,2,0),"") -> 宝箱马里奥 | J39: 5000 | K39: 4 | L39: =IFERROR((J39/K39),"") -> 1250 | M39: 46267 | N39: =M39-2 -> 46265 | P39: G1526RR02 | Q39: 标准唛+TTT | R39: 7/7 ok | Y39: 2.15 | Z39: =J39*Y39 -> 10750 | AA39: =Z39*7.75 -> 83312.5 | AE39: =IFERROR(VLOOKUP(H39,名称!A:D,4,0),"") -> KIK | AH39: 46189 | AK39: 无 | AL39: 无 | AO39: =M39-A39 -> 97 | AP39: =M39-AH39 -> 78
A40: 46170 | B40: =IF(TODAY()>=A40,IF(R40="","未",""),"") | C40: 美国 | D40: TOMY INTERNATIONAL INC. | E40: Olivia | F40: 10128336 | G40: PO-000001105 | H40: E73858 | I40: =IFERROR(VLOOKUP(H40,名称!A:C,2,0),"") -> 浮水马里奥 | J40: 5001 | K40: 3 | L40: =IFERROR((J40/K40),"") -> 1667 | M40: 46267 | N40: =M40-2 -> 46265 | P40: H1426RR02 | Q40: 标准唛+TTT | R40: 8/3 寄出 | Y40: 3.182 | Z40: =J40*Y40 -> 15913.18 | AA40: =Z40*7.75 -> 123327.15 | AE40: =IFERROR(VLOOKUP(H40,名称!A:D,4,0),"") -> KIK | AH40: 46197 | AI40: 46197 | AK40: 无 | AL40: 预计6/18 | AO40: =M40-A40 -> 97 | AP40: =M40-AH40 -> 70
...

Sheet RRM总排期
A1: 接单期 | B1: 提交化学测试 | C1: 国家 | D1: 第三客户名称 | E1: 客跟单 | F1: TOMY PO | G1: CUSTOMER PO | H1: 货号 | I1: 产品名称 | J1: 数量 | K1: 外箱 | L1: 总箱数 | M1: PO走货期 | N1: 验货期 | O1: 实际验货期 | P1: 日期码 | Q1: 箱唛资料 | R1: Spot check | S1: 年报测试 | T1: 客贴纸 | U1: 印尼回复上拉时间 | V1: 印尼回复完成时间 | W1: 箱唛状态 | X1: 备注 | Y1: 单价USD | Z1: 金额USD | AA1: 金额HKD | AB1: 发票号 | AC1: 船期 | AD1: 是否入系统 | AE1: 车间 | AF1: 混装比例 | AG1: 确认采购日期 | AH1: 包材上料时间 | AI1: 塑胶件上料时间 | AJ1: 纸吉 | AK1: 五金上料时间 | AL1: 贴纸 | AM1: 仓库复来料时间 | AN1: 接单周期 | AO1: 印尼周期
A2: 46001 | B2: =IF(TODAY()>=A2,IF(R2="","未",""),"") | C2: 澳大利亚 | D2: TOMY AUSTRALIA PTY, LTD. | E2: Doreen | F2: 10116691 | G2: 20218751 | H2: 47274J | I2: =IFERROR(VLOOKUP(H2,名称!A:C,2,0),"") -> 1#农场朋友混合 | J2: 5000 | K2: =IFERROR(VLOOKUP(H2,名称!A:D,3,0),"") -> 4 | L2: =IFERROR((J2/K2),"") -> 1250 | M2: 46232 | N2: =M2-2 -> 46230 | O2: 46232 | P2: F1526RR03 | Q2: 标准唛+TTT | R2: 7/28 ok | S2: OK | T2: 有JD贴纸 | Y2: 1.746 | Z2: =J2*Y2 -> 8730 | AA2: =Z2*7.75 -> 67657.5 | AE2: =IFERROR(VLOOKUP(H2,名称!A:D,4,0),"") -> RRM | AH2: 2026/6/24 OPP带 7/1空运 | AI2: 无 | AK2: 46197 | AL2: 7/1空运 | AN2: =M2-A2 -> 231 | AO2: =M2-AH2 -> #VALUE!
A3: 46123 | B3: =IF(TODAY()>=A3,IF(R3="","未",""),"") | C3: 澳大利亚 | D3: TOMY AUSTRALIA PTY, LTD. | E3: Toby | F3: 10125011 | G3: 20219058 | H3: 47274J | I3: =IFERROR(VLOOKUP(H3,名称!A:C,2,0),"") -> 1#农场朋友混合 | J3: 3000 | K3: =IFERROR(VLOOKUP(H3,名称!A:D,3,0),"") -> 4 | L3: =IFERROR((J3/K3),"") -> 750 | M3: 46232 | N3: =M3-2 -> 46230 | O3: 46232 | P3: F1526RR03 | Q3: 标准唛+TTT | R3: 7/28 ok | S3: OK | T3: 有JD贴纸 | Y3: 1.746 | Z3: =J3*Y3 -> 5238 | AA3: =Z3*7.75 -> 40594.5 | AE3: =IFERROR(VLOOKUP(H3,名称!A:D,4,0),"") -> RRM | AH3: 2026/6/24 OPP带 7/1空运 | AI3: 无 | AK3: 46197 | AL3: 7/1空运 | AN3: =M3-A3 -> 109 | AO3: =M3-AH3 -> #VALUE!
A4: 46030 | B4: =IF(TODAY()>=A4,IF(R4="","未",""),"") | C4: 澳大利亚 | D4: TOMY AUSTRALIA PTY, LTD. | E4: Doreen | F4: 10118546 | G4: 20218828 | H4: 35766C | I4: =IFERROR(VLOOKUP(H4,名称!A:C,2,0),"") -> JD15 英寸大铲斗自卸卡车 | J4: 5000 | K4: =IFERROR(VLOOKUP(H4,名称!A:D,3,0),"") -> 2 | L4: =IFERROR((J4/K4),"") -> 2500 | M4: 46246 | N4: =M4-2 -> 46244 | O4: 46246 | P4: G1526RR03 | Q4: 标准唛+TTT | R4: 7/30 ok | S4: OK | T4: 有JD贴纸 | Y4: 4.131 | Z4: =J4*Y4 -> 20655 | AA4: =Z4*7.75 -> 160076.25 | AE4: =IFERROR(VLOOKUP(H4,名称!A:D,4,0),"") -> RRM | AH4: 彩盒6/25 OK | AI4: 无 | AK4: 46206 | AL4: 46206 | AN4: =M4-A4 -> 216 | AO4: =M4-AH4 -> #VALUE!
A5: 46030 | B5: =IF(TODAY()>=A5,IF(R5="","未",""),"") | C5: 澳大利亚 | D5: TOMY AUSTRALIA PTY, LTD. | E5: Doreen | F5: 10118546 | G5: 20218828 | H5: 35765D | I5: =IFERROR(VLOOKUP(H5,名称!A:C,2,0),"") -> JD 大铲斗挖掘机 | J5: 5000 | K5: =IFERROR(VLOOKUP(H5,名称!A:D,3,0),"") -> 2 | L5: =IFERROR((J5/K5),"") -> 2500 | M5: 46253 | N5: =M5-2 -> 46251 | O5: 预计8/19 | P5: G1526RR03 | Q5: 标准唛+TTT | R5: 7/30 ok | T5: 有JD贴纸 | Y5: 4.081 | Z5: =J5*Y5 -> 20405 | AA5: =Z5*7.75 -> 158138.75 | AE5: =IFERROR(VLOOKUP(H5,名称!A:D,4,0),"") -> RRM | AH5: 彩盒6/25 OK | AI5: 无 | AK5: 46206 | AL5: 46206 | AN5: =M5-A5 -> 223 | AO5: =M5-AH5 -> #VALUE!
A6: 46129 | B6: =IF(TODAY()>=A6,IF(R6="","未",""),"") | C6: 美国 | D6: TOMY INTERNATIONAL INC. | E6: Nancy | F6: 10125372 | G6: PO-000000072 | H6: 35874VAZJ | I6: =IFERROR(VLOOKUP(H6,名称!A:C,2,0),"") -> 沙河交通工具两件套 | J6: 5004 | K6: =IFERROR(VLOOKUP(H6,名称!A:D,3,0),"") -> 12 | L6: 1250 | M6: 46260 | N6: =M6-2 -> 46258 | P6: G1526RR03 | Q6: 标准唛+TTT | R6: 7/30 ok | S6: OK | T6: 有JD贴纸 | Y6: 2.215 | Z6: =J6*Y6 -> 11083.86 | AA6: =Z6*7.75 -> 85899.92 | AE6: =IFERROR(VLOOKUP(H6,名称!A:D,4,0),"") -> RRM | AH6: 密盒6/25 OK | AI6: 无 | AK6: 46206 | AL6: 46206 | AN6: =M6-A6 -> 131 | AO6: =M6-AH6 -> #VALUE!
A7: 46108 | B7: =IF(TODAY()>=A7,IF(R7="","未",""),"") | C7: 美国 | D7: TOMY INTERNATIONAL INC. | E7: Toby | F7: 10123487 | G7: 202608270087 | H7: 47616A | I7: =IFERROR(VLOOKUP(H7,名称!A:C,2,0),"") -> 沙盒建造三件套 | J7: 5000 | K7: =IFERROR(VLOOKUP(H7,名称!A:D,3,0),"") -> 4 | L7: =IFERROR((J7/K7),"") -> 1250 | M7: 46267 | N7: =M7-2 -> 46265 | P7: G1526RR03 | Q7: 标准唛+TTT | R7: 8.14寄出 | S7: 年报测试 | T7: 有JD贴纸 | Y7: 2.542 | Z7: =J7*Y7 -> 12710 | AA7: =Z7*7.75 -> 98502.5 | AE7: =IFERROR(VLOOKUP(H7,名称!A:D,4,0),"") -> RRM | AH7: 吊牌退货 7/18已装柜 | AK7: 46214 | AL7: 46214 | AN7: =M7-A7 -> 159 | AO7: =M7-AH7 -> #VALUE!
A8: 46108 | B8: =IF(TODAY()>=A8,IF(R8="","未",""),"") | C8: 澳大利亚 | D8: TOMY AUSTRALIA PTY, LTD. | E8: Toby | F8: 10123464 | G8: 20219008 | H8: 47616A | I8: =IFERROR(VLOOKUP(H8,名称!A:C,2,0),"") -> 沙盒建造三件套 | J8: 720 | K8: =IFERROR(VLOOKUP(H8,名称!A:D,3,0),"") -> 4 | L8: =IFERROR((J8/K8),"") -> 180 | M8: 46267 | N8: =M8-2 -> 46265 | P8: G1526RR03 | Q8: 标准唛+TTT | R8: 8.14寄出 | T8: 有JD贴纸 | Y8: 2.542 | Z8: =J8*Y8 -> 1830.24 | AA8: =Z8*7.75 -> 14184.36 | AE8: =IFERROR(VLOOKUP(H8,名称!A:D,4,0),"") -> RRM | AH8: 吊牌退货 7/18已装柜 | AK8: 46214 | AL8: 46214 | AN8: =M8-A8 -> 159 | AO8: =M8-AH8 -> #VALUE!
A9: 46123 | B9: =IF(TODAY()>=A9,IF(R9="","未",""),"") | C9: 澳大利亚 | D9: TOMY AUSTRALIA PTY, LTD. | E9: Toby | F9: 10125013 | G9: 20219061 | H9: 35765D | I9: =IFERROR(VLOOKUP(H9,名称!A:C,2,0),"") -> JD 大铲斗挖掘机 | J9: 2000 | K9: =IFERROR(VLOOKUP(H9,名称!A:D,3,0),"") -> 2 | L9: =IFERROR((J9/K9),"") -> 1000 | M9: 46267 | N9: =M9-2 -> 46265 | P9: G1526RR03 | Q9: 标准唛+TTT | R9: 7/30 ok | T9: 有JD贴纸 | Y9: 4.081 | Z9: =J9*Y9 -> 8162 | AA9: =Z9*7.75 -> 63255.5 | AE9: =IFERROR(VLOOKUP(H9,名称!A:D,4,0),"") -> RRM | AH9: 彩盒6/25 OK | AI9: 无 | AK9: 46206 | AL9: 46206 | AN9: =M9-A9 -> 144 | AO9: =M9-AH9 -> #VALUE!
A10: 46129 | B10: =IF(TODAY()>=A10,IF(R10="","未",""),"") | C10: 澳大利亚 | D10: TOMY AUSTRALIA PTY, LTD. | E10: Toby | F10: 10125013 | G10: 20219061 | H10: 35766C | I10: =IFERROR(VLOOKUP(H10,名称!A:C,2,0),"") -> JD15 英寸大铲斗自卸卡车 | J10: 3000 | K10: =IFERROR(VLOOKUP(H10,名称!A:D,3,0),"") -> 2 | L10: =IFERROR((J10/K10),"") -> 1500 | M10: 46267 | N10: =M10-2 -> 46265 | P10: G1526RR03 | Q10: 标准唛+TTT | R10: 7/30 ok | S10: OK | T10: 有JD贴纸 | Y10: 4.131 | Z10: =J10*Y10 -> 12393 | AA10: =Z10*7.75 -> 96045.75 | AE10: =IFERROR(VLOOKUP(H10,名称!A:D,4,0),"") -> RRM | AH10: 彩盒6/25 OK | AI10: 无 | AK10: 46206 | AL10: 46206 | AN10: =M10-A10 -> 138 | AO10: =M10-AH10 -> #VALUE!
A11: 46105 | B11: =IF(TODAY()>=A11,IF(R11="","未",""),"") | C11: 美国 | D11: TOMY INTERNATIONAL INC. | E11: Toby | F11: 10123136 | G11: 202607270116 | H11: 47023A1 | I11: =IFERROR(VLOOKUP(H11,名称!A:C,2,0),"") -> 工程玩具挖掘机 | J11: 5000 | K11: =IFERROR(VLOOKUP(H11,名称!A:D,3,0),"") -> 2 | L11: =IFERROR((J11/K11),"") -> 2500 | M11: 46274 | N11: =M11-2 -> 46272 | P11: G1526RR03 | Q11: 标准唛+TTT | R11: 8.19寄出 | S11: 7/21 OK | T11: 有JD贴纸 | Y11: 4.419 | Z11: =J11*Y11 -> 22095 | AA11: =Z11*7.75 -> 171236.25 | AE11: =IFERROR(VLOOKUP(H11,名称!A:D,4,0),"") -> RRM | AH11: 彩盒6/25 OK | AK11: 46214 | AL11: 46219 | AN11: =M11-A11 -> 169 | AO11: =M11-AH11 -> #VALUE!
A12: 46106 | B12: =IF(TODAY()>=A12,IF(R12="","未",""),"") | C12: 澳大利亚 | D12: TOMY AUSTRALIA PTY, LTD. | E12: Toby | F12: 10123190 | G12: 20218996 | H12: 47023A1 | I12: =IFERROR(VLOOKUP(H12,名称!A:C,2,0),"") -> 工程玩具挖掘机 | J12: 600 | K12: =IFERROR(VLOOKUP(H12,名称!A:D,3,0),"") -> 2 | L12: =IFERROR((J12/K12),"") -> 300 | M12: 46274 | N12: =M12-2 -> 46272 | P12: G1526RR03 | Q12: 标准唛+TTT | R12: 8.19寄出 | S12: 7/21 OK | T12: 有JD贴纸 | Y12: 4.419 | Z12: =J12*Y12 -> 2651.4 | AA12: =Z12*7.75 -> 20548.35 | AE12: =IFERROR(VLOOKUP(H12,名称!A:D,4,0),"") -> RRM | AH12: 彩盒6/25 OK | AK12: 46214 | AL12: 46219 | AN12: =M12-A12 -> 168 | AO12: =M12-AH12 -> #VALUE!
A13: 46129 | B13: =IF(TODAY()>=A13,IF(R13="","未",""),"") | C13: 美国 | D13: TOMY INTERNATIONAL INC. | E13: Nancy | F13: 10125389 | G13: PO-000000080 | H13: 47023AZ2 | I13: =IFERROR(VLOOKUP(H13,名称!A:C,2,0),"") -> 工程玩具挖掘机 | J13: 5000 | K13: =IFERROR(VLOOKUP(H13,名称!A:D,3,0),"") -> 2 | L13: 2500 | M13: 46274 | N13: =M13-2 -> 46272 | P13: G1526RR03 | Q13: 标准唛+TTT | R13: 8.19寄出 | T13: 有JD贴纸 | Y13: 4.419 | Z13: =J13*Y13 -> 22095 | AA13: =Z13*7.75 -> 171236.25 | AE13: =IFERROR(VLOOKUP(H13,名称!A:D,4,0),"") -> RRM | AH13: 46233 | AK13: 46233 | AL13: 46233 | AN13: =M13-A13 -> 145 | AO13: =M13-AH13 -> 41
A14: 46129 | B14: =IF(TODAY()>=A14,IF(R14="","未",""),"") | C14: 美国 | D14: TOMY INTERNATIONAL INC. | E14: Nancy | F14: 10125372 | G14: PO-000000072 | H14: 35874VAZJ | I14: =IFERROR(VLOOKUP(H14,名称!A:C,2,0),"") -> 沙河交通工具两件套 | J14: 5004 | K14: =IFERROR(VLOOKUP(H14,名称!A:D,3,0),"") -> 12 | L14: 1250 | M14: 46274 | N14: =M14-2 -> 46272 | P14: G1526RR03 | Q14: 标准唛+TTT | R14: 7/30 ok | S14: OK | T14: 有JD贴纸 | Y14: 2.215 | Z14: =J14*Y14 -> 11083.86 | AA14: =Z14*7.75 -> 85899.92 | AE14: =IFERROR(VLOOKUP(H14,名称!A:D,4,0),"") -> RRM | AH14: 密盒6/25 OK | AI14: 无 | AK14: 46206 | AL14: 46206 | AN14: =M14-A14 -> 145 | AO14: =M14-AH14 -> #VALUE!
A15: 46129 | B15: =IF(TODAY()>=A15,IF(R15="","未",""),"") | C15: 美国 | D15: TOMY INTERNATIONAL INC. | E15: Nancy | F15: 10125372 | G15: PO-000000072 | H15: 35874VAZJ | I15: =IFERROR(VLOOKUP(H15,名称!A:C,2,0),"") -> 沙河交通工具两件套 | J15: 4992 | K15: =IFERROR(VLOOKUP(H15,名称!A:D,3,0),"") -> 12 | L15: 1250 | M15: 46274 | N15: =M15-2 -> 46272 | P15: G1526RR03 | Q15: 标准唛+TTT | R15: 7/30 ok | S15: OK | T15: 有JD贴纸 | Y15: 2.215 | Z15: =J15*Y15 -> 11057.28 | AA15: =Z15*7.75 -> 85693.92 | AE15: =IFERROR(VLOOKUP(H15,名称!A:D,4,0),"") -> RRM | AH15: 密盒6/25 OK | AI15: 无 | AK15: 46206 | AL15: 46206 | AN15: =M15-A15 -> 145 | AO15: =M15-AH15 -> #VALUE!
A16: 46130 | B16: =IF(TODAY()>=A16,IF(R16="","未",""),"") -> 未 | C16: 美国 | D16: TOMY INTERNATIONAL INC. | E16: Toby | F16: 10125700 | G16: PO-000000101 | H16: 47193C | I16: =IFERROR(VLOOKUP(H16,名称!A:C,2,0),"") -> 农场朋友组合 | J16: 4400 | K16: =IFERROR(VLOOKUP(H16,名称!A:D,3,0),"") -> 4 | L16: 1250 | M16: 46281 | N16: =M16-2 -> 46279 | P16: G1526RR03 | Q16: 标准唛+TTT | T16: 有JD贴纸 | Y16: 2.881 | Z16: =J16*Y16 -> 12676.4 | AA16: =Z16*7.75 -> 98242.1 | AE16: =IFERROR(VLOOKUP(H16,名称!A:D,4,0),"") -> RRM | AH16: 46233 | AK16: 46233 | AL16: 46233 | AN16: =M16-A16 -> 151 | AO16: =M16-AH16 -> 48
A17: 46142 | B17: =IF(TODAY()>=A17,IF(R17="","未",""),"") -> 未 | C17: 澳大利亚 | D17: TOMY AUSTRALIA PTY, LTD. | E17: Toby | F17: 10125362 | G17: 20219091 | H17: 47193C | I17: =IFERROR(VLOOKUP(H17,名称!A:C,2,0),"") -> 农场朋友组合 | J17: 600 | K17: =IFERROR(VLOOKUP(H17,名称!A:D,3,0),"") -> 4 | L17: 1250 | M17: 46281 | N17: =M17-2 -> 46279 | P17: G1526RR03 | Q17: 标准唛+TTT | T17: 有JD贴纸 | Y17: 2.881 | Z17: =J17*Y17 -> 1728.6 | AA17: =Z17*7.75 -> 13396.65 | AB17: KIK | AE17: =IFERROR(VLOOKUP(H17,名称!A:D,4,0),"") -> RRM | AH17: 46233 | AK17: 46233 | AL17: 46233 | AN17: =M17-A17 -> 139 | AO17: =M17-AH17 -> 48
A18: 46179 | B18: =IF(TODAY()>=A18,IF(R18="","未",""),"") | C18: 澳大利亚 | D18: TOMY AUSTRALIA PTY, LTD. | E18: Toby | F18: 10129036 | G18: 20219196 | H18: 35765D | I18: =IFERROR(VLOOKUP(H18,名称!A:C,2,0),"") -> JD 大铲斗挖掘机 | J18: 4000 | K18: 2 | L18: =IFERROR((J18/K18),"") -> 2000 | M18: 46281 | N18: =M18-2 -> 46279 | P18: G1526RR03 | Q18: 标准唛+TTT | R18: 7/30 ok | T18: 有JD贴纸 | Y18: 4.081 | Z18: =J18*Y18 -> 16324 | AA18: =Z18*7.75 -> 126511 | AE18: =IFERROR(VLOOKUP(H18,名称!A:D,4,0),"") -> RRM | AH18: 彩盒6/25 OK | AI18: 无 | AK18: 46206 | AL18: 46206 | AN18: =M18-A18 -> 102 | AO18: =M18-AH18 -> #VALUE!
A19: 46179 | B19: =IF(TODAY()>=A19,IF(R19="","未",""),"") | C19: 澳大利亚 | D19: TOMY AUSTRALIA PTY, LTD. | E19: Toby | F19: 10129036 | G19: 20219196 | H19: 35766C | I19: =IFERROR(VLOOKUP(H19,名称!A:C,2,0),"") -> JD15 英寸大铲斗自卸卡车 | J19: 4000 | K19: 2 | L19: =IFERROR((J19/K19),"") -> 2000 | M19: 46281 | N19: =M19-2 -> 46279 | P19: G1526RR03 | Q19: 标准唛+TTT | R19: 7/30 ok | S19: OK | T19: 有JD贴纸 | Y19: 4.131 | Z19: =J19*Y19 -> 16524 | AA19: =Z19*7.75 -> 128061 | AE19: =IFERROR(VLOOKUP(H19,名称!A:D,4,0),"") -> RRM | AH19: 彩盒6/25 OK | AI19: 无 | AK19: 46206 | AL19: 46206 | AN19: =M19-A19 -> 102 | AO19: =M19-AH19 -> #VALUE!
A20: 46179 | B20: =IF(TODAY()>=A20,IF(R20="","未",""),"") | C20: 澳大利亚 | D20: TOMY AUSTRALIA PTY, LTD. | E20: Toby | F20: 10129036 | G20: 20219196 | H20: 47274J | I20: =IFERROR(VLOOKUP(H20,名称!A:C,2,0),"") -> 1#农场朋友混合 | J20: 3000 | K20: 4 | L20: =IFERROR((J20/K20),"") -> 750 | M20: 46281 | N20: =M20-2 -> 46279 | P20: G1526RR03 | Q20: 标准唛+TTT | R20: 7/28 ok | S20: OK | T20: 有JD贴纸 | Y20: 1.746 | Z20: =J20*Y20 -> 5238 | AA20: =Z20*7.75 -> 40594.5 | AE20: =IFERROR(VLOOKUP(H20,名称!A:D,4,0),"") -> RRM | AH20: 2026/6/24 OPP带 7/1空运 | AI20: 无 | AK20: 46197 | AL20: 7/1空运 | AN20: =M20-A20 -> 102 | AO20: =M20-AH20 -> #VALUE!
A21: 46185 | B21: =IF(TODAY()>=A21,IF(R21="","未",""),"") | C21: 比利时 | D21: TOMY UK CO LTD | E21: Nancy | F21: 10129303 | G21: 4500032948 | H21: 35765D | I21: =IFERROR(VLOOKUP(H21,名称!A:C,2,0),"") -> JD 大铲斗挖掘机 | J21: 1800 | K21: 2 | L21: =IFERROR((J21/K21),"") -> 900 | M21: 46281 | N21: =M21-2 -> 46279 | P21: G1526RR03 | Q21: 标准唛+TTT+欧盟信息 | R21: 7/30 ok | T21: 有JD贴纸 | Y21: 4.081 | Z21: =J21*Y21 -> 7345.8 | AA21: =Z21*7.75 -> 56929.95 | AE21: RRM | AH21: 彩盒6/25 OK | AI21: 无 | AK21: 46206 | AL21: 46206 | AN21: =M21-A21 -> 96 | AO21: =M21-AH21 -> #VALUE!
A22: 46129 | B22: =IF(TODAY()>=A22,IF(R22="","未",""),"") -> 未 | C22: 澳大利亚 | D22: TOMY AUSTRALIA PTY, LTD. | E22: Toby | F22: 10125362 | G22: 20219091 | H22: 35874A1J | I22: =IFERROR(VLOOKUP(H22,名称!A:C,2,0),"") -> 沙河交通工具两件套 | J22: 3000 | K22: 4 | L22: =IFERROR((J22/K22),"") -> 750 | M22: 46288 | N22: =M22-2 -> 46286 | P22: G1526RR03 | Q22: 标准唛+TTT | T22: 有JD贴纸 | Y22: 2.215 | Z22: =J22*Y22 -> 6645 | AA22: =Z22*7.75 -> 51498.75 | AE22: =IFERROR(VLOOKUP(H22,名称!A:D,4,0),"") -> RRM | AH22: 46242 | AI22: 无 | AK22: 46206 | AL22: 46206 | AN22: =M22-A22 -> 159 | AO22: =M22-AH22 -> 46
A23: 46179 | B23: =IF(TODAY()>=A23,IF(R23="","未",""),"") -> 未 | C23: 英国 | D23: TOMY UK CO., Ltd. | F23: 4500032587 | H23: F5861ML2 | I23: 管道吹风球 | J23: =7002-3000 -> 4002 | K23: 3 | L23: =IFERROR((J23/K23),"") -> 1334 | M23: 46293 | N23: =M23-2 -> 46291 | P23: H1426RR02 | Q23: 标准唛+TTT+欧盟信息 | T23: 待定 | X23: 欧洲版本充电器，有在Fat Brain扣MA | Y23: 25.96 | Z23: =J23*Y23 -> 103891.92 | AA23: =Z23*7.75 -> 805162.38 | AE23: =IFERROR(VLOOKUP(H23,名称!A:D,4,0),"") -> RRM | AN23: =M23-A23 -> 114 | AO23: =M23-#REF! -> #REF!
A24: 46199 | B24: =IF(TODAY()>=A24,IF(R24="","未",""),"") -> 未 | C24: 澳大利亚 | D24: Tomy Australia Pty Ltd | F24: 20219232 | H24: FA586-2AUT | I24: 管道吹风球 | J24: 4110 | K24: 3 | L24: =IFERROR((J24/K24),"") -> 1370 | M24: 46293 | N24: =M24-2 -> 46291 | Q24: 客唛 | T24: 有特殊贴纸，档案待提供，我司负责印刷。 说明书跟美文版不同 | X24: 澳洲版本充电器，有在Fat Brain扣MA | Y24: 25.96 | Z24: =J24*Y24 -> 106695.6 | AA24: =Z24*7.75 -> 826890.9 | AE24: RRM | AN24: =M24-A24 -> 94 | AO24: =M24-AH23 -> 46293
A25: 46172 | B25: =IF(TODAY()>=A25,IF(R25="","未",""),"") -> 未 | C25: 美国 | D25: TOMY INTERNATIONAL INC. | E25: Nancy | F25: 10128490 | G25: PO-000001107 | H25: 47020A1 | I25: 6 英寸工程车辆 两件套装 | J25: 5000 | K25: 4 | L25: =IFERROR((J25/K25),"") -> 1250 | M25: 46295 | N25: =M25-2 -> 46293 | P25: G1526RR03 | Q25: 标准唛+TTT | T25: 有JD贴纸 | Y25: 0 | Z25: =J25*Y25 -> 0 | AA25: =Z25*7.75 -> 0 | AE25: RRM | AH25: 46242 | AI25: 无 | AK25: 46242 | AL25: 46242 | AN25: =M25-A25 -> 123 | AO25: =M25-AH25 -> 53
A26: 46172 | B26: =IF(TODAY()>=A26,IF(R26="","未",""),"") -> 未 | C26: 澳大利亚 | D26: TOMY AUSTRALIA PTY, LTD. | E26: Toby | F26: 10128547 | G26: 20219183 | H26: 47020A1 | I26: 6 英寸工程车辆 两件套装 | J26: 1000 | K26: 4 | L26: =IFERROR((J26/K26),"") -> 250 | M26: 46302 | N26: =M26-2 -> 46300 | P26: I1526RR03 | Q26: 标准唛+TTT | T26: 有JD贴纸 | Y26: 0 | Z26: =J26*Y26 -> 0 | AA26: =Z26*7.75 -> 0 | AE26: RRM | AH26: 46242 | AI26: 无 | AK26: 46242 | AL26: 46242 | AN26: =M26-A26 -> 130 | AO26: =M26-AH26 -> 60
A27: 46179 | B27: =IF(TODAY()>=A27,IF(R27="","未",""),"") -> 未 | C27: 澳大利亚 | D27: TOMY AUSTRALIA PTY, LTD. | E27: Toby | F27: 10129036 | G27: 20219196 | H27: 46510A1 | I27: 大铲斗配沙池工具 | J27: 1000 | K27: 2 | L27: =IFERROR((J27/K27),"") -> 500 | M27: 46302 | N27: =M27-2 -> 46300 | P27: I1526RR03 | Q27: 标准唛+TTT | T27: 有JD贴纸 | Y27: 4.944 | Z27: =J27*Y27 -> 4944 | AA27: =Z27*7.75 -> 38316 | AE27: RRM | AH27: 8/12放订 | AN27: =M27-A27 -> 123 | AO27: =M27-AH27 -> #VALUE!
A28: 46182 | B28: =IF(TODAY()>=A28,IF(R28="","未",""),"") -> 未 | C28: 美国 | D28: TOMY INTERNATIONAL INC. | E28: Nancy | F28: 10129125 | G28: PO-000001300 | H28: 46701A1 | I28: 大铲斗配沙池工具 | J28: 5000 | K28: 2 | L28: =IFERROR((J28/K28),"") -> 2500 | M28: 46302 | N28: =M28-2 -> 46300 | P28: I1526RR03 | Q28: 标准唛+TTT | T28: 有JD贴纸 | Y28: 4.944 | Z28: =J28*Y28 -> 24720 | AA28: =Z28*7.75 -> 191580 | AE28: RRM | AH28: 8/12放订 | AN28: =M28-A28 -> 120 | AO28: =M28-AH28 -> #VALUE!
A29: 46182 | B29: =IF(TODAY()>=A29,IF(R29="","未",""),"") -> 未 | C29: 美国 | D29: TOMY INTERNATIONAL INC. | E29: Toby | F29: 10129130 | G29: PO-000001315 | H29: 46510A1 | I29: 大铲斗配沙池工具 | J29: 4000 | K29: 2 | L29: =IFERROR((J29/K29),"") -> 2000 | M29: 46302 | N29: =M29-2 -> 46300 | P29: I1526RR03 | Q29: 标准唛+TTT | T29: 有JD贴纸 | Y29: 4.944 | Z29: =J29*Y29 -> 19776 | AA29: =Z29*7.75 -> 153264 | AE29: RRM | AH29: 8/12放订 | AN29: =M29-A29 -> 120 | AO29: =M29-AH29 -> #VALUE!
A30: 46150 | B30: =IF(TODAY()>=A30,IF(R30="","未",""),"") -> 未 | F30: MA | H30: F5861ML2 | I30: 管道吹风球 | J30: =24992-300-4800-2130-4110-4002-3000 -> 6650 | K30: =IFERROR(VLOOKUP(H30,名称!A:D,3,0),"") -> 3 | L30: =IFERROR((J30/K30),"") -> 2216.6667 | M30: 46309 | N30: =M30-2 -> 46307 | X30: 适配器待定，有在Fat Brain扣MA | Z30: =J30*Y30 -> 0 | AA30: =Z30*7.75 -> 0 | AE30: =IFERROR(VLOOKUP(H30,名称!A:D,4,0),"") -> RRM | AN30: =M30-A30 -> 159 | AO30: =M30-AH30 -> 46309
A31: 46141 | B31: =IF(TODAY()>=A31,IF(R31="","未",""),"") -> 未 | C31: 波兰 | D31: TOMY UK CO., Ltd. | F31: 4500032736 | H31: F5861ML2 | I31: 管道吹风球 | J31: 2130 | K31: =IFERROR(VLOOKUP(H31,名称!A:D,3,0),"") -> 3 | L31: =IFERROR((J31/K31),"") -> 710 | M31: 46310 | N31: =M31-2 -> 46308 | P31: H1426RR02 | Q31: 标准唛+TTT+欧盟信息 | T31: 彩盒底部需贴标签 | X31: 欧洲版本充电器，有在Fat Brain扣MA | Y31: 25.96 | Z31: =J31*Y31 -> 55294.8 | AA31: =Z31*7.75 -> 428534.7 | AE31: =IFERROR(VLOOKUP(H31,名称!A:D,4,0),"") -> RRM | AN31: =M31-A31 -> 169 | AO31: =M31-AH31 -> 46310
A32: 46179 | B32: =IF(TODAY()>=A32,IF(R32="","未",""),"") -> 未 | C32: 澳大利亚 | D32: TOMY AUSTRALIA PTY, LTD. | E32: Toby | F32: 10129036 | G32: 20219196 | H32: 47207B | I32: 农场朋友运输套装 | J32: 600 | K32: 4 | L32: =IFERROR((J32/K32),"") -> 150 | M32: 46316 | N32: =M32-2 -> 46314 | P32: I1526RR03 | Q32: 标准唛+TTT | S32: 8/11 寄出 | T32: 有JD贴纸 | Y32: 5.774 | Z32: =J32*Y32 -> 3464.4 | AA32: =Z32*7.75 -> 26849.1 | AE32: RRM | AN32: =M32-A32 -> 137 | AO32: =M32-AH32 -> 46316
A33: 46182 | B33: =IF(TODAY()>=A33,IF(R33="","未",""),"") -> 未 | C33: 美国 | D33: TOMY INTERNATIONAL INC. | E33: Toby | F33: 10129130 | G33: PO-000001315 | H33: 47207B | I33: 农场朋友运输套装 | J33: 4400 | K33: 4 | L33: =IFERROR((J33/K33),"") -> 1100 | M33: 46316 | N33: =M33-2 -> 46314 | P33: I1526RR03 | Q33: 标准唛+TTT | S33: 8/11 寄出 | T33: 有JD贴纸 | Y33: 5.774 | Z33: =J33*Y33 -> 25405.6 | AA33: =Z33*7.75 -> 196893.4 | AE33: RRM | AN33: =M33-A33 -> 134 | AO33: =M33-AH33 -> 46316
A34: 46186 | B34: =IF(TODAY()>=A34,IF(R34="","未",""),"") -> 未 | C34: 比利时 | D34: TOMY UK CO LTD | E34: Nancy | F34: 10129356 | G34: 4500032955 | H34: 47207B | I34: 农场朋友运输套装 | J34: 2500 | K34: 4 | L34: =IFERROR((J34/K34),"") -> 625 | M34: 46323 | N34: =M34-2 -> 46321 | P34: I1526RR03 | Q34: 标准唛+TTT+欧盟信息 | T34: 有JD贴纸 | Y34: 5.774 | Z34: =J34*Y34 -> 14435 | AA34: =Z34*7.75 -> 111871.25 | AE34: RRM | AN34: =M34-A34 -> 137 | AO34: =M34-AH34 -> 46323
A35: 46186 | B35: =IF(TODAY()>=A35,IF(R35="","未",""),"") -> 未 | C35: 比利时 | D35: TOMY UK CO LTD | E35: Nancy | F35: 10129356 | G35: 4500032955 | H35: 47207B | I35: 农场朋友运输套装 | J35: 2500 | K35: 4 | L35: =IFERROR((J35/K35),"") -> 625 | M35: 46323 | N35: =M35-2 -> 46321 | P35: I1526RR03 | Q35: 标准唛+TTT+欧盟信息 | T35: 有JD贴纸 | Y35: 5.774 | Z35: =J35*Y35 -> 14435 | AA35: =Z35*7.75 -> 111871.25 | AE35: RRM | AN35: =M35-A35 -> 137 | AO35: =M35-AH35 -> 46323
A36: 46206 | B36: =IF(TODAY()>=A36,IF(R36="","未",""),"") -> 未 | C36: 中国 | D36: TOMY UK CO LTD | E36: Nancy | F36: 10131243 | G36: 4500033055 | H36: 47207B | I36: 农场朋友运输套装 | J36: 1000 | K36: 4 | L36: =IFERROR((J36/K36),"") -> 250 | M36: 46337 | N36: =M36-2 -> 46335 | P36: J1526RR03 | Q36: 标准唛+TTT+欧盟信息 | T36: 有JD贴纸 | Y36: 5.774 | Z36: =J36*Y36 -> 5774 | AA36: =Z36*7.75 -> 44748.5 | AE36: RRM
A37: 46179 | B37: =IF(TODAY()>=A37,IF(R37="","未",""),"") -> 未 | C37: 英国 | D37: TOMY UK CO., Ltd. | F37: 4500032587 | H37: F5861ML2 | I37: 管道吹风球 | J37: 3000 | K37: 3 | L37: =IFERROR((J37/K37),"") -> 1000 | M37: 46354 | N37: =M37-2 -> 46352 | P37: J1526RR03 | Q37: 标准唛+TTT+欧盟信息 | T37: 待定 | X37: 欧洲版本充电器，有在Fat Brain扣MA | Y37: 25.96 | Z37: =J37*Y37 -> 77880 | AA37: =Z37*7.75 -> 603570 | AE37: =IFERROR(VLOOKUP(H37,名称!A:D,4,0),"") -> RRM | AN37: =M37-A37 -> 175 | AO37: =M37-AH37 -> 46354
A38: 46114 | B38: =IF(TODAY()>=A38,IF(R38="","未",""),"") -> 未 | C38: 比利时 | D38: TOMY UK CO., Ltd. | F38: 4500032586 | H38: F5861ML2 | I38: 管道吹风球 | J38: 4800 | K38: =IFERROR(VLOOKUP(H38,名称!A:D,3,0),"") -> 3 | L38: =IFERROR((J38/K38),"") -> 1600 | M38: 46391 | N38: =M38-2 -> 46389 | P38: H1426RR03 | Q38: 标准唛+TTT+欧盟信息 | T38: 待定 | W38: 7/15放箱唛 | X38: 欧洲版本充电器，有在Fat Brain扣MA | Y38: 25.96 | Z38: =J38*Y38 -> 124608 | AA38: =Z38*7.75 -> 965712 | AE38: =IFERROR(VLOOKUP(H38,名称!A:D,4,0),"") -> RRM | AN38: =M38-A38 -> 277 | AO38: =M38-AH38 -> 46391
A39: 46221 | C39: 澳大利亚 | D39: TOMY AUSTRALIA PTY, LTD. | E39: Toby | F39: 10132947 | G39: 20219244 | H39: E74062C | I39: 弹出皮特寻宝器 | J39: 2000 | K39: 4 | L39: =IFERROR((J39/K39),"") -> 500 | M39: 46309 | N39: =M39-2 -> 46307 | P39: I1526RR03 | Q39: 标准唛+TTT | Y39: 2.26 | Z39: =J39*Y39 -> 4520 | AA39: =Z39*7.75 -> 35030 | AE39: RRM
A40: 46225 | C40: 比利时 | D40: TOMY UK CO LTD | E40: Gary | F40: 10133076 | G40: 4500033113 | H40: E74062C | I40: 弹出皮特寻宝器 | J40: 7200 | K40: 4 | L40: =IFERROR((J40/K40),"") -> 1800 | M40: 46316 | N40: =M40-2 -> 46314 | P40: I1526RR03 | Q40: 标准唛+TTT+欧盟信息 | Y40: 2.26 | Z40: =J40*Y40 -> 16272 | AA40: =Z40*7.75 -> 126108 | AE40: RRM
...

Sheet 测试明细
A1: 需做测试订单
A2: 序号 | B2: PO号 | C2: 货号 | D2: 货期 | E2: 产地 | F2: 需寄出时间 | G2: 备注
A3: 1 | B3: 10118393 | C3: E73622A | D3: 46092 | E3: 印尼 | F3: =D3-25 -> 46067 | G3: 4/1 测试OK
A4: 2 | B4: 10120677 | C4: 47674DG2 | D4: 2026/4/1 | E4: 印尼 | F4: =D4-25 -> 46088 | G4: 已走货
A5: 3 | B5: 10116164 | C5: 47600J | D5: 2026/4/1 | E5: 印尼 | F5: =D5-25 -> 46088 | G5: 4.9 pass
A6: 4 | B6: 10118279 | C6: 47669 | D6: 2026/4/1 | E6: 印尼 | F6: =D6-25 -> 46088 | G6: 4.9 pass
A7: 5 | B7: 10120342 | C7: E73705A | D7: 2026/4/11 | E7: 印尼 | F7: =D7-25 -> 46098 | G7: 4.8 pass
A8: 6 | B8: 10118943 | C8: 46696 | D8: 2026/4/22 | E8: 东莞 | F8: =D8-25 -> 46109 | G8: 4.9 pass
A9: 7 | B9: 10119984 | C9: 47714A | D9: 2026/5/6 | E9: 印尼 | F9: =D9-25 -> 46123 | G9: 5.27 pass
A10: 8 | B10: 10119985 | C10: 47722A | D10: 2026/5/6 | E10: 印尼 | F10: =D10-25 -> 46123 | G10: 5.28 pass
A11: 9 | B11: 10119986 | C11: 47723A | D11: 2026/5/6 | E11: 印尼 | F11: =D11-25 -> 46123 | G11: 5.28 pass
A12: 10 | B12: 10116494 | C12: 47712A | D12: 2026/5/13 | E12: 印尼 | F12: =D12-25 -> 46130 | G12: 使用之前的测试结果
A13: 11 | B13: 10116495 | C13: 47716A | D13: 2026/5/13 | E13: 印尼 | F13: =D13-25 -> 46130 | G13: 使用之前的测试结果
A14: 12 | B14: 10121464 | C14: Y2341C | D14: 2026/5/13 | E14: 印尼 | F14: =D14-25 -> 46130 | G14: ok
A15: 13 | B15: 10122742 | C15: T72465ML3 | D15: 2026/5/20 | E15: 东莞 | F15: =D15-25 -> 46137 | G15: 5/28 ok
... A34: 32 | B34: 10123136 | C34: 47023A1 | D34: 2026/8/26 | E34: 印尼 | F34: =D34-25 -> 46235 | G34: 7/21pass
A35: 33 | B35: 10123487 | C35: 47616A | D35: 2026/8/12 | E35: 印尼 | F35: =D35-25 -> 46221
A36: 34 | B36: 10118546 | C36: 35765D | D36: 46253 | E36: 印尼 | F36: =D36-25 -> 46228 | G36: 印尼寄出做测试
