Workbook

Sheet 总接单
A1: 接单日期 | B1: 计划PO出货期 | C1: 客户名称 （第三方客名） | D1: 国家 | E1: PO号 | F1: ITEM NO | G1: 名称 | H1: 数量 | I1: 装箱数 | J1: 总箱数 | K1: BS082D6 | L1: BS083D6 | M1: MZ002D6 | N1: BS062D3/BS062A3/BS062D1/BS062D4 | O1: BS067D1 | P1: BS071D6 | Q1: BS077D6 | R1: BS064D1/BS064D2 | S1: ZC006A1/ZC006E1 | T1: BS068D12 | U1: MZ003D1/MZ003D9 | V1: CZ001D6 | W1: CZ002D6 | X1: CZ003D6 | Y1: CZ004D6 | Z1: CZ014D6 | AA1: BS069A1 | AB1: BS065D6 | AC1: MZ002D9 | AD1: CZ007E1 | AE1: CZ005A1 三角龙 | AF1: CZ005A2 双脊龙 | AG1: CZ005A3 水豚 | AH1: CZ005A4 高地牛 | AI1: CZ005A5 兔子 | AJ1: CZ005A6 海狸 | AK1: CZ005A7 小猫 | AL1: CZ005A8 小狗 | AM1: CZ005A9 蝾螈 | AN1: CZ005A10 树懒 | AO1: CZ005A11 狐狸 | AP1: CZ005A12 河马 | AQ1: CZ006D6（水豚、兔子、高地牛、美西螈、河马、猫） | AR1: SP002A1/SP003A1 | AS1: SP003A2 | AT1: SP005A1 | AU1: BS074D6 | AV1: CZ021D1/D2/D3/D4 | AW1: ZC001A1 | AX1: PF001A1 | AY1: CZ007A1 | AZ1: CZ007A2 | BA1: CZ007A4 | BB1: CZ007A5 | BC1: CZ007A6 | BD1: CZ007A7 | BE1: CZ007A8 | BF1: CZ007A9 | BG1: CZ007A10 | BH1: CZ007A11 | BI1: CZ022D6 | BJ1: CZ007A12 | BK1: CZ007D1 | BL1: CZ023D6 | BM1: CZ017D6 | BN1: BS090D6 | BO1: CZ019D6 | BP1: CZ018D6 | BQ1: CZ018E1 | BR1: BS086D6 | BS1: BS085D6 | BT1: BS089D12 | BU1: 336 FSDU | BV1: 单价USD | BW1: 总金额USD | BX1: 总金额HK$ | BY1: 发票号 | BZ1: 车间
A2: 45902 | B2: 46132 | C2: KMART (AUS / NZ) | D2: 澳大利亚 | E2: THT1402 | F2: BS077D6 | G2: 草莓熊手提包 | H2: 2952 | I2: 6 | J2: =H2/I2 -> 492 | Q2: =H2 -> 2952 | BV2: 3.126 | BW2: =SUM(K2:BU2)*BV2 -> 9227.952 | BX2: =BW2*7.75 -> 71516.628 | BY2: FE63717 | BZ2: B
A3: 45902 | B3: 46132 | C3: KMART (AUS / NZ) | D3: 新西兰 | E3: THT1403 | F3: BS077D6 | G3: 草莓熊手提包 | H3: 48 | I3: 6 | J3: =H3/I3 -> 8 | Q3: =H3 -> 48 | BV3: 3.126 | BW3: =SUM(K3:BU3)*BV3 -> 150.048 | BX3: =BW3*7.75 -> 1162.872 | BY3: FE63718 | BZ3: B
A4: 45954 | B4: 46008 | C4: Wal-Mart Inc. USA | D4: 美国 | E4: THT1430 | F4: CZ021D1 | G4: 按压发声公仔（兔） | H4: 7656 | I4: 6 | J4: =H4/I4 -> 1276 | AV4: =H4 -> 7656 | BV4: 3.77 | BW4: =SUM(K4:BU4)*BV4 -> 28863.12 | BX4: =BW4*7.75 -> 223689.18 | BY4: FE61268 | BZ4: 印尼
A5: 45954 | B5: 46008 | C5: Wal-Mart Inc. USA | D5: 美国 | E5: THT1430 | F5: CZ021D2 | G5: 按压发声公仔（鸭） | H5: 3828 | I5: 6 | J5: =H5/I5 -> 638 | AV5: =H5 -> 3828 | BV5: 3.77 | BW5: =SUM(K5:BU5)*BV5 -> 14431.56 | BX5: =BW5*7.75 -> 111844.59 | BY5: FE61268 | BZ5: 印尼
A6: 45954 | B6: 46008 | C6: Wal-Mart Inc. USA | D6: 美国 | E6: THT1430 | F6: CZ021D3 | G6: 按压发声公仔（牛） | H6: 1914 | I6: 6 | J6: =H6/I6 -> 319 | AV6: =H6 -> 1914 | BV6: 3.77 | BW6: =SUM(K6:BU6)*BV6 -> 7215.78 | BX6: =BW6*7.75 -> 55922.295 | BY6: FE61268 | BZ6: 印尼
A7: 45954 | B7: 46008 | C7: Wal-Mart Inc. USA | D7: 美国 | E7: THT1430 | F7: CZ021D4 | G7: 按压发声公仔（羊） | H7: 1914 | I7: 6 | J7: =H7/I7 -> 319 | AV7: =H7 -> 1914 | BV7: 3.77 | BW7: =SUM(K7:BU7)*BV7 -> 7215.78 | BX7: =BW7*7.75 -> 55922.295 | BY7: FE61268 | BZ7: 印尼
A8: 45954 | B8: 46008 | C8: Wal-Mart Inc. USA | D8: 美国 | E8: THT1433 | F8: CZ021D1 | G8: 按压发声公仔（兔） | H8: 7968 | I8: 6 | J8: =H8/I8 -> 1328 | AV8: =H8 -> 7968 | BV8: 3.77 | BW8: =SUM(K8:BU8)*BV8 -> 30039.36 | BX8: =BW8*7.75 -> 232805.04 | BY8: FE61271 | BZ8: 印尼
A9: 45954 | B9: 46008 | C9: Wal-Mart Inc. USA | D9: 美国 | E9: THT1433 | F9: CZ021D2 | G9: 按压发声公仔（鸭） | H9: 3984 | I9: 6 | J9: =H9/I9 -> 664 | AV9: =H9 -> 3984 | BV9: 3.77 | BW9: =SUM(K9:BU9)*BV9 -> 15019.68 | BX9: =BW9*7.75 -> 116402.52 | BY9: FE61271 | BZ9: 印尼
A10: 45954 | B10: 46008 | C10: Wal-Mart Inc. USA | D10: 美国 | E10: THT1433 | F10: CZ021D3 | G10: 按压发声公仔（牛） | H10: 1992 | I10: 6 | J10: =H10/I10 -> 332 | AV10: =H10 -> 1992 | BV10: 3.77 | BW10: =SUM(K10:BU10)*BV10 -> 7509.84 | BX10: =BW10*7.75 -> 58201.26 | BY10: FE61271 | BZ10: 印尼
A11: 45954 | B11: 46008 | C11: Wal-Mart Inc. USA | D11: 美国 | E11: THT1433 | F11: CZ021D4 | G11: 按压发声公仔（羊） | H11: 1992 | I11: 6 | J11: =H11/I11 -> 332 | AV11: =H11 -> 1992 | BV11: 3.77 | BW11: =SUM(K11:BU11)*BV11 -> 7509.84 | BX11: =BW11*7.75 -> 58201.26 | BY11: FE61271 | BZ11: 印尼
A12: 45954 | B12: 46008 | C12: Wal-Mart Inc. USA | D12: 美国 | E12: THT1434 | F12: CZ021D1 | G12: 按压发声公仔（兔） | H12: 5736 | I12: 6 | J12: =H12/I12 -> 956 | AV12: =H12 -> 5736 | BV12: 3.77 | BW12: =SUM(K12:BU12)*BV12 -> 21624.72 | BX12: =BW12*7.75 -> 167591.58 | BY12: FE61272 | BZ12: 印尼
A13: 45954 | B13: 46008 | C13: Wal-Mart Inc. USA | D13: 美国 | E13: THT1434 | F13: CZ021D2 | G13: 按压发声公仔（鸭） | H13: 2868 | I13: 6 | J13: =H13/I13 -> 478 | AV13: =H13 -> 2868 | BV13: 3.77 | BW13: =SUM(K13:BU13)*BV13 -> 10812.36 | BX13: =BW13*7.75 -> 83795.79 | BY13: FE61272 | BZ13: 印尼
A14: 45954 | B14: 46008 | C14: Wal-Mart Inc. USA | D14: 美国 | E14: THT1434 | F14: CZ021D3 | G14: 按压发声公仔（牛） | H14: 1434 | I14: 6 | J14: =H14/I14 -> 239 | AV14: =H14 -> 1434 | BV14: 3.77 | BW14: =SUM(K14:BU14)*BV14 -> 5406.18 | BX14: =BW14*7.75 -> 41897.895 | BY14: FE61272 | BZ14: 印尼
A15: 45954 | B15: 46008 | C15: Wal-Mart Inc. USA | D15: 美国 | E15: THT1434 | F15: CZ021D4 | G15: 按压发声公仔（羊） | H15: 1434 | I15: 6 | J15: =H15/I15 -> 239 | AV15: =H15 -> 1434 | BV15: 3.77 | BW15: =SUM(K15:BU15)*BV15 -> 5406.18 | BX15: =BW15*7.75 -> 41897.895 | BY15: FE61272 | BZ15: 印尼
A16: 45960 | B16: 46014 | C16: LINIEX APS | D16: 英国 | E16: THT1435 | F16: BS064D1 | G16: MINI手提包系列 | H16: 7008 | I16: 12 | J16: =H16/I16 -> 584 | R16: =H16 -> 7008 | BV16: 1.38 | BW16: =SUM(K16:BU16)*BV16 -> 9671.04 | BX16: =BW16*7.75 -> 74950.56 | BY16: FE61269 | BZ16: B
A17: 45960 | B17: 46014 | C17: LINIEX APS | D17: 英国 | E17: THT1435 | F17: BS065D6 | G17: 手提包狗系列 | H17: 2004 | I17: 6 | J17: =H17/I17 -> 334 | AB17: =H17 -> 2004 | BV17: 2.969 | BW17: =SUM(K17:BU17)*BV17 -> 5949.876 | BX17: =BW17*7.75 -> 46111.539 | BY17: FE61269 | BZ17: B
A18: 45960 | B18: 46014 | C18: LINIEX APS | D18: 英国 | E18: THT1435 | F18: BS074D6 | G18: 独角兽手提包 | H18: 3198 | I18: 6 | J18: =H18/I18 -> 533 | AU18: =H18 -> 3198 | BV18: 2.993 | BW18: =SUM(K18:BU18)*BV18 -> 9571.614 | BX18: =BW18*7.75 -> 74180.008 | BY18: FE61269 | BZ18: B
A19: 45960 | B19: 46014 | C19: LINIEX APS | D19: 英国 | E19: THT1435 | F19: BS067D1 | G19: 手提包猫系列 | H19: 2400 | I19: 6 | J19: =H19/I19 -> 400 | O19: =H19 -> 2400 | BV19: 2.971 | BW19: =SUM(K19:BU19)*BV19 -> 7130.4 | BX19: =BW19*7.75 -> 55260.6 | BY19: FE61269 | BZ19: B
A20: 45966 | B20: 46021 | C20: CREATIVE TOYS (PORTUGAL) | D20: 葡萄牙 | E20: THT1436A | F20: BS068D12 | G20: MINI猫+狗手提包系列 | H20: 14004 | I20: 12 | J20: =H20/I20 -> 1167 | T20: =H20 -> 14004 | BV20: 1.469 | BW20: =SUM(K20:BU20)*BV20 -> 20571.876 | BX20: =BW20*7.75 -> 159432.04 | BY20: FE61270 | BZ20: B
A21: 45966 | B21: 46021 | C21: CREATIVE TOYS (PORTUGAL) | D21: 葡萄牙 | E21: THT1436A | F21: BS074D6 | G21: 独角兽手提包 | H21: 6000 | I21: 6 | J21: =H21/I21 -> 1000 | AU21: =H21 -> 6000 | BV21: 2.942 | BW21: =SUM(K21:BU21)*BV21 -> 17652 | BX21: =BW21*7.75 -> 136803 | BY21: FE61270 | BZ21: B
A22: 45966 | B22: 46021 | C22: CREATIVE TOYS (PORTUGAL) | D22: 葡萄牙 | E22: THT1436A | F22: CZ006D6 | G22: 按压发声公仔（6款混装） | H22: 4002 | I22: 6 | J22: =H22/I22 -> 667 | AQ22: =H22 -> 4002 | BV22: 3.855 | BW22: =SUM(K22:BU22)*BV22 -> 15427.71 | BX22: =BW22*7.75 -> 119564.75 | BY22: FE61270 | BZ22: B
A23: 45968 | B23: 46044 | C23: KMART (AUS / NZ) | D23: 澳大利亚 | E23: THT1450 | F23: MZ002D6 | G23: 鲨鱼实验室2 | H23: 1686 | I23: 6 | J23: =H23/I23 -> 281 | M23: =H23 -> 1686 | BV23: 3.958 | BW23: =SUM(K23:BU23)*BV23 -> 6673.188 | BX23: =BW23*7.75 -> 51717.207 | BY23: FE61275 | BZ23: B
A24: 45968 | B24: 46044 | C24: KMART (AUS / NZ) | D24: 新西兰 | E24: THT1451 | F24: MZ002D6 | G24: 鲨鱼实验室2 | H24: 114 | I24: 6 | J24: =H24/I24 -> 19 | M24: =H24 -> 114 | BV24: 3.958 | BW24: =SUM(K24:BU24)*BV24 -> 451.212 | BX24: =BW24*7.75 -> 3496.893 | BY24: FE61276 | BZ24: B
A25: 45974 | B25: 46053 | C25: TOYRRIFIC (ISRAEL) | D25: 以色列 | E25: THT1453 | F25: BS082D6 | G25: 二代独角兽手提包 | H25: 4110 | I25: 6 | J25: =H25/I25 -> 685 | K25: =H25 -> 4110 | BV25: 3.283 | BW25: =SUM(K25:BU25)*BV25 -> 13493.13 | BX25: =BW25*7.75 -> 104571.76 | BY25: FE61279 | BZ25: B
A26: 45974 | B26: 46053 | C26: TOYRRIFIC (ISRAEL) | D26: 以色列 | E26: THT1453 | F26: BS065D6 | G26: 手提包狗系列 | H26: 4110 | I26: 6 | J26: =H26/I26 -> 685 | AB26: =H26 -> 4110 | BV26: 2.969 | BW26: =SUM(K26:BU26)*BV26 -> 12202.59 | BX26: =BW26*7.75 -> 94570.072 | BY26: FE61279 | BZ26: B
A27: 45983 | B27: 46053 | C27: ROFU (GERMANY) | D27: 德国 | E27: THT1454 | F27: CZ031E1 | G27: 336 FSDU | H27: 120 | I27: 1 | J27: =H27/I27 -> 120 | BU27: =H27 -> 120 | BV27: 1389.696 | BW27: =SUM(K27:BU27)*BV27 -> 166763.52 | BX27: =BW27*7.75 -> 1292417.3 | BY27: FE61281 | BZ27: B
A28: 45988 | B28: 46059 | C28: KMART (AUS / NZ) | D28: 新西兰 | E28: THT1456 | F28: MZ003D1 | G28: 恐龙实验室2 | H28: 498 | I28: 6 | J28: =H28/I28 -> 83 | U28: =H28 -> 498 | BV28: 3.924 | BW28: =SUM(K28:BU28)*BV28 -> 1954.152 | BX28: =BW28*7.75 -> 15144.678 | BY28: FE61283 | BZ28: B
A29: 45988 | B29: 46091 | C29: KMART (AUS / NZ) | D29: 澳大利亚 | E29: THT1457 | F29: MZ002D6 | G29: 鲨鱼实验室2 | H29: 1710 | I29: 6 | J29: =H29/I29 -> 285 | M29: =H29 -> 1710 | BV29: 3.958 | BW29: =SUM(K29:BU29)*BV29 -> 6768.18 | BX29: =BW29*7.75 -> 52453.395 | BY29: FE61293 | BZ29: B
A30: 45988 | B30: 46091 | C30: KMART (AUS / NZ) | D30: 新西兰 | E30: THT1458 | F30: MZ002D6 | G30: 鲨鱼实验室2 | H30: 90 | I30: 6 | J30: =H30/I30 -> 15 | M30: =H30 -> 90 | BV30: 3.958 | BW30: =SUM(K30:BU30)*BV30 -> 356.22 | BX30: =BW30*7.75 -> 2760.705 | BY30: FE61294 | BZ30: B
A31: 45993 | B31: 46059 | C31: KMART (AUS / NZ) | D31: 澳大利亚 | E31: THT1463 | F31: PF001A1 | G31: 马桶遥控车 | H31: 800 | I31: 4 | J31: =H31/I31 -> 200 | AX31: =H31 -> 800 | BV31: 10.262 | BW31: =SUM(K31:BU31)*BV31 -> 8209.6 | BX31: =BW31*7.75 -> 63624.4 | BY31: FE61286 | BZ31: A
A32: 45993 | B32: 46059 | C32: KMART (AUS / NZ) | D32: 新西兰 | E32: THT1464 | F32: MZ003D1 | G32: 恐龙实验室2 | H32: 36 | I32: 6 | J32: =H32/I32 -> 6 | U32: =H32 -> 36 | BV32: 3.924 | BW32: =SUM(K32:BU32)*BV32 -> 141.264 | BX32: =BW32*7.75 -> 1094.796 | BY32: FE61284 | BZ32: B
A33: 45993 | B33: 46059 | C33: KMART (AUS / NZ) | D33: 新西兰 | E33: THT1464 | F33: PF001A1 | G33: 马桶遥控车 | H33: 68 | I33: 4 | J33: =H33/I33 -> 17 | AX33: =H33 -> 68 | BV33: 10.262 | BW33: =SUM(K33:BU33)*BV33 -> 697.816 | BX33: =BW33*7.75 -> 5408.074 | BY33: FE61284 | BZ33: A
A34: 45994 | B34: 46052 | C34: GROUPE RICOCHET INC. (CANADA) | D34: 加拿大 | E34: THT1452A | F34: CZ018D6 | G34: 按压发声公仔（一代牙齿怪） | H34: 5004 | I34: 6 | J34: =H34/I34 -> 834 | BP34: =H34 -> 5004 | BV34: 3.905 | BW34: =SUM(K34:BU34)*BV34 -> 19540.62 | BX34: =BW34*7.75 -> 151439.8 | BY34: FE61278 | BZ34: B
A35: 46006 | B35: 46056 | C35: ORBICO D.O.O. (CROATIA) | D35: 克罗地亚 | E35: THT1469 | F35: BS064D1 | G35: MINI手提包系列 | H35: 4752 | I35: 6 | J35: =H35/I35 -> 792 | R35: =H35 -> 4752 | BV35: 1.38 | BW35: =SUM(K35:BU35)*BV35 -> 6557.76 | BX35: =BW35*7.75 -> 50822.64 | BY35: FE61282 | BZ35: B
A36: 46006 | B36: 46056 | C36: ORBICO D.O.O. (CROATIA) | D36: 克罗地亚 | E36: THT1469 | F36: BS067D1 | G36: 手提包猫系列 | H36: 1020 | I36: 6 | J36: =H36/I36 -> 170 | O36: =H36 -> 1020 | BV36: 2.971 | BW36: =SUM(K36:BU36)*BV36 -> 3030.42 | BX36: =BW36*7.75 -> 23485.755 | BY36: FE61282 | BZ36: B
A37: 46006 | B37: 46056 | C37: ORBICO D.O.O. (CROATIA) | D37: 克罗地亚 | E37: THT1469 | F37: BS065D6 | G37: 手提包狗系列 | H37: 6360 | I37: 6 | J37: =H37/I37 -> 1060 | AB37: =H37 -> 6360 | BV37: 2.969 | BW37: =SUM(K37:BU37)*BV37 -> 18882.84 | BX37: =BW37*7.75 -> 146342.01 | BY37: FE61282 | BZ37: B
A38: 46008 | B38: 46050 | C38: EL ZAYAT (EGYPT) | D38: 埃及 | E38: THT1462B | F38: CZ001D6 | G38: 按压发声玩偶(两款恐龙) | H38: 306 | I38: 6 | J38: =H38/I38 -> 51 | V38: =H38 -> 306 | BV38: 3.648 | BW38: =SUM(K38:BU38)*BV38 -> 1116.288 | BX38: =BW38*7.75 -> 8651.232 | BY38: FE61330 | BZ38: B
A39: 46008 | B39: 46050 | C39: EL ZAYAT (EGYPT) | D39: 埃及 | E39: THT1462B | F39: BS067D1 | G39: 手提包猫系列 | H39: 360 | I39: 6 | J39: =H39/I39 -> 60 | O39: =H39 -> 360 | BV39: 3.09 | BW39: =SUM(K39:BU39)*BV39 -> 1112.4 | BX39: =BW39*7.75 -> 8621.1 | BY39: FE61330 | BZ39: B
A40: 46008 | B40: 46050 | C40: EL ZAYAT (EGYPT) | D40: 埃及 | E40: THT1462B | F40: BS069A1 | G40: 大、小手提包 | H40: 300 | I40: 4 | J40: =H40/I40 -> 75 | AA40: =H40 -> 300 | BV40: 5.064 | BW40: =SUM(K40:BU40)*BV40 -> 1519.2 | BX40: =BW40*7.75 -> 11773.8 | BY40: FE61330 | BZ40: B
...

Sheet A车间总排期
A1: 接单日期 | B1: 国家 | C1: 客跟单 | D1: 客户名称 （第三方客名） | E1: 订单PO.NO | G1: ITEM NO | H1: 名称 | I1: 数量 | J1: 装箱数 | K1: 总箱数 | L1: 计划PO出货期 | M1: 计划验货期 | N1: 第三方 验货期 | O1: 验货结果 | P1: 船期SO （截仓时间） | Q1: 箱唛资料 提供时间 | R1: 箱唛打稿 完成时间 | S1: 箱唛打稿 确认时间 | T1: 客贴纸档案 提供时间 | U1: 包装资料是否提供 | V1: 包装档案 版本 | W1: 布标版本 | X1: 系统货号 | Y1: 是否翻单 | Z1: 是否寄出签办 | AA1: 客供物料 | AB1: 布标日期码 | AC1: 产品、包装 日期码 | AD1: 备注 | AE1: 单价USD | AF1: 总金额USD | AG1: 总金额HK$ | AH1: 是否入系统 | AI1: 下单明细 | AJ1: 送回数量 | AK1: 欠数 | AL1: 贴纸 | AM1: 湖南回复完成时间 | AN1: 询单备料情况
A2: 46172 | B2: 澳大利亚 | C2: Kenix Lin | D2: KMART AUS | E2: THT1664 | F2: PF001A1 | G2: PF001A1 | H2: 马桶遥控车 | I2: 3984 | J2: 4 | K2: =I2/J2 -> 996 | L2: 46238 | M2: 46238 | N2: 46238 | O2: PASS | P2: 8/19-8/24 | Q2: 46183 | R2: 46183 | S2: 46198 | T2: 46184 | U2: 是 | V2: KMART客版 | W2: 无 | X2: {=INDEX(系统货号!C:C,MATCH(1,(系统货号!A:A=G2)*(系统货号!B:B=V2),0))} -> PF001A1-KMART | Y2: 包装跟之前的KMART订单，包装档案如有日期码需修改，除SSCC贴纸外 | AB2: 无 | AC2: 05/26 | AD2: 客版包装+客版说明书+SSCC外箱贴纸+客版日期码05/26+客验货+所有Kmart 订单需要用60MM宽的，“Anko” logo 胶纸封箱； | AE2: 10.262 | AF2: =I2*AE2 -> 40883.808 | AG2: =AF2*7.75 -> 316849.51 | AH2: 46175 | AI2: 系统出单 | AJ2: =672+1976+1120+216 -> 3984 | AK2: =AJ2-I2 -> 0
K3: =I3/J3 -> #DIV/0! | X3: {=INDEX(系统货号!C:C,MATCH(1,(系统货号!A:A=G3)*(系统货号!B:B=V3),0))} -> 0 | AF3: =I3*AE3 -> 0 | AG3: =AF3*7.75 -> 0
K4: =I4/J4 -> #DIV/0! | X4: {=INDEX(系统货号!C:C,MATCH(1,(系统货号!A:A=G4)*(系统货号!B:B=V4),0))} -> 0 | AF4: =I4*AE4 -> 0 | AG4: =AF4*7.75 -> 0
K5: =I5/J5 -> #DIV/0! | X5: {=INDEX(系统货号!C:C,MATCH(1,(系统货号!A:A=G5)*(系统货号!B:B=V5),0))} -> 0 | AF5: =I5*AE5 -> 0 | AG5: =AF5*7.75 -> 0
K6: =I6/J6 -> #DIV/0! | X6: {=INDEX(系统货号!C:C,MATCH(1,(系统货号!A:A=G6)*(系统货号!B:B=V6),0))} -> 0 | AF6: =I6*AE6 -> 0 | AG6: =AF6*7.75 -> 0
I7: =SUM(I2:I6) -> 3984 | AE7: =SUM(AE2:AE6) -> 10.262 | AF7: =SUM(AF2:AF6) -> 40883.808 | AG7: =SUM(AG2:AG6) -> 316849.51

Sheet B车间总排期
A1: 接单日期 | B1: 国家 | C1: 客跟单 | D1: 客户名称 （第三方客名） | E1: 订单PO.NO | F1: 客PO.NO | G1: ITEM NO | H1: 名称 | I1: 数量 | J1: 装箱数 | K1: 总箱数 | L1: 计划PO出货期 | M1: 计划验货期 | N1: 第三方 验货期 | O1: 验货结果 | P1: 船期SO （截仓时间） | Q1: 箱唛资料 提供时间 | R1: 箱唛打稿 完成时间 | S1: 箱唛打稿 确认时间 | T1: 客贴纸档案 提供时间 | U1: 包装资料是否提供 | V1: 包装档案 版本 | W1: 布标版本 | X1: 系统货号 | Y1: 是否翻单 | Z1: 是否寄出签办 | AA1: 客供物料 | AB1: 布标日期码 | AC1: 产品、包装 日期码 | AD1: 备注 | AE1: 单价USD | AF1: 总金额USD | AG1: 总金额HK$ | AH1: 是否入系统 | AI1: 生产车间 | AJ1: 下单明细 | AK1: 送回数量 | AL1: 欠数 | AM1: 贴纸 | AN1: 湖南回复完成时间 | AO1: 询单备料情况
A2: 46147 | B2: 南非 | C2: Kenix Lin | D2: HTIC LIMITED (CHECKERS - South Africa) | E2: THT1615B | G2: BS085D6 | H2: 美人鱼手提包 | I2: 2004 | J2: 6 | K2: =I2/J2 -> 334 | L2: 46238 | M2: 46238 | N2: 自检 | O2: PASS | P2: 46254 | Q2: 46182 | R2: 46185 | S2: 46213 | T2: 46174 | U2: 是 | V2: 标准包装 | W2: 标准布标 | X2: {=INDEX(系统货号!C:C,MATCH(1,(系统货号!A:A=G2)*(系统货号!B:B=V2),0))} -> BS085D6 | AB2: 260720 HS | AC2: 260720 HS | AD2: 标准布标+标准收缩膜+标准说明书+标准传单+客版贴纸+标准银行卡+标准CDU | AE2: 3.27 | AF2: 6553.08 | AG2: 50786.37 | AH2: 46155 | AI2: 邵阳 | AJ2: 系统出单 | AK2: 2004
A3: 46147 | B3: 南非 | C3: Kenix Lin | D3: HTIC LIMITED (CHECKERS - South Africa) | E3: THT1615B | G3: BS086D6 | H3: 蝴蝶结公主手提包 | I3: 2004 | J3: 6 | K3: =I3/J3 -> 334 | L3: 46238 | M3: 46238 | N3: 自检 | O3: PASS | P3: 46254 | Q3: 46182 | R3: 46185 | S3: 46213 | T3: 46174 | U3: 是 | V3: 标准包装 | W3: 标准布标 | X3: {=INDEX(系统货号!C:C,MATCH(1,(系统货号!A:A=G3)*(系统货号!B:B=V3),0))} -> BS086D6 | AB3: 260608 HS | AC3: 260608 HS | AD3: 标准布标+标准收缩膜+标准说明书+标准传单+客版贴纸+标准身份证+标准CDU | AE3: 3.369 | AF3: 6751.476 | AG3: 52323.939 | AH3: 46155 | AI3: 邵阳 | AJ3: 系统出单 | AK3: 2004 | AL3: =AK3-I3 -> 0
A4: 46147 | B4: 南非 | C4: Kenix Lin | D4: HTIC LIMITED (CHECKERS - South Africa) | E4: THT1615B | G4: BS068D12 | H4: MINI猫+狗手提包系列 | I4: 3600 | J4: 12 | K4: =I4/J4 -> 300 | L4: 46238 | M4: 46238 | N4: 自检 | O4: PASS | P4: 46254 | Q4: 46182 | R4: 46185 | S4: 46213 | T4: 46174 | U4: 是 | V4: 标准包装 | W4: 无 | X4: {=INDEX(系统货号!C:C,MATCH(1,(系统货号!A:A=G4)*(系统货号!B:B=V4),0))} -> BS068D12 | AB4: 无 | AC4: 260720 HS | AD4: 标准吊牌+标准说明书+标准传单+客版贴纸+标准身份证+标准CDU+唇彩贴纸（贴纸日期码：150626） | AE4: 1.469 | AF4: 5288.4 | AG4: 40985.1 | AH4: 46155 | AI4: 东莞
A5: 46147 | B5: 南非 | C5: Kenix Lin | D5: HTIC LIMITED (CHECKERS - South Africa) | E5: THT1615B | G5: BS074D6 | H5: 独角兽手提包 | I5: 3600 | J5: 6 | K5: =I5/J5 -> 600 | L5: 46238 | M5: 46238 | N5: 自检 | O5: PASS | P5: 46254 | Q5: 46182 | R5: 46185 | S5: 46213 | T5: 46174 | U5: 是 | V5: 标准包装 | W5: 标准布标 | X5: {=INDEX(系统货号!C:C,MATCH(1,(系统货号!A:A=G5)*(系统货号!B:B=V5),0))} -> BS074D6 | AB5: 260720 HS | AC5: 260720 HS | AD5: 标准布标+标准收缩膜+标准说明书+标准传单+客版贴纸+标准银行卡+标准CDU+指甲油贴纸（贴纸日期码：150626） | AE5: 2.942 | AF5: 10591.2 | AG5: 82081.8 | AH5: 46155 | AI5: 邵阳 | AJ5: 系统出单 | AK5: =3516+84 -> 3600
A6: 46174 | B6: 菲律宾 | C6: Kenix Lin | D6: ANKO (Philippines) | E6: THT1708 | G6: SP002A1 | H6: 冰杯带手柄 | I6: 1440 | J6: 6 | K6: =I6/J6 -> 240 | L6: 46238 | M6: 46238 | N6: 46246 | O6: PASS | P6: 8/19-8/24 | Q6: 46213 | R6: 46214 | S6: 46219 | T6: 46155 | U6: 是 | V6: KMART客版 | W6: 无 | X6: {=INDEX(系统货号!C:C,MATCH(1,(系统货号!A:A=G6)*(系统货号!B:B=V6),0))} -> SP002A1-KMART | AB6: 无 | AC6: 28/25 | AD6: 客版包装+客版说明书+新冰袋(圆角)+客验货+无SSCC贴纸+客版包装和Kmart AUS订单的客包装一致+订单需要用60MM宽的，“Anko” logo 胶纸封箱； | AE6: 1.193 | AF6: =I6*AE6 -> 1717.92 | AG6: =AF6*7.75 -> 13313.88 | AH6: 46175 | AI6: 东莞
A7: 46174 | B7: 菲律宾 | C7: Kenix Lin | D7: ANKO (Philippines) | E7: THT1708 | G7: SP005A1 | H7: 玩具总动员冰杯 | I7: 1440 | J7: 6 | K7: =I7/J7 -> 240 | L7: 46238 | M7: 46238 | N7: 46246 | O7: PASS | P7: 8/19-8/24 | Q7: 46213 | R7: 46214 | S7: 46219 | T7: 46155 | U7: 是 | V7: KMART客版 | W7: 无 | X7: {=INDEX(系统货号!C:C,MATCH(1,(系统货号!A:A=G7)*(系统货号!B:B=V7),0))} -> SP005A1-KMART客版本 | AB7: 无 | AC7: 26/26 | AD7: 客版包装+客版说明书+新冰袋(圆角)+客验货+无SSCC贴纸+客版包装和Kmart AUS订单的客包装一致+订单需要用60MM宽的，“Anko” logo 胶纸封箱； | AE7: 1.452 | AF7: =I7*AE7 -> 2090.88 | AG7: =AF7*7.75 -> 16204.32 | AH7: 46175 | AI7: 东莞
A8: 46169 | B8: 丹麦 | C8: Kenix Lin | D8: LINIEX APS (DENMARK) | E8: THT1621 | G8: BS074D6 | H8: 独角兽手提包（2款混装） | I8: 3000 | J8: 6 | K8: =I8/J8 -> 500 | L8: 46239 | M8: 46239 | N8: 46244 | O8: PASS | P8: 8/17-8/19 | Q8: 46183 | R8: 46183 | S8: 46183 | T8: 46197 | U8: 是 | V8: 丹麦包装 | W8: 标准布标 | X8: {=INDEX(系统货号!C:C,MATCH(1,(系统货号!A:A=G8)*(系统货号!B:B=V8),0))} -> BS074-丹麦 | AB8: 260720 HS | AC8: 260720 HS | AD8: 标准布标+标准收缩膜+标准传单+标准传单+客版贴纸+标准银行卡+标准CDU+指甲油贴纸（贴纸日期码：150626）+客验货+两款混装：PURSE3&PURSE4 | AE8: 2.993 | AF8: =I8*AE8 -> 8979 | AG8: =AF8*7.75 -> 69587.25 | AH8: 46189 | AI8: 邵阳 | AJ8: 系统出单 | AK8: 3000
A9: 46169 | B9: 丹麦 | C9: Kenix Lin | D9: LINIEX APS (DENMARK) | E9: THT1621 | G9: BS085D6 | H9: 美人鱼手提包 | I9: 2400 | J9: 6 | K9: =I9/J9 -> 400 | L9: 46239 | M9: 46239 | N9: 46244 | O9: PASS | P9: 8/17-8/19 | Q9: 46183 | R9: 46183 | S9: 46183 | T9: 46197 | U9: 是 | V9: 标准包装 | W9: 标准布标 | X9: {=INDEX(系统货号!C:C,MATCH(1,(系统货号!A:A=G9)*(系统货号!B:B=V9),0))} -> BS085D6 | AB9: 260713 HS | AC9: 260713 HS | AD9: 标准布标+标准收缩膜+标准传单+客版贴纸+标准银行卡+标准CDU+客验货 | AE9: 3.32 | AF9: =I9*AE9 -> 7968 | AG9: =AF9*7.75 -> 61752 | AH9: 46170 | AI9: 邵阳 | AJ9: 系统出单 | AK9: 2400
A10: 46169 | B10: 丹麦 | C10: Kenix Lin | D10: LINIEX APS (DENMARK) | E10: THT1621 | G10: BS086D6 | H10: 蝴蝶结公主手提包 | I10: 1200 | J10: 6 | K10: =I10/J10 -> 200 | L10: 46239 | M10: 46239 | N10: 46244 | O10: PASS | P10: 8/17-8/19 | Q10: 46183 | R10: 46183 | S10: 46183 | T10: 46197 | U10: 是 | V10: 标准包装 | W10: 标准布标 | X10: {=INDEX(系统货号!C:C,MATCH(1,(系统货号!A:A=G10)*(系统货号!B:B=V10),0))} -> BS086D6 | AB10: 260608 HS | AC10: 260713 HS | AD10: 标准布标+标准收缩膜+标准传单+客版贴纸+标准银行卡+标准CDU+客验货+有从THT1654中转进180PCS，外箱照常用THT1654的外箱，外箱内容无需修改 | AE10: 3.419 | AF10: =I10*AE10 -> 4102.8 | AG10: =AF10*7.75 -> 31796.7 | AH10: 46170 | AI10: 邵阳 | AJ10: 系统出单 | AK10: 1200
A11: 46169 | B11: 丹麦 | C11: Kenix Lin | D11: LINIEX APS (DENMARK) | E11: THT1621 | G11: BS064D1 | H11: MINI手提包系列 | I11: 3000 | J11: 12 | K11: =I11/J11 -> 250 | L11: 46239 | M11: 46239 | N11: 46244 | O11: PASS | P11: 8/17-8/19 | Q11: 46183 | R11: 46183 | S11: 46183 | T11: 46197 | U11: 是 | V11: 标准包装 | W11: 无 | X11: {=INDEX(系统货号!C:C,MATCH(1,(系统货号!A:A=G11)*(系统货号!B:B=V11),0))} -> BS064D1 | AB11: 无 | AC11: 260720 HS | AD11: 标准吊牌+标准传单+客版贴纸+标准CDU+标准银行卡+客验货 | AE11: 1.38 | AF11: =I11*AE11 -> 4140 | AG11: =AF11*7.75 -> 32085 | AH11: 46170 | AI11: 东莞 | AK11: 3000
A12: 46126 | B12: 澳大利亚 | C12: Kenix Lin | D12: KMART (AUS / NZ) | E12: THT1570 | G12: SP002A1 | H12: 冰杯带手柄 | I12: 35100 | J12: 6 | K12: =I12/J12 -> 5850 | L12: 46244 | M12: 46244 | N12: 46258 | Q12: 46157 | R12: 46161 | S12: 46174 | T12: 46155 | U12: 是 | V12: KMART客版 | W12: 无 | X12: {=INDEX(系统货号!C:C,MATCH(1,(系统货号!A:A=G12)*(系统货号!B:B=V12),0))} -> SP002A1-KMART | Y12: 库存订单塑胶件等部分物料无需再次采购，彩盒、说明书、SSCC外箱贴纸需更换 | AB12: 无 | AC12: 28/25 | AD12: 客版包装+客版说明书+新冰袋+SSCC外箱贴纸+客版日期码28/25+客验货+所有Kmart 订单需要用60MM宽的，“Anko” logo 胶纸封箱； | AE12: 1.189 | AF12: =I12*AE12 -> 41733.9 | AG12: =AF12*7.75 -> 323437.72 | AH12: 46137 | AI12: 东莞
A13: 46126 | B13: 新西兰 | C13: Kenix Lin | D13: KMART (AUS / NZ) | E13: THT1571 | G13: SP002A1 | H13: 冰杯带手柄 | I13: 3510 | J13: 6 | K13: =I13/J13 -> 585 | L13: 46244 | M13: 46244 | N13: 46258 | Q13: 46157 | R13: 46161 | S13: 46174 | T13: 46155 | U13: 是 | V13: KMART客版 | W13: 无 | X13: {=INDEX(系统货号!C:C,MATCH(1,(系统货号!A:A=G13)*(系统货号!B:B=V13),0))} -> SP002A1-KMART | Y13: 库存订单塑胶件等部分物料无需再次采购，彩盒、说明书、SSCC外箱贴纸需更换 | AB13: 无 | AC13: 28/25 | AD13: 客版包装+客版说明书+新冰袋+SSCC外箱贴纸+客版日期码28/25+客验货+所有Kmart 订单需要用60MM宽的，“Anko” logo 胶纸封箱； | AE13: 1.189 | AF13: =I13*AE13 -> 4173.39 | AG13: =AF13*7.75 -> 32343.772 | AH13: 46137 | AI13: 东莞
A14: 46126 | B14: 澳大利亚 | C14: Kenix Lin | D14: KMART (AUS / NZ) | E14: THT1572 | G14: SP003A2 | H14: 史迪仔冰杯 | I14: 8754 | J14: 6 | K14: =I14/J14 -> 1459 | L14: 46244 | M14: 46244 | N14: 46258 | Q14: 46157 | R14: 46161 | S14: 46174 | T14: 46155 | U14: 是 | V14: KMART客版 | W14: 无 | X14: {=INDEX(系统货号!C:C,MATCH(1,(系统货号!A:A=G14)*(系统货号!B:B=V14),0))} -> SP003A2-KMART | Y14: 库存订单塑胶件等部分物料无需再次采购，彩盒、说明书、SSCC外箱贴纸需更换 | AB14: 无 | AC14: 28/25 | AD14: 客版包装+客版说明书+新冰袋+SSCC外箱贴纸+客版日期码28/25+客验货+所有Kmart 订单需要用60MM宽的，“Anko” logo 胶纸封箱； | AE14: 1.462 | AF14: =I14*AE14 -> 12798.348 | AG14: =AF14*7.75 -> 99187.197 | AH14: 46137 | AI14: 东莞
A15: 46126 | B15: 新西兰 | C15: Kenix Lin | D15: KMART (AUS / NZ) | E15: THT1573 | G15: SP003A2 | H15: 史迪仔冰杯 | I15: 870 | J15: 6 | K15: =I15/J15 -> 145 | L15: 46244 | M15: 46244 | N15: 46258 | Q15: 46157 | R15: 46161 | S15: 46174 | T15: 46155 | U15: 是 | V15: KMART客版 | W15: 无 | X15: {=INDEX(系统货号!C:C,MATCH(1,(系统货号!A:A=G15)*(系统货号!B:B=V15),0))} -> SP003A2-KMART | Y15: 库存订单塑胶件等部分物料无需再次采购，彩盒、说明书、SSCC外箱贴纸需更换 | AB15: 无 | AC15: 28/25 | AD15: 客版包装+客版说明书+新冰袋+SSCC外箱贴纸+客版日期码28/25+客验货+所有Kmart 订单需要用60MM宽的，“Anko” logo 胶纸封箱； | AE15: 1.462 | AF15: =I15*AE15 -> 1271.94 | AG15: =AF15*7.75 -> 9857.535 | AH15: 46137 | AI15: 东莞
A16: 46126 | B16: 澳大利亚 | C16: Kenix Lin | D16: KMART (AUS / NZ) | E16: THT1574 | G16: SP003A3 | H16: 公主冰杯 | I16: 8754 | J16: 6 | K16: =I16/J16 -> 1459 | L16: 46244 | M16: 46244 | N16: 46258 | Q16: 46157 | R16: 46161 | S16: 46174 | T16: 46155 | U16: 是 | V16: KMART客版 | W16: 无 | X16: {=INDEX(系统货号!C:C,MATCH(1,(系统货号!A:A=G16)*(系统货号!B:B=V16),0))} -> SP003A3-KMART | Y16: 库存订单塑胶件等部分物料无需再次采购，彩盒、说明书、SSCC外箱贴纸需更换 | AB16: 无 | AC16: 28/25 | AD16: 客版包装+客版说明书+新冰袋+SSCC外箱贴纸+客版日期码28/25+客验货+所有Kmart 订单需要用60MM宽的，“Anko” logo 胶纸封箱； | AE16: 1.462 | AF16: =I16*AE16 -> 12798.348 | AG16: =AF16*7.75 -> 99187.197 | AH16: 46137 | AI16: 东莞
A17: 46126 | B17: 新西兰 | C17: Kenix Lin | D17: KMART (AUS / NZ) | E17: THT1575 | G17: SP003A3 | H17: 公主冰杯 | I17: 870 | J17: 6 | K17: =I17/J17 -> 145 | L17: 46244 | M17: 46244 | N17: 46258 | Q17: 46157 | R17: 46161 | S17: 46174 | T17: 46155 | U17: 是 | V17: KMART客版 | W17: 无 | X17: {=INDEX(系统货号!C:C,MATCH(1,(系统货号!A:A=G17)*(系统货号!B:B=V17),0))} -> SP003A3-KMART | Y17: 库存订单塑胶件等部分物料无需再次采购，彩盒、说明书、SSCC外箱贴纸需更换 | AB17: 无 | AC17: 28/25 | AD17: 客版包装+客版说明书+新冰袋+SSCC外箱贴纸+客版日期码28/25+客验货+所有Kmart 订单需要用60MM宽的，“Anko” logo 胶纸封箱； | AE17: 1.462 | AF17: =I17*AE17 -> 1271.94 | AG17: =AF17*7.75 -> 9857.535 | AH17: 46137 | AI17: 东莞
A18: 46126 | B18: 澳大利亚 | C18: Kenix Lin | D18: KMART (AUS / NZ) | E18: THT1576 | G18: SP005A1 | H18: 玩具总动员冰杯 | I18: 12954 | J18: 6 | K18: =I18/J18 -> 2159 | L18: 46244 | M18: 46244 | N18: 46258 | Q18: 46157 | R18: 46161 | S18: 46174 | T18: 46155 | U18: 是 | V18: KMART客版 | W18: 无 | X18: {=INDEX(系统货号!C:C,MATCH(1,(系统货号!A:A=G18)*(系统货号!B:B=V18),0))} -> SP005A1-KMART客版本 | AB18: 无 | AC18: 26/26 | AD18: 客版包装+客版说明书+新冰袋+SSCC外箱贴纸+客版日期码26/26+客验货+所有Kmart 订单需要用60MM宽的，“Anko” logo 胶纸封箱； | AE18: 1.452 | AF18: =I18*AE18 -> 18809.208 | AG18: =AF18*7.75 -> 145771.36 | AH18: 46155 | AI18: 东莞
A19: 46126 | B19: 新西兰 | C19: Kenix Lin | D19: KMART (AUS / NZ) | E19: THT1577 | G19: SP005A1 | H19: 玩具总动员冰杯 | I19: 1290 | J19: 6 | K19: =I19/J19 -> 215 | L19: 46244 | M19: 46244 | N19: 46258 | Q19: 46157 | R19: 46161 | S19: 46174 | T19: 46155 | U19: 是 | V19: KMART客版 | W19: 无 | X19: {=INDEX(系统货号!C:C,MATCH(1,(系统货号!A:A=G19)*(系统货号!B:B=V19),0))} -> SP005A1-KMART客版本 | AB19: 无 | AC19: 26/26 | AD19: 客版包装+客版说明书+新冰袋+SSCC外箱贴纸+客版日期码26/26+客验货+所有Kmart 订单需要用60MM宽的，“Anko” logo 胶纸封箱； | AE19: 1.452 | AF19: =I19*AE19 -> 1873.08 | AG19: =AF19*7.75 -> 14516.37 | AH19: 46155 | AI19: 东莞
A20: 46126 | B20: 澳大利亚 | C20: Kenix Lin | D20: TARGET AUS | E20: THT1589 | G20: SP002A1 | H20: 冰杯带手柄 | I20: 3900 | J20: 6 | K20: =I20/J20 -> 650 | L20: 46244 | M20: 46244 | N20: 46258 | Q20: 46157 | R20: 46161 | S20: 46169 | T20: 46155 | U20: 是 | V20: KMART客版 | W20: 无 | X20: {=INDEX(系统货号!C:C,MATCH(1,(系统货号!A:A=G20)*(系统货号!B:B=V20),0))} -> SP002A1-KMART | Y20: 库存订单塑胶件等部分物料无需再次采购，彩盒、说明书、SSCC外箱贴纸需更换 | AB20: 无 | AC20: 28/25 | AD20: 客版包装+客版说明书+新冰袋+SSCC外箱贴纸+客版日期码28/25+客验货+所有Kmart 订单需要用60MM宽的，“Anko” logo 胶纸封箱； | AE20: 1.189 | AF20: =I20*AE20 -> 4637.1 | AG20: =AF20*7.75 -> 35937.525 | AH20: 46137 | AI20: 东莞
A21: 46183 | B21: 澳大利亚 | C21: Kenix Lin | D21: KMART (AUS / NZ) | E21: THT1723 | G21: BS090D6 | H21: 美人鱼+蝴蝶结混装手提包 | I21: 3000 | J21: 6 | K21: =I21/J21 -> 500 | L21: 46252 | M21: 46260 | N21: 跟客人延期，待确认，先按此货期进行 | Q21: 46220 | R21: 46221 | S21: 46231 | T21: 46220 | U21: 是 | V21: KMART客版 | W21: 标准布标 | X21: {=INDEX(系统货号!C:C,MATCH(1,(系统货号!A:A=G21)*(系统货号!B:B=V21),0))} -> BS090D6-KMART客版本 | Y21: 欠亚克力吊牌8月7号 | AB21: 31/26 | AC21: 31/26 | AD21: 标准布标++客版收缩膜+客版传单+标准银行卡+SSCC贴纸+客版CDU+客版日期码31/26+客验货+所有Kmart 订单需要用60MM宽的，“Anko” logo 胶纸封箱； | AE21: 3.503 | AF21: =I21*AE21 -> 10509 | AG21: =AF21*7.75 -> 81444.75 | AH21: 46203 | AI21: 邵阳 | AJ21: 系统出单
A22: 46183 | B22: 新西兰 | C22: Kenix Lin | D22: KMART (AUS / NZ) | E22: THT1724 | G22: BS090D6 | H22: 美人鱼+蝴蝶结混装手提包 | I22: 300 | J22: 6 | K22: =I22/J22 -> 50 | L22: 46252 | M22: 46260 | N22: 跟客人延期，待确认，先按此货期进行 | Q22: 46220 | R22: 46221 | S22: 46231 | T22: 46220 | U22: 是 | V22: KMART客版 | W22: 标准布标 | X22: {=INDEX(系统货号!C:C,MATCH(1,(系统货号!A:A=G22)*(系统货号!B:B=V22),0))} -> BS090D6-KMART客版本 | Y22: 欠亚克力吊牌8月7号 | AB22: 31/26 | AC22: 31/26 | AD22: 标准布标+客版收缩膜+客版传单+标准银行卡+SSCC贴纸+客版CDU+客版日期码31/26+客验货+所有Kmart 订单需要用60MM宽的，“Anko” logo 胶纸封箱； | AE22: 3.503 | AF22: =I22*AE22 -> 1050.9 | AG22: =AF22*7.75 -> 8144.475 | AH22: 46203 | AI22: 邵阳 | AJ22: 系统出单
A23: 46178 | B23: 台湾 | C23: Kenix Lin | D23: TRU ASIA (TWN / THA/ HKG / SGA / MLY) | E23: THT1697 | G23: BS085D6 | H23: 美人鱼手提包 | I23: 108 | J23: 6 | K23: =I23/J23 -> 18 | L23: 46255 | M23: 46255 | N23: 自检7/7号提供布标 | Q23: 46211 | R23: 46214 | S23: 46219 | T23: 46211 | U23: 是 | V23: TRU客版 | W23: 客版布标 | X23: {=INDEX(系统货号!C:C,MATCH(1,(系统货号!A:A=G23)*(系统货号!B:B=V23),0))} -> BS085D6-TRU | Y23: 欠亚克力吊牌8月7号 | AB23: 100826 | AC23: 100826 | AD23: 客版布标+标准收缩膜+标准传单+客版贴纸+标准CDU+标准银行卡 | AE23: 3.443 | AF23: =I23*AE23 -> 371.844 | AG23: =AF23*7.75 -> 2881.791 | AH23: 46212 | AI23: 邵阳 | AJ23: 系统出单
A24: 46178 | B24: 台湾 | C24: Kenix Lin | D24: TRU ASIA (TWN / THA/ HKG / SGA / MLY) | E24: THT1697 | G24: BS086D6 | H24: 蝴蝶结公主手提包 | I24: 108 | J24: 6 | K24: =I24/J24 -> 18 | L24: 46255 | M24: 46255 | N24: 自检7/7号提供布标 | Q24: 46211 | R24: 46214 | S24: 46219 | T24: 46211 | U24: 是 | V24: TRU客版 | W24: 客版布标 | X24: {=INDEX(系统货号!C:C,MATCH(1,(系统货号!A:A=G24)*(系统货号!B:B=V24),0))} -> BS086D6-TRU | Y24: 欠亚克力吊牌8月7号 | AB24: 100826 | AC24: 100826 | AD24: 客版布标+标准收缩膜+标准传单+客版贴纸+标准CDU+标准银行卡 | AE24: 3.542 | AF24: =I24*AE24 -> 382.536 | AG24: =AF24*7.75 -> 2964.654 | AH24: 46212 | AI24: 邵阳 | AJ24: 系统出单
A25: 46178 | B25: 泰国 | C25: Kenix Lin | D25: TRU ASIA (TWN / THA/ HKG / SGA / MLY) | E25: THT1698 | G25: BS085D6 | H25: 美人鱼手提包 | I25: 36 | J25: 6 | K25: =I25/J25 -> 6 | L25: 46255 | M25: 46255 | N25: 自检7/7号提供布标 | Q25: 46211 | R25: 46214 | S25: 46219 | T25: 46211 | U25: 是 | V25: TRU客版 | W25: 客版布标 | X25: {=INDEX(系统货号!C:C,MATCH(1,(系统货号!A:A=G25)*(系统货号!B:B=V25),0))} -> BS085D6-TRU | Y25: 欠亚克力吊牌8月7号 | AB25: 100826 | AC25: 100826 | AD25: 客版布标+标准收缩膜+标准传单+客版贴纸+标准CDU+标准银行卡 | AE25: 3.443 | AF25: =I25*AE25 -> 123.948 | AG25: =AF25*7.75 -> 960.597 | AH25: 46212 | AI25: 邵阳 | AJ25: 系统出单
A26: 46178 | B26: 泰国 | C26: Kenix Lin | D26: TRU ASIA (TWN / THA/ HKG / SGA / MLY) | E26: THT1698 | G26: BS086D6 | H26: 蝴蝶结公主手提包 | I26: 36 | J26: 6 | K26: =I26/J26 -> 6 | L26: 46255 | M26: 46255 | N26: 自检7/7号提供布标 | Q26: 46211 | R26: 46214 | S26: 46219 | T26: 46211 | U26: 是 | V26: TRU客版 | W26: 客版布标 | X26: {=INDEX(系统货号!C:C,MATCH(1,(系统货号!A:A=G26)*(系统货号!B:B=V26),0))} -> BS086D6-TRU | Y26: 欠亚克力吊牌8月7号 | AB26: 100826 | AC26: 100826 | AD26: 客版布标+标准收缩膜+标准传单+客版贴纸+标准CDU+标准银行卡 | AE26: 3.542 | AF26: =I26*AE26 -> 127.512 | AG26: =AF26*7.75 -> 988.218 | AH26: 46212 | AI26: 邵阳 | AJ26: 系统出单
A27: 46178 | B27: 香港 | C27: Kenix Lin | D27: TRU ASIA (TWN / THA/ HKG / SGA / MLY) | E27: THT1704 | G27: BS085D6 | H27: 美人鱼手提包 | I27: 288 | J27: 6 | K27: =I27/J27 -> 48 | L27: 46255 | M27: 46255 | N27: 自检7/7号提供布标 | Q27: 46211 | R27: 46214 | S27: 46219 | T27: 46211 | U27: 是 | V27: TRU客版 | W27: 客版布标 | X27: {=INDEX(系统货号!C:C,MATCH(1,(系统货号!A:A=G27)*(系统货号!B:B=V27),0))} -> BS085D6-TRU | Y27: 欠亚克力吊牌8月7号 | AB27: 100826 | AC27: 100826 | AD27: 客版布标+标准收缩膜+标准传单+客版贴纸+标准CDU+标准银行卡 | AE27: 3.443 | AF27: =I27*AE27 -> 991.584 | AG27: =AF27*7.75 -> 7684.776 | AH27: 46212 | AI27: 邵阳 | AJ27: 系统出单
A28: 46178 | B28: 香港 | C28: Kenix Lin | D28: TRU ASIA (TWN / THA/ HKG / SGA / MLY) | E28: THT1704 | G28: BS086D6 | H28: 蝴蝶结公主手提包 | I28: 288 | J28: 6 | K28: =I28/J28 -> 48 | L28: 46255 | M28: 46255 | N28: 自检7/7号提供布标 | Q28: 46211 | R28: 46214 | S28: 46219 | T28: 46211 | U28: 是 | V28: TRU客版 | W28: 客版布标 | X28: {=INDEX(系统货号!C:C,MATCH(1,(系统货号!A:A=G28)*(系统货号!B:B=V28),0))} -> BS086D6-TRU | Y28: 欠亚克力吊牌8月7号 | AB28: 100826 | AC28: 100826 | AD28: 客版布标+标准收缩膜+标准传单+客版贴纸+标准CDU+标准银行卡 | AE28: 3.542 | AF28: =I28*AE28 -> 1020.096 | AG28: =AF28*7.75 -> 7905.744 | AH28: 46212 | AI28: 邵阳 | AJ28: 系统出单
A29: 46178 | B29: 新加坡 | C29: Kenix Lin | D29: TRU ASIA (TWN / THA/ HKG / SGA / MLY) | E29: THT1705 | G29: BS085D6 | H29: 美人鱼手提包 | I29: 288 | J29: 6 | K29: =I29/J29 -> 48 | L29: 46255 | M29: 46255 | N29: 自检7/7号提供布标 | Q29: 46211 | R29: 46214 | S29: 46219 | T29: 46211 | U29: 是 | V29: TRU客版 | W29: 客版布标 | X29: {=INDEX(系统货号!C:C,MATCH(1,(系统货号!A:A=G29)*(系统货号!B:B=V29),0))} -> BS085D6-TRU | Y29: 欠亚克力吊牌8月7号 | AB29: 100826 | AC29: 100826 | AD29: 客版布标+标准收缩膜+标准传单+客版贴纸+标准CDU+标准银行卡 | AE29: 3.443 | AF29: =I29*AE29 -> 991.584 | AG29: =AF29*7.75 -> 7684.776 | AH29: 46212 | AI29: 邵阳 | AJ29: 系统出单
A30: 46178 | B30: 新加坡 | C30: Kenix Lin | D30: TRU ASIA (TWN / THA/ HKG / SGA / MLY) | E30: THT1705 | G30: BS086D6 | H30: 蝴蝶结公主手提包 | I30: 288 | J30: 6 | K30: =I30/J30 -> 48 | L30: 46255 | M30: 46255 | N30: 自检7/7号提供布标 | Q30: 46211 | R30: 46214 | S30: 46219 | T30: 46211 | U30: 是 | V30: TRU客版 | W30: 客版布标 | X30: {=INDEX(系统货号!C:C,MATCH(1,(系统货号!A:A=G30)*(系统货号!B:B=V30),0))} -> BS086D6-TRU | Y30: 欠亚克力吊牌8月7号 | AB30: 100826 | AC30: 100826 | AD30: 客版布标+标准收缩膜+标准传单+客版贴纸+标准CDU+标准银行卡 | AE30: 3.542 | AF30: =I30*AE30 -> 1020.096 | AG30: =AF30*7.75 -> 7905.744 | AH30: 46212 | AI30: 邵阳 | AJ30: 系统出单
A31: 46178 | B31: 马来西亚 | C31: Kenix Lin | D31: TRU ASIA (TWN / THA/ HKG / SGA / MLY) | E31: THT1706 | G31: BS085D6 | H31: 美人鱼手提包 | I31: 288 | J31: 6 | K31: =I31/J31 -> 48 | L31: 46255 | M31: 46255 | N31: 自检7/7号提供布标 | Q31: 46211 | R31: 46214 | S31: 46219 | T31: 46211 | U31: 是 | V31: TRU客版 | W31: 客版布标 | X31: {=INDEX(系统货号!C:C,MATCH(1,(系统货号!A:A=G31)*(系统货号!B:B=V31),0))} -> BS085D6-TRU | Y31: 欠亚克力吊牌8月7号 | AB31: 100826 | AC31: 100826 | AD31: 客版布标+标准收缩膜+标准传单+客版贴纸+标准CDU+标准银行卡 | AE31: 3.443 | AF31: =I31*AE31 -> 991.584 | AG31: =AF31*7.75 -> 7684.776 | AH31: 46212 | AI31: 邵阳 | AJ31: 系统出单
A32: 46178 | B32: 马来西亚 | C32: Kenix Lin | D32: TRU ASIA (TWN / THA/ HKG / SGA / MLY) | E32: THT1706 | G32: BS086D6 | H32: 蝴蝶结公主手提包 | I32: 288 | J32: 6 | K32: =I32/J32 -> 48 | L32: 46255 | M32: 46255 | N32: 自检7/7号提供布标 | Q32: 46211 | R32: 46214 | S32: 46219 | T32: 46211 | U32: 是 | V32: TRU客版 | W32: 客版布标 | X32: {=INDEX(系统货号!C:C,MATCH(1,(系统货号!A:A=G32)*(系统货号!B:B=V32),0))} -> BS086D6-TRU | Y32: 欠亚克力吊牌8月7号 | AB32: 100826 | AC32: 100826 | AD32: 客版布标+标准收缩膜+标准传单+客版贴纸+标准CDU+标准银行卡 | AE32: 3.542 | AF32: =I32*AE32 -> 1020.096 | AG32: =AF32*7.75 -> 7905.744 | AH32: 46212 | AI32: 邵阳 | AJ32: 系统出单
A33: 46178 | B33: 菲律宾 | C33: Kenix Lin | D33: ANKO (Philippines) | E33: THT1712 | G33: SP002A1 | H33: 冰杯带手柄 | I33: 1902 | J33: 6 | K33: =I33/J33 -> 317 | L33: 46265 | M33: 46265 | Q33: 46213 | R33: 46214 | S33: 46219 | T33: 46155 | U33: 是 | V33: KMART客版 | W33: 无 | X33: {=INDEX(系统货号!C:C,MATCH(1,(系统货号!A:A=G33)*(系统货号!B:B=V33),0))} -> SP002A1-KMART | AB33: 无 | AC33: 28/25 | AD33: 客版包装+客版说明书+新冰袋(圆角)+客验货+无SSCC贴纸+客版包装和Kmart AUS订单的客包装一致+订单需要用60MM宽的，“Anko” logo 胶纸封箱； | AE33: 1.193 | AF33: =I33*AE33 -> 2269.086 | AG33: =AF33*7.75 -> 17585.416 | AH33: 46183 | AI33: 东莞
A34: 46126 | B34: 澳大利亚 | C34: Kenix Lin | D34: KMART (AUS / NZ) | E34: THT1578 | G34: SP002A1 | H34: 冰杯带手柄 | I34: 35100 | J34: 6 | K34: =I34/J34 -> 5850 | L34: 46266 | M34: 46266 | Q34: 46157 | R34: 46161 | S34: 46174 | T34: 46155 | U34: 是 | V34: KMART客版 | W34: 无 | X34: {=INDEX(系统货号!C:C,MATCH(1,(系统货号!A:A=G34)*(系统货号!B:B=V34),0))} -> SP002A1-KMART | Y34: 库存订单塑胶件等部分物料无需再次采购，彩盒、说明书、SSCC外箱贴纸需更换 | AB34: 无 | AC34: 28/25 | AD34: 客版包装+客版说明书+新冰袋+SSCC外箱贴纸+客版日期码28/25+客验货+所有Kmart 订单需要用60MM宽的，“Anko” logo 胶纸封箱； | AE34: 1.189 | AF34: =I34*AE34 -> 41733.9 | AG34: =AF34*7.75 -> 323437.72 | AH34: 46137 | AI34: 东莞
A35: 46126 | B35: 新西兰 | C35: Kenix Lin | D35: KMART (AUS / NZ) | E35: THT1579 | G35: SP002A1 | H35: 冰杯带手柄 | I35: 3510 | J35: 6 | K35: =I35/J35 -> 585 | L35: 46266 | M35: 46266 | Q35: 46157 | R35: 46161 | S35: 46174 | T35: 46155 | U35: 是 | V35: KMART客版 | W35: 无 | X35: {=INDEX(系统货号!C:C,MATCH(1,(系统货号!A:A=G35)*(系统货号!B:B=V35),0))} -> SP002A1-KMART | Y35: 库存订单塑胶件等部分物料无需再次采购，彩盒、说明书、SSCC外箱贴纸需更换 | AB35: 无 | AC35: 28/25 | AD35: 客版包装+客版说明书+新冰袋+SSCC外箱贴纸+客版日期码28/25+客验货+所有Kmart 订单需要用60MM宽的，“Anko” logo 胶纸封箱； | AE35: 1.189 | AF35: =I35*AE35 -> 4173.39 | AG35: =AF35*7.75 -> 32343.772 | AH35: 46137 | AI35: 东莞
A36: 46126 | B36: 澳大利亚 | C36: Kenix Lin | D36: KMART (AUS / NZ) | E36: THT1580 | G36: SP003A2 | H36: 史迪仔冰杯 | I36: 7500 | J36: 6 | K36: =I36/J36 -> 1250 | L36: 46266 | M36: 46266 | Q36: 46157 | R36: 46161 | S36: 46174 | T36: 46155 | U36: 是 | V36: KMART客版 | W36: 无 | X36: {=INDEX(系统货号!C:C,MATCH(1,(系统货号!A:A=G36)*(系统货号!B:B=V36),0))} -> SP003A2-KMART | Y36: 库存订单塑胶件等部分物料无需再次采购，彩盒、说明书、SSCC外箱贴纸需更换 | AB36: 无 | AC36: 28/25 | AD36: 客版包装+客版说明书+新冰袋+SSCC外箱贴纸+客版日期码28/25+客验货+所有Kmart 订单需要用60MM宽的，“Anko” logo 胶纸封箱； | AE36: 1.462 | AF36: =I36*AE36 -> 10965 | AG36: =AF36*7.75 -> 84978.75 | AH36: 46137 | AI36: 东莞
A37: 46126 | B37: 新西兰 | C37: Kenix Lin | D37: KMART (AUS / NZ) | E37: THT1581 | G37: SP003A2 | H37: 史迪仔冰杯 | I37: 750 | J37: 6 | K37: =I37/J37 -> 125 | L37: 46266 | M37: 46266 | Q37: 46157 | R37: 46161 | S37: 46174 | T37: 46155 | U37: 是 | V37: KMART客版 | W37: 无 | X37: {=INDEX(系统货号!C:C,MATCH(1,(系统货号!A:A=G37)*(系统货号!B:B=V37),0))} -> SP003A2-KMART | Y37: 库存订单塑胶件等部分物料无需再次采购，彩盒、说明书、SSCC外箱贴纸需更换 | AB37: 无 | AC37: 28/25 | AD37: 客版包装+客版说明书+新冰袋+SSCC外箱贴纸+客版日期码28/25+客验货+所有Kmart 订单需要用60MM宽的，“Anko” logo 胶纸封箱； | AE37: 1.462 | AF37: =I37*AE37 -> 1096.5 | AG37: =AF37*7.75 -> 8497.875 | AH37: 46137 | AI37: 东莞
A38: 46126 | B38: 澳大利亚 | C38: Kenix Lin | D38: KMART (AUS / NZ) | E38: THT1582 | G38: SP003A3 | H38: 公主冰杯 | I38: 7500 | J38: 6 | K38: =I38/J38 -> 1250 | L38: 46266 | M38: 46266 | Q38: 46157 | R38: 46161 | S38: 46174 | T38: 46155 | U38: 是 | V38: KMART客版 | W38: 无 | X38: {=INDEX(系统货号!C:C,MATCH(1,(系统货号!A:A=G38)*(系统货号!B:B=V38),0))} -> SP003A3-KMART | Y38: 库存订单塑胶件等部分物料无需再次采购，彩盒、说明书、SSCC外箱贴纸需更换 | AB38: 无 | AC38: 28/25 | AD38: 客版包装+客版说明书+新冰袋+SSCC外箱贴纸+客版日期码28/25+客验货+所有Kmart 订单需要用60MM宽的，“Anko” logo 胶纸封箱； | AE38: 1.462 | AF38: =I38*AE38 -> 10965 | AG38: =AF38*7.75 -> 84978.75 | AH38: 46137 | AI38: 东莞
A39: 46126 | B39: 新西兰 | C39: Kenix Lin | D39: KMART (AUS / NZ) | E39: THT1583 | G39: SP003A3 | H39: 公主冰杯 | I39: 750 | J39: 6 | K39: =I39/J39 -> 125 | L39: 46266 | M39: 46266 | Q39: 46157 | R39: 46161 | S39: 46174 | T39: 46155 | U39: 是 | V39: KMART客版 | W39: 无 | X39: {=INDEX(系统货号!C:C,MATCH(1,(系统货号!A:A=G39)*(系统货号!B:B=V39),0))} -> SP003A3-KMART | Y39: 库存订单塑胶件等部分物料无需再次采购，彩盒、说明书、SSCC外箱贴纸需更换 | AB39: 无 | AC39: 28/25 | AD39: 客版包装+客版说明书+新冰袋+SSCC外箱贴纸+客版日期码28/25+客验货+所有Kmart 订单需要用60MM宽的，“Anko” logo 胶纸封箱； | AE39: 1.462 | AF39: =I39*AE39 -> 1096.5 | AG39: =AF39*7.75 -> 8497.875 | AH39: 46137 | AI39: 东莞
A40: 46126 | B40: 澳大利亚 | C40: Kenix Lin | D40: KMART (AUS / NZ) | E40: THT1584 | G40: SP005A1 | H40: 玩具总动员冰杯 | I40: 11100 | J40: 6 | K40: =I40/J40 -> 1850 | L40: 46266 | M40: 46266 | Q40: 46157 | R40: 46161 | S40: 46174 | T40: 46155 | U40: 是 | V40: KMART客版 | W40: 无 | X40: {=INDEX(系统货号!C:C,MATCH(1,(系统货号!A:A=G40)*(系统货号!B:B=V40),0))} -> SP005A1-KMART客版本 | AB40: 无 | AC40: 26/26 | AD40: 客版包装+客版说明书+新冰袋+SSCC外箱贴纸+客版日期码26/26+客验货+所有Kmart 订单需要用60MM宽的，“Anko” logo 胶纸封箱； | AE40: 1.452 | AF40: =I40*AE40 -> 16117.2 | AG40: =AF40*7.75 -> 124908.3 | AH40: 46155 | AI40: 东莞
...

Sheet 印尼总排期
A1: 接单日期 | B1: 国家 | C1: 客跟单 | D1: 客户名称 （第三方客名） | E1: 订单PO.NO | F1: 客PO.NO | G1: ITEM NO | H1: 名称 | I1: 数量 | J1: 装箱数 | K1: 总箱数 | L1: 计划PO出货期 | M1: 计划验货期 | N1: 第三方 验货期 | O1: 验货结果 | P1: 船期SO （截仓时间） | Q1: 箱唛资料 提供时间 | R1: 箱唛打稿 完成时间 | S1: 箱唛打稿 确认时间 | T1: 客贴纸档案 提供时间 | U1: 包装资料是否提供 | V1: 包装档案 版本 | W1: 布标版本 | X1: 系统货号 | Y1: 是否翻单 | Z1: 是否寄出签办 | AA1: 客供物料 | AB1: 布标日期码 | AC1: 产品、包装 日期码 | AD1: 备注 | AE1: 单价USD | AF1: 总金额USD | AG1: 总金额HK$ | AH1: 是否入系统 | AI1: 下单明细 | AJ1: 送回数量 | AK1: 欠数 | AL1: 贴纸 | AM1: 湖南回复完成时间 | AN1: 询单备料情况
X2: {=INDEX(系统货号!C:C,MATCH(1,(系统货号!A:A=G2)*(系统货号!B:B=V2),0))} -> 0
X3: {=INDEX(系统货号!C:C,MATCH(1,(系统货号!A:A=G3)*(系统货号!B:B=V3),0))} -> 0
X4: {=INDEX(系统货号!C:C,MATCH(1,(系统货号!A:A=G4)*(系统货号!B:B=V4),0))} -> 0
X5: {=INDEX(系统货号!C:C,MATCH(1,(系统货号!A:A=G5)*(系统货号!B:B=V5),0))} -> 0
X6: {=INDEX(系统货号!C:C,MATCH(1,(系统货号!A:A=G6)*(系统货号!B:B=V6),0))} -> 0
I7: =SUM(I2:I6) -> 0 | X7: {=INDEX(系统货号!C:C,MATCH(1,(系统货号!A:A=G7)*(系统货号!B:B=V7),0))} -> 0 | AE7: =SUM(AE2:AE6) -> 0 | AF7: =SUM(AF2:AF6) -> 0 | AG7: =SUM(AG2:AG6) -> 0

Sheet 已走货
A1: 接单日期 | B1: 国家 | C1: 客跟单 | D1: 客户名称 （第三方客名） | E1: 订单PO.NO | F1: 客PO.NO | G1: ITEM NO | H1: 名称 | I1: 数量 | J1: 装箱数 | K1: 总箱数 | L1: 计划PO出货期 | M1: 计划验货期 | N1: 第三方 验货期 | O1: 验货结果 | P1: 船期SO （截仓时间） | Q1: 箱唛资料 提供时间 | R1: 箱唛打稿 完成时间 | S1: 箱唛打稿 确认时间 | T1: 客贴纸档案 提供时间 | U1: 按资料提供时间预计完成时间 | V1: 包装资料是否提供 | W1: 包装档案 版本 | X1: 布标版本 | Y1: 系统货号 | Z1: 是否寄出签办 | AA1: 客供物料 | AB1: 布标日期码 | AC1: 产品、包装 日期码 | AD1: 备注 | AE1: 单价USD | AF1: 总金额USD | AG1: 总金额HK$ | AH1: 是否入系统 | AI1: 下单明细 | AJ1: 送回数量 | AK1: 欠数 | AL1: 贴纸 | AM1: 湖南回复完成时间 | AN1: 询单备料情况 | AO1: 发票号 | AP1: 发票日期 | AQ1: 出货日期
A2: 45954 | B2: 美国 | C2: Kenix Lin | D2: Wal-Mart Inc. USA | E2: THT1430 | F2: 950881599 | G2: CZ021D1 | H2: 按压发声公仔（兔） | I2: 7656 | J2: 6 | K2: =I2/J2 -> 1276 | L2: 46008 | M2: 46008 | P2: 46027 | V2: WM客版 （印尼） | W2: WM客版布标 （印尼） | X2: {=INDEX(系统货号!C:C,MATCH(1,(系统货号!A:A=G2)*(系统货号!B:B=V2),0))} -> CZ021D1-WM客版（印尼） | AB2: 09/25 | AC2: 09/25 | AD2: 标准CDU+客版吊牌（WM印尼版）+客布标（WM印尼版）+RFID产品贴纸+AD外箱贴纸+日期码格式：09/25+客验货 | AE2: 3.77 | AF2: =I2*AE2 -> 28863.12 | AG2: =AF2*7.75 -> 223689.18 | AO2: FE61268 | AP2: 46027 | AQ2: 46027
A3: 45954 | B3: 美国 | C3: Kenix Lin | D3: Wal-Mart Inc. USA | E3: THT1430 | F3: 950881599 | G3: CZ021D2 | H3: 按压发声公仔（鸭） | I3: 3828 | J3: 6 | K3: =I3/J3 -> 638 | L3: 46008 | M3: 46008 | P3: 46027 | V3: WM客版 （印尼） | W3: WM客版布标 （印尼） | X3: {=INDEX(系统货号!C:C,MATCH(1,(系统货号!A:A=G3)*(系统货号!B:B=V3),0))} -> CZ021D2-WM客版（印尼） | AB3: 09/25 | AC3: 09/25 | AD3: 标准CDU+客版吊牌（WM印尼版）+客布标（WM印尼版）+RFID产品贴纸+AD外箱贴纸+日期码格式：09/25+客验货 | AE3: 3.77 | AF3: =I3*AE3 -> 14431.56 | AG3: =AF3*7.75 -> 111844.59 | AO3: FE61268 | AP3: 46027 | AQ3: 46027
A4: 45954 | B4: 美国 | C4: Kenix Lin | D4: Wal-Mart Inc. USA | E4: THT1430 | F4: 950881599 | G4: CZ021D3 | H4: 按压发声公仔（牛） | I4: 1914 | J4: 6 | K4: =I4/J4 -> 319 | L4: 46008 | M4: 46008 | P4: 46027 | V4: WM客版 （印尼） | W4: WM客版布标 （印尼） | X4: {=INDEX(系统货号!C:C,MATCH(1,(系统货号!A:A=G4)*(系统货号!B:B=V4),0))} -> CZ021D3-WM客版（印尼） | AB4: 09/25 | AC4: 09/25 | AD4: 标准CDU+客版吊牌（WM印尼版）+客布标（WM印尼版）+RFID产品贴纸+AD外箱贴纸+日期码格式：09/25+客验货 | AE4: 3.77 | AF4: =I4*AE4 -> 7215.78 | AG4: =AF4*7.75 -> 55922.295 | AO4: FE61268 | AP4: 46027 | AQ4: 46027
A5: 45954 | B5: 美国 | C5: Kenix Lin | D5: Wal-Mart Inc. USA | E5: THT1430 | F5: 950881599 | G5: CZ021D4 | H5: 按压发声公仔（羊） | I5: 1914 | J5: 6 | K5: =I5/J5 -> 319 | L5: 46008 | M5: 46008 | P5: 46027 | V5: WM客版 （印尼） | W5: WM客版布标 （印尼） | X5: {=INDEX(系统货号!C:C,MATCH(1,(系统货号!A:A=G5)*(系统货号!B:B=V5),0))} -> CZ021D4-WM客版（印尼） | AB5: 09/25 | AC5: 09/25 | AD5: 标准CDU+客版吊牌（WM印尼版）+客布标（WM印尼版）+RFID产品贴纸+AD外箱贴纸+日期码格式：09/25+客验货 | AE5: 3.77 | AF5: =I5*AE5 -> 7215.78 | AG5: =AF5*7.75 -> 55922.295 | AO5: FE61268 | AP5: 46027 | AQ5: 46027
A6: 45960 | B6: 丹麦 | C6: Kenix Lin | D6: LINIEX APS | E6: THT1435 | G6: BS064D1 | H6: MINI手提包系列 | I6: 7008 | J6: 12 | K6: =I6/J6 -> 584 | L6: 46014 | M6: 46014 | N6: 12-23客验货 | P6: 46027 | Q6: 45980 | R6: 45982 | S6: 45982 | T6: 与之前THT1214订单相同 | U6: 是 | V6: 标准包装 | W6: 无 | X6: {=INDEX(系统货号!C:C,MATCH(1,(系统货号!A:A=G6)*(系统货号!B:B=V6),0))} -> BS064D1 | Y6: 包装跟之前THT1214订单相同 | AB6: 无 | AC6: 2750-1225 | AD6: 标准吊牌+标准说明书+标准传单+客版贴纸+标准CDU+客验货 | AE6: 1.38 | AF6: =I6*AE6 -> 9671.04 | AG6: =AF6*7.75 -> 74950.56 | AH6: 45968 | AO6: FE61269 | AP6: 46028 | AQ6: 46027
A7: 45960 | B7: 丹麦 | C7: Kenix Lin | D7: LINIEX APS | E7: THT1435 | G7: BS065D6 | H7: 手提包狗系列 | I7: 2004 | J7: 6 | K7: =I7/J7 -> 334 | L7: 46014 | M7: 46014 | N7: 12-23客验货 | P7: 46027 | Q7: 45980 | R7: 45982 | S7: 45982 | T7: 与之前THT1316订单相同 | U7: 是 | V7: 标准包装 | W7: 标准布标 | X7: {=INDEX(系统货号!C:C,MATCH(1,(系统货号!A:A=G7)*(系统货号!B:B=V7),0))} -> BS065D6 | Y7: 包装跟之前THT1214订单相同 | AB7: 2750-1225 | AC7: 2750-1225 | AD7: 标准布标+标准收缩膜+标准说明书+标准传单+客版贴纸+标准CDU+客验货 | AE7: 2.969 | AF7: =I7*AE7 -> 5949.876 | AG7: =AF7*7.75 -> 46111.539 | AH7: 45968 | AI7: 系统出单 | AJ7: =1578+408+18 -> 2004 | AK7: =AJ7-I7 -> 0 | AL7: OK | AO7: FE61269 | AP7: 46028 | AQ7: 46027
A8: 45960 | B8: 丹麦 | C8: Kenix Lin | D8: LINIEX APS | E8: THT1435 | G8: BS074D6 | H8: 独角兽手提包 | I8: 3198 | J8: 6 | K8: =I8/J8 -> 533 | L8: 46014 | M8: 46014 | N8: 12-23客验货 | P8: 46027 | Q8: 45980 | R8: 45982 | S8: 45982 | T8: 45980 | U8: 是 | V8: 标准包装 | W8: 无 | X8: {=INDEX(系统货号!C:C,MATCH(1,(系统货号!A:A=G8)*(系统货号!B:B=V8),0))} -> BS074D6 | Y8: 否 | AB8: 无 | AC8: 2750-1225 | AD8: 标准收缩膜+标准说明书+标准传单+标准CDU+指甲油贴纸+收缩膜贴纸（贴纸日期码：171125）+客验货+质量保证样品2套CDU | AE8: 2.993 | AF8: =I8*AE8 -> 9571.614 | AG8: =AF8*7.75 -> 74180.008 | AH8: 45968 | AI8: 系统出单 | AJ8: =3036+162 -> 3198 | AK8: =AJ8-I8 -> 0 | AL8: OK | AO8: FE61269 | AP8: 46028 | AQ8: 46027
A9: 45960 | B9: 丹麦 | C9: Kenix Lin | D9: LINIEX APS | E9: THT1435 | G9: BS067D1 | H9: 手提包猫系列 | I9: 2400 | J9: 6 | K9: =I9/J9 -> 400 | L9: 46014 | M9: 46014 | N9: 12-23客验货 | P9: 46027 | Q9: 45980 | R9: 45982 | S9: 45982 | T9: 与之前THT1316订单相同 | U9: 是 | V9: 标准包装 | W9: 标准布标 | X9: {=INDEX(系统货号!C:C,MATCH(1,(系统货号!A:A=G9)*(系统货号!B:B=V9),0))} -> BS067D1 | Y9: 包装跟之前THT1214订单相同 | AB9: 2750-1225 | AC9: 2750-1225 | AD9: 标准布标+标准收缩膜+标准说明书+标准传单+客版贴纸+标准CDU+客验货 | AE9: 2.971 | AF9: =I9*AE9 -> 7130.4 | AG9: =AF9*7.75 -> 55260.6 | AH9: 45968 | AI9: 系统出单 | AJ9: =2244+132+24 -> 2400 | AK9: =AJ9-I9 -> 0 | AL9: OK | AO9: FE61269 | AP9: 46028 | AQ9: 46027
A10: 45966 | B10: 葡萄牙 | C10: Kenix Lin | D10: CREATIVE TOYS (PORTUGAL) | E10: THT1436A | G10: BS068D12 | H10: MINI猫+狗手提包系列 | I10: 14004 | J10: 12 | K10: =I10/J10 -> 1167 | L10: 46021 | M10: 46021 | P10: 1/2-1/5 | Q10: 45982 | R10: 45994 | S10: 45994 | T10: 45982 | U10: 是 | V10: 葡萄牙客版 | W10: 无 | X10: {=INDEX(系统货号!C:C,MATCH(1,(系统货号!A:A=G10)*(系统货号!B:B=V10),0))} -> BS068D12-葡萄牙客版 | Y10: 否 | AB10: 无 | AC10: 251209 HS | AD10: 客版吊牌+客版传单+客版CDU+唇彩贴纸（贴纸日期码：171125） | AE10: 1.469 | AF10: =I10*AE10 -> 20571.876 | AG10: =AF10*7.75 -> 159432.04 | AH10: 45974 | AO10: FE61270 | AP10: 46028 | AQ10: 46027
A11: 45966 | B11: 葡萄牙 | C11: Kenix Lin | D11: CREATIVE TOYS (PORTUGAL) | E11: THT1436A | G11: BS074D6 | H11: 独角兽手提包 | I11: 6000 | J11: 6 | K11: =I11/J11 -> 1000 | L11: 46021 | M11: 46021 | P11: 1/2-1/5 | Q11: 45982 | R11: 45994 | S11: 45994 | T11: 45982 | U11: 是 | V11: 葡萄牙客版 | W11: 无 | X11: {=INDEX(系统货号!C:C,MATCH(1,(系统货号!A:A=G11)*(系统货号!B:B=V11),0))} -> BS074D6-葡萄牙客版 | Y11: 否 | AB11: 无 | AC11: 251209 HS | AD11: 客版收缩膜（已提供）+客版传单+客版CDU（收缩膜、传单按实单数量采购）+指甲油贴纸+收缩膜贴纸（贴纸日期码：171125） | AE11: 2.942 | AF11: =I11*AE11 -> 17652 | AG11: =AF11*7.75 -> 136803 | AH11: 45971 | AI11: 系统出单 | AO11: FE61270 | AP11: 46028 | AQ11: 46027
A12: 45966 | B12: 葡萄牙 | C12: Kenix Lin | D12: CREATIVE TOYS (PORTUGAL) | E12: THT1436A | G12: CZ006D6 | H12: 按压发声公仔（6款混装） | I12: 4002 | J12: 6 | K12: =I12/J12 -> 667 | L12: 46021 | M12: 46021 | P12: 1/2-1/5 | Q12: 45982 | R12: 45994 | S12: 45994 | T12: 45982 | U12: 是 | V12: 葡萄牙客版 | W12: 客版布标 | X12: {=INDEX(系统货号!C:C,MATCH(1,(系统货号!A:A=G12)*(系统货号!B:B=V12),0))} -> CZ006D6-葡萄牙客版 | Y12: 否 | AB12: 251209 HS | AC12: 251209 HS | AD12: 客版吊牌+标准CDU+客版布标（已提供）（吊牌按实单数量采购） | AE12: 3.855 | AF12: =I12*AE12 -> 15427.71 | AG12: =AF12*7.75 -> 119564.75 | AH12: 45971 | AI12: 系统出单 | AJ12: 4002 | AK12: =AJ12-I12 -> 0 | AO12: FE61270 | AP12: 46028 | AQ12: 46027
A13: 45954 | B13: 美国 | C13: Kenix Lin | D13: Wal-Mart Inc. USA | E13: THT1433 | F13: 950881614 | G13: CZ021D1 | H13: 按压发声公仔（兔） | I13: 7968 | J13: 6 | K13: =I13/J13 -> 1328 | L13: 46008 | M13: 46008 | P13: 46034 | V13: WM客版 （印尼） | W13: WM客版布标 （印尼） | X13: {=INDEX(系统货号!C:C,MATCH(1,(系统货号!A:A=G13)*(系统货号!B:B=V13),0))} -> CZ021D1-WM客版（印尼） | AB13: 09/25 | AC13: 09/25 | AD13: 标准CDU+客版吊牌（WM印尼版）+客布标（WM印尼版）+RFID产品贴纸+AD外箱贴纸+日期码格式：09/25+客验货 | AE13: 3.77 | AF13: =I13*AE13 -> 30039.36 | AG13: =AF13*7.75 -> 232805.04 | AO13: FE61271 | AP13: 46034 | AQ13: 46031
A14: 45954 | B14: 美国 | C14: Kenix Lin | D14: Wal-Mart Inc. USA | E14: THT1433 | F14: 950881614 | G14: CZ021D2 | H14: 按压发声公仔（鸭） | I14: 3984 | J14: 6 | K14: =I14/J14 -> 664 | L14: 46008 | M14: 46008 | P14: 46034 | V14: WM客版 （印尼） | W14: WM客版布标 （印尼） | X14: {=INDEX(系统货号!C:C,MATCH(1,(系统货号!A:A=G14)*(系统货号!B:B=V14),0))} -> CZ021D2-WM客版（印尼） | AB14: 09/25 | AC14: 09/25 | AD14: 标准CDU+客版吊牌（WM印尼版）+客布标（WM印尼版）+RFID产品贴纸+AD外箱贴纸+日期码格式：09/25+客验货 | AE14: 3.77 | AF14: =I14*AE14 -> 15019.68 | AG14: =AF14*7.75 -> 116402.52 | AO14: FE61271 | AP14: 46034 | AQ14: 46031
A15: 45954 | B15: 美国 | C15: Kenix Lin | D15: Wal-Mart Inc. USA | E15: THT1433 | F15: 950881614 | G15: CZ021D3 | H15: 按压发声公仔（牛） | I15: 1992 | J15: 6 | K15: =I15/J15 -> 332 | L15: 46008 | M15: 46008 | P15: 46034 | V15: WM客版 （印尼） | W15: WM客版布标 （印尼） | X15: {=INDEX(系统货号!C:C,MATCH(1,(系统货号!A:A=G15)*(系统货号!B:B=V15),0))} -> CZ021D3-WM客版（印尼） | AB15: 09/25 | AC15: 09/25 | AD15: 标准CDU+客版吊牌（WM印尼版）+客布标（WM印尼版）+RFID产品贴纸+AD外箱贴纸+日期码格式：09/25+客验货 | AE15: 3.77 | AF15: =I15*AE15 -> 7509.84 | AG15: =AF15*7.75 -> 58201.26 | AO15: FE61271 | AP15: 46034 | AQ15: 46031
A16: 45954 | B16: 美国 | C16: Kenix Lin | D16: Wal-Mart Inc. USA | E16: THT1433 | F16: 950881614 | G16: CZ021D4 | H16: 按压发声公仔（羊） | I16: 1992 | J16: 6 | K16: =I16/J16 -> 332 | L16: 46008 | M16: 46008 | P16: 46034 | V16: WM客版 （印尼） | W16: WM客版布标 （印尼） | X16: {=INDEX(系统货号!C:C,MATCH(1,(系统货号!A:A=G16)*(系统货号!B:B=V16),0))} -> CZ021D4-WM客版（印尼） | AB16: 09/25 | AC16: 09/25 | AD16: 标准CDU+客版吊牌（WM印尼版）+客布标（WM印尼版）+RFID产品贴纸+AD外箱贴纸+日期码格式：09/25+客验货 | AE16: 3.77 | AF16: =I16*AE16 -> 7509.84 | AG16: =AF16*7.75 -> 58201.26 | AO16: FE61271 | AP16: 46034 | AQ16: 46031
A17: 45954 | B17: 美国 | C17: Kenix Lin | D17: Wal-Mart Inc. USA | E17: THT1434 | F17: 950881612 | G17: CZ021D1 | H17: 按压发声公仔（兔） | I17: 5736 | J17: 6 | K17: =I17/J17 -> 956 | L17: 46008 | M17: 46008 | P17: 46035 | V17: WM客版 （印尼） | W17: WM客版布标 （印尼） | X17: {=INDEX(系统货号!C:C,MATCH(1,(系统货号!A:A=G17)*(系统货号!B:B=V17),0))} -> CZ021D1-WM客版（印尼） | AB17: 09/25 | AC17: 09/25 | AD17: 标准CDU+客版吊牌（WM印尼版）+客布标（WM印尼版）+RFID产品贴纸+AD外箱贴纸+日期码格式：09/25+客验货 | AE17: 3.77 | AF17: =I17*AE17 -> 21624.72 | AG17: =AF17*7.75 -> 167591.58 | AO17: FE61272 | AP17: 46034 | AQ17: 46034
A18: 45954 | B18: 美国 | C18: Kenix Lin | D18: Wal-Mart Inc. USA | E18: THT1434 | F18: 950881612 | G18: CZ021D2 | H18: 按压发声公仔（鸭） | I18: 2868 | J18: 6 | K18: =I18/J18 -> 478 | L18: 46008 | M18: 46008 | P18: 46035 | V18: WM客版 （印尼） | W18: WM客版布标 （印尼） | X18: {=INDEX(系统货号!C:C,MATCH(1,(系统货号!A:A=G18)*(系统货号!B:B=V18),0))} -> CZ021D2-WM客版（印尼） | AB18: 09/25 | AC18: 09/25 | AD18: 标准CDU+客版吊牌（WM印尼版）+客布标（WM印尼版）+RFID产品贴纸+AD外箱贴纸+日期码格式：09/25+客验货 | AE18: 3.77 | AF18: =I18*AE18 -> 10812.36 | AG18: =AF18*7.75 -> 83795.79 | AO18: FE61272 | AP18: 46034 | AQ18: 46034
A19: 45954 | B19: 美国 | C19: Kenix Lin | D19: Wal-Mart Inc. USA | E19: THT1434 | F19: 950881612 | G19: CZ021D3 | H19: 按压发声公仔（牛） | I19: 1434 | J19: 6 | K19: =I19/J19 -> 239 | L19: 46008 | M19: 46008 | P19: 46035 | V19: WM客版 （印尼） | W19: WM客版布标 （印尼） | X19: {=INDEX(系统货号!C:C,MATCH(1,(系统货号!A:A=G19)*(系统货号!B:B=V19),0))} -> CZ021D3-WM客版（印尼） | AB19: 09/25 | AC19: 09/25 | AD19: 标准CDU+客版吊牌（WM印尼版）+客布标（WM印尼版）+RFID产品贴纸+AD外箱贴纸+日期码格式：09/25+客验货 | AE19: 3.77 | AF19: =I19*AE19 -> 5406.18 | AG19: =AF19*7.75 -> 41897.895 | AO19: FE61272 | AP19: 46034 | AQ19: 46034
A20: 45954 | B20: 美国 | C20: Kenix Lin | D20: Wal-Mart Inc. USA | E20: THT1434 | F20: 950881612 | G20: CZ021D4 | H20: 按压发声公仔（羊） | I20: 1434 | J20: 6 | K20: =I20/J20 -> 239 | L20: 46008 | M20: 46008 | P20: 46035 | V20: WM客版 （印尼） | W20: WM客版布标 （印尼） | X20: {=INDEX(系统货号!C:C,MATCH(1,(系统货号!A:A=G20)*(系统货号!B:B=V20),0))} -> CZ021D4-WM客版（印尼） | AB20: 09/25 | AC20: 09/25 | AD20: 标准CDU+客版吊牌（WM印尼版）+客布标（WM印尼版）+RFID产品贴纸+AD外箱贴纸+日期码格式：09/25+客验货 | AE20: 3.77 | AF20: =I20*AE20 -> 5406.18 | AG20: =AF20*7.75 -> 41897.895 | AO20: FE61272 | AP20: 46034 | AQ20: 46034
A21: 46015 | B21: 澳大利亚 | C21: Kenix Lin | D21: KMART (AUS / NZ) | E21: THT1478 | G21: PF001A1 | H21: 马桶遥控车 | I21: 712 | J21: 4 | K21: =I21/J21 -> 178 | L21: 46045 | M21: 46045 | N21: 46048 | P21: 1/28-2/2 | Q21: 46015 | R21: 46016 | S21: 46017 | T21: 46015 | U21: 是 | V21: KMART客版 | W21: 无 | X21: {=INDEX(系统货号!C:C,MATCH(1,(系统货号!A:A=G21)*(系统货号!B:B=V21),0))} -> PF001A1-KMART | Y21: 包装跟之前的KMART订单，包装档案如有日期码需修改，除SSCC贴纸外 | AB21: 无 | AC21: 30/25 | AD21: 客版包装+客版说明书+SSCC外箱贴纸+客版日期码30/25+客验货+所有Kmart 订单需要用60MM宽的，“Anko” logo 胶纸封箱； | AE21: 10.262 | AF21: =I21*AE21 -> 7306.544 | AG21: =AF21*7.75 -> 56625.716 | AH21: 46020 | AI21: 系统出单 | AJ21: =648+64 -> 712 | AK21: =AJ21-I21 -> 0 | AO21: FE61273 | AP21: 46052 | AQ21: 46050
A22: 46015 | B22: 新西兰 | C22: Kenix Lin | D22: KMART (AUS / NZ) | E22: THT1479 | G22: PF001A1 | H22: 马桶遥控车 | I22: 80 | J22: 4 | K22: =I22/J22 -> 20 | L22: 46045 | M22: 46045 | N22: 46048 | P22: 1/28-2/2 | Q22: 46015 | R22: 46016 | S22: 46017 | T22: 46015 | U22: 是 | V22: KMART客版 | W22: 无 | X22: {=INDEX(系统货号!C:C,MATCH(1,(系统货号!A:A=G22)*(系统货号!B:B=V22),0))} -> PF001A1-KMART | Y22: 包装跟之前的KMART订单，包装档案如有日期码需修改，除SSCC贴纸外 | AB22: 无 | AC22: 30/25 | AD22: 客版包装+客版说明书+SSCC外箱贴纸+客版日期码30/25+客验货+所有Kmart 订单需要用60MM宽的，“Anko” logo 胶纸封箱； | AE22: 10.262 | AF22: =I22*AE22 -> 820.96 | AG22: =AF22*7.75 -> 6362.44 | AH22: 46020 | AI22: 系统出单 | AJ22: 80 | AK22: =AJ22-I22 -> 0 | AO22: FE61274 | AP22: 46052 | AQ22: 46050
A23: 45968 | B23: 澳大利亚 | C23: Kenix Lin | D23: KMART (AUS / NZ) | E23: THT1450 | G23: MZ002D6 | H23: 鲨鱼实验室2 | I23: 1686 | J23: 6 | K23: =I23/J23 -> 281 | L23: 46044 | M23: 46044 | N23: 46048 | Q23: 46010 | R23: 46010 | S23: 46017 | T23: 46010 | U23: 是 | V23: 标准KMART包装 | W23: 无 | X23: {=INDEX(系统货号!C:C,MATCH(1,(系统货号!A:A=G23)*(系统货号!B:B=V23),0))} -> MZ002D6-标准KMART版 | Y23: 包装跟之前的KMART订单，除SSCC贴纸外 | AB23: 45/25 | AC23: 45/25 | AD23: 标准包装+标准说明书+Kmart客版条码贴纸+标准CDU+SSCC外箱贴纸+客版日期码45/25+客验货+所有Kmart 订单需要用60MM宽的，“Anko” logo 胶纸封箱； | AE23: 3.958 | AF23: =I23*AE23 -> 6673.188 | AG23: =AF23*7.75 -> 51717.207 | AH23: 45968 | AO23: FE61275 | AP23: 46058 | AQ23: 46057
A24: 45968 | B24: 新西兰 | C24: Kenix Lin | D24: KMART (AUS / NZ) | E24: THT1451 | G24: MZ002D6 | H24: 鲨鱼实验室2 | I24: 114 | J24: 6 | K24: =I24/J24 -> 19 | L24: 46044 | M24: 46044 | N24: 46048 | Q24: 46010 | R24: 46010 | S24: 46017 | T24: 46010 | U24: 是 | V24: 标准KMART包装 | W24: 无 | X24: {=INDEX(系统货号!C:C,MATCH(1,(系统货号!A:A=G24)*(系统货号!B:B=V24),0))} -> MZ002D6-标准KMART版 | Y24: 包装跟之前的KMART订单，除SSCC贴纸外 | AB24: 45/25 | AC24: 45/25 | AD24: 标准包装+标准说明书+Kmart客版条码贴纸+标准CDU+SSCC外箱贴纸+客版日期码45/25+客验货+所有Kmart 订单需要用60MM宽的，“Anko” logo 胶纸封箱； | AE24: 3.958 | AF24: =I24*AE24 -> 451.212 | AG24: =AF24*7.75 -> 3496.893 | AH24: 45968 | AO24: FE61276 | AP24: 46058 | AQ24: 46057
A25: 46008 | B25: 克罗地亚 | C25: Kenix Lin | D25: Talent Show d.o.o. (Croatia) | E25: THT1471A | G25: ZC006A1 | H25: 冰杯 | I25: 3948 | J25: 6 | K25: =I25/J25 -> 658 | L25: 46045 | M25: 46045 | O25: PASS | P25: 46058 | Q25: 46008 | R25: 46009 | S25: 46010 | T25: 46386 | U25: 是 | V25: 克罗地亚客版 | W25: 无 | X25: {=INDEX(系统货号!C:C,MATCH(1,(系统货号!A:A=G25)*(系统货号!B:B=V25),0))} -> ZC006A1-克罗地亚客版 | Y25: 否 | AB25: 无 | AC25: 260114 HS | AD25: 新版标准彩盒+客版贴纸+客版说明书+新冰粒 | AE25: 1.15 | AF25: =I25*AE25 -> 4540.2 | AG25: =AF25*7.75 -> 35186.55 | AH25: 46008 | AO25: FE61277 | AP25: 46058 | AQ25: 46057
A26: 45994 | B26: 加拿大 | C26: Kenix Lin | D26: GROUPE RICOCHET INC. (CANADA) | E26: THT1452A | G26: CZ018D6 | H26: 按压发声公仔（一代牙齿怪） | I26: 5004 | J26: 6 | K26: =I26/J26 -> 834 | L26: 46052 | M26: 46052 | N26: 客要求提供自检报告时间1-28 | O26: PASS | P26: 46059 | Q26: 46008 | R26: 46009 | S26: 46010 | T26: 46008 | U26: 是 | V26: 加拿大客版 | W26: 客版布标 | X26: {=INDEX(系统货号!C:C,MATCH(1,(系统货号!A:A=G26)*(系统货号!B:B=V26),0))} -> CZ018D6-加拿大客版 | Y26: 否 | AB26: C251024 1450 | AC26: C251024 1450 | AD26: 客版布标+客版吊牌+客版CDU+客日期码 | AE26: 3.905 | AF26: =I26*AE26 -> 19540.62 | AG26: =AF26*7.75 -> 151439.8 | AH26: 46000 | AI26: 系统出单 | AJ26: =2280+2706 -> 4986 | AK26: =AJ26-I26 -> -18 | AO26: FE61278 | AP26: 46059 | AQ26: 46057
A27: 45974 | B27: 以色列 | C27: Kenix Lin | D27: TOYRRIFIC (ISRAEL) | E27: THT1453 | G27: BS082D6 | H27: 二代独角兽手提包 | I27: 4110 | J27: 6 | K27: =I27/J27 -> 685 | L27: 46053 | M27: 46053 | P27: 46059 | Q27: 46008 | R27: 46010 | S27: 46387 | T27: 46001 | U27: 是 | V27: 以色列客版 | W27: 标准布标 | X27: {=INDEX(系统货号!C:C,MATCH(1,(系统货号!A:A=G27)*(系统货号!B:B=V27),0))} -> BS082D6-以色列客版 | Y27: 否 | AB27: 260112 HS | AC27: 260112 HS | AD27: 标准包装+标准布标+客版说明书+客贴纸 | AE27: 3.283 | AF27: =I27*AE27 -> 13493.13 | AG27: =AF27*7.75 -> 104571.76 | AH27: 45979 | AI27: 系统出单 | AJ27: =3594+516 -> 4110 | AK27: =AJ27-I27 -> 0 | AL27: OK | AO27: FE61279 | AP27: 46059 | AQ27: 46059
A28: 45974 | B28: 以色列 | C28: Kenix Lin | D28: TOYRRIFIC (ISRAEL) | E28: THT1453 | G28: BS065D6 | H28: 手提包狗系列 | I28: 4110 | J28: 6 | K28: =I28/J28 -> 685 | L28: 46053 | M28: 46053 | P28: 46059 | Q28: 46008 | R28: 46010 | S28: 46387 | T28: 46001 | U28: 是 | V28: 以色列客版 | W28: 标准布标 | X28: {=INDEX(系统货号!C:C,MATCH(1,(系统货号!A:A=G28)*(系统货号!B:B=V28),0))} -> BS065D6-以色列客版 | Y28: 否 | AB28: 260112 HS | AC28: 260112 HS | AD28: 标准包装+标准布标+客版说明书+客贴纸 | AE28: 2.969 | AF28: =I28*AE28 -> 12202.59 | AG28: =AF28*7.75 -> 94570.072 | AH28: 45979 | AI28: 系统出单 | AJ28: =4092+18 -> 4110 | AK28: =AJ28-I28 -> 0 | AL28: OK | AO28: FE61279 | AP28: 46059 | AQ28: 46059
A29: 45983 | B29: 德国 | C29: Kenix Lin | D29: ROFU (GERMANY) | E29: THT1454 | G29: CZ031E1 | H29: 按压发声公仔 （336个公仔混装展示柜） | I29: 120 | J29: 1 | K29: =I29/J29 -> 120 | L29: 46053 | M29: 46053 | N29: 复客2-6提供自检报告 | P29: 46062 | Q29: 46008 | R29: 46013 | S29: 46386 | T29: 45988 | U29: 是 | V29: 德国客版 | W29: 客版布标 | X29: {=INDEX(系统货号!C:C,MATCH(1,(系统货号!A:A=G29)*(系统货号!B:B=V29),0))} -> CZ031E1 | Y29: 否 | AB29: 250975 | AC29: 250975 | AD29: 客版布标+客版吊牌+客版贴纸+标准CDU+标准展示柜+客日期码 | AE29: 1389.696 | AF29: =I29*AE29 -> 166763.52 | AG29: =AF29*7.75 -> 1292417.3 | AH29: 45988 | AI29: 系统出单 | AJ29: =7776+11136+360+4632 -> 23904 | AK29: =AJ29-I29*336 -> -16416 | AL29: OK | AO29: FE61281 | AP29: 46077 | AQ29: 46062
A30: 46006 | B30: 克罗地亚 | C30: Kenix Lin | D30: ORBICO D.O.O. (CROATIA) | E30: THT1469 | G30: BS064D1 | H30: MINI手提包系列 | I30: 4752 | J30: 12 | K30: =I30/J30 -> 396 | L30: 46056 | M30: 46056 | P30: 46062 | Q30: 46008 | R30: 46009 | S30: 46010 | T30: 46013 | U30: 是 | V30: 克罗地亚客版 | W30: 无 | X30: {=INDEX(系统货号!C:C,MATCH(1,(系统货号!A:A=G30)*(系统货号!B:B=V30),0))} -> BS064D1-克罗地亚客版 | Y30: 吊牌新档案、传单跟之前THT1211A订单相同 | AB30: 无 | AC30: 260122 HS | AD30: 客版吊牌+客版传单+标准CDU | AE30: 1.38 | AF30: =I30*AE30 -> 6557.76 | AG30: =AF30*7.75 -> 50822.64 | AH30: 46007 | AO30: FE61282 | AP30: 46077 | AQ30: 46063
A31: 46006 | B31: 克罗地亚 | C31: Kenix Lin | D31: ORBICO D.O.O. (CROATIA) | E31: THT1469 | G31: BS067D1 | H31: 手提包猫系列 | I31: 1020 | J31: 6 | K31: =I31/J31 -> 170 | L31: 46056 | M31: 46056 | P31: 46062 | Q31: 46008 | R31: 46009 | S31: 46010 | T31: 46013 | U31: 是 | V31: 克罗地亚客版 | W31: 客版布标 | X31: {=INDEX(系统货号!C:C,MATCH(1,(系统货号!A:A=G31)*(系统货号!B:B=V31),0))} -> BS067D1-克罗地亚客版 | Y31: 身份证卡跟之前THT1211A订单，客贴纸、说明书、布标新档案 | AB31: 260122 HS | AC31: 260122 HS | AD31: 标准收缩膜+客版贴纸+客版布标+客版说明书+客版身份证卡+标准CDU | AE31: 2.971 | AF31: =I31*AE31 -> 3030.42 | AG31: =AF31*7.75 -> 23485.755 | AH31: 46007 | AI31: 系统出单 | AJ31: 1020 | AK31: =AJ31-I31 -> 0 | AO31: FE61282 | AP31: 46077 | AQ31: 46063
A32: 46006 | B32: 克罗地亚 | C32: Kenix Lin | D32: ORBICO D.O.O. (CROATIA) | E32: THT1469 | G32: BS065D6 | H32: 手提包狗系列 | I32: 6360 | J32: 6 | K32: =I32/J32 -> 1060 | L32: 46056 | M32: 46056 | P32: 46062 | Q32: 46008 | R32: 46009 | S32: 46010 | T32: 46013 | U32: 是 | V32: 克罗地亚客版 | W32: 客版布标 | X32: {=INDEX(系统货号!C:C,MATCH(1,(系统货号!A:A=G32)*(系统货号!B:B=V32),0))} -> BS065D6-克罗地亚客版 | Y32: 身份证卡、说明书跟之前THT1288订单相同，客贴纸新档案 | AB32: 260122 HS | AC32: 260122 HS | AD32: 标准收缩膜+客版贴纸+客版布标+客版说明书+客版身份证卡+标准CDU | AE32: 2.969 | AF32: =I32*AE32 -> 18882.84 | AG32: =AF32*7.75 -> 146342.01 | AH32: 46007 | AI32: 系统出单 | AJ32: =5910+450 -> 6360 | AK32: =AJ32-I32 -> 0 | AO32: FE61282 | AP32: 46077 | AQ32: 46063
A33: 45988 | B33: 新西兰 | C33: Kenix Lin | D33: KMART (AUS / NZ) | E33: THT1456 | G33: MZ003D1 | H33: 恐龙实验室2 | I33: 498 | J33: 6 | K33: 83 | L33: 46059 | M33: 46059 | N33: 46059 | P33: 3/4~3/9 | Q33: 46010 | R33: 46010 | S33: 46013 | T33: 46010 | U33: 是 | V33: 标准KMART包装 | W33: 无 | X33: MZ003D1-标准KMART包装 | Y33: 包装跟之前的KMART订单，除SSCC贴纸外 | AB33: 无 | AC33: 04/26 | AD33: 标准收缩膜+标准说明书+Kmart客翻单条码贴纸+标准CDU+SSCC外箱贴纸+客版日期码04/26+客验货+所有Kmart 订单需要用60MM宽的，“Anko” logo 胶纸封箱； | AE33: 3.924 | AF33: 1954.152 | AG33: 15144.678 | AH33: 45994 | AO33: FE61283 | AP33: 46090 | AQ33: 46087
A34: 45993 | B34: 新西兰 | C34: Kenix Lin | D34: KMART (AUS / NZ) | E34: THT1464 | G34: PF001A1 | H34: 马桶遥控车 | I34: 68 | J34: 4 | K34: =I34/J34 -> 17 | L34: 46059 | M34: 46059 | N34: 2/6需做DD测试 | Q34: 46010 | R34: 46011 | S34: 46013 | T34: 46010 | U34: 是 | V34: KMART客版 | W34: 无 | X34: {=INDEX(系统货号!C:C,MATCH(1,(系统货号!A:A=G34)*(系统货号!B:B=V34),0))} -> PF001A1-KMART | Y34: 包装跟之前的KMART订单，包装档案如有日期码需修改，除SSCC贴纸外 | AB34: 无 | AC34: 05/26 | AD34: 客版包装+客版说明书+SSCC外箱贴纸+客版日期码05/26+客验货+所有Kmart 订单需要用60MM宽的，“Anko” logo 胶纸封箱； | AE34: 10.262 | AF34: =I34*AE34 -> 697.816 | AG34: =AF34*7.75 -> 5408.074 | AH34: 45994 | AI34: 系统出单 | AJ34: 湖南送回半成品-车间包装 | AO34: FE61284 | AP34: 46090 | AQ34: 46087
A35: 45993 | B35: 新西兰 | C35: Kenix Lin | D35: KMART (AUS / NZ) | E35: THT1464 | G35: MZ003D1 | H35: 恐龙实验室2 | I35: 36 | J35: 6 | K35: 6 | L35: 46059 | M35: 46059 | N35: 46059 | Q35: 46010 | R35: 46011 | S35: 46013 | T35: 46010 | U35: 是 | V35: 标准KMART包装 | W35: 无 | X35: MZ003D1-标准KMART包装 | Y35: 包装跟之前的KMART订单，除SSCC贴纸外 | AB35: 无 | AC35: 04/26 | AD35: 标准收缩膜+标准说明书+Kmart客翻单条码贴纸+标准CDU+SSCC外箱贴纸+客版日期码04/26+客验货+所有Kmart 订单需要用60MM宽的，“Anko” logo 胶纸封箱； | AE35: 3.924 | AF35: 141.264 | AG35: 1094.796 | AH35: 45994 | AO35: FE61284 | AP35: 46090 | AQ35: 46087
A36: 46008 | B36: 新西兰 | C36: Kenix Lin | D36: KMART (AUS / NZ) | E36: THT1474 | G36: BS065D6 | H36: 手提包狗系列 | I36: 276 | J36: 6 | K36: 46 | L36: 46059 | M36: 46059 | N36: 2/6需要DD测试抽办 | Q36: 46008 | R36: 46011 | S36: 46013 | T36: 46010 | U36: 是 | V36: KMART客版 | W36: 标准布标 | X36: BS065D1-KMART客版 | Y36: 包装跟之前的KMART订单，包装档案如有日期码需修改，除SSCC贴纸外 | AB36: 04/26 | AC36: 04/26 | AD36: 标准布标+客版收缩膜+客版传单+客版CDU+SSCC外箱贴纸+客版日期码（04/26）+客验货+所有Kmart 订单需要用60MM宽的，“Anko” logo 胶纸封箱； | AE36: 3.088 | AF36: 852.288 | AG36: 6605.232 | AH36: 46008 | AI36: 系统出单 | AJ36: 276 | AK36: 0 | AO36: FE61285 | AP36: 46090 | AQ36: 46087
