Workbook

Sheet 名称
A1: 货号 | B1: 名称 | C1: 系列 | D1: 装箱数
A2: 10727 | B2: 工具箱 | C2: ROB
A3: 10730 | B3: 6只公仔装 | C3: ROB
A4: 10740 | B4: 工具箱 | C4: ROB
A5: 10761 | B5: 瞭望台 | C5: ROB
A6: 11588 | B6: NERF标靶 | C6: NER
A7: 19852 | C7: ROB
A8: 97759 | B8: 皮卡丘 | C8: PKW
A9: 19820 (19821) | B9: 时尚女孩 | C9: ROB
A10: BLF0007 | B10: 麦克风 | C10: CMW
A11: CIF0001 | B11: 摇铃 | C11: CMW
A12: CMI0011 | B12: 农场屋 | C12: CMW
A13: CMI0013 | B13: 西瓜音乐箱 | C13: CMW
A14: CMI0029 | B14: 西瓜音乐箱(WM货号) | C14: CMW
A15: CMW0015 | B15: 校车巴士 | C15: CMW | D15: 4
A16: CMW0023 | B16: 搪胶鱼/乌龟混装 | C16: CMW
A17: CMW0029 | B17: 搪胶鱼 | C17: CMW | D17: 9
A18: CMW0031 | B18: 校车巴士 | C18: CMW
A19: CMW0035=CMW0169 | B19: 4只公仔装 | C19: CMW
A20: CMW0038 | B20: 拖车 | C20: CMW
A21: CMW0044 | B21: 拖车 | C21: CMW
A22: CMW0048 | B22: 盲盒 (二代) | C22: CMW
A23: CMW0048 (火车公仔) | B23: 火车公仔(旧结构) | C23: CMW
A24: CMW0048 (拖车公仔) | B24: 拖车公仔(旧结构) | C24: CMW
A25: CMW0048 (校车公仔) | B25: 校车公仔(旧结构) | C25: CMW
A26: CMW0054 | B26: 拖车 | C26: CMW
A27: CMW0080 | B27: 火车 | C27: CMW
A28: CMW0086 | B28: 搪胶鱼+乌龟 | C28: CMW
A29: CMW0108 | B29: 厨房 | C29: CMW
... A36: CMW0169 | B36: 4只公仔装 | C36: CMW
A37: CMW0170 | B37: 6只公仔装 | C37: CMW | D37: 6
A38: CMW0171 | B38: 盲盒装公仔 | C38: CMW
A39: CMW0174 | B39: 盲盒公仔三代 | C39: CMW
A40: CMW0182 | B40: 跳舞公仔 | C40: CMW | D40: 4
A41: CMW0201 | B41: 纸盒装公仔 | C41: CMW
A42: CMW0208 | B42: 4只公仔装(二代) | C42: CMW
A43: CMW0209 | B43: 4只公仔装 | C43: CMW
A44: CMW0212 | B44: 8只公仔装 (亚马逊货号) | C44: CMW
A45: CMW0252 | B45: JJ+渔夫公仔 | C45: CMW
A46: CMW0282 | B46: 俄语校车 | C46: CMW
...

Sheet CMW+NER+PKW接单
A1: 产品名称 | AD1: FNT1608-G/FNT1675-G | AG1: FNT1608-H | AJ1: FNT1608-I/FNT1608-K
A2: 接单期 | B2: 出货期 | C2: PO版本 | D2: 原PO | E2: 现PO | F2: 货号 | G2: 数量 | H2: 包装版本 | I2: 系列 | J2: CMW0015 | K2: CMW0029 | L2: CMW0170 | M2: CMW0182 | N2: CMW0298 | O2: CMW0352 | P2: FNT1612 | Q2: FNT1624 | R2: FNT1658 | S2: FNT1665 | T2: FNT1666 | U2: FNT1667 | V2: FNT1693 | W2: FNT1702 | X2: NER0156 | Y2: SNF0145 | Z2: SNF0181 | AA2: SNF0182 | AB2: SNF0220 | AC2: SNF0355 | AD2: FNT1611 | AE2: FNT1610 | AF2: FNT1609 | AG2: FNT1618 | AH2: FNT1619 | AI2: FNT1620 | AJ2: FNT1653 | AK2: FNT1654 | AL2: FNT1655 | AM2: FNT1657 | AN2: FNT1696 | AP2: 单价(USD) | AQ2: 金额USD | AR2: 金额HKD
A3: 44487 | B3: 44641 | C3: V1 | E3: JAZ068876 | F3: NER0156 | G3: =9000-300 -> 8700 | H3: 美文包装+美文说明书 | I3: =IFERROR(VLOOKUP(F3,名称!A:C,3,0),"") -> NER | J3: =IF(AND($F3=J$2,$G3>0),$G3,"") | K3: =IF(AND($F3=K$2,$G3>0),$G3,"") | L3: =IF(AND($F3=L$2,$G3>0),$G3,"") | M3: =IF(AND($F3=M$2,$G3>0),$G3,"") | N3: =IF(AND($F3=N$2,$G3>0),$G3,"") | O3: =IF(AND($F3=O$2,$G3>0),$G3,"") | P3: =IF(AND($F3=P$2,$G3>0),$G3,"") | Q3: =IF(AND($F3=Q$2,$G3>0),$G3,"") | ... AC3: =IF(AND($F3=AC$2,$G3>0),$G3,"") | AD3: =IF(AND($G3>0,$F3<>""),IF(OR($F3="FNT1608-G",$F3="FNT1675-G"),IF(OR(AD$2="FNT1611",AD$2="FNT1610",AD$2="FNT1609"),$G3/3,""),IF($F3=AD$2,$G3,"")),"") | AE3: =IF(AND($G3>0,$F3<>""),IF(OR($F3="FNT1608-G",$F3="FNT1675-G"),IF(OR(AE$2="FNT1611",AE$2="FNT1610",AE$2="FNT1609"),$G3/3,""),IF($F3=AE$2,$G3,"")),"") | AF3: =IF(AND($G3>0,$F3<>""),IF(OR($F3="FNT1608-G",$F3="FNT1675-G"),IF(OR(AF$2="FNT1611",AF$2="FNT1610",AF$2="FNT1609"),$G3/3,""),IF($F3=AF$2,$G3,"")),"") | AG3: =IF(AND($G3>0,$F3<>""),IF($F3="FNT1608-H",IF(OR(AG$2="FNT1618",AG$2="FNT1619",AG$2="FNT1620"),$G3/3,""),IF($F3=AG$2,$G3,"")),"") | AH3: =IF(AND($G3>0,$F3<>""),IF($F3="FNT1608-H",IF(OR(AH$2="FNT1618",AH$2="FNT1619",AH$2="FNT1620"),$G3/3,""),IF($F3=AH$2,$G3,"")),"") | AI3: =IF(AND($G3>0,$F3<>""),IF($F3="FNT1608-H",IF(OR(AI$2="FNT1618",AI$2="FNT1619",AI$2="FNT1620"),$G3/3,""),IF($F3=AI$2,$G3,"")),"") | AJ3: =IF(AND($G3>0,$F3<>""),IF($F3="FNT1608-I",IF(AJ$2="FNT1653",$G3*2/6,IF(AJ$2="FNT1654",$G3*1/6,IF(AJ$2="FNT1655",$G3*1/6,IF(AJ$2="FNT1657",$G3*2/6,"")))),IF($F3="FNT1608-K",IF(AJ$2="FNT1653",$G3*1/6,IF(AJ$2="FNT1654",$G3*2/6,IF(AJ$2="FNT1655",$G3*1/6,IF(AJ$2="FNT1657",$G3*2/6,"")))),IF($F3=AJ$2,$G3,""))),"") | AK3: =IF(AND($G3>0,$F3<>""),IF($F3="FNT1608-I",IF(AK$2="FNT1653",$G3*2/6,IF(AK$2="FNT1654",$G3*1/6,IF(AK$2="FNT1655",$G3*1/6,IF(AK$2="FNT1657",$G3*2/6,"")))),IF($F3="FNT1608-K",IF(AK$2="FNT1653",$G3*1/6,IF(AK$2="FNT1654",$G3*2/6,IF(AK$2="FNT1655",$G3*1/6,IF(AK$2="FNT1657",$G3*2/6,"")))),IF($F3=AK$2,$G3,""))),"") | AL3: =IF(AND($G3>0,$F3<>""),IF($F3="FNT1608-I",IF(AL$2="FNT1653",$G3*2/6,IF(AL$2="FNT1654",$G3*1/6,IF(AL$2="FNT1655",$G3*1/6,IF(AL$2="FNT1657",$G3*2/6,"")))),IF($F3="FNT1608-K",IF(AL$2="FNT1653",$G3*1/6,IF(AL$2="FNT1654",$G3*2/6,IF(AL$2="FNT1655",$G3*1/6,IF(AL$2="FNT1657",$G3*2/6,"")))),IF($F3=AL$2,$G3,""))),"") | AM3: =IF(AND($G3>0,$F3<>""),IF($F3="FNT1608-I",IF(AM$2="FNT1653",$G3*2/6,IF(AM$2="FNT1654",$G3*1/6,IF(AM$2="FNT1655",$G3*1/6,IF(AM$2="FNT1657",$G3*2/6,"")))),IF($F3="FNT1608-K",IF(AM$2="FNT1653",$G3*1/6,IF(AM$2="FNT1654",$G3*2/6,IF(AM$2="FNT1655",$G3*1/6,IF(AM$2="FNT1657",$G3*2/6,"")))),IF($F3=AM$2,$G3,""))),"") | AN3: =IF(AND($G3>0,$F3<>""),IF(OR($F3="FNT1608-G",$F3="FNT1675-G"),IF(OR(AN$2="FNT1611",AN$2="FNT1610",AN$2="FNT1609"),$G3/3,""),IF($F3="FNT1608-H",IF(OR(AN$2="FNT1618",AN$2="FNT1619",AN$2="FNT1620"),$G3/3,""),IF($F3="FNT1608-I",IF(AN$2="FNT1653",$G3*2/6,IF(AN$2="FNT1654",$G3*1/6,IF(AN$2="FNT1655",$G3*1/6,IF(AN$2="FNT1657",$G3*2/6,"")))),IF($F3="FNT1608-K",IF(AN$2="FNT1653",$G3*1/6,IF(AN$2="FNT1654",$G3*2/6,IF(AN$2="FNT1655",$G3*1/6,IF(AN$2="FNT1657",$G3*2/6,"")))),IF($F3=AN$2,$G3,""))))),"") | AO3: =IF(AND($G3>0,$F3<>""),IF(OR($F3="FNT1608-G",$F3="FNT1675-G"),IF(OR(AO$2="FNT1611",AO$2="FNT1610",AO$2="FNT1609"),$G3/3,""),IF($F3="FNT1608-H",IF(OR(AO$2="FNT1618",AO$2="FNT1619",AO$2="FNT1620"),$G3/3,""),IF($F3="FNT1608-I",IF(AO$2="FNT1653",$G3*2/6,IF(AO$2="FNT1654",$G3*1/6,IF(AO$2="FNT1655",$G3*1/6,IF(AO$2="FNT1657",$G3*2/6,"")))),IF($F3="FNT1608-K",IF(AO$2="FNT1653",$G3*1/6,IF(AO$2="FNT1654",$G3*2/6,IF(AO$2="FNT1655",$G3*1/6,IF(AO$2="FNT1657",$G3*2/6,"")))),IF($F3=AO$2,$G3,""))))),"") | AP3: 5.38 | AQ3: =SUM(J3:AO3)*AP3 -> 46806 | AR3: =AQ3*7.75 -> 362746.5
A4: 45068 | B4: 45127 | C4: V1 | D4: 仓单转客单 | E4: JAZ136222 | F4: SNF0181 | G4: =198-54 -> 144 | H4: 7L包装+PET吸塑 | I4: =IFERROR(VLOOKUP(F4,名称!A:C,3,0),"") -> SNF | J4: =IF(AND($F4=J$2,$G4>0),$G4,"") | K4: =IF(AND($F4=K$2,$G4>0),$G4,"") | L4: =IF(AND($F4=L$2,$G4>0),$G4,"") | M4: =IF(AND($F4=M$2,$G4>0),$G4,"") | N4: =IF(AND($F4=N$2,$G4>0),$G4,"") | O4: =IF(AND($F4=O$2,$G4>0),$G4,"") | P4: =IF(AND($F4=P$2,$G4>0),$G4,"") | Q4: =IF(AND($F4=Q$2,$G4>0),$G4,"") | ... AC4: =IF(AND($F4=AC$2,$G4>0),$G4,"") | AD4: =IF(AND($G4>0,$F4<>""),IF(OR($F4="FNT1608-G",$F4="FNT1675-G"),IF(OR(AD$2="FNT1611",AD$2="FNT1610",AD$2="FNT1609"),$G4/3,""),IF($F4=AD$2,$G4,"")),"") | AE4: =IF(AND($G4>0,$F4<>""),IF(OR($F4="FNT1608-G",$F4="FNT1675-G"),IF(OR(AE$2="FNT1611",AE$2="FNT1610",AE$2="FNT1609"),$G4/3,""),IF($F4=AE$2,$G4,"")),"") | AF4: =IF(AND($G4>0,$F4<>""),IF(OR($F4="FNT1608-G",$F4="FNT1675-G"),IF(OR(AF$2="FNT1611",AF$2="FNT1610",AF$2="FNT1609"),$G4/3,""),IF($F4=AF$2,$G4,"")),"") | AG4: =IF(AND($G4>0,$F4<>""),IF($F4="FNT1608-H",IF(OR(AG$2="FNT1618",AG$2="FNT1619",AG$2="FNT1620"),$G4/3,""),IF($F4=AG$2,$G4,"")),"") | AH4: =IF(AND($G4>0,$F4<>""),IF($F4="FNT1608-H",IF(OR(AH$2="FNT1618",AH$2="FNT1619",AH$2="FNT1620"),$G4/3,""),IF($F4=AH$2,$G4,"")),"") | AI4: =IF(AND($G4>0,$F4<>""),IF($F4="FNT1608-H",IF(OR(AI$2="FNT1618",AI$2="FNT1619",AI$2="FNT1620"),$G4/3,""),IF($F4=AI$2,$G4,"")),"") | AJ4: =IF(AND($G4>0,$F4<>""),IF($F4="FNT1608-I",IF(AJ$2="FNT1653",$G4*2/6,IF(AJ$2="FNT1654",$G4*1/6,IF(AJ$2="FNT1655",$G4*1/6,IF(AJ$2="FNT1657",$G4*2/6,"")))),IF($F4="FNT1608-K",IF(AJ$2="FNT1653",$G4*1/6,IF(AJ$2="FNT1654",$G4*2/6,IF(AJ$2="FNT1655",$G4*1/6,IF(AJ$2="FNT1657",$G4*2/6,"")))),IF($F4=AJ$2,$G4,""))),"") | AK4: =IF(AND($G4>0,$F4<>""),IF($F4="FNT1608-I",IF(AK$2="FNT1653",$G4*2/6,IF(AK$2="FNT1654",$G4*1/6,IF(AK$2="FNT1655",$G4*1/6,IF(AK$2="FNT1657",$G4*2/6,"")))),IF($F4="FNT1608-K",IF(AK$2="FNT1653",$G4*1/6,IF(AK$2="FNT1654",$G4*2/6,IF(AK$2="FNT1655",$G4*1/6,IF(AK$2="FNT1657",$G4*2/6,"")))),IF($F4=AK$2,$G4,""))),"") | AL4: =IF(AND($G4>0,$F4<>""),IF($F4="FNT1608-I",IF(AL$2="FNT1653",$G4*2/6,IF(AL$2="FNT1654",$G4*1/6,IF(AL$2="FNT1655",$G4*1/6,IF(AL$2="FNT1657",$G4*2/6,"")))),IF($F4="FNT1608-K",IF(AL$2="FNT1653",$G4*1/6,IF(AL$2="FNT1654",$G4*2/6,IF(AL$2="FNT1655",$G4*1/6,IF(AL$2="FNT1657",$G4*2/6,"")))),IF($F4=AL$2,$G4,""))),"") | AM4: =IF(AND($G4>0,$F4<>""),IF($F4="FNT1608-I",IF(AM$2="FNT1653",$G4*2/6,IF(AM$2="FNT1654",$G4*1/6,IF(AM$2="FNT1655",$G4*1/6,IF(AM$2="FNT1657",$G4*2/6,"")))),IF($F4="FNT1608-K",IF(AM$2="FNT1653",$G4*1/6,IF(AM$2="FNT1654",$G4*2/6,IF(AM$2="FNT1655",$G4*1/6,IF(AM$2="FNT1657",$G4*2/6,"")))),IF($F4=AM$2,$G4,""))),"") | AN4: =IF(AND($G4>0,$F4<>""),IF(OR($F4="FNT1608-G",$F4="FNT1675-G"),IF(OR(AN$2="FNT1611",AN$2="FNT1610",AN$2="FNT1609"),$G4/3,""),IF($F4="FNT1608-H",IF(OR(AN$2="FNT1618",AN$2="FNT1619",AN$2="FNT1620"),$G4/3,""),IF($F4="FNT1608-I",IF(AN$2="FNT1653",$G4*2/6,IF(AN$2="FNT1654",$G4*1/6,IF(AN$2="FNT1655",$G4*1/6,IF(AN$2="FNT1657",$G4*2/6,"")))),IF($F4="FNT1608-K",IF(AN$2="FNT1653",$G4*1/6,IF(AN$2="FNT1654",$G4*2/6,IF(AN$2="FNT1655",$G4*1/6,IF(AN$2="FNT1657",$G4*2/6,"")))),IF($F4=AN$2,$G4,""))))),"") | AO4: =IF(AND($G4>0,$F4<>""),IF(OR($F4="FNT1608-G",$F4="FNT1675-G"),IF(OR(AO$2="FNT1611",AO$2="FNT1610",AO$2="FNT1609"),$G4/3,""),IF($F4="FNT1608-H",IF(OR(AO$2="FNT1618",AO$2="FNT1619",AO$2="FNT1620"),$G4/3,""),IF($F4="FNT1608-I",IF(AO$2="FNT1653",$G4*2/6,IF(AO$2="FNT1654",$G4*1/6,IF(AO$2="FNT1655",$G4*1/6,IF(AO$2="FNT1657",$G4*2/6,"")))),IF($F4="FNT1608-K",IF(AO$2="FNT1653",$G4*1/6,IF(AO$2="FNT1654",$G4*2/6,IF(AO$2="FNT1655",$G4*1/6,IF(AO$2="FNT1657",$G4*2/6,"")))),IF($F4=AO$2,$G4,""))))),"") | AP4: 2.22 | AQ4: =SUM(J4:AO4)*AP4 -> 319.68 | AR4: =AQ4*7.75 -> 2477.52
A5: 45128 | B5: 45184 | C5: V1 | D5: 仓单转客单 | E5: JAZ143501 | F5: CMW0182 | G5: =1820-836-56-188-60-500+100-180 -> 100 | H5: 7L(G-LOGO)包装 | I5: =IFERROR(VLOOKUP(F5,名称!A:C,3,0),"") -> CMW | J5: =IF(AND($F5=J$2,$G5>0),$G5,"") | K5: =IF(AND($F5=K$2,$G5>0),$G5,"") | L5: =IF(AND($F5=L$2,$G5>0),$G5,"") | M5: =IF(AND($F5=M$2,$G5>0),$G5,"") -> 100 | N5: =IF(AND($F5=N$2,$G5>0),$G5,"") | O5: =IF(AND($F5=O$2,$G5>0),$G5,"") | P5: =IF(AND($F5=P$2,$G5>0),$G5,"") | Q5: =IF(AND($F5=Q$2,$G5>0),$G5,"") | ... AC5: =IF(AND($F5=AC$2,$G5>0),$G5,"") | AD5: =IF(AND($G5>0,$F5<>""),IF(OR($F5="FNT1608-G",$F5="FNT1675-G"),IF(OR(AD$2="FNT1611",AD$2="FNT1610",AD$2="FNT1609"),$G5/3,""),IF($F5=AD$2,$G5,"")),"") | AE5: =IF(AND($G5>0,$F5<>""),IF(OR($F5="FNT1608-G",$F5="FNT1675-G"),IF(OR(AE$2="FNT1611",AE$2="FNT1610",AE$2="FNT1609"),$G5/3,""),IF($F5=AE$2,$G5,"")),"") | AF5: =IF(AND($G5>0,$F5<>""),IF(OR($F5="FNT1608-G",$F5="FNT1675-G"),IF(OR(AF$2="FNT1611",AF$2="FNT1610",AF$2="FNT1609"),$G5/3,""),IF($F5=AF$2,$G5,"")),"") | AG5: =IF(AND($G5>0,$F5<>""),IF($F5="FNT1608-H",IF(OR(AG$2="FNT1618",AG$2="FNT1619",AG$2="FNT1620"),$G5/3,""),IF($F5=AG$2,$G5,"")),"") | AH5: =IF(AND($G5>0,$F5<>""),IF($F5="FNT1608-H",IF(OR(AH$2="FNT1618",AH$2="FNT1619",AH$2="FNT1620"),$G5/3,""),IF($F5=AH$2,$G5,"")),"") | AI5: =IF(AND($G5>0,$F5<>""),IF($F5="FNT1608-H",IF(OR(AI$2="FNT1618",AI$2="FNT1619",AI$2="FNT1620"),$G5/3,""),IF($F5=AI$2,$G5,"")),"") | AJ5: =IF(AND($G5>0,$F5<>""),IF($F5="FNT1608-I",IF(AJ$2="FNT1653",$G5*2/6,IF(AJ$2="FNT1654",$G5*1/6,IF(AJ$2="FNT1655",$G5*1/6,IF(AJ$2="FNT1657",$G5*2/6,"")))),IF($F5="FNT1608-K",IF(AJ$2="FNT1653",$G5*1/6,IF(AJ$2="FNT1654",$G5*2/6,IF(AJ$2="FNT1655",$G5*1/6,IF(AJ$2="FNT1657",$G5*2/6,"")))),IF($F5=AJ$2,$G5,""))),"") | AK5: =IF(AND($G5>0,$F5<>""),IF($F5="FNT1608-I",IF(AK$2="FNT1653",$G5*2/6,IF(AK$2="FNT1654",$G5*1/6,IF(AK$2="FNT1655",$G5*1/6,IF(AK$2="FNT1657",$G5*2/6,"")))),IF($F5="FNT1608-K",IF(AK$2="FNT1653",$G5*1/6,IF(AK$2="FNT1654",$G5*2/6,IF(AK$2="FNT1655",$G5*1/6,IF(AK$2="FNT1657",$G5*2/6,"")))),IF($F5=AK$2,$G5,""))),"") | AL5: =IF(AND($G5>0,$F5<>""),IF($F5="FNT1608-I",IF(AL$2="FNT1653",$G5*2/6,IF(AL$2="FNT1654",$G5*1/6,IF(AL$2="FNT1655",$G5*1/6,IF(AL$2="FNT1657",$G5*2/6,"")))),IF($F5="FNT1608-K",IF(AL$2="FNT1653",$G5*1/6,IF(AL$2="FNT1654",$G5*2/6,IF(AL$2="FNT1655",$G5*1/6,IF(AL$2="FNT1657",$G5*2/6,"")))),IF($F5=AL$2,$G5,""))),"") | AM5: =IF(AND($G5>0,$F5<>""),IF($F5="FNT1608-I",IF(AM$2="FNT1653",$G5*2/6,IF(AM$2="FNT1654",$G5*1/6,IF(AM$2="FNT1655",$G5*1/6,IF(AM$2="FNT1657",$G5*2/6,"")))),IF($F5="FNT1608-K",IF(AM$2="FNT1653",$G5*1/6,IF(AM$2="FNT1654",$G5*2/6,IF(AM$2="FNT1655",$G5*1/6,IF(AM$2="FNT1657",$G5*2/6,"")))),IF($F5=AM$2,$G5,""))),"") | AN5: =IF(AND($G5>0,$F5<>""),IF(OR($F5="FNT1608-G",$F5="FNT1675-G"),IF(OR(AN$2="FNT1611",AN$2="FNT1610",AN$2="FNT1609"),$G5/3,""),IF($F5="FNT1608-H",IF(OR(AN$2="FNT1618",AN$2="FNT1619",AN$2="FNT1620"),$G5/3,""),IF($F5="FNT1608-I",IF(AN$2="FNT1653",$G5*2/6,IF(AN$2="FNT1654",$G5*1/6,IF(AN$2="FNT1655",$G5*1/6,IF(AN$2="FNT1657",$G5*2/6,"")))),IF($F5="FNT1608-K",IF(AN$2="FNT1653",$G5*1/6,IF(AN$2="FNT1654",$G5*2/6,IF(AN$2="FNT1655",$G5*1/6,IF(AN$2="FNT1657",$G5*2/6,"")))),IF($F5=AN$2,$G5,""))))),"") | AO5: =IF(AND($G5>0,$F5<>""),IF(OR($F5="FNT1608-G",$F5="FNT1675-G"),IF(OR(AO$2="FNT1611",AO$2="FNT1610",AO$2="FNT1609"),$G5/3,""),IF($F5="FNT1608-H",IF(OR(AO$2="FNT1618",AO$2="FNT1619",AO$2="FNT1620"),$G5/3,""),IF($F5="FNT1608-I",IF(AO$2="FNT1653",$G5*2/6,IF(AO$2="FNT1654",$G5*1/6,IF(AO$2="FNT1655",$G5*1/6,IF(AO$2="FNT1657",$G5*2/6,"")))),IF($F5="FNT1608-K",IF(AO$2="FNT1653",$G5*1/6,IF(AO$2="FNT1654",$G5*2/6,IF(AO$2="FNT1655",$G5*1/6,IF(AO$2="FNT1657",$G5*2/6,"")))),IF($F5=AO$2,$G5,""))))),"") | AP5: 13.42 | AQ5: =SUM(J5:AO5)*AP5 -> 1342 | AR5: =AQ5*7.75 -> 10400.5
A6: 45313 | B6: 45444 | C6: V1 | E6: JAZ174061 | F6: CMW0352 | G6: =2250-1126-224-896 -> 4 | H6: 美文包装+RPET吸塑 | I6: =IFERROR(VLOOKUP(F6,名称!A:C,3,0),"") -> CMW | J6: =IF(AND($F6=J$2,$G6>0),$G6,"") | K6: =IF(AND($F6=K$2,$G6>0),$G6,"") | L6: =IF(AND($F6=L$2,$G6>0),$G6,"") | M6: =IF(AND($F6=M$2,$G6>0),$G6,"") | N6: =IF(AND($F6=N$2,$G6>0),$G6,"") | O6: =IF(AND($F6=O$2,$G6>0),$G6,"") -> 4 | P6: =IF(AND($F6=P$2,$G6>0),$G6,"") | Q6: =IF(AND($F6=Q$2,$G6>0),$G6,"") | ... AC6: =IF(AND($F6=AC$2,$G6>0),$G6,"") | AD6: =IF(AND($G6>0,$F6<>""),IF(OR($F6="FNT1608-G",$F6="FNT1675-G"),IF(OR(AD$2="FNT1611",AD$2="FNT1610",AD$2="FNT1609"),$G6/3,""),IF($F6=AD$2,$G6,"")),"") | AE6: =IF(AND($G6>0,$F6<>""),IF(OR($F6="FNT1608-G",$F6="FNT1675-G"),IF(OR(AE$2="FNT1611",AE$2="FNT1610",AE$2="FNT1609"),$G6/3,""),IF($F6=AE$2,$G6,"")),"") | AF6: =IF(AND($G6>0,$F6<>""),IF(OR($F6="FNT1608-G",$F6="FNT1675-G"),IF(OR(AF$2="FNT1611",AF$2="FNT1610",AF$2="FNT1609"),$G6/3,""),IF($F6=AF$2,$G6,"")),"") | AG6: =IF(AND($G6>0,$F6<>""),IF($F6="FNT1608-H",IF(OR(AG$2="FNT1618",AG$2="FNT1619",AG$2="FNT1620"),$G6/3,""),IF($F6=AG$2,$G6,"")),"") | AH6: =IF(AND($G6>0,$F6<>""),IF($F6="FNT1608-H",IF(OR(AH$2="FNT1618",AH$2="FNT1619",AH$2="FNT1620"),$G6/3,""),IF($F6=AH$2,$G6,"")),"") | AI6: =IF(AND($G6>0,$F6<>""),IF($F6="FNT1608-H",IF(OR(AI$2="FNT1618",AI$2="FNT1619",AI$2="FNT1620"),$G6/3,""),IF($F6=AI$2,$G6,"")),"") | AJ6: =IF(AND($G6>0,$F6<>""),IF($F6="FNT1608-I",IF(AJ$2="FNT1653",$G6*2/6,IF(AJ$2="FNT1654",$G6*1/6,IF(AJ$2="FNT1655",$G6*1/6,IF(AJ$2="FNT1657",$G6*2/6,"")))),IF($F6="FNT1608-K",IF(AJ$2="FNT1653",$G6*1/6,IF(AJ$2="FNT1654",$G6*2/6,IF(AJ$2="FNT1655",$G6*1/6,IF(AJ$2="FNT1657",$G6*2/6,"")))),IF($F6=AJ$2,$G6,""))),"") | AK6: =IF(AND($G6>0,$F6<>""),IF($F6="FNT1608-I",IF(AK$2="FNT1653",$G6*2/6,IF(AK$2="FNT1654",$G6*1/6,IF(AK$2="FNT1655",$G6*1/6,IF(AK$2="FNT1657",$G6*2/6,"")))),IF($F6="FNT1608-K",IF(AK$2="FNT1653",$G6*1/6,IF(AK$2="FNT1654",$G6*2/6,IF(AK$2="FNT1655",$G6*1/6,IF(AK$2="FNT1657",$G6*2/6,"")))),IF($F6=AK$2,$G6,""))),"") | AL6: =IF(AND($G6>0,$F6<>""),IF($F6="FNT1608-I",IF(AL$2="FNT1653",$G6*2/6,IF(AL$2="FNT1654",$G6*1/6,IF(AL$2="FNT1655",$G6*1/6,IF(AL$2="FNT1657",$G6*2/6,"")))),IF($F6="FNT1608-K",IF(AL$2="FNT1653",$G6*1/6,IF(AL$2="FNT1654",$G6*2/6,IF(AL$2="FNT1655",$G6*1/6,IF(AL$2="FNT1657",$G6*2/6,"")))),IF($F6=AL$2,$G6,""))),"") | AM6: =IF(AND($G6>0,$F6<>""),IF($F6="FNT1608-I",IF(AM$2="FNT1653",$G6*2/6,IF(AM$2="FNT1654",$G6*1/6,IF(AM$2="FNT1655",$G6*1/6,IF(AM$2="FNT1657",$G6*2/6,"")))),IF($F6="FNT1608-K",IF(AM$2="FNT1653",$G6*1/6,IF(AM$2="FNT1654",$G6*2/6,IF(AM$2="FNT1655",$G6*1/6,IF(AM$2="FNT1657",$G6*2/6,"")))),IF($F6=AM$2,$G6,""))),"") | AN6: =IF(AND($G6>0,$F6<>""),IF(OR($F6="FNT1608-G",$F6="FNT1675-G"),IF(OR(AN$2="FNT1611",AN$2="FNT1610",AN$2="FNT1609"),$G6/3,""),IF($F6="FNT1608-H",IF(OR(AN$2="FNT1618",AN$2="FNT1619",AN$2="FNT1620"),$G6/3,""),IF($F6="FNT1608-I",IF(AN$2="FNT1653",$G6*2/6,IF(AN$2="FNT1654",$G6*1/6,IF(AN$2="FNT1655",$G6*1/6,IF(AN$2="FNT1657",$G6*2/6,"")))),IF($F6="FNT1608-K",IF(AN$2="FNT1653",$G6*1/6,IF(AN$2="FNT1654",$G6*2/6,IF(AN$2="FNT1655",$G6*1/6,IF(AN$2="FNT1657",$G6*2/6,"")))),IF($F6=AN$2,$G6,""))))),"") | AO6: =IF(AND($G6>0,$F6<>""),IF(OR($F6="FNT1608-G",$F6="FNT1675-G"),IF(OR(AO$2="FNT1611",AO$2="FNT1610",AO$2="FNT1609"),$G6/3,""),IF($F6="FNT1608-H",IF(OR(AO$2="FNT1618",AO$2="FNT1619",AO$2="FNT1620"),$G6/3,""),IF($F6="FNT1608-I",IF(AO$2="FNT1653",$G6*2/6,IF(AO$2="FNT1654",$G6*1/6,IF(AO$2="FNT1655",$G6*1/6,IF(AO$2="FNT1657",$G6*2/6,"")))),IF($F6="FNT1608-K",IF(AO$2="FNT1653",$G6*1/6,IF(AO$2="FNT1654",$G6*2/6,IF(AO$2="FNT1655",$G6*1/6,IF(AO$2="FNT1657",$G6*2/6,"")))),IF($F6=AO$2,$G6,""))))),"") | AP6: 13.53 | AQ6: =SUM(J6:AO6)*AP6 -> 54.12 | AR6: =AQ6*7.75 -> 419.43
A7: 45588 | B7: 45609 | C7: V1 | D7: JAZ175961 | E7: SAM220161 | F7: CMW0015 | G7: =60+60 -> 120 | H7: 7L包装+RPET吸塑 | I7: =IFERROR(VLOOKUP(F7,名称!A:C,3,0),"") -> CMW | J7: =IF(AND($F7=J$2,$G7>0),$G7,"") -> 120 | K7: =IF(AND($F7=K$2,$G7>0),$G7,"") | L7: =IF(AND($F7=L$2,$G7>0),$G7,"") | M7: =IF(AND($F7=M$2,$G7>0),$G7,"") | N7: =IF(AND($F7=N$2,$G7>0),$G7,"") | O7: =IF(AND($F7=O$2,$G7>0),$G7,"") | P7: =IF(AND($F7=P$2,$G7>0),$G7,"") | Q7: =IF(AND($F7=Q$2,$G7>0),$G7,"") | ... AC7: =IF(AND($F7=AC$2,$G7>0),$G7,"") | AD7: =IF(AND($G7>0,$F7<>""),IF(OR($F7="FNT1608-G",$F7="FNT1675-G"),IF(OR(AD$2="FNT1611",AD$2="FNT1610",AD$2="FNT1609"),$G7/3,""),IF($F7=AD$2,$G7,"")),"") | AE7: =IF(AND($G7>0,$F7<>""),IF(OR($F7="FNT1608-G",$F7="FNT1675-G"),IF(OR(AE$2="FNT1611",AE$2="FNT1610",AE$2="FNT1609"),$G7/3,""),IF($F7=AE$2,$G7,"")),"") | AF7: =IF(AND($G7>0,$F7<>""),IF(OR($F7="FNT1608-G",$F7="FNT1675-G"),IF(OR(AF$2="FNT1611",AF$2="FNT1610",AF$2="FNT1609"),$G7/3,""),IF($F7=AF$2,$G7,"")),"") | AG7: =IF(AND($G7>0,$F7<>""),IF($F7="FNT1608-H",IF(OR(AG$2="FNT1618",AG$2="FNT1619",AG$2="FNT1620"),$G7/3,""),IF($F7=AG$2,$G7,"")),"") | AH7: =IF(AND($G7>0,$F7<>""),IF($F7="FNT1608-H",IF(OR(AH$2="FNT1618",AH$2="FNT1619",AH$2="FNT1620"),$G7/3,""),IF($F7=AH$2,$G7,"")),"") | AI7: =IF(AND($G7>0,$F7<>""),IF($F7="FNT1608-H",IF(OR(AI$2="FNT1618",AI$2="FNT1619",AI$2="FNT1620"),$G7/3,""),IF($F7=AI$2,$G7,"")),"") | AJ7: =IF(AND($G7>0,$F7<>""),IF($F7="FNT1608-I",IF(AJ$2="FNT1653",$G7*2/6,IF(AJ$2="FNT1654",$G7*1/6,IF(AJ$2="FNT1655",$G7*1/6,IF(AJ$2="FNT1657",$G7*2/6,"")))),IF($F7="FNT1608-K",IF(AJ$2="FNT1653",$G7*1/6,IF(AJ$2="FNT1654",$G7*2/6,IF(AJ$2="FNT1655",$G7*1/6,IF(AJ$2="FNT1657",$G7*2/6,"")))),IF($F7=AJ$2,$G7,""))),"") | AK7: =IF(AND($G7>0,$F7<>""),IF($F7="FNT1608-I",IF(AK$2="FNT1653",$G7*2/6,IF(AK$2="FNT1654",$G7*1/6,IF(AK$2="FNT1655",$G7*1/6,IF(AK$2="FNT1657",$G7*2/6,"")))),IF($F7="FNT1608-K",IF(AK$2="FNT1653",$G7*1/6,IF(AK$2="FNT1654",$G7*2/6,IF(AK$2="FNT1655",$G7*1/6,IF(AK$2="FNT1657",$G7*2/6,"")))),IF($F7=AK$2,$G7,""))),"") | AL7: =IF(AND($G7>0,$F7<>""),IF($F7="FNT1608-I",IF(AL$2="FNT1653",$G7*2/6,IF(AL$2="FNT1654",$G7*1/6,IF(AL$2="FNT1655",$G7*1/6,IF(AL$2="FNT1657",$G7*2/6,"")))),IF($F7="FNT1608-K",IF(AL$2="FNT1653",$G7*1/6,IF(AL$2="FNT1654",$G7*2/6,IF(AL$2="FNT1655",$G7*1/6,IF(AL$2="FNT1657",$G7*2/6,"")))),IF($F7=AL$2,$G7,""))),"") | AM7: =IF(AND($G7>0,$F7<>""),IF($F7="FNT1608-I",IF(AM$2="FNT1653",$G7*2/6,IF(AM$2="FNT1654",$G7*1/6,IF(AM$2="FNT1655",$G7*1/6,IF(AM$2="FNT1657",$G7*2/6,"")))),IF($F7="FNT1608-K",IF(AM$2="FNT1653",$G7*1/6,IF(AM$2="FNT1654",$G7*2/6,IF(AM$2="FNT1655",$G7*1/6,IF(AM$2="FNT1657",$G7*2/6,"")))),IF($F7=AM$2,$G7,""))),"") | AN7: =IF(AND($G7>0,$F7<>""),IF(OR($F7="FNT1608-G",$F7="FNT1675-G"),IF(OR(AN$2="FNT1611",AN$2="FNT1610",AN$2="FNT1609"),$G7/3,""),IF($F7="FNT1608-H",IF(OR(AN$2="FNT1618",AN$2="FNT1619",AN$2="FNT1620"),$G7/3,""),IF($F7="FNT1608-I",IF(AN$2="FNT1653",$G7*2/6,IF(AN$2="FNT1654",$G7*1/6,IF(AN$2="FNT1655",$G7*1/6,IF(AN$2="FNT1657",$G7*2/6,"")))),IF($F7="FNT1608-K",IF(AN$2="FNT1653",$G7*1/6,IF(AN$2="FNT1654",$G7*2/6,IF(AN$2="FNT1655",$G7*1/6,IF(AN$2="FNT1657",$G7*2/6,"")))),IF($F7=AN$2,$G7,""))))),"") | AO7: =IF(AND($G7>0,$F7<>""),IF(OR($F7="FNT1608-G",$F7="FNT1675-G"),IF(OR(AO$2="FNT1611",AO$2="FNT1610",AO$2="FNT1609"),$G7/3,""),IF($F7="FNT1608-H",IF(OR(AO$2="FNT1618",AO$2="FNT1619",AO$2="FNT1620"),$G7/3,""),IF($F7="FNT1608-I",IF(AO$2="FNT1653",$G7*2/6,IF(AO$2="FNT1654",$G7*1/6,IF(AO$2="FNT1655",$G7*1/6,IF(AO$2="FNT1657",$G7*2/6,"")))),IF($F7="FNT1608-K",IF(AO$2="FNT1653",$G7*1/6,IF(AO$2="FNT1654",$G7*2/6,IF(AO$2="FNT1655",$G7*1/6,IF(AO$2="FNT1657",$G7*2/6,"")))),IF($F7=AO$2,$G7,""))))),"") | AP7: 4.26 | AQ7: =SUM(J7:AO7)*AP7 -> 511.2 | AR7: =AQ7*7.75 -> 3961.8
A8: 45722 | B8: 45806 | C8: V2 | D8: JAZ209199 | E8: 1SS3YYVR | F8: CMW0170 | G8: 300 | H8: 7L包装+RPET吸塑 | I8: =IFERROR(VLOOKUP(F8,名称!A:C,3,0),"") -> CMW | J8: =IF(AND($F8=J$2,$G8>0),$G8,"") | K8: =IF(AND($F8=K$2,$G8>0),$G8,"") | L8: =IF(AND($F8=L$2,$G8>0),$G8,"") -> 300 | M8: =IF(AND($F8=M$2,$G8>0),$G8,"") | N8: =IF(AND($F8=N$2,$G8>0),$G8,"") | O8: =IF(AND($F8=O$2,$G8>0),$G8,"") | P8: =IF(AND($F8=P$2,$G8>0),$G8,"") | Q8: =IF(AND($F8=Q$2,$G8>0),$G8,"") | ... AC8: =IF(AND($F8=AC$2,$G8>0),$G8,"") | AD8: =IF(AND($G8>0,$F8<>""),IF(OR($F8="FNT1608-G",$F8="FNT1675-G"),IF(OR(AD$2="FNT1611",AD$2="FNT1610",AD$2="FNT1609"),$G8/3,""),IF($F8=AD$2,$G8,"")),"") | AE8: =IF(AND($G8>0,$F8<>""),IF(OR($F8="FNT1608-G",$F8="FNT1675-G"),IF(OR(AE$2="FNT1611",AE$2="FNT1610",AE$2="FNT1609"),$G8/3,""),IF($F8=AE$2,$G8,"")),"") | AF8: =IF(AND($G8>0,$F8<>""),IF(OR($F8="FNT1608-G",$F8="FNT1675-G"),IF(OR(AF$2="FNT1611",AF$2="FNT1610",AF$2="FNT1609"),$G8/3,""),IF($F8=AF$2,$G8,"")),"") | AG8: =IF(AND($G8>0,$F8<>""),IF($F8="FNT1608-H",IF(OR(AG$2="FNT1618",AG$2="FNT1619",AG$2="FNT1620"),$G8/3,""),IF($F8=AG$2,$G8,"")),"") | AH8: =IF(AND($G8>0,$F8<>""),IF($F8="FNT1608-H",IF(OR(AH$2="FNT1618",AH$2="FNT1619",AH$2="FNT1620"),$G8/3,""),IF($F8=AH$2,$G8,"")),"") | AI8: =IF(AND($G8>0,$F8<>""),IF($F8="FNT1608-H",IF(OR(AI$2="FNT1618",AI$2="FNT1619",AI$2="FNT1620"),$G8/3,""),IF($F8=AI$2,$G8,"")),"") | AJ8: =IF(AND($G8>0,$F8<>""),IF($F8="FNT1608-I",IF(AJ$2="FNT1653",$G8*2/6,IF(AJ$2="FNT1654",$G8*1/6,IF(AJ$2="FNT1655",$G8*1/6,IF(AJ$2="FNT1657",$G8*2/6,"")))),IF($F8="FNT1608-K",IF(AJ$2="FNT1653",$G8*1/6,IF(AJ$2="FNT1654",$G8*2/6,IF(AJ$2="FNT1655",$G8*1/6,IF(AJ$2="FNT1657",$G8*2/6,"")))),IF($F8=AJ$2,$G8,""))),"") | AK8: =IF(AND($G8>0,$F8<>""),IF($F8="FNT1608-I",IF(AK$2="FNT1653",$G8*2/6,IF(AK$2="FNT1654",$G8*1/6,IF(AK$2="FNT1655",$G8*1/6,IF(AK$2="FNT1657",$G8*2/6,"")))),IF($F8="FNT1608-K",IF(AK$2="FNT1653",$G8*1/6,IF(AK$2="FNT1654",$G8*2/6,IF(AK$2="FNT1655",$G8*1/6,IF(AK$2="FNT1657",$G8*2/6,"")))),IF($F8=AK$2,$G8,""))),"") | AL8: =IF(AND($G8>0,$F8<>""),IF($F8="FNT1608-I",IF(AL$2="FNT1653",$G8*2/6,IF(AL$2="FNT1654",$G8*1/6,IF(AL$2="FNT1655",$G8*1/6,IF(AL$2="FNT1657",$G8*2/6,"")))),IF($F8="FNT1608-K",IF(AL$2="FNT1653",$G8*1/6,IF(AL$2="FNT1654",$G8*2/6,IF(AL$2="FNT1655",$G8*1/6,IF(AL$2="FNT1657",$G8*2/6,"")))),IF($F8=AL$2,$G8,""))),"") | AM8: =IF(AND($G8>0,$F8<>""),IF($F8="FNT1608-I",IF(AM$2="FNT1653",$G8*2/6,IF(AM$2="FNT1654",$G8*1/6,IF(AM$2="FNT1655",$G8*1/6,IF(AM$2="FNT1657",$G8*2/6,"")))),IF($F8="FNT1608-K",IF(AM$2="FNT1653",$G8*1/6,IF(AM$2="FNT1654",$G8*2/6,IF(AM$2="FNT1655",$G8*1/6,IF(AM$2="FNT1657",$G8*2/6,"")))),IF($F8=AM$2,$G8,""))),"") | AN8: =IF(AND($G8>0,$F8<>""),IF(OR($F8="FNT1608-G",$F8="FNT1675-G"),IF(OR(AN$2="FNT1611",AN$2="FNT1610",AN$2="FNT1609"),$G8/3,""),IF($F8="FNT1608-H",IF(OR(AN$2="FNT1618",AN$2="FNT1619",AN$2="FNT1620"),$G8/3,""),IF($F8="FNT1608-I",IF(AN$2="FNT1653",$G8*2/6,IF(AN$2="FNT1654",$G8*1/6,IF(AN$2="FNT1655",$G8*1/6,IF(AN$2="FNT1657",$G8*2/6,"")))),IF($F8="FNT1608-K",IF(AN$2="FNT1653",$G8*1/6,IF(AN$2="FNT1654",$G8*2/6,IF(AN$2="FNT1655",$G8*1/6,IF(AN$2="FNT1657",$G8*2/6,"")))),IF($F8=AN$2,$G8,""))))),"") | AO8: =IF(AND($G8>0,$F8<>""),IF(OR($F8="FNT1608-G",$F8="FNT1675-G"),IF(OR(AO$2="FNT1611",AO$2="FNT1610",AO$2="FNT1609"),$G8/3,""),IF($F8="FNT1608-H",IF(OR(AO$2="FNT1618",AO$2="FNT1619",AO$2="FNT1620"),$G8/3,""),IF($F8="FNT1608-I",IF(AO$2="FNT1653",$G8*2/6,IF(AO$2="FNT1654",$G8*1/6,IF(AO$2="FNT1655",$G8*1/6,IF(AO$2="FNT1657",$G8*2/6,"")))),IF($F8="FNT1608-K",IF(AO$2="FNT1653",$G8*1/6,IF(AO$2="FNT1654",$G8*2/6,IF(AO$2="FNT1655",$G8*1/6,IF(AO$2="FNT1657",$G8*2/6,"")))),IF($F8=AO$2,$G8,""))))),"") | AP8: 3.84 | AQ8: =SUM(J8:AO8)*AP8 -> 1152 | AR8: =AQ8*7.75 -> 8928
A9: 45741 | B9: 46001 | C9: V3 | D9: JAZ274484 | E9: JAZ-SUB-SP26-02改6000063660 | F9: FNT1608-G | G9: 804 | H9: 7L包装+RPET吸塑 | I9: =IFERROR(VLOOKUP(F9,名称!A:C,3,0),"") -> FNT | J9: =IF(AND($F9=J$2,$G9>0),$G9,"") | K9: =IF(AND($F9=K$2,$G9>0),$G9,"") | L9: =IF(AND($F9=L$2,$G9>0),$G9,"") | M9: =IF(AND($F9=M$2,$G9>0),$G9,"") | N9: =IF(AND($F9=N$2,$G9>0),$G9,"") | O9: =IF(AND($F9=O$2,$G9>0),$G9,"") | P9: =IF(AND($F9=P$2,$G9>0),$G9,"") | Q9: =IF(AND($F9=Q$2,$G9>0),$G9,"") | ... AC9: =IF(AND($F9=AC$2,$G9>0),$G9,"") | AD9: =IF(AND($G9>0,$F9<>""),IF(OR($F9="FNT1608-G",$F9="FNT1675-G"),IF(OR(AD$2="FNT1611",AD$2="FNT1610",AD$2="FNT1609"),$G9/3,""),IF($F9=AD$2,$G9,"")),"") -> 268 | AE9: =IF(AND($G9>0,$F9<>""),IF(OR($F9="FNT1608-G",$F9="FNT1675-G"),IF(OR(AE$2="FNT1611",AE$2="FNT1610",AE$2="FNT1609"),$G9/3,""),IF($F9=AE$2,$G9,"")),"") -> 268 | AF9: =IF(AND($G9>0,$F9<>""),IF(OR($F9="FNT1608-G",$F9="FNT1675-G"),IF(OR(AF$2="FNT1611",AF$2="FNT1610",AF$2="FNT1609"),$G9/3,""),IF($F9=AF$2,$G9,"")),"") -> 268 | AG9: =IF(AND($G9>0,$F9<>""),IF($F9="FNT1608-H",IF(OR(AG$2="FNT1618",AG$2="FNT1619",AG$2="FNT1620"),$G9/3,""),IF($F9=AG$2,$G9,"")),"") | AH9: =IF(AND($G9>0,$F9<>""),IF($F9="FNT1608-H",IF(OR(AH$2="FNT1618",AH$2="FNT1619",AH$2="FNT1620"),$G9/3,""),IF($F9=AH$2,$G9,"")),"") | AI9: =IF(AND($G9>0,$F9<>""),IF($F9="FNT1608-H",IF(OR(AI$2="FNT1618",AI$2="FNT1619",AI$2="FNT1620"),$G9/3,""),IF($F9=AI$2,$G9,"")),"") | AJ9: =IF(AND($G9>0,$F9<>""),IF($F9="FNT1608-I",IF(AJ$2="FNT1653",$G9*2/6,IF(AJ$2="FNT1654",$G9*1/6,IF(AJ$2="FNT1655",$G9*1/6,IF(AJ$2="FNT1657",$G9*2/6,"")))),IF($F9="FNT1608-K",IF(AJ$2="FNT1653",$G9*1/6,IF(AJ$2="FNT1654",$G9*2/6,IF(AJ$2="FNT1655",$G9*1/6,IF(AJ$2="FNT1657",$G9*2/6,"")))),IF($F9=AJ$2,$G9,""))),"") | AK9: =IF(AND($G9>0,$F9<>""),IF($F9="FNT1608-I",IF(AK$2="FNT1653",$G9*2/6,IF(AK$2="FNT1654",$G9*1/6,IF(AK$2="FNT1655",$G9*1/6,IF(AK$2="FNT1657",$G9*2/6,"")))),IF($F9="FNT1608-K",IF(AK$2="FNT1653",$G9*1/6,IF(AK$2="FNT1654",$G9*2/6,IF(AK$2="FNT1655",$G9*1/6,IF(AK$2="FNT1657",$G9*2/6,"")))),IF($F9=AK$2,$G9,""))),"") | AL9: =IF(AND($G9>0,$F9<>""),IF($F9="FNT1608-I",IF(AL$2="FNT1653",$G9*2/6,IF(AL$2="FNT1654",$G9*1/6,IF(AL$2="FNT1655",$G9*1/6,IF(AL$2="FNT1657",$G9*2/6,"")))),IF($F9="FNT1608-K",IF(AL$2="FNT1653",$G9*1/6,IF(AL$2="FNT1654",$G9*2/6,IF(AL$2="FNT1655",$G9*1/6,IF(AL$2="FNT1657",$G9*2/6,"")))),IF($F9=AL$2,$G9,""))),"") | AM9: =IF(AND($G9>0,$F9<>""),IF($F9="FNT1608-I",IF(AM$2="FNT1653",$G9*2/6,IF(AM$2="FNT1654",$G9*1/6,IF(AM$2="FNT1655",$G9*1/6,IF(AM$2="FNT1657",$G9*2/6,"")))),IF($F9="FNT1608-K",IF(AM$2="FNT1653",$G9*1/6,IF(AM$2="FNT1654",$G9*2/6,IF(AM$2="FNT1655",$G9*1/6,IF(AM$2="FNT1657",$G9*2/6,"")))),IF($F9=AM$2,$G9,""))),"") | AN9: =IF(AND($G9>0,$F9<>""),IF(OR($F9="FNT1608-G",$F9="FNT1675-G"),IF(OR(AN$2="FNT1611",AN$2="FNT1610",AN$2="FNT1609"),$G9/3,""),IF($F9="FNT1608-H",IF(OR(AN$2="FNT1618",AN$2="FNT1619",AN$2="FNT1620"),$G9/3,""),IF($F9="FNT1608-I",IF(AN$2="FNT1653",$G9*2/6,IF(AN$2="FNT1654",$G9*1/6,IF(AN$2="FNT1655",$G9*1/6,IF(AN$2="FNT1657",$G9*2/6,"")))),IF($F9="FNT1608-K",IF(AN$2="FNT1653",$G9*1/6,IF(AN$2="FNT1654",$G9*2/6,IF(AN$2="FNT1655",$G9*1/6,IF(AN$2="FNT1657",$G9*2/6,"")))),IF($F9=AN$2,$G9,""))))),"") | AO9: =IF(AND($G9>0,$F9<>""),IF(OR($F9="FNT1608-G",$F9="FNT1675-G"),IF(OR(AO$2="FNT1611",AO$2="FNT1610",AO$2="FNT1609"),$G9/3,""),IF($F9="FNT1608-H",IF(OR(AO$2="FNT1618",AO$2="FNT1619",AO$2="FNT1620"),$G9/3,""),IF($F9="FNT1608-I",IF(AO$2="FNT1653",$G9*2/6,IF(AO$2="FNT1654",$G9*1/6,IF(AO$2="FNT1655",$G9*1/6,IF(AO$2="FNT1657",$G9*2/6,"")))),IF($F9="FNT1608-K",IF(AO$2="FNT1653",$G9*1/6,IF(AO$2="FNT1654",$G9*2/6,IF(AO$2="FNT1655",$G9*1/6,IF(AO$2="FNT1657",$G9*2/6,"")))),IF($F9=AO$2,$G9,""))))),"") | AP9: 2.06 | AQ9: =SUM(J9:AO9)*AP9 -> 1656.24 | AR9: =AQ9*7.75 -> 12835.86
A10: 45766 | B10: 45812 | C10: V2 | E10: SAM235920 | F10: FNT1608-G | G10: 6 | H10: 7L包装+RPET吸塑 | I10: =IFERROR(VLOOKUP(F10,名称!A:C,3,0),"") -> FNT | J10: =IF(AND($F10=J$2,$G10>0),$G10,"") | K10: =IF(AND($F10=K$2,$G10>0),$G10,"") | L10: =IF(AND($F10=L$2,$G10>0),$G10,"") | M10: =IF(AND($F10=M$2,$G10>0),$G10,"") | N10: =IF(AND($F10=N$2,$G10>0),$G10,"") | O10: =IF(AND($F10=O$2,$G10>0),$G10,"") | P10: =IF(AND($F10=P$2,$G10>0),$G10,"") | Q10: =IF(AND($F10=Q$2,$G10>0),$G10,"") | ... AC10: =IF(AND($F10=AC$2,$G10>0),$G10,"") | AD10: =IF(AND($G10>0,$F10<>""),IF(OR($F10="FNT1608-G",$F10="FNT1675-G"),IF(OR(AD$2="FNT1611",AD$2="FNT1610",AD$2="FNT1609"),$G10/3,""),IF($F10=AD$2,$G10,"")),"") -> 2 | AE10: =IF(AND($G10>0,$F10<>""),IF(OR($F10="FNT1608-G",$F10="FNT1675-G"),IF(OR(AE$2="FNT1611",AE$2="FNT1610",AE$2="FNT1609"),$G10/3,""),IF($F10=AE$2,$G10,"")),"") -> 2 | AF10: =IF(AND($G10>0,$F10<>""),IF(OR($F10="FNT1608-G",$F10="FNT1675-G"),IF(OR(AF$2="FNT1611",AF$2="FNT1610",AF$2="FNT1609"),$G10/3,""),IF($F10=AF$2,$G10,"")),"") -> 2 | AG10: =IF(AND($G10>0,$F10<>""),IF($F10="FNT1608-H",IF(OR(AG$2="FNT1618",AG$2="FNT1619",AG$2="FNT1620"),$G10/3,""),IF($F10=AG$2,$G10,"")),"") | AH10: =IF(AND($G10>0,$F10<>""),IF($F10="FNT1608-H",IF(OR(AH$2="FNT1618",AH$2="FNT1619",AH$2="FNT1620"),$G10/3,""),IF($F10=AH$2,$G10,"")),"") | AI10: =IF(AND($G10>0,$F10<>""),IF($F10="FNT1608-H",IF(OR(AI$2="FNT1618",AI$2="FNT1619",AI$2="FNT1620"),$G10/3,""),IF($F10=AI$2,$G10,"")),"") | AJ10: =IF(AND($G10>0,$F10<>""),IF($F10="FNT1608-I",IF(AJ$2="FNT1653",$G10*2/6,IF(AJ$2="FNT1654",$G10*1/6,IF(AJ$2="FNT1655",$G10*1/6,IF(AJ$2="FNT1657",$G10*2/6,"")))),IF($F10="FNT1608-K",IF(AJ$2="FNT1653",$G10*1/6,IF(AJ$2="FNT1654",$G10*2/6,IF(AJ$2="FNT1655",$G10*1/6,IF(AJ$2="FNT1657",$G10*2/6,"")))),IF($F10=AJ$2,$G10,""))),"") | AK10: =IF(AND($G10>0,$F10<>""),IF($F10="FNT1608-I",IF(AK$2="FNT1653",$G10*2/6,IF(AK$2="FNT1654",$G10*1/6,IF(AK$2="FNT1655",$G10*1/6,IF(AK$2="FNT1657",$G10*2/6,"")))),IF($F10="FNT1608-K",IF(AK$2="FNT1653",$G10*1/6,IF(AK$2="FNT1654",$G10*2/6,IF(AK$2="FNT1655",$G10*1/6,IF(AK$2="FNT1657",$G10*2/6,"")))),IF($F10=AK$2,$G10,""))),"") | AL10: =IF(AND($G10>0,$F10<>""),IF($F10="FNT1608-I",IF(AL$2="FNT1653",$G10*2/6,IF(AL$2="FNT1654",$G10*1/6,IF(AL$2="FNT1655",$G10*1/6,IF(AL$2="FNT1657",$G10*2/6,"")))),IF($F10="FNT1608-K",IF(AL$2="FNT1653",$G10*1/6,IF(AL$2="FNT1654",$G10*2/6,IF(AL$2="FNT1655",$G10*1/6,IF(AL$2="FNT1657",$G10*2/6,"")))),IF($F10=AL$2,$G10,""))),"") | AM10: =IF(AND($G10>0,$F10<>""),IF($F10="FNT1608-I",IF(AM$2="FNT1653",$G10*2/6,IF(AM$2="FNT1654",$G10*1/6,IF(AM$2="FNT1655",$G10*1/6,IF(AM$2="FNT1657",$G10*2/6,"")))),IF($F10="FNT1608-K",IF(AM$2="FNT1653",$G10*1/6,IF(AM$2="FNT1654",$G10*2/6,IF(AM$2="FNT1655",$G10*1/6,IF(AM$2="FNT1657",$G10*2/6,"")))),IF($F10=AM$2,$G10,""))),"") | AN10: =IF(AND($G10>0,$F10<>""),IF(OR($F10="FNT1608-G",$F10="FNT1675-G"),IF(OR(AN$2="FNT1611",AN$2="FNT1610",AN$2="FNT1609"),$G10/3,""),IF($F10="FNT1608-H",IF(OR(AN$2="FNT1618",AN$2="FNT1619",AN$2="FNT1620"),$G10/3,""),IF($F10="FNT1608-I",IF(AN$2="FNT1653",$G10*2/6,IF(AN$2="FNT1654",$G10*1/6,IF(AN$2="FNT1655",$G10*1/6,IF(AN$2="FNT1657",$G10*2/6,"")))),IF($F10="FNT1608-K",IF(AN$2="FNT1653",$G10*1/6,IF(AN$2="FNT1654",$G10*2/6,IF(AN$2="FNT1655",$G10*1/6,IF(AN$2="FNT1657",$G10*2/6,"")))),IF($F10=AN$2,$G10,""))))),"") | AO10: =IF(AND($G10>0,$F10<>""),IF(OR($F10="FNT1608-G",$F10="FNT1675-G"),IF(OR(AO$2="FNT1611",AO$2="FNT1610",AO$2="FNT1609"),$G10/3,""),IF($F10="FNT1608-H",IF(OR(AO$2="FNT1618",AO$2="FNT1619",AO$2="FNT1620"),$G10/3,""),IF($F10="FNT1608-I",IF(AO$2="FNT1653",$G10*2/6,IF(AO$2="FNT1654",$G10*1/6,IF(AO$2="FNT1655",$G10*1/6,IF(AO$2="FNT1657",$G10*2/6,"")))),IF($F10="FNT1608-K",IF(AO$2="FNT1653",$G10*1/6,IF(AO$2="FNT1654",$G10*2/6,IF(AO$2="FNT1655",$G10*1/6,IF(AO$2="FNT1657",$G10*2/6,"")))),IF($F10=AO$2,$G10,""))))),"") | AP10: 2.143 | AQ10: =SUM(J10:AO10)*AP10 -> 12.86 | AR10: =AQ10*7.75 -> 99.67
A11: 45864 | B11: 45926 | C11: V1 | E11: EKHA-FALL25 | F11: CMW0015 | G11: 360 | H11: 7L包装+RPET吸塑 | I11: =IFERROR(VLOOKUP(F11,名称!A:C,3,0),"") -> CMW | J11: =IF(AND($F11=J$2,$G11>0),$G11,"") -> 360 | K11: =IF(AND($F11=K$2,$G11>0),$G11,"") | L11: =IF(AND($F11=L$2,$G11>0),$G11,"") | M11: =IF(AND($F11=M$2,$G11>0),$G11,"") | N11: =IF(AND($F11=N$2,$G11>0),$G11,"") | O11: =IF(AND($F11=O$2,$G11>0),$G11,"") | P11: =IF(AND($F11=P$2,$G11>0),$G11,"") | Q11: =IF(AND($F11=Q$2,$G11>0),$G11,"") | ... AC11: =IF(AND($F11=AC$2,$G11>0),$G11,"") | AD11: =IF(AND($G11>0,$F11<>""),IF(OR($F11="FNT1608-G",$F11="FNT1675-G"),IF(OR(AD$2="FNT1611",AD$2="FNT1610",AD$2="FNT1609"),$G11/3,""),IF($F11=AD$2,$G11,"")),"") | AE11: =IF(AND($G11>0,$F11<>""),IF(OR($F11="FNT1608-G",$F11="FNT1675-G"),IF(OR(AE$2="FNT1611",AE$2="FNT1610",AE$2="FNT1609"),$G11/3,""),IF($F11=AE$2,$G11,"")),"") | AF11: =IF(AND($G11>0,$F11<>""),IF(OR($F11="FNT1608-G",$F11="FNT1675-G"),IF(OR(AF$2="FNT1611",AF$2="FNT1610",AF$2="FNT1609"),$G11/3,""),IF($F11=AF$2,$G11,"")),"") | AG11: =IF(AND($G11>0,$F11<>""),IF($F11="FNT1608-H",IF(OR(AG$2="FNT1618",AG$2="FNT1619",AG$2="FNT1620"),$G11/3,""),IF($F11=AG$2,$G11,"")),"") | AH11: =IF(AND($G11>0,$F11<>""),IF($F11="FNT1608-H",IF(OR(AH$2="FNT1618",AH$2="FNT1619",AH$2="FNT1620"),$G11/3,""),IF($F11=AH$2,$G11,"")),"") | AI11: =IF(AND($G11>0,$F11<>""),IF($F11="FNT1608-H",IF(OR(AI$2="FNT1618",AI$2="FNT1619",AI$2="FNT1620"),$G11/3,""),IF($F11=AI$2,$G11,"")),"") | AJ11: =IF(AND($G11>0,$F11<>""),IF($F11="FNT1608-I",IF(AJ$2="FNT1653",$G11*2/6,IF(AJ$2="FNT1654",$G11*1/6,IF(AJ$2="FNT1655",$G11*1/6,IF(AJ$2="FNT1657",$G11*2/6,"")))),IF($F11="FNT1608-K",IF(AJ$2="FNT1653",$G11*1/6,IF(AJ$2="FNT1654",$G11*2/6,IF(AJ$2="FNT1655",$G11*1/6,IF(AJ$2="FNT1657",$G11*2/6,"")))),IF($F11=AJ$2,$G11,""))),"") | AK11: =IF(AND($G11>0,$F11<>""),IF($F11="FNT1608-I",IF(AK$2="FNT1653",$G11*2/6,IF(AK$2="FNT1654",$G11*1/6,IF(AK$2="FNT1655",$G11*1/6,IF(AK$2="FNT1657",$G11*2/6,"")))),IF($F11="FNT1608-K",IF(AK$2="FNT1653",$G11*1/6,IF(AK$2="FNT1654",$G11*2/6,IF(AK$2="FNT1655",$G11*1/6,IF(AK$2="FNT1657",$G11*2/6,"")))),IF($F11=AK$2,$G11,""))),"") | AL11: =IF(AND($G11>0,$F11<>""),IF($F11="FNT1608-I",IF(AL$2="FNT1653",$G11*2/6,IF(AL$2="FNT1654",$G11*1/6,IF(AL$2="FNT1655",$G11*1/6,IF(AL$2="FNT1657",$G11*2/6,"")))),IF($F11="FNT1608-K",IF(AL$2="FNT1653",$G11*1/6,IF(AL$2="FNT1654",$G11*2/6,IF(AL$2="FNT1655",$G11*1/6,IF(AL$2="FNT1657",$G11*2/6,"")))),IF($F11=AL$2,$G11,""))),"") | AM11: =IF(AND($G11>0,$F11<>""),IF($F11="FNT1608-I",IF(AM$2="FNT1653",$G11*2/6,IF(AM$2="FNT1654",$G11*1/6,IF(AM$2="FNT1655",$G11*1/6,IF(AM$2="FNT1657",$G11*2/6,"")))),IF($F11="FNT1608-K",IF(AM$2="FNT1653",$G11*1/6,IF(AM$2="FNT1654",$G11*2/6,IF(AM$2="FNT1655",$G11*1/6,IF(AM$2="FNT1657",$G11*2/6,"")))),IF($F11=AM$2,$G11,""))),"") | AN11: =IF(AND($G11>0,$F11<>""),IF(OR($F11="FNT1608-G",$F11="FNT1675-G"),IF(OR(AN$2="FNT1611",AN$2="FNT1610",AN$2="FNT1609"),$G11/3,""),IF($F11="FNT1608-H",IF(OR(AN$2="FNT1618",AN$2="FNT1619",AN$2="FNT1620"),$G11/3,""),IF($F11="FNT1608-I",IF(AN$2="FNT1653",$G11*2/6,IF(AN$2="FNT1654",$G11*1/6,IF(AN$2="FNT1655",$G11*1/6,IF(AN$2="FNT1657",$G11*2/6,"")))),IF($F11="FNT1608-K",IF(AN$2="FNT1653",$G11*1/6,IF(AN$2="FNT1654",$G11*2/6,IF(AN$2="FNT1655",$G11*1/6,IF(AN$2="FNT1657",$G11*2/6,"")))),IF($F11=AN$2,$G11,""))))),"") | AO11: =IF(AND($G11>0,$F11<>""),IF(OR($F11="FNT1608-G",$F11="FNT1675-G"),IF(OR(AO$2="FNT1611",AO$2="FNT1610",AO$2="FNT1609"),$G11/3,""),IF($F11="FNT1608-H",IF(OR(AO$2="FNT1618",AO$2="FNT1619",AO$2="FNT1620"),$G11/3,""),IF($F11="FNT1608-I",IF(AO$2="FNT1653",$G11*2/6,IF(AO$2="FNT1654",$G11*1/6,IF(AO$2="FNT1655",$G11*1/6,IF(AO$2="FNT1657",$G11*2/6,"")))),IF($F11="FNT1608-K",IF(AO$2="FNT1653",$G11*1/6,IF(AO$2="FNT1654",$G11*2/6,IF(AO$2="FNT1655",$G11*1/6,IF(AO$2="FNT1657",$G11*2/6,"")))),IF($F11=AO$2,$G11,""))))),"") | AP11: 4.26 | AQ11: =SUM(J11:AO11)*AP11 -> 1533.6 | AR11: =AQ11*7.75 -> 11885.4
A12: 45887 | B12: 45992 | C12: V1 | E12: POUK10310 | F12: FNT1612 | G12: 240 | H12: 7L包装+RPET吸塑 | I12: =IFERROR(VLOOKUP(F12,名称!A:C,3,0),"") -> FNT | J12: =IF(AND($F12=J$2,$G12>0),$G12,"") | K12: =IF(AND($F12=K$2,$G12>0),$G12,"") | L12: =IF(AND($F12=L$2,$G12>0),$G12,"") | M12: =IF(AND($F12=M$2,$G12>0),$G12,"") | N12: =IF(AND($F12=N$2,$G12>0),$G12,"") | O12: =IF(AND($F12=O$2,$G12>0),$G12,"") | P12: =IF(AND($F12=P$2,$G12>0),$G12,"") -> 240 | Q12: =IF(AND($F12=Q$2,$G12>0),$G12,"") | ... AC12: =IF(AND($F12=AC$2,$G12>0),$G12,"") | AD12: =IF(AND($G12>0,$F12<>""),IF(OR($F12="FNT1608-G",$F12="FNT1675-G"),IF(OR(AD$2="FNT1611",AD$2="FNT1610",AD$2="FNT1609"),$G12/3,""),IF($F12=AD$2,$G12,"")),"") | AE12: =IF(AND($G12>0,$F12<>""),IF(OR($F12="FNT1608-G",$F12="FNT1675-G"),IF(OR(AE$2="FNT1611",AE$2="FNT1610",AE$2="FNT1609"),$G12/3,""),IF($F12=AE$2,$G12,"")),"") | AF12: =IF(AND($G12>0,$F12<>""),IF(OR($F12="FNT1608-G",$F12="FNT1675-G"),IF(OR(AF$2="FNT1611",AF$2="FNT1610",AF$2="FNT1609"),$G12/3,""),IF($F12=AF$2,$G12,"")),"") | AG12: =IF(AND($G12>0,$F12<>""),IF($F12="FNT1608-H",IF(OR(AG$2="FNT1618",AG$2="FNT1619",AG$2="FNT1620"),$G12/3,""),IF($F12=AG$2,$G12,"")),"") | AH12: =IF(AND($G12>0,$F12<>""),IF($F12="FNT1608-H",IF(OR(AH$2="FNT1618",AH$2="FNT1619",AH$2="FNT1620"),$G12/3,""),IF($F12=AH$2,$G12,"")),"") | AI12: =IF(AND($G12>0,$F12<>""),IF($F12="FNT1608-H",IF(OR(AI$2="FNT1618",AI$2="FNT1619",AI$2="FNT1620"),$G12/3,""),IF($F12=AI$2,$G12,"")),"") | AJ12: =IF(AND($G12>0,$F12<>""),IF($F12="FNT1608-I",IF(AJ$2="FNT1653",$G12*2/6,IF(AJ$2="FNT1654",$G12*1/6,IF(AJ$2="FNT1655",$G12*1/6,IF(AJ$2="FNT1657",$G12*2/6,"")))),IF($F12="FNT1608-K",IF(AJ$2="FNT1653",$G12*1/6,IF(AJ$2="FNT1654",$G12*2/6,IF(AJ$2="FNT1655",$G12*1/6,IF(AJ$2="FNT1657",$G12*2/6,"")))),IF($F12=AJ$2,$G12,""))),"") | AK12: =IF(AND($G12>0,$F12<>""),IF($F12="FNT1608-I",IF(AK$2="FNT1653",$G12*2/6,IF(AK$2="FNT1654",$G12*1/6,IF(AK$2="FNT1655",$G12*1/6,IF(AK$2="FNT1657",$G12*2/6,"")))),IF($F12="FNT1608-K",IF(AK$2="FNT1653",$G12*1/6,IF(AK$2="FNT1654",$G12*2/6,IF(AK$2="FNT1655",$G12*1/6,IF(AK$2="FNT1657",$G12*2/6,"")))),IF($F12=AK$2,$G12,""))),"") | AL12: =IF(AND($G12>0,$F12<>""),IF($F12="FNT1608-I",IF(AL$2="FNT1653",$G12*2/6,IF(AL$2="FNT1654",$G12*1/6,IF(AL$2="FNT1655",$G12*1/6,IF(AL$2="FNT1657",$G12*2/6,"")))),IF($F12="FNT1608-K",IF(AL$2="FNT1653",$G12*1/6,IF(AL$2="FNT1654",$G12*2/6,IF(AL$2="FNT1655",$G12*1/6,IF(AL$2="FNT1657",$G12*2/6,"")))),IF($F12=AL$2,$G12,""))),"") | AM12: =IF(AND($G12>0,$F12<>""),IF($F12="FNT1608-I",IF(AM$2="FNT1653",$G12*2/6,IF(AM$2="FNT1654",$G12*1/6,IF(AM$2="FNT1655",$G12*1/6,IF(AM$2="FNT1657",$G12*2/6,"")))),IF($F12="FNT1608-K",IF(AM$2="FNT1653",$G12*1/6,IF(AM$2="FNT1654",$G12*2/6,IF(AM$2="FNT1655",$G12*1/6,IF(AM$2="FNT1657",$G12*2/6,"")))),IF($F12=AM$2,$G12,""))),"") | AN12: =IF(AND($G12>0,$F12<>""),IF(OR($F12="FNT1608-G",$F12="FNT1675-G"),IF(OR(AN$2="FNT1611",AN$2="FNT1610",AN$2="FNT1609"),$G12/3,""),IF($F12="FNT1608-H",IF(OR(AN$2="FNT1618",AN$2="FNT1619",AN$2="FNT1620"),$G12/3,""),IF($F12="FNT1608-I",IF(AN$2="FNT1653",$G12*2/6,IF(AN$2="FNT1654",$G12*1/6,IF(AN$2="FNT1655",$G12*1/6,IF(AN$2="FNT1657",$G12*2/6,"")))),IF($F12="FNT1608-K",IF(AN$2="FNT1653",$G12*1/6,IF(AN$2="FNT1654",$G12*2/6,IF(AN$2="FNT1655",$G12*1/6,IF(AN$2="FNT1657",$G12*2/6,"")))),IF($F12=AN$2,$G12,""))))),"") | AO12: =IF(AND($G12>0,$F12<>""),IF(OR($F12="FNT1608-G",$F12="FNT1675-G"),IF(OR(AO$2="FNT1611",AO$2="FNT1610",AO$2="FNT1609"),$G12/3,""),IF($F12="FNT1608-H",IF(OR(AO$2="FNT1618",AO$2="FNT1619",AO$2="FNT1620"),$G12/3,""),IF($F12="FNT1608-I",IF(AO$2="FNT1653",$G12*2/6,IF(AO$2="FNT1654",$G12*1/6,IF(AO$2="FNT1655",$G12*1/6,IF(AO$2="FNT1657",$G12*2/6,"")))),IF($F12="FNT1608-K",IF(AO$2="FNT1653",$G12*1/6,IF(AO$2="FNT1654",$G12*2/6,IF(AO$2="FNT1655",$G12*1/6,IF(AO$2="FNT1657",$G12*2/6,"")))),IF($F12=AO$2,$G12,""))))),"") | AP12: 2.12 | AQ12: =SUM(J12:AO12)*AP12 -> 508.8 | AR12: =AQ12*7.75 -> 3943.2
A13: 45887 | B13: 45992 | C13: V1 | E13: POUK10310 | F13: FNT1612 | G13: 480 | H13: 7L包装+RPET吸塑 | I13: =IFERROR(VLOOKUP(F13,名称!A:C,3,0),"") -> FNT | J13: =IF(AND($F13=J$2,$G13>0),$G13,"") | K13: =IF(AND($F13=K$2,$G13>0),$G13,"") | L13: =IF(AND($F13=L$2,$G13>0),$G13,"") | M13: =IF(AND($F13=M$2,$G13>0),$G13,"") | N13: =IF(AND($F13=N$2,$G13>0),$G13,"") | O13: =IF(AND($F13=O$2,$G13>0),$G13,"") | P13: =IF(AND($F13=P$2,$G13>0),$G13,"") -> 480 | Q13: =IF(AND($F13=Q$2,$G13>0),$G13,"") | ... AC13: =IF(AND($F13=AC$2,$G13>0),$G13,"") | AD13: =IF(AND($G13>0,$F13<>""),IF(OR($F13="FNT1608-G",$F13="FNT1675-G"),IF(OR(AD$2="FNT1611",AD$2="FNT1610",AD$2="FNT1609"),$G13/3,""),IF($F13=AD$2,$G13,"")),"") | AE13: =IF(AND($G13>0,$F13<>""),IF(OR($F13="FNT1608-G",$F13="FNT1675-G"),IF(OR(AE$2="FNT1611",AE$2="FNT1610",AE$2="FNT1609"),$G13/3,""),IF($F13=AE$2,$G13,"")),"") | AF13: =IF(AND($G13>0,$F13<>""),IF(OR($F13="FNT1608-G",$F13="FNT1675-G"),IF(OR(AF$2="FNT1611",AF$2="FNT1610",AF$2="FNT1609"),$G13/3,""),IF($F13=AF$2,$G13,"")),"") | AG13: =IF(AND($G13>0,$F13<>""),IF($F13="FNT1608-H",IF(OR(AG$2="FNT1618",AG$2="FNT1619",AG$2="FNT1620"),$G13/3,""),IF($F13=AG$2,$G13,"")),"") | AH13: =IF(AND($G13>0,$F13<>""),IF($F13="FNT1608-H",IF(OR(AH$2="FNT1618",AH$2="FNT1619",AH$2="FNT1620"),$G13/3,""),IF($F13=AH$2,$G13,"")),"") | AI13: =IF(AND($G13>0,$F13<>""),IF($F13="FNT1608-H",IF(OR(AI$2="FNT1618",AI$2="FNT1619",AI$2="FNT1620"),$G13/3,""),IF($F13=AI$2,$G13,"")),"") | AJ13: =IF(AND($G13>0,$F13<>""),IF($F13="FNT1608-I",IF(AJ$2="FNT1653",$G13*2/6,IF(AJ$2="FNT1654",$G13*1/6,IF(AJ$2="FNT1655",$G13*1/6,IF(AJ$2="FNT1657",$G13*2/6,"")))),IF($F13="FNT1608-K",IF(AJ$2="FNT1653",$G13*1/6,IF(AJ$2="FNT1654",$G13*2/6,IF(AJ$2="FNT1655",$G13*1/6,IF(AJ$2="FNT1657",$G13*2/6,"")))),IF($F13=AJ$2,$G13,""))),"") | AK13: =IF(AND($G13>0,$F13<>""),IF($F13="FNT1608-I",IF(AK$2="FNT1653",$G13*2/6,IF(AK$2="FNT1654",$G13*1/6,IF(AK$2="FNT1655",$G13*1/6,IF(AK$2="FNT1657",$G13*2/6,"")))),IF($F13="FNT1608-K",IF(AK$2="FNT1653",$G13*1/6,IF(AK$2="FNT1654",$G13*2/6,IF(AK$2="FNT1655",$G13*1/6,IF(AK$2="FNT1657",$G13*2/6,"")))),IF($F13=AK$2,$G13,""))),"") | AL13: =IF(AND($G13>0,$F13<>""),IF($F13="FNT1608-I",IF(AL$2="FNT1653",$G13*2/6,IF(AL$2="FNT1654",$G13*1/6,IF(AL$2="FNT1655",$G13*1/6,IF(AL$2="FNT1657",$G13*2/6,"")))),IF($F13="FNT1608-K",IF(AL$2="FNT1653",$G13*1/6,IF(AL$2="FNT1654",$G13*2/6,IF(AL$2="FNT1655",$G13*1/6,IF(AL$2="FNT1657",$G13*2/6,"")))),IF($F13=AL$2,$G13,""))),"") | AM13: =IF(AND($G13>0,$F13<>""),IF($F13="FNT1608-I",IF(AM$2="FNT1653",$G13*2/6,IF(AM$2="FNT1654",$G13*1/6,IF(AM$2="FNT1655",$G13*1/6,IF(AM$2="FNT1657",$G13*2/6,"")))),IF($F13="FNT1608-K",IF(AM$2="FNT1653",$G13*1/6,IF(AM$2="FNT1654",$G13*2/6,IF(AM$2="FNT1655",$G13*1/6,IF(AM$2="FNT1657",$G13*2/6,"")))),IF($F13=AM$2,$G13,""))),"") | AN13: =IF(AND($G13>0,$F13<>""),IF(OR($F13="FNT1608-G",$F13="FNT1675-G"),IF(OR(AN$2="FNT1611",AN$2="FNT1610",AN$2="FNT1609"),$G13/3,""),IF($F13="FNT1608-H",IF(OR(AN$2="FNT1618",AN$2="FNT1619",AN$2="FNT1620"),$G13/3,""),IF($F13="FNT1608-I",IF(AN$2="FNT1653",$G13*2/6,IF(AN$2="FNT1654",$G13*1/6,IF(AN$2="FNT1655",$G13*1/6,IF(AN$2="FNT1657",$G13*2/6,"")))),IF($F13="FNT1608-K",IF(AN$2="FNT1653",$G13*1/6,IF(AN$2="FNT1654",$G13*2/6,IF(AN$2="FNT1655",$G13*1/6,IF(AN$2="FNT1657",$G13*2/6,"")))),IF($F13=AN$2,$G13,""))))),"") | AO13: =IF(AND($G13>0,$F13<>""),IF(OR($F13="FNT1608-G",$F13="FNT1675-G"),IF(OR(AO$2="FNT1611",AO$2="FNT1610",AO$2="FNT1609"),$G13/3,""),IF($F13="FNT1608-H",IF(OR(AO$2="FNT1618",AO$2="FNT1619",AO$2="FNT1620"),$G13/3,""),IF($F13="FNT1608-I",IF(AO$2="FNT1653",$G13*2/6,IF(AO$2="FNT1654",$G13*1/6,IF(AO$2="FNT1655",$G13*1/6,IF(AO$2="FNT1657",$G13*2/6,"")))),IF($F13="FNT1608-K",IF(AO$2="FNT1653",$G13*1/6,IF(AO$2="FNT1654",$G13*2/6,IF(AO$2="FNT1655",$G13*1/6,IF(AO$2="FNT1657",$G13*2/6,"")))),IF($F13=AO$2,$G13,""))))),"") | AP13: 2.12 | AQ13: =SUM(J13:AO13)*AP13 -> 1017.6 | AR13: =AQ13*7.75 -> 7886.4
A14: 45887 | B14: 45992 | C14: V1 | E14: POUK10310 | F14: FNT1612 | G14: =804+240+480+480-804-240-480 -> 480 | H14: 7L包装+RPET吸塑 | I14: =IFERROR(VLOOKUP(F14,名称!A:C,3,0),"") -> FNT | J14: =IF(AND($F14=J$2,$G14>0),$G14,"") | K14: =IF(AND($F14=K$2,$G14>0),$G14,"") | L14: =IF(AND($F14=L$2,$G14>0),$G14,"") | M14: =IF(AND($F14=M$2,$G14>0),$G14,"") | N14: =IF(AND($F14=N$2,$G14>0),$G14,"") | O14: =IF(AND($F14=O$2,$G14>0),$G14,"") | P14: =IF(AND($F14=P$2,$G14>0),$G14,"") -> 480 | Q14: =IF(AND($F14=Q$2,$G14>0),$G14,"") | ... AC14: =IF(AND($F14=AC$2,$G14>0),$G14,"") | AD14: =IF(AND($G14>0,$F14<>""),IF(OR($F14="FNT1608-G",$F14="FNT1675-G"),IF(OR(AD$2="FNT1611",AD$2="FNT1610",AD$2="FNT1609"),$G14/3,""),IF($F14=AD$2,$G14,"")),"") | AE14: =IF(AND($G14>0,$F14<>""),IF(OR($F14="FNT1608-G",$F14="FNT1675-G"),IF(OR(AE$2="FNT1611",AE$2="FNT1610",AE$2="FNT1609"),$G14/3,""),IF($F14=AE$2,$G14,"")),"") | AF14: =IF(AND($G14>0,$F14<>""),IF(OR($F14="FNT1608-G",$F14="FNT1675-G"),IF(OR(AF$2="FNT1611",AF$2="FNT1610",AF$2="FNT1609"),$G14/3,""),IF($F14=AF$2,$G14,"")),"") | AG14: =IF(AND($G14>0,$F14<>""),IF($F14="FNT1608-H",IF(OR(AG$2="FNT1618",AG$2="FNT1619",AG$2="FNT1620"),$G14/3,""),IF($F14=AG$2,$G14,"")),"") | AH14: =IF(AND($G14>0,$F14<>""),IF($F14="FNT1608-H",IF(OR(AH$2="FNT1618",AH$2="FNT1619",AH$2="FNT1620"),$G14/3,""),IF($F14=AH$2,$G14,"")),"") | AI14: =IF(AND($G14>0,$F14<>""),IF($F14="FNT1608-H",IF(OR(AI$2="FNT1618",AI$2="FNT1619",AI$2="FNT1620"),$G14/3,""),IF($F14=AI$2,$G14,"")),"") | AJ14: =IF(AND($G14>0,$F14<>""),IF($F14="FNT1608-I",IF(AJ$2="FNT1653",$G14*2/6,IF(AJ$2="FNT1654",$G14*1/6,IF(AJ$2="FNT1655",$G14*1/6,IF(AJ$2="FNT1657",$G14*2/6,"")))),IF($F14="FNT1608-K",IF(AJ$2="FNT1653",$G14*1/6,IF(AJ$2="FNT1654",$G14*2/6,IF(AJ$2="FNT1655",$G14*1/6,IF(AJ$2="FNT1657",$G14*2/6,"")))),IF($F14=AJ$2,$G14,""))),"") | AK14: =IF(AND($G14>0,$F14<>""),IF($F14="FNT1608-I",IF(AK$2="FNT1653",$G14*2/6,IF(AK$2="FNT1654",$G14*1/6,IF(AK$2="FNT1655",$G14*1/6,IF(AK$2="FNT1657",$G14*2/6,"")))),IF($F14="FNT1608-K",IF(AK$2="FNT1653",$G14*1/6,IF(AK$2="FNT1654",$G14*2/6,IF(AK$2="FNT1655",$G14*1/6,IF(AK$2="FNT1657",$G14*2/6,"")))),IF($F14=AK$2,$G14,""))),"") | AL14: =IF(AND($G14>0,$F14<>""),IF($F14="FNT1608-I",IF(AL$2="FNT1653",$G14*2/6,IF(AL$2="FNT1654",$G14*1/6,IF(AL$2="FNT1655",$G14*1/6,IF(AL$2="FNT1657",$G14*2/6,"")))),IF($F14="FNT1608-K",IF(AL$2="FNT1653",$G14*1/6,IF(AL$2="FNT1654",$G14*2/6,IF(AL$2="FNT1655",$G14*1/6,IF(AL$2="FNT1657",$G14*2/6,"")))),IF($F14=AL$2,$G14,""))),"") | AM14: =IF(AND($G14>0,$F14<>""),IF($F14="FNT1608-I",IF(AM$2="FNT1653",$G14*2/6,IF(AM$2="FNT1654",$G14*1/6,IF(AM$2="FNT1655",$G14*1/6,IF(AM$2="FNT1657",$G14*2/6,"")))),IF($F14="FNT1608-K",IF(AM$2="FNT1653",$G14*1/6,IF(AM$2="FNT1654",$G14*2/6,IF(AM$2="FNT1655",$G14*1/6,IF(AM$2="FNT1657",$G14*2/6,"")))),IF($F14=AM$2,$G14,""))),"") | AN14: =IF(AND($G14>0,$F14<>""),IF(OR($F14="FNT1608-G",$F14="FNT1675-G"),IF(OR(AN$2="FNT1611",AN$2="FNT1610",AN$2="FNT1609"),$G14/3,""),IF($F14="FNT1608-H",IF(OR(AN$2="FNT1618",AN$2="FNT1619",AN$2="FNT1620"),$G14/3,""),IF($F14="FNT1608-I",IF(AN$2="FNT1653",$G14*2/6,IF(AN$2="FNT1654",$G14*1/6,IF(AN$2="FNT1655",$G14*1/6,IF(AN$2="FNT1657",$G14*2/6,"")))),IF($F14="FNT1608-K",IF(AN$2="FNT1653",$G14*1/6,IF(AN$2="FNT1654",$G14*2/6,IF(AN$2="FNT1655",$G14*1/6,IF(AN$2="FNT1657",$G14*2/6,"")))),IF($F14=AN$2,$G14,""))))),"") | AO14: =IF(AND($G14>0,$F14<>""),IF(OR($F14="FNT1608-G",$F14="FNT1675-G"),IF(OR(AO$2="FNT1611",AO$2="FNT1610",AO$2="FNT1609"),$G14/3,""),IF($F14="FNT1608-H",IF(OR(AO$2="FNT1618",AO$2="FNT1619",AO$2="FNT1620"),$G14/3,""),IF($F14="FNT1608-I",IF(AO$2="FNT1653",$G14*2/6,IF(AO$2="FNT1654",$G14*1/6,IF(AO$2="FNT1655",$G14*1/6,IF(AO$2="FNT1657",$G14*2/6,"")))),IF($F14="FNT1608-K",IF(AO$2="FNT1653",$G14*1/6,IF(AO$2="FNT1654",$G14*2/6,IF(AO$2="FNT1655",$G14*1/6,IF(AO$2="FNT1657",$G14*2/6,"")))),IF($F14=AO$2,$G14,""))))),"") | AP14: 2.12 | AQ14: =SUM(J14:AO14)*AP14 -> 1017.6 | AR14: =AQ14*7.75 -> 7886.4
A15: 45887 | B15: 46028 | C15: V1 | E15: POUK10311 | F15: FNT1609 | G15: 900 | H15: 7L包装+RPET吸塑 | I15: =IFERROR(VLOOKUP(F15,名称!A:C,3,0),"") -> FNT | J15: =IF(AND($F15=J$2,$G15>0),$G15,"") | K15: =IF(AND($F15=K$2,$G15>0),$G15,"") | L15: =IF(AND($F15=L$2,$G15>0),$G15,"") | M15: =IF(AND($F15=M$2,$G15>0),$G15,"") | N15: =IF(AND($F15=N$2,$G15>0),$G15,"") | O15: =IF(AND($F15=O$2,$G15>0),$G15,"") | P15: =IF(AND($F15=P$2,$G15>0),$G15,"") | Q15: =IF(AND($F15=Q$2,$G15>0),$G15,"") | ... AC15: =IF(AND($F15=AC$2,$G15>0),$G15,"") | AD15: =IF(AND($G15>0,$F15<>""),IF(OR($F15="FNT1608-G",$F15="FNT1675-G"),IF(OR(AD$2="FNT1611",AD$2="FNT1610",AD$2="FNT1609"),$G15/3,""),IF($F15=AD$2,$G15,"")),"") | AE15: =IF(AND($G15>0,$F15<>""),IF(OR($F15="FNT1608-G",$F15="FNT1675-G"),IF(OR(AE$2="FNT1611",AE$2="FNT1610",AE$2="FNT1609"),$G15/3,""),IF($F15=AE$2,$G15,"")),"") | AF15: =IF(AND($G15>0,$F15<>""),IF(OR($F15="FNT1608-G",$F15="FNT1675-G"),IF(OR(AF$2="FNT1611",AF$2="FNT1610",AF$2="FNT1609"),$G15/3,""),IF($F15=AF$2,$G15,"")),"") -> 900 | AG15: =IF(AND($G15>0,$F15<>""),IF($F15="FNT1608-H",IF(OR(AG$2="FNT1618",AG$2="FNT1619",AG$2="FNT1620"),$G15/3,""),IF($F15=AG$2,$G15,"")),"") | AH15: =IF(AND($G15>0,$F15<>""),IF($F15="FNT1608-H",IF(OR(AH$2="FNT1618",AH$2="FNT1619",AH$2="FNT1620"),$G15/3,""),IF($F15=AH$2,$G15,"")),"") | AI15: =IF(AND($G15>0,$F15<>""),IF($F15="FNT1608-H",IF(OR(AI$2="FNT1618",AI$2="FNT1619",AI$2="FNT1620"),$G15/3,""),IF($F15=AI$2,$G15,"")),"") | AJ15: =IF(AND($G15>0,$F15<>""),IF($F15="FNT1608-I",IF(AJ$2="FNT1653",$G15*2/6,IF(AJ$2="FNT1654",$G15*1/6,IF(AJ$2="FNT1655",$G15*1/6,IF(AJ$2="FNT1657",$G15*2/6,"")))),IF($F15="FNT1608-K",IF(AJ$2="FNT1653",$G15*1/6,IF(AJ$2="FNT1654",$G15*2/6,IF(AJ$2="FNT1655",$G15*1/6,IF(AJ$2="FNT1657",$G15*2/6,"")))),IF($F15=AJ$2,$G15,""))),"") | AK15: =IF(AND($G15>0,$F15<>""),IF($F15="FNT1608-I",IF(AK$2="FNT1653",$G15*2/6,IF(AK$2="FNT1654",$G15*1/6,IF(AK$2="FNT1655",$G15*1/6,IF(AK$2="FNT1657",$G15*2/6,"")))),IF($F15="FNT1608-K",IF(AK$2="FNT1653",$G15*1/6,IF(AK$2="FNT1654",$G15*2/6,IF(AK$2="FNT1655",$G15*1/6,IF(AK$2="FNT1657",$G15*2/6,"")))),IF($F15=AK$2,$G15,""))),"") | AL15: =IF(AND($G15>0,$F15<>""),IF($F15="FNT1608-I",IF(AL$2="FNT1653",$G15*2/6,IF(AL$2="FNT1654",$G15*1/6,IF(AL$2="FNT1655",$G15*1/6,IF(AL$2="FNT1657",$G15*2/6,"")))),IF($F15="FNT1608-K",IF(AL$2="FNT1653",$G15*1/6,IF(AL$2="FNT1654",$G15*2/6,IF(AL$2="FNT1655",$G15*1/6,IF(AL$2="FNT1657",$G15*2/6,"")))),IF($F15=AL$2,$G15,""))),"") | AM15: =IF(AND($G15>0,$F15<>""),IF($F15="FNT1608-I",IF(AM$2="FNT1653",$G15*2/6,IF(AM$2="FNT1654",$G15*1/6,IF(AM$2="FNT1655",$G15*1/6,IF(AM$2="FNT1657",$G15*2/6,"")))),IF($F15="FNT1608-K",IF(AM$2="FNT1653",$G15*1/6,IF(AM$2="FNT1654",$G15*2/6,IF(AM$2="FNT1655",$G15*1/6,IF(AM$2="FNT1657",$G15*2/6,"")))),IF($F15=AM$2,$G15,""))),"") | AN15: =IF(AND($G15>0,$F15<>""),IF(OR($F15="FNT1608-G",$F15="FNT1675-G"),IF(OR(AN$2="FNT1611",AN$2="FNT1610",AN$2="FNT1609"),$G15/3,""),IF($F15="FNT1608-H",IF(OR(AN$2="FNT1618",AN$2="FNT1619",AN$2="FNT1620"),$G15/3,""),IF($F15="FNT1608-I",IF(AN$2="FNT1653",$G15*2/6,IF(AN$2="FNT1654",$G15*1/6,IF(AN$2="FNT1655",$G15*1/6,IF(AN$2="FNT1657",$G15*2/6,"")))),IF($F15="FNT1608-K",IF(AN$2="FNT1653",$G15*1/6,IF(AN$2="FNT1654",$G15*2/6,IF(AN$2="FNT1655",$G15*1/6,IF(AN$2="FNT1657",$G15*2/6,"")))),IF($F15=AN$2,$G15,""))))),"") | AO15: =IF(AND($G15>0,$F15<>""),IF(OR($F15="FNT1608-G",$F15="FNT1675-G"),IF(OR(AO$2="FNT1611",AO$2="FNT1610",AO$2="FNT1609"),$G15/3,""),IF($F15="FNT1608-H",IF(OR(AO$2="FNT1618",AO$2="FNT1619",AO$2="FNT1620"),$G15/3,""),IF($F15="FNT1608-I",IF(AO$2="FNT1653",$G15*2/6,IF(AO$2="FNT1654",$G15*1/6,IF(AO$2="FNT1655",$G15*1/6,IF(AO$2="FNT1657",$G15*2/6,"")))),IF($F15="FNT1608-K",IF(AO$2="FNT1653",$G15*1/6,IF(AO$2="FNT1654",$G15*2/6,IF(AO$2="FNT1655",$G15*1/6,IF(AO$2="FNT1657",$G15*2/6,"")))),IF($F15=AO$2,$G15,""))))),"") | AP15: 2.13 | AQ15: =SUM(J15:AO15)*AP15 -> 1917 | AR15: =AQ15*7.75 -> 14856.75
A16: 45887 | B16: 46028 | C16: V1 | E16: POUK10311 | F16: FNT1611 | G16: 1002 | H16: 7L包装+RPET吸塑 | I16: =IFERROR(VLOOKUP(F16,名称!A:C,3,0),"") -> FNT | J16: =IF(AND($F16=J$2,$G16>0),$G16,"") | K16: =IF(AND($F16=K$2,$G16>0),$G16,"") | L16: =IF(AND($F16=L$2,$G16>0),$G16,"") | M16: =IF(AND($F16=M$2,$G16>0),$G16,"") | N16: =IF(AND($F16=N$2,$G16>0),$G16,"") | O16: =IF(AND($F16=O$2,$G16>0),$G16,"") | P16: =IF(AND($F16=P$2,$G16>0),$G16,"") | Q16: =IF(AND($F16=Q$2,$G16>0),$G16,"") | ... AC16: =IF(AND($F16=AC$2,$G16>0),$G16,"") | AD16: =IF(AND($G16>0,$F16<>""),IF(OR($F16="FNT1608-G",$F16="FNT1675-G"),IF(OR(AD$2="FNT1611",AD$2="FNT1610",AD$2="FNT1609"),$G16/3,""),IF($F16=AD$2,$G16,"")),"") -> 1002 | AE16: =IF(AND($G16>0,$F16<>""),IF(OR($F16="FNT1608-G",$F16="FNT1675-G"),IF(OR(AE$2="FNT1611",AE$2="FNT1610",AE$2="FNT1609"),$G16/3,""),IF($F16=AE$2,$G16,"")),"") | AF16: =IF(AND($G16>0,$F16<>""),IF(OR($F16="FNT1608-G",$F16="FNT1675-G"),IF(OR(AF$2="FNT1611",AF$2="FNT1610",AF$2="FNT1609"),$G16/3,""),IF($F16=AF$2,$G16,"")),"") | AG16: =IF(AND($G16>0,$F16<>""),IF($F16="FNT1608-H",IF(OR(AG$2="FNT1618",AG$2="FNT1619",AG$2="FNT1620"),$G16/3,""),IF($F16=AG$2,$G16,"")),"") | AH16: =IF(AND($G16>0,$F16<>""),IF($F16="FNT1608-H",IF(OR(AH$2="FNT1618",AH$2="FNT1619",AH$2="FNT1620"),$G16/3,""),IF($F16=AH$2,$G16,"")),"") | AI16: =IF(AND($G16>0,$F16<>""),IF($F16="FNT1608-H",IF(OR(AI$2="FNT1618",AI$2="FNT1619",AI$2="FNT1620"),$G16/3,""),IF($F16=AI$2,$G16,"")),"") | AJ16: =IF(AND($G16>0,$F16<>""),IF($F16="FNT1608-I",IF(AJ$2="FNT1653",$G16*2/6,IF(AJ$2="FNT1654",$G16*1/6,IF(AJ$2="FNT1655",$G16*1/6,IF(AJ$2="FNT1657",$G16*2/6,"")))),IF($F16="FNT1608-K",IF(AJ$2="FNT1653",$G16*1/6,IF(AJ$2="FNT1654",$G16*2/6,IF(AJ$2="FNT1655",$G16*1/6,IF(AJ$2="FNT1657",$G16*2/6,"")))),IF($F16=AJ$2,$G16,""))),"") | AK16: =IF(AND($G16>0,$F16<>""),IF($F16="FNT1608-I",IF(AK$2="FNT1653",$G16*2/6,IF(AK$2="FNT1654",$G16*1/6,IF(AK$2="FNT1655",$G16*1/6,IF(AK$2="FNT1657",$G16*2/6,"")))),IF($F16="FNT1608-K",IF(AK$2="FNT1653",$G16*1/6,IF(AK$2="FNT1654",$G16*2/6,IF(AK$2="FNT1655",$G16*1/6,IF(AK$2="FNT1657",$G16*2/6,"")))),IF($F16=AK$2,$G16,""))),"") | AL16: =IF(AND($G16>0,$F16<>""),IF($F16="FNT1608-I",IF(AL$2="FNT1653",$G16*2/6,IF(AL$2="FNT1654",$G16*1/6,IF(AL$2="FNT1655",$G16*1/6,IF(AL$2="FNT1657",$G16*2/6,"")))),IF($F16="FNT1608-K",IF(AL$2="FNT1653",$G16*1/6,IF(AL$2="FNT1654",$G16*2/6,IF(AL$2="FNT1655",$G16*1/6,IF(AL$2="FNT1657",$G16*2/6,"")))),IF($F16=AL$2,$G16,""))),"") | AM16: =IF(AND($G16>0,$F16<>""),IF($F16="FNT1608-I",IF(AM$2="FNT1653",$G16*2/6,IF(AM$2="FNT1654",$G16*1/6,IF(AM$2="FNT1655",$G16*1/6,IF(AM$2="FNT1657",$G16*2/6,"")))),IF($F16="FNT1608-K",IF(AM$2="FNT1653",$G16*1/6,IF(AM$2="FNT1654",$G16*2/6,IF(AM$2="FNT1655",$G16*1/6,IF(AM$2="FNT1657",$G16*2/6,"")))),IF($F16=AM$2,$G16,""))),"") | AN16: =IF(AND($G16>0,$F16<>""),IF(OR($F16="FNT1608-G",$F16="FNT1675-G"),IF(OR(AN$2="FNT1611",AN$2="FNT1610",AN$2="FNT1609"),$G16/3,""),IF($F16="FNT1608-H",IF(OR(AN$2="FNT1618",AN$2="FNT1619",AN$2="FNT1620"),$G16/3,""),IF($F16="FNT1608-I",IF(AN$2="FNT1653",$G16*2/6,IF(AN$2="FNT1654",$G16*1/6,IF(AN$2="FNT1655",$G16*1/6,IF(AN$2="FNT1657",$G16*2/6,"")))),IF($F16="FNT1608-K",IF(AN$2="FNT1653",$G16*1/6,IF(AN$2="FNT1654",$G16*2/6,IF(AN$2="FNT1655",$G16*1/6,IF(AN$2="FNT1657",$G16*2/6,"")))),IF($F16=AN$2,$G16,""))))),"") | AO16: =IF(AND($G16>0,$F16<>""),IF(OR($F16="FNT1608-G",$F16="FNT1675-G"),IF(OR(AO$2="FNT1611",AO$2="FNT1610",AO$2="FNT1609"),$G16/3,""),IF($F16="FNT1608-H",IF(OR(AO$2="FNT1618",AO$2="FNT1619",AO$2="FNT1620"),$G16/3,""),IF($F16="FNT1608-I",IF(AO$2="FNT1653",$G16*2/6,IF(AO$2="FNT1654",$G16*1/6,IF(AO$2="FNT1655",$G16*1/6,IF(AO$2="FNT1657",$G16*2/6,"")))),IF($F16="FNT1608-K",IF(AO$2="FNT1653",$G16*1/6,IF(AO$2="FNT1654",$G16*2/6,IF(AO$2="FNT1655",$G16*1/6,IF(AO$2="FNT1657",$G16*2/6,"")))),IF($F16=AO$2,$G16,""))))),"") | AP16: 1.88 | AQ16: =SUM(J16:AO16)*AP16 -> 1883.76 | AR16: =AQ16*7.75 -> 14599.14
A17: 45887 | B17: 45948 | C17: V1 | E17: POUK10066 | F17: FNT1611 | G17: 1002 | H17: 7L包装+RPET吸塑 | I17: =IFERROR(VLOOKUP(F17,名称!A:C,3,0),"") -> FNT | J17: =IF(AND($F17=J$2,$G17>0),$G17,"") | K17: =IF(AND($F17=K$2,$G17>0),$G17,"") | L17: =IF(AND($F17=L$2,$G17>0),$G17,"") | M17: =IF(AND($F17=M$2,$G17>0),$G17,"") | N17: =IF(AND($F17=N$2,$G17>0),$G17,"") | O17: =IF(AND($F17=O$2,$G17>0),$G17,"") | P17: =IF(AND($F17=P$2,$G17>0),$G17,"") | Q17: =IF(AND($F17=Q$2,$G17>0),$G17,"") | ... AC17: =IF(AND($F17=AC$2,$G17>0),$G17,"") | AD17: =IF(AND($G17>0,$F17<>""),IF(OR($F17="FNT1608-G",$F17="FNT1675-G"),IF(OR(AD$2="FNT1611",AD$2="FNT1610",AD$2="FNT1609"),$G17/3,""),IF($F17=AD$2,$G17,"")),"") -> 1002 | AE17: =IF(AND($G17>0,$F17<>""),IF(OR($F17="FNT1608-G",$F17="FNT1675-G"),IF(OR(AE$2="FNT1611",AE$2="FNT1610",AE$2="FNT1609"),$G17/3,""),IF($F17=AE$2,$G17,"")),"") | AF17: =IF(AND($G17>0,$F17<>""),IF(OR($F17="FNT1608-G",$F17="FNT1675-G"),IF(OR(AF$2="FNT1611",AF$2="FNT1610",AF$2="FNT1609"),$G17/3,""),IF($F17=AF$2,$G17,"")),"") | AG17: =IF(AND($G17>0,$F17<>""),IF($F17="FNT1608-H",IF(OR(AG$2="FNT1618",AG$2="FNT1619",AG$2="FNT1620"),$G17/3,""),IF($F17=AG$2,$G17,"")),"") | AH17: =IF(AND($G17>0,$F17<>""),IF($F17="FNT1608-H",IF(OR(AH$2="FNT1618",AH$2="FNT1619",AH$2="FNT1620"),$G17/3,""),IF($F17=AH$2,$G17,"")),"") | AI17: =IF(AND($G17>0,$F17<>""),IF($F17="FNT1608-H",IF(OR(AI$2="FNT1618",AI$2="FNT1619",AI$2="FNT1620"),$G17/3,""),IF($F17=AI$2,$G17,"")),"") | AJ17: =IF(AND($G17>0,$F17<>""),IF($F17="FNT1608-I",IF(AJ$2="FNT1653",$G17*2/6,IF(AJ$2="FNT1654",$G17*1/6,IF(AJ$2="FNT1655",$G17*1/6,IF(AJ$2="FNT1657",$G17*2/6,"")))),IF($F17="FNT1608-K",IF(AJ$2="FNT1653",$G17*1/6,IF(AJ$2="FNT1654",$G17*2/6,IF(AJ$2="FNT1655",$G17*1/6,IF(AJ$2="FNT1657",$G17*2/6,"")))),IF($F17=AJ$2,$G17,""))),"") | AK17: =IF(AND($G17>0,$F17<>""),IF($F17="FNT1608-I",IF(AK$2="FNT1653",$G17*2/6,IF(AK$2="FNT1654",$G17*1/6,IF(AK$2="FNT1655",$G17*1/6,IF(AK$2="FNT1657",$G17*2/6,"")))),IF($F17="FNT1608-K",IF(AK$2="FNT1653",$G17*1/6,IF(AK$2="FNT1654",$G17*2/6,IF(AK$2="FNT1655",$G17*1/6,IF(AK$2="FNT1657",$G17*2/6,"")))),IF($F17=AK$2,$G17,""))),"") | AL17: =IF(AND($G17>0,$F17<>""),IF($F17="FNT1608-I",IF(AL$2="FNT1653",$G17*2/6,IF(AL$2="FNT1654",$G17*1/6,IF(AL$2="FNT1655",$G17*1/6,IF(AL$2="FNT1657",$G17*2/6,"")))),IF($F17="FNT1608-K",IF(AL$2="FNT1653",$G17*1/6,IF(AL$2="FNT1654",$G17*2/6,IF(AL$2="FNT1655",$G17*1/6,IF(AL$2="FNT1657",$G17*2/6,"")))),IF($F17=AL$2,$G17,""))),"") | AM17: =IF(AND($G17>0,$F17<>""),IF($F17="FNT1608-I",IF(AM$2="FNT1653",$G17*2/6,IF(AM$2="FNT1654",$G17*1/6,IF(AM$2="FNT1655",$G17*1/6,IF(AM$2="FNT1657",$G17*2/6,"")))),IF($F17="FNT1608-K",IF(AM$2="FNT1653",$G17*1/6,IF(AM$2="FNT1654",$G17*2/6,IF(AM$2="FNT1655",$G17*1/6,IF(AM$2="FNT1657",$G17*2/6,"")))),IF($F17=AM$2,$G17,""))),"") | AN17: =IF(AND($G17>0,$F17<>""),IF(OR($F17="FNT1608-G",$F17="FNT1675-G"),IF(OR(AN$2="FNT1611",AN$2="FNT1610",AN$2="FNT1609"),$G17/3,""),IF($F17="FNT1608-H",IF(OR(AN$2="FNT1618",AN$2="FNT1619",AN$2="FNT1620"),$G17/3,""),IF($F17="FNT1608-I",IF(AN$2="FNT1653",$G17*2/6,IF(AN$2="FNT1654",$G17*1/6,IF(AN$2="FNT1655",$G17*1/6,IF(AN$2="FNT1657",$G17*2/6,"")))),IF($F17="FNT1608-K",IF(AN$2="FNT1653",$G17*1/6,IF(AN$2="FNT1654",$G17*2/6,IF(AN$2="FNT1655",$G17*1/6,IF(AN$2="FNT1657",$G17*2/6,"")))),IF($F17=AN$2,$G17,""))))),"") | AO17: =IF(AND($G17>0,$F17<>""),IF(OR($F17="FNT1608-G",$F17="FNT1675-G"),IF(OR(AO$2="FNT1611",AO$2="FNT1610",AO$2="FNT1609"),$G17/3,""),IF($F17="FNT1608-H",IF(OR(AO$2="FNT1618",AO$2="FNT1619",AO$2="FNT1620"),$G17/3,""),IF($F17="FNT1608-I",IF(AO$2="FNT1653",$G17*2/6,IF(AO$2="FNT1654",$G17*1/6,IF(AO$2="FNT1655",$G17*1/6,IF(AO$2="FNT1657",$G17*2/6,"")))),IF($F17="FNT1608-K",IF(AO$2="FNT1653",$G17*1/6,IF(AO$2="FNT1654",$G17*2/6,IF(AO$2="FNT1655",$G17*1/6,IF(AO$2="FNT1657",$G17*2/6,"")))),IF($F17=AO$2,$G17,""))))),"") | AP17: 1.88 | AQ17: =SUM(J17:AO17)*AP17 -> 1883.76 | AR17: =AQ17*7.75 -> 14599.14
