Workbook

Sheet 名称
A1: 货号 | B1: PWP系统货号 | C1: 名称 | D1: 描述 | E1: 内箱 | F1: 外箱
A2: LM986 | B2: V553D/80-LS | C2: 桶装野生动物 | D2: WILD ANIMAL COUNTERS | E2: 6 | F2: 24
A3: 142BT | B3: 1083DN | C3: 蝙蝠 | D3: 5.5" BLACK BAT | E3: 144 | F3: 864
A4: 411CR | B4: 913DCR-LA | C4: 饼干 | D4: CRACKER | E4: 120 | F4: 360
A5: 682TC | B5: 98DTZ/2-N | C5: 2只2寸小老虎 | D5: 2 ASSTD. 2" TIGER CUB | E5: 50 | F5: 400
A6: HH994 | B6: AE-D2113D-LS | C6: 西班牙家庭 | D6: HISPANIC SOFT& SAFE FAMILY SET | E6: 0 | F6: 6
A7: HH993 | B7: AE-D2114D-LS | C7: 亚洲家庭 | D7: ASIAN SOFT & SAFE FAMILY SET | E7: 0 | F7: 6
A8: HH991 | B8: AE-D2115D-LS | C8: 非洲家庭 | D8: BLACK SOFT & SAFE FAMILY SET | E8: 0 | F8: 6
A9: HH992 | B9: AE-D2116D-LS | C9: 欧洲家庭 | D9: WHITE SOFT & SAFE FAMILY SET | E9: 0 | F9: 6
A10: GS673 | B10: AE-PT8573D-LS | C10: 巨型恐龙组1 | D10: GIANT SOFT & SAFE DINOSAURS-1 | E10: 2 | F10: 4
A11: GS675 | B11: AE-PT8574D-LS | C11: 巨型恐龙组2 | D11: GIANT SOFT & SAFE DINOSAURS-2 | E11: 0 | F11: 4
A12: RA369 | B12: AE-ZT4059D-LS | C12: 8款恐龙玩具 | D12: 8 ASSTD. DINOSAUR PLAYSET | E12: 9 | F12: 18
A13: RA362 | B13: AE-ZT4060D-LS | C13: 8款野生动物套装 | D13: 8 ASSTD. WILDLIFE PLAYSET | E13: 6 | F13: 12
... A27: P111D | B27: 154DS | C27: 5"恐龙 | D27: 8 ASSTD.5"DINOSAURS | E27: 50 | F27: 100

Sheet 总接单
A1: 产品名称
A2: 接单期 | B2: 出货期 | C2: Customer | D2: PO号 | E2: 货号 | F2: 数量 | G2: 包装版本 | H2: HH393 | I2: RA367 | J2: RA362 | K2: HH994 | L2: HH993 | M2: HH991 | N2: HH992 | O2: DC346 | P2: GS675 | Q2: RA369 | R2: LC630 | S2: 142BT | T2: 682TC | U2: 856T1 | V2: GS673 | W2: LM986 | X2: RA368 | Y2: HH429 | Z2: 376MM | AA2: 300OK | AB2: 154DS | AE2: 单价(USD) | AF2: 金额USD | AG2: 金额HKD
A3: 45840 | B3: 45915 | C3: AE-D2115D-LS | D3: 1000000721 | E3: HH991 | F3: =1602-564 -> 1038 | H3: =IF(OR($E3="",H$2=""),"",IF(TRIM(LEFT($E3,MIN(IFERROR(FIND("CDU",UPPER($E3)),999),IFERROR(FIND("BULK",UPPER($E3)),999),IFERROR(FIND("-",$E3),999),IFERROR(FIND("（",$E3),999))-1))=H$2,$F3,"")) | I3: =IF(OR($E3="",I$2=""),"",IF(TRIM(LEFT($E3,MIN(IFERROR(FIND("CDU",UPPER($E3)),999),IFERROR(FIND("BULK",UPPER($E3)),999),IFERROR(FIND("-",$E3),999),IFERROR(FIND("（",$E3),999))-1))=I$2,$F3,"")) | J3: =IF(OR($E3="",J$2=""),"",IF(TRIM(LEFT($E3,MIN(IFERROR(FIND("CDU",UPPER($E3)),999),IFERROR(FIND("BULK",UPPER($E3)),999),IFERROR(FIND("-",$E3),999),IFERROR(FIND("（",$E3),999))-1))=J$2,$F3,"")) | K3: =IF(OR($E3="",K$2=""),"",IF(TRIM(LEFT($E3,MIN(IFERROR(FIND("CDU",UPPER($E3)),999),IFERROR(FIND("BULK",UPPER($E3)),999),IFERROR(FIND("-",$E3),999),IFERROR(FIND("（",$E3),999))-1))=K$2,$F3,"")) | L3: =IF(OR($E3="",L$2=""),"",IF(TRIM(LEFT($E3,MIN(IFERROR(FIND("CDU",UPPER($E3)),999),IFERROR(FIND("BULK",UPPER($E3)),999),IFERROR(FIND("-",$E3),999),IFERROR(FIND("（",$E3),999))-1))=L$2,$F3,"")) | M3: =IF(OR($E3="",M$2=""),"",IF(TRIM(LEFT($E3,MIN(IFERROR(FIND("CDU",UPPER($E3)),999),IFERROR(FIND("BULK",UPPER($E3)),999),IFERROR(FIND("-",$E3),999),IFERROR(FIND("（",$E3),999))-1))=M$2,$F3,"")) -> 1038 | N3: =IF(OR($E3="",N$2=""),"",IF(TRIM(LEFT($E3,MIN(IFERROR(FIND("CDU",UPPER($E3)),999),IFERROR(FIND("BULK",UPPER($E3)),999),IFERROR(FIND("-",$E3),999),IFERROR(FIND("（",$E3),999))-1))=N$2,$F3,"")) | O3: =IF(OR($E3="",O$2=""),"",IF(TRIM(LEFT($E3,MIN(IFERROR(FIND("CDU",UPPER($E3)),999),IFERROR(FIND("BULK",UPPER($E3)),999),IFERROR(FIND("-",$E3),999),IFERROR(FIND("（",$E3),999))-1))=O$2,$F3,"")) | ... AD3: =IF(OR($E3="",AD$2=""),"",IF(TRIM(LEFT($E3,MIN(IFERROR(FIND("CDU",UPPER($E3)),999),IFERROR(FIND("BULK",UPPER($E3)),999),IFERROR(FIND("-",$E3),999),IFERROR(FIND("（",$E3),999))-1))=AD$2,$F3,"")) | AE3: 4.72 | AF3: =SUM(H3:AD3)*AE3 -> 4899.36 | AG3: =AF3*7.75 -> 37970.04
A4: 45840 | B4: 45915 | C4: AE-D2116D-LS | D4: 1000000721 | E4: HH992 | F4: =1602-612 -> 990 | H4: =IF(OR($E4="",H$2=""),"",IF(TRIM(LEFT($E4,MIN(IFERROR(FIND("CDU",UPPER($E4)),999),IFERROR(FIND("BULK",UPPER($E4)),999),IFERROR(FIND("-",$E4),999),IFERROR(FIND("（",$E4),999))-1))=H$2,$F4,"")) | I4: =IF(OR($E4="",I$2=""),"",IF(TRIM(LEFT($E4,MIN(IFERROR(FIND("CDU",UPPER($E4)),999),IFERROR(FIND("BULK",UPPER($E4)),999),IFERROR(FIND("-",$E4),999),IFERROR(FIND("（",$E4),999))-1))=I$2,$F4,"")) | J4: =IF(OR($E4="",J$2=""),"",IF(TRIM(LEFT($E4,MIN(IFERROR(FIND("CDU",UPPER($E4)),999),IFERROR(FIND("BULK",UPPER($E4)),999),IFERROR(FIND("-",$E4),999),IFERROR(FIND("（",$E4),999))-1))=J$2,$F4,"")) | K4: =IF(OR($E4="",K$2=""),"",IF(TRIM(LEFT($E4,MIN(IFERROR(FIND("CDU",UPPER($E4)),999),IFERROR(FIND("BULK",UPPER($E4)),999),IFERROR(FIND("-",$E4),999),IFERROR(FIND("（",$E4),999))-1))=K$2,$F4,"")) | L4: =IF(OR($E4="",L$2=""),"",IF(TRIM(LEFT($E4,MIN(IFERROR(FIND("CDU",UPPER($E4)),999),IFERROR(FIND("BULK",UPPER($E4)),999),IFERROR(FIND("-",$E4),999),IFERROR(FIND("（",$E4),999))-1))=L$2,$F4,"")) | M4: =IF(OR($E4="",M$2=""),"",IF(TRIM(LEFT($E4,MIN(IFERROR(FIND("CDU",UPPER($E4)),999),IFERROR(FIND("BULK",UPPER($E4)),999),IFERROR(FIND("-",$E4),999),IFERROR(FIND("（",$E4),999))-1))=M$2,$F4,"")) | N4: =IF(OR($E4="",N$2=""),"",IF(TRIM(LEFT($E4,MIN(IFERROR(FIND("CDU",UPPER($E4)),999),IFERROR(FIND("BULK",UPPER($E4)),999),IFERROR(FIND("-",$E4),999),IFERROR(FIND("（",$E4),999))-1))=N$2,$F4,"")) -> 990 | O4: =IF(OR($E4="",O$2=""),"",IF(TRIM(LEFT($E4,MIN(IFERROR(FIND("CDU",UPPER($E4)),999),IFERROR(FIND("BULK",UPPER($E4)),999),IFERROR(FIND("-",$E4),999),IFERROR(FIND("（",$E4),999))-1))=O$2,$F4,"")) | ... AD4: =IF(OR($E4="",AD$2=""),"",IF(TRIM(LEFT($E4,MIN(IFERROR(FIND("CDU",UPPER($E4)),999),IFERROR(FIND("BULK",UPPER($E4)),999),IFERROR(FIND("-",$E4),999),IFERROR(FIND("（",$E4),999))-1))=AD$2,$F4,"")) | AE4: 4.92 | AF4: =SUM(H4:AD4)*AE4 -> 4870.8 | AG4: =AF4*7.75 -> 37748.7
A5: 45840 | B5: 45915 | C5: AE-D2113D-LS | D5: 1000000721 | E5: HH994 | F5: =1602-1026 -> 576 | H5: =IF(OR($E5="",H$2=""),"",IF(TRIM(LEFT($E5,MIN(IFERROR(FIND("CDU",UPPER($E5)),999),IFERROR(FIND("BULK",UPPER($E5)),999),IFERROR(FIND("-",$E5),999),IFERROR(FIND("（",$E5),999))-1))=H$2,$F5,"")) | I5: =IF(OR($E5="",I$2=""),"",IF(TRIM(LEFT($E5,MIN(IFERROR(FIND("CDU",UPPER($E5)),999),IFERROR(FIND("BULK",UPPER($E5)),999),IFERROR(FIND("-",$E5),999),IFERROR(FIND("（",$E5),999))-1))=I$2,$F5,"")) | J5: =IF(OR($E5="",J$2=""),"",IF(TRIM(LEFT($E5,MIN(IFERROR(FIND("CDU",UPPER($E5)),999),IFERROR(FIND("BULK",UPPER($E5)),999),IFERROR(FIND("-",$E5),999),IFERROR(FIND("（",$E5),999))-1))=J$2,$F5,"")) | K5: =IF(OR($E5="",K$2=""),"",IF(TRIM(LEFT($E5,MIN(IFERROR(FIND("CDU",UPPER($E5)),999),IFERROR(FIND("BULK",UPPER($E5)),999),IFERROR(FIND("-",$E5),999),IFERROR(FIND("（",$E5),999))-1))=K$2,$F5,"")) -> 576 | L5: =IF(OR($E5="",L$2=""),"",IF(TRIM(LEFT($E5,MIN(IFERROR(FIND("CDU",UPPER($E5)),999),IFERROR(FIND("BULK",UPPER($E5)),999),IFERROR(FIND("-",$E5),999),IFERROR(FIND("（",$E5),999))-1))=L$2,$F5,"")) | M5: =IF(OR($E5="",M$2=""),"",IF(TRIM(LEFT($E5,MIN(IFERROR(FIND("CDU",UPPER($E5)),999),IFERROR(FIND("BULK",UPPER($E5)),999),IFERROR(FIND("-",$E5),999),IFERROR(FIND("（",$E5),999))-1))=M$2,$F5,"")) | N5: =IF(OR($E5="",N$2=""),"",IF(TRIM(LEFT($E5,MIN(IFERROR(FIND("CDU",UPPER($E5)),999),IFERROR(FIND("BULK",UPPER($E5)),999),IFERROR(FIND("-",$E5),999),IFERROR(FIND("（",$E5),999))-1))=N$2,$F5,"")) | O5: =IF(OR($E5="",O$2=""),"",IF(TRIM(LEFT($E5,MIN(IFERROR(FIND("CDU",UPPER($E5)),999),IFERROR(FIND("BULK",UPPER($E5)),999),IFERROR(FIND("-",$E5),999),IFERROR(FIND("（",$E5),999))-1))=O$2,$F5,"")) | ... AD5: =IF(OR($E5="",AD$2=""),"",IF(TRIM(LEFT($E5,MIN(IFERROR(FIND("CDU",UPPER($E5)),999),IFERROR(FIND("BULK",UPPER($E5)),999),IFERROR(FIND("-",$E5),999),IFERROR(FIND("（",$E5),999))-1))=AD$2,$F5,"")) | AE5: 4.92 | AF5: =SUM(H5:AD5)*AE5 -> 2833.92 | AG5: =AF5*7.75 -> 21962.88
A6: 45910 | B6: 45995 | C6: AE-PT8573D-LS | D6: 1000001352 | E6: GS673 | F6: =1532-340 -> 1192 | H6: =IF(OR($E6="",H$2=""),"",IF(TRIM(LEFT($E6,MIN(IFERROR(FIND("CDU",UPPER($E6)),999),IFERROR(FIND("BULK",UPPER($E6)),999),IFERROR(FIND("-",$E6),999),IFERROR(FIND("（",$E6),999))-1))=H$2,$F6,"")) | I6: =IF(OR($E6="",I$2=""),"",IF(TRIM(LEFT($E6,MIN(IFERROR(FIND("CDU",UPPER($E6)),999),IFERROR(FIND("BULK",UPPER($E6)),999),IFERROR(FIND("-",$E6),999),IFERROR(FIND("（",$E6),999))-1))=I$2,$F6,"")) | J6: =IF(OR($E6="",J$2=""),"",IF(TRIM(LEFT($E6,MIN(IFERROR(FIND("CDU",UPPER($E6)),999),IFERROR(FIND("BULK",UPPER($E6)),999),IFERROR(FIND("-",$E6),999),IFERROR(FIND("（",$E6),999))-1))=J$2,$F6,"")) | K6: =IF(OR($E6="",K$2=""),"",IF(TRIM(LEFT($E6,MIN(IFERROR(FIND("CDU",UPPER($E6)),999),IFERROR(FIND("BULK",UPPER($E6)),999),IFERROR(FIND("-",$E6),999),IFERROR(FIND("（",$E6),999))-1))=K$2,$F6,"")) | L6: =IF(OR($E6="",L$2=""),"",IF(TRIM(LEFT($E6,MIN(IFERROR(FIND("CDU",UPPER($E6)),999),IFERROR(FIND("BULK",UPPER($E6)),999),IFERROR(FIND("-",$E6),999),IFERROR(FIND("（",$E6),999))-1))=L$2,$F6,"")) | M6: =IF(OR($E6="",M$2=""),"",IF(TRIM(LEFT($E6,MIN(IFERROR(FIND("CDU",UPPER($E6)),999),IFERROR(FIND("BULK",UPPER($E6)),999),IFERROR(FIND("-",$E6),999),IFERROR(FIND("（",$E6),999))-1))=M$2,$F6,"")) | N6: =IF(OR($E6="",N$2=""),"",IF(TRIM(LEFT($E6,MIN(IFERROR(FIND("CDU",UPPER($E6)),999),IFERROR(FIND("BULK",UPPER($E6)),999),IFERROR(FIND("-",$E6),999),IFERROR(FIND("（",$E6),999))-1))=N$2,$F6,"")) | O6: =IF(OR($E6="",O$2=""),"",IF(TRIM(LEFT($E6,MIN(IFERROR(FIND("CDU",UPPER($E6)),999),IFERROR(FIND("BULK",UPPER($E6)),999),IFERROR(FIND("-",$E6),999),IFERROR(FIND("（",$E6),999))-1))=O$2,$F6,"")) | ... AD6: =IF(OR($E6="",AD$2=""),"",IF(TRIM(LEFT($E6,MIN(IFERROR(FIND("CDU",UPPER($E6)),999),IFERROR(FIND("BULK",UPPER($E6)),999),IFERROR(FIND("-",$E6),999),IFERROR(FIND("（",$E6),999))-1))=AD$2,$F6,"")) | AE6: 11.5 | AF6: =SUM(H6:AD6)*AE6 -> 13708 | AG6: =AF6*7.75 -> 106237
A7: 45910 | B7: 45995 | C7: AE-D2116D-LS | D7: 1000001352 | E7: HH992 | F7: 1602 | H7: =IF(OR($E7="",H$2=""),"",IF(TRIM(LEFT($E7,MIN(IFERROR(FIND("CDU",UPPER($E7)),999),IFERROR(FIND("BULK",UPPER($E7)),999),IFERROR(FIND("-",$E7),999),IFERROR(FIND("（",$E7),999))-1))=H$2,$F7,"")) | I7: =IF(OR($E7="",I$2=""),"",IF(TRIM(LEFT($E7,MIN(IFERROR(FIND("CDU",UPPER($E7)),999),IFERROR(FIND("BULK",UPPER($E7)),999),IFERROR(FIND("-",$E7),999),IFERROR(FIND("（",$E7),999))-1))=I$2,$F7,"")) | J7: =IF(OR($E7="",J$2=""),"",IF(TRIM(LEFT($E7,MIN(IFERROR(FIND("CDU",UPPER($E7)),999),IFERROR(FIND("BULK",UPPER($E7)),999),IFERROR(FIND("-",$E7),999),IFERROR(FIND("（",$E7),999))-1))=J$2,$F7,"")) | K7: =IF(OR($E7="",K$2=""),"",IF(TRIM(LEFT($E7,MIN(IFERROR(FIND("CDU",UPPER($E7)),999),IFERROR(FIND("BULK",UPPER($E7)),999),IFERROR(FIND("-",$E7),999),IFERROR(FIND("（",$E7),999))-1))=K$2,$F7,"")) | L7: =IF(OR($E7="",L$2=""),"",IF(TRIM(LEFT($E7,MIN(IFERROR(FIND("CDU",UPPER($E7)),999),IFERROR(FIND("BULK",UPPER($E7)),999),IFERROR(FIND("-",$E7),999),IFERROR(FIND("（",$E7),999))-1))=L$2,$F7,"")) | M7: =IF(OR($E7="",M$2=""),"",IF(TRIM(LEFT($E7,MIN(IFERROR(FIND("CDU",UPPER($E7)),999),IFERROR(FIND("BULK",UPPER($E7)),999),IFERROR(FIND("-",$E7),999),IFERROR(FIND("（",$E7),999))-1))=M$2,$F7,"")) | N7: =IF(OR($E7="",N$2=""),"",IF(TRIM(LEFT($E7,MIN(IFERROR(FIND("CDU",UPPER($E7)),999),IFERROR(FIND("BULK",UPPER($E7)),999),IFERROR(FIND("-",$E7),999),IFERROR(FIND("（",$E7),999))-1))=N$2,$F7,"")) -> 1602 | O7: =IF(OR($E7="",O$2=""),"",IF(TRIM(LEFT($E7,MIN(IFERROR(FIND("CDU",UPPER($E7)),999),IFERROR(FIND("BULK",UPPER($E7)),999),IFERROR(FIND("-",$E7),999),IFERROR(FIND("（",$E7),999))-1))=O$2,$F7,"")) | ... AD7: =IF(OR($E7="",AD$2=""),"",IF(TRIM(LEFT($E7,MIN(IFERROR(FIND("CDU",UPPER($E7)),999),IFERROR(FIND("BULK",UPPER($E7)),999),IFERROR(FIND("-",$E7),999),IFERROR(FIND("（",$E7),999))-1))=AD$2,$F7,"")) | AE7: 4.92 | AF7: =SUM(H7:AD7)*AE7 -> 7881.84 | AG7: =AF7*7.75 -> 61084.26
A8: 45910 | B8: 45995 | C8: AE-D2113D-LS | D8: 1000001352 | E8: HH994 | F8: 1602 | H8: =IF(OR($E8="",H$2=""),"",IF(TRIM(LEFT($E8,MIN(IFERROR(FIND("CDU",UPPER($E8)),999),IFERROR(FIND("BULK",UPPER($E8)),999),IFERROR(FIND("-",$E8),999),IFERROR(FIND("（",$E8),999))-1))=H$2,$F8,"")) | I8: =IF(OR($E8="",I$2=""),"",IF(TRIM(LEFT($E8,MIN(IFERROR(FIND("CDU",UPPER($E8)),999),IFERROR(FIND("BULK",UPPER($E8)),999),IFERROR(FIND("-",$E8),999),IFERROR(FIND("（",$E8),999))-1))=I$2,$F8,"")) | J8: =IF(OR($E8="",J$2=""),"",IF(TRIM(LEFT($E8,MIN(IFERROR(FIND("CDU",UPPER($E8)),999),IFERROR(FIND("BULK",UPPER($E8)),999),IFERROR(FIND("-",$E8),999),IFERROR(FIND("（",$E8),999))-1))=J$2,$F8,"")) | K8: =IF(OR($E8="",K$2=""),"",IF(TRIM(LEFT($E8,MIN(IFERROR(FIND("CDU",UPPER($E8)),999),IFERROR(FIND("BULK",UPPER($E8)),999),IFERROR(FIND("-",$E8),999),IFERROR(FIND("（",$E8),999))-1))=K$2,$F8,"")) -> 1602 | L8: =IF(OR($E8="",L$2=""),"",IF(TRIM(LEFT($E8,MIN(IFERROR(FIND("CDU",UPPER($E8)),999),IFERROR(FIND("BULK",UPPER($E8)),999),IFERROR(FIND("-",$E8),999),IFERROR(FIND("（",$E8),999))-1))=L$2,$F8,"")) | M8: =IF(OR($E8="",M$2=""),"",IF(TRIM(LEFT($E8,MIN(IFERROR(FIND("CDU",UPPER($E8)),999),IFERROR(FIND("BULK",UPPER($E8)),999),IFERROR(FIND("-",$E8),999),IFERROR(FIND("（",$E8),999))-1))=M$2,$F8,"")) | N8: =IF(OR($E8="",N$2=""),"",IF(TRIM(LEFT($E8,MIN(IFERROR(FIND("CDU",UPPER($E8)),999),IFERROR(FIND("BULK",UPPER($E8)),999),IFERROR(FIND("-",$E8),999),IFERROR(FIND("（",$E8),999))-1))=N$2,$F8,"")) | O8: =IF(OR($E8="",O$2=""),"",IF(TRIM(LEFT($E8,MIN(IFERROR(FIND("CDU",UPPER($E8)),999),IFERROR(FIND("BULK",UPPER($E8)),999),IFERROR(FIND("-",$E8),999),IFERROR(FIND("（",$E8),999))-1))=O$2,$F8,"")) | ... AD8: =IF(OR($E8="",AD$2=""),"",IF(TRIM(LEFT($E8,MIN(IFERROR(FIND("CDU",UPPER($E8)),999),IFERROR(FIND("BULK",UPPER($E8)),999),IFERROR(FIND("-",$E8),999),IFERROR(FIND("（",$E8),999))-1))=AD$2,$F8,"")) | AE8: 4.92 | AF8: =SUM(H8:AD8)*AE8 -> 7881.84 | AG8: =AF8*7.75 -> 61084.26
A9: 45930 | B9: 45989 | C9: P318D/5 | D9: 1000001583 | E9: 376MM | F9: 1440 | H9: =IF(OR($E9="",H$2=""),"",IF(TRIM(LEFT($E9,MIN(IFERROR(FIND("CDU",UPPER($E9)),999),IFERROR(FIND("BULK",UPPER($E9)),999),IFERROR(FIND("-",$E9),999),IFERROR(FIND("（",$E9),999))-1))=H$2,$F9,"")) | I9: =IF(OR($E9="",I$2=""),"",IF(TRIM(LEFT($E9,MIN(IFERROR(FIND("CDU",UPPER($E9)),999),IFERROR(FIND("BULK",UPPER($E9)),999),IFERROR(FIND("-",$E9),999),IFERROR(FIND("（",$E9),999))-1))=I$2,$F9,"")) | J9: =IF(OR($E9="",J$2=""),"",IF(TRIM(LEFT($E9,MIN(IFERROR(FIND("CDU",UPPER($E9)),999),IFERROR(FIND("BULK",UPPER($E9)),999),IFERROR(FIND("-",$E9),999),IFERROR(FIND("（",$E9),999))-1))=J$2,$F9,"")) | K9: =IF(OR($E9="",K$2=""),"",IF(TRIM(LEFT($E9,MIN(IFERROR(FIND("CDU",UPPER($E9)),999),IFERROR(FIND("BULK",UPPER($E9)),999),IFERROR(FIND("-",$E9),999),IFERROR(FIND("（",$E9),999))-1))=K$2,$F9,"")) | L9: =IF(OR($E9="",L$2=""),"",IF(TRIM(LEFT($E9,MIN(IFERROR(FIND("CDU",UPPER($E9)),999),IFERROR(FIND("BULK",UPPER($E9)),999),IFERROR(FIND("-",$E9),999),IFERROR(FIND("（",$E9),999))-1))=L$2,$F9,"")) | M9: =IF(OR($E9="",M$2=""),"",IF(TRIM(LEFT($E9,MIN(IFERROR(FIND("CDU",UPPER($E9)),999),IFERROR(FIND("BULK",UPPER($E9)),999),IFERROR(FIND("-",$E9),999),IFERROR(FIND("（",$E9),999))-1))=M$2,$F9,"")) | N9: =IF(OR($E9="",N$2=""),"",IF(TRIM(LEFT($E9,MIN(IFERROR(FIND("CDU",UPPER($E9)),999),IFERROR(FIND("BULK",UPPER($E9)),999),IFERROR(FIND("-",$E9),999),IFERROR(FIND("（",$E9),999))-1))=N$2,$F9,"")) | O9: =IF(OR($E9="",O$2=""),"",IF(TRIM(LEFT($E9,MIN(IFERROR(FIND("CDU",UPPER($E9)),999),IFERROR(FIND("BULK",UPPER($E9)),999),IFERROR(FIND("-",$E9),999),IFERROR(FIND("（",$E9),999))-1))=O$2,$F9,"")) | ... AD9: =IF(OR($E9="",AD$2=""),"",IF(TRIM(LEFT($E9,MIN(IFERROR(FIND("CDU",UPPER($E9)),999),IFERROR(FIND("BULK",UPPER($E9)),999),IFERROR(FIND("-",$E9),999),IFERROR(FIND("（",$E9),999))-1))=AD$2,$F9,"")) | AE9: 1.01 | AF9: =SUM(H9:AD9)*AE9 -> 1454.4 | AG9: =AF9*7.75 -> 11271.6
A10: 45966 | B10: 46036 | C10: D4802D-LS | D10: 1000001879 | E10: DC346 | F10: 752 | H10: =IF(OR($E10="",H$2=""),"",IF(TRIM(LEFT($E10,MIN(IFERROR(FIND("CDU",UPPER($E10)),999),IFERROR(FIND("BULK",UPPER($E10)),999),IFERROR(FIND("-",$E10),999),IFERROR(FIND("（",$E10),999))-1))=H$2,$F10,"")) | I10: =IF(OR($E10="",I$2=""),"",IF(TRIM(LEFT($E10,MIN(IFERROR(FIND("CDU",UPPER($E10)),999),IFERROR(FIND("BULK",UPPER($E10)),999),IFERROR(FIND("-",$E10),999),IFERROR(FIND("（",$E10),999))-1))=I$2,$F10,"")) | J10: =IF(OR($E10="",J$2=""),"",IF(TRIM(LEFT($E10,MIN(IFERROR(FIND("CDU",UPPER($E10)),999),IFERROR(FIND("BULK",UPPER($E10)),999),IFERROR(FIND("-",$E10),999),IFERROR(FIND("（",$E10),999))-1))=J$2,$F10,"")) | K10: =IF(OR($E10="",K$2=""),"",IF(TRIM(LEFT($E10,MIN(IFERROR(FIND("CDU",UPPER($E10)),999),IFERROR(FIND("BULK",UPPER($E10)),999),IFERROR(FIND("-",$E10),999),IFERROR(FIND("（",$E10),999))-1))=K$2,$F10,"")) | L10: =IF(OR($E10="",L$2=""),"",IF(TRIM(LEFT($E10,MIN(IFERROR(FIND("CDU",UPPER($E10)),999),IFERROR(FIND("BULK",UPPER($E10)),999),IFERROR(FIND("-",$E10),999),IFERROR(FIND("（",$E10),999))-1))=L$2,$F10,"")) | M10: =IF(OR($E10="",M$2=""),"",IF(TRIM(LEFT($E10,MIN(IFERROR(FIND("CDU",UPPER($E10)),999),IFERROR(FIND("BULK",UPPER($E10)),999),IFERROR(FIND("-",$E10),999),IFERROR(FIND("（",$E10),999))-1))=M$2,$F10,"")) | N10: =IF(OR($E10="",N$2=""),"",IF(TRIM(LEFT($E10,MIN(IFERROR(FIND("CDU",UPPER($E10)),999),IFERROR(FIND("BULK",UPPER($E10)),999),IFERROR(FIND("-",$E10),999),IFERROR(FIND("（",$E10),999))-1))=N$2,$F10,"")) | O10: =IF(OR($E10="",O$2=""),"",IF(TRIM(LEFT($E10,MIN(IFERROR(FIND("CDU",UPPER($E10)),999),IFERROR(FIND("BULK",UPPER($E10)),999),IFERROR(FIND("-",$E10),999),IFERROR(FIND("（",$E10),999))-1))=O$2,$F10,"")) -> 752 | ... AD10: =IF(OR($E10="",AD$2=""),"",IF(TRIM(LEFT($E10,MIN(IFERROR(FIND("CDU",UPPER($E10)),999),IFERROR(FIND("BULK",UPPER($E10)),999),IFERROR(FIND("-",$E10),999),IFERROR(FIND("（",$E10),999))-1))=AD$2,$F10,"")) | AE10: 9.71 | AF10: =SUM(H10:AD10)*AE10 -> 7301.92 | AG10: =AF10*7.75 -> 56589.88
A11: 45966 | B11: 46036 | C11: D4802D-LS | D11: 1000001879 | E11: DC346 | F11: =1500-752 -> 748 | H11: =IF(OR($E11="",H$2=""),"",IF(TRIM(LEFT($E11,MIN(IFERROR(FIND("CDU",UPPER($E11)),999),IFERROR(FIND("BULK",UPPER($E11)),999),IFERROR(FIND("-",$E11),999),IFERROR(FIND("（",$E11),999))-1))=H$2,$F11,"")) | I11: =IF(OR($E11="",I$2=""),"",IF(TRIM(LEFT($E11,MIN(IFERROR(FIND("CDU",UPPER($E11)),999),IFERROR(FIND("BULK",UPPER($E11)),999),IFERROR(FIND("-",$E11),999),IFERROR(FIND("（",$E11),999))-1))=I$2,$F11,"")) | J11: =IF(OR($E11="",J$2=""),"",IF(TRIM(LEFT($E11,MIN(IFERROR(FIND("CDU",UPPER($E11)),999),IFERROR(FIND("BULK",UPPER($E11)),999),IFERROR(FIND("-",$E11),999),IFERROR(FIND("（",$E11),999))-1))=J$2,$F11,"")) | K11: =IF(OR($E11="",K$2=""),"",IF(TRIM(LEFT($E11,MIN(IFERROR(FIND("CDU",UPPER($E11)),999),IFERROR(FIND("BULK",UPPER($E11)),999),IFERROR(FIND("-",$E11),999),IFERROR(FIND("（",$E11),999))-1))=K$2,$F11,"")) | L11: =IF(OR($E11="",L$2=""),"",IF(TRIM(LEFT($E11,MIN(IFERROR(FIND("CDU",UPPER($E11)),999),IFERROR(FIND("BULK",UPPER($E11)),999),IFERROR(FIND("-",$E11),999),IFERROR(FIND("（",$E11),999))-1))=L$2,$F11,"")) | M11: =IF(OR($E11="",M$2=""),"",IF(TRIM(LEFT($E11,MIN(IFERROR(FIND("CDU",UPPER($E11)),999),IFERROR(FIND("BULK",UPPER($E11)),999),IFERROR(FIND("-",$E11),999),IFERROR(FIND("（",$E11),999))-1))=M$2,$F11,"")) | N11: =IF(OR($E11="",N$2=""),"",IF(TRIM(LEFT($E11,MIN(IFERROR(FIND("CDU",UPPER($E11)),999),IFERROR(FIND("BULK",UPPER($E11)),999),IFERROR(FIND("-",$E11),999),IFERROR(FIND("（",$E11),999))-1))=N$2,$F11,"")) | O11: =IF(OR($E11="",O$2=""),"",IF(TRIM(LEFT($E11,MIN(IFERROR(FIND("CDU",UPPER($E11)),999),IFERROR(FIND("BULK",UPPER($E11)),999),IFERROR(FIND("-",$E11),999),IFERROR(FIND("（",$E11),999))-1))=O$2,$F11,"")) -> 748 | ... AD11: =IF(OR($E11="",AD$2=""),"",IF(TRIM(LEFT($E11,MIN(IFERROR(FIND("CDU",UPPER($E11)),999),IFERROR(FIND("BULK",UPPER($E11)),999),IFERROR(FIND("-",$E11),999),IFERROR(FIND("（",$E11),999))-1))=AD$2,$F11,"")) | AE11: 9.71 | AF11: =SUM(H11:AD11)*AE11 -> 7263.08 | AG11: =AF11*7.75 -> 56288.87
A12: 45966 | B12: 46036 | C12: AE-PT8574D-LS | D12: 1000001879 | E12: GS675 | F12: 1500 | H12: =IF(OR($E12="",H$2=""),"",IF(TRIM(LEFT($E12,MIN(IFERROR(FIND("CDU",UPPER($E12)),999),IFERROR(FIND("BULK",UPPER($E12)),999),IFERROR(FIND("-",$E12),999),IFERROR(FIND("（",$E12),999))-1))=H$2,$F12,"")) | I12: =IF(OR($E12="",I$2=""),"",IF(TRIM(LEFT($E12,MIN(IFERROR(FIND("CDU",UPPER($E12)),999),IFERROR(FIND("BULK",UPPER($E12)),999),IFERROR(FIND("-",$E12),999),IFERROR(FIND("（",$E12),999))-1))=I$2,$F12,"")) | J12: =IF(OR($E12="",J$2=""),"",IF(TRIM(LEFT($E12,MIN(IFERROR(FIND("CDU",UPPER($E12)),999),IFERROR(FIND("BULK",UPPER($E12)),999),IFERROR(FIND("-",$E12),999),IFERROR(FIND("（",$E12),999))-1))=J$2,$F12,"")) | K12: =IF(OR($E12="",K$2=""),"",IF(TRIM(LEFT($E12,MIN(IFERROR(FIND("CDU",UPPER($E12)),999),IFERROR(FIND("BULK",UPPER($E12)),999),IFERROR(FIND("-",$E12),999),IFERROR(FIND("（",$E12),999))-1))=K$2,$F12,"")) | L12: =IF(OR($E12="",L$2=""),"",IF(TRIM(LEFT($E12,MIN(IFERROR(FIND("CDU",UPPER($E12)),999),IFERROR(FIND("BULK",UPPER($E12)),999),IFERROR(FIND("-",$E12),999),IFERROR(FIND("（",$E12),999))-1))=L$2,$F12,"")) | M12: =IF(OR($E12="",M$2=""),"",IF(TRIM(LEFT($E12,MIN(IFERROR(FIND("CDU",UPPER($E12)),999),IFERROR(FIND("BULK",UPPER($E12)),999),IFERROR(FIND("-",$E12),999),IFERROR(FIND("（",$E12),999))-1))=M$2,$F12,"")) | N12: =IF(OR($E12="",N$2=""),"",IF(TRIM(LEFT($E12,MIN(IFERROR(FIND("CDU",UPPER($E12)),999),IFERROR(FIND("BULK",UPPER($E12)),999),IFERROR(FIND("-",$E12),999),IFERROR(FIND("（",$E12),999))-1))=N$2,$F12,"")) | O12: =IF(OR($E12="",O$2=""),"",IF(TRIM(LEFT($E12,MIN(IFERROR(FIND("CDU",UPPER($E12)),999),IFERROR(FIND("BULK",UPPER($E12)),999),IFERROR(FIND("-",$E12),999),IFERROR(FIND("（",$E12),999))-1))=O$2,$F12,"")) | ... AD12: =IF(OR($E12="",AD$2=""),"",IF(TRIM(LEFT($E12,MIN(IFERROR(FIND("CDU",UPPER($E12)),999),IFERROR(FIND("BULK",UPPER($E12)),999),IFERROR(FIND("-",$E12),999),IFERROR(FIND("（",$E12),999))-1))=AD$2,$F12,"")) | AE12: 12 | AF12: =SUM(H12:AD12)*AE12 -> 18000 | AG12: =AF12*7.75 -> 139500
A13: 45966 | B13: 46036 | C13: AE-D2115D-LS | D13: 1000001879 | E13: HH991 | F13: 1602 | H13: =IF(OR($E13="",H$2=""),"",IF(TRIM(LEFT($E13,MIN(IFERROR(FIND("CDU",UPPER($E13)),999),IFERROR(FIND("BULK",UPPER($E13)),999),IFERROR(FIND("-",$E13),999),IFERROR(FIND("（",$E13),999))-1))=H$2,$F13,"")) | I13: =IF(OR($E13="",I$2=""),"",IF(TRIM(LEFT($E13,MIN(IFERROR(FIND("CDU",UPPER($E13)),999),IFERROR(FIND("BULK",UPPER($E13)),999),IFERROR(FIND("-",$E13),999),IFERROR(FIND("（",$E13),999))-1))=I$2,$F13,"")) | J13: =IF(OR($E13="",J$2=""),"",IF(TRIM(LEFT($E13,MIN(IFERROR(FIND("CDU",UPPER($E13)),999),IFERROR(FIND("BULK",UPPER($E13)),999),IFERROR(FIND("-",$E13),999),IFERROR(FIND("（",$E13),999))-1))=J$2,$F13,"")) | K13: =IF(OR($E13="",K$2=""),"",IF(TRIM(LEFT($E13,MIN(IFERROR(FIND("CDU",UPPER($E13)),999),IFERROR(FIND("BULK",UPPER($E13)),999),IFERROR(FIND("-",$E13),999),IFERROR(FIND("（",$E13),999))-1))=K$2,$F13,"")) | L13: =IF(OR($E13="",L$2=""),"",IF(TRIM(LEFT($E13,MIN(IFERROR(FIND("CDU",UPPER($E13)),999),IFERROR(FIND("BULK",UPPER($E13)),999),IFERROR(FIND("-",$E13),999),IFERROR(FIND("（",$E13),999))-1))=L$2,$F13,"")) | M13: =IF(OR($E13="",M$2=""),"",IF(TRIM(LEFT($E13,MIN(IFERROR(FIND("CDU",UPPER($E13)),999),IFERROR(FIND("BULK",UPPER($E13)),999),IFERROR(FIND("-",$E13),999),IFERROR(FIND("（",$E13),999))-1))=M$2,$F13,"")) -> 1602 | N13: =IF(OR($E13="",N$2=""),"",IF(TRIM(LEFT($E13,MIN(IFERROR(FIND("CDU",UPPER($E13)),999),IFERROR(FIND("BULK",UPPER($E13)),999),IFERROR(FIND("-",$E13),999),IFERROR(FIND("（",$E13),999))-1))=N$2,$F13,"")) | O13: =IF(OR($E13="",O$2=""),"",IF(TRIM(LEFT($E13,MIN(IFERROR(FIND("CDU",UPPER($E13)),999),IFERROR(FIND("BULK",UPPER($E13)),999),IFERROR(FIND("-",$E13),999),IFERROR(FIND("（",$E13),999))-1))=O$2,$F13,"")) | ... AD13: =IF(OR($E13="",AD$2=""),"",IF(TRIM(LEFT($E13,MIN(IFERROR(FIND("CDU",UPPER($E13)),999),IFERROR(FIND("BULK",UPPER($E13)),999),IFERROR(FIND("-",$E13),999),IFERROR(FIND("（",$E13),999))-1))=AD$2,$F13,"")) | AE13: 4.72 | AF13: =SUM(H13:AD13)*AE13 -> 7561.44 | AG13: =AF13*7.75 -> 58601.16
A14: 45966 | B14: 46021 | C14: AE-ZT4060D-LS | D14: 1000001880 | E14: RA362 | F14: =2508+720 -> 3228 | H14: =IF(OR($E14="",H$2=""),"",IF(TRIM(LEFT($E14,MIN(IFERROR(FIND("CDU",UPPER($E14)),999),IFERROR(FIND("BULK",UPPER($E14)),999),IFERROR(FIND("-",$E14),999),IFERROR(FIND("（",$E14),999))-1))=H$2,$F14,"")) | I14: =IF(OR($E14="",I$2=""),"",IF(TRIM(LEFT($E14,MIN(IFERROR(FIND("CDU",UPPER($E14)),999),IFERROR(FIND("BULK",UPPER($E14)),999),IFERROR(FIND("-",$E14),999),IFERROR(FIND("（",$E14),999))-1))=I$2,$F14,"")) | J14: =IF(OR($E14="",J$2=""),"",IF(TRIM(LEFT($E14,MIN(IFERROR(FIND("CDU",UPPER($E14)),999),IFERROR(FIND("BULK",UPPER($E14)),999),IFERROR(FIND("-",$E14),999),IFERROR(FIND("（",$E14),999))-1))=J$2,$F14,"")) -> 3228 | K14: =IF(OR($E14="",K$2=""),"",IF(TRIM(LEFT($E14,MIN(IFERROR(FIND("CDU",UPPER($E14)),999),IFERROR(FIND("BULK",UPPER($E14)),999),IFERROR(FIND("-",$E14),999),IFERROR(FIND("（",$E14),999))-1))=K$2,$F14,"")) | L14: =IF(OR($E14="",L$2=""),"",IF(TRIM(LEFT($E14,MIN(IFERROR(FIND("CDU",UPPER($E14)),999),IFERROR(FIND("BULK",UPPER($E14)),999),IFERROR(FIND("-",$E14),999),IFERROR(FIND("（",$E14),999))-1))=L$2,$F14,"")) | M14: =IF(OR($E14="",M$2=""),"",IF(TRIM(LEFT($E14,MIN(IFERROR(FIND("CDU",UPPER($E14)),999),IFERROR(FIND("BULK",UPPER($E14)),999),IFERROR(FIND("-",$E14),999),IFERROR(FIND("（",$E14),999))-1))=M$2,$F14,"")) | N14: =IF(OR($E14="",N$2=""),"",IF(TRIM(LEFT($E14,MIN(IFERROR(FIND("CDU",UPPER($E14)),999),IFERROR(FIND("BULK",UPPER($E14)),999),IFERROR(FIND("-",$E14),999),IFERROR(FIND("（",$E14),999))-1))=N$2,$F14,"")) | O14: =IF(OR($E14="",O$2=""),"",IF(TRIM(LEFT($E14,MIN(IFERROR(FIND("CDU",UPPER($E14)),999),IFERROR(FIND("BULK",UPPER($E14)),999),IFERROR(FIND("-",$E14),999),IFERROR(FIND("（",$E14),999))-1))=O$2,$F14,"")) | ... AD14: =IF(OR($E14="",AD$2=""),"",IF(TRIM(LEFT($E14,MIN(IFERROR(FIND("CDU",UPPER($E14)),999),IFERROR(FIND("BULK",UPPER($E14)),999),IFERROR(FIND("-",$E14),999),IFERROR(FIND("（",$E14),999))-1))=AD$2,$F14,"")) | AE14: 7.34 | AF14: =SUM(H14:AD14)*AE14 -> 23693.52 | AG14: =AF14*7.75 -> 183624.78
A15: 45966 | B15: 46021 | C15: AE-ZT8351D-LS | D15: 1000001880 | E15: RA367 | F15: 2832 | H15: =IF(OR($E15="",H$2=""),"",IF(TRIM(LEFT($E15,MIN(IFERROR(FIND("CDU",UPPER($E15)),999),IFERROR(FIND("BULK",UPPER($E15)),999),IFERROR(FIND("-",$E15),999),IFERROR(FIND("（",$E15),999))-1))=H$2,$F15,"")) | I15: =IF(OR($E15="",I$2=""),"",IF(TRIM(LEFT($E15,MIN(IFERROR(FIND("CDU",UPPER($E15)),999),IFERROR(FIND("BULK",UPPER($E15)),999),IFERROR(FIND("-",$E15),999),IFERROR(FIND("（",$E15),999))-1))=I$2,$F15,"")) -> 2832 | J15: =IF(OR($E15="",J$2=""),"",IF(TRIM(LEFT($E15,MIN(IFERROR(FIND("CDU",UPPER($E15)),999),IFERROR(FIND("BULK",UPPER($E15)),999),IFERROR(FIND("-",$E15),999),IFERROR(FIND("（",$E15),999))-1))=J$2,$F15,"")) | K15: =IF(OR($E15="",K$2=""),"",IF(TRIM(LEFT($E15,MIN(IFERROR(FIND("CDU",UPPER($E15)),999),IFERROR(FIND("BULK",UPPER($E15)),999),IFERROR(FIND("-",$E15),999),IFERROR(FIND("（",$E15),999))-1))=K$2,$F15,"")) | L15: =IF(OR($E15="",L$2=""),"",IF(TRIM(LEFT($E15,MIN(IFERROR(FIND("CDU",UPPER($E15)),999),IFERROR(FIND("BULK",UPPER($E15)),999),IFERROR(FIND("-",$E15),999),IFERROR(FIND("（",$E15),999))-1))=L$2,$F15,"")) | M15: =IF(OR($E15="",M$2=""),"",IF(TRIM(LEFT($E15,MIN(IFERROR(FIND("CDU",UPPER($E15)),999),IFERROR(FIND("BULK",UPPER($E15)),999),IFERROR(FIND("-",$E15),999),IFERROR(FIND("（",$E15),999))-1))=M$2,$F15,"")) | N15: =IF(OR($E15="",N$2=""),"",IF(TRIM(LEFT($E15,MIN(IFERROR(FIND("CDU",UPPER($E15)),999),IFERROR(FIND("BULK",UPPER($E15)),999),IFERROR(FIND("-",$E15),999),IFERROR(FIND("（",$E15),999))-1))=N$2,$F15,"")) | O15: =IF(OR($E15="",O$2=""),"",IF(TRIM(LEFT($E15,MIN(IFERROR(FIND("CDU",UPPER($E15)),999),IFERROR(FIND("BULK",UPPER($E15)),999),IFERROR(FIND("-",$E15),999),IFERROR(FIND("（",$E15),999))-1))=O$2,$F15,"")) | ... AD15: =IF(OR($E15="",AD$2=""),"",IF(TRIM(LEFT($E15,MIN(IFERROR(FIND("CDU",UPPER($E15)),999),IFERROR(FIND("BULK",UPPER($E15)),999),IFERROR(FIND("-",$E15),999),IFERROR(FIND("（",$E15),999))-1))=AD$2,$F15,"")) | AE15: 7.38 | AF15: =SUM(H15:AD15)*AE15 -> 20900.16 | AG15: =AF15*7.75 -> 161976.24
A16: 45966 | B16: 46021 | C16: AE-ZT8351D-LS | D16: 1000001880 | E16: RA367 | F16: =2520+720-2832 -> 408 | H16: =IF(OR($E16="",H$2=""),"",IF(TRIM(LEFT($E16,MIN(IFERROR(FIND("CDU",UPPER($E16)),999),IFERROR(FIND("BULK",UPPER($E16)),999),IFERROR(FIND("-",$E16),999),IFERROR(FIND("（",$E16),999))-1))=H$2,$F16,"")) | I16: =IF(OR($E16="",I$2=""),"",IF(TRIM(LEFT($E16,MIN(IFERROR(FIND("CDU",UPPER($E16)),999),IFERROR(FIND("BULK",UPPER($E16)),999),IFERROR(FIND("-",$E16),999),IFERROR(FIND("（",$E16),999))-1))=I$2,$F16,"")) -> 408 | J16: =IF(OR($E16="",J$2=""),"",IF(TRIM(LEFT($E16,MIN(IFERROR(FIND("CDU",UPPER($E16)),999),IFERROR(FIND("BULK",UPPER($E16)),999),IFERROR(FIND("-",$E16),999),IFERROR(FIND("（",$E16),999))-1))=J$2,$F16,"")) | K16: =IF(OR($E16="",K$2=""),"",IF(TRIM(LEFT($E16,MIN(IFERROR(FIND("CDU",UPPER($E16)),999),IFERROR(FIND("BULK",UPPER($E16)),999),IFERROR(FIND("-",$E16),999),IFERROR(FIND("（",$E16),999))-1))=K$2,$F16,"")) | L16: =IF(OR($E16="",L$2=""),"",IF(TRIM(LEFT($E16,MIN(IFERROR(FIND("CDU",UPPER($E16)),999),IFERROR(FIND("BULK",UPPER($E16)),999),IFERROR(FIND("-",$E16),999),IFERROR(FIND("（",$E16),999))-1))=L$2,$F16,"")) | M16: =IF(OR($E16="",M$2=""),"",IF(TRIM(LEFT($E16,MIN(IFERROR(FIND("CDU",UPPER($E16)),999),IFERROR(FIND("BULK",UPPER($E16)),999),IFERROR(FIND("-",$E16),999),IFERROR(FIND("（",$E16),999))-1))=M$2,$F16,"")) | N16: =IF(OR($E16="",N$2=""),"",IF(TRIM(LEFT($E16,MIN(IFERROR(FIND("CDU",UPPER($E16)),999),IFERROR(FIND("BULK",UPPER($E16)),999),IFERROR(FIND("-",$E16),999),IFERROR(FIND("（",$E16),999))-1))=N$2,$F16,"")) | O16: =IF(OR($E16="",O$2=""),"",IF(TRIM(LEFT($E16,MIN(IFERROR(FIND("CDU",UPPER($E16)),999),IFERROR(FIND("BULK",UPPER($E16)),999),IFERROR(FIND("-",$E16),999),IFERROR(FIND("（",$E16),999))-1))=O$2,$F16,"")) | ... AD16: =IF(OR($E16="",AD$2=""),"",IF(TRIM(LEFT($E16,MIN(IFERROR(FIND("CDU",UPPER($E16)),999),IFERROR(FIND("BULK",UPPER($E16)),999),IFERROR(FIND("-",$E16),999),IFERROR(FIND("（",$E16),999))-1))=AD$2,$F16,"")) | AE16: 7.38 | AF16: =SUM(H16:AD16)*AE16 -> 3011.04 | AG16: =AF16*7.75 -> 23335.56
A17: 45966 | B17: 46021 | C17: AE-ZT4059D-LS | D17: 1000001880 | E17: RA369 | F17: =2520+1080 -> 3600 | H17: =IF(OR($E17="",H$2=""),"",IF(TRIM(LEFT($E17,MIN(IFERROR(FIND("CDU",UPPER($E17)),999),IFERROR(FIND("BULK",UPPER($E17)),999),IFERROR(FIND("-",$E17),999),IFERROR(FIND("（",$E17),999))-1))=H$2,$F17,"")) | I17: =IF(OR($E17="",I$2=""),"",IF(TRIM(LEFT($E17,MIN(IFERROR(FIND("CDU",UPPER($E17)),999),IFERROR(FIND("BULK",UPPER($E17)),999),IFERROR(FIND("-",$E17),999),IFERROR(FIND("（",$E17),999))-1))=I$2,$F17,"")) | J17: =IF(OR($E17="",J$2=""),"",IF(TRIM(LEFT($E17,MIN(IFERROR(FIND("CDU",UPPER($E17)),999),IFERROR(FIND("BULK",UPPER($E17)),999),IFERROR(FIND("-",$E17),999),IFERROR(FIND("（",$E17),999))-1))=J$2,$F17,"")) | K17: =IF(OR($E17="",K$2=""),"",IF(TRIM(LEFT($E17,MIN(IFERROR(FIND("CDU",UPPER($E17)),999),IFERROR(FIND("BULK",UPPER($E17)),999),IFERROR(FIND("-",$E17),999),IFERROR(FIND("（",$E17),999))-1))=K$2,$F17,"")) | L17: =IF(OR($E17="",L$2=""),"",IF(TRIM(LEFT($E17,MIN(IFERROR(FIND("CDU",UPPER($E17)),999),IFERROR(FIND("BULK",UPPER($E17)),999),IFERROR(FIND("-",$E17),999),IFERROR(FIND("（",$E17),999))-1))=L$2,$F17,"")) | M17: =IF(OR($E17="",M$2=""),"",IF(TRIM(LEFT($E17,MIN(IFERROR(FIND("CDU",UPPER($E17)),999),IFERROR(FIND("BULK",UPPER($E17)),999),IFERROR(FIND("-",$E17),999),IFERROR(FIND("（",$E17),999))-1))=M$2,$F17,"")) | N17: =IF(OR($E17="",N$2=""),"",IF(TRIM(LEFT($E17,MIN(IFERROR(FIND("CDU",UPPER($E17)),999),IFERROR(FIND("BULK",UPPER($E17)),999),IFERROR(FIND("-",$E17),999),IFERROR(FIND("（",$E17),999))-1))=N$2,$F17,"")) | O17: =IF(OR($E17="",O$2=""),"",IF(TRIM(LEFT($E17,MIN(IFERROR(FIND("CDU",UPPER($E17)),999),IFERROR(FIND("BULK",UPPER($E17)),999),IFERROR(FIND("-",$E17),999),IFERROR(FIND("（",$E17),999))-1))=O$2,$F17,"")) | ... AD17: =IF(OR($E17="",AD$2=""),"",IF(TRIM(LEFT($E17,MIN(IFERROR(FIND("CDU",UPPER($E17)),999),IFERROR(FIND("BULK",UPPER($E17)),999),IFERROR(FIND("-",$E17),999),IFERROR(FIND("（",$E17),999))-1))=AD$2,$F17,"")) | AE17: 7.31 | AF17: =SUM(H17:AD17)*AE17 -> 26316 | AG17: =AF17*7.75 -> 203949
A18: 45972 | B18: 46043 | C18: AE-D2116D-LS | D18: 1000002006 | E18: HH992 | F18: 1002 | H18: =IF(OR($E18="",H$2=""),"",IF(TRIM(LEFT($E18,MIN(IFERROR(FIND("CDU",UPPER($E18)),999),IFERROR(FIND("BULK",UPPER($E18)),999),IFERROR(FIND("-",$E18),999),IFERROR(FIND("（",$E18),999))-1))=H$2,$F18,"")) | I18: =IF(OR($E18="",I$2=""),"",IF(TRIM(LEFT($E18,MIN(IFERROR(FIND("CDU",UPPER($E18)),999),IFERROR(FIND("BULK",UPPER($E18)),999),IFERROR(FIND("-",$E18),999),IFERROR(FIND("（",$E18),999))-1))=I$2,$F18,"")) | J18: =IF(OR($E18="",J$2=""),"",IF(TRIM(LEFT($E18,MIN(IFERROR(FIND("CDU",UPPER($E18)),999),IFERROR(FIND("BULK",UPPER($E18)),999),IFERROR(FIND("-",$E18),999),IFERROR(FIND("（",$E18),999))-1))=J$2,$F18,"")) | K18: =IF(OR($E18="",K$2=""),"",IF(TRIM(LEFT($E18,MIN(IFERROR(FIND("CDU",UPPER($E18)),999),IFERROR(FIND("BULK",UPPER($E18)),999),IFERROR(FIND("-",$E18),999),IFERROR(FIND("（",$E18),999))-1))=K$2,$F18,"")) | L18: =IF(OR($E18="",L$2=""),"",IF(TRIM(LEFT($E18,MIN(IFERROR(FIND("CDU",UPPER($E18)),999),IFERROR(FIND("BULK",UPPER($E18)),999),IFERROR(FIND("-",$E18),999),IFERROR(FIND("（",$E18),999))-1))=L$2,$F18,"")) | M18: =IF(OR($E18="",M$2=""),"",IF(TRIM(LEFT($E18,MIN(IFERROR(FIND("CDU",UPPER($E18)),999),IFERROR(FIND("BULK",UPPER($E18)),999),IFERROR(FIND("-",$E18),999),IFERROR(FIND("（",$E18),999))-1))=M$2,$F18,"")) | N18: =IF(OR($E18="",N$2=""),"",IF(TRIM(LEFT($E18,MIN(IFERROR(FIND("CDU",UPPER($E18)),999),IFERROR(FIND("BULK",UPPER($E18)),999),IFERROR(FIND("-",$E18),999),IFERROR(FIND("（",$E18),999))-1))=N$2,$F18,"")) -> 1002 | O18: =IF(OR($E18="",O$2=""),"",IF(TRIM(LEFT($E18,MIN(IFERROR(FIND("CDU",UPPER($E18)),999),IFERROR(FIND("BULK",UPPER($E18)),999),IFERROR(FIND("-",$E18),999),IFERROR(FIND("（",$E18),999))-1))=O$2,$F18,"")) | ... AD18: =IF(OR($E18="",AD$2=""),"",IF(TRIM(LEFT($E18,MIN(IFERROR(FIND("CDU",UPPER($E18)),999),IFERROR(FIND("BULK",UPPER($E18)),999),IFERROR(FIND("-",$E18),999),IFERROR(FIND("（",$E18),999))-1))=AD$2,$F18,"")) | AE18: 4.92 | AF18: =SUM(H18:AD18)*AE18 -> 4929.84 | AG18: =AF18*7.75 -> 38206.26
A19: 45972 | B19: 46043 | C19: AE-D2116D-LS | D19: 1000002006 | E19: HH992 | F19: =1608-1002 -> 606 | H19: =IF(OR($E19="",H$2=""),"",IF(TRIM(LEFT($E19,MIN(IFERROR(FIND("CDU",UPPER($E19)),999),IFERROR(FIND("BULK",UPPER($E19)),999),IFERROR(FIND("-",$E19),999),IFERROR(FIND("（",$E19),999))-1))=H$2,$F19,"")) | I19: =IF(OR($E19="",I$2=""),"",IF(TRIM(LEFT($E19,MIN(IFERROR(FIND("CDU",UPPER($E19)),999),IFERROR(FIND("BULK",UPPER($E19)),999),IFERROR(FIND("-",$E19),999),IFERROR(FIND("（",$E19),999))-1))=I$2,$F19,"")) | J19: =IF(OR($E19="",J$2=""),"",IF(TRIM(LEFT($E19,MIN(IFERROR(FIND("CDU",UPPER($E19)),999),IFERROR(FIND("BULK",UPPER($E19)),999),IFERROR(FIND("-",$E19),999),IFERROR(FIND("（",$E19),999))-1))=J$2,$F19,"")) | K19: =IF(OR($E19="",K$2=""),"",IF(TRIM(LEFT($E19,MIN(IFERROR(FIND("CDU",UPPER($E19)),999),IFERROR(FIND("BULK",UPPER($E19)),999),IFERROR(FIND("-",$E19),999),IFERROR(FIND("（",$E19),999))-1))=K$2,$F19,"")) | L19: =IF(OR($E19="",L$2=""),"",IF(TRIM(LEFT($E19,MIN(IFERROR(FIND("CDU",UPPER($E19)),999),IFERROR(FIND("BULK",UPPER($E19)),999),IFERROR(FIND("-",$E19),999),IFERROR(FIND("（",$E19),999))-1))=L$2,$F19,"")) | M19: =IF(OR($E19="",M$2=""),"",IF(TRIM(LEFT($E19,MIN(IFERROR(FIND("CDU",UPPER($E19)),999),IFERROR(FIND("BULK",UPPER($E19)),999),IFERROR(FIND("-",$E19),999),IFERROR(FIND("（",$E19),999))-1))=M$2,$F19,"")) | N19: =IF(OR($E19="",N$2=""),"",IF(TRIM(LEFT($E19,MIN(IFERROR(FIND("CDU",UPPER($E19)),999),IFERROR(FIND("BULK",UPPER($E19)),999),IFERROR(FIND("-",$E19),999),IFERROR(FIND("（",$E19),999))-1))=N$2,$F19,"")) -> 606 | O19: =IF(OR($E19="",O$2=""),"",IF(TRIM(LEFT($E19,MIN(IFERROR(FIND("CDU",UPPER($E19)),999),IFERROR(FIND("BULK",UPPER($E19)),999),IFERROR(FIND("-",$E19),999),IFERROR(FIND("（",$E19),999))-1))=O$2,$F19,"")) | ... AD19: =IF(OR($E19="",AD$2=""),"",IF(TRIM(LEFT($E19,MIN(IFERROR(FIND("CDU",UPPER($E19)),999),IFERROR(FIND("BULK",UPPER($E19)),999),IFERROR(FIND("-",$E19),999),IFERROR(FIND("（",$E19),999))-1))=AD$2,$F19,"")) | AE19: 4.92 | AF19: =SUM(H19:AD19)*AE19 -> 2981.52 | AG19: =AF19*7.75 -> 23106.78
A20: 45972 | B20: 46043 | C20: AE-D2114D-LS | D20: 1000002006 | E20: HH993 | F20: 1602 | H20: =IF(OR($E20="",H$2=""),"",IF(TRIM(LEFT($E20,MIN(IFERROR(FIND("CDU",UPPER($E20)),999),IFERROR(FIND("BULK",UPPER($E20)),999),IFERROR(FIND("-",$E20),999),IFERROR(FIND("（",$E20),999))-1))=H$2,$F20,"")) | I20: =IF(OR($E20="",I$2=""),"",IF(TRIM(LEFT($E20,MIN(IFERROR(FIND("CDU",UPPER($E20)),999),IFERROR(FIND("BULK",UPPER($E20)),999),IFERROR(FIND("-",$E20),999),IFERROR(FIND("（",$E20),999))-1))=I$2,$F20,"")) | J20: =IF(OR($E20="",J$2=""),"",IF(TRIM(LEFT($E20,MIN(IFERROR(FIND("CDU",UPPER($E20)),999),IFERROR(FIND("BULK",UPPER($E20)),999),IFERROR(FIND("-",$E20),999),IFERROR(FIND("（",$E20),999))-1))=J$2,$F20,"")) | K20: =IF(OR($E20="",K$2=""),"",IF(TRIM(LEFT($E20,MIN(IFERROR(FIND("CDU",UPPER($E20)),999),IFERROR(FIND("BULK",UPPER($E20)),999),IFERROR(FIND("-",$E20),999),IFERROR(FIND("（",$E20),999))-1))=K$2,$F20,"")) | L20: =IF(OR($E20="",L$2=""),"",IF(TRIM(LEFT($E20,MIN(IFERROR(FIND("CDU",UPPER($E20)),999),IFERROR(FIND("BULK",UPPER($E20)),999),IFERROR(FIND("-",$E20),999),IFERROR(FIND("（",$E20),999))-1))=L$2,$F20,"")) -> 1602 | M20: =IF(OR($E20="",M$2=""),"",IF(TRIM(LEFT($E20,MIN(IFERROR(FIND("CDU",UPPER($E20)),999),IFERROR(FIND("BULK",UPPER($E20)),999),IFERROR(FIND("-",$E20),999),IFERROR(FIND("（",$E20),999))-1))=M$2,$F20,"")) | N20: =IF(OR($E20="",N$2=""),"",IF(TRIM(LEFT($E20,MIN(IFERROR(FIND("CDU",UPPER($E20)),999),IFERROR(FIND("BULK",UPPER($E20)),999),IFERROR(FIND("-",$E20),999),IFERROR(FIND("（",$E20),999))-1))=N$2,$F20,"")) | O20: =IF(OR($E20="",O$2=""),"",IF(TRIM(LEFT($E20,MIN(IFERROR(FIND("CDU",UPPER($E20)),999),IFERROR(FIND("BULK",UPPER($E20)),999),IFERROR(FIND("-",$E20),999),IFERROR(FIND("（",$E20),999))-1))=O$2,$F20,"")) | ... AD20: =IF(OR($E20="",AD$2=""),"",IF(TRIM(LEFT($E20,MIN(IFERROR(FIND("CDU",UPPER($E20)),999),IFERROR(FIND("BULK",UPPER($E20)),999),IFERROR(FIND("-",$E20),999),IFERROR(FIND("（",$E20),999))-1))=AD$2,$F20,"")) | AE20: 4.92 | AF20: =SUM(H20:AD20)*AE20 -> 7881.84 | AG20: =AF20*7.75 -> 61084.26
A21: 45972 | B21: 46043 | C21: AE-D2113D-LS | D21: 1000002006 | E21: HH994 | F21: 1002 | H21: =IF(OR($E21="",H$2=""),"",IF(TRIM(LEFT($E21,MIN(IFERROR(FIND("CDU",UPPER($E21)),999),IFERROR(FIND("BULK",UPPER($E21)),999),IFERROR(FIND("-",$E21),999),IFERROR(FIND("（",$E21),999))-1))=H$2,$F21,"")) | I21: =IF(OR($E21="",I$2=""),"",IF(TRIM(LEFT($E21,MIN(IFERROR(FIND("CDU",UPPER($E21)),999),IFERROR(FIND("BULK",UPPER($E21)),999),IFERROR(FIND("-",$E21),999),IFERROR(FIND("（",$E21),999))-1))=I$2,$F21,"")) | J21: =IF(OR($E21="",J$2=""),"",IF(TRIM(LEFT($E21,MIN(IFERROR(FIND("CDU",UPPER($E21)),999),IFERROR(FIND("BULK",UPPER($E21)),999),IFERROR(FIND("-",$E21),999),IFERROR(FIND("（",$E21),999))-1))=J$2,$F21,"")) | K21: =IF(OR($E21="",K$2=""),"",IF(TRIM(LEFT($E21,MIN(IFERROR(FIND("CDU",UPPER($E21)),999),IFERROR(FIND("BULK",UPPER($E21)),999),IFERROR(FIND("-",$E21),999),IFERROR(FIND("（",$E21),999))-1))=K$2,$F21,"")) -> 1002 | L21: =IF(OR($E21="",L$2=""),"",IF(TRIM(LEFT($E21,MIN(IFERROR(FIND("CDU",UPPER($E21)),999),IFERROR(FIND("BULK",UPPER($E21)),999),IFERROR(FIND("-",$E21),999),IFERROR(FIND("（",$E21),999))-1))=L$2,$F21,"")) | M21: =IF(OR($E21="",M$2=""),"",IF(TRIM(LEFT($E21,MIN(IFERROR(FIND("CDU",UPPER($E21)),999),IFERROR(FIND("BULK",UPPER($E21)),999),IFERROR(FIND("-",$E21),999),IFERROR(FIND("（",$E21),999))-1))=M$2,$F21,"")) | N21: =IF(OR($E21="",N$2=""),"",IF(TRIM(LEFT($E21,MIN(IFERROR(FIND("CDU",UPPER($E21)),999),IFERROR(FIND("BULK",UPPER($E21)),999),IFERROR(FIND("-",$E21),999),IFERROR(FIND("（",$E21),999))-1))=N$2,$F21,"")) | O21: =IF(OR($E21="",O$2=""),"",IF(TRIM(LEFT($E21,MIN(IFERROR(FIND("CDU",UPPER($E21)),999),IFERROR(FIND("BULK",UPPER($E21)),999),IFERROR(FIND("-",$E21),999),IFERROR(FIND("（",$E21),999))-1))=O$2,$F21,"")) | ... AD21: =IF(OR($E21="",AD$2=""),"",IF(TRIM(LEFT($E21,MIN(IFERROR(FIND("CDU",UPPER($E21)),999),IFERROR(FIND("BULK",UPPER($E21)),999),IFERROR(FIND("-",$E21),999),IFERROR(FIND("（",$E21),999))-1))=AD$2,$F21,"")) | AE21: 4.92 | AF21: =SUM(H21:AD21)*AE21 -> 4929.84 | AG21: =AF21*7.75 -> 38206.26
A22: 45972 | B22: 46043 | C22: AE-D2113D-LS | D22: 1000002006 | E22: HH994 | F22: =1602-1002 -> 600 | H22: =IF(OR($E22="",H$2=""),"",IF(TRIM(LEFT($E22,MIN(IFERROR(FIND("CDU",UPPER($E22)),999),IFERROR(FIND("BULK",UPPER($E22)),999),IFERROR(FIND("-",$E22),999),IFERROR(FIND("（",$E22),999))-1))=H$2,$F22,"")) | I22: =IF(OR($E22="",I$2=""),"",IF(TRIM(LEFT($E22,MIN(IFERROR(FIND("CDU",UPPER($E22)),999),IFERROR(FIND("BULK",UPPER($E22)),999),IFERROR(FIND("-",$E22),999),IFERROR(FIND("（",$E22),999))-1))=I$2,$F22,"")) | J22: =IF(OR($E22="",J$2=""),"",IF(TRIM(LEFT($E22,MIN(IFERROR(FIND("CDU",UPPER($E22)),999),IFERROR(FIND("BULK",UPPER($E22)),999),IFERROR(FIND("-",$E22),999),IFERROR(FIND("（",$E22),999))-1))=J$2,$F22,"")) | K22: =IF(OR($E22="",K$2=""),"",IF(TRIM(LEFT($E22,MIN(IFERROR(FIND("CDU",UPPER($E22)),999),IFERROR(FIND("BULK",UPPER($E22)),999),IFERROR(FIND("-",$E22),999),IFERROR(FIND("（",$E22),999))-1))=K$2,$F22,"")) -> 600 | L22: =IF(OR($E22="",L$2=""),"",IF(TRIM(LEFT($E22,MIN(IFERROR(FIND("CDU",UPPER($E22)),999),IFERROR(FIND("BULK",UPPER($E22)),999),IFERROR(FIND("-",$E22),999),IFERROR(FIND("（",$E22),999))-1))=L$2,$F22,"")) | M22: =IF(OR($E22="",M$2=""),"",IF(TRIM(LEFT($E22,MIN(IFERROR(FIND("CDU",UPPER($E22)),999),IFERROR(FIND("BULK",UPPER($E22)),999),IFERROR(FIND("-",$E22),999),IFERROR(FIND("（",$E22),999))-1))=M$2,$F22,"")) | N22: =IF(OR($E22="",N$2=""),"",IF(TRIM(LEFT($E22,MIN(IFERROR(FIND("CDU",UPPER($E22)),999),IFERROR(FIND("BULK",UPPER($E22)),999),IFERROR(FIND("-",$E22),999),IFERROR(FIND("（",$E22),999))-1))=N$2,$F22,"")) | O22: =IF(OR($E22="",O$2=""),"",IF(TRIM(LEFT($E22,MIN(IFERROR(FIND("CDU",UPPER($E22)),999),IFERROR(FIND("BULK",UPPER($E22)),999),IFERROR(FIND("-",$E22),999),IFERROR(FIND("（",$E22),999))-1))=O$2,$F22,"")) | ... AD22: =IF(OR($E22="",AD$2=""),"",IF(TRIM(LEFT($E22,MIN(IFERROR(FIND("CDU",UPPER($E22)),999),IFERROR(FIND("BULK",UPPER($E22)),999),IFERROR(FIND("-",$E22),999),IFERROR(FIND("（",$E22),999))-1))=AD$2,$F22,"")) | AE22: 4.92 | AF22: =SUM(H22:AD22)*AE22 -> 2952 | AG22: =AF22*7.75 -> 22878
A23: 45972 | B23: 46043 | C23: AE-ZT4060D-LS | D23: 1000002006 | E23: RA362 | F23: 1968 | H23: =IF(OR($E23="",H$2=""),"",IF(TRIM(LEFT($E23,MIN(IFERROR(FIND("CDU",UPPER($E23)),999),IFERROR(FIND("BULK",UPPER($E23)),999),IFERROR(FIND("-",$E23),999),IFERROR(FIND("（",$E23),999))-1))=H$2,$F23,"")) | I23: =IF(OR($E23="",I$2=""),"",IF(TRIM(LEFT($E23,MIN(IFERROR(FIND("CDU",UPPER($E23)),999),IFERROR(FIND("BULK",UPPER($E23)),999),IFERROR(FIND("-",$E23),999),IFERROR(FIND("（",$E23),999))-1))=I$2,$F23,"")) | J23: =IF(OR($E23="",J$2=""),"",IF(TRIM(LEFT($E23,MIN(IFERROR(FIND("CDU",UPPER($E23)),999),IFERROR(FIND("BULK",UPPER($E23)),999),IFERROR(FIND("-",$E23),999),IFERROR(FIND("（",$E23),999))-1))=J$2,$F23,"")) -> 1968 | K23: =IF(OR($E23="",K$2=""),"",IF(TRIM(LEFT($E23,MIN(IFERROR(FIND("CDU",UPPER($E23)),999),IFERROR(FIND("BULK",UPPER($E23)),999),IFERROR(FIND("-",$E23),999),IFERROR(FIND("（",$E23),999))-1))=K$2,$F23,"")) | L23: =IF(OR($E23="",L$2=""),"",IF(TRIM(LEFT($E23,MIN(IFERROR(FIND("CDU",UPPER($E23)),999),IFERROR(FIND("BULK",UPPER($E23)),999),IFERROR(FIND("-",$E23),999),IFERROR(FIND("（",$E23),999))-1))=L$2,$F23,"")) | M23: =IF(OR($E23="",M$2=""),"",IF(TRIM(LEFT($E23,MIN(IFERROR(FIND("CDU",UPPER($E23)),999),IFERROR(FIND("BULK",UPPER($E23)),999),IFERROR(FIND("-",$E23),999),IFERROR(FIND("（",$E23),999))-1))=M$2,$F23,"")) | N23: =IF(OR($E23="",N$2=""),"",IF(TRIM(LEFT($E23,MIN(IFERROR(FIND("CDU",UPPER($E23)),999),IFERROR(FIND("BULK",UPPER($E23)),999),IFERROR(FIND("-",$E23),999),IFERROR(FIND("（",$E23),999))-1))=N$2,$F23,"")) | O23: =IF(OR($E23="",O$2=""),"",IF(TRIM(LEFT($E23,MIN(IFERROR(FIND("CDU",UPPER($E23)),999),IFERROR(FIND("BULK",UPPER($E23)),999),IFERROR(FIND("-",$E23),999),IFERROR(FIND("（",$E23),999))-1))=O$2,$F23,"")) | ... AD23: =IF(OR($E23="",AD$2=""),"",IF(TRIM(LEFT($E23,MIN(IFERROR(FIND("CDU",UPPER($E23)),999),IFERROR(FIND("BULK",UPPER($E23)),999),IFERROR(FIND("-",$E23),999),IFERROR(FIND("（",$E23),999))-1))=AD$2,$F23,"")) | AE23: 7.34 | AF23: =SUM(H23:AD23)*AE23 -> 14445.12 | AG23: =AF23*7.75 -> 111949.68
A24: 45972 | B24: 46043 | C24: AE-ZT4060D-LS | D24: 1000002006 | E24: RA362 | F24: =2508-1968 -> 540 | H24: =IF(OR($E24="",H$2=""),"",IF(TRIM(LEFT($E24,MIN(IFERROR(FIND("CDU",UPPER($E24)),999),IFERROR(FIND("BULK",UPPER($E24)),999),IFERROR(FIND("-",$E24),999),IFERROR(FIND("（",$E24),999))-1))=H$2,$F24,"")) | I24: =IF(OR($E24="",I$2=""),"",IF(TRIM(LEFT($E24,MIN(IFERROR(FIND("CDU",UPPER($E24)),999),IFERROR(FIND("BULK",UPPER($E24)),999),IFERROR(FIND("-",$E24),999),IFERROR(FIND("（",$E24),999))-1))=I$2,$F24,"")) | J24: =IF(OR($E24="",J$2=""),"",IF(TRIM(LEFT($E24,MIN(IFERROR(FIND("CDU",UPPER($E24)),999),IFERROR(FIND("BULK",UPPER($E24)),999),IFERROR(FIND("-",$E24),999),IFERROR(FIND("（",$E24),999))-1))=J$2,$F24,"")) -> 540 | K24: =IF(OR($E24="",K$2=""),"",IF(TRIM(LEFT($E24,MIN(IFERROR(FIND("CDU",UPPER($E24)),999),IFERROR(FIND("BULK",UPPER($E24)),999),IFERROR(FIND("-",$E24),999),IFERROR(FIND("（",$E24),999))-1))=K$2,$F24,"")) | L24: =IF(OR($E24="",L$2=""),"",IF(TRIM(LEFT($E24,MIN(IFERROR(FIND("CDU",UPPER($E24)),999),IFERROR(FIND("BULK",UPPER($E24)),999),IFERROR(FIND("-",$E24),999),IFERROR(FIND("（",$E24),999))-1))=L$2,$F24,"")) | M24: =IF(OR($E24="",M$2=""),"",IF(TRIM(LEFT($E24,MIN(IFERROR(FIND("CDU",UPPER($E24)),999),IFERROR(FIND("BULK",UPPER($E24)),999),IFERROR(FIND("-",$E24),999),IFERROR(FIND("（",$E24),999))-1))=M$2,$F24,"")) | N24: =IF(OR($E24="",N$2=""),"",IF(TRIM(LEFT($E24,MIN(IFERROR(FIND("CDU",UPPER($E24)),999),IFERROR(FIND("BULK",UPPER($E24)),999),IFERROR(FIND("-",$E24),999),IFERROR(FIND("（",$E24),999))-1))=N$2,$F24,"")) | O24: =IF(OR($E24="",O$2=""),"",IF(TRIM(LEFT($E24,MIN(IFERROR(FIND("CDU",UPPER($E24)),999),IFERROR(FIND("BULK",UPPER($E24)),999),IFERROR(FIND("-",$E24),999),IFERROR(FIND("（",$E24),999))-1))=O$2,$F24,"")) | ... AD24: =IF(OR($E24="",AD$2=""),"",IF(TRIM(LEFT($E24,MIN(IFERROR(FIND("CDU",UPPER($E24)),999),IFERROR(FIND("BULK",UPPER($E24)),999),IFERROR(FIND("-",$E24),999),IFERROR(FIND("（",$E24),999))-1))=AD$2,$F24,"")) | AE24: 7.34 | AF24: =SUM(H24:AD24)*AE24 -> 3963.6 | AG24: =AF24*7.75 -> 30717.9
A25: 45972 | B25: 46043 | C25: AE-ZT4062D-LS | D25: 1000002006 | E25: RA368 | F25: 2520 | H25: =IF(OR($E25="",H$2=""),"",IF(TRIM(LEFT($E25,MIN(IFERROR(FIND("CDU",UPPER($E25)),999),IFERROR(FIND("BULK",UPPER($E25)),999),IFERROR(FIND("-",$E25),999),IFERROR(FIND("（",$E25),999))-1))=H$2,$F25,"")) | I25: =IF(OR($E25="",I$2=""),"",IF(TRIM(LEFT($E25,MIN(IFERROR(FIND("CDU",UPPER($E25)),999),IFERROR(FIND("BULK",UPPER($E25)),999),IFERROR(FIND("-",$E25),999),IFERROR(FIND("（",$E25),999))-1))=I$2,$F25,"")) | J25: =IF(OR($E25="",J$2=""),"",IF(TRIM(LEFT($E25,MIN(IFERROR(FIND("CDU",UPPER($E25)),999),IFERROR(FIND("BULK",UPPER($E25)),999),IFERROR(FIND("-",$E25),999),IFERROR(FIND("（",$E25),999))-1))=J$2,$F25,"")) | K25: =IF(OR($E25="",K$2=""),"",IF(TRIM(LEFT($E25,MIN(IFERROR(FIND("CDU",UPPER($E25)),999),IFERROR(FIND("BULK",UPPER($E25)),999),IFERROR(FIND("-",$E25),999),IFERROR(FIND("（",$E25),999))-1))=K$2,$F25,"")) | L25: =IF(OR($E25="",L$2=""),"",IF(TRIM(LEFT($E25,MIN(IFERROR(FIND("CDU",UPPER($E25)),999),IFERROR(FIND("BULK",UPPER($E25)),999),IFERROR(FIND("-",$E25),999),IFERROR(FIND("（",$E25),999))-1))=L$2,$F25,"")) | M25: =IF(OR($E25="",M$2=""),"",IF(TRIM(LEFT($E25,MIN(IFERROR(FIND("CDU",UPPER($E25)),999),IFERROR(FIND("BULK",UPPER($E25)),999),IFERROR(FIND("-",$E25),999),IFERROR(FIND("（",$E25),999))-1))=M$2,$F25,"")) | N25: =IF(OR($E25="",N$2=""),"",IF(TRIM(LEFT($E25,MIN(IFERROR(FIND("CDU",UPPER($E25)),999),IFERROR(FIND("BULK",UPPER($E25)),999),IFERROR(FIND("-",$E25),999),IFERROR(FIND("（",$E25),999))-1))=N$2,$F25,"")) | O25: =IF(OR($E25="",O$2=""),"",IF(TRIM(LEFT($E25,MIN(IFERROR(FIND("CDU",UPPER($E25)),999),IFERROR(FIND("BULK",UPPER($E25)),999),IFERROR(FIND("-",$E25),999),IFERROR(FIND("（",$E25),999))-1))=O$2,$F25,"")) | ... AD25: =IF(OR($E25="",AD$2=""),"",IF(TRIM(LEFT($E25,MIN(IFERROR(FIND("CDU",UPPER($E25)),999),IFERROR(FIND("BULK",UPPER($E25)),999),IFERROR(FIND("-",$E25),999),IFERROR(FIND("（",$E25),999))-1))=AD$2,$F25,"")) | AE25: 7 | AF25: =SUM(H25:AD25)*AE25 -> 17640 | AG25: =AF25*7.75 -> 136710
A26: 45981 | B26: 46065 | C26: AE-PT8573D-LS | D26: 1000002079 | E26: GS673 | F26: =1500-752 -> 748 | H26: =IF(OR($E26="",H$2=""),"",IF(TRIM(LEFT($E26,MIN(IFERROR(FIND("CDU",UPPER($E26)),999),IFERROR(FIND("BULK",UPPER($E26)),999),IFERROR(FIND("-",$E26),999),IFERROR(FIND("（",$E26),999))-1))=H$2,$F26,"")) | I26: =IF(OR($E26="",I$2=""),"",IF(TRIM(LEFT($E26,MIN(IFERROR(FIND("CDU",UPPER($E26)),999),IFERROR(FIND("BULK",UPPER($E26)),999),IFERROR(FIND("-",$E26),999),IFERROR(FIND("（",$E26),999))-1))=I$2,$F26,"")) | J26: =IF(OR($E26="",J$2=""),"",IF(TRIM(LEFT($E26,MIN(IFERROR(FIND("CDU",UPPER($E26)),999),IFERROR(FIND("BULK",UPPER($E26)),999),IFERROR(FIND("-",$E26),999),IFERROR(FIND("（",$E26),999))-1))=J$2,$F26,"")) | K26: =IF(OR($E26="",K$2=""),"",IF(TRIM(LEFT($E26,MIN(IFERROR(FIND("CDU",UPPER($E26)),999),IFERROR(FIND("BULK",UPPER($E26)),999),IFERROR(FIND("-",$E26),999),IFERROR(FIND("（",$E26),999))-1))=K$2,$F26,"")) | L26: =IF(OR($E26="",L$2=""),"",IF(TRIM(LEFT($E26,MIN(IFERROR(FIND("CDU",UPPER($E26)),999),IFERROR(FIND("BULK",UPPER($E26)),999),IFERROR(FIND("-",$E26),999),IFERROR(FIND("（",$E26),999))-1))=L$2,$F26,"")) | M26: =IF(OR($E26="",M$2=""),"",IF(TRIM(LEFT($E26,MIN(IFERROR(FIND("CDU",UPPER($E26)),999),IFERROR(FIND("BULK",UPPER($E26)),999),IFERROR(FIND("-",$E26),999),IFERROR(FIND("（",$E26),999))-1))=M$2,$F26,"")) | N26: =IF(OR($E26="",N$2=""),"",IF(TRIM(LEFT($E26,MIN(IFERROR(FIND("CDU",UPPER($E26)),999),IFERROR(FIND("BULK",UPPER($E26)),999),IFERROR(FIND("-",$E26),999),IFERROR(FIND("（",$E26),999))-1))=N$2,$F26,"")) | O26: =IF(OR($E26="",O$2=""),"",IF(TRIM(LEFT($E26,MIN(IFERROR(FIND("CDU",UPPER($E26)),999),IFERROR(FIND("BULK",UPPER($E26)),999),IFERROR(FIND("-",$E26),999),IFERROR(FIND("（",$E26),999))-1))=O$2,$F26,"")) | ... AD26: =IF(OR($E26="",AD$2=""),"",IF(TRIM(LEFT($E26,MIN(IFERROR(FIND("CDU",UPPER($E26)),999),IFERROR(FIND("BULK",UPPER($E26)),999),IFERROR(FIND("-",$E26),999),IFERROR(FIND("（",$E26),999))-1))=AD$2,$F26,"")) | AE26: 11.5 | AF26: =SUM(H26:AD26)*AE26 -> 8602 | AG26: =AF26*7.75 -> 66665.5
A27: 45981 | B27: 46065 | C27: AE-PT8574D-LS | D27: 1000002079 | E27: GS675 | F27: =1500-180-280-292 -> 748 | H27: =IF(OR($E27="",H$2=""),"",IF(TRIM(LEFT($E27,MIN(IFERROR(FIND("CDU",UPPER($E27)),999),IFERROR(FIND("BULK",UPPER($E27)),999),IFERROR(FIND("-",$E27),999),IFERROR(FIND("（",$E27),999))-1))=H$2,$F27,"")) | I27: =IF(OR($E27="",I$2=""),"",IF(TRIM(LEFT($E27,MIN(IFERROR(FIND("CDU",UPPER($E27)),999),IFERROR(FIND("BULK",UPPER($E27)),999),IFERROR(FIND("-",$E27),999),IFERROR(FIND("（",$E27),999))-1))=I$2,$F27,"")) | J27: =IF(OR($E27="",J$2=""),"",IF(TRIM(LEFT($E27,MIN(IFERROR(FIND("CDU",UPPER($E27)),999),IFERROR(FIND("BULK",UPPER($E27)),999),IFERROR(FIND("-",$E27),999),IFERROR(FIND("（",$E27),999))-1))=J$2,$F27,"")) | K27: =IF(OR($E27="",K$2=""),"",IF(TRIM(LEFT($E27,MIN(IFERROR(FIND("CDU",UPPER($E27)),999),IFERROR(FIND("BULK",UPPER($E27)),999),IFERROR(FIND("-",$E27),999),IFERROR(FIND("（",$E27),999))-1))=K$2,$F27,"")) | L27: =IF(OR($E27="",L$2=""),"",IF(TRIM(LEFT($E27,MIN(IFERROR(FIND("CDU",UPPER($E27)),999),IFERROR(FIND("BULK",UPPER($E27)),999),IFERROR(FIND("-",$E27),999),IFERROR(FIND("（",$E27),999))-1))=L$2,$F27,"")) | M27: =IF(OR($E27="",M$2=""),"",IF(TRIM(LEFT($E27,MIN(IFERROR(FIND("CDU",UPPER($E27)),999),IFERROR(FIND("BULK",UPPER($E27)),999),IFERROR(FIND("-",$E27),999),IFERROR(FIND("（",$E27),999))-1))=M$2,$F27,"")) | N27: =IF(OR($E27="",N$2=""),"",IF(TRIM(LEFT($E27,MIN(IFERROR(FIND("CDU",UPPER($E27)),999),IFERROR(FIND("BULK",UPPER($E27)),999),IFERROR(FIND("-",$E27),999),IFERROR(FIND("（",$E27),999))-1))=N$2,$F27,"")) | O27: =IF(OR($E27="",O$2=""),"",IF(TRIM(LEFT($E27,MIN(IFERROR(FIND("CDU",UPPER($E27)),999),IFERROR(FIND("BULK",UPPER($E27)),999),IFERROR(FIND("-",$E27),999),IFERROR(FIND("（",$E27),999))-1))=O$2,$F27,"")) | ... AD27: =IF(OR($E27="",AD$2=""),"",IF(TRIM(LEFT($E27,MIN(IFERROR(FIND("CDU",UPPER($E27)),999),IFERROR(FIND("BULK",UPPER($E27)),999),IFERROR(FIND("-",$E27),999),IFERROR(FIND("（",$E27),999))-1))=AD$2,$F27,"")) | AE27: 12 | AF27: =SUM(H27:AD27)*AE27 -> 8976 | AG27: =AF27*7.75 -> 69564
A28: 45981 | B28: 46065 | C28: AE-PT8573D-LS | D28: 1000002079 | E28: GS673 | F28: 752 | H28: =IF(OR($E28="",H$2=""),"",IF(TRIM(LEFT($E28,MIN(IFERROR(FIND("CDU",UPPER($E28)),999),IFERROR(FIND("BULK",UPPER($E28)),999),IFERROR(FIND("-",$E28),999),IFERROR(FIND("（",$E28),999))-1))=H$2,$F28,"")) | I28: =IF(OR($E28="",I$2=""),"",IF(TRIM(LEFT($E28,MIN(IFERROR(FIND("CDU",UPPER($E28)),999),IFERROR(FIND("BULK",UPPER($E28)),999),IFERROR(FIND("-",$E28),999),IFERROR(FIND("（",$E28),999))-1))=I$2,$F28,"")) | J28: =IF(OR($E28="",J$2=""),"",IF(TRIM(LEFT($E28,MIN(IFERROR(FIND("CDU",UPPER($E28)),999),IFERROR(FIND("BULK",UPPER($E28)),999),IFERROR(FIND("-",$E28),999),IFERROR(FIND("（",$E28),999))-1))=J$2,$F28,"")) | K28: =IF(OR($E28="",K$2=""),"",IF(TRIM(LEFT($E28,MIN(IFERROR(FIND("CDU",UPPER($E28)),999),IFERROR(FIND("BULK",UPPER($E28)),999),IFERROR(FIND("-",$E28),999),IFERROR(FIND("（",$E28),999))-1))=K$2,$F28,"")) | L28: =IF(OR($E28="",L$2=""),"",IF(TRIM(LEFT($E28,MIN(IFERROR(FIND("CDU",UPPER($E28)),999),IFERROR(FIND("BULK",UPPER($E28)),999),IFERROR(FIND("-",$E28),999),IFERROR(FIND("（",$E28),999))-1))=L$2,$F28,"")) | M28: =IF(OR($E28="",M$2=""),"",IF(TRIM(LEFT($E28,MIN(IFERROR(FIND("CDU",UPPER($E28)),999),IFERROR(FIND("BULK",UPPER($E28)),999),IFERROR(FIND("-",$E28),999),IFERROR(FIND("（",$E28),999))-1))=M$2,$F28,"")) | N28: =IF(OR($E28="",N$2=""),"",IF(TRIM(LEFT($E28,MIN(IFERROR(FIND("CDU",UPPER($E28)),999),IFERROR(FIND("BULK",UPPER($E28)),999),IFERROR(FIND("-",$E28),999),IFERROR(FIND("（",$E28),999))-1))=N$2,$F28,"")) | O28: =IF(OR($E28="",O$2=""),"",IF(TRIM(LEFT($E28,MIN(IFERROR(FIND("CDU",UPPER($E28)),999),IFERROR(FIND("BULK",UPPER($E28)),999),IFERROR(FIND("-",$E28),999),IFERROR(FIND("（",$E28),999))-1))=O$2,$F28,"")) | ... AD28: =IF(OR($E28="",AD$2=""),"",IF(TRIM(LEFT($E28,MIN(IFERROR(FIND("CDU",UPPER($E28)),999),IFERROR(FIND("BULK",UPPER($E28)),999),IFERROR(FIND("-",$E28),999),IFERROR(FIND("（",$E28),999))-1))=AD$2,$F28,"")) | AE28: 11.5 | AF28: =SUM(H28:AD28)*AE28 -> 8648 | AG28: =AF28*7.75 -> 67022
A29: 45981 | B29: 46065 | C29: AE-PT8574D-LS | D29: 1000002079 | E29: GS675 | F29: =180+280+292 -> 752 | H29: =IF(OR($E29="",H$2=""),"",IF(TRIM(LEFT($E29,MIN(IFERROR(FIND("CDU",UPPER($E29)),999),IFERROR(FIND("BULK",UPPER($E29)),999),IFERROR(FIND("-",$E29),999),IFERROR(FIND("（",$E29),999))-1))=H$2,$F29,"")) | I29: =IF(OR($E29="",I$2=""),"",IF(TRIM(LEFT($E29,MIN(IFERROR(FIND("CDU",UPPER($E29)),999),IFERROR(FIND("BULK",UPPER($E29)),999),IFERROR(FIND("-",$E29),999),IFERROR(FIND("（",$E29),999))-1))=I$2,$F29,"")) | J29: =IF(OR($E29="",J$2=""),"",IF(TRIM(LEFT($E29,MIN(IFERROR(FIND("CDU",UPPER($E29)),999),IFERROR(FIND("BULK",UPPER($E29)),999),IFERROR(FIND("-",$E29),999),IFERROR(FIND("（",$E29),999))-1))=J$2,$F29,"")) | K29: =IF(OR($E29="",K$2=""),"",IF(TRIM(LEFT($E29,MIN(IFERROR(FIND("CDU",UPPER($E29)),999),IFERROR(FIND("BULK",UPPER($E29)),999),IFERROR(FIND("-",$E29),999),IFERROR(FIND("（",$E29),999))-1))=K$2,$F29,"")) | L29: =IF(OR($E29="",L$2=""),"",IF(TRIM(LEFT($E29,MIN(IFERROR(FIND("CDU",UPPER($E29)),999),IFERROR(FIND("BULK",UPPER($E29)),999),IFERROR(FIND("-",$E29),999),IFERROR(FIND("（",$E29),999))-1))=L$2,$F29,"")) | M29: =IF(OR($E29="",M$2=""),"",IF(TRIM(LEFT($E29,MIN(IFERROR(FIND("CDU",UPPER($E29)),999),IFERROR(FIND("BULK",UPPER($E29)),999),IFERROR(FIND("-",$E29),999),IFERROR(FIND("（",$E29),999))-1))=M$2,$F29,"")) | N29: =IF(OR($E29="",N$2=""),"",IF(TRIM(LEFT($E29,MIN(IFERROR(FIND("CDU",UPPER($E29)),999),IFERROR(FIND("BULK",UPPER($E29)),999),IFERROR(FIND("-",$E29),999),IFERROR(FIND("（",$E29),999))-1))=N$2,$F29,"")) | O29: =IF(OR($E29="",O$2=""),"",IF(TRIM(LEFT($E29,MIN(IFERROR(FIND("CDU",UPPER($E29)),999),IFERROR(FIND("BULK",UPPER($E29)),999),IFERROR(FIND("-",$E29),999),IFERROR(FIND("（",$E29),999))-1))=O$2,$F29,"")) | ... AD29: =IF(OR($E29="",AD$2=""),"",IF(TRIM(LEFT($E29,MIN(IFERROR(FIND("CDU",UPPER($E29)),999),IFERROR(FIND("BULK",UPPER($E29)),999),IFERROR(FIND("-",$E29),999),IFERROR(FIND("（",$E29),999))-1))=AD$2,$F29,"")) | AE29: 12 | AF29: =SUM(H29:AD29)*AE29 -> 9024 | AG29: =AF29*7.75 -> 69936
A30: 45981 | B30: 46065 | C30: PZ5840-LS | D30: 1000002079 | E30: HH429 | F30: 3000 | H30: =IF(OR($E30="",H$2=""),"",IF(TRIM(LEFT($E30,MIN(IFERROR(FIND("CDU",UPPER($E30)),999),IFERROR(FIND("BULK",UPPER($E30)),999),IFERROR(FIND("-",$E30),999),IFERROR(FIND("（",$E30),999))-1))=H$2,$F30,"")) | I30: =IF(OR($E30="",I$2=""),"",IF(TRIM(LEFT($E30,MIN(IFERROR(FIND("CDU",UPPER($E30)),999),IFERROR(FIND("BULK",UPPER($E30)),999),IFERROR(FIND("-",$E30),999),IFERROR(FIND("（",$E30),999))-1))=I$2,$F30,"")) | J30: =IF(OR($E30="",J$2=""),"",IF(TRIM(LEFT($E30,MIN(IFERROR(FIND("CDU",UPPER($E30)),999),IFERROR(FIND("BULK",UPPER($E30)),999),IFERROR(FIND("-",$E30),999),IFERROR(FIND("（",$E30),999))-1))=J$2,$F30,"")) | K30: =IF(OR($E30="",K$2=""),"",IF(TRIM(LEFT($E30,MIN(IFERROR(FIND("CDU",UPPER($E30)),999),IFERROR(FIND("BULK",UPPER($E30)),999),IFERROR(FIND("-",$E30),999),IFERROR(FIND("（",$E30),999))-1))=K$2,$F30,"")) | L30: =IF(OR($E30="",L$2=""),"",IF(TRIM(LEFT($E30,MIN(IFERROR(FIND("CDU",UPPER($E30)),999),IFERROR(FIND("BULK",UPPER($E30)),999),IFERROR(FIND("-",$E30),999),IFERROR(FIND("（",$E30),999))-1))=L$2,$F30,"")) | M30: =IF(OR($E30="",M$2=""),"",IF(TRIM(LEFT($E30,MIN(IFERROR(FIND("CDU",UPPER($E30)),999),IFERROR(FIND("BULK",UPPER($E30)),999),IFERROR(FIND("-",$E30),999),IFERROR(FIND("（",$E30),999))-1))=M$2,$F30,"")) | N30: =IF(OR($E30="",N$2=""),"",IF(TRIM(LEFT($E30,MIN(IFERROR(FIND("CDU",UPPER($E30)),999),IFERROR(FIND("BULK",UPPER($E30)),999),IFERROR(FIND("-",$E30),999),IFERROR(FIND("（",$E30),999))-1))=N$2,$F30,"")) | O30: =IF(OR($E30="",O$2=""),"",IF(TRIM(LEFT($E30,MIN(IFERROR(FIND("CDU",UPPER($E30)),999),IFERROR(FIND("BULK",UPPER($E30)),999),IFERROR(FIND("-",$E30),999),IFERROR(FIND("（",$E30),999))-1))=O$2,$F30,"")) | ... AD30: =IF(OR($E30="",AD$2=""),"",IF(TRIM(LEFT($E30,MIN(IFERROR(FIND("CDU",UPPER($E30)),999),IFERROR(FIND("BULK",UPPER($E30)),999),IFERROR(FIND("-",$E30),999),IFERROR(FIND("（",$E30),999))-1))=AD$2,$F30,"")) | AE30: 4.26 | AF30: =SUM(H30:AD30)*AE30 -> 12780 | AG30: =AF30*7.75 -> 99045
A31: 45994 | B31: 46065 | C31: P1246/2-LS | D31: 1000002184 | E31: 300OK | F31: 1800 | H31: =IF(OR($E31="",H$2=""),"",IF(TRIM(LEFT($E31,MIN(IFERROR(FIND("CDU",UPPER($E31)),999),IFERROR(FIND("BULK",UPPER($E31)),999),IFERROR(FIND("-",$E31),999),IFERROR(FIND("（",$E31),999))-1))=H$2,$F31,"")) | I31: =IF(OR($E31="",I$2=""),"",IF(TRIM(LEFT($E31,MIN(IFERROR(FIND("CDU",UPPER($E31)),999),IFERROR(FIND("BULK",UPPER($E31)),999),IFERROR(FIND("-",$E31),999),IFERROR(FIND("（",$E31),999))-1))=I$2,$F31,"")) | J31: =IF(OR($E31="",J$2=""),"",IF(TRIM(LEFT($E31,MIN(IFERROR(FIND("CDU",UPPER($E31)),999),IFERROR(FIND("BULK",UPPER($E31)),999),IFERROR(FIND("-",$E31),999),IFERROR(FIND("（",$E31),999))-1))=J$2,$F31,"")) | K31: =IF(OR($E31="",K$2=""),"",IF(TRIM(LEFT($E31,MIN(IFERROR(FIND("CDU",UPPER($E31)),999),IFERROR(FIND("BULK",UPPER($E31)),999),IFERROR(FIND("-",$E31),999),IFERROR(FIND("（",$E31),999))-1))=K$2,$F31,"")) | L31: =IF(OR($E31="",L$2=""),"",IF(TRIM(LEFT($E31,MIN(IFERROR(FIND("CDU",UPPER($E31)),999),IFERROR(FIND("BULK",UPPER($E31)),999),IFERROR(FIND("-",$E31),999),IFERROR(FIND("（",$E31),999))-1))=L$2,$F31,"")) | M31: =IF(OR($E31="",M$2=""),"",IF(TRIM(LEFT($E31,MIN(IFERROR(FIND("CDU",UPPER($E31)),999),IFERROR(FIND("BULK",UPPER($E31)),999),IFERROR(FIND("-",$E31),999),IFERROR(FIND("（",$E31),999))-1))=M$2,$F31,"")) | N31: =IF(OR($E31="",N$2=""),"",IF(TRIM(LEFT($E31,MIN(IFERROR(FIND("CDU",UPPER($E31)),999),IFERROR(FIND("BULK",UPPER($E31)),999),IFERROR(FIND("-",$E31),999),IFERROR(FIND("（",$E31),999))-1))=N$2,$F31,"")) | O31: =IF(OR($E31="",O$2=""),"",IF(TRIM(LEFT($E31,MIN(IFERROR(FIND("CDU",UPPER($E31)),999),IFERROR(FIND("BULK",UPPER($E31)),999),IFERROR(FIND("-",$E31),999),IFERROR(FIND("（",$E31),999))-1))=O$2,$F31,"")) | ... AD31: =IF(OR($E31="",AD$2=""),"",IF(TRIM(LEFT($E31,MIN(IFERROR(FIND("CDU",UPPER($E31)),999),IFERROR(FIND("BULK",UPPER($E31)),999),IFERROR(FIND("-",$E31),999),IFERROR(FIND("（",$E31),999))-1))=AD$2,$F31,"")) | AE31: 0.36 | AF31: =SUM(H31:AD31)*AE31 -> 648 | AG31: =AF31*7.75 -> 5022
