Workbook

Sheet 樣板單
A1: ZURU Rainbocorn 樣板訂單 | V1: 1代珠片公仔#9201 | AE1: 2代珠片公仔#9202 | AN1: #9204 | AW1: #9214 | BE1: #9209 | BV1: #9202 | CI1: #9204 | CO1: #9214（第二代） | CU1: #9209 | CX1: #9215 | DE1: #9212 | DK1: #9213 | DN1: #9207 | DO1: #9208
V2: 收縮膜 | Y2: 說明書 | AE2: 收縮膜 | AH2: 說明書 | AN2: A版本 | AP2: B版本 | BJ2: 3 | BL2: 4 | BN2: 5 | BP2: 5 | BR2: 4 | BT2: 3
A3: 香港接单日期 | B3: ZURU 跟单 | C3: ZURU PO NO# | D3: 第三方客户 PO NO# | E3: 第三方客户名称 | F3: ITEM# | G3: 中文名 | H3: PO数量 (pcs) | I3: 内箱装箱数量(pcs) | J3: 外箱装箱数量(pcs) | K3: 总箱数 | L3: 单价USD | M3: 金额USD | N3: ZURU验货 日期 | O3: 驗貨結果 | P3: 第三方客户公证行验货 | Q3: ZURU订单走货日期 | R3: ZURU确认走货日期 | S3: 箱唛资料(收到日期) | T3: 箱唛资料(确认日期) | U3: 客供贴纸AI(收到日期) | V3: MA 1語收縮膜 | W3: MA 3語收縮膜 | X3: 客版收縮膜 | Y3: MA 1語说明书 A版本 | Z3: MA 1語说明书 B版本 | AA3: MA 3語說明書 A版本 | AB3: MA 3語說明書 B版本 | AC3: 客版說明書 | AD3: 布標 | AE3: MA 1語收縮膜 | AF3: MA 3語收縮膜 | AG3: 客版收縮膜 | AH3: MA 1語说明书 A版本 | AI3: MA 1語说明书 B版本 | AJ3: MA 3語說明書 A版本 | AK3: MA 3語說明書 B版本 | AL3: 客版說明書 | AM3: 布標 | AN3: MA 1語收縮膜 | AO3: MA 1語說明書 | AP3: MA 1語收縮膜 | AQ3: MA 1語說明書 | AR3: MA 2語收縮膜（加拿大版本） | AS3: MA 2語說明書（加拿大版本） | AT3: 落加拿大 棉花泥 | AU3: 9201SQ1 | AV3: 9204UQ1 | AW3: MA 1語收縮膜 A | AX3: MA 1語收縮膜 B | AY3: MA 1語說明書 A | AZ3: MA 1語收縮膜 B | BA3: MA 1語說明書 B | BB3: MA领养卡 | BC3: 9214SQ1 MA PDQ盒 | BD3: 9214UQ1 客办PDQ盒 | BE3: MA 1語收縮膜 | BF3: MA 1語說明書 | BG3: MA 3語收縮膜 | BH3: MA 3語說明書 | BI3: 發票號 | BJ3: 玫紅猴子 Monkey（A） | BK3: 黃色猴子 Monkey（B） | BL3: 粉紅貓 Kitty （A） | BM3: 玫紅貓 Kitty （B） | BN3: 白色兔子 Rabbit （A） | BO3: 玫紅兔子 Rabbit （B） | BP3: 白色獨角獸 Unicorn （A） | BQ3: 玫紅獨角獸 Unicorn （B） | BR3: 紫色小狗 Puppy （A） | BS3: 藍色小狗 Puppy （B） | BT3: 粉色倉鼠 Hamster （A） | BU3: 橙色倉鼠 Hamster （B） | BV3: 羊駝 Llama（白色） | BW3: 羊駝 Llama（紫色） | BX3: 火烈鳥 Flamingo （玫紅色） | BY3: 火烈鳥 Flamingo （彩虹色） | BZ3: 火烈鳥 Flamingo （金色） | CA3: 熊貓 Panda （黑白色） | CB3: 熊貓 Panda （粉紅色） | CC3: 貓頭鷹 OWL （紫色） | CD3: 貓頭鷹 OWL （白色） | CE3: 獨角獸 Unicorn （白色） | CF3: 獨角獸 Unicorn （紫色） | CG3: 獅子 Lion （粉紅色） | CH3: 獅子 Lion （黃色） | CI3: 白色獨角獸 Unicorn | CJ3: 枚红色火烈鸟 Flamingo | CK3: 白色羊驼 Llama | CL3: 粉红色猫 Kitty | CM3: 紫色兔子 Bunny | CN3: 蓝色小狗 Puppy | CO3: 白色猫头鹰 White Owl | CP3: 粉色狮子 Pink Lion | CQ3: 黄色猴子 Yellow Monkey | CR3: 紫色独角兽 Purple Unicorn | CS3: 白色熊猫 White Panda | CT3: 彩色火烈鸟 Colour Flamingo | CU3: 獨角獸 Unicorn | CV3: 白色羊驼 Llama | CW3: 枚红色火烈鸟 Flamingo | CX3: 孔雀 Peacock | CY3: 火烈鸟 Toucan | CZ3: 树懒 Sloth | DA3: 大象 Elephant | DB3: 老虎 Tiger | DC3: 梅花鹿 Giraffe | DD3: 斑马 Zebra | DE3: 兔子 Bunny 含海绵 | DF3: 小狗 Puppy | DG3: 羊驼 Llama | DH3: 小猫 Kitty 含海绵 | DI3: 独角兽 Unicorn | DJ3: 猴子 Monkey | DK3: 小猫 Kitten | DL3: 独角兽 Unicorn | DM3: 大嘴鸟 Toucan | DN3: 2PK超小蛋殼公仔 | DO3: 4PK超小蛋殼公仔
A4: 43243 | B4: Binnie | C4: ZMPO18068 | F4: 9201-S001 | G4: 珠片公仔 | H4: 360 | V4: =H4 -> 360 | Y4: =H4 -> 360 | AD4: MA布標 | BI4: 19573 | BJ4: =H4/12 -> 30 | BK4: =H4/12 -> 30 | BL4: =H4/12 -> 30 | BM4: =H4/12 -> 30 | BN4: =H4/12 -> 30 | BO4: =H4/12 -> 30 | BP4: =H4/12 -> 30 | BQ4: =H4/12 -> 30 | BR4: =H4/12 -> 30 | BS4: =H4/12 -> 30 | BT4: =H4/12 -> 30 | BU4: =H4/12 -> 30
A5: 43265 | B5: Amanda | C5: ZMPO18078 | F5: 9201-S001 | G5: 珠片公仔 | H5: 480 | V5: =H5 -> 480 | Y5: =H5 -> 480 | AD5: MA布標 | BI5: 19654 | BJ5: =H5/12 -> 40 | BK5: =H5/12 -> 40 | BL5: =H5/12 -> 40 | BM5: =H5/12 -> 40 | BN5: =H5/12 -> 40 | BO5: =H5/12 -> 40 | BP5: =H5/12 -> 40 | BQ5: =H5/12 -> 40 | BR5: =H5/12 -> 40 | BS5: =H5/12 -> 40 | BT5: =H5/12 -> 40 | BU5: =H5/12 -> 40
A6: 43265 | B6: Angela | C6: 4500010393 | E6: 簽板 | F6: 9201-S001 | G6: 珠片公仔 | H6: 36 | V6: =H6 -> 36 | Y6: =H6 -> 36 | AD6: MA布標 | BJ6: =H6/12 -> 3 | BK6: =H6/12 -> 3 | BL6: =H6/12 -> 3 | BM6: =H6/12 -> 3 | BN6: =H6/12 -> 3 | BO6: =H6/12 -> 3 | BP6: =H6/12 -> 3 | BQ6: =H6/12 -> 3 | BR6: =H6/12 -> 3 | BS6: =H6/12 -> 3 | BT6: =H6/12 -> 3 | BU6: =H6/12 -> 3
A7: 43265 | B7: Lingly | C7: 4500010570 | E7: GP測試版 | F7: 9201-S001 | G7: 珠片公仔 | H7: 12 | V7: =H7 -> 12 | Y7: =H7 -> 12 | AD7: MA布標 | BJ7: =H7/12 -> 1 | BK7: =H7/12 -> 1 | BL7: =H7/12 -> 1 | BM7: =H7/12 -> 1 | BN7: =H7/12 -> 1 | BO7: =H7/12 -> 1 | BP7: =H7/12 -> 1 | BQ7: =H7/12 -> 1 | BR7: =H7/12 -> 1 | BS7: =H7/12 -> 1 | BT7: =H7/12 -> 1 | BU7: =H7/12 -> 1
A8: 43265 | B8: Holly | C8: 4500009837 | E8: 寄客版 | F8: 9201-S001 | G8: 珠片公仔 | H8: 12 | V8: =H8 -> 12 | Y8: =H8 -> 12 | AD8: MA布標 | BJ8: =H8/12 -> 1 | BK8: =H8/12 -> 1 | BL8: =H8/12 -> 1 | BM8: =H8/12 -> 1 | BN8: =H8/12 -> 1 | BO8: =H8/12 -> 1 | BP8: =H8/12 -> 1 | BQ8: =H8/12 -> 1 | BR8: =H8/12 -> 1 | BS8: =H8/12 -> 1 | BT8: =H8/12 -> 1 | BU8: =H8/12 -> 1
A9: 43270 | B9: Sara | C9: 郵件 | E9: Candide客户样品 | F9: 9201-S001 | G9: 珠片公仔 | H9: 6 | V9: =H9 -> 6 | Y9: =H9 -> 6 | AD9: MA布標 | BJ9: 1 | BL9: 1 | BN9: 1 | BP9: 1 | BR9: 1 | BT9: 1
A10: 43270 | B10: Sara | C10: 4500010598 | E10: WABRO | F10: 9201-S001 | G10: 珠片公仔 | H10: 24 | V10: =H10 -> 24 | Y10: =H10 -> 24 | AD10: MA布標 | BJ10: =H10/12 -> 2 | BK10: =H10/12 -> 2 | BL10: =H10/12 -> 2 | BM10: =H10/12 -> 2 | BN10: =H10/12 -> 2 | BO10: =H10/12 -> 2 | BP10: =H10/12 -> 2 | BQ10: =H10/12 -> 2 | BR10: =H10/12 -> 2 | BS10: =H10/12 -> 2 | BT10: =H10/12 -> 2 | BU10: =H10/12 -> 2
A11: 43277 | B11: Tiffany | C11: 4500010957 | D11: 大貨簽板 | E11: EURO TOYS EUROPE BV | F11: 9201-S001 | G11: 珠片公仔 | H11: 36 | X11: 36 | AC11: 36 | AD11: MA布標 | BJ11: =H11/12 -> 3 | BK11: =H11/12 -> 3 | BL11: =H11/12 -> 3 | BM11: =H11/12 -> 3 | BN11: =H11/12 -> 3 | BO11: =H11/12 -> 3 | BP11: =H11/12 -> 3 | BQ11: =H11/12 -> 3 | BR11: =H11/12 -> 3 | BS11: =H11/12 -> 3 | BT11: =H11/12 -> 3 | BU11: =H11/12 -> 3
A12: 43277 | B12: Lucky | C12: 450012096 | D12: 產前測試 | E12: CENCOSUD CHILE | F12: 9201-S001 | G12: 珠片公仔 | H12: 12 | V12: 12 | Y12: 12 | AD12: MA布標 | BJ12: =H12/12 -> 1 | BK12: =H12/12 -> 1 | BL12: =H12/12 -> 1 | BM12: =H12/12 -> 1 | BN12: =H12/12 -> 1 | BO12: =H12/12 -> 1 | BP12: =H12/12 -> 1 | BQ12: =H12/12 -> 1 | BR12: =H12/12 -> 1 | BS12: =H12/12 -> 1 | BT12: =H12/12 -> 1 | BU12: =H12/12 -> 1
A13: 43265 | B13: Lingly | C13: 4500010570 | E13: 年齡評估樣品 | F13: 9201-S001 | G13: 珠片公仔 | H13: 2 | V13: 12 | Y13: 12 | AD13: MA布標 | BN13: 1 | BO13: 1
A14: 43284 | C14: ZMPO18086 | F14: 9201-S001 | G14: 珠片公仔 | H14: 480 | V14: 480 | Y14: 480 | AD14: MA布標 | BI14: 19655 | BJ14: =H14/12 -> 40 | BK14: =H14/12 -> 40 | BL14: =H14/12 -> 40 | BM14: =H14/12 -> 40 | BN14: =H14/12 -> 40 | BO14: =H14/12 -> 40 | BP14: =H14/12 -> 40 | BQ14: =H14/12 -> 40 | BR14: =H14/12 -> 40 | BS14: =H14/12 -> 40 | BT14: =H14/12 -> 40 | BU14: =H14/12 -> 40
A15: 43286 | C15: 4500010467 | F15: 9201-S001 | G15: 珠片公仔 | H15: 10 | V15: 10 | Y15: 10 | AD15: MA布標 | BL15: 1 | BM15: 1 | BN15: 1 | BO15: 1 | BP15: 1 | BQ15: 1 | BR15: 1 | BS15: 1 | BT15: 1 | BU15: 1
A16: 43287 | C16: 4500010333 | F16: 9201-S001 | G16: 珠片公仔 | H16: 10 | V16: 10 | Y16: 10 | AD16: MA布標 | BL16: 1 | BM16: 1 | BN16: 1 | BO16: 1 | BP16: 1 | BQ16: 1 | BR16: 1 | BS16: 1 | BT16: 1 | BU16: 1
A17: 43302 | C17: 4500012533 | F17: 9201-S001 | G17: 珠片公仔 | H17: 12 | V17: 12 | Y17: 12 | AD17: MA布標 | BJ17: 1 | BK17: 1 | BL17: 1 | BM17: 1 | BN17: 1 | BO17: 1 | BP17: 1 | BQ17: 1 | BR17: 1 | BS17: 1 | BT17: 1 | BU17: 1
A18: 43302 | C18: 4500010568 | F18: 9201-S001 | G18: 珠片公仔 | H18: 4 | V18: 4 | AC18: 4 | AD18: 丹麥布標 | BJ18: 1 | BL18: 1 | BN18: 1 | BP18: 1
A19: 43306 | C19: 4500010570 | E19: GP FRANCE | F19: 9201-S001 | G19: 珠片公仔 | H19: 28 | X19: 28 | Y19: 28 | AD19: 法國布標 | BJ19: 3 | BK19: 2 | BL19: 3 | BM19: 2 | BN19: 3 | BO19: 2 | BP19: 3 | BQ19: 2 | BR19: 2 | BS19: 2 | BT19: 2 | BU19: 2
A20: 43306 | C20: 4500010574 | E20: GP ITALY | F20: 9201-S001 | G20: 珠片公仔 | H20: 25 | X20: 25 | Y20: 25 | AD20: 意大利布標 | BJ20: 2 | BK20: 2 | BL20: 2 | BM20: 2 | BN20: 2 | BO20: 2 | BP20: 3 | BQ20: 2 | BR20: 2 | BS20: 2 | BT20: 2 | BU20: 2
A21: 43313 | C21: 4500009768 | E21: TOY TRIANGLE CO.W.L.L | F21: 9201-S001 | G21: 珠片公仔 | H21: 2 | V21: 2 | Y21: 2 | AD21: MA布標 | BN21: 1 | BP21: 1
A22: 43313 | C22: 4500012277 | E22: Express Gifts Ltd | F22: 9201-S006 | G22: 珠片公仔 | H22: 10 | V22: 10 | Y22: 10 | AD22: MA布標 | BL22: 1 | BM22: 1 | BN22: 1 | BO22: 1 | BP22: 1 | BQ22: 1 | BR22: 1 | BS22: 1 | BT22: 1 | BU22: 1
A23: 43316 | C23: 4500009878 | E23: P.M.I TRADING & ENTERPRISE LTS34 | F23: 9201-S001 | G23: 珠片公仔 | H23: 2 | V23: 2 | Y23: 2 | AD23: MA布標
A24: 43318 | C24: 4500012769 | E24: TOYS kingdom | F24: 9201-S001 | G24: 珠片公仔 | H24: 2 | AD24: MA布標 | BT24: 2
A25: 43321 | C25: 4500012192 | D25: 簽板 | E25: CANDIDE IND E COM LTDA | F25: 9201-S001 | G25: 珠片公仔 | H25: 25 | X25: 25 | AC25: 25 | AD25: 巴西布標 | BJ25: 2 | BK25: 2 | BL25: 2 | BM25: 2 | BN25: 2 | BO25: 2 | BP25: 3 | BQ25: 2 | BR25: 2 | BS25: 2 | BT25: 2 | BU25: 2
A26: 43323 | C26: 4500012835 | D26: 產前測試 | E26: WAL-MART.COM | F26: 9201-S001 | G26: 珠片公仔 | H26: 18 | V26: 18 | Y26: 18 | AD26: MA布標 | BJ26: 3 | BL26: 3 | BN26: 3 | BP26: 3 | BR26: 3 | BT26: 3
A27: 43332 | C27: 4500010580 | D27: 大貨版、簽板 | E27: GP SPAIN | F27: 9201-S001 | G27: 珠片公仔 | H27: 12 | X27: 12 | Y27: 12 | AD27: 西班牙布標 | BJ27: 2 | BK27: 2 | BL27: 2 | BM27: 2 | BN27: 2 | BO27: 2 | BP27: 3 | BQ27: 2 | BR27: 2 | BS27: 2 | BT27: 2 | BU27: 2
A28: 43332 | C28: 4500011417 | D28: 大貨版、簽板 | E28: GP TURKEY | F28: 9201-S001 | G28: 珠片公仔 | H28: 12 | X28: 12 | Y28: 12 | AD28: 土耳其布標 | BJ28: 2 | BK28: 2 | BL28: 2 | BM28: 2 | BN28: 2 | BO28: 2 | BP28: 3 | BQ28: 2 | BR28: 2 | BS28: 2 | BT28: 2 | BU28: 2
A29: 43335 | C29: 4500012306 | D29: MA 3語簽板 | E29: 360 SALES SOLUTIONS INC | F29: 9201-S001 | G29: 珠片公仔 | H29: 24 | W29: 24 | AA29: 24 | AD29: MA布標 | BJ29: 2 | BK29: 2 | BL29: 2 | BM29: 2 | BN29: 2 | BO29: 2 | BP29: 2 | BQ29: 2 | BR29: 2 | BS29: 2 | BT29: 2 | BU29: 2
A30: 43336 | C30: 4500009673 | D30: 大貨樣板 | E30: B&M RETAIL LIMITED | F30: 9201-S003 | G30: 珠片公仔 | H30: 10 | V30: 10 | Y30: 10 | AD30: MA布標 | BL30: 1 | BM30: 1 | BN30: 1 | BO30: 1 | BP30: 1 | BQ30: 1 | BR30: 1 | BS30: 1 | BT30: 1 | BU30: 1
A31: 43336 | C31: 郵件 | D31: Intek 客户样品 | E31: Lucky | F31: 9201-S001 | G31: 珠片公仔 | H31: 24 | V31: 24 | Y31: 24 | AD31: MA布標 | BJ31: 2 | BK31: 2 | BL31: 2 | BM31: 2 | BN31: 2 | BO31: 2 | BP31: 2 | BQ31: 2 | BR31: 2 | BS31: 2 | BT31: 2 | BU31: 2
A32: 43342 | C32: ZMPO18108 | F32: 9201-S001 | G32: 珠片公仔 | H32: 360 | V32: 24 | Y32: 24 | BI32: 19952 | BJ32: =H32/24*3/2 -> 22.5 | BK32: =H32/24*3/2 -> 22.5 | BL32: =H32/24*4/2 -> 30 | BM32: =H32/24*4/2 -> 30 | BN32: =H32/24*5/2 -> 37.5 | BO32: =H32/24*5/2 -> 37.5 | BP32: =H32/24*5/2 -> 37.5 | BQ32: =H32/24*5/2 -> 37.5 | BR32: =H32/24*4/2 -> 30 | BS32: =H32/24*4/2 -> 30 | BT32: =H32/24*3/2 -> 22.5 | BU32: =H32/24*3/2 -> 22.5
A33: 43364 | C33: 4500011712 | D33: 大貨樣板 | E33: TARGET US | F33: 9201-S001 | G33: 珠片公仔 | H33: 9 | V33: 9 | Y33: 9 | AD33: MA布標 | BJ33: 1 | BK33: 1 | BL33: 1 | BM33: 1 | BQ33: 1 | BR33: 1 | BS33: 1 | BT33: 1 | BU33: 1
A34: 43364 | C34: 4500013372 | D34: 大貨樣板 | E34: DISTRIBUIDORA JUGUETRON S.A DE C.V | F34: 9201-S001 | G34: 珠片公仔 | H34: 2 | W34: 2 | AA34: 2 | AD34: MA布標 | BN34: 1 | BP34: 1
A35: 43369 | C35: 4500013085 | D35: 抽版 | F35: 9201-S001 | G35: 粉紅色獨角獸 | H35: 8 | V35: 8 | Y35: 8 | AD35: MA布標 | BQ35: 8
A36: 43382 | C36: 4500013648 | D36: 簽板 | F36: 9201-S001 | G36: 珠片公仔 | H36: 24 | V36: 24 | Y36: 24 | AD36: MA布標 | BJ36: 2 | BK36: 2 | BL36: 2 | BM36: 2 | BN36: 2 | BO36: 2 | BP36: 2 | BQ36: 2 | BR36: 2 | BS36: 2 | BT36: 2 | BU36: 2
A37: 43384 | C37: 4500013155 | D37: 大貨版 | F37: 9201-S001 | G37: 珠片公仔 | H37: 12 | V37: 12 | Y37: 12 | AD37: MA布標 | BJ37: 1 | BK37: 1 | BL37: 1 | BM37: 1 | BN37: 1 | BO37: 1 | BP37: 1 | BQ37: 1 | BR37: 1 | BS37: 1 | BT37: 1 | BU37: 1
A38: 43392 | C38: 4500013641 | D38: 大貨版 | F38: 9201-S001 | G38: 珠片公仔 | H38: 12 | X38: 12 | AC38: 12 | AD38: GP法國 | BJ38: 1 | BK38: 1 | BL38: 1 | BM38: 1 | BN38: 1 | BO38: 1 | BP38: 1 | BQ38: 1 | BR38: 1 | BS38: 1 | BT38: 1 | BU38: 1
A39: 43392 | C39: ZMPO18123 | D39: 樣品訂單 | F39: 9201-S001 | G39: 珠片公仔 | H39: 204 | V39: 204 | Y39: 204 | AD39: MA布標 | BJ39: 17 | BK39: 17 | BL39: 17 | BM39: 17 | BN39: 17 | BO39: 17 | BP39: 17 | BQ39: 17 | BR39: 17 | BS39: 17 | BT39: 17 | BU39: 17
A40: 43392 | C40: ZMPO18131 | D40: 樣品訂單 | F40: 9201-S001 | G40: 珠片公仔 | H40: 480 | V40: 480 | Y40: 480 | AD40: MA布標 | BJ40: 40 | BK40: 40 | BL40: 40 | BM40: 40 | BN40: 40 | BO40: 40 | BP40: 40 | BQ40: 40 | BR40: 40 | BS40: 40 | BT40: 40 | BU40: 40
...

Sheet 9561
A2: =#REF! -> #REF! | H2: （黃色表示更改或增加） | K2: （蓝色表示已完货） | O2: （綠色表示調整貨期） | AF2: 收缩膜 | AR2: 展示架
A3: 接单日期 | B3: 第三方客户名称 | C3: 国家 | D3: PO号 | E3: 客户PO号 | F3: SKU | G3: ITEM# | H3: 中文名 | I3: PO数量 (pcs) | J3: 内箱装箱数量(pcs) | K3: 外箱装箱数量(pcs) | L3: 总箱数 | M3: 客PO期 | N3: 验货期 | O3: 第三方验货期 | P3: 驗貨結果 | Q3: 船期SO | R3: 箱唛资料 | S3: 外箱贴纸 | T3: 客贴纸资料 | U3: 布料 | V3: 说明书（书纸） | W3: 客供物料 | X3: 日期码 | Y3: 备注 | Z3: ZURU 跟单 | AA3: 单价USD | AB3: 金额USD | AC3: 发票号 | AD3: 系统货号 | AE3: 是否入系统 | AF3: MA 1L收缩膜 | AG3: MA 5L收缩膜 | AH3: 客版收縮膜 | AI3: MA 1L收缩膜B版 | AJ3: MA 5L收缩膜 | AK3: MA 5L收缩膜B版 | AL3: MA 6L说明书 | AM3: MA6L说明书B版 | AN3: 客版说明书 | AO3: 客版收藏指南 | AP3: 纸卡A版 | AQ3: 纸卡B版 | AR3: EC展示架1L | AS3: EC展示架3L | AT3: 布標 | AU3: 合计数量 | AV3: 累计数量
A4: 45649 | D4: ZPO2411015 | G4: 9561-S001 | H4: 魔法小鸟 | I4: 650 | M4: 45673 | N4: 45670 | AA4: 5.4 | AB4: =AA4*I4 -> 3510 | AD4: # | AE4: # | AF4: =I4 -> 650 | AL4: =I4 -> 650 | AP4: =I4 -> 650 | AU4: 650 | AV4: =AU4 -> 650
A5: 45649 | D5: ZPO2411015 | G5: 9561EC-S001 | H5: 魔法小鸟 | M5: 45673 | N5: 45670 | AD5: # | AE5: # | AP5: =I5 -> 0 | AU5: =I5 -> 0 | AV5: =AV4+AU5 -> 650
A6: 45683 | B6: THE WAREHOUSE LIMITED | C6: 新西兰 | D6: 4500156569 | F6: 4500156569-20 | G6: 9561-S001 | H6: 魔法小鸟 | I6: 48 | J6: 0 | K6: 4 | L6: =I6/K6 -> 12 | M6: 45716 | N6: 45712 | P6: 走PP | X6: 日期码格式：ZURU INC(BVI) 标准格式 日期：按实际生产日期 | Y6: 日期码格式：ZURU INC(BVI) 标准格式 日期：按实际生产日期 Packaging Info: MA UPC 英语包装（优先1L英语版本，或者3L/5L含英语都可） 此客人不接受易掉落或者剥落或者可直接触碰的闪粉，可降解也不行，但可以接受符合欧洲微塑料标准的珠光粉或者闪片。 9561: 包装正面和说明书都需要加电池警告语贴纸（法规要求） 9561：外箱四个面要加一张大黄贴："ZURU Product for NZ test " Remark: 9561: 3PCS LR41 BATTERIES(INCLUDED) | Z6: Abby Liang | AA6: 5.4 | AB6: 259.2 | AC6: 94694-4.3 | AD6: 9561-S001 | AE6: 已入 | AF6: =I6 -> 48 | AL6: =I6 -> 48 | AP6: =I6 -> 48 | AU6: =I6 -> 48 | AV6: =AV5+AU6 -> 698
A7: 45666 | B7: PT.MAP Aktif Adiperkasa, Tbk | C7: 印度尼西亚 | D7: 4500155574 | E7: 241227-2MAAJKTQ225-ZURU | F7: 4500155574-40 | G7: 9561-S001 | H7: 魔法小鸟 | I7: 252 | J7: 0 | K7: 4 | L7: =I7/K7 -> 63 | M7: 45733 | N7: 45729 | P7: PASS | R7: 45667 | S7: 无 | T7: 2/6进口商贴纸 | U7: MA | X7: 日期码格式：ZURU INC(BVI) 标准格式 日期：按实际生产日期 | Y7: 日期码格式：ZURU INC(BVI) 标准格式 日期：按实际生产日期 Packaging Info: MA UPC包装（优先1L)+1张进口商贴纸, 所有item使用含电池信息的进口商贴纸，贴纸待提供 1.可能会被抽大货样做测试，请多备料，CRD前半个月会通知是否有抽到该订单中的item。 2.此订单送普通仓，送仓后会有第三方验货，所以需要按CRD准时完货。 Remark: 9561-3pcs LR41 Batteries（included） | Z7: Emma Wu | AA7: 5.4 | AB7: =I7*AA7 -> 1360.8 | AC7: 94672-3.29 | AD7: 9561-S001 | AE7: 已入 | AF7: =I7 -> 252 | AL7: =I7 -> 252 | AP7: =I7 -> 252 | AU7: =I7 -> 252 | AV7: =AV6+AU7 -> 950
A8: 45681 | B8: ALL BRANDS TOYS PTY LTD | C8: 澳大利亚 | D8: 4500156597 | E8: 83575 | F8: 4500156597-20 | G8: 9561-S001 | H8: 魔法小鸟 | I8: 1200 | J8: 0 | K8: 4 | L8: =I8/K8 -> 300 | M8: 45737 | N8: =M8-4 -> 45733 | P8: PASS | R8: 45694 | S8: 无 | T8: 口商贴纸+一张收缩膜纽扣电池警告语进口商贴纸 + 1张说明书纽扣电池+警告语贴纸 | U8: MA | X8: 日期码格式：ZURU INC(BVI) 标准格式 日期：按实际生产日期 | Y8: 日期码格式：ZURU INC(BVI) 标准格式 日期：按实际生产日期 Packaging Info: 9561：MA_UPC版本包装（收缩膜/彩卡和说明书, MA首选1L，如无1L可用多语且含英语的配套多语UPC包装）+ 1张收缩膜纽扣电池警告语进口商贴纸 + 1张说明书纽 扣电池警告语贴纸 Remark: 1.按实际生产日期; 2.出澳大利亚，请按照相应标准生产; | Z8: Lydia Wu | AA8: 5.4 | AB8: =I8*AA8 -> 6480 | AC8: 94724-4.8 | AD8: 9561-S001 | AE8: 已入 | AF8: =I8 -> 1200 | AL8: =I8 -> 1200 | AP8: =I8 -> 1200 | AU8: =I8 -> 1200 | AV8: =AV7+AU8 -> 2150
A9: 45683 | B9: ALL BRANDS TOYS PTY LTD | C9: 澳大利亚 | D9: 4500156675 | E9: 83576 | F9: 4500156675-10 | G9: 9561-S001 | H9: 魔法小鸟 | I9: 240 | J9: 0 | K9: 4 | L9: =I9/K9 -> 60 | M9: 45743 | N9: 45740 | O9: PASS | P9: PASS | R9: 45694 | S9: 无 | T9: 进口商贴纸+一张收缩膜纽扣电池警告语进口商贴纸 + 1张说明书纽 扣电池警告语贴纸 警告语贴纸翻单4500156597 | U9: MA | X9: 日期码格式：ZURU INC(BVI) 标准格式 日期：按实际生产日期 | Y9: 日期码格式：ZURU INC(BVI) 标准格式 日期：按实际生产日期 Packaging Info: 9560：MA_UPC版本包装（收缩膜/彩卡和说明书, MA首选1L，如无1L可用多语且含英语的配套多语UPC包装）+ 1张收缩膜纽扣电池警告语进口商贴纸 + 1张说明书纽 扣电池警告语贴纸 警告语贴纸翻单4500156597 Remark: | Z9: Lydia Wu | AA9: 5.4 | AB9: =I9*AA9 -> 1296 | AC9: 94664-3.28 | AD9: 9561-S001 | AE9: 已入 | AF9: =I9 -> 240 | AL9: =I9 -> 240 | AP9: =I9 -> 240 | AU9: =I9 -> 240 | AV9: =AV8+AU9 -> 2390
A10: 45716 | B10: PRO & PACIFIC CO.,LTD | C10: 台湾 | D10: 4500158781 | E10: ZU25021702 | F10: 4500158781-30 | G10: 9561-S001 | H10: 魔法小鸟 | I10: 600 | J10: 0 | K10: 4 | L10: =I10/K10 -> 150 | M10: 45744 | N10: 45740 | P10: PASS | R10: 45719 | S10: 无 | T10: 3/6进口商贴纸 | U10: MA | X10: 日期码格式：ZURU INC(BVI) 标准格式 日期：按实际生产日期 | Y10: 日期码格式：ZURU INC(BVI) 标准格式 日期：按实际生产日期 Packaging Info: MA 1L UPC包装+1张进口商贴纸,贴纸资料待提供 Remark: | Z10: Emma Wu | AA10: 5.4 | AB10: =I10*AA10 -> 3240 | AC10: 94827-4.22 | AD10: 9561-S001 | AE10: 已入 | AF10: =I10 -> 600 | AL10: =I10 -> 600 | AP10: =I10 -> 600 | AU10: =I10 -> 600 | AV10: =AV9+AU10 -> 2990
A11: 45703 | B11: TARGET AUSTRALIA PTY LTD | C11: 澳大利亚 | D11: 4500157612 | E11: 2447992 | F11: 4500157612-10 | G11: 9561-S001 | H11: 魔法小鸟 | I11: 2000 | J11: 0 | K11: 4 | L11: =I11/K11 -> 500 | M11: 45754 | N11: 45750 | P11: PASS | R11: 45706 | S11: 有 | T11: 3/3SSCC label外箱贴纸+2/24纽扣电池警告语贴纸 | U11: MA | X11: 日期码格式：ZURU INC(BVI) 标准格式 日期：按实际生产日期 | Y11: 日期码格式：ZURU INC(BVI) 标准格式 日期：按实际生产日期 Packaging Info: 9561：英文MA包装(UPC版本，首选1L，无1L可用多L含英语)+箱唛+SSCC label外箱贴纸，另外9561包含纽扣电池，包装跟说明书上需加纽扣电池警告语贴纸。 Remark: 1. 客人要求箱唛不可出现任何手写内容，重量与实际一致且不可手写; 2. 此单去澳大利亚，请按相应澳新标准生产; 3. 使用普通透明封箱胶封箱; 4. 外箱需要贴Target SSCC LABEL,客供PDF文档，工厂自行订购。请贴在正唛右下角（一箱一张，贴1面正唛右下角,封箱胶纸不能挡住贴纸内容。)；外箱贴纸距离 外箱边缘应在2cm以上。如果正唛无位置可以贴在侧唛; 5. 外箱材质为ZURU标准; 6. 产品和包装上要有tracking label信息：格式为Zuru标准格式（可以自行调整具体年月日生产日期,避开节假期日）; 7. SSCC Label 尺寸更新为：4x4 inch; 8. 请务必按时完货，验货PASS后请按时送货入货代指定仓库，如果晚了导致船期Delay将会有罚金产生或者客户要求空运，所产生的罚金和空运费由工厂承担。 | Z11: Christine Liao | AA11: 5.7921 | AB11: =I11*AA11 -> 11584.2 | AC11: 94741-4.10 | AD11: 9561-S001 | AE11: 已入 | AF11: =I11 -> 2000 | AL11: =I11 -> 2000 | AP11: =I11 -> 2000 | AU11: =I11 -> 2000 | AV11: =AV10+AU11 -> 4990
A12: 45707 | B12: KINGSKY CLEAN-TECH CO., LTD. | C12: 香港 | D12: 4500158006 | E12: ZU25020701HK | F12: 4500158006-10 | G12: 9561-S001 | H12: 魔法小鸟 | I12: 500 | J12: 0 | K12: 4 | L12: =I12/K12 -> 125 | M12: 45754 | N12: 45750 | P12: PASS | R12: 45721 | S12: 无 | T12: 3/5进口商贴纸 | U12: MA | X12: 日期码格式：ZURU INC(BVI) 标准格式 日期：按实际生产日期 | Y12: 日期码格式：ZURU INC(BVI) 标准格式 日期：按实际生产日期 Packaging Info: MA UPC包装（优先1L)+1张进口商贴纸 贴纸AW、位置图待提供 此单客人要求4月初出货，所以后面会尽量提前交期，请尽快处理此单 Remark: 3PCS LR44 BATTERIES(INCLUDED) | Z12: Emma Wu | AA12: 5.7921 | AB12: =I12*AA12 -> 2896.05 | AC12: 94742-4.10 | AD12: 9561-S001 | AE12: 已入 | AF12: =I12 -> 500 | AL12: =I12 -> 500 | AP12: =I12 -> 500 | AU12: =I12 -> 500 | AV12: =AV11+AU12 -> 5490
A13: 45657 | B13: DM LLC | C13: 俄罗斯联邦 | D13: 4500155065 | E13: 出Bekasovo 2 | F13: 4500155065-10 | G13: 9561-S001 | H13: 魔法小鸟 | I13: 2092 | J13: 0 | K13: 4 | L13: =I13/K13 -> 523 | M13: 45755 | N13: 45751 | P13: PASS | R13: 45700 | S13: 无 | T13: 2/12进口商贴纸+ EAN条码贴纸 | U13: MA | X13: 外箱不要打ZURU标准日期码!胶件可以打日期码。 | Y13: 日期码格式：外包装/外箱不要打ZURU标准日期码 日期： Packaging Info: 注意:外包装(指:收缩膜/彩卡/铝箔袋/挂卡/PDQ)/外箱不要打ZURU标准日期码!胶件可以打日期码。 1L MA 收缩膜 + 进口商贴纸+ EAN条码贴纸， MA 指南/说明书（如有）； Remark: 标准配比 请按期完货， 会有罚金。 出港口Bekasovo 2和 | Z13: Ann Zhang | AA13: 5.4 | AB13: =I13*AA13 -> 11296.8 | AC13: 94818-4.23 | AD13: 9561-S001 | AE13: 已入 | AF13: =I13 -> 2092 | AL13: =I13 -> 2092 | AP13: =I13 -> 2092 | AU13: =I13 -> 2092 | AV13: =AV12+AU13 -> 7582
A14: 45657 | B14: DM LLC | C14: 俄罗斯联邦 | D14: 4500155065 | E14: 出Ural | F14: 4500155065-20 | G14: 9561-S001 | H14: 魔法小鸟 | I14: 476 | J14: 0 | K14: 4 | L14: =I14/K14 -> 119 | M14: 45755 | N14: 45751 | P14: PASS | R14: 45700 | S14: 无 | T14: 2/12进口商贴纸+ EAN条码贴纸 | U14: MA | X14: 外箱不要打ZURU标准日期码!胶件可以打日期码。 | Y14: 日期码格式：外包装/外箱不要打ZURU标准日期码 日期： Packaging Info: 注意:外包装(指:收缩膜/彩卡/铝箔袋/挂卡/PDQ)/外箱不要打ZURU标准日期码!胶件可以打日期码。 1L MA 收缩膜 + 进口商贴纸+ EAN条码贴纸， MA 指南/说明书（如有）； Remark: 标准配比 请按期完货， 会有罚金。 出港口Bekasovo 2和 | Z14: Ann Zhang | AA14: 5.4 | AB14: =I14*AA14 -> 2570.4 | AC14: 94818-4.23 | AD14: 9561-S001 | AE14: 已入 | AF14: =I14 -> 476 | AL14: =I14 -> 476 | AP14: =I14 -> 476 | AU14: =I14 -> 476 | AV14: =AV13+AU14 -> 8058
A15: 45716 | B15: TARGET US | C15: 美国 | D15: 4500158830 | E15: 10001240713-3890 | F15: 4500158830-20 | G15: 9561-S001 | H15: 魔法小鸟 | I15: 12000 | J15: 0 | K15: 4 | L15: =I15/K15 -> 3000 | M15: 45761 | N15: 45757 | P15: PASS | Q15: 暂停出货 | R15: 45728 | S15: 有 | T15: 外箱正唛左上角位置粘贴条码箱贴纸，来料贴纸上显示的客户DPCI#086-08-0267, UPC显示10193052078909+Event label内容显示Toys Set Date：7/20/2025 | U15: MA | X15: 日期码格式：ZURU INC(BVI) 标准格式 日期：按实际生产日期 | Y15: 日期码格式：ZURU INC(BVI) 标准格式 日期：按实际生产日期 Packaging Info: 9561：产品包装MA 收缩膜(UPC版) Remark: 9561: 1.9561-S001-PETS ALIVE-MAGIC BIRD-SERIES 1-MAGIC BIRD SURPRISE PLAYSET-SHRINK WRAP-4PCS/CTN 2. 产品包装MA 收缩膜(UPC版)，收缩膜上的UPC显示193052078902； 3. 外箱正唛左上角位置粘贴条码箱贴纸，每箱只贴一张，由ZURU订购。来料贴纸上显示的客户DPCI#086-08-0267, UPC显示10193052078909; 此订单所有item： 1. 外箱正唛箱唛内容右侧需贴一张Event label，内容显示Toys Set Date：7/20/2025，工厂自行订购； 2. 产品和包装上印刷 tracking code信息，格式为ZURU常规格式; 3. 出货方式：货代自提 | Z15: Holly Zheng | AA15: 5.4 | AB15: =I15*AA15 -> 64800 | AC15: ZB00336-5.27 ZB00390-6.2 | AD15: 9561-S001 | AE15: 已入 | AF15: =I15 -> 12000 | AL15: =I15 -> 12000 | AP15: =I15 -> 12000 | AU15: =I15 -> 12000 | AV15: =AV14+AU15 -> 20058
A16: 45721 | B16: KMART AUSTRALIA LTD(NEW ZEALAND) | C16: 新西兰 | D16: 4500159288 | E16: 20676972 | F16: 4500159288-10 | G16: 9561-S001 | H16: 魔法小鸟 | I16: 180 | J16: 0 | K16: 4 | L16: =I16/K16 -> 45 | M16: 45761 | N16: 45757 | P16: PASS | R16: 45733 | S16: 有 | T16: 1张包装纽扣电池警告语贴纸 + 1张说明书纽扣电池警告语 贴纸 （贴纸及位置图翻单: PO#4500157612）+ 1张防盗贴纸 (贴纸以及位置图翻单PO#4500159287） | U16: MA | X16: 日期码格式：ZURU INC(BVI) 标准格式 日期：按实际生产日期 | Y16: 日期码格式：ZURU INC(BVI) 标准格式 日期：按实际生产日期 Packaging Info: 9561: MA英语UPC版本包装（收缩膜和说明书, MA首选1L，如无1L可用多语且含英语的配套多语包装) + 1张包装纽扣电池警告语贴纸 + 1张说明书纽扣电池警告语 贴纸 （贴纸及位置图翻单: PO#4500157612）+ 1张防盗贴纸 (贴纸以及位置图翻单PO#4500159287）+ 箱唛 + 外箱SSCC Label 配比信息：3pcs mini turtles: 4pcs mini tutles: 5pcs mini turtles= 87:10:3 Remark: 1.请务必按时完货，验货。并且按期送货入货代指定仓库，如果晚了导致船期Delay将会有罚金产生或者客户要求空运，所产生的罚金和空运费由工厂承担。 2.SSCC 外箱贴纸请同纸箱瓦楞纸方向（竖纹向）垂直，即外箱贴纸横着贴(注意条码不要被胶带粘住），贴1pc，贴1面正唛，封箱胶纸不能挡住贴纸内容。外箱贴纸 离外箱边距离不少于2cm。 3.外箱材质为ZURU标准； 4.此单需使用KMART封箱胶上下工字型封箱;从2019年6月开始，要用KMART 新版封箱胶带，此单要用"ANKO"封箱胶带 5.此单出口新西兰，请按相应的澳新标准生产； 6.产品和包装上生产批号的显示格式ZURU标准日期码格式 7.外箱信息不可手写，重量和体积需要与实际的一致(不可手写） 8. 每款item装箱后的G.W.超过10KG或者CBM超过0.13,(9.5KG或者以上，四舍五入后也属于10KG) 需在外箱上加印超 重或者Bulky LOGO，若发现我们资料没有，请 帮忙提醒 1)重量超过10kg但不超过16kg且CBM不超过0.13,10-16kg 超重logo 2）CBM超过0.13且重量少于17kg，bulky logo 3）不属于以上两种情况，需要使用相应重量范围内的超重logo 4）超重logo需要在外箱四面都印刷(箱唛右上角，两面侧唛超重logo需要尽量靠近毛重)，尺寸为:110mm height* 95mm width 9. 实际外箱重量跟印在箱唛上的数据差异不能超3%，尺寸按实际数据印刷 | Z16: Lydia Wu | AA16: 5.7921 | AB16: =I16*AA16 -> 1042.578 | AC16: 94784-4.17 | AD16: 9561-S001 | AE16: 已入 | AF16: =I16 -> 180 | AL16: =I16 -> 180 | AP16: =I16 -> 180 | AU16: =I16 -> 180 | AV16: =AV15+AU16 -> 20238
A17: 45721 | B17: KMART AUSTRALIA LTD | C17: 澳大利亚 | D17: 4500159287 | E17: 20676967 | F17: 4500159287-10 | G17: 9561-S001 | H17: 魔法小鸟 | I17: 1620 | J17: 0 | K17: 4 | L17: =I17/K17 -> 405 | M17: 45761 | N17: 45757 | P17: PASS | R17: 45733 | S17: 有 | T17: 1张包装纽扣电池警告语贴纸 + 1张说明书纽扣电池警告语 贴纸 （贴纸及位置图翻单: PO#4500157612）+ 1张防盗贴纸+ 箱唛 + 外箱SSCC Label | U17: MA | X17: 日期码格式：ZURU INC(BVI) 标准格式 日期：按实际生产日期 | Y17: 日期码格式：ZURU INC(BVI) 标准格式 日期：按实际生产日期 Packaging Info: 9561: MA英语UPC版本包装（收缩膜和说明书, MA首选1L，如无1L可用多语且含英语的配套多语包装) + 1张包装纽扣电池警告语贴纸 + 1张说明书纽扣电池警告语 贴纸 （贴纸及位置图翻单: PO#4500157612）+ 1张防盗贴纸+ 箱唛 + 外箱SSCC Label 配比信息：3pcs mini turtles: 4pcs mini tutles: 5pcs mini turtles= 87:10:3 Remark: 1.请务必按时完货，验货。并且按期送货入货代指定仓库，如果晚了导致船期Delay将会有罚金产生或者客户要求空运，所产生的罚金和空运费由工厂承担。 2.SSCC 外箱贴纸请同纸箱瓦楞纸方向（竖纹向）垂直，即外箱贴纸横着贴(注意条码不要被胶带粘住），贴1pc，贴1面正唛，封箱胶纸不能挡住贴纸内容。外箱贴纸 离外箱边距离不少于2cm。 3.外箱材质为ZURU标准； 4.此单需使用KMART封箱胶上下工字型封箱;从2019年6月开始，要用KMART 新版封箱胶带，此单要用"ANKO"封箱胶带 5.此单出口澳大利亚，请按相应的澳新标准生产； 6.产品和包装上生产批号的显示格式ZURU标准日期码格式 7.外箱信息不可手写，重量和体积需要与实际的一致(不可手写） 8. 每款item装箱后的G.W.超过10KG或者CBM超过0.13,(9.5KG或者以上，四舍五入后也属于10KG) 需在外箱上加印超 重或者Bulky LOGO，若发现我们资料没有，请 帮忙提醒 1)重量超过10kg但不超过16kg且CBM不超过0.13,10-16kg 超重logo 2）CBM超过0.13且重量少于17kg，bulky logo 3）不属于以上两种情况，需要使用相应重量范围内的超重logo 4）超重logo需要在外箱四面都印刷(箱唛右上角，两面侧唛超重logo需要尽量靠近毛重)，尺寸为:110mm height* 95mm width 9. 实际外箱重量跟印在箱唛上的数据差异不能超3%，尺寸按实际数据印刷 | Z17: Lydia Wu | AA17: 5.7921 | AB17: =I17*AA17 -> 9383.202 | AC17: 94783-4.17 | AD17: 9561-S001 | AE17: 已入 | AF17: =I17 -> 1620 | AL17: =I17 -> 1620 | AP17: =I17 -> 1620 | AU17: =I17 -> 1620 | AV17: =AV16+AU17 -> 21858
A18: 45726 | B18: PPTOYS PTE LTD (SG) | C18: 新加坡 | D18: 4500159608 | E18: ZU25022002SG | F18: 4500159608-20 | G18: 9561-S001 | H18: 魔法小鸟 | I18: 600 | J18: 0 | K18: 4 | L18: =I18/K18 -> 150 | M18: 45761 | N18: 45757 | P18: PASS | R18: 45726 | S18: 无 | T18: 3/14进口商贴纸 | U18: MA | X18: 日期码格式：ZURU INC(BVI) 标准格式 日期：按实际生产日期 | Y18: 日期码格式：ZURU INC(BVI) 标准格式 日期：按实际生产日期 Packaging Info: MA UPC包装（优先1L)+1张进口商贴纸 其他item贴纸AW、位置图待提供 此客人用的贴纸内容都是一样的，个别item可能存在尺寸差别，如果发现贴纸尺寸没差别，就请都统一订购节省成本 Remark: 9561-3PCS LR44 BATTERIES(INCLUDED) | Z18: Emma Wu | AA18: 5.3566 | AB18: =I18*AA18 -> 3213.96 | AC18: 94794-4.18 | AD18: 9561-S001 | AE18: 已入 | AF18: =I18 -> 600 | AL18: =I18 -> 600 | AP18: =I18 -> 600 | AU18: =I18 -> 600 | AV18: =AV17+AU18 -> 22458
A19: 45723 | B19: ZURU LLC | C19: 美国 | D19: 4500159483 | E19: 5200006344 | F19: 4500159483-10 | G19: 9561-S003-MB-MTS | H19: 魔法小鸟 （邮包盒装） | I19: 756 | J19: 0 | K19: 2 | L19: =I19/K19 -> 378 | M19: 45765 | N19: 45761 | P19: PASS | R19: 45726 | S19: 无 | T19: 无 | U19: MA | W19: 邮包盒图稿翻EU单4500159392. | X19: 日期码格式：ZURU INC(BVI) 标准格式 日期：按实际生产日期 | Y19: 日期码格式：ZURU INC(BVI) 标准格式 日期：按实际生产日期 Packaging Info: 9561 MA UPC版 包装入邮包盒，邮包盒图稿翻EU单4500159392. Remark: 1.Amazon domestic 订单。出口美国。外箱最长边不能超过25" （超过了，case pack只能为1），不符合要求的大货，一律不接受。 2.无第三方验货/测试要求。 3.日期码使用ZURU标准版本。 | Z19: Kelly Shen/Mia Pan/P | AA19: 6.2626 | AB19: =I19*AA19 -> 4734.5256 | AC19: ZB00163-4.23 | AD19: 9561-S003-MB-MTS | AE19: 已入 | AF19: =I19 -> 756 | AL19: =I19 -> 756 | AP19: =I19 -> 756 | AU19: =I19 -> 756 | AV19: =AV18+AU19 -> 23214
A20: 45721 | B20: THE FARMERS' TRADING COMPANY LIMITE | C20: 新西兰 | D20: 4500159217 | E20: SSF793 | F20: 4500159217-10 | G20: 9561-S001 | H20: 魔法小鸟 | I20: 720 | J20: 0 | K20: 4 | L20: =I20/K20 -> 180 | M20: 45766 | N20: 45762 | P20: PASS | R20: 45734 | S20: 无 | T20: 4/1包装正面和说明书都需要加电池警告语贴纸（法规要求）+可移动材质的价格贴纸（价格贴纸要切虚线） | U20: MA | X20: 日期码格式：ZURU INC(BVI) 标准格式 日期：按实际生产日期 | Y20: 日期码格式：ZURU INC(BVI) 标准格式 日期：按实际生产日期 Packaging Info: #9561:3PCS LR44 BATTERIES(INCLUDED);包装正面和说明书都需要加电池警告语贴纸（法规要求） Remark: MA UPC英语包装（优先1L英语版本,或者3L/L含英语即可); 可移动材质的价格贴纸（价格贴纸要切虚线） | Z20: Abby Liang | AA20: 5.4 | AB20: =I20*AA20 -> 3888 | AC20: 94884-4.30 | AD20: 9561-S001 | AE20: 已入 | AF20: =I20 -> 720 | AL20: =I20 -> 720 | AP20: =I20 -> 720 | AU20: =I20 -> 720 | AV20: =AV19+AU20 -> 23934
A21: 45707 | B21: ZURU Germany GMBH | C21: 德国 | D21: 4500157858 | E21: 5200006149 | F21: 4500157858-70 | G21: 9561-S001-MTS | H21: 魔法小鸟 | I21: 4000 | J21: 0 | K21: 4 | L21: =I21/K21 -> 1000 | M21: 45768 | N21: 45764 | P21: PASS | R21: 45707 | S21: 无 | T21: 3/7EAN条码贴纸+FR/DE/IT/ES警语贴纸+FR/DE/IT/ES说明书黑白书纸+WEEE通用黑白书纸（8L) | U21: MA | X21: 日期码格式：ZURU INC(BVI) 标准格式 日期：按实际生产日期 | Y21: 日期码格式：ZURU INC(BVI) 标准格式 日期：按实际生产日期 Packaging Info: 9561：MA最新版5L EAN收缩膜+多语折叠语警告贴纸+MA最新版5L收藏指南+MA最新版6L说明书+WEEE通用黑白书纸（8L) Remark: "1.德国内销单，需要通过ZURU 验货结果后才能出货 (工厂需要主动提前同ZURU QC预约验货避免延期出货造成不必要麻烦)； 2. 若有特定款有特殊外箱条码要求时,需要明确列出产品款对应的具体外箱条码号码/条码类型 (若无,可以忽略此需求) 3.所有出口欧洲的产品, 法规规定禁止在包装和共公众用的印刷品中使用矿物油中含有的物质, 包装印刷油墨中含有的MOAH/MOSH的质量浓度不能超过1%, 否则出货 到法国被抽检出现问题, 供应商需要对此负责; 4. date code: 外箱日期码要晚于或等于产品日期码，不能早于产品的日期码 5. 所有电子产品身上需要加字唛，为ZURU FRANCE 地址 (如无电子产品，或者产品布标有此地址，可忽略此信息) ZURU France 1/3, Rue d'Argenteuil 95210 SAINT-GRATIEN, FRANCE 6. 装柜时需要按照款式号码从小到大一款款依次装,避免终端仓库卸货混乱.若一个柜子涉及到几个不同国家内销单,装柜时需要一个国家装完后再装另一个国家的 产品,依次装柜,避免终端仓库因不同国家不同库位位置卸货混乱. (此点需要同工厂装柜人员强调)" | Z21: SD82 | AA21: 5.4 | AB21: =I21*AA21 -> 21600 | AC21: 94852-4.28 | AD21: 9561-S001-5L | AE21: 已入 | AJ21: =I21 -> 4000 | AL21: =I21 -> 4000 | AP21: =I21 -> 4000 | AU21: =I21 -> 4000 | AV21: =AV20+AU21 -> 27934
A22: 45729 | B22: Babyhouse | C22: 乌兹别克斯坦 | D22: 4500159866 | F22: 4500159866-30 | G22: 9561-S001 | H22: 魔法小鸟 | I22: 180 | J22: 0 | K22: 4 | L22: =I22/K22 -> 45 | M22: 45769 | N22: 45765 | P22: PASS | R22: 45729 | S22: 无 | T22: 3/14进口商贴纸 | U22: MA | X22: 日期码格式：ZURU INC(BVI) 标准格式 日期：按实际生产日期 | Y22: 日期码格式：ZURU INC(BVI) 标准格式 日期：按实际生产日期 Packaging Info: 9561 : 1L MA 收缩膜 + 进口商贴纸 ; MA 说明书/指南（如有）; Remark: 标准配比 | Z22: Ann Zhang | AA22: 5.4 | AB22: =I22*AA22 -> 972 | AC22: 94879-4.29 | AD22: 9561-S001 | AE22: 已入 | AF22: =I22 -> 180 | AL22: =I22 -> 180 | AP22: =I22 -> 180 | AU22: =I22 -> 180 | AV22: =AV21+AU22 -> 28114
A23: 45728 | B23: Smyths Toys HQ UC IE | C23: 爱尔兰 | D23: 4500159926 | E23: 4400471618 | F23: 4500159926-10 | G23: 9561-S001 | H23: 魔法小鸟 | I23: 1000 | J23: 0 | K23: 4 | L23: =I23/K23 -> 250 | M23: 45771 | N23: 45761 | P23: PASS | R23: 45734 | S23: 无 | T23: 无 | U23: MA | X23: 日期码格式：ZURU INC(BVI) 标准格式 日期：按实际生产日期 | Y23: 日期码格式：ZURU INC(BVI) 标准格式 日期：按实际生产日期 Packaging Info: 9561：MA 5L-6L EAN收缩膜+MA 5L-6L说明书<(>&<)>收藏指南 Remark: 1) 包装日期码按ZURU格式即可，请确保不迟于外箱日期码，可等于或者早于外箱日期码，必须为法定工作日，印刷前请先检查外箱日期码。 2) 订单出英国，请注意检查产品及包装应带UKCA图标（14+产品除外），包装显示ZURU UK LTD/ZURU France地址信息，QC部门请查核，如有问题与跟单确认 3) 需要完全符合欧洲标准(符合微塑料法规)，否则不合法规会有客诉产生 | Z23: May Wu | AA23: 5.4 | AB23: =I23*AA23 -> 5400 | AD23: 9561-S001-5L | AE23: 已入 | AJ23: =I23 -> 1000 | AL23: =I23 -> 1000 | AP23: =I23 -> 1000 | AU23: =I23 -> 1000 | AV23: =AV22+AU23 -> 29114
A24: 45733 | B24: SMYTHS TOYS HQ UC | C24: 法国 | D24: 4500160446 | E24: 4400472143 | F24: 4500160446-10 | G24: 9561-S001 | H24: 魔法小鸟 | I24: 800 | J24: 0 | K24: 4 | L24: =I24/K24 -> 200 | M24: 45771 | N24: 45764 | P24: PASS | R24: 45734 | S24: 无 | T24: 无 | U24: MA | X24: 日期码格式：ZURU INC(BVI) 标准格式 日期：按实际生产日期 | Y24: 日期码格式：ZURU INC(BVI) 标准格式 日期：按实际生产日期 Packaging Info: 1.9561:MA 5L-6L EAN收缩膜+MA 5L-6L说明书<(>&<)>收藏指南 Remark: 1. 此单出法国，所有包装都需要含有法语，需要满足Zuru Standard欧洲标准测试要求； 2. 请准时出货，推期会有罚款； 3. 所有出口法国的产品, 法规规定禁止在包装和共公众用的印刷品中使用矿物油中含有的物质, 包装印刷油墨中含有的MOAH/MOSH的质量浓度不能超过1%, 否则出 货到法国被抽检出现问题, 供应商需要对此负责; | Z24: Ula Zhao | AA24: 5.4 | AB24: =I24*AA24 -> 4320 | AC24: 94812-4.22 | AD24: 9561-S001-5L | AE24: 已入 | AJ24: =I24 -> 800 | AL24: =I24 -> 800 | AP24: =I24 -> 800 | AU24: =I24 -> 800 | AV24: =AV23+AU24 -> 29914
A25: 45728 | B25: Smyths Toys HQ UC IE | C25: 英国 | D25: 4500159895 | E25: 客户PO4400471 627 | F25: 4500159895-10 | G25: 9561-S001 | H25: 魔法小鸟 | I25: 2000 | J25: 0 | K25: 4 | L25: =I25/K25 -> 500 | M25: 45771 | N25: 45764 | P25: PASS | R25: 45734 | S25: 无 | T25: 无 | U25: MA | X25: 日期码格式：ZURU INC(BVI) 标准格式 日期：按实际生产日期 | Y25: 日期码格式：ZURU INC(BVI) 标准格式 日期：按实际生产日期 Packaging Info: 9561：MA 5L-6L EAN收缩膜+MA 5L-6L说明书<(>&<)>收藏指南 Remark: 1) 包装日期码按ZURU格式即可，请确保不迟于外箱日期码，可等于或者早于外箱日期码，必须为法定工作日，印刷前请先检查外箱日期码。 2) 订单出英国，请注意检查产品及包装应带UKCA图标（14+产品除外），包装显示ZURU UK LTD/ZURU France地址信息，QC部门请查核，如有问题与跟单确认 3) 需要完全符合欧洲标准(符合微塑料法规)，否则不合法规会有客诉产生 | Z25: May Wu | AA25: 5.4 | AB25: =I25*AA25 -> 10800 | AC25: 94853-4.28 | AD25: 9561-S001-5L | AE25: 已入 | AJ25: =I25 -> 2000 | AL25: =I25 -> 2000 | AP25: =I25 -> 2000 | AU25: =I25 -> 2000 | AV25: =AV24+AU25 -> 31914
A26: 45732 | B26: Smyths Toys HQ UC IE | C26: 英国 | D26: 4500159895 | E26: 客户PO4400471 628 | F26: 4500159895-20 | G26: 9561-S001 | H26: 魔法小鸟 | I26: 2000 | J26: 0 | K26: 4 | L26: =I26/K26 -> 500 | M26: 45771 | N26: 45764 | P26: PASS | R26: 45734 | S26: 无 | T26: 无 | U26: MA | X26: 日期码格式：ZURU INC(BVI) 标准格式 日期：按实际生产日期 | Y26: 日期码格式：ZURU INC(BVI) 标准格式 日期：按实际生产日期 Packaging Info: 9561：MA 5L-6L EAN收缩膜+MA 5L-6L说明书<(>&<)>收藏指南 Remark: 1) 包装日期码按ZURU格式即可，请确保不迟于外箱日期码，可等于或者早于外箱日期码，必须为法定工作日，印刷前请先检查外箱日期码。 2) 订单出英国，请注意检查产品及包装应带UKCA图标（14+产品除外），包装显示ZURU UK LTD/ZURU France地址信息，QC部门请查核，如有问题与跟单确认 3) 需要完全符合欧洲标准(符合微塑料法规)，否则不合法规会有客诉产生 | Z26: May Wu | AA26: 5.4 | AB26: =I26*AA26 -> 10800 | AC26: 94853-4.28 | AD26: 9561-S001-5L | AE26: 已入 | AJ26: =I26 -> 2000 | AL26: =I26 -> 2000 | AP26: =I26 -> 2000 | AU26: =I26 -> 2000 | AV26: =AV25+AU26 -> 33914
A27: 45719 | B27: PERTINI TOYS doo | C27: 塞尔维亚/蒙特内 | D27: 4500158989 | F27: 4500158989-10 | G27: 9561-S001 | H27: 魔法小鸟 | I27: 1400 | J27: 0 | K27: 4 | L27: =I27/K27 -> 350 | M27: 45772 | N27: 45768 | P27: PASS | R27: 45719 | S27: 无 | T27: 3/20EAN条码贴纸+进口商贴纸 | U27: MA | X27: 日期码格式：ZURU INC(BVI) 标准格式 日期：按实际生产日期 | Y27: 日期码格式：ZURU INC(BVI) 标准格式 日期：按实际生产日期 Packaging Info: 9561: MA 1L UPC 收缩膜+EAN条码贴纸+进口商贴纸;MA A版指南书，MA 5L+6L警告语/收藏指南 Remark: 此单出EU，需满足EU测试标准要求，不能含微塑料。 1. 9561-S001: 3PCS LR44 BATTERIES(INCLUDED) 2. 9543GQ1-S001: Ratio:bule/purple/pink/orange =5:6:6:5; 2PCS AAA BATTERIES(NOT INCLUDED) | Z27: Sharon Zhao | AA27: 5.4 | AB27: =I27*AA27 -> 7560 | AC27: 94930-5.6 | AD27: 9561-S001 | AE27: 已入 | AF27: =I27 -> 1400 | AL27: =I27 -> 1400 | AP27: =I27 -> 1400 | AU27: =I27 -> 1400 | AV27: =AV26+AU27 -> 35314
A28: 45736 | B28: THE ENTERTAINER | C28: 英国 | D28: 4500160901 | E28: 4500160901-1: FB12977 | F28: 4500160901-20 | G28: 9561-S001 | H28: 魔法小鸟 | I28: 368 | J28: 0 | K28: 4 | L28: =I28/K28 -> 92 | M28: 45772 | N28: 45768 | P28: PASS | R28: 45740 | S28: 无 | T28: 3/24一张2国语言电池说明书(英语+阿拉伯语) | U28: MA | X28: 日期码格式：ZURU INC(BVI) 标准格式 日期：按实际生产日期 | Y28: 日期码格式：ZURU INC(BVI) 标准格式 日期：按实际生产日期 Packaging Info: 9561-S001: MA 最新1L UPC包装+一张2国语言电池说明书(英语+阿拉伯语); BARCODE: 193052078902 Remark: *MA版本按工厂现有最新库存即可，订单出英国，请注意检查产品及包装应带UKCA图标，包装显示ZURU UK LTD信息，QC同事请查核，如有问题与跟单确认 *生产日期按实际（法定工作日），按ZURU标准格式即可 ，但是请知悉包装日期码需要早于或者等于外箱日期码 ，不能晚于外箱日期码 *请注意所有订单都需要经过ZURU QC验货并且通过后方可出货 *所有产品按符合欧洲标准走货，需要是不含微塑料版本 。 *涉及到硼的，如可选择情况下应使用低硼版本 （slime 类别低硼一般低于300ppm)，无选择的应与跟单复核再安排 。 *条码以订单显示为准 ，请安排生产前先核对 ，有问题请提出。 *订单对应客户3个PO号 ，备注有显示 ，注意分开做货/验货/装柜 ，混装有罚款。 * 大货样： 请在4/10 前寄出每款1整套大货样到罗湖办公室7B Sandy Shao 收。 | Z28: Sandy Shao | AA28: 5.3727 | AB28: =I28*AA28 -> 1977.1536 | AC28: 94866-4.29 | AD28: 9561-S001 | AE28: 已入 | AF28: =I28 -> 368 | AL28: =I28 -> 368 | AP28: =I28 -> 368 | AU28: =I28 -> 368 | AV28: =AV27+AU28 -> 35682
A29: 45736 | B29: THE ENTERTAINER | C29: 英国 | D29: 4500160901 | E29: 4500160901-2: FB12978 | F29: 4500160901-110 | G29: 9561-S001 | H29: 魔法小鸟 | I29: 368 | J29: 0 | K29: 4 | L29: =I29/K29 -> 92 | M29: 45772 | N29: 45768 | P29: PASS | R29: 45740 | S29: 无 | T29: 3/24一张2国语言电池说明书(英语+阿拉伯语) | U29: MA | X29: 日期码格式：ZURU INC(BVI) 标准格式 日期：按实际生产日期 | Y29: 日期码格式：ZURU INC(BVI) 标准格式 日期：按实际生产日期 Packaging Info: 9561-S001: MA 最新1L UPC包装+一张2国语言电池说明书(英语+阿拉伯语); BARCODE: 193052078902 Remark: *MA版本按工厂现有最新库存即可，订单出英国，请注意检查产品及包装应带UKCA图标，包装显示ZURU UK LTD信息，QC同事请查核，如有问题与跟单确认 *生产日期按实际（法定工作日），按ZURU标准格式即可 ，但是请知悉包装日期码需要早于或者等于外箱日期码 ，不能晚于外箱日期码 *请注意所有订单都需要经过ZURU QC验货并且通过后方可出货 *所有产品按符合欧洲标准走货，需要是不含微塑料版本 。 *涉及到硼的，如可选择情况下应使用低硼版本 （slime 类别低硼一般低于300ppm)，无选择的应与跟单复核再安排 。 *条码以订单显示为准 ，请安排生产前先核对 ，有问题请提出。 *订单对应客户3个PO号 ，备注有显示 ，注意分开做货/验货/装柜 ，混装有罚款。 * 大货样： 请在4/10 前寄出每款1整套大货样到罗湖办公室7B Sandy Shao 收。 | Z29: Sandy Shao | AA29: 5.3727 | AB29: =I29*AA29 -> 1977.1536 | AC29: 94866-4.29 | AD29: 9561-S001 | AE29: 已入 | AF29: =I29 -> 368 | AL29: =I29 -> 368 | AP29: =I29 -> 368 | AU29: =I29 -> 368 | AV29: =AV28+AU29 -> 36050
A30: 45736 | B30: THE ENTERTAINER | C30: 英国 | D30: 4500160901 | E30: 4500160901-3: FB12979 | F30: 4500160901-200 | G30: 9561-S001 | H30: 魔法小鸟 | I30: 368 | J30: 0 | K30: 4 | L30: =I30/K30 -> 92 | M30: 45772 | N30: 45768 | P30: PASS | R30: 45740 | S30: 无 | T30: 3/24一张2国语言电池说明书(英语+阿拉伯语) | U30: MA | X30: 日期码格式：ZURU INC(BVI) 标准格式 日期：按实际生产日期 | Y30: 日期码格式：ZURU INC(BVI) 标准格式 日期：按实际生产日期 Packaging Info: 9561-S001: MA 最新1L UPC包装+一张2国语言电池说明书(英语+阿拉伯语); BARCODE: 193052078902 Remark: *MA版本按工厂现有最新库存即可，订单出英国，请注意检查产品及包装应带UKCA图标，包装显示ZURU UK LTD信息，QC同事请查核，如有问题与跟单确认 *生产日期按实际（法定工作日），按ZURU标准格式即可 ，但是请知悉包装日期码需要早于或者等于外箱日期码 ，不能晚于外箱日期码 *请注意所有订单都需要经过ZURU QC验货并且通过后方可出货 *所有产品按符合欧洲标准走货，需要是不含微塑料版本 。 *涉及到硼的，如可选择情况下应使用低硼版本 （slime 类别低硼一般低于300ppm)，无选择的应与跟单复核再安排 。 *条码以订单显示为准 ，请安排生产前先核对 ，有问题请提出。 *订单对应客户3个PO号 ，备注有显示 ，注意分开做货/验货/装柜 ，混装有罚款。 * 大货样： 请在4/10 前寄出每款1整套大货样到罗湖办公室7B Sandy Shao 收。 | Z30: Sandy Shao | AA30: 5.3727 | AB30: =I30*AA30 -> 1977.1536 | AC30: 94866-4.29 | AD30: 9561-S001 | AE30: 已入 | AF30: =I30 -> 368 | AL30: =I30 -> 368 | AP30: =I30 -> 368 | AU30: =I30 -> 368 | AV30: =AV29+AU30 -> 36418
A31: 45761 | D31: ZMPO250315 | G31: 9561-S001 | H31: 魔法小鸟 | I31: 252 | J31: 0 | K31: 4 | L31: =I31/K31 -> 63 | M31: 45775 | N31: 45768 | P31: PASS | R31: 空白外箱 | S31: 无 | T31: 无 | U31: MA | Y31: Remark:大货最新版本/大货标准箱装箱/箱唛参照邮件附件;备注： 收到样品订单后尽快安排 ，此订单麻烦在外箱上备注是海运订单/注意样板品质质量要求要高于大货品质质量 ，送货时必须要附带送货单(没有送货单和QC检验合格报告的仓库一律拒绝收货)，请知悉，谢谢！ | Z31: Angus | AD31: 9561-S001 | AE31: 已入 | AF31: =I31 -> 252 | AL31: =I31 -> 252 | AP31: =I31 -> 252 | AU31: =I31 -> 252 | AV31: =AV30+AU31 -> 36670
A32: 45705 | B32: DIAMANT TOYS LTD | C32: 以色列 | D32: 4500157252 | E32: 56121 | F32: 4500157252-10 | G32: 9561-S001 | H32: 魔法小鸟 | I32: 1340 | J32: 0 | K32: 4 | L32: =I32/K32 -> 335 | M32: 45777 | N32: 45773 | P32: PASS | R32: 45707 | S32: 无 | T32: 3/10进口商贴纸+2张彩色贴纸 | U32: MA | X32: 日期码格式：ZURU INC(BVI) 标准格式 日期：按实际生产日期 | Y32: 日期码格式：ZURU INC(BVI) 标准格式 日期：按实际生产日期 Tracking Code: Packaging Info: 9561：1L MA包装+进口商贴纸+2张彩色贴纸; MA说明书 Remark: | Z32: Lena Huang | AA32: 5.4 | AB32: =I32*AA32 -> 7236 | AC32: 94885-4.30 | AD32: 9561-S001 | AE32: 已入 | AF32: =I32 -> 1340 | AL32: =I32 -> 1340 | AP32: =I32 -> 1340 | AU32: =I32 -> 1340 | AV32: =AV31+AU32 -> 38010
A33: 45734 | B33: ZURU LLC | C33: 美国 | D33: 4500160498 | E33: B0DR3T17RV | F33: 4500160498-20 | G33: 9561-S003-MB-MTS | H33: 魔法小鸟 （邮包盒装） | I33: 2744 | J33: 0 | K33: 2 | L33: =I33/K33 -> 1372 | M33: 45777 | N33: 45773 | P33: PASS | R33: 45735 | S33: 无 | T33: 邮包盒图稿翻EU单4500159392. | U33: MA | X33: 日期码格式：ZURU INC(BVI) 标准格式 日期：按实际生产日期 | Y33: 日期码格式：ZURU INC(BVI) 标准格式 日期：按实际生产日期 Packaging Info: #9561: MA 1L UPC版包装入邮包盒，邮包盒图稿翻EU单4500159392. Remark: 1.Amazon domestic 订单。出口美国。外箱最长边不能超过25" （超过了，case pack只能为1），不符合要求的大货，一律不接受。 2.无第三方验货/测试要求。 3.日期码使用ZURU标准版本。 4.邮包盒要印刷日期码。 | Z33: Kelly Shen/Mia Pan/P | AA33: 5.9569 | AB33: =I33*AA33 -> 16345.734 | AC33: ZB00241-5.13 | AD33: 9561-S003-MB-MTS | AE33: 已入 | AF33: =I33 -> 2744 | AL33: =I33 -> 2744 | AP33: =I33 -> 2744 | AU33: =I33 -> 2744 | AV33: =AV32+AU33 -> 40754
A34: 45737 | B34: Model & Hobby Toys | C34: 匈牙利 | D34: 4500161125 | F34: 4500161125-10 | G34: 9561-S001 | H34: 魔法小鸟 | I34: 300 | J34: 0 | K34: 4 | L34: =I34/K34 -> 75 | M34: 45782 | N34: 45778 | P34: PASS | R34: 45750 | S34: 无 | T34: 4/3进口商贴纸 | U34: MA | X34: 日期码格式：ZURU INC(BVI) 标准格式 日期：按实际生产日期 | Y34: 日期码格式：ZURU INC(BVI) 标准格式 日期：按实际生产日期 Packaging Info: 9561: A 版5L MA 收缩膜+进口商贴纸; A 版 5L MA guide book Remark: 1、若产品有比例使用ZURU STD 比例 2、所有item 均用MA UPC 条码，若包装不是UPC 条码的请告知 3、此单出欧洲需满足EU测试标准要求 | Z34: Snowy | AA34: 5.3727 | AB34: =I34*AA34 -> 1611.81 | AD34: 9561-S001-5L | AE34: 已入 | AJ34: =I34 -> 300 | AL34: =I34 -> 300 | AP34: =I34 -> 300 | AU34: =I34 -> 300 | AV34: =AV33+AU34 -> 41054
A35: 45737 | B35: FELYX TOYS | C35: 保加利亚 | D35: 4500161118 | F35: 4500161118-10 | G35: 9561-S001 | H35: 魔法小鸟 | I35: 1640 | J35: 0 | K35: 4 | L35: =I35/K35 -> 410 | M35: 45782 | N35: 45778 | P35: PASS | R35: 45741 | S35: 无 | T35: 4/7进口商贴纸 | U35: MA | X35: 日期码格式：ZURU INC(BVI) 标准格式 日期：按实际生产日期 | Y35: 日期码格式：ZURU INC(BVI) 标准格式 日期：按实际生产日期 Packaging Info: 9561:A 版 1L MA 收缩膜+进口商贴纸；客版guide book/客版说明书 Remark: 1、若产品有比例使用ZURU STD 比例 2、所有item 均用MA UPC 条码，若包装不是UPC 条码的请告知 3、此单出欧洲需满足EU测试标准要求 | Z35: Snowy Wu | AA35: 5.1379 | AB35: =I35*AA35 -> 8426.156 | AC35: 94953-5.9 | AD35: 9561-S001-1 | AE35: 已入 | AF35: =I35 -> 1640 | AN35: =I35 -> 1640 | AO35: =I35 -> 1640 | AP35: =I35 -> 1640 | AU35: =I35 -> 1640 | AV35: =AV34+AU35 -> 42694
A36: 45737 | B36: FELYX TOYS | C36: 保加利亚 | D36: 4500161118 | F36: 4500161118-20 | G36: 9561EC-S001 | H36: 魔法小鸟 | I36: 360 | J36: 0 | K36: 18 | L36: =I36/K36 -> 20 | M36: 45782 | N36: 45778 | P36: PASS | R36: 45741 | S36: 无 | T36: 4/7进口商贴纸 | U36: MA | X36: 日期码格式：ZURU INC(BVI) 标准格式 日期：按实际生产日期 | Y36: 日期码格式：ZURU INC(BVI) 标准格式 日期：按实际生产日期 Packaging Info: 9561EC:A 版 1L MA 收缩膜+进口商贴纸；客版guide book/客版说明书/A 版 1L MA 展示架 Remark: 1、若产品有比例使用ZURU STD 比例 2、所有item 均用MA UPC 条码，若包装不是UPC 条码的请告知 3、此单出欧洲需满足EU测试标准要求 | Z36: Snowy Wu | AA36: 118.7504 | AB36: =AA36*L36 -> 2375.008 | AC36: 94953-5.9 | AD36: 9561EC-S001-1 | AE36: 已入 | AF36: =I36 -> 360 | AN36: =I36 -> 360 | AO36: =I36 -> 360 | AP36: =I36 -> 360 | AR36: =L36 -> 20 | AU36: =I36 -> 360 | AV36: =AV35+AU36 -> 43054
A37: 45743 | B37: Smyths Toys EU HQ UC | C37: 德国 | D37: 4500161489 | E37: 4400474092 | F37: 4500161489-10 | G37: 9561-S001 | H37: 魔法小鸟 | I37: 2400 | J37: 0 | K37: 4 | L37: =I37/K37 -> 600 | M37: 45783 | N37: 45779 | P37: PASS | R37: 45744 | S37: 无 | T37: 产品贴纸(ZURU FRANCE 地址)翻单#4500136411+客版WEEE声明通用8L说明书(带电池，翻4500155594), EAN 条码：4894680042520 | U37: MA | X37: 日期码格式：ZURU INC(BVI) 标准格式 日期：按实际生产日期 | Y37: 日期码格式：ZURU INC(BVI) 标准格式 日期：按实际生产日期 Packaging Info: 9561:最新MA 5L(6L warning) EAN 收缩膜+MA 6L Guide book+产品贴纸(ZURU FRANCE 地址)+客版WEEE声明通用8L说明书(带电池，翻4500155594)+说明书法语贴纸 （翻4500160446）,EAN 条码：4894680042520 请核对条码后再做货 Remark: 1. 此单出德国，需要满足Zuru Standard欧洲标准测试要求； 2. 请准时出货，推期会有罚款； 3. 出口欧洲，微塑料需符合法规； 4. 所有电子产品身上需要加字唛，为ZURU FRANCE 地址 (如无电子产品，产品布标有此地址，或产品太小无法增加可忽略此信息) ZURU France 1/3, Rue d'Argenteuil 95210 SAINT-GRATIEN, FRANCE 5. 所有出往德国订单的电子产品需增加一张客版WEEE声明说明书，区分带电池和不带电池版本, 如已做客版说明书可忽略此要求。 6. 所有出往德国订单，化学品需无堋无香版本。 7. 标准配比 | Z37: Shirley Zhou | AA37: 5.1219 | AB37: =I37*AA37 -> 12292.56 | AD37: 9561-S001-5L | AE37: 已入 | AJ37: =I37 -> 2400 | AL37: =I37 -> 2400 | AP37: =I37 -> 2400 | AU37: =I37 -> 2400 | AV37: =AV36+AU37 -> 45454
A38: 45737 | B38: KMART AUSTRALIA LTD(NEW ZEALAND) | C38: 新西兰 | D38: 4500161020 | E38: 20722717 | F38: 4500161020-10 | G38: 9561-S001 | H38: 魔法小鸟 | I38: 48 | J38: 0 | K38: 4 | L38: =I38/K38 -> 12 | M38: 45783 | N38: 45779 | P38: PASS | R38: 45748 | S38: 有 | T38: 1张包装纽扣电池警告语贴纸 + 1张说明书纽扣电池警告语 贴纸 （贴纸及位置图翻单: PO#4500157612）+ 1张防盗贴纸 (贴纸以及位置图翻单PO#4500159287） | U38: MA | X38: 日期码格式：ZURU INC(BVI) 标准格式 日期：按实际生产日期 | Y38: 日期码格式：ZURU INC(BVI) 标准格式 日期：按实际生产日期 Packaging Info: 9561: MA英语UPC版本包装（收缩膜和说明书, MA首选1L，如无1L可用多语且含英语的配套多语包装) + 1张包装纽扣电池警告语贴纸 + 1张说明书纽扣电池警告语 贴纸 （贴纸及位置图翻单: PO#4500157612）+ 1张防盗贴纸 (贴纸以及位置图翻单PO#4500159287）+ 箱唛 + 外箱SSCC Label 配比信息：3pcs mini turtles: 4pcs mini tutles: 5pcs mini turtles= 87:10:3 Remark: 1.请务必按时完货，验货。并且按期送货入货代指定仓库，如果晚了导致船期Delay将会有罚金产生或者客户要求空运，所产生的罚金和空运费由工厂承担。 2.SSCC 外箱贴纸请同纸箱瓦楞纸方向（竖纹向）垂直，即外箱贴纸横着贴(注意条码不要被胶带粘住），贴1pc，贴1面正唛，封箱胶纸不能挡住贴纸内容。外箱贴纸 离外箱边距离不少于2cm。 3.外箱材质为ZURU标准； 4.此单需使用KMART封箱胶上下工字型封箱;从2019年6月开始，要用KMART 新版封箱胶带，此单要用"ANKO"封箱胶带 5.此单出口新西兰，请按相应的澳新标准生产； 6.产品和包装上生产批号的显示格式ZURU标准日期码格式 7.外箱信息不可手写，重量和体积需要与实际的一致(不可手写） 8. 每款item装箱后的G.W.超过10KG或者CBM超过0.13,(9.5KG或者以上，四舍五入后也属于10KG) 需在外箱上加印超 重或者Bulky LOGO，若发现我们资料没有，请 帮忙提醒 1)重量超过10kg但不超过16kg且CBM不超过0.13,10-16kg 超重logo 2）CBM超过0.13且重量少于17kg，bulky logo 3）不属于以上两种情况，需要使用相应重量范围内的超重logo 4）超重logo需要在外箱四面都印刷(箱唛右上角，两面侧唛超重logo需要尽量靠近毛重)，尺寸为:110mm height* 95mm width 9. 实际外箱重量跟印在箱唛上的数据差异不能超3%，尺寸按实际数据印刷 | Z38: Lydia Wu | AA38: 5.837 | AB38: =I38*AA38 -> 280.176 | AC38: 94954-5.9 | AD38: 9561-S001 | AE38: 已入 | AF38: =I38 -> 48 | AL38: =I38 -> 48 | AP38: =I38 -> 48 | AU38: =I38 -> 48 | AV38: =AV37+AU38 -> 45502
A39: 45737 | B39: KMART AUSTRALIA LTD | C39: 澳大利亚 | D39: 4500161007 | E39: 20722716 | F39: 4500161007-10 | G39: 9561-S001 | H39: 魔法小鸟 | I39: 1452 | J39: 0 | K39: 4 | L39: =I39/K39 -> 363 | M39: 45783 | N39: 45779 | P39: PASS | R39: 45748 | S39: 有 | T39: 1张包装纽扣电池警告语贴纸 + 1张说明书纽扣电池警告语 贴纸 （贴纸及位置图翻单: PO#4500157612）+ 1张防盗贴纸 (贴纸以及位置图翻单PO#4500159287）+ 箱唛 + 外箱SSCC Label | U39: MA | X39: 日期码格式：ZURU INC(BVI) 标准格式 日期：按实际生产日期 | Y39: 日期码格式：ZURU INC(BVI) 标准格式 日期：按实际生产日期 Packaging Info: 9561: MA英语UPC版本包装（收缩膜和说明书, MA首选1L，如无1L可用多语且含英语的配套多语包装) + 1张包装纽扣电池警告语贴纸 + 1张说明书纽扣电池警告语 贴纸 （贴纸及位置图翻单: PO#4500157612）+ 1张防盗贴纸 (贴纸以及位置图翻单PO#4500159287）+ 箱唛 + 外箱SSCC Label 配比信息：3pcs mini turtles: 4pcs mini tutles: 5pcs mini turtles= 87:10:3 Remark: 1.请务必按时完货，验货。并且按期送货入货代指定仓库，如果晚了导致船期Delay将会有罚金产生或者客户要求空运，所产生的罚金和空运费由工厂承担。 2.SSCC 外箱贴纸请同纸箱瓦楞纸方向（竖纹向）垂直，即外箱贴纸横着贴(注意条码不要被胶带粘住），贴1pc，贴1面正唛，封箱胶纸不能挡住贴纸内容。外箱贴纸 离外箱边距离不少于2cm。 3.外箱材质为ZURU标准； 4.此单需使用KMART封箱胶上下工字型封箱;从2019年6月开始，要用KMART 新版封箱胶带，此单要用"ANKO"封箱胶带 5.此单出口澳大利亚，请按相应的澳新标准生产； 6.产品和包装上生产批号的显示格式ZURU标准日期码格式 7.外箱信息不可手写，重量和体积需要与实际的一致(不可手写） 8. 每款item装箱后的G.W.超过10KG或者CBM超过0.13,(9.5KG或者以上，四舍五入后也属于10KG) 需在外箱上加印超 重或者Bulky LOGO，若发现我们资料没有，请 帮忙提醒 1)重量超过10kg但不超过16kg且CBM不超过0.13,10-16kg 超重logo 2）CBM超过0.13且重量少于17kg，bulky logo 3）不属于以上两种情况，需要使用相应重量范围内的超重logo 4）超重logo需要在外箱四面都印刷(箱唛右上角，两面侧唛超重logo需要尽量靠近毛重)，尺寸为:110mm height* 95mm width 9. 实际外箱重量跟印在箱唛上的数据差异不能超3%，尺寸按实际数据印刷 | Z39: Lydia Wu | AA39: 5.8209 | AB39: =I39*AA39 -> 8451.9468 | AC39: 94956-5.9 | AD39: 9561-S001 | AE39: 已入 | AF39: =I39 -> 1452 | AL39: =I39 -> 1452 | AP39: =I39 -> 1452 | AU39: =I39 -> 1452 | AV39: =AV38+AU39 -> 46954
A40: 45754 | B40: ZURU Denmark ApS | C40: 丹麦 | D40: 4500162346 | E40: 5200006527 | F40: 4500162346-40 | G40: 9561-S001-MTS | H40: 魔法小鸟 | I40: 1156 | J40: 0 | K40: 4 | L40: =I40/K40 -> 289 | M40: 45783 | N40: 45779 | P40: PASS | R40: 45763 | S40: 无 | T40: 1*多语折叠警告语贴纸（翻单4500157858）+ 北欧六语客版说明书(英语/丹麦/瑞典/芬兰/挪威/爱沙尼亚语言<(>,<)>翻单#450 0160993)+ 北欧六语客版guide book(英语/丹麦/瑞典/芬兰/挪威/爱沙尼亚语言, 翻单#4500160993) + 8L Slime袋子 + 北欧五语通用Slime黑白说明书 + 北欧五语通用带电池 出货黑白电池说明书+ZURU地址贴纸贴在鸟身上 | U40: MA | Y40: 日期码格式：ZURU INC(BVI) 标准格式 日期：按实际生产日期 Packaging Info: 9561: MA 5L+9L警语 EAN A版包装 +1*多语折叠警告语贴纸（翻单4500157858）+ 北欧六语客版说明书(英语/丹麦/瑞典/芬兰/挪威/爱沙尼亚语言<(>,<)>翻单#450 0160993)+ 北欧六语客版guide book(英语/丹麦/瑞典/芬兰/挪威/爱沙尼亚语言, 翻单#4500160993) + 8L Slime袋子 + 北欧五语通用Slime黑白说明书 + 北欧6语通用带电池 出货黑白电池说明书 Remark: 1.北欧内销单，需要通过ZURU 验货结果后才能出货 (工厂需要主动提前同ZURU QC预约验货避免延期出货造成不必要麻烦)； 2. 产品如含有化学品，需要无硼无香， 3.包装不能含有PVC，使用PET 4. date code: 外箱日期码要晚于产品日期码 5. 装柜时需要按照款式号码从小到大一款款依次装,避免终端仓库卸货混乱.若一个柜子涉及到几个不同国家内销单,装柜时需要一个国家装完后再装另一个国家的 产品,依次装柜,避免终端仓库因不同国家不同库位位置卸货混乱. (此点需要同工厂装柜人员强调)" 6.若有特定款有特殊外箱条码要求时,需要明确列出产品款对应的具体外箱条码号码/条码类型 (若无,可以忽略此需求) 7.所有出口欧洲的产品, 法规规定禁止在包装和共公众用的印刷品中使用矿物油中含有的物质, 包装印刷油墨中含有的MOAH/MOSH的质量浓度不能超过1%, 否则出货 到法国被抽检出现问题, 供应商需要对此负责; 8.带电池出货的产品所用到的电池需要符合欧洲电池新规(EU) 2023-1542。 9.ratio 同MA | Z40: SD04 | AA40: 5.4 | AB40: =I40*AA40 -> 6242.4 | AC40: 94941-5.7 | AD40: 9561-S001-芬兰 | AE40: 已入 | AJ40: =I40 -> 1156 | AN40: =I40 -> 1156 | AO40: =I40 -> 1156 | AP40: =I40 -> 1156 | AU40: =I40 -> 1156 | AV40: =AV39+AU40 -> 48110
A41: 45728 | B41: COOP Cooperative | C41: 瑞士 | D41: 4500159905 | E41: 7186490420 | F41: 4500159905-10 | G41: 9561-S001 | H41: 魔法小鸟 | I41: 264 | J41: 0 | K41: 4 | L41: =I41/K41 -> 66 | M41: 45783 | N41: 45779 | P41: PASS | R41: 45730 | S41: 无 | T41: 4/3WEEE说明书+客人价格贴纸 | U41: MA | X41: 日期码格式：ZURU INC(BVI) 标准格式 日期：按实际生产日期 | Y41: 日期码格式：ZURU INC(BVI) 标准格式 日期：按实际生产日期 Packaging Info: 9561: 最新MA 5L+6L EAN 收缩膜+ 最新MA 6L警语收藏指南+ WEEE说明书+客人价格贴纸 Remark: "1. 大货样品3套/item，用于第三方验货签办，请多备料。 2. 价格贴纸需使用可移动并无表面处理 3. EAN条码贴纸覆盖原先的条码；球的价格贴纸尽量贴平整避免起翘 4. 出口欧洲 微塑料需合规" | Z41: Joyce Chen | AA41: 5.4 | AB41: =I41*AA41 -> 1425.6 | AD41: 9561-S001-5L | AE41: 已入 | AJ41: =I41 -> 264 | AL41: =I41 -> 264 | AP41: =I41 -> 264 | AU41: =I41 -> 264 | AV41: =AV40+AU41 -> 48374
...

Sheet 布料MA
B2: 9561魔法小鸟IC MA
B3: 日期 | C3: MA订单号码 | D3: ITEM | E3: 名称 | F3: MA数量 | G3: 要求交货日期 | H3: IC 供应商 | I3: IC编号 | J3: 备注
B4: 45623 | C4: MA-RR-1459 | D4: 9561 | E4: IC | F4: 1000 | G4: 45638 | H4: 矽源特 | I4: CST2403170-13A MH 6118SOP-8 MHW 233B SOP23-6 MH261AA SOT-23 | J4: 开PP使用
B5: 45650 | C5: MA-RR-1491 | D5: 9561 | E5: IC | F5: 40000 | G5: 45665 | H5: 矽源特 | I5: CST2403170-13A MH 6118SOP-8 MHW 233B SOP23-6 MH261AA SOT-23
B6: 45673 | C6: MA-RR-1523 | D6: 9561 | E6: IC | F6: 40000 | G6: 45714 | H6: 矽源特 | I6: CST2403170-13A MH 6118SOP-8 MHW 233B SOP23-6 MH261AA SOT-23
B7: 45714 | C7: MA-RR-1563 | D7: 9561 | E7: IC | F7: 119000 | G7: 45729 | H7: 矽源特 | I7: CST2403170-13A MH 6118SOP-8 MHW 233B SOP23-6 MH261AA SOT-23
B8: 45735 | C8: MA-RR-1598 | D8: 9561 | E8: IC | F8: 120000 | G8: 45760 | H8: 矽源特 | I8: CST2403170-13A MH 6118SOP-8 MHW 233B SOP23-6 MH261AA SOT-23
B9: 45790 | C9: MA-RR-1654 | D9: 9561 | E9: IC | F9: 80000 | G9: 45805 | H9: 矽源特 | I9: CST2403170-13A MH 6118SOP-8 MHW 233B SOP23-6 MH261AA SOT-23
B10: 45803 | C10: MA-RR-1685 | D10: 9561 | E10: IC | F10: 100000 | G10: 45828 | H10: 矽源特 | I10: CST2403170-13A MH 6118SOP-8 MHW 233B SOP23-6 MH261AA SOT-23
B11: 45804 | C11: MA-RR-1689 | D11: 9561 | E11: IC | F11: 50000 | G11: 45829 | H11: 矽源特 | I11: CST2403170-13A MH 6118SOP-8 MHW 233B SOP23-6 MH261AA SOT-23
B12: 45824 | C12: MA-RR-1736 | D12: 9561 | E12: IC | F12: 100000 | G12: 45844 | H12: 矽源特 | I12: CST2403170-13A MH 6118SOP-8 MHW 233B SOP23-6 MH261AA SOT-23
B13: 45846 | C13: MA-RR-1780 | D13: 9561 | E13: IC | F13: 80000 | G13: 45866 | H13: 矽源特 | I13: CST2403170-13A MH 6118SOP-8 MHW 233B SOP23-6 MH261AA SOT-23
B14: 45999 | C14: MA-RR-1997 | D14: 9561 | E14: IC | F14: 30000 | G14: 46036 | H14: 矽源特 | I14: CST2403170-13A MH 6118SOP-8 MHW 233B SOP23-6 MH261AA SOT-23
B15: 46015 | C15: MA-RR-2017 | D15: 9561 | E15: IC | F15: 40000 | G15: 46035 | H15: 矽源特 | I15: CST2403170-13A MH 6118SOP-8 MHW 233B SOP23-6 MH261AA SOT-23
B16: 46031 | C16: MA-RR-2048 | D16: 9561 | E16: IC | F16: 60000 | G16: 46042 | H16: 矽源特 | I16: CST2403170-13A MH 6118SOP-8 MHW 233B SOP23-6 MH261AA SOT-23
... B21: 46169 | C21: MA-RR-2328 | D21: 9561 | E21: IC | F21: 80000 | G21: 46209 | H21: 矽源特 | I21: CST2403170-13A MH 6118SOP-8 MHW 233B SOP23-6 MH261AA SOT-23
E23: 合计 | F23: =SUM(F4:F22) -> 1150000
E24: 半成品MA数 | F24: =G52 -> 0
E25: 接单总数 | F25: ='9561'!I727 -> 974175
E26: 按实单扣数的IC MA剩余 | F26: =F23-F25 -> 175825
E27: 按半成品MA扣数的IC MA剩余 | F27: =F23-F24 -> 1150000
B31: 9561魔法小鸟 半成品生产MA
B32: 日期 | C32: MA订单号码 | D32: ITEM | E32: 名称 | H32: 合计 | I32: 要求完成日期 | J32: 备注
B33: 45706 | C33: MA_RR_1522 | D33: 9561 | E33: 魔法小鸟 | H33: 200000 | I33: 45767 | J33: 胶件
B34: 45735 | C34: MA-RR-1597 | D34: 9561 | E34: 魔法小鸟 | H34: 120000 | I34: 45794 | J34: 胶件
B35: 45789 | C35: MA-RR-1651 | D35: 9561 | E35: 魔法小鸟 | H35: 80000 | I35: 45849 | J35: 胶件
B36: 45803 | C36: MA-RR-1679 | D36: 9561 | E36: 魔法小鸟 | H36: 100000 | I36: 45859 | J36: 胶件
B37: 45824 | C37: MA-RR-1735 | D37: 9561 | E37: 魔法小鸟 | H37: 150000 | I37: 45884 | J37: 胶件
B38: 45846 | C38: MA-RR-1779 | D38: 9561 | E38: 魔法小鸟 | H38: 80000 | I38: 45906 | J38: 胶件
B39: 45999 | C39: MA-RR-1992 | D39: 9561 | E39: 魔法小鸟 | H39: 30000 | I39: 46047 | J39: 胶件
B40: 46015 | C40: MA-RR-2018 | D40: 9561 | E40: 魔法小鸟 | H40: 40000 | I40: 46079 | J40: 胶件
B41: 46057 | C41: MA-RR-2107 | D41: 9561 | E41: 魔法小鸟 | H41: 60000 | I41: 46143 | J41: 胶件
B42: 46090 | C42: MA-RR-2165 | D42: 9561 | E42: 魔法小鸟 | H42: 40000 | I42: 46150 | J42: 胶件
B43: 46094 | C43: MA-RR-2192 | D43: 9561 | E43: 魔法小鸟 | H43: 60000 | I43: 46186 | J43: 胶件
B44: 46140 | C44: MA-RR-2266 | D44: 9561 | E44: 魔法小鸟 | H44: 20000 | I44: 46234 | J44: 胶件
... B46: 46167 | C46: MA-RR-2321 | D46: 9561 | E46: 魔法小鸟 | H46: 30000 | I46: 46259 | J46: 胶件
E52: MA合计 | H52: =SUM(H33:H51) -> 1070000
G53: 接单总数 | H53: ='9561'!I727 -> 974175
G54: MA剩余 | H54: =H52-H53 -> 95825
G55: MA剩余占MA数比率 | H55: =H54/H52 -> 0.089556075
...

Sheet 包装MA
A2: 日期
C3: 名称 | D3: 包装名称 | E3: MA订单号码 | F3: 货号 | G3: 数量 | H3: 语言 | I3: 版本号 | J3: 镭射贴纸 | K3: 纸卡A版 | L3: 纸卡B版 | M3: 珍珠棉 | N3: 收藏指南A | O3: 收藏指南B | P3: 说明书A | Q3: 说明书B | R3: 收缩膜1L | S3: 收缩膜1LB版本 | T3: 收缩膜5L | U3: 收缩膜5LB版本 | V3: 客版收缩膜 | W3: 客版说明书 | X3: 客版收藏指南 | Y3: Endcap EC展架1L | Z3: Endcap EC展架3L | AA3: PLD展示架
A4: 45708 | C4: S001-PETS ALIVE-MAGIC BIRD-SERIES 1-MAGIC BIRD SURPRISE PLAYSET-SHRINK WRAP-4PCS/CTN | D4: Logo贴纸（无语言） | E4: 1000025855 | F4: 9561 | G4: 100000 | H4: 无语言 | I4: A | J4: 100000
A5: 45708 | C5: S001-PETS ALIVE-MAGIC BIRD-SERIES 1-MAGIC BIRD SURPRISE PLAYSET-SHRINK WRAP-4PCS/CTN | D5: 围卡 | E5: 1000025856 | F5: 9561 | G5: 100000 | H5: 无语言 | I5: A | K5: 100000
A6: 45708 | C6: S001-PETS ALIVE-MAGIC BIRD-SERIES 1-MAGIC BIRD SURPRISE PLAYSET-SHRINK WRAP-4PCS/CTN | D6: 珍珠膜 | E6: 1000025857 | F6: 9561 | G6: 100000 | H6: 无语言 | I6: A | M6: 100000
A7: 45708 | C7: S001-PETS ALIVE-MAGIC BIRD-SERIES 1-MAGIC BIRD SURPRISE PLAYSET-SHRINK WRAP-4PCS/CTN | D7: 说明书- (大张) | E7: 1000025858 | F7: 9561 | G7: 100000 | H7: 6L | I7: A | N7: 100000
A8: 45708 | C8: S001-PETS ALIVE-MAGIC BIRD-SERIES 1-MAGIC BIRD SURPRISE PLAYSET-SHRINK WRAP-4PCS/CTN | D8: 说明书-（小张) | E8: 1000025859 | F8: 9561 | G8: 100000 | H8: 5L+6L | I8: A | P8: 100000
A9: 45708 | C9: S001-PETS ALIVE-MAGIC BIRD-SERIES 1-MAGIC BIRD SURPRISE PLAYSET-SHRINK WRAP-4PCS/CTN | D9: 收缩套 | E9: 1000025860 | F9: 9561 | G9: 100000 | H9: 1L | I9: A | R9: 100000
A10: 45708 | C10: S001-PETS ALIVE-MAGIC BIRD-SERIES 1-MAGIC BIRD SURPRISE PLAYSET-SHRINK WRAP-4PCS/CTN | D10: 收缩套 | E10: 1000025861 | F10: 9561 | G10: 30000 | H10: 5L+6L | I10: A | T10: 30000
A11: 45708 | C11: S001-PETS ALIVE-MAGIC BIRD-SERIES 1-MAGIC BIRD SURPRISE PLAYSET-SHRINK WRAP-4PCS/CTN | D11: 展示架 | E11: 1000026887 | F11: 9561 | G11: 300 | H11: 1L | I11: A | Y11: 300
A12: 45768 | C12: S001-PETS ALIVE-MAGIC BIRD-SERIES 1-MAGIC BIRD SURPRISE PLAYSET-SHRINK WRAP-4PCS/CTN | D12: Logo贴纸（无语言） | F12: 9561 | G12: 30000 | H12: 无语言 | I12: A | J12: =G12 -> 30000
A13: 45768 | C13: S001-PETS ALIVE-MAGIC BIRD-SERIES 1-MAGIC BIRD SURPRISE PLAYSET-SHRINK WRAP-4PCS/CTN | D13: 围卡 | F13: 9561 | G13: 30000 | H13: 无语言 | I13: A | K13: =G13 -> 30000
A14: 45768 | C14: S001-PETS ALIVE-MAGIC BIRD-SERIES 1-MAGIC BIRD SURPRISE PLAYSET-SHRINK WRAP-4PCS/CTN | D14: 珍珠膜 | F14: 9561 | G14: 30000 | H14: 无语言 | I14: A | M14: =G14 -> 30000
A15: 45768 | C15: S001-PETS ALIVE-MAGIC BIRD-SERIES 1-MAGIC BIRD SURPRISE PLAYSET-SHRINK WRAP-4PCS/CTN | D15: 说明书- (大张) | E15: 1000027277 | F15: 9561 | G15: 30000 | H15: 6L | I15: A | N15: =G15 -> 30000
A16: 45768 | C16: S001-PETS ALIVE-MAGIC BIRD-SERIES 1-MAGIC BIRD SURPRISE PLAYSET-SHRINK WRAP-4PCS/CTN | D16: 说明书-（小张) | E16: 1000027278 | F16: 9561 | G16: 30000 | H16: 5L+6L | I16: A | P16: =G16 -> 30000
A17: 45768 | C17: S001-PETS ALIVE-MAGIC BIRD-SERIES 1-MAGIC BIRD SURPRISE PLAYSET-SHRINK WRAP-4PCS/CTN | D17: 收缩套 | E17: 1000027279 | F17: 9561 | G17: 15000 | H17: 5L+6L | I17: A | T17: =G17 -> 15000
A18: 45768 | C18: S001-PETS ALIVE-MAGIC BIRD-SERIES 1-MAGIC BIRD SURPRISE PLAYSET-SHRINK WRAP-4PCS/CTN | D18: 展示架 | E18: 1000027284 | F18: 9561 | G18: 500 | H18: 3L | I18: A | Z18: =G18 -> 500
A19: 45784 | C19: S001-PETS ALIVE-MAGIC BIRD-SERIES 1-MAGIC BIRD SURPRISE PLAYSET-SHRINK WRAP-4PCS/CTN | D19: Logo贴纸（无语言） | E19: 1000027683 | F19: 9561 | G19: 50000 | H19: 无语言 | J19: =G19 -> 50000
A20: 45789 | C20: S001-PETS ALIVE-MAGIC BIRD-SERIES 1-MAGIC BIRD SURPRISE PLAYSET-SHRINK WRAP-4PCS/CTN | D20: 围卡 | E20: 1000028378 | F20: 9561 | G20: 50000 | H20: 无语言 | I20: A | K20: =G20 -> 50000
A21: 45784 | C21: S001-PETS ALIVE-MAGIC BIRD-SERIES 1-MAGIC BIRD SURPRISE PLAYSET-SHRINK WRAP-4PCS/CTN | D21: 珍珠膜 | E21: 1000027685 | F21: 9561 | G21: 50000 | H21: 无语言 | M21: =G21 -> 50000
A22: 45784 | C22: S001-PETS ALIVE-MAGIC BIRD-SERIES 1-MAGIC BIRD SURPRISE PLAYSET-SHRINK WRAP-4PCS/CTN | D22: 说明书- (大张) | E22: 1000028375 | F22: 9561 | G22: 50000 | H22: 6L | I22: A | N22: =G22 -> 50000
A23: 45784 | C23: S001-PETS ALIVE-MAGIC BIRD-SERIES 1-MAGIC BIRD SURPRISE PLAYSET-SHRINK WRAP-4PCS/CTN | D23: 说明书-（小张) | E23: 1000028376 | F23: 9561 | G23: 50000 | H23: 5L+6L | I23: A | P23: =G23 -> 50000
A24: 45784 | C24: S001-PETS ALIVE-MAGIC BIRD-SERIES 1-MAGIC BIRD SURPRISE PLAYSET-SHRINK WRAP-4PCS/CTN | D24: 收缩套 | E24: 1000028377 | F24: 9561 | G24: 50000 | H24: 5L+6L | I24: A | T24: =G24 -> 50000
A25: 45784 | C25: S001-PETS ALIVE-MAGIC BIRD-SERIES 1-MAGIC BIRD SURPRISE PLAYSET-SHRINK WRAP-4PCS/CTN | D25: 展示架 | E25: 1000027689 | F25: 9561 | G25: 300 | H25: 3L | Z25: 300
A26: 45792 | C26: S001-PETS ALIVE-MAGIC BIRD-SERIES 1-MAGIC BIRD SURPRISE PLAYSET-SHRINK WRAP-4PCS/CTN | D26: 围卡 | E26: 1000027905 | F26: 9561 | G26: 50000 | H26: 无语言 | I26: A | K26: =G26 -> 50000
A27: 45792 | C27: S001-PETS ALIVE-MAGIC BIRD-SERIES 1-MAGIC BIRD SURPRISE PLAYSET-SHRINK WRAP-4PCS/CTN | D27: 说明书- (大张) | E27: 1000027906 | F27: 9561 | G27: 50000 | H27: 6L | I27: A | N27: =G27 -> 50000
A28: 45792 | C28: S001-PETS ALIVE-MAGIC BIRD-SERIES 1-MAGIC BIRD SURPRISE PLAYSET-SHRINK WRAP-4PCS/CTN | D28: 说明书-（小张) | E28: 1000027907 | F28: 9561 | G28: 50000 | H28: 5L+6L | I28: A | P28: =G28 -> 50000
A29: 45792 | C29: S001-PETS ALIVE-MAGIC BIRD-SERIES 1-MAGIC BIRD SURPRISE PLAYSET-SHRINK WRAP-4PCS/CTN | D29: 收缩套 | E29: 1000027908 | F29: 9561 | G29: 40000 | H29: 5L+6L | I29: A | T29: =G29 -> 40000
A30: 45803 | C30: S001-PETS ALIVE-MAGIC BIRD-SERIES 1-MAGIC BIRD SURPRISE PLAYSET-SHRINK WRAP-4PCS/CTN | D30: Logo贴纸（无语言） | E30: 1000028408 | F30: 9561 | G30: 150000 | H30: 无语言 | I30: A | J30: =G30 -> 150000
A31: 45803 | C31: S001-PETS ALIVE-MAGIC BIRD-SERIES 1-MAGIC BIRD SURPRISE PLAYSET-SHRINK WRAP-4PCS/CTN | D31: 围卡 | E31: 1000028397 | F31: 9561 | G31: 100000 | H31: 无语言 | I31: A | K31: =G31 -> 100000
A32: 45803 | C32: S001-PETS ALIVE-MAGIC BIRD-SERIES 1-MAGIC BIRD SURPRISE PLAYSET-SHRINK WRAP-4PCS/CTN | D32: 珍珠膜 | E32: 1000028398 | F32: 9561 | G32: 150000 | H32: 无语言 | I32: A | M32: =G32 -> 150000
A33: 45803 | C33: S001-PETS ALIVE-MAGIC BIRD-SERIES 1-MAGIC BIRD SURPRISE PLAYSET-SHRINK WRAP-4PCS/CTN | D33: 说明书- (大张) | E33: 1000028399 | F33: 9561 | G33: 60000 | H33: 6L | I33: A | N33: =G33 -> 60000
A34: 45803 | C34: S001-PETS ALIVE-MAGIC BIRD-SERIES 1-MAGIC BIRD SURPRISE PLAYSET-SHRINK WRAP-4PCS/CTN | D34: 说明书-（小张) | E34: 1000028400 | F34: 9561 | G34: 60000 | H34: 5L+6L | I34: A | P34: =G34 -> 60000
A35: 45803 | C35: S001-PETS ALIVE-MAGIC BIRD-SERIES 1-MAGIC BIRD SURPRISE PLAYSET-SHRINK WRAP-4PCS/CTN | D35: 收缩套 | E35: 1000028401 | F35: 9561 | G35: 150000 | H35: 1L | I35: A | R35: =G35 -> 150000
A36: 45828 | C36: S001-PETS ALIVE-MAGIC BIRD-SERIES 1-MAGIC BIRD SURPRISE PLAYSET-SHRINK WRAP-4PCS/CTN | D36: Logo贴纸（无语言） | E36: 1000029192 | F36: 9561 | G36: 150000 | H36: 无语言 | I36: A | J36: =G36 -> 150000
A37: 45828 | C37: S001-PETS ALIVE-MAGIC BIRD-SERIES 1-MAGIC BIRD SURPRISE PLAYSET-SHRINK WRAP-4PCS/CTN | D37: 围卡 | E37: 1000029194 | F37: 9561 | G37: 200000 | H37: 无语言 | I37: B | L37: =G37 -> 200000
A38: 45828 | C38: S001-PETS ALIVE-MAGIC BIRD-SERIES 1-MAGIC BIRD SURPRISE PLAYSET-SHRINK WRAP-4PCS/CTN | D38: 珍珠膜 | E38: 1000029193 | F38: 9561 | G38: 200000 | H38: 无语言 | I38: A | M38: =G38 -> 200000
A39: 45828 | C39: S001-PETS ALIVE-MAGIC BIRD-SERIES 1-MAGIC BIRD SURPRISE PLAYSET-SHRINK WRAP-4PCS/CTN | D39: 说明书- (大张) | E39: 1000029195 | F39: 9561 | G39: 200000 | H39: 6L | I39: B | O39: =G39 -> 200000
A40: 45828 | C40: S001-PETS ALIVE-MAGIC BIRD-SERIES 1-MAGIC BIRD SURPRISE PLAYSET-SHRINK WRAP-4PCS/CTN | D40: 说明书-（小张) | E40: 1000029196 | F40: 9561 | G40: 200000 | H40: 5L+6L | I40: B | Q40: =G40 -> 200000
A41: 45828 | C41: S001-PETS ALIVE-MAGIC BIRD-SERIES 1-MAGIC BIRD SURPRISE PLAYSET-SHRINK WRAP-4PCS/CTN | D41: 收缩套 | E41: 1000029197 | F41: 9561 | G41: 100000 | H41: 1L | I41: B | S41: =G41 -> 100000
...

Sheet 取消单
A1: 接单日期 | B1: 第三方客户名称 | C1: 国家 | D1: PO号 | E1: 客PO号 | F1: SKU | G1: 系统货号 | H1: ITEM# | I1: 中文名 | J1: PO数量 (pcs) | K1: 内箱装箱数量(pcs) | L1: 外箱装箱数量(pcs) | M1: 总箱数 | N1: 客PO期 | O1: 验货期 | P1: 第三方验货期 | Q1: 驗貨結果 | R1: 船期SO | S1: 箱唛资料 | T1: 外箱贴纸 | U1: 客贴纸资料 | V1: 布料 | W1: 客供物料 | X1: 日期码 | Y1: 备注 | Z1: ZURU 跟单 | AA1: 单价USD | AB1: 金额USD | AC1: 发票号 | AD1: 是否入系统 | AE1: MA 1L收缩膜 | AF1: MA 5L收缩膜 | AG1: MA 6L说明书 | AH1: MA 5L说明书 | AI1: 客版说明书 | AJ1: 客版收藏指南 | AK1: EC展示架1L | AL1: EC展示架3L | AM1: 布標 | AN1: 合计数量 | AO1: 累计数量
A2: 45747 | B2: Mid-States Distributing, LLC | C2: 美国 | D2: 4500161570 | E2: Murdoch's Southern DC PO 671605134 | F2: 4500161570-270 | G2: 9561-S001 | H2: 9561-S001 | I2: 魔法小鸟 | J2: 12 | K2: 0 | L2: 4 | M2: =J2/L2 -> 3 | N2: 45818 | O2: 45814 | P2: 取消 | S2: 欠 | T2: 无 | U2: 无 | V2: MA | Y2: 日期码格式：ZURU INC(BVI) 标准格式 日期：按实际生产日期 Packaging Info: 1.使用 MA UPC版本包装，优先1L，出口美国。 Remark: 1.产品和包装上印刷tracking code信息，格式为ZURU常规。 2.ZURU QC验货 | Z2: Cara Li | AA2: 5.837 | AB2: =J2*AA2 -> 70.044 | AD2: 已入 | AE2: =J2 -> 12 | AI2: =J2 -> 12 | AP2: =J2 -> 12 | AQ2: ='9561'!AV96+AP2 -> 106660
A3: 45747 | B3: Mid-States Distributing, LLC | C3: 美国 | D3: 4500161570 | E3: Murdoch's Norther DC PO 671605135 | F3: 4500161570-280 | G3: 9561-S001 | H3: 9561-S001 | I3: 魔法小鸟 | J3: 20 | K3: 0 | L3: 4 | M3: =J3/L3 -> 5 | N3: 45818 | O3: 45814 | P3: 取消 | S3: 欠 | T3: 无 | U3: 无 | V3: MA | Y3: 日期码格式：ZURU INC(BVI) 标准格式 日期：按实际生产日期 Packaging Info: 1.使用 MA UPC版本包装，优先1L，出口美国。 Remark: 1.产品和包装上印刷tracking code信息，格式为ZURU常规。 2.ZURU QC验货 | Z3: Cara Li | AA3: 5.837 | AB3: =J3*AA3 -> 116.74 | AD3: 已入 | AE3: =J3 -> 20 | AI3: =J3 -> 20 | AP3: =J3 -> 20 | AQ3: =AQ2+AP3 -> 106680
A4: 45747 | B4: Mid-States Distributing, LLC | C4: 美国 | D4: 4500161570 | E4: Murdoch's TX DC PO 671605136 | F4: 4500161570-290 | G4: 9561-S001 | H4: 9561-S001 | I4: 魔法小鸟 | J4: 8 | K4: 0 | L4: 4 | M4: =J4/L4 -> 2 | N4: 45818 | O4: 45814 | P4: 取消 | S4: 欠 | T4: 无 | U4: 无 | V4: MA | Y4: 日期码格式：ZURU INC(BVI) 标准格式 日期：按实际生产日期 Packaging Info: 1.使用 MA UPC版本包装，优先1L，出口美国。 Remark: 1.产品和包装上印刷tracking code信息，格式为ZURU常规。 2.ZURU QC验货 | Z4: Cara Li | AA4: 5.837 | AB4: =J4*AA4 -> 46.696 | AD4: 已入 | AE4: =J4 -> 8 | AI4: =J4 -> 8 | AP4: =J4 -> 8 | AQ4: =AQ3+AP4 -> 106688
