Workbook

Sheet 9543
A1: ZURU Hamster Mania 仓鼠生产排期表 #9543
A2: 44887 | H2: （黃色表示更改或增加） | K2: （蓝色表示已完货） | O2: （綠色表示調整貨期） | AI2: 收縮膜 | AL2: 收缩膜 | AT2: 收藏指南 | AW2: PDQ版本 | AX2: PDQ 1L | BA2: PDQ 3L | BW2: GQ1配比： | BX2: 5 | BY2: 6 | BZ2: 6 | CA2: 5
A3: 接单期 | B3: 第三方客户名称 | C3: 国家 | D3: PO | E3: 客户PO号 | F3: SKU号 | G3: 货号 | H3: 名称 | I3: 数量 | J3: 内箱装箱数量(pcs) | K3: 装箱数（PCS） | L3: 总箱数 | M3: 计划出货期 | N3: 计划验货期 | O3: 第三方验货期 | P3: 驗貨結果 | Q3: 船期SO | R3: 箱唛资料(收到日期) | S3: 外箱贴纸 | T3: PMC订购 说明书纸 | U3: 贴纸AI(收到日期) | V3: 客供物料 | W3: 日期码 | X3: 备注 | Y3: ZURU 跟单 | Z3: 单价USD | AA3: 金额USD | AB3: 送回情况 | AC3: 欠数 | AD3: 贴纸 | AE3: 系统货号 | AF3: 是否入系统 | AG3: 系统出单 | AH3: 發票號 | AI3: MA 1語收縮膜 A版本 | AJ3: MA 1語收縮膜 B版本 | AK3: MA 1語收縮膜 C版本 | AL3: MA 1語收縮膜 D版本 | AM3: MA 1語收縮膜 E版本 | AN3: MA 3语收缩膜 | AO3: MA 3語收縮膜 C版本 | AP3: MA 3語收縮膜 D版本 | AQ3: 客版收縮膜 | AR3: MA 9语 收藏指南 A版本 | AS3: MA 9语 收藏指南 B版本 | AT3: MA 5语 收藏指南 A版本 | AU3: MA 5语 收藏指南 B版本 | AV3: 客版收藏指南 | AW3: GQ1-MA 1L | AX3: GQ1-MA 1L-B版本 | AY3: GQ1-MA 1L-C版本 | AZ3: GQ1-MA 3L | BA3: GQ1-MA 3L-B版本 | BB3: GQ1-MA 3L-C版本 | BC3: GQ2-MA 3L KM单+WM-CA-A版本 | BD3: GQ2-MA 3L KM单+WM-CA-B版本 | BE3: GQ2-MA 3L KM单+WM-CA-C版本 | BF3: GQ3- 客版 1L | BG3: GQ3-客版 1L-B版本 | BH3: GQ3-客版 1L-C版本 | BI3: GQ4-MA 1L TG单-A版本 | BJ3: GQ4-MA 1L TG单-B版本 | BK3: GQ4-MA 1L TG单-C版本 | BL3: GQ4-MA 1L TG单-D版本 | BM3: TQ1 WM单 | BN3: TQ2-3PCS | BO3: TQ2-B 版本 | BP3: GQ5-A版本 | BQ3: GQ5-B版本 | BR3: GQ6 | BS3: GQ6-B版本 | BT3: SK-S001-3L 无底座 | BU3: SK-S002 -3L有底座 | BV3: 客版PDQ | BW3: 布標 | BX3: 蓝色仓鼠(Blue)（A) | BY3: 粉色仓鼠(Pink)（B) | BZ3: 紫色仓鼠(Purple)(D) | CA3: 土黄色仓鼠(Orange)(E) | CB3: 透明球 | CC3: 无功能 粉色仓鼠 | CD3: 总数 | CE3: 相差 | XBS3: =SUM(A3:XBR3) -> 0 | XCB3: =SUBTOTAL(9,A3:XCA3) -> 0 | XCS3: =SUM(A3:XCR3) -> 0 | XDA3: =SUBTOTAL(9,A3:XCZ3) -> 0 | XEN3: =SUBTOTAL(9,A3:XEM3) -> 0
A4: 45463 | B4: DM LLC | C4: 俄罗斯 | D4: 4500137881 | E4: Ural | F4: 4500137881-90 | G4: 9543-S001 | H4: 仓鼠 | I4: 792 | J4: 0 | K4: 24 | L4: =I4/K4 -> 33 | M4: 45498 | N4: 45500 | P4: PASS | Q4: 预计7/31出 | R4: 6/26收到 | U4: 7/9收到进口商贴纸+EAN条码贴纸 | X4: 日期码格式：彩卡/收缩膜/PDQ/外箱不要打ZURU标准日期码！ 日期： Packaging Info: 9543 优先1L MA 收缩膜+进口商贴纸+EAN条码贴纸; MA 说明书/指南(如有); 注意 ：彩卡/收缩膜/PDQ/外箱不要打ZURU标准日期码！！ Remark: 1. 出 Bekasovo 2和Ural; | Y4: Ann Zhang | Z4: 2.5721 | AA4: =I4*Z4 -> 2037.1032 | AB4: 792 | AC4: =AB4-I4 -> 0 | AD4: ok | AE4: 9543-S001 | AF4: 已入 | AG4: 系统出单 | AH4: 88869-1.4 | AL4: =I4 -> 792 | AT4: =I4 -> 792 | BW4: 增加移印布标内容 | BX4: =I4/4 -> 198 | BY4: =I4/4 -> 198 | BZ4: =I4/4 -> 198 | CA4: =I4/4 -> 198 | CB4: =I4 -> 792 | CD4: =SUM(BX4:CA4) -> 792 | CE4: =I4-CD4 -> 0
A5: 45593 | D5: ZMPO24801 | G5: 9543GQ1-S001 | H5: 仓鼠 | I5: 220 | J5: 0 | K5: 22 | L5: =I5/K5 -> 10 | M5: 45608 | N5: 45604 | P5: PASS | R5: 周转箱 | U5: 无 | X5: 备注： 收到样品订单后尽快安排 ，注意样板品质质量要求要高于大货品质要求 ，送货时必须要附带送货单(没有送货单和QC检验合格报告的仓库一律拒绝收货)，请知悉，谢谢！ Remark:大货最新ZURU Logo版本/款号平均/请用大货标准箱装箱22PCS/箱共10箱/箱唛请参照邮件附件 | Y5: Angus | AB5: 220 | AC5: =AB5-I5 -> 0 | AE5: 9543GQ1-S001 | AF5: 已入 | AG5: 系统出单 | AL5: =I5 -> 220 | AT5: =I5 -> 220 | AX5: =I5/11 -> 20 | BW5: 增加移印布标内容 | BX5: =I5/22*5 -> 50 | BY5: =I5/22*6 -> 60 | BZ5: =I5/22*6 -> 60 | CA5: =I5/22*5 -> 50 | CB5: =I5 -> 220 | CC5: =I5/11 -> 20 | CD5: =SUM(BX5:CA5) -> 220 | CE5: =I5-CD5 -> 0
A6: 45523 | B6: DM LLC | C6: 俄罗斯 | D6: 4500143263 | E6: 出Bekasovo 2 | F6: 4500143263-10 | G6: 9543-S001 | H6: 仓鼠 | I6: 1608 | J6: 0 | K6: 24 | L6: =I6/K6 -> 67 | M6: 45667 | N6: 45663 | P6: PASS | Q6: 2/10出 | R6: 10/28收到 | U6: 进口商贴纸+EAN条码贴纸（翻4500143236） | W6: 外包装 (指: 收缩膜/彩卡/吊牌/PDQ) /外箱不要打ZURU标准日期码！ | X6: 日期码格式：注意:外包装(指: 收缩膜/彩卡/吊牌/PDQ)/外箱不要打ZURU标准日期码！ 日期： Packaging Info: 出Bekasovo 2 和Ural 2 个港口； LC 货期不可延期有罚款 ； 1. 1L MA 收缩膜 or 彩卡+进口商贴纸（翻4500143236）+EAN条码贴纸（翻4500143236）; MA 说明书/指南（如有）; 注意 ：外包装 (指: 收缩膜/彩卡/吊牌/PDQ) /外箱不要打ZURU标准日期码！ Remark: 标准配比 | Y6: Ann Zhang | Z6: 2.5721 | AA6: =I6*Z6 -> 4135.9368 | AB6: =1584+24 -> 1608 | AC6: =AB6-I6 -> 0 | AD6: OK | AE6: 9543-S001 | AF6: 已入 | AG6: 系统出单 | AH6: 94200-2.10 | AL6: =I6 -> 1608 | AT6: =I6 -> 1608 | BW6: 增加移印布标内容 | BX6: =I6/4 -> 402 | BY6: =I6/4 -> 402 | BZ6: =I6/4 -> 402 | CA6: =I6/4 -> 402 | CB6: =I6 -> 1608 | CD6: =SUM(BX6:CA6) -> 1608 | CE6: =I6-CD6 -> 0
A7: 45523 | B7: DM LLC | C7: 俄罗斯 | D7: 4500143263 | E7: 出Ural | F7: 4500143263-40 | G7: 9543-S001 | H7: 仓鼠 | I7: 816 | J7: 0 | K7: 24 | L7: =I7/K7 -> 34 | M7: 45667 | N7: 45663 | P7: PASS | Q7: 2/10出 | R7: 10/28收到 | U7: 进口商贴纸+EAN条码贴纸（翻4500143236） | W7: 外包装 (指: 收缩膜/彩卡/吊牌/PDQ) /外箱不要打ZURU标准日期码！ | X7: 日期码格式：注意:外包装(指: 收缩膜/彩卡/吊牌/PDQ)/外箱不要打ZURU标准日期码！ 日期： Packaging Info: 出Bekasovo 2 和Ural 2 个港口； LC 货期不可延期有罚款 ； 1.9543 ： 1L MA 收缩膜 or 彩卡+进口商贴纸（翻4500143236）+EAN条码贴纸（翻4500143236）; MA 说明书/指南（如有）; 注意 ：外包装 (指: 收缩膜/彩卡/吊牌/PDQ) /外箱不要打ZURU标准日期码！ Remark: 标准配比 | Y7: Ann Zhang | Z7: 2.5721 | AA7: =I7*Z7 -> 2098.8336 | AB7: 816 | AC7: =AB7-I7 -> 0 | AD7: OK | AE7: 9543-S001 | AF7: 已入 | AG7: 系统出单 | AH7: 94200-2.10 | AL7: =I7 -> 816 | AT7: =I7 -> 816 | BW7: 增加移印布标内容 | BX7: =I7/4 -> 204 | BY7: =I7/4 -> 204 | BZ7: =I7/4 -> 204 | CA7: =I7/4 -> 204 | CB7: =I7 -> 816 | CD7: =SUM(BX7:CA7) -> 816 | CE7: =I7-CD7 -> 0
A8: 45614 | B8: Amazon Mexico, S. DE R.L. DE CV | C8: 墨西哥 | D8: 4500151559 | E8: 64SP3ZYY | F8: 4500151559-30 | G8: 9543A-S001 | H8: 仓鼠 | I8: 96 | J8: 0 | K8: 24 | L8: =I8/K8 -> 4 | M8: 45649 | N8: 45645 | P8: PASS | R8: 空白外箱加印ZURU Logo+MADE IN CHINA+SSCC LABEL(客供贴纸） | U8: UPC贴纸翻4500098824+12/4-进口商贴纸 | V8: 12/6-SSCC贴纸 | X8: 日期码格式：ZURU INC(BVI) 标准格式 日期：按实际生产日期 Packaging Info: 9543: MA 加UPC贴纸， UPC贴纸跟翻单4500098824+进口商贴纸+SSCC贴纸。 Remark: Amazon FOB订单，出口Mexico，外箱最长边不能超过25" （超过了，case pack只能为1），不符合要求的大货，一律不接受。 1.空白外箱加印ZURU Logo+MADE IN CHINA+SSCC LABEL(客供贴纸），无shipping mark,日期使用ZURU 标准版本。SSCC Label显示的是客人自己的item#，SSCC Lab el 贴在外箱正面的正中间，贴一面即可，跟单订购，贴纸离外箱距必须至少3cm,每一张SSCC Label都是唯一且有不同流水及条码的，没有损耗，绝对不可贴错，否 则贴错或损坏一张会导致全部都错，千万要注意！ 2. 日期码使用ZURU标准版 3. 客户PO备注在remark处 6.9543: 2PCS AAA Batteries(Not Include) | Y8: Zoe Luo | Z8: 2.6514 | AA8: =I8*Z8 -> 254.5344 | AB8: 96 | AC8: =AB8-I8 -> 0 | AD8: ok | AE8: 9543A-S001-MTS | AF8: 已入 | AG8: 系统出单 | AH8: 88897-1.6 | AL8: =I8 -> 96 | AT8: =I8 -> 96 | BW8: 增加移印布标内容 | BX8: =I8 -> 96 | CB8: =SUM(BX8:CA8) -> 96 | CD8: =SUM(BX8:CA8) -> 96 | CE8: =CD8-I8 -> 0
A9: 45614 | B9: Amazon Mexico, S. DE R.L. DE CV | C9: 墨西哥 | D9: 4500151559 | E9: 64SP3ZYY | F9: 4500151559-40 | G9: 9543D-S001 | H9: 仓鼠 | I9: 24 | J9: 0 | K9: 24 | L9: =I9/K9 -> 1 | M9: 45649 | N9: 45645 | P9: PASS | R9: 空白外箱加印ZURU Logo+MADE IN CHINA+SSCC LABEL(客供贴纸） | U9: UPC贴纸翻4500098824+12/4-进口商贴纸 | V9: 12/6-SSCC贴纸 | X9: 日期码格式：ZURU INC(BVI) 标准格式 日期：按实际生产日期 Packaging Info: 9543: MA 加UPC贴纸， UPC贴纸跟翻单4500098824+进口商贴纸+SSCC贴纸。 Remark: Amazon FOB订单，出口Mexico，外箱最长边不能超过25" （超过了，case pack只能为1），不符合要求的大货，一律不接受。 1.空白外箱加印ZURU Logo+MADE IN CHINA+SSCC LABEL(客供贴纸），无shipping mark,日期使用ZURU 标准版本。SSCC Label显示的是客人自己的item#，SSCC Lab el 贴在外箱正面的正中间，贴一面即可，跟单订购，贴纸离外箱距必须至少3cm,每一张SSCC Label都是唯一且有不同流水及条码的，没有损耗，绝对不可贴错，否 则贴错或损坏一张会导致全部都错，千万要注意！ 2. 日期码使用ZURU标准版 3. 客户PO备注在remark处 6.9543: 2PCS AAA Batteries(Not Include) | Y9: Zoe Luo | Z9: 2.6514 | AA9: =I9*Z9 -> 63.6336 | AB9: 24 | AC9: =AB9-I9 -> 0 | AD9: ok | AE9: 9543D-S001-MTS | AF9: 已入 | AG9: 系统出单 | AH9: 88897-1.6 | AL9: =I9 -> 24 | AT9: =I9 -> 24 | BW9: 增加移印布标内容 | BZ9: =I9 -> 24 | CB9: =I9 -> 24 | CD9: =SUM(BX9:CA9) -> 24 | CE9: =I9-CD9 -> 0
A10: 45590 | B10: Amazon EU SARL, Ndl Deutschland | C10: 德国 | D10: 4500148999 | E10: 5WJDQBAA | F10: 4500148999-30 | G10: 9543D-S001 | H10: 仓鼠 | I10: 504 | J10: 0 | K10: 24 | L10: =I10/K10 -> 21 | M10: 45651 | N10: 45647 | P10: PASS | Q10: 1/4-1/8出 | R10: 空白外箱（加印带Zuru字样的最新logo，除了邮包盒直接做外箱的产品） + SSCC LABEL一张, 无箱唛’MADE IN CHINA 外箱只印一正一侧。 | U10: UPC+IT sorting labe翻4500120504+ZURU邮箱贴纸翻4500149035 | V10: 11/21收到客供外箱贴纸 | X10: 日期码格式：ZURU INC(BVI) 标准格式 日期：按实际生产日期 Packaging Info: Amazon DE 9543D 3.9543D: 9543D 24pcs/ctn, no inner, purple; MA 3L（9L warning）C版收缩膜+4张贴纸(1张UPC#，参考翻单PO#4500120504；1张IT环保标，参考翻单PO#4500120 504；1张ES回收标, 参考翻单PO#4500149035；1张ZURU邮箱，参考翻单PO#4500149035)+5L(9L warning)说明书； 5. ZURU 验货最迟不得晚于2024/12/26 Remark: 1.空白外箱（加印带Zuru字样的最新logo，除了邮包盒直接做外箱的产品） + SSCC LABEL一张, 无箱唛. (SSCC LABEL贴在外箱正面的正中间，贴一面即可,贴纸离外箱边距必须至少3.2CM),SSCC贴纸由工厂直接跟勤得采购或者工厂自行采购，每一张SSCC Label都是唯一 且有不同流水及条码，且需要检查条码是否能正常扫描，另外，此贴纸印刷不可出现模糊，溢出及粘胶不牢易脱落等现象，如工厂不按此要求导致贴纸有任何问题产 生的罚款将由工厂承担一切责任 。’MADE IN CHINA 外箱只印一正一侧。 2. 出往UK的产品+包装务必打上UKCA logo ，否则客人会退货且当地会有罚款。 3.订单必须经过ZURU QC验货并且通过后方可出货。 4.法国订单要求包装不使用矿物油，请按要求提供以下其中一份文件再出货 ，产品出到法国被相关部门抽检出现包装不符合此要求的，供应商需要为此承担责任， 故此请严格把关 。 -油墨物质""由1 ~ 7个芳香环组成的MOAH""的包装检测报告，要求限值≤1.0%; -包装材料清单，包括包装油墨或物质的信息 -油墨制造商的证书。 5 . 每一批次出货只能有一个生产日期，不可多个生产日期混在同一批次出货；且邮包盒上必须统一加上日期码； 6. 涉及到相关款式会有闪粉的或 者微塑料的，请统一默认出无闪粉或者不含微塑料 版本; 7 .邮包盒及外箱封箱必须是工字型封箱方式； 8 . 5 Surprise or Mini Brands涉及包装是2个及2个以上的球入PVC桶包装时，单个球上若有UPC#或者EAN#，请用白色贴纸覆盖住； | Y10: Zoe Chen | Z10: 2.5958 | AA10: =I10*Z10 -> 1308.2832 | AB10: 504 | AC10: =AB10-I10 -> 0 | AD10: ok | AE10: 9543D-S001-3L | AF10: 已入 | AG10: 系统出单 | AH10: 88946-1.8 | AO10: =I10 -> 504 | AT10: =I10 -> 504 | BW10: 增加移印布标内容 | BZ10: =I10 -> 504 | CB10: =I10 -> 504 | CD10: =SUM(BX10:CA10) -> 504 | CE10: =I10-CD10 -> 0
A11: 45609 | B11: Amazon ES | C11: 西班牙 | D11: 4500151280 | E11: 5KXG56ZT | F11: 4500151280-10 | G11: 9543B-S001 | H11: 仓鼠 | I11: 504 | J11: 0 | K11: 24 | L11: =I11/K11 -> 21 | M11: 45652 | N11: 45649 | P11: PASS | Q11: 1/5-1/9出 | R11: 空白外箱（加印带Zuru字样的最新logo，除了邮包盒直接做外箱的产品） + SSCC LABEL一张, 无箱唛。 | U11: 11/15收到UPC+IT 翻4500120504+ES回收标+ZURU邮箱贴纸 | V11: 11/29-外箱贴纸 | X11: 日期码格式：ZURU INC(BVI) 标准格式 日期：按实际生产日期 Tracking Code: Packaging Info: Amazon ES(9543B, 7150B) 1. 9543B：9543B 24pcs/ctn, no inner, pink; MA 3L（9L warning）C版收缩膜+4张贴纸(1张#UPC+1张IT sorting label，参考翻单PO#4500120504；1张ES回收标 ，参考翻单PO#4500151280；1张ZURU邮箱)+5L(9L warning)A说明书； 3. 最迟验货不得晚于2024/12/27; Remark: 1.空白外箱（加印带Zuru字样的最新logo，除了邮包盒直接做外箱的产品） + SSCC LABEL一张, 无箱唛。 (SSCC LABEL贴在外箱正面的正中间，贴一面即可,贴纸离外箱边距必须至少3.2CM), SSCC贴纸由工厂直接跟勤得采购或者工厂自行采购，每一张SSCC Label都是唯一 且有不同流水及条码，且需要检查条码是否能正常扫描，另外，此贴纸印刷不可出现模糊，溢出及粘胶不牢易脱落等现象，如工厂不按此要求导致贴纸有任何问题产 生的罚款将由工厂承担一切责任 。’MADE IN CHINA 外箱只印一正一侧。 2.出往UK的产品+包装务必打上UKCA logo ，否则客人会退货且当地会有罚款。 3.订单必须经过ZURU QC验货并且通过后方可出货。 4.法国订单要求包装不使用矿物油，请按要求提供以下其中一份文件再出货 ，产品出到法国被相关部门抽检出现包装不符合此要求的，供应商需要为此承担责任， 故此请严格把关。 -油墨物质""由1 ~ 7个芳香环组成的MOAH""的包装检测报告，要求限值≤1.0%； -包装材料清单，包括包装油墨或物质的信息； -油墨制造商的证书； 5.每一批次出货只能有一个生产日期，不可多个生产日期混在同一批次出货；且邮包盒上必须统一加上日期码； 6.涉及到相关款式会有闪粉的或者微塑料的，请统一默认出无闪粉或者不含微塑料版本； 7.邮包盒及外箱封箱必须是工字型封箱方式； 8.5 Surprise or Mini Brands涉及包装是2个及2个以上的球入PVC桶包装时，单个球上若有UPC#或者EAN#，请用白色贴纸覆盖住； 9.箱唛资料按照给定的标准去做即可，无需发回我方再行审批(新标准将另行通知); | Y11: Mandy Hu | Z11: 2.5958 | AA11: =I11*Z11 -> 1308.2832 | AB11: 504 | AC11: =AB11-I11 -> 0 | AD11: ok | AE11: 9543B-S001-3L | AF11: 已入 | AG11: 系统出单 | AH11: 88939-1.8 | AO11: =I11 -> 504 | AT11: =I11 -> 504 | BW11: 增加移印布标内容 | BY11: =I11 -> 504 | CB11: =I11 -> 504 | CD11: =SUM(BX11:CA11) -> 504 | CE11: =I11-CD11 -> 0
A12: 45609 | B12: AMAZON FR | C12: 法国 | D12: 4500151278 | E12: 59XSZYJX | F12: 4500151278-20 | G12: 9543B-S001 | H12: 仓鼠 | I12: 504 | J12: 0 | K12: 24 | L12: =I12/K12 -> 21 | M12: 45652 | N12: 45649 | P12: PASS | Q12: 1/5-1/9出 | R12: 空白外箱（加印带Zuru字样的最新logo，除了邮包盒直接做外箱的产品） + SSCC LABEL一张, 无箱唛。 | U12: UPC+IT翻4500120504 | V12: 12/5-外箱贴纸 | X12: 日期码格式：ZURU INC(BVI) 标准格式 日期：按实际生产日期 Packaging Info: Amazon FR(7150B, 9543B) 2. 9543B：9543B 24pcs/ctn, no inner, pink; MA 3L（9L warning）C版收缩膜+2张贴纸(含1张#UPC；1张IT sorting label)+5L(9L warning)A说明书；参考翻单P O#4500120504； 3. 最迟验货不得晚于2024/12/27; Remark: 1.空白外箱（加印带Zuru字样的最新logo，除了邮包盒直接做外箱的产品） + SSCC LABEL一张, 无箱唛。 (SSCC LABEL贴在外箱正面的正中间，贴一面即可,贴纸离外箱边距必须至少3.2CM), SSCC贴纸由工厂直接跟勤得采购或者工厂自行采购，每一张SSCC Label都是唯一 且有不同流水及条码，且需要检查条码是否能正常扫描，另外，此贴纸印刷不可出现模糊，溢出及粘胶不牢易脱落等现象，如工厂不按此要求导致贴纸有任何问题产 生的罚款将由工厂承担一切责任 。’MADE IN CHINA 外箱只印一正一侧。 2.出往UK的产品+包装务必打上UKCA logo ，否则客人会退货且当地会有罚款。 3.订单必须经过ZURU QC验货并且通过后方可出货。 4.法国订单要求包装不使用矿物油，请按要求提供以下其中一份文件再出货 ，产品出到法国被相关部门抽检出现包装不符合此要求的，供应商需要为此承担责任， 故此请严格把关。 -油墨物质""由1 ~ 7个芳香环组成的MOAH""的包装检测报告，要求限值≤1.0%； -包装材料清单，包括包装油墨或物质的信息； -油墨制造商的证书； 5.每一批次出货只能有一个生产日期，不可多个生产日期混在同一批次出货；且邮包盒上必须统一加上日期码； 6.涉及到相关款式会有闪粉的或者微塑料的，请统一默认出无闪粉或者不含微塑料版本； 7.邮包盒及外箱封箱必须是工字型封箱方式； 8.5 Surprise or Mini Brands涉及包装是2个及2个以上的球入PVC桶包装时，单个球上若有UPC#或者EAN#，请用白色贴纸覆盖住； 9.箱唛资料按照给定的标准去做即可，无需发回我方再行审批(新标准将另行通知); | Y12: Crystal Chen | Z12: 2.5958 | AA12: =I12*Z12 -> 1308.2832 | AB12: 504 | AC12: =AB12-I12 -> 0 | AD12: ok | AE12: 9543B-S001-3L | AF12: 已入 | AG12: 系统出单 | AH12: 88956-1.9 | AO12: =I12 -> 504 | AT12: =I12 -> 504 | BW12: 增加移印布标内容 | BY12: =I12 -> 504 | CB12: =I12 -> 504 | CD12: =SUM(BX12:CA12) -> 504 | CE12: =I12-CD12 -> 0
A13: 45608 | B13: Amazon CA (Vendor Center) | C13: 加拿大 | D13: 4500150978 | E13: 3NHSHWDA | F13: 4500150978-30 | G13: 9543B-S001 | H13: 仓鼠 | I13: 72 | J13: 0 | K13: 24 | L13: =I13/K13 -> 3 | M13: 45653 | N13: 45649 | P13: PASS | Q13: 1/1-1/7出 | R13: 11/12收到 | U13: UPC贴纸跟翻4500098824 | X13: 日期码格式：ZURU INC(BVI) 标准格式 日期：按实际生产日期 Packaging Info: 出口加拿大，包装需要至少2/3L UPC版，无硼版本 #9543: MA 3L UPC版本加UPC贴纸，UPC贴纸跟翻单4500098824。A:193052051776, B:193052051783, E:193052051806,; Remark: 1. Amazon FOB订单，出口CA。外箱最长边不能超过25" （超过了，case pack只能为1），不符合要求的大货，一律不接受。 2. 外箱正面印ZURU Logo + SSCC LABEL（客供贴纸)，侧面印item#（订单上显示的SKU#) + carton size(以工厂实际尺寸为准，单位: inch) + MADE IN CHINA， 日期使用ZURU 标准版本 SSCC Label 显示的是客人自己的item#，SSCC Label 贴在外箱正面的正中间，贴一面即可，跟单订购，贴纸离外箱距必须至少3cm，每一 张SSCC label 都是唯一且有不同流水及条码的，没有损耗，绝对不可贴错 ，否则贴错或损坏一张会导致全部都错，千万要注意: SSCC 贴纸务必要在正中间(可以覆 盖Logo <(>&<)> 箱唛)，否则会影响到仓库扫描识别。 3. 日期码使用ZURU标准版本。 4. 如果大货有要求入邮包盒，则对应的邮包盒上面要打上日期码。 5. 按照客户PO# 装柜/箱号顺序装柜，跟单会提前给到装柜计划。在大货生产/仓库存放时，请留意该装柜要求，以便装柜时不混乱（避免装错/装漏/找不到货号等 ）。 6. 出口加拿大，包装需要至少2/3L UPC版，无硼版本。 7.邮包盒上要印刷日期码 | Y13: Kelly/Mia | Z13: 2.6514 | AA13: =I13*Z13 -> 190.9008 | AB13: 72 | AC13: =AB13-I13 -> 0 | AD13: ok | AE13: 9543B-S001-3L | AF13: 已入 | AG13: 系统出单 | AH13: 88919-1.7 | AO13: =I13 -> 72 | AT13: =I13 -> 72 | BW13: 增加移印布标内容 | BY13: =I13 -> 72 | CB13: =I13 -> 72 | CD13: =SUM(BX13:CA13) -> 72 | CE13: =I13-CD13 -> 0
A14: 45608 | B14: Amazon CA (Vendor Center) | C14: 加拿大 | D14: 4500150978 | E14: 3A8P5CWW | F14: 4500150978-40 | G14: 9543E-S001 | H14: 仓鼠 | I14: 24 | J14: 0 | K14: 24 | L14: =I14/K14 -> 1 | M14: 45653 | N14: 45649 | P14: PASS | Q14: 1/1-1/7出 | R14: 11/12收到 | U14: UPC贴纸跟翻4500098824 | X14: 日期码格式：ZURU INC(BVI) 标准格式 日期：按实际生产日期 Packaging Info: 出口加拿大，包装需要至少2/3L UPC版，无硼版本 #9543: MA 3L UPC版本加UPC贴纸，UPC贴纸跟翻单4500098824。A:193052051776, B:193052051783, E:193052051806,; Remark: 1. Amazon FOB订单，出口CA。外箱最长边不能超过25" （超过了，case pack只能为1），不符合要求的大货，一律不接受。 2. 外箱正面印ZURU Logo + SSCC LABEL（客供贴纸)，侧面印item#（订单上显示的SKU#) + carton size(以工厂实际尺寸为准，单位: inch) + MADE IN CHINA， 日期使用ZURU 标准版本 SSCC Label 显示的是客人自己的item#，SSCC Label 贴在外箱正面的正中间，贴一面即可，跟单订购，贴纸离外箱距必须至少3cm，每一 张SSCC label 都是唯一且有不同流水及条码的，没有损耗，绝对不可贴错 ，否则贴错或损坏一张会导致全部都错，千万要注意: SSCC 贴纸务必要在正中间(可以覆 盖Logo <(>&<)> 箱唛)，否则会影响到仓库扫描识别。 3. 日期码使用ZURU标准版本。 4. 如果大货有要求入邮包盒，则对应的邮包盒上面要打上日期码。 5. 按照客户PO# 装柜/箱号顺序装柜，跟单会提前给到装柜计划。在大货生产/仓库存放时，请留意该装柜要求，以便装柜时不混乱（避免装错/装漏/找不到货号等 ）。 6. 出口加拿大，包装需要至少2/3L UPC版，无硼版本。 7.邮包盒上要印刷日期码 | Y14: Kelly/Mia | Z14: 2.6514 | AA14: =I14*Z14 -> 63.6336 | AB14: 24 | AC14: =AB14-I14 -> 0 | AD14: ok | AE14: 9543E-S001-3L | AF14: 已入 | AG14: 系统出单 | AH14: 88919-1.7 | AO14: =I14 -> 24 | AT14: =I14 -> 24 | BW14: 增加移印布标内容 | CA14: =I14 -> 24 | CB14: =I14 -> 24 | CD14: =SUM(BX14:CA14) -> 24 | CE14: =I14-CD14 -> 0
A15: 45608 | B15: Amazon CA (Vendor Center) | C15: 加拿大 | D15: 4500150978 | E15: 2IK4A3AH | F15: 4500150978-50 | G15: 9543A-S001 | H15: 仓鼠 | I15: 48 | J15: 0 | K15: 24 | L15: =I15/K15 -> 2 | M15: 45653 | N15: 45649 | P15: PASS | Q15: 1/1-1/7出 | R15: 11/12收到 | U15: UPC贴纸跟翻4500098824 | X15: 日期码格式：ZURU INC(BVI) 标准格式 日期：按实际生产日期 Packaging Info: 出口加拿大，包装需要至少2/3L UPC版，无硼版本 #9543: MA 3L UPC版本加UPC贴纸，UPC贴纸跟翻单4500098824。A:193052051776, B:193052051783, E:193052051806,; Remark: 1. Amazon FOB订单，出口CA。外箱最长边不能超过25" （超过了，case pack只能为1），不符合要求的大货，一律不接受。 2. 外箱正面印ZURU Logo + SSCC LABEL（客供贴纸)，侧面印item#（订单上显示的SKU#) + carton size(以工厂实际尺寸为准，单位: inch) + MADE IN CHINA， 日期使用ZURU 标准版本 SSCC Label 显示的是客人自己的item#，SSCC Label 贴在外箱正面的正中间，贴一面即可，跟单订购，贴纸离外箱距必须至少3cm，每一 张SSCC label 都是唯一且有不同流水及条码的，没有损耗，绝对不可贴错 ，否则贴错或损坏一张会导致全部都错，千万要注意: SSCC 贴纸务必要在正中间(可以覆 盖Logo <(>&<)> 箱唛)，否则会影响到仓库扫描识别。 3. 日期码使用ZURU标准版本。 4. 如果大货有要求入邮包盒，则对应的邮包盒上面要打上日期码。 5. 按照客户PO# 装柜/箱号顺序装柜，跟单会提前给到装柜计划。在大货生产/仓库存放时，请留意该装柜要求，以便装柜时不混乱（避免装错/装漏/找不到货号等 ）。 6. 出口加拿大，包装需要至少2/3L UPC版，无硼版本。 7.邮包盒上要印刷日期码 | Y15: Kelly/Mia | Z15: 2.5695 | AA15: =I15*Z15 -> 123.336 | AB15: 48 | AC15: =AB15-I15 -> 0 | AD15: ok | AE15: 9543A-S001-3L | AF15: 已入 | AG15: 系统出单 | AH15: 88919-1.7 | AO15: =I15 -> 48 | AT15: =I15 -> 48 | BW15: 增加移印布标内容 | BX15: =I15 -> 48 | CB15: =I15 -> 48 | CD15: =SUM(BX15:CA15) -> 48 | CE15: =I15-CD15 -> 0
A16: 45602 | B16: Dirk Rossmann GmbH | C16: 德国 | D16: 4500149853 | E16: 30241146A | F16: 4500149853-50 | G16: 9543-S001 | H16: 仓鼠 | I16: 1008 | J16: 0 | K16: 24 | L16: =I16/K16 -> 42 | M16: 45649 | N16: 45645 | O16: 12/25 第三方 | P16: PASS | Q16: 1/2出 | R16: 11/18收到 外箱需要是5层瓦楞纸，厚度在5-9mm。 | U16: EAN条码贴纸翻4500116318+德语callout贴纸翻4500122326+客版黑白WEEE声明说明书纸翻4500145491 | X16: 日期码格式：ZURU INC(BVI) 标准格式 日期：按实际生产日期 Packaging Info:9543: 最新MA 1L+多语收缩膜+EAN条码贴纸(翻单4500116318)+德语callout贴纸(翻单4500122326)+ 5L+9L说明书+客版黑白WEEE声明说明书纸(翻单#4500145491) Remark: 1. 出口欧洲，微塑料需符合法规，电池符合欧洲法规要求(如有) 2. 此客户要求：化学品无硼无香。 3. 外箱上下需加保护卡，以防开箱时产品被划破。（保护卡需要时整面） 4. 此单在出货前4周提供大货样品给Rossmann德国客人安排第三方验货。 请备额外物料。 5. 此单需要第三方验货，验货时间为完货后第二天，验货OK待客人放货后才能安排走货。 6. 所有包装材料都需要用PET材质。 7. 每箱需要放一包干燥剂（不能是silicon) 。品牌SUPER DRY，规格：10g/pc 。 8. 外箱需要是5层瓦楞纸，厚度在5-9mm。 9. 此单出德国，走整柜请知悉。 10.标准配比。 | Y16: Shirley Zhou | Z16: 2.5816 | AA16: =I16*Z16 -> 2602.2528 | AB16: 1008 | AC16: =AB16-I16 -> 0 | AD16: ok | AE16: 9543-S001 | AF16: 已入 | AG16: 系统出单 | AH16: 94159-1.23 | AL16: =I16 -> 1008 | AT16: =I16 -> 1008 | BW16: 增加移印布标内容 | BX16: =I16/4 -> 252 | BY16: =I16/4 -> 252 | BZ16: =I16/4 -> 252 | CA16: =I16/4 -> 252 | CB16: =I16 -> 1008 | CD16: =SUM(BX16:CA16) -> 1008 | CE16: =I16-CD16 -> 0
A17: 45604 | B17: Inventive Toys | C17: 俄罗斯联邦 | D17: 4500150797 | F17: 4500150797-20 | G17: 9543GQ1-S001 | H17: 仓鼠 | I17: 5016 | J17: 0 | K17: 22 | L17: =I17/K17 -> 228 | M17: 45649 | N17: 45645 | P17: PASS | Q17: 1/3出 | R17: 11/26收到 | U17: 12/3-进口商贴纸+EAN 条码贴纸 | W17: 外包装/外箱不要打ZURU标准日期码 | X17: 日期码格式：外包装/外箱不要打ZURU标准日期码 日期： Packaging Info: 注意 ：外包装 (指: 收缩膜/彩卡/铝箔袋/挂卡/PDQ) /外箱不要打ZURU标准日期码！胶件可以打日期码。 外包装（包括收缩膜/彩卡/PDQ）都不能含Instagram and facebook logo等社交logo; 1L MA 收缩膜+ 进口商贴纸； MA PDQ+ EAN 条码贴纸 ， MA 指南/说明书（如有） Remark: 标准配比 ； | Y17: Ann Zhang | Z17: 2.7397 | AA17: =I17*Z17 -> 13742.335 | AB17: =3168+1848 -> 5016 | AC17: =AB17-I17 -> 0 | AD17: ok | AE17: 9543GQ1-S001 | AF17: 已入 | AG17: 系统出单 | AH17: 94064-1.16 | AL17: =I17 -> 5016 | AT17: =I17 -> 5016 | AX17: =I17/11 -> 456 | BW17: 增加移印布标内容 | BX17: =I17/22*5 -> 1140 | BY17: =I17/22*6 -> 1368 | BZ17: =I17/22*6 -> 1368 | CA17: =I17/22*5 -> 1140 | CB17: =I17 -> 5016 | CC17: =I17/11 -> 456 | CD17: =SUM(BX17:CA17) -> 5016 | CE17: =I17-CD17 -> 0
A18: 45601 | B18: DD’S DISCOUNTS | C18: 美国 | D18: 4500150186 | E18: 70054043 | F18: 4500150186-10 | G18: 9543GQ1-S001 | H18: 仓鼠 | I18: 616 | J18: 0 | K18: 22 | L18: =I18/K18 -> 28 | M18: 45653 | N18: 45649 | P18: PASS | Q18: 1/7出 | R18: ROSS指定箱唛格式 | U18: 无 | V18: 11/20-客供价格贴纸 | X18: 日期码格式：ZURU INC(BVI) 标准格式 日期：按实际生产日期 Packaging Info: 1.ZURU MA UPC 现有版本包装 + 客供价格贴纸，出口美国 , 优先使用MA 1L 最新版本 。 Remark: 1.ZURU MA UPC 现有版本包装 + 客供价格贴纸，出口美国 , 优先使用MA 1L 最新版本 。 2.价格贴纸位于包装正面右下角，不挡住重要信息即可，可适当调整 ，价格贴纸由跟单提供。 3.标准日期码格式，产品和包装必须有日期码 。 4.同个产品同个货期不可出现不同的包装。 5. 跟单提供ROSS通用的箱唛模版，工厂按实际45 PO上客户PO/Item号/装箱数 提供箱唛排版来确认。 | Y18: Taylor Liao | Z18: 2.8179 | AA18: =I18*Z18 -> 1735.8264 | AB18: 616 | AC18: =AB18-I18 -> 0 | AD18: ok | AE18: 9543GQ1-S001 | AF18: 已入 | AG18: 系统出单 | AH18: 88920-1.7 | AL18: =I18 -> 616 | AT18: =I18 -> 616 | AX18: =I18/11 -> 56 | BW18: 增加移印布标内容 | BX18: =I18/22*5 -> 140 | BY18: =I18/22*6 -> 168 | BZ18: =I18/22*6 -> 168 | CA18: =I18/22*5 -> 140 | CB18: =I18 -> 616 | CC18: =I18/11 -> 56 | CD18: =SUM(BX18:CA18) -> 616 | CE18: =I18-CD18 -> 0
A19: 45611 | B19: ToyChamp Belgium nv | C19: 比利时 | D19: 4500151401 | E19: 2024101316 | F19: 4500151401-40 | G19: 9543GQ1-S001 | H19: 仓鼠 | I19: 1584 | J19: 0 | K19: 22 | L19: =I19/K19 -> 72 | M19: 45657 | N19: 45653 | P19: PASS | Q19: 1/19出 | R19: 11/21收到 | U19: 11/21收到EAN条码贴纸 | X19: 日期码格式：ZURU INC(BVI) 标准格式 日期：按实际生产日期 Packaging Info: 9543GQ1: MA C版 3L（9L warning）收缩膜+1张EAN条码贴纸，MA 5L说明书（9L warning），MA B版 3L PDQ Remark: 1.外箱需要印条码，请确保条码可以清晰扫描，且条码内容正确 2.出欧洲，微塑料需合规（如item本身不含微塑料,则忽略此要求） 3.STD配比 | Y19: Amber Zhang | Z19: 2.8038 | AA19: =I19*Z19 -> 4441.2192 | AB19: 1584 | AC19: =AB19-I19 -> 0 | AD19: ok | AE19: 9543GQ1-S001-3L | AF19: 已入 | AG19: 系统出单 | AH19: 94107-1.18 | AO19: =I19 -> 1584 | AT19: =I19 -> 1584 | BA19: =I19/11 -> 144 | BW19: 增加移印布标内容 | BX19: =I19/22*5 -> 360 | BY19: =I19/22*6 -> 432 | BZ19: =I19/22*6 -> 432 | CA19: =I19/22*5 -> 360 | CB19: =I19 -> 1584 | CC19: =I19/11 -> 144 | CD19: =SUM(BX19:CA19) -> 1584 | CE19: =I19-CD19 -> 0
A20: 45616 | B20: N.V. DREAMLAND | C20: 比利时 | D20: 4500151832 | E20: 4500054541 | F20: 4500151832-10 | G20: 9543GQ1-S001 | H20: 仓鼠 | I20: 1584 | J20: 0 | K20: 22 | L20: =I20/K20 -> 72 | M20: 45657 | N20: 45653 | P20: PASS | Q20: 1/6出 | R20: 11/20收到 | U20: 11/20收到EAN条码贴纸 | X20: 日期码格式：ZURU INC(BVI) 标准格式 日期：按实际生产日期 Packaging Info: 9543GQ1: MA C版 3L（9L warning）收缩膜+1张EAN条码贴纸，MA 5L说明书（9L warning），MA B版 3L PDQ Remark: 1.外箱需要印条码，请确保条码可以清晰扫描，且条码内容正确 2.出欧洲，微塑料需合规（如item本身不含微塑料,则忽略此要求） 3.STD配比 4. 所有产品符合REACH申明 | Y20: Amber Zhang | Z20: 2.8038 | AA20: =I20*Z20 -> 4441.2192 | AB20: 1584 | AC20: =AB20-I20 -> 0 | AD20: ok | AE20: 9543GQ1-S001-3L | AF20: 已入 | AG20: 系统出单 | AH20: 88874-1.4 | AO20: =I20 -> 1584 | AT20: =I20 -> 1584 | BA20: =I20/11 -> 144 | BW20: 增加移印布标内容 | BX20: =I20/22*5 -> 360 | BY20: =I20/22*6 -> 432 | BZ20: =I20/22*6 -> 432 | CA20: =I20/22*5 -> 360 | CB20: =I20 -> 1584 | CC20: =I20/11 -> 144 | CD20: =SUM(BX20:CA20) -> 1584 | CE20: =I20-CD20 -> 0
A21: 45624 | B21: «Market Group» LLC | C21: 俄罗斯联邦 | D21: 4500152880 | F21: 4500152880-10 | G21: 9543GQ1-S002 | H21: 仓鼠 | I21: 1980 | J21: 0 | K21: 11 | L21: =I21/K21 -> 180 | M21: 45657 | N21: 45653 | P21: PASS | Q21: 1/2出 | R21: 11/29收到 | U21: 12/6-进口商贴纸+ EAN条码贴纸 | X21: 日期码格式：ZURU INC(BVI) 标准格式 日期：按实际生产日期 Packaging Info: 1. 9543GQ1 : 1L MA 收缩膜 or 彩卡 + 进口商贴纸+ EAN条码贴纸，MA 指南 /说明书/PDQ 如有; 2. 货期不能延后，客人有罚金。 3. 需要安排3套大货样，请多备料。 Remark: 标准配比 | Y21: Ann Zhang | Z21: 2.7662 | AA21: =I21*Z21 -> 5477.076 | AB21: 1980 | AC21: =AB21-I21 -> 0 | AD21: ok | AE21: 9543GQ1-S002 | AF21: 已入 | AG21: 系统出单 | AH21: 88935-1.8 | AL21: =I21 -> 1980 | AT21: =I21 -> 1980 | AX21: =I21/11 -> 180 | BW21: 增加移印布标内容 | BX21: =I21/22*5 -> 450 | BY21: =I21/22*6 -> 540 | BZ21: =I21/22*6 -> 540 | CA21: =I21/22*5 -> 450 | CB21: =I21 -> 1980 | CC21: =I21/11 -> 180 | CD21: =SUM(BX21:CA21) -> 1980 | CE21: =I21-CD21 -> 0
A22: 45624 | B22: BIG W | C22: 澳大利亚 | D22: 4500152763 | E22: CUS PO#47779210 SYD | F22: 4500152763-10 | G22: 9543GQ1-S001 | H22: 仓鼠 | I22: 506 | J22: 0 | K22: 22 | L22: =I22/K22 -> 23 | M22: 45657 | N22: 45653 | P22: PASS | Q22: 1/3出 | R22: 11/28收到 | U22: 进口商贴纸翻4500106537 | X22: 日期码格式：ZURU INC(BVI) 标准格式 日期：按实际生产日期 Packaging Info: 1. 包装 9543GQ1：英文MA包装 (UPC版本，首选1L，无1L可用多L含英语)+1张进口商贴纸，贴纸翻单4500106537 2. 产品和包装上的日期码一致，请按要求在包装上打日期码（进口商贴纸不覆盖日期码） 3. 使用ZURU标准日期码 Remark: 1. 共出4港口(SYD, BNE, MEL, FRE), 不同港口数量信息请见订单行项目，并请参考箱唛资料，港口不同，箱唛资料也不同； 2. 箱唛不可出现任何手写内容（箱数除外），重量与实际一致且不可手写; 3. 此单出澳大利亚，请按澳洲标准生产并满足当地法规要求; 4. 出无闪粉版本，需符合欧洲微塑料法规 | Y22: Christine Liao | Z22: 2.8789 | AA22: =I22*Z22 -> 1456.7234 | AB22: 506 | AC22: =AB22-I22 -> 0 | AD22: ok | AE22: 9543GQ1-S001 | AF22: 已入 | AG22: 系统出单 | AH22: 88832-1.2 | AL22: =I22 -> 506 | AT22: =I22 -> 506 | AX22: =I22/11 -> 46 | BW22: 增加移印布标内容 | BX22: =I22/22*5 -> 115 | BY22: =I22/22*6 -> 138 | BZ22: =I22/22*6 -> 138 | CA22: =I22/22*5 -> 115 | CB22: =I22 -> 506 | CC22: =I22/11 -> 46 | CD22: =SUM(BX22:CA22) -> 506 | CE22: =I22-CD22 -> 0
A23: 45624 | B23: BIG W | C23: 澳大利亚 | D23: 4500152763 | E23: CUS PO#47779211 BNE | F23: 4500152763-30 | G23: 9543GQ1-S001 | H23: 仓鼠 | I23: 440 | J23: 0 | K23: 22 | L23: =I23/K23 -> 20 | M23: 45657 | N23: 45653 | P23: PASS | Q23: 1/4出 | R23: 11/28收到 | U23: 进口商贴纸翻4500106537 | X23: 日期码格式：ZURU INC(BVI) 标准格式 日期：按实际生产日期 Packaging Info: 1. 包装 9543GQ1：英文MA包装 (UPC版本，首选1L，无1L可用多L含英语)+1张进口商贴纸，贴纸翻单4500106537 2. 产品和包装上的日期码一致，请按要求在包装上打日期码（进口商贴纸不覆盖日期码） 3. 使用ZURU标准日期码 Remark: 1. 共出4港口(SYD, BNE, MEL, FRE), 不同港口数量信息请见订单行项目，并请参考箱唛资料，港口不同，箱唛资料也不同； 2. 箱唛不可出现任何手写内容（箱数除外），重量与实际一致且不可手写; 3. 此单出澳大利亚，请按澳洲标准生产并满足当地法规要求; 4. 出无闪粉版本，需符合欧洲微塑料法规 | Y23: Christine Liao | Z23: 2.8789 | AA23: =I23*Z23 -> 1266.716 | AB23: 440 | AC23: =AB23-I23 -> 0 | AD23: ok | AE23: 9543GQ1-S001 | AF23: 已入 | AG23: 系统出单 | AH23: 88853-1.3 | AL23: =I23 -> 440 | AT23: =I23 -> 440 | AX23: =I23/11 -> 40 | BW23: 增加移印布标内容 | BX23: =I23/22*5 -> 100 | BY23: =I23/22*6 -> 120 | BZ23: =I23/22*6 -> 120 | CA23: =I23/22*5 -> 100 | CB23: =I23 -> 440 | CC23: =I23/11 -> 40 | CD23: =SUM(BX23:CA23) -> 440 | CE23: =I23-CD23 -> 0
A24: 45624 | B24: BIG W | C24: 澳大利亚 | D24: 4500152763 | E24: CUS PO#47779212 MEL | F24: 4500152763-50 | G24: 9543GQ1-S001 | H24: 仓鼠 | I24: 352 | J24: 0 | K24: 22 | L24: =I24/K24 -> 16 | M24: 45657 | N24: 45653 | P24: PASS | Q24: 1/8出 | R24: 11/28收到 | U24: 进口商贴纸翻4500106537 | X24: 日期码格式：ZURU INC(BVI) 标准格式 日期：按实际生产日期 Packaging Info: 1. 包装 9543GQ1：英文MA包装 (UPC版本，首选1L，无1L可用多L含英语)+1张进口商贴纸，贴纸翻单4500106537 2. 产品和包装上的日期码一致，请按要求在包装上打日期码（进口商贴纸不覆盖日期码） 3. 使用ZURU标准日期码 Remark: 1. 共出4港口(SYD, BNE, MEL, FRE), 不同港口数量信息请见订单行项目，并请参考箱唛资料，港口不同，箱唛资料也不同； 2. 箱唛不可出现任何手写内容（箱数除外），重量与实际一致且不可手写; 3. 此单出澳大利亚，请按澳洲标准生产并满足当地法规要求; 4. 出无闪粉版本，需符合欧洲微塑料法规 | Y24: Christine Liao | Z24: 2.8789 | AA24: =I24*Z24 -> 1013.3728 | AB24: 352 | AC24: =AB24-I24 -> 0 | AD24: ok | AE24: 9543GQ1-S001 | AF24: 已入 | AG24: 系统出单 | AH24: 88887-1.6 | AL24: =I24 -> 352 | AT24: =I24 -> 352 | AX24: =I24/11 -> 32 | BW24: 增加移印布标内容 | BX24: =I24/22*5 -> 80 | BY24: =I24/22*6 -> 96 | BZ24: =I24/22*6 -> 96 | CA24: =I24/22*5 -> 80 | CB24: =I24 -> 352 | CC24: =I24/11 -> 32 | CD24: =SUM(BX24:CA24) -> 352 | CE24: =I24-CD24 -> 0
A25: 45624 | B25: BIG W | C25: 澳大利亚 | D25: 4500152763 | E25: CUS PO#47779213 FRE | F25: 4500152763-70 | G25: 9543GQ1-S001 | H25: 仓鼠 | I25: 220 | J25: 0 | K25: 22 | L25: =I25/K25 -> 10 | M25: 45657 | N25: 45653 | P25: PASS | Q25: 1/4出 | R25: 11/28收到 | U25: 进口商贴纸翻4500106537 | X25: 日期码格式：ZURU INC(BVI) 标准格式 日期：按实际生产日期 Packaging Info: 1. 包装 9543GQ1：英文MA包装 (UPC版本，首选1L，无1L可用多L含英语)+1张进口商贴纸，贴纸翻单4500106537 2. 产品和包装上的日期码一致，请按要求在包装上打日期码（进口商贴纸不覆盖日期码） 3. 使用ZURU标准日期码 Remark: 1. 共出4港口(SYD, BNE, MEL, FRE), 不同港口数量信息请见订单行项目，并请参考箱唛资料，港口不同，箱唛资料也不同； 2. 箱唛不可出现任何手写内容（箱数除外），重量与实际一致且不可手写; 3. 此单出澳大利亚，请按澳洲标准生产并满足当地法规要求; 4. 出无闪粉版本，需符合欧洲微塑料法规 | Y25: Christine Liao | Z25: 2.8789 | AA25: =I25*Z25 -> 633.358 | AB25: 220 | AC25: =AB25-I25 -> 0 | AD25: ok | AE25: 9543GQ1-S001 | AF25: 已入 | AG25: 系统出单 | AH25: 88867-1.4 | AL25: =I25 -> 220 | AT25: =I25 -> 220 | AX25: =I25/11 -> 20 | BW25: 增加移印布标内容 | BX25: =I25/22*5 -> 50 | BY25: =I25/22*6 -> 60 | BZ25: =I25/22*6 -> 60 | CA25: =I25/22*5 -> 50 | CB25: =I25 -> 220 | CC25: =I25/11 -> 20 | CD25: =SUM(BX25:CA25) -> 220 | CE25: =I25-CD25 -> 0
A26: 45615 | B26: THE WAREHOUSE LIMITED | C26: 新西兰 | D26: 4500151669 | E26: 28682677 | F26: 4500151669-10 | G26: 9543GQ1-S001 | H26: 仓鼠 | I26: 1144 | J26: 0 | K26: 22 | L26: =I26/K26 -> 52 | M26: 45660 | N26: 45656 | P26: PASS | Q26: 1/14出 | R26: 11/19收到 | U26: 无 | X26: 日期码格式：ZURU INC(BVI) 标准格式 日期：按实际生产日期 Packaging Info: MA UPC 英语包装（优先1L英语版本，或者3L/5L含英语都可） 此客人不接受易掉落或者剥落或者可直接触碰的闪粉，可降解也不行，但可以接受符合欧洲微塑料标准的珠光粉或者闪片。 Remark: 此单出AKL 9543GQ1: bule/purple/pink/orange =5:6:6:5; 2PCS AAA Batteries(Not Include) | Y26: Abby Liang | Z26: 2.8038 | AA26: =I26*Z26 -> 3207.5472 | AB26: 1144 | AC26: =AB26-I26 -> 0 | AD26: 无 | AE26: 9543GQ1-S001 | AF26: 已入 | AG26: 系统出单 | AH26: 94011-1.13 | AL26: =I26 -> 1144 | AT26: =I26 -> 1144 | AX26: =I26/11 -> 104 | BW26: 增加移印布标内容 | BX26: =I26/22*5 -> 260 | BY26: =I26/22*6 -> 312 | BZ26: =I26/22*6 -> 312 | CA26: =I26/22*5 -> 260 | CB26: =I26 -> 1144 | CC26: =I26/11 -> 104 | CD26: =SUM(BX26:CA26) -> 1144 | CE26: =I26-CD26 -> 0
A27: 45618 | B27: CRG | C27: 哥斯达黎加 | D27: 4500152087 | E27: ZU01-25 | F27: 4500152087-80 | G27: 9543GQ1-S001 | H27: 仓鼠 | I27: 528 | J27: 0 | K27: 22 | L27: =I27/K27 -> 24 | M27: 45660 | N27: 45656 | P27: PASS | Q27: 1/8出 | R27: 11/25收到 | U27: 进口商贴纸翻4500098650 | X27: 日期码格式：ZURU INC(BVI) 标准格式 日期：按实际生产日期 Packaging Info: 9543GQ1:MA 1L包装+MA 5L说明书+进口商贴纸+箱唛，进口商贴纸翻单PO4500098650 Remark: | Y27: Ava Liang | Z27: 2.8179 | AA27: =I27*Z27 -> 1487.8512 | AB27: 528 | AC27: =AB27-I27 -> 0 | AD27: OK | AE27: 9543GQ1-S001 | AF27: 已入 | AG27: 系统出单 | AH27: 88961-1.9 | AL27: =I27 -> 528 | AT27: =I27 -> 528 | AX27: =I27/11 -> 48 | BW27: 增加移印布标内容 | BX27: =I27/22*5 -> 120 | BY27: =I27/22*6 -> 144 | BZ27: =I27/22*6 -> 144 | CA27: =I27/22*5 -> 120 | CB27: =I27 -> 528 | CC27: =I27/11 -> 48 | CD27: =SUM(BX27:CA27) -> 528 | CE27: =I27-CD27 -> 0
A28: 45615 | B28: THE WAREHOUSE LIMITED | C28: 新西兰 | D28: 4500151670 | E28: 28682679 | F28: 4500151670-10 | G28: 9543GQ1-S001 | H28: 仓鼠 | I28: 374 | J28: 0 | K28: 22 | L28: =I28/K28 -> 17 | M28: 45660 | N28: 45656 | P28: PASS | Q28: 1/14出 | R28: 11/19收到 | U28: 无 | X28: 日期码格式：ZURU INC(BVI) 标准格式 日期：按实际生产日期 Packaging Info: MA UPC 英语包装（优先1L英语版本，或者3L/5L含英语都可） 此客人不接受易掉落或者剥落或者可直接触碰的闪粉，可降解也不行，但可以接受符合欧洲微塑料标准的珠光粉或者闪片。 Remark: 此单出LYT 9543GQ1: bule/purple/pink/orange =5:6:6:5; 2PCS AAA Batteries(Not Include) | Y28: Abby Liang | Z28: 2.8179 | AA28: =I28*Z28 -> 1053.8946 | AB28: 374 | AC28: =AB28-I28 -> 0 | AD28: 无 | AE28: 9543GQ1-S001 | AF28: 已入 | AG28: 系统出单 | AH28: 94012-1.13 | AL28: =I28 -> 374 | AT28: =I28 -> 374 | AX28: =I28/11 -> 34 | BW28: 增加移印布标内容 | BX28: =I28/22*5 -> 85 | BY28: =I28/22*6 -> 102 | BZ28: =I28/22*6 -> 102 | CA28: =I28/22*5 -> 85 | CB28: =I28 -> 374 | CC28: =I28/11 -> 34 | CD28: =SUM(BX28:CA28) -> 374 | CE28: =I28-CD28 -> 0
A29: 45625 | B29: FREDMEYER INC | C29: 美国 | D29: 4500152951 | E29: 37333959 | F29: 4500152951-10 | G29: 9543GQ1-S002 | H29: 仓鼠 | I29: 5500 | J29: 0 | K29: 11 | L29: =I29/K29 -> 500 | M29: 45657 | N29: 45653 | P29: PASS | R29: 11/29收到 | U29: 无 | X29: 日期码格式：ZURU INC(BVI) 标准格式 日期：按实际生产日期 Packaging Info: 1、包装方式： MA UPC优先1L最新版，出口美国 Remark: 2、无第三方测试验货要求。 3、纸箱4面印ZURU LOGO + 箱唛。 4、日期码请按ZURU标准版执行即可。 5、ZURU QC验货 6、REMARK: 2pcs *AAA battery not Includedd; Integral single ratio=bule/purple/pink/orange =5:6:6:5; IF Kroger/Fredmeyer need new GTIN:60193052050320 | Y29: Vicky Wu | Z29: 2.7699 | AA29: =I29*Z29 -> 15234.45 | AB29: 5500 | AC29: =AB29-I29 -> 0 | AD29: 无 | AE29: 9543GQ1-S002 | AF29: 已入 | AG29: 系统出单 | AH29: 88886-1.6 | AL29: =I29 -> 5500 | AT29: =I29 -> 5500 | AX29: =I29/11 -> 500 | BW29: 增加移印布标内容 | BX29: =I29/22*5 -> 1250 | BY29: =I29/22*6 -> 1500 | BZ29: =I29/22*6 -> 1500 | CA29: =I29/22*5 -> 1250 | CB29: =I29 -> 5500 | CC29: =I29/11 -> 500 | CD29: =SUM(BX29:CA29) -> 5500 | CE29: =I29-CD29 -> 0
A30: 45621 | B30: ATLAS AMBASSADOR | C30: 摩洛哥 | D30: 4500152205 | F30: 4500152205-10 | G30: 9543GQ1-S001 | H30: 仓鼠 | I30: 506 | J30: 0 | K30: 22 | L30: =I30/K30 -> 23 | M30: 45659 | N30: 45656 | P30: PASS | Q30: 1/15出 | R30: 11/27收到 | U30: 12/11-进口商贴纸+说明书贴纸 | X30: 日期码格式：ZURU INC(BVI) 标准格式 日期：按实际生产日期 Packaging Info: 1.9543GQ1:1L MA UPC收缩膜+进口商贴纸;MA说明书;MA PDQ 2.此客户需要进行COC认证，装柜前在主拼工厂会有第三方验货，每款item需备2pcs 验货备品。 Remark: 标准产品标准配比 | Y30: Lena Huang | Z30: 2.8179 | AA30: =I30*Z30 -> 1425.8574 | AB30: 506 | AC30: =AB30-I30 -> 0 | AD30: ok | AE30: 9543GQ1-S001 | AF30: 已入 | AG30: 系统出单 | AH30: 94106-1.18 | AL30: =I30 -> 506 | AT30: =I30 -> 506 | AX30: =I30/11 -> 46 | BW30: 增加移印布标内容 | BX30: =I30/22*5 -> 115 | BY30: =I30/22*6 -> 138 | BZ30: =I30/22*6 -> 138 | CA30: =I30/22*5 -> 115 | CB30: =I30 -> 506 | CC30: =I30/11 -> 46 | CD30: =SUM(BX30:CA30) -> 506 | CE30: =I30-CD30 -> 0
A31: 45573 | B31: Ansaldo Chile | C31: 智利 | D31: 4500146540 | E31: 2024-HKC0026 | F31: 4500146540-30 | G31: 9543GQ1-S001 | H31: 仓鼠 | I31: 946 | J31: 0 | K31: 22 | L31: =I31/K31 -> 43 | M31: 45659 | N31: 45656 | P31: PASS | Q31: 1/10出 | R31: 10/15收到 | U31: 进口商贴纸翻450014636 | X31: 日期码格式：ZURU INC(BVI) 标准格式 日期：按实际生产日期 Packaging Info: 9543GQ1:MA 3L UPC包装+进口商贴纸+箱唛,进口商贴纸翻单PO4500146361 Remark: | Y31: Ava Liang | Z31: 2.8179 | AA31: =I31*Z31 -> 2665.7334 | AB31: 946 | AC31: =AB31-I31 -> 0 | AD31: ok | AE31: 9543GQ1-S001-3L | AF31: 已入 | AG31: 系统出单 | AH31: 88980-1.10 | AO31: =I31 -> 946 | AT31: =I31 -> 946 | BA31: =I31/11 -> 86 | BW31: 增加移印布标内容 | BX31: =I31/22*5 -> 215 | BY31: =I31/22*6 -> 258 | BZ31: =I31/22*6 -> 258 | CA31: =I31/22*5 -> 215 | CB31: =I31 -> 946 | CC31: =I31/11 -> 86 | CD31: =SUM(BX31:CA31) -> 946 | CE31: =I31-CD31 -> 0
A32: 45615 | B32: Wonderland Toys Inc DBA The Zoofy G | C32: 美国 | D32: 4500151635 | E32: 4357 | F32: 4500151635-10 | G32: 9543GQ1-S002 | H32: 仓鼠 | I32: 3718 | J32: 0 | K32: 11 | L32: =I32/K32 -> 338 | M32: 45665 | N32: 45661 | P32: PASS | Q32: 1/20出 | R32: 11/27收到 | U32: 11/27-价格贴纸+要UCC贴纸 | X32: 日期码格式：ZURU INC(BVI) 标准格式 日期：按实际生产日期 Packaging Info: 1. 出口美国，MA UPC 版本包装，优先1L。 #9543GQ1: PRICER TICK-10.99; Shipped without batteries; operated by 2PCS AAA batteries; 2. 产品需要价格贴纸， 贴纸资料后面提供。 3. 外箱需要UCC贴纸。贴纸资料后面提供。 Remark: 4. Zuru QC 验货即可。 | Y32: Abby Mai, Lluviazeng | Z32: 2.7552 | AA32: =I32*Z32 -> 10243.834 | AB32: 3718 | AC32: =AB32-I32 -> 0 | AD32: ok | AE32: 9543GQ1-S002 | AF32: 已入 | AG32: 系统出单 | AH32: 94108-1.18 | AL32: =I32 -> 3718 | AT32: =I32 -> 3718 | AX32: =I32/11 -> 338 | BW32: 增加移印布标内容 | BX32: =I32/22*5 -> 845 | BY32: =I32/22*6 -> 1014 | BZ32: =I32/22*6 -> 1014 | CA32: =I32/22*5 -> 845 | CB32: =I32 -> 3718 | CC32: =I32/11 -> 338 | CD32: =SUM(BX32:CA32) -> 3718 | CE32: =I32-CD32 -> 0
A33: 45631 | B33: Ambiental Paraguay | C33: 巴拉圭 | D33: 4500153347 | F33: 4500153347-50 | G33: 9543GQ1-S001 | H33: 仓鼠 | I33: 968 | J33: 0 | K33: 22 | L33: =I33/K33 -> 44 | M33: 45667 | N33: 45663 | P33: PASS | Q33: 1/11出 | R33: 12/5收到 | U33: 12/5-进口商贴纸 | X33: 日期码格式：ZURU INC(BVI) 标准格式 日期：按实际生产日期 Packaging Info: 9543GQ1:MA 3L UPC包装+进口商贴纸+箱唛，进口商贴纸贴于位置"B" | Y33: Ava Liang | Z33: 2.8179 | AA33: =I33*Z33 -> 2727.7272 | AB33: 968 | AC33: =AB33-I33 -> 0 | AD33: ok | AE33: 9543GQ1-S001-3L | AF33: 已入 | AG33: 系统出单 | AH33: 94049-1.15 | AO33: =I33 -> 968 | AT33: =I33 -> 968 | BA33: =I33/11 -> 88 | BW33: 增加移印布标内容 | BX33: =I33/22*5 -> 220 | BY33: =I33/22*6 -> 264 | BZ33: =I33/22*6 -> 264 | CA33: =I33/22*5 -> 220 | CB33: =I33 -> 968 | CC33: =I33/11 -> 88 | CD33: =SUM(BX33:CA33) -> 968 | CE33: =I33-CD33 -> 0
A34: 45603 | B34: DD’S DISCOUNTS | C34: 美国 | D34: 4500150314 | E34: 70054056 | F34: 4500150314-10 | G34: 9543GQ1-S001 | H34: 仓鼠 | I34: 616 | J34: 0 | K34: 22 | L34: =I34/K34 -> 28 | M34: 45670 | N34: 45666 | P34: PASS | R34: ROSS指定箱唛格式 | U34: 无 | V34: 12/2-客供价格贴纸 | X34: 日期码格式： 标准格式 日期：按实际生产日期 Packaging Info: 1.ZURU MA UPC 现有版本包装 + 客供价格贴纸，出口美国 , 优先使用MA 1L 最新版本 。 Remark: 1.ZURU MA UPC 现有版本包装 + 客供价格贴纸，出口美国 , 优先使用MA 1L 最新版本 。 2.价格贴纸位于包装正面右下角，不挡住重要信息即可，可适当调整 ，价格贴纸由跟单提供。 3.标准日期码格式，产品和包装必须有日期码 。 4.同个产品同个货期不可出现不同的包装。 5. 跟单提供ROSS通用的箱唛模版，工厂按实际45 PO上客户PO/Item号/装箱数 提供箱唛排版来确认 | Y34: Taylor Liao | Z34: 2.8179 | AA34: =I34*Z34 -> 1735.8264 | AB34: 616 | AC34: =AB34-I34 -> 0 | AD34: ok | AE34: 9543GQ1-S001 | AF34: 已入 | AG34: 系统出单 | AH34: 94127-1.21 | AL34: =I34 -> 616 | AT34: =I34 -> 616 | AX34: =I34/11 -> 56 | BW34: 增加移印布标内容 | BX34: =I34/22*5 -> 140 | BY34: =I34/22*6 -> 168 | BZ34: =I34/22*6 -> 168 | CA34: =I34/22*5 -> 140 | CB34: =I34 -> 616 | CC34: =I34/11 -> 56 | CD34: =SUM(BX34:CA34) -> 616 | CE34: =I34-CD34 -> 0
A35: 45623 | B35: Amazon CA (Vendor Center) | C35: 加拿大 | D35: 4500152544 | E35: 6QVOH9XX | F35: 4500152544-70 | G35: 9543A-S001 | H35: 仓鼠 | I35: 24 | J35: 0 | K35: 24 | L35: =I35/K35 -> 1 | M35: 45670 | N35: 45666 | P35: PASS | Q35: 1/16-1/21出 | R35: 11/27收到 | U35: UPC贴纸跟翻4500098824 | V35: 12/20-客供外箱贴纸 | X35: 日期码格式：ZURU INC(BVI) 标准格式 日期：按实际生产日期 Packaging Info: 出口加拿大，包装需要至少2/3L UPC版，无硼版本。 #9543: MA 3L UPC版本。A:193052051776, B:193052051783, E:193052051806,; Remark: 1. Amazon FOB订单，出口CA。外箱最长边不能超过25" （超过了，case pack只能为1），不符合要求的大货，一律不接受。 2. 外箱正面印ZURU Logo + SSCC LABEL（客供贴纸)，侧面印item#（订单上显示的SKU#) + carton size(以工厂实际尺寸为准，单位: inch) + MADE IN CHINA， 日期使用ZURU 标准版本 SSCC Label 显示的是客人自己的item#，SSCC Label 贴在外箱正面的正中间，贴一面即可，跟单订购，贴纸离外箱距必须至少3cm，每一 张SSCC label 都是唯一且有不同流水及条码的，没有损耗，绝对不可贴错 ，否则贴错或损坏一张会导致全部都错，千万要注意: SSCC 贴纸务必要在正中间(可以覆 盖Logo <(>&<)> 箱唛)，否则会影响到仓库扫描识别。 3. 日期码使用ZURU标准版本。 4. 如果大货有要求入邮包盒，则对应的邮包盒上面要打上日期码。 5. 按照客户PO# 装柜/箱号顺序装柜，跟单会提前给到装柜计划。在大货生产/仓库存放时，请留意该装柜要求，以便装柜时不混乱（避免装错/装漏/找不到货号等 ）。 6. 出口加拿大，包装需要至少2/3L UPC版，无硼版本。 7.邮包盒上要印刷日期码 | Y35: Kelly/Mia | Z35: 2.5695 | AA35: =I35*Z35 -> 61.668 | AB35: 24 | AC35: =AB35-I35 -> 0 | AD35: ok | AE35: 9543A-S001-3L | AF35: 已入 | AG35: 系统出单 | AH35: 94134-1.21 | AO35: =I35 -> 24 | AT35: =I35 -> 24 | BW35: 增加移印布标内容 | BX35: =I35 -> 24 | CB35: =I35 -> 24 | CD35: =SUM(BX35:CA35) -> 24 | CE35: =I35-CD35 -> 0
A36: 45623 | B36: Amazon CA (Vendor Center) | C36: 加拿大 | D36: 4500152544 | E36: 741V7UML | F36: 4500152544-90 | G36: 9543B-S001 | H36: 仓鼠 | I36: 24 | J36: 0 | K36: 24 | L36: =I36/K36 -> 1 | M36: 45670 | N36: 45666 | P36: PASS | Q36: 1/16-1/21出 | R36: 11/27收到 | U36: UPC贴纸跟翻4500098824 | V36: 12/20-客供外箱贴纸 | X36: 日期码格式：ZURU INC(BVI) 标准格式 日期：按实际生产日期 Packaging Info: 出口加拿大，包装需要至少2/3L UPC版，无硼版本。 #9543: MA 3L UPC版本。A:193052051776, B:193052051783, E:193052051806,; Remark: 1. Amazon FOB订单，出口CA。外箱最长边不能超过25" （超过了，case pack只能为1），不符合要求的大货，一律不接受。 2. 外箱正面印ZURU Logo + SSCC LABEL（客供贴纸)，侧面印item#（订单上显示的SKU#) + carton size(以工厂实际尺寸为准，单位: inch) + MADE IN CHINA， 日期使用ZURU 标准版本 SSCC Label 显示的是客人自己的item#，SSCC Label 贴在外箱正面的正中间，贴一面即可，跟单订购，贴纸离外箱距必须至少3cm，每一 张SSCC label 都是唯一且有不同流水及条码的，没有损耗，绝对不可贴错 ，否则贴错或损坏一张会导致全部都错，千万要注意: SSCC 贴纸务必要在正中间(可以覆 盖Logo <(>&<)> 箱唛)，否则会影响到仓库扫描识别。 3. 日期码使用ZURU标准版本。 4. 如果大货有要求入邮包盒，则对应的邮包盒上面要打上日期码。 5. 按照客户PO# 装柜/箱号顺序装柜，跟单会提前给到装柜计划。在大货生产/仓库存放时，请留意该装柜要求，以便装柜时不混乱（避免装错/装漏/找不到货号等 ）。 6. 出口加拿大，包装需要至少2/3L UPC版，无硼版本。 7.邮包盒上要印刷日期码 | Y36: Kelly/Mia | Z36: 2.5695 | AA36: =I36*Z36 -> 61.668 | AB36: 24 | AC36: =AB36-I36 -> 0 | AD36: ok | AE36: 9543B-S001-3L | AF36: 已入 | AG36: 系统出单 | AH36: 94134-1.21 | AO36: =I36 -> 24 | AT36: =I36 -> 24 | BW36: 增加移印布标内容 | BY36: =I36 -> 24 | CB36: =I36 -> 24 | CD36: =SUM(BX36:CA36) -> 24 | CE36: =I36-CD36 -> 0
A37: 45623 | B37: Amazon CA (Vendor Center) | C37: 加拿大 | D37: 4500152544 | E37: 1OGZNF3F | F37: 4500152544-120 | G37: 9543A-S001 | H37: 仓鼠 | I37: 24 | J37: 0 | K37: 24 | L37: =I37/K37 -> 1 | M37: 45670 | N37: 45666 | P37: PASS | Q37: 1/16-1/21出 | R37: 11/27收到 | U37: UPC贴纸跟翻4500098824 | V37: 12/20-客供外箱贴纸 | X37: 日期码格式：ZURU INC(BVI) 标准格式 日期：按实际生产日期 Packaging Info: 出口加拿大，包装需要至少2/3L UPC版，无硼版本。 #9543: MA 3L UPC版本。A:193052051776, B:193052051783, E:193052051806,; Remark: 1. Amazon FOB订单，出口CA。外箱最长边不能超过25" （超过了，case pack只能为1），不符合要求的大货，一律不接受。 2. 外箱正面印ZURU Logo + SSCC LABEL（客供贴纸)，侧面印item#（订单上显示的SKU#) + carton size(以工厂实际尺寸为准，单位: inch) + MADE IN CHINA， 日期使用ZURU 标准版本 SSCC Label 显示的是客人自己的item#，SSCC Label 贴在外箱正面的正中间，贴一面即可，跟单订购，贴纸离外箱距必须至少3cm，每一 张SSCC label 都是唯一且有不同流水及条码的，没有损耗，绝对不可贴错 ，否则贴错或损坏一张会导致全部都错，千万要注意: SSCC 贴纸务必要在正中间(可以覆 盖Logo <(>&<)> 箱唛)，否则会影响到仓库扫描识别。 3. 日期码使用ZURU标准版本。 4. 如果大货有要求入邮包盒，则对应的邮包盒上面要打上日期码。 5. 按照客户PO# 装柜/箱号顺序装柜，跟单会提前给到装柜计划。在大货生产/仓库存放时，请留意该装柜要求，以便装柜时不混乱（避免装错/装漏/找不到货号等 ）。 6. 出口加拿大，包装需要至少2/3L UPC版，无硼版本。 7.邮包盒上要印刷日期码 | Y37: Kelly/Mia | Z37: 2.5695 | AA37: =I37*Z37 -> 61.668 | AB37: 24 | AC37: =AB37-I37 -> 0 | AD37: ok | AE37: 9543A-S001-3L | AF37: 已入 | AG37: 系统出单 | AH37: 94134-1.21 | AO37: =I37 -> 24 | AT37: =I37 -> 24 | BW37: 增加移印布标内容 | BX37: =I37 -> 24 | CB37: =I37 -> 24 | CD37: =SUM(BX37:CA37) -> 24 | CE37: =I37-CD37 -> 0
A38: 45623 | B38: Amazon CA (Vendor Center) | C38: 加拿大 | D38: 4500152544 | E38: 6GPK2DAR | F38: 4500152544-130 | G38: 9543E-S001 | H38: 仓鼠 | I38: 24 | J38: 0 | K38: 24 | L38: =I38/K38 -> 1 | M38: 45670 | N38: 45666 | P38: PASS | Q38: 1/16-1/21出 | R38: 11/27收到 | U38: UPC贴纸跟翻4500098824 | V38: 12/20-客供外箱贴纸 | X38: 日期码格式：ZURU INC(BVI) 标准格式 日期：按实际生产日期 Packaging Info: 出口加拿大，包装需要至少2/3L UPC版，无硼版本。 #9543: MA 3L UPC版本。A:193052051776, B:193052051783, E:193052051806,; Remark: 1. Amazon FOB订单，出口CA。外箱最长边不能超过25" （超过了，case pack只能为1），不符合要求的大货，一律不接受。 2. 外箱正面印ZURU Logo + SSCC LABEL（客供贴纸)，侧面印item#（订单上显示的SKU#) + carton size(以工厂实际尺寸为准，单位: inch) + MADE IN CHINA， 日期使用ZURU 标准版本 SSCC Label 显示的是客人自己的item#，SSCC Label 贴在外箱正面的正中间，贴一面即可，跟单订购，贴纸离外箱距必须至少3cm，每一 张SSCC label 都是唯一且有不同流水及条码的，没有损耗，绝对不可贴错 ，否则贴错或损坏一张会导致全部都错，千万要注意: SSCC 贴纸务必要在正中间(可以覆 盖Logo <(>&<)> 箱唛)，否则会影响到仓库扫描识别。 3. 日期码使用ZURU标准版本。 4. 如果大货有要求入邮包盒，则对应的邮包盒上面要打上日期码。 5. 按照客户PO# 装柜/箱号顺序装柜，跟单会提前给到装柜计划。在大货生产/仓库存放时，请留意该装柜要求，以便装柜时不混乱（避免装错/装漏/找不到货号等 ）。 6. 出口加拿大，包装需要至少2/3L UPC版，无硼版本。 7.邮包盒上要印刷日期码 | Y38: Kelly/Mia | Z38: 2.5695 | AA38: =I38*Z38 -> 61.668 | AB38: 24 | AC38: =AB38-I38 -> 0 | AD38: ok | AE38: 9543E-S001-3L | AF38: 已入 | AG38: 系统出单 | AH38: 94134-1.21 | AO38: =I38 -> 24 | AT38: =I38 -> 24 | BW38: 增加移印布标内容 | CA38: =I38 -> 24 | CB38: =I38 -> 24 | CD38: =SUM(BX38:CA38) -> 24 | CE38: =I38-CD38 -> 0
A39: 45623 | B39: Amazon CA (Vendor Center) | C39: 加拿大 | D39: 4500152544 | E39: 2SPNAMFN | F39: 4500152544-140 | G39: 9543E-S001 | H39: 仓鼠 | I39: 24 | J39: 0 | K39: 24 | L39: =I39/K39 -> 1 | M39: 45670 | N39: 45666 | P39: PASS | Q39: 1/16-1/21出 | R39: 11/27收到 | U39: UPC贴纸跟翻4500098824 | V39: 12/20-客供外箱贴纸 | X39: 日期码格式：ZURU INC(BVI) 标准格式 日期：按实际生产日期 Packaging Info: 出口加拿大，包装需要至少2/3L UPC版，无硼版本。 #9543: MA 3L UPC版本。A:193052051776, B:193052051783, E:193052051806,; Remark: 1. Amazon FOB订单，出口CA。外箱最长边不能超过25" （超过了，case pack只能为1），不符合要求的大货，一律不接受。 2. 外箱正面印ZURU Logo + SSCC LABEL（客供贴纸)，侧面印item#（订单上显示的SKU#) + carton size(以工厂实际尺寸为准，单位: inch) + MADE IN CHINA， 日期使用ZURU 标准版本 SSCC Label 显示的是客人自己的item#，SSCC Label 贴在外箱正面的正中间，贴一面即可，跟单订购，贴纸离外箱距必须至少3cm，每一 张SSCC label 都是唯一且有不同流水及条码的，没有损耗，绝对不可贴错 ，否则贴错或损坏一张会导致全部都错，千万要注意: SSCC 贴纸务必要在正中间(可以覆 盖Logo <(>&<)> 箱唛)，否则会影响到仓库扫描识别。 3. 日期码使用ZURU标准版本。 4. 如果大货有要求入邮包盒，则对应的邮包盒上面要打上日期码。 5. 按照客户PO# 装柜/箱号顺序装柜，跟单会提前给到装柜计划。在大货生产/仓库存放时，请留意该装柜要求，以便装柜时不混乱（避免装错/装漏/找不到货号等 ）。 6. 出口加拿大，包装需要至少2/3L UPC版，无硼版本。 7.邮包盒上要印刷日期码 | Y39: Kelly/Mia | Z39: 2.5695 | AA39: =I39*Z39 -> 61.668 | AB39: 24 | AC39: =AB39-I39 -> 0 | AD39: ok | AE39: 9543E-S001-3L | AF39: 已入 | AG39: 系统出单 | AH39: 94134-1.21 | AO39: =I39 -> 24 | AT39: =I39 -> 24 | BW39: 增加移印布标内容 | CA39: =I39 -> 24 | CB39: =I39 -> 24 | CD39: =SUM(BX39:CA39) -> 24 | CE39: =I39-CD39 -> 0
A40: 45623 | B40: Amazon CA (Vendor Center) | C40: 加拿大 | D40: 4500152544 | E40: 6ZIX89BO | F40: 4500152544-180 | G40: 9543E-S001 | H40: 仓鼠 | I40: 24 | J40: 0 | K40: 24 | L40: =I40/K40 -> 1 | M40: 45670 | N40: 45666 | P40: PASS | Q40: 1/16-1/21出 | R40: 11/27收到 | U40: UPC贴纸跟翻4500098824 | V40: 12/20-客供外箱贴纸 | X40: 日期码格式：ZURU INC(BVI) 标准格式 日期：按实际生产日期 Packaging Info: 出口加拿大，包装需要至少2/3L UPC版，无硼版本。 #9543: MA 3L UPC版本。A:193052051776, B:193052051783, E:193052051806,; Remark: 1. Amazon FOB订单，出口CA。外箱最长边不能超过25" （超过了，case pack只能为1），不符合要求的大货，一律不接受。 2. 外箱正面印ZURU Logo + SSCC LABEL（客供贴纸)，侧面印item#（订单上显示的SKU#) + carton size(以工厂实际尺寸为准，单位: inch) + MADE IN CHINA， 日期使用ZURU 标准版本 SSCC Label 显示的是客人自己的item#，SSCC Label 贴在外箱正面的正中间，贴一面即可，跟单订购，贴纸离外箱距必须至少3cm，每一 张SSCC label 都是唯一且有不同流水及条码的，没有损耗，绝对不可贴错 ，否则贴错或损坏一张会导致全部都错，千万要注意: SSCC 贴纸务必要在正中间(可以覆 盖Logo <(>&<)> 箱唛)，否则会影响到仓库扫描识别。 3. 日期码使用ZURU标准版本。 4. 如果大货有要求入邮包盒，则对应的邮包盒上面要打上日期码。 5. 按照客户PO# 装柜/箱号顺序装柜，跟单会提前给到装柜计划。在大货生产/仓库存放时，请留意该装柜要求，以便装柜时不混乱（避免装错/装漏/找不到货号等 ）。 6. 出口加拿大，包装需要至少2/3L UPC版，无硼版本。 7.邮包盒上要印刷日期码 | Y40: Kelly/Mia | Z40: 2.5695 | AA40: =I40*Z40 -> 61.668 | AB40: 24 | AC40: =AB40-I40 -> 0 | AD40: ok | AE40: 9543E-S001-3L | AF40: 已入 | AG40: 系统出单 | AH40: 94134-1.21 | AO40: =I40 -> 24 | AT40: =I40 -> 24 | BW40: 增加移印布标内容 | CA40: =I40 -> 24 | CB40: =I40 -> 24 | CD40: =SUM(BX40:CA40) -> 24 | CE40: =I40-CD40 -> 0
...

Sheet 布料MA
A1: Description | C1: Ratio | F1: MA-RR-758 | G1: MA-RR-784 | H1: MA-RR-808 | I1: MA-RR-858 | M1: Total
A2: 下单日期 | C2: Bulk | D2: GQ1 | E2: SK | F2: 44853 | G2: 44897 | H2: 45005 | I2: 45039
A3: 要求完货日期 | F3: 44995 | G3: 45021 | H3: 45095 | I3: 45143
B4: 透明球 | F4: =SUM(F6:F9) -> 120000 | G4: =SUM(G6:G9) -> 80000 | H4: =SUM(H6:H9) -> 106000 | I4: 136000 | M4: =SUM(F4:I4) -> 442000
A5: SUM | F5: =SUM(F4:F4) -> 120000 | G5: =SUM(G4:G4) -> 80000 | H5: =SUM(H4:H4) -> 106000 | I5: 136000 | M5: =SUM(M4:M4) -> 442000
A6: 9543# Hamstermania | B6: 蓝色仓鼠(Blue) | C6: 6 | D6: 5 | E6: 6 | F6: 30000 | G6: 20000 | H6: 20000 | I6: 23000 | M6: =SUM(F6:I6) -> 93000
B7: 粉色仓鼠(Pink) | C7: 6 | D7: 6 | E7: 8 | F7: 30000 | G7: 20000 | H7: 41000 | I7: 62000 | M7: =SUM(F7:I7) -> 153000
B8: 紫色仓鼠(Purple) | C8: 6 | D8: 6 | E8: 8 | F8: 30000 | G8: 20000 | H8: 25000 | I8: 28000 | M8: =SUM(F8:I8) -> 103000
B9: 土黄色仓鼠(Orange) | C9: 6 | D9: 5 | E9: 7 | F9: 30000 | G9: 20000 | H9: 20000 | I9: 23000 | M9: =SUM(F9:I9) -> 93000
A10: SUM | C10: =SUM(C6:C9) -> 24 | D10: =SUM(D6:D9) -> 22 | E10: =SUM(E6:E9) -> 29 | F10: =SUM(F6:F9) -> 120000 | G10: =SUM(G6:G9) -> 80000 | H10: =SUM(H6:H9) -> 106000 | I10: 136000 | M10: =SUM(M6:M9) -> 442000
A11: 9543GQ1/GQ3/SK Demo（无功能） | B11: 粉色仓鼠(Pink)-Demo | H11: 20000 | M11: =SUM(F11:I11) -> 20000
A12: SUM | F12: =SUM(F11:F11) -> 0 | G12: =SUM(G11:G11) -> 0 | H12: =SUM(H11:H11) -> 20000 | I12: 0 | M12: =SUM(M11:M11) -> 20000

Sheet 9543包装MA
A1: 9543-仓鼠
A2: 日期 | C2: MA PO | D2: 負責 | E2: 扣MA | J2: 扣MA | M2: 扣MA | R2: 标准版 | U2: 标准版 | X2: 客办 | AP2: 标准版 | AQ2: 标准版
E3: MA 1語收縮膜 | F3: MA 1語收縮膜-B版本 | G3: MA 1語收縮膜-C版本 | H3: MA 1語收縮膜-D版本 | I3: MA 1語收縮膜-E版本 | J3: MA 3語收縮膜-A版本 | K3: MA 3語收縮膜-C版本 | L3: MA 3語收縮膜-D版本 | M3: MA 9語收藏指南-A版本 | N3: MA 9語收藏指南-B版本 | O3: MA 5語收藏指南-A版本 | P3: MA 5語收藏指南-B版本 | Q3: 客办说明书 | R3: GQ1-1L-A版本 | S3: GQ1-1L-B版本 | T3: GQ1-1L-C版本 | U3: GQ1-3L-A版本 | V3: GQ1-3L-B版本 | W3: GQ1-3L-C版本 | X3: GQ2-3L-KM单-WMCA-A版本 | Y3: GQ2-3L-KM单-WMCA-B版本 | Z3: GQ2-3L-KM单-WMCA-C版本 | AA3: GQ2-3L-KM单-WMCA-D版本 | AB3: GQ3-1L-客办 | AC3: GQ3-1L-客办-B版本 | AD3: GQ4-3L-TG单-A版本 | AE3: GQ4-3L-TG单-B版本 | AF3: GQ4-3L-TG单-C版本 | AG3: GQ4-3L-TG单-D版本 | AH3: TQ1 WM单 | AI3: TQ2 | AJ3: GQ5-A版本 | AK3: GQ5-B版本 | AL3: GQ6 | AM3: GQ6-B版本 | AN3: 客办收缩膜 | AO3: 客办PDQ | AP3: 9543 SK-S001展示架-无底盒-3L | AQ3: 9543 SK-S002展示架-有底盒-3L | AR3: 客办扣数PO
E4: A版本 | F4: B版本 | J4: A版本 | M4: A版本 | N4: B版本 | R4: A版本 | U4: A版本 | X4: A版本 | AB4: A版本 | AD4: A版本 | AH4: A版本 | AJ4: A版本
A5: 44923 | C5: 1000012936 | D5: Emily | E5: 80000
A6: 44923 | C6: 1000012937 | D6: Emily | M6: 80000
A7: 44923 | C7: 1000012938 | D7: Emily | R7: 2000
X8: 730 | AR8: @sara 4500095104 4500095105 4500096539 4500096550
A9: 44992 | B9: 44992 | C9: 1000013403 | D9: Emily | J9: 50000
A10: 44992 | B10: 44992 | C10: 1000013397 | D10: Emily | N10: 50000
A11: 44992 | B11: 44992 | C11: 1000013402 | D11: Emily | U11: 2000
B12: 45002 | D12: Daisy | X12: =2882+166 -> 3048 | AR12: @Willow 4500097125 & 4500097126 & 4500097127 & 4500097128 & 4500097511 & 4500103368 & 4500103370 & 4500105660 & 4500105661 & 4500106312 & 4500111177 & 4500111176
A13: 45006 | C13: 1000013551 | AH13: 1932 | AR13: Effy 用于订单 4500097065 4500097066
A14: 45020 | D14: Peggy Wu | AD14: 2548 | AR14: Holly/Jaycee 4500095175
A15: 45020 | C15: 1000013752 | D15: Emily | F15: 50000
A16: 45020 | C16: 1000013750 | D16: Emily | N16: 50000
A17: 45020 | C17: 1000013743 | D17: Emily | R17: 3000
A18: 45020 | C18: 1000013751 | D18: Emily | U18: 2000
C19: 1000013945 | D19: Charine Chen | AN19: 30000 | AR19: Linda#PO#4500094401-4500097498-4500101349-4500102943-4500102361-4500101675
C20: 1000013946 | D20: Charine Chen | AO20: 1603 | AR20: Linda#PO#4500094401-4500097498-4500102943-4500102361
A21: 45037 | B21: 45037 | C21: 1000014631 | D21: Emily | F21: 50000
A22: 45037 | B22: 45037 | C22: 1000014632 | D22: Emily | J22: 30000
A23: 45037 | B23: 45037 | C23: 1000014633 | D23: Emily | N23: 100000
A24: 45037 | B24: 45037 | C24: 1000014634 | D24: Emily | R24: 5000
A25: 45037 | B25: 45037 | C25: 1000014635 | D25: Emily | U25: 2000
A26: 45037 | B26: 45042 | C26: 10000114110 | D26: Emily | AQ26: 300
AB27: 448
C28: 1000014104 | D28: Daisy | AH28: 4256 | AR28: Effy用于订单 4500101892 4500101897 4500101900 4500101913 4500101901 4500101920 4500101923 4500101925 4500101928
C29: 1000014159 | D29: Charine Chen | AB29: 1140 | AR29: Sheba#TESCO UK NEW PO 4500096046 & 4500100986 & 4500106764
B30: 45044 | C30: 1000014162 | D30: Emily | F30: 100000
B31: 45044 | C31: 1000014163 | D31: Emily | N31: 100000
B32: 45042 | C32: 1000014164 | D32: Emily | AP32: 300
B33: 45055 | C33: 1000014298 | D33: Peggy Wu | AD33: 917 | AR33: @Holly/Jaycee 4500102786&4500103118
B34: 45061 | C34: 1000014386 | D34: Daisy | AL34: 1780 | AR34: Coral用于PO#4500100969 4500099925
B35: 45072 | C35: 1000014579 | D35: Charine Chen | AN35: 30000 | AR35: 4500102945-4500104422-4500105374-4500105999-4500104088-4500106823-4500107294-4500108108-4500108130
B36: 45072 | C36: 1000014580 | D36: Charine Chen | AO36: 951 | AR36: 4500102945-4500104422
B37: 45072 | C37: 1000014558 | D37: Daisy | AH37: 9408 | AR37: Effy用于订单 4500104809 4500104811 4500104812 4500104814 4500104815 4500104820 4500104822 4500104816 4500104817 4500104825 4500104828 4500104829 4500104830 4500104818 4500104832
B38: 45079 | D38: Peggy Wu | AE38: 583 | AR38: JayceePO#4500104446
B39: 45084 | C39: 1000014710 | D39: Daisy | AH39: 9354 | AR39: Effy用于订单 4500098420 4500098422 4500098423 4500098425 4500098426 4500098427 4500098434 4500098471 4500098473 4500098475 4500098476 4500099624 4500099625 4500099626 4500099627 4500099628 4500099629 4500099630 4500099631 4500099632
B40: 45093 | C40: 1000014944 | D40: Emily | F40: 60000
...

Sheet 9543MA半成品
A1: MA半成品扣數表 | L1: IC扣數表
A2: MA訂單號 | B2: 日期 | C2: #9543 | L2: MA訂單號 | M2: 日期 | N2: #9543
C3: 蓝色仓鼠 | D3: 粉色仓鼠 | E3: 紫色仓鼠 | F3: 土黄色仓鼠 | G3: 透明球 | H3: 四款合计 | I3: 无功能粉色仓鼠 | J3: 完成时间 | O3: 收货时间
C4: (Blue) | D4: (Pink) | E4: (Purple) | F4: (Orange)
A5: MA-RR-758 | B5: 44853 | C5: 30000 | D5: 30000 | E5: 30000 | F5: 30000 | G5: =SUM(C5:F5) -> 120000 | H5: =SUM(C5:F5) -> 120000 | J5: 44995 | L5: MA_RR_729 | M5: 44790 | N5: 68000
A6: MA-RR-784 | B6: 44897 | C6: 20000 | D6: 20000 | E6: 20000 | F6: 20000 | G6: =SUM(C6:F6) -> 80000 | H6: =SUM(C6:F6) -> 80000 | J6: 45021 | L6: MA_RR_737 | M6: 44805 | N6: 34000 | P6: 旧IC
A7: MA-RR-808 | B7: 45005 | C7: 20000 | D7: 41000 | E7: 25000 | F7: 20000 | G7: =SUM(C7:F7)+I7 -> 126000 | H7: =SUM(C7:F7) -> 106000 | I7: 20000 | J7: 45095 | L7: MA_RR_751 | M7: 44834 | N7: 102000 | P7: 旧IC
A8: MA-RR-858 | B8: 45039 | C8: 23000 | D8: 62000 | E8: 28000 | F8: 23000 | G8: =SUM(C8:F8) -> 136000 | H8: =SUM(C8:F8) -> 136000 | J8: 45143 | L8: MA_RR_815 | M8: 44984 | N8: 102000 | P8: 旧IC
A9: MA-RR-888 | B9: 45064 | C9: 21000 | D9: 38000 | E9: 21000 | F9: 22000 | G9: =SUM(C9:F9)+I9 -> 107000 | H9: =SUM(C9:F9) -> 102000 | I9: 5000 | J9: 45181 | L9: MA_RR_859 | M9: 45043 | N9: 136000 | P9: 旧IC
A10: MA-RR-894 | B10: 45082 | C10: 21000 | D10: 21500 | E10: 22500 | F10: 20000 | G10: =SUM(C10:F10) -> 85000 | H10: =SUM(C10:F10) -> 85000 | J10: 45188 | L10: MA_RR_889 | M10: 45064 | N10: 102000 | O10: 45096 | P10: 旧IC
A11: MA-RR-905 | B11: 45089 | D11: 34000 | G11: =SUM(C11:F11) -> 34000 | H11: =SUM(C11:F11) -> 34000 | J11: 45195 | L11: MA_RR_892 | M11: 45079 | N11: 85000 | O11: 45108 | P11: 旧IC
A12: MA-RR-913 | B12: 45111 | C12: 22500 | E12: 23000 | F12: 22500 | G12: =SUM(C12:F12) -> 68000 | H12: =SUM(C12:F12) -> 68000 | J12: 45208 | L12: MA_RR_906 | M12: 45091 | N12: 34000 | O12: 45117 | P12: 旧IC
A13: MA-RR-931 | B13: 45134 | C13: 20000 | D13: 22500 | E13: 22500 | F13: 20000 | G13: =SUM(C13:F13)+I13 -> 90000 | H13: =SUM(C13:F13) -> 85000 | I13: 5000 | J13: 45208 | L13: MA_RR_914 | M13: 45112 | N13: 68000 | O13: 45142 | P13: 旧IC
A14: MA-RR-948 | B14: 45152 | C14: 20000 | D14: 33000 | E14: 24000 | F14: 25000 | G14: =SUM(C14:F14)+I14 -> 107000 | H14: =SUM(C14:F14) -> 102000 | I14: 5000 | J14: 45252 | L14: MA_RR_932 | M14: 45132 | N14: 85000 | O14: 45161 | P14: 旧IC
A15: MA-RR-960 | B15: 45180 | C15: 20000 | D15: 25000 | E15: 20000 | F15: 20000 | G15: =SUM(C15:F15)+I15 -> 95000 | H15: =SUM(C15:F15) -> 85000 | I15: 10000 | J15: 45280 | L15: MA_RR_949 | M15: 45152 | N15: 102000 | O15: 45190 | P15: 旧IC
A16: MA-RR-1001 | B16: 45237 | C16: 20000 | D16: 28000 | E16: 20000 | F16: 20000 | G16: =SUM(C16:F16)+I16 -> 98000 | H16: =SUM(C16:F16) -> 88000 | I16: 10000 | J16: 45330.857 | L16: MA_RR_961 | M16: 45180 | N16: 85000 | P16: 旧IC
A17: MA-RR-1028 | B17: 45273 | C17: 20000 | D17: 30000 | E17: 20000 | F17: 20000 | G17: =SUM(C17:F17)+I17 -> 100000 | H17: =SUM(C17:F17) -> 90000 | I17: 10000 | J17: 45365 | M17: 45208 | N17: 34000 | P17: 旧IC
A18: MA-RR-1064 | B18: 45301 | C18: 20000 | D18: 30000 | E18: 20000 | F18: 20000 | G18: =SUM(C18:F18)+I18 -> 90000 | H18: =SUM(C18:F18) -> 90000 | J18: 45412 | L18: MA_RR_998 | M18: 45229 | N18: 54000 | P18: 新供应商：矽源特
A19: MA-RR-1106 | B19: 45356 | C19: 20000 | D19: 43000 | E19: 25000 | F19: 20000 | G19: =SUM(C19:F19)+I19 -> 118000 | H19: =SUM(C19:F19) -> 108000 | I19: 10000 | J19: 45435 | L19: MA_RR_1022 | M19: 45265 | N19: 90000 | P19: 新供应商：矽源特
A20: MA-RR-1128 | B20: 45370 | C20: 20000 | D20: 57000 | E20: 27000 | F20: 22000 | G20: =SUM(C20:F20)+I20 -> 126000 | H20: =SUM(C20:F20) -> 126000 | J20: 45474.571 | L20: MA_RR_1050 | M20: 45286 | N20: 90000 | P20: 新供应商：矽源特
A21: MA-RR-1157 | B21: 45390 | C21: 20000 | D21: 37000 | E21: 27000 | F21: 24000 | G21: =SUM(C21:F21)+I21 -> 118000 | H21: =SUM(C21:F21) -> 108000 | I21: 10000 | J21: 45509 | L21: MA_RR_1071 | M21: 45315 | N21: 108000 | P21: 新供应商：矽源特
A22: MA-RR-1196 | B22: 45411 | C22: 22000 | D22: 52000 | E22: 27000 | F22: 25000 | G22: =SUM(C22:F22)+I22 -> 126000 | H22: =SUM(C22:F22) -> 126000 | J22: 45522 | L22: MA_RR_1129 | M22: 45370 | N22: 126000 | P22: 新供应商：矽源特
A23: MA-RR-1218 | B23: 45422 | D23: 54000 | G23: =SUM(C23:F23)+I23 -> 54000 | H23: =SUM(C23:F23) -> 54000 | J23: 45547 | L23: MA_RR_1152 | M23: 45385 | N23: 108000 | P23: 新供应商：矽源特
A24: MA-RR-1228 | B24: 45427 | C24: 32500 | D24: 20000 | E24: 27500 | F24: 28000 | G24: =SUM(C24:F24)+I24 -> 118000 | H24: =SUM(C24:F24) -> 108000 | I24: 10000 | J24: 45552 | L24: MA_RR_1193 | M24: 45410 | N24: 72000 | P24: 新供应商：矽源特
A25: MA-RR-1290 | B25: 45467 | C25: 24500 | D25: 33500 | E25: 26500 | F25: 23500 | G25: =SUM(C25:F25)+I25 -> 118000 | H25: =SUM(C25:F25) -> 108000 | I25: 10000 | J25: 45595 | L25: MA_RR_1197 | M25: 45410 | N25: 54000 | P25: 新供应商：矽源特
A26: MA-RR-1385 | B26: 45559 | C26: 20000 | D26: 25000 | E26: 20000 | G26: =SUM(C26:F26)+I26 -> 65000 | H26: =SUM(C26:F26) -> 65000 | J26: 45614 | L26: MA_RR_1217 | M26: 45422 | N26: 54000 | P26: 新供应商：矽源特
A27: MA-RR-1413 | B27: 45582 | F27: 20000 | G27: =SUM(C27:F27)+I27 -> 20000 | H27: =SUM(C27:F27) -> 20000 | J27: 45639 | L27: MA_RR_1227 | M27: 45427 | N27: 108000 | P27: 新供应商：矽源特
A28: MA-RR-1450 | B28: 45618 | C28: 22000 | D28: 26000 | E28: 27000 | F28: 20000 | G28: =SUM(C28:F28)+I28 -> 115000 | H28: =SUM(C28:F28) -> 95000 | I28: 20000 | J28: 45342 | L28: MA_RR_1294 | M28: 45468 | N28: 108000 | P28: 新供应商：矽源特
A29: MA-RR-1468 | B29: 45630 | C29: 23000 | D29: 24000 | E29: 23000 | F29: 20000 | G29: =SUM(C29:F29)+I29 -> 90000 | H29: =SUM(C29:F29) -> 90000 | J29: 45666 | L29: MA_RR_1346 | M29: 45504 | N29: 54000 | P29: 新供应商：矽源特
A30: MA-RR-1595 | B30: 45733 | C30: 20000 | D30: 28500 | E30: 20000 | F30: 21500 | G30: =SUM(C30:F30)+I30 -> 90000 | H30: =SUM(C30:F30) -> 90000 | J30: 45795 | L30: MA_RR_1380 | M30: 45539 | N30: 18000 | P30: 新供应商：矽源特
A31: MA-RR-1637 | B31: 45784 | C31: 20000 | D31: 25000 | E31: 25000 | F31: 20000 | G31: =SUM(C31:F31)+I31 -> 90000 | H31: =SUM(C31:F31) -> 90000 | J31: 45859 | L31: MA_RR_1393 | M31: 45559 | N31: 36000 | P31: 新供应商：矽源特
A32: MA-RR-1709 | B32: 45806 | C32: 20000 | D32: 25000 | E32: 25000 | F32: 20000 | G32: =SUM(C32:F32)+I32 -> 100000 | H32: =SUM(C32:F32) -> 90000 | I32: 10000 | J32: 45881 | L32: MA_RR_1433 | M32: 45593 | N32: 72000 | P32: 新供应商：矽源特
A33: MA-RR-1790 | B33: 45849 | C33: 24000 | D33: 20000 | E33: 25000 | F33: 21000 | G33: =SUM(C33:F33)+I33 -> 100000 | H33: =SUM(C33:F33) -> 90000 | I33: 10000 | J33: 45940 | L33: MA_RR_1463 | M33: 45625 | N33: 90000 | P33: 新供应商：矽源特
A34: MA-RR-1943 | B34: 45954 | C34: 20500 | D34: 23500 | E34: 22000 | F34: 24000 | G34: =SUM(C34:F34)+I34 -> 90000 | H34: =SUM(C34:F34) -> 90000 | J34: 45985 | L34: MA_RR_1496 | M34: 45702 | N34: 72000 | P34: 新供应商：矽源特
A35: MA-RR-1999 | B35: 46000 | C35: 20000 | D35: 25000 | E35: 25000 | F35: 20000 | G35: =SUM(C35:F35)+I35 -> 100000 | H35: =SUM(C35:F35) -> 90000 | I35: 10000 | J35: 46027 | L35: MA_RR_1604 | M35: 45742 | N35: 72000 | P35: 新供应商：矽源特（降价）
A36: MA-RR-2133 | B36: 46091 | C36: 32000 | D36: 40500 | E36: 37500 | F36: 34000 | G36: =SUM(C36:F36)+I36 -> 144000 | H36: =SUM(C36:F36) -> 144000 | J36: 46213 | L36: MA_RR_1638 | N36: 36000 | P36: 新供应商：矽源特（降价）
A37: MA-RR-2317 | B37: 46167 | C37: 22500 | D37: 22250 | E37: 22750 | F37: 22500 | G37: =SUM(C37:F37)+I37 -> 90000 | H37: =SUM(C37:F37) -> 90000 | J37: 46275 | L37: MA_RR_1697 | M37: 45804 | N37: 72000 | P37: 新供应商：矽源特（降价）
A38: MA-RR-2467 | B38: 46240 | C38: 20000 | D38: 26000 | E38: 24000 | F38: 20000 | G38: =SUM(C38:F38)+I38 -> 100000 | H38: =SUM(C38:F38) -> 90000 | I38: 10000 | J38: 46320 | L38: MA_RR_1710 | M38: 45806 | N38: 18000 | P38: 新供应商：矽源特（降价）
L39: MA_RR_1756 | M39: 45838 | N39: 90000 | P39: 新供应商：矽源特（降价）
L40: MA_RR_1811 | M40: 45866 | N40: 54000 | P40: 新供应商：矽源特（降价）
...

Sheet 取消订单
A1: 接单期 | B1: 第三方客户名称 | C1: 国家 | D1: PO号 | E1: 小PO号 | F1: SKU号 | G1: 系统货号 | H1: 货号 | I1: 名称 | J1: 数量 | K1: 内箱装箱数量(pcs) | L1: 装箱数（PCS） | M1: 总箱数 | N1: 计划出货期 | O1: 计划验货期 | P1: 取消时间 | Q1: 物料情况 | R1: 纸箱滞留 | S1: 箱唛资料(收到日期) | T1: 外箱贴纸 | U1: 客供贴纸AI(收到日期) | V1: 客供物料 | W1: 日期码 | X1: 备注 | Y1: ZURU 跟单 | Z1: 单价USD | AA1: 金额USD | AB1: 發票號 | AC1: 是否入系统 | AD1: MA 1語收縮膜 A版本 | AE1: MA 3语收缩膜 | AF1: 客版收縮膜 | AG1: MA 9语 收藏指南 A版本 | AH1: 客版收藏指南 | AI1: GQ1-MA 1L | AJ1: GQ1-MA 3L | AK1: GQ2-MA 1L KM单+WM-CA | AL1: GQ3- 客版 1L | AM1: GQ4-MA 1L TG单 | AN1: TQ1 WM单 | AQ1: 客版PDQ | AR1: 客办收缩膜 | AT1: 布標 | AU1: 發票號 | AV1: 蓝色仓鼠(Blue) | AW1: 粉色仓鼠(Pink) | AX1: 紫色仓鼠(Purple) | AY1: 土黄色仓鼠(Orange) | AZ1: 透明球 | BA1: 无功能 粉色仓鼠 | BB1: 总数 | BC1: 相差 | BW1: 成品滞留
A2: 44986 | B2: SUOMEN OSUUSKAUPPOJEN | C2: 芬兰 | D2: 4500096312 | E2: =SUM(A2:C2) -> 44986 | F2: 4500096312-40 | G2: 9543GQ1-S001 | H2: 9543GQ1-S001 | I2: 仓鼠 | J2: 2002 | K2: 0 | L2: 22 | M2: =J2/L2 -> 91 | N2: 45056 | O2: 取消订单（3/16转PO) | S2: 欠 | U2: 欠EAN贴纸+警告语贴纸 | V2: 客办收藏指南 | X2: 日期码格式：ZURU 标准格式 日期：按实际生产日期 Packaging Info: 9543GQ1:1L A版收缩膜+1L A版PDQ+客版说明书+EAN贴纸+警告语贴纸 Remark: 1. 包装不可有PVC，包装上的吸塑需要用PET代替。 2. 产品要求无硼无香 3. 工厂款号 条码 9543GQ1 4894680026995 4. 产品信息： 9543GQ1:2pcs *AAA battery not include; bule/purple/pink/orange =5:6:6:5 5.此单有客人客验，请多备料。 6.出货前需寄3-4套大货样给客人签样。 7.客人需要大货样1pcs，请在4/21前寄到深圳办公室Luna签收 | Y2: Rose | Z2: 2.64 | AA2: =J2*Z2 -> 5285.28 | AD2: =J2 -> 2002 | AH2: =J2 -> 2002 | AI2: =J2/11 -> 182 | AT2: 无 | AV2: =J2/22*5 -> 455 | AW2: =J2/22*6 -> 546 | AX2: =J2/22*6 -> 546 | AY2: =J2/22*5 -> 455 | AZ2: =J2 -> 2002 | BA2: =J2/11 -> 182 | BB2: =SUM(AV2:AY2) -> 2002 | BC2: =BB2-J2 -> 0
A3: 45090 | B3: TARGET US | C3: 美国 | D3: 4500106533 | F3: 4500106533-10 | G3: 未接到实单 | H3: 9543GQ4-S001 | I3: 仓鼠 | J3: 15000 | K3: 0 | L3: 6 | M3: =J3/L3 -> 2500 | N3: 45159 | O3: 45211 | P3: 9/12取消订单 | S3: 欠 | U3: 无 | V3: 欠外箱贴纸 | X3: 日期码格式：ZURU INC(BVI) 标准格式 日期：按实际生产日期 Packaging Info: 9543GQ4: MA 1L，客版PDQ Remark: 1. 9543GQ4-S001-PETS ALIVE-HAMSTERMANIA- SERIES 1 CAPSULE,1Facing6pcs/Gravity PDQ,6pcs/CTN,No Inner,STD Color Assortment 2. 产品MA 1L包装，客版PDQ. 产品UPC显示193052050328, Integral single ratio=bule/purple/pink/orange =1:1:1:1 3. 外箱正唛左上角位置粘贴条码箱贴纸，每箱只贴一张，由ZURU订购。来料贴纸上显示的客户DPCI# 086-08-4053，UPC显示10193052050325; 4. 9543GQ4：Semi-Products (Customized PDQ), 做半成品-球，客版PDQ等我们通知再订购 6. 产品/包装:MA+1L, UPC显示 193052050014. MA PDQ 7. 外箱正唛左上角位置粘贴条码箱贴纸，每箱只贴一张，由ZURU订购。来料贴纸上显示的客户DPCI#086-08-3096， UPC显示10193052050011 10. MA 1L包装. 产品UPC显示193052050106,Kitten:Bunny:Puppy:Cow:Elephant:Flamingo=1:1:1:1:1:1; 11. 外箱正唛左上角位置粘贴条码箱贴纸，每箱只贴一张，由ZURU订购。来料贴纸上显示的客户DPCI# 086-08-6431，UPC显示10193052050103; 13. 产品和包装上印刷 tracking code信息，格式为ZURU常规格式; 14. 出货方式：货代自提。 | Y3: Holly Zheng | Z3: 2.5968 | AA3: =J3*Z3 -> 38952 | AC3: =AB3-J3 -> -15000 | AD3: ok | AI3: =J3 -> 15000 | AM3: =J3 -> 15000 | BH3: 3750 | BI3: 3750 | BJ3: 3750 | BK3: 3750 | BL3: 15000 | BN3: 15000 | BO3: 0
A4: 45089 | B4: ZURU | C4: 库有 | D4: MO20230612 | G4: 待定 | H4: 9543-S001 | I4: 仓鼠 | J4: 11000 | K4: 0 | L4: 24 | M4: =J4/L4 -> 458.33333 | N4: 45159 | O4: 45237 | P4: 未收到实单先取消9/28 | S4: 欠 | U4: 无 | V4: 欠客供RFID贴纸 | X4: 9543 1.包装信息：, MA A 版 1L收缩膜，MA A 版3L 收藏指南，客供RFID贴纸，客版PDQ 2.在外箱印刷带条码的箱唛以及四面印刷RFID的箱唛（新增ZURU黑色色带顶格四面印刷 ），不需要贴白色艾利贴纸(由我们提供艾利贴纸替代箱唛），箱唛内容见附件, 外箱侧面任一角落标注"MADE IN CHINA" 字样。每个slip sheet上面贴一张艾利贴纸和一张普通贴纸（可A4纸打印），slip sheet打印的普通贴纸的尺寸不能比艾利贴纸小。 3.产品如有扎带口要剪平，不能刮手。 4.此单需要验货以及抽板做测试，请自行多备包装物料。 5.此单打卡板出货 2Facing2pcs/PDQ, 2pcs *AAA battery not include | AC4: =AB4-J4 -> -11000 | AJ4: =J4 -> 11000 | AO4: =J4 -> 11000 | BB4: 确认后再订 | BM4: =J4 -> 11000 | BP4: 11000 | BR4: 11000 | BS4: 0
