Workbook

Sheet 77772
A1: 香港接单日期 | B1: 第三方客户名称 | C1: 走货国家 | D1: ZURU PO NO# | E1: 第三方客户 PO NO# | F1: SKU | G1: ITEM# | H1: 货品名称 | I1: PO数量(只) | J1: 内箱装箱数量(只) | K1: 外箱装箱数量(只) | L1: 总箱数 | M1: 计划出货期 | N1: 计划验货期 | O1: 湖南完成时间 | P1: 第三方客户公证行验货 | Q1: 验货结果 | R1: S/O(截仓期) | S1: 生产情况 | T1: 已回数量 | U1: 欠数 | V1: 贴纸 | W1: 箱唛 (收到日期) | X1: 外箱贴纸 | Y1: 贴纸资料 (收到日期及订购日期) | Z1: 其他物料 | AA1: 额外说明书/保证书 | AB1: 样办 | AC1: 备注 | AD1: ZURU跟单组员 | AE1: 单价USD | AF1: 金额USD | AG1: 发票号 | AH1: 系统货号 | AI1: 是否入系统 | AJ1: 下单情况 | AK1: 77772 MA版本球数 | AL1: 77772 COSTCO球数 | AM1: 77772 Target球数 | AN1: 收缩膜 1L A版本 | AO1: "收缩膜 1L B版本" | AP1: 收缩膜 3L A版本 | AQ1: 客版3L无条码收缩膜（美国） | AR1: 客版3L无条码收缩膜（英法西） | AS1: WM CA客版收缩膜 | AT1: TARGET客版收缩膜 | AU1: 收藏指南 5L A版本 | AV1: 唱片架组装说明书 | AW1: 客版收藏指南（移除21唱片） | AX1: 客版收藏指南（移除21/23唱片） | AY1: 客版收藏指南（移除17款唱片） | AZ1: 中文收藏指南 | BA1: 中文黑白唱片架组装说明书 | BB1: COSTCO客版收缩膜 | BC1: COSTCO客版收藏指南 | BD1: COSTCO客版说明书 | BE1: COSTCO客版彩盒 | BF1: COSTCO客版托盘 | BG1: Smyths客版收缩膜 | BH1: Smyths客版收藏指南 | BI1: TARGET客版收缩膜 | BJ1: TARGET客版收藏指南 | BK1: MA GQ1 1L 13pcs | BL1: MA GQ1 3L 13pcs | BM1: MA GQ8 1L 48pcs | BN1: MA GQ2 1L 24/25pcs | BO1: MA GQ2 3L 24/25pcs | BP1: 客版GQ1 1L | BQ1: 客版GQ2 1L | BR1: 客版GQ3 1L | BS1: 客版GQ3 3L | BT1: 客版GQ4 | BU1: 客版GQ5 | BV1: EMC457 | BW1: MEC473 | BX1: MEC426 | BY1: MEC426 TARGET专属 | BZ1: MSLD188 | CA1: MSLD182 | CB1: SK-S002 | CC1: SK1-S002 | CD1: GQ2/GQ3 Demo | CE1: Target-US Demo | CF1: 77772展示架DOEM SK | CG1: ENDCAP Demo(set)-STD | CH1: 77944彩盒 | CI1: 77944托盘UQ1 | CJ1: 77876圆筒 | CK1: 77876彩纸 | CL1: 77876贴纸
A2: 46037 | D2: ZMPO260055 | F2: ZMPO260055-10 | G2: 77772-S001 | H2: 唱片球24 pcs/箱 | I2: 80套散件 | J2: 0 | K2: 24 | L2: =80/24 -> 3.3333333 | M2: 46052 | N2: 46048 | W2: 周转箱 | X2: 无 | Y2: 无 | AC2: Remark：大货版本/只需要齐全套散件/麻烦用胶袋分装好一套为一袋 备注： 收到样品订单后尽快安排 ，注意样板品质质量要求要高于大货品质要求 ，送货时必须要附带送货单(没有送货单和QC检验合格报告的仓库一律拒绝收货)，请知悉，谢谢！ | AD2: sally Li | AH2: N/A | AI2: # | CD2: =BN2+BO2+BQ2+BS2+BR2 -> 0 | CE2: =BU2 -> 0 | CF2: =CC2 -> 0 | CG2: =BV2+BW2+BX2 -> 0
A3: 46029 | B3: ZURU NEW ZEALAND LIMITED | C3: 新西兰 | D3: 4500190798 | E3: 5200008655 | F3: 4500190798-10 | G3: 77772GQ2-S002-FS | H3: 唱片球25 pcs/PDQ/箱 | I3: 100 | J3: 0 | K3: 25 | L3: =I3/K3 -> 4 | M3: 46059 | N3: 46055 | P3: 试销单 | Q3: PASS | W3: 46029 | X3: 有 | Y3: 每箱需要增加一张黄色A4贴纸，印“fast start"。 | AC3: 日期码格式：ZURU INC(BVI) 标准格式 日期：按实际生产日期 Packaging Info: Remark: NZ Fast start order, 从PP PO中扣除，每款需要更换UPC贴纸，除常规箱唛外，每箱需要增加一张黄色A4贴纸，印“fast start"。 | AD3: SD92 | AE3: 1.27 | AF3: =I3*AE3 -> 127 | AH3: 77772GQ2-S002-3L | AI3: 已入 | AJ3: 系统入单 | AK3: =I3 -> 100 | AP3: =I3 -> 100 | BO3: =I3/25 -> 4 | CD3: =BN3+BO3+BQ3+BS3+BR3 -> 4 | CE3: =BU3 -> 0 | CF3: =CC3 -> 0 | CG3: =BV3+BW3+BX3 -> 0
A4: 46014 | B4: TARGET US | C4: 美国 | D4: 4500189603 | E4: 10001643491-3 890 | F4: 4500189603-10 | G4: 77772GQ5-S001 | H4: 唱片球25 pcs/PDQ/箱 | I4: 48750 | J4: 0 | K4: 25 | L4: =I4/K4 -> 1950 | M4: 46085 | N4: =M4-4 -> 46081 | Q4: PASS | R4: 3/16 提货 | T4: =9500+18000+21250 -> 48750 | U4: =T4-I4 -> 0 | V4: OK | W4: 46027 | X4: 有 | Y4: 1/22寄出 | AC4: 日期码格式：ZURU INC(BVI) 标准格式 日期：按实际生产日期 Packaging Info: 7772GQ5：产品包装MA 1L 收缩膜+MA 5L 收藏指南，客版PDQ Remark: 7772GQ5： 1.77772GQ5-S001-MINI BRANDS-VINYL-SERIES 1-CAPSULE,WITH DEMO,25PCS/GRAVITY PDQ,25PCS/PDQ/CTN； 2.产品包装MA 1L 收缩膜+MA 5L 收藏指南，客版PDQ； 3.产品UPC显示193052090065，Sweet Caroline Neil Diamond是TARGET独家款唱片； 4. 外箱正唛左上角位置粘贴条码箱贴纸，每箱只贴一张，由ZURU订购。来料贴纸上显示的客户DPCI# 086-02-8931, UPC显示10193052090062; 5. 外箱正唛箱唛内容右侧需贴一张EVENT LABEL，内容显示：TOYS SET DATE: 5/31/2026，由工厂自行订购； 6. 产品和包装上印刷 tracking code信息，格式为ZURU常规格式; 7. 出货方式：货代自提 | AD4: Holly Zheng | AE4: 1.29 | AF4: =I4*AE4 -> 62887.5 | AG4: ZB04936-8.17 | AH4: 77772GQ5-S001 | AI4: 已入 | AJ4: 系统入单 | AM4: =I4 -> 48750 | AN4: =I4 -> 48750 | AU4: =I4 -> 48750 | AV4: =I4*0.06 -> 2925 | BU4: =I4/25 -> 1950 | CD4: =BN4+BO4+BQ4+BS4+BR4 -> 0 | CE4: =BU4 -> 1950 | CF4: =CC4 -> 0 | CG4: =BV4+BW4+BX4 -> 0
A5: 46058 | D5: ZMPO260157 | F5: ZMPO260157-10 | G5: 77772-S001 | H5: 唱片球24 pcs/箱 | I5: 10套散件 | J5: 0 | K5: 24 | L5: 1 | M5: 46090 | N5: 46086 | Q5: PASS | U5: =T5-I5 -> #VALUE! | W5: 周转箱 | X5: 无 | Y5: 无 | AC5: Remark：大货最新版本/只需要齐套散件/麻烦用胶袋分装好一套为一袋/箱唛参照邮件附件 备注： 收到订单后请尽快安排，谢谢 | AD5: sally Li | AH5: N/A | AI5: # | CD5: =BN5+BO5+BQ5+BS5+BR5 -> 0 | CE5: =BU5 -> 0 | CF5: =CC5 -> 0 | CG5: =BV5+BW5+BX5 -> 0
A6: 46013 | B6: TARGET US | C6: 美国 | D6: 4500189608 | E6: 10001643496-3 890 | F6: 4500189608-10 | G6: 77772GQ5-S001 | H6: 唱片球25 pcs/PDQ/箱 | I6: 161250 | J6: 0 | K6: 25 | L6: =I6/K6 -> 6450 | M6: 46091 | N6: 46087 | Q6: PASS | R6: 3/23 提货 | T6: 161250 | U6: =T6-I6 -> 0 | V6: OK | W6: 46027 | X6: 有 | Y6: 1/22寄出 | AC6: 日期码格式：ZURU INC(BVI) 标准格式 日期：按实际生产日期 Packaging Info: 7772GQ5：产品包装MA 1L 收缩膜+MA 5L 收藏指南，客版PDQ Remark: 7772GQ5： 1.77772GQ5-S001-MINI BRANDS-VINYL-SERIES 1-CAPSULE,WITH DEMO,25PCS/GRAVITY PDQ,25PCS/PDQ/CTN； 2.产品包装MA 1L 收缩膜+MA 5L 收藏指南，客版PDQ； 3.产品UPC显示193052090065，Sweet Caroline Neil Diamond是TARGET独家款唱片； 4. 外箱正唛左上角位置粘贴条码箱贴纸，每箱只贴一张，由ZURU订购。来料贴纸上显示的客户DPCI# 086-02-8931, UPC显示10193052090062; 5. 产品和包装上印刷 tracking code信息，格式为ZURU常规格式; 6. 出货方式：货代自提 | AD6: Holly Zheng | AE6: 1.29 | AF6: =I6*AE6 -> 208012.5 | AG6: ZB04934-8.17 | AH6: 77772GQ5-S001 | AI6: 已入 | AJ6: 系统入单 | AM6: =I6 -> 161250 | AN6: =I6 -> 161250 | AU6: =I6 -> 161250 | AV6: =I6*0.06 -> 9675 | BU6: =I6/25 -> 6450 | CD6: =BN6+BO6+BQ6+BS6+BR6 -> 0 | CE6: =BU6 -> 6450 | CF6: =CC6 -> 0 | CG6: =BV6+BW6+BX6 -> 0
A7: 46043 | B7: SMYTHS TOYS HQ UC UK | C7: 英国 | D7: 4500191960 | E7: 4400528768 | F7: 4500191960-30 | G7: 77772GQ2-S001-PRODCC | H7: 唱片球50 pcs/2PDQ/箱 | I7: 10000 | J7: 0 | K7: 50 | L7: =I7/K7 -> 200 | M7: 46097 | N7: 46093 | Q7: PASS | R7: 3/23 出货 | T7: 10000 | U7: =T7-I7 -> 0 | V7: 无 | W7: 46044 | X7: 无 | Y7: 无 | Z7: 移除#21唱片 | AC7: 日期码格式：ZURU INC(BVI) 标准格式 日期：按实际生产日期 Packaging Info: 77772GQ2客版5L(英法德意荷)配套包装=MA PDQ (优先多语)+客版3L-5Lwarning收缩膜(翻PO#4500191961)+客版5L收藏指南(翻PO#4500191961)+MA 23L组装说明+MA 复合袋 EAN#4894680051133 77772GQ2必须移除Messy Lola Young (VINYL-S1-021) 这个唱片 ,比例按Una 更新的安排，如未按要求做货被客罚由工厂承担责任。 -------------------------------------------------------------------- Remark: Smyths 英国/爱尔兰 1. 请准时出货，推期会有罚款； 2. 所有产品按符合欧洲标准走货，需要是不含微塑料版本。 3.包装日期码按ZURU格式即可，请确保不迟于外箱日期码，可等于或者早于外箱日期码，必须为法定工作日，印刷前请先检查外箱日期码。 4.请注意检查产品及包装应带UKCA图标（14+产品除外），包装显示ZURU UK LTD/ZURU France地址信息，QC部门请查核，如有问题与跟单确认 5.电子产品需增加一张WEEE声明30L通用黑白说明书(不接受A版本，翻译有误)，区分带电池和不带电池出货版本, 如已做客版说明书可忽略此要求； 6.订单备注显示有分批的（不同仓库/订单号） ，注意分开做货出货，否则会导致罚款 。 7.做货前请先复核包装条码与订单是否一致再安排，对不上的需与ZURU跟单确认再安排。 | AD7: Sherry Lu | AE7: 1.007 | AF7: =I7*AE7 -> 10070 | AH7: 77772GQ2-S001-PRODCC | AI7: 已入 | AJ7: 系统入单 | AK7: =I7 -> 10000 | AV7: =I7*0.06 -> 600 | BG7: =I7 -> 10000 | BH7: =I7 -> 10000 | BO7: =I7/25 -> 400 | CD7: =BN7+BO7+BQ7+BS7+BR7 -> 400 | CE7: =BU7 -> 0 | CF7: =CC7 -> 0 | CG7: =BV7+BW7+BX7 -> 0
A8: 46084 | B8: ZURU NEW ZEALAND LIMITED | C8: 新西兰 | D8: 4500194964 | E8: 5200009119 | F8: 4500194964-10 | G8: 77772GQ2-S002-FS | H8: 唱片球25 pcs/PDQ/箱 | I8: 100 | J8: 0 | K8: 25 | L8: =I8/K8 -> 4 | M8: 46097 | N8: 46093 | Q8: PASS | R8: 3/19 出货 | T8: 100 | U8: =T8-I8 -> 0 | W8: 46029 | X8: 有 | Y8: 每箱需要增加一张黄色A4贴纸，印“fast start"。 | AC8: 日期码格式：ZURU INC(BVI) 标准格式 日期：按实际生产日期 Packaging Info: Remark: NZ Fast start order, 每款需要更换UPC贴纸，除常规箱唛外，每箱需要增加一张黄色A4贴纸，印"fast start"。 | AD8: SD92 | AE8: 1.27 | AF8: =I8*AE8 -> 127 | AH8: 77772GQ2-S002 | AI8: 已入 | AJ8: 系统入单 | AK8: =I8 -> 100 | AN8: =I8 -> 100 | AU8: =I8 -> 100 | AV8: =I8*0.06*2 -> 12 | BN8: =I8/25 -> 4 | CD8: =BN8+BO8+BQ8+BS8+BR8 -> 4 | CE8: =BU8 -> 0 | CF8: =CC8 -> 0 | CG8: =BV8+BW8+BX8 -> 0
A9: 46044 | B9: SMYTHS TOYS EU HQ UNLIMITED COMPANY | C9: 法国 | D9: 4500191989 | E9: 4400528766 | F9: 4500191989-10 | G9: MEC457-77772-S001 | H9: 唱片机+唱片球混装展示架 | I9: 3528 | J9: 0 | K9: 84 | L9: =I9/K9 -> 42 | M9: 46097 | N9: 46093 | Q9: PASS | R9: 4/6 出货 | T9: 3528 | U9: =T9-I9 -> 0 | W9: 46044 | X9: 有 | Y9: UN3481锂电池运输标签 | Z9: 移除#21唱片 | AC9: 日期码格式：ZURU INC(BVI) 标准格式 日期：按实际生产日期 Packaging Info: MEC457: 客版5L(英法德意荷)展示架[84pcs#77772+48pcs#77794; 所有客版资料翻PO#4500191961] 77772: 客版3L-5Lwarning收缩膜+客版5L收藏指南+MA 23L组装说明+MA复合袋 EAN#4894680051133 77794: 客版3L-5Lwarning纸盒底座+客版3L镭射贴纸+客版3L单铜纸贴纸+MA23L游戏说明书+MA23L warning说明书+1张WEEE声明(带电池)走货欧洲通用29L-C版说明 书 EAN#4894680051430 做货前请先核对条码无误 RECHARGEABLE LITHIUM BATTERY(INCLUDED) *#77772必须移除Messy Lola Young (VINYL-S1-021) 这个唱片, 比例按PM更新的安排* *展架上的Demo Box的唱片需要用"A Little Too Much"(VINYL-S1-025)替代原来的"Messy"(VINYL-S1-021)* *外箱需加一张UN3481锂电池运输标签* Remark: Smyths 法国 1. 请准时出货，推期会有罚款； 2. 所有产品按符合欧洲标准走货，需要是不含微塑料版本。 3. 电子产品需增加一张WEEE声明30L通用黑白说明书(不接受A版本，翻译有误)，区分带电池和不带电池出货版本, 如已做客版说明书可忽略此要求； 4. 出口法国的产品, 法规规定禁止在包装和共公众用的印刷品中使用矿物油中含有的物质, 包装印刷油墨中含有的MOAH/MOSH的质量浓度不能超过1%, 否则出货到 法国被抽检出现问题, 供应商需要对此负责; 5.订单备注显示有分批的（不同仓库/订单号） ，注意分开做货出货，否则会导致罚款 。 6.包装日期码按ZURU格式即可，请确保不迟于外箱日期码，可等于或者早于外箱日期码，必须为法定工作日。 7.做货前请先复核包装条码与订单是否一致再安排，对不上的需与ZURU跟单确认再安排。 | AD9: Sherry Lu | AE9: 306.676 | AF9: =L9*AE9 -> 12880.392 | AH9: MEC457-S001-77772 | AI9: 已入 | AJ9: 系统入单 | AK9: =I9 -> 3528 | AV9: =I9*0.06 -> 211.68 | BG9: =I9 -> 3528 | BH9: =I9 -> 3528 | BV9: =I9/K9 -> 42 | CD9: =BN9+BO9+BQ9+BS9+BR9 -> 0 | CE9: =BU9 -> 0 | CF9: =CC9 -> 0 | CG9: =BV9+BW9+BX9 -> 42
A10: 46044 | B10: SMYTHS TOYS EU HQ UNLIMITED COMPANY | C10: 法国 | D10: 4500191989 | E10: 4400528767 | F10: 4500191989-20 | G10: MEC457-77772-S001 | H10: 唱片机+唱片球混装展示架 | I10: 1512 | J10: 0 | K10: 84 | L10: =I10/K10 -> 18 | M10: 46097 | N10: 46093 | Q10: PASS | R10: 4/6 出货 | T10: 1512 | U10: =T10-I10 -> 0 | V10: 无 | W10: 46044 | X10: 无 | Y10: 无 | Z10: 移除#21唱片 | AC10: 日期码格式：ZURU INC(BVI) 标准格式 日期：按实际生产日期 Packaging Info: MEC457: 客版5L(英法德意荷)展示架[84pcs#77772+48pcs#77794; 所有客版资料翻PO#4500191961] 77772: 客版3L-5Lwarning收缩膜+客版5L收藏指南+MA 23L组装说明+MA复合袋 EAN#4894680051133 77794: 客版3L-5Lwarning纸盒底座+客版3L镭射贴纸+客版3L单铜纸贴纸+MA23L游戏说明书+MA23L warning说明书+1张WEEE声明(带电池)走货欧洲通用29L-C版说明 书 EAN#4894680051430 做货前请先核对条码无误 RECHARGEABLE LITHIUM BATTERY(INCLUDED) *#77772必须移除Messy Lola Young (VINYL-S1-021) 这个唱片, 比例按PM更新的安排* *展架上的Demo Box的唱片需要用"A Little Too Much"(VINYL-S1-025)替代原来的"Messy"(VINYL-S1-021)* *外箱需加一张UN3481锂电池运输标签* Remark: Smyths 法国 1. 请准时出货，推期会有罚款； 2. 所有产品按符合欧洲标准走货，需要是不含微塑料版本。 3. 电子产品需增加一张WEEE声明30L通用黑白说明书(不接受A版本，翻译有误)，区分带电池和不带电池出货版本, 如已做客版说明书可忽略此要求； 4. 出口法国的产品, 法规规定禁止在包装和共公众用的印刷品中使用矿物油中含有的物质, 包装印刷油墨中含有的MOAH/MOSH的质量浓度不能超过1%, 否则出货到 法国被抽检出现问题, 供应商需要对此负责; 5.订单备注显示有分批的（不同仓库/订单号） ，注意分开做货出货，否则会导致罚款 。 6.包装日期码按ZURU格式即可，请确保不迟于外箱日期码，可等于或者早于外箱日期码，必须为法定工作日。 7.做货前请先复核包装条码与订单是否一致再安排，对不上的需与ZURU跟单确认再安排。 | AD10: Sherry Lu | AE10: 306.676 | AF10: =L10*AE10 -> 5520.168 | AH10: MEC457-S001-77772 | AI10: 已入 | AJ10: 系统入单 | AK10: =I10 -> 1512 | AV10: =I10*0.06 -> 90.72 | BG10: =I10 -> 1512 | BH10: =I10 -> 1512 | BV10: =I10/K10 -> 18 | CD10: =BN10+BO10+BQ10+BS10+BR10 -> 0 | CE10: =BU10 -> 0 | CF10: =CC10 -> 0 | CG10: =BV10+BW10+BX10 -> 18
A11: 46044 | B11: SMYTHS TOYS EU HQ UNLIMITED COMPANY | C11: 法国 | D11: 4500191990 | E11: 4400528766 | F11: 4500191990-50 | G11: 77772GQ2-S001-PRODCC | H11: 唱片球50 pcs/2PDQ/箱 | I11: 1400 | J11: 0 | K11: 50 | L11: =I11/K11 -> 28 | M11: 46098 | N11: 46094 | Q11: PASS | R11: 4/7 出货 | T11: 1400 | U11: =T11-I11 -> 0 | V11: 无 | W11: 46044 | X11: 无 | Y11: 无 | Z11: 移除#21唱片 | AC11: 日期码格式：ZURU INC(BVI) 标准格式 日期：按实际生产日期 Packaging Info: 77772GQ2客版5L(英法德意荷)配套包装=MA PDQ (优先多语)+客版3L-5Lwarning收缩膜(翻PO#4500191961)+客版5L收藏指南(翻PO#4500191961)+MA 23L组装说明+MA 复合袋 EAN#4894680051133 77772GQ2必须移除Messy Lola Young (VINYL-S1-021) 这个唱片 ,比例按Una 更新的安排，如未按要求做货被客罚由工厂承担责任。 -------------------------------------------------------------------- Remark: Smyths 法国 1. 请准时出货，推期会有罚款； 2. 所有产品按符合欧洲标准走货，需要是不含微塑料版本。 3. 电子产品需增加一张WEEE声明30L通用黑白说明书(不接受A版本，翻译有误)，区分带电池和不带电池出货版本, 如已做客版说明书可忽略此要求； 4. 出口法国的产品, 法规规定禁止在包装和共公众用的印刷品中使用矿物油中含有的物质, 包装印刷油墨中含有的MOAH/MOSH的质量浓度不能超过1%, 否则出货到 法国被抽检出现问题, 供应商需要对此负责; 5.订单备注显示有分批的（不同仓库/订单号） ，注意分开做货出货，否则会导致罚款 。 6.包装日期码按ZURU格式即可，请确保不迟于外箱日期码，可等于或者早于外箱日期码，必须为法定工作日。 7.做货前请先复核包装条码与订单是否一致再安排，对不上的需与ZURU跟单确认再安排。 | AD11: Sherry Lu | AE11: 1.007 | AF11: =I11*AE11 -> 1409.8 | AH11: 77772GQ2-S001-PRODCC | AI11: 已入 | AJ11: 系统入单 | AK11: =I11 -> 1400 | AV11: =I11*0.06 -> 84 | BG11: =I11 -> 1400 | BH11: =I11 -> 1400 | BO11: =I11/25 -> 56 | CD11: =BN11+BO11+BQ11+BS11+BR11 -> 56 | CE11: =BU11 -> 0 | CF11: =CC11 -> 0 | CG11: =BV11+BW11+BX11 -> 0
A12: 46044 | B12: SMYTHS TOYS EU HQ UNLIMITED COMPANY | C12: 法国 | D12: 4500191990 | E12: 4400528767 | F12: 4500191990-60 | G12: 77772GQ2-S001-PRODCC | H12: 唱片球50 pcs/2PDQ/箱 | I12: 600 | J12: 0 | K12: 50 | L12: =I12/K12 -> 12 | M12: 46098 | N12: 46094 | Q12: PASS | R12: 4/7 出货 | T12: 600 | U12: =T12-I12 -> 0 | V12: 无 | W12: 46044 | X12: 无 | Y12: 无 | Z12: 移除#21唱片 | AC12: 日期码格式：ZURU INC(BVI) 标准格式 日期：按实际生产日期 Packaging Info: 77772GQ2客版5L(英法德意荷)配套包装=MA PDQ (优先多语)+客版3L-5Lwarning收缩膜(翻PO#4500191961)+客版5L收藏指南(翻PO#4500191961)+MA 23L组装说明+MA 复合袋 EAN#4894680051133 77772GQ2必须移除Messy Lola Young (VINYL-S1-021) 这个唱片 ,比例按Una 更新的安排，如未按要求做货被客罚由工厂承担责任。 -------------------------------------------------------------------- Remark: Smyths 法国 1. 请准时出货，推期会有罚款； 2. 所有产品按符合欧洲标准走货，需要是不含微塑料版本。 3. 电子产品需增加一张WEEE声明30L通用黑白说明书(不接受A版本，翻译有误)，区分带电池和不带电池出货版本, 如已做客版说明书可忽略此要求； 4. 出口法国的产品, 法规规定禁止在包装和共公众用的印刷品中使用矿物油中含有的物质, 包装印刷油墨中含有的MOAH/MOSH的质量浓度不能超过1%, 否则出货到 法国被抽检出现问题, 供应商需要对此负责; 5.订单备注显示有分批的（不同仓库/订单号） ，注意分开做货出货，否则会导致罚款 。 6.包装日期码按ZURU格式即可，请确保不迟于外箱日期码，可等于或者早于外箱日期码，必须为法定工作日。 7.做货前请先复核包装条码与订单是否一致再安排，对不上的需与ZURU跟单确认再安排。 | AD12: Sherry Lu | AE12: 1.007 | AF12: =I12*AE12 -> 604.2 | AH12: 77772GQ2-S001-PRODCC | AI12: 已入 | AJ12: 系统入单 | AK12: =I12 -> 600 | AV12: =I12*0.06 -> 36 | BG12: =I12 -> 600 | BH12: =I12 -> 600 | BO12: =I12/25 -> 24 | CD12: =BN12+BO12+BQ12+BS12+BR12 -> 24 | CE12: =BU12 -> 0 | CF12: =CC12 -> 0 | CG12: =BV12+BW12+BX12 -> 0
A13: 46043 | B13: SMYTHS TOYS HQ UC UK | C13: 英国 | D13: 4500191961 | E13: 4400528768 | F13: 4500191961-10 | G13: MEC457-77772-S001 | H13: 唱片机+唱片球混装展示架 | I13: 11172 | J13: 0 | K13: 84 | L13: =I13/K13 -> 133 | M13: 46098 | N13: 46094 | Q13: PASS | R13: 4/6 出货 | T13: 11172 | U13: =T13-I13 -> 0 | W13: 46044 | X13: 有 | Y13: UN3481锂电池运输标签 | Z13: 移除#21唱片 | AC13: 日期码格式：ZURU INC(BVI) 标准格式 日期：按实际生产日期 Packaging Info: MEC457: 客版5L(英法德意荷)展示架[84pcs#77772+48pcs#77794; 所有客版资料翻PO#4500191961] 77772: 客版3L-5Lwarning收缩膜+客版5L收藏指南+MA 23L组装说明+MA复合袋 EAN#4894680051133 77794: 客版3L-5Lwarning纸盒底座+客版3L镭射贴纸+客版3L单铜纸贴纸+MA23L游戏说明书+MA23L warning说明书+1张WEEE声明(带电池)走货欧洲通用29L-C版说明 书 EAN#4894680051430 做货前请先核对条码无误 RECHARGEABLE LITHIUM BATTERY(INCLUDED) *#77772必须移除Messy Lola Young (VINYL-S1-021) 这个唱片, 比例按PM更新的安排* *展架上的Demo Box的唱片需要用"A Little Too Much"(VINYL-S1-025)替代原来的"Messy"(VINYL-S1-021)* *外箱需加一张UN3481锂电池运输标签* Remark: Smyths 英国/爱尔兰 1. 请准时出货，推期会有罚款； 2. 所有产品按符合欧洲标准走货，需要是不含微塑料版本。 3.包装日期码按ZURU格式即可，请确保不迟于外箱日期码，可等于或者早于外箱日期码，必须为法定工作日，印刷前请先检查外箱日期码。 4.请注意检查产品及包装应带UKCA图标（14+产品除外），包装显示ZURU UK LTD/ZURU France地址信息，QC部门请查核，如有问题与跟单确认 5.电子产品需增加一张WEEE声明30L通用黑白说明书(不接受A版本，翻译有误)，区分带电池和不带电池出货版本, 如已做客版说明书可忽略此要求； 6.订单备注显示有分批的（不同仓库/订单号） ，注意分开做货出货，否则会导致罚款 。 7.做货前请先复核包装条码与订单是否一致再安排，对不上的需与ZURU跟单确认再安排。 | AD13: Sherry Lu | AE13: 306.676 | AF13: =L13*AE13 -> 40787.908 | AH13: MEC457-S001-77772 | AI13: 已入 | AJ13: 系统入单 | AK13: =I13 -> 11172 | AV13: =I13*0.06 -> 670.32 | BG13: =I13 -> 11172 | BH13: =I13 -> 11172 | BV13: =I13/K13 -> 133 | CD13: =BN13+BO13+BQ13+BS13+BR13 -> 0 | CE13: =BU13 -> 0 | CF13: =CC13 -> 0 | CG13: =BV13+BW13+BX13 -> 133
A14: 46044 | B14: SMYTHS TOYS EU HQ UC | C14: 德国 | D14: 4500191996 | E14: 4400528770 | F14: 4500191996-50 | G14: 77772GQ2-S001-PRODCC | H14: 唱片球50 pcs/2PDQ/箱 | I14: 1700 | J14: 0 | K14: 50 | L14: =I14/K14 -> 34 | M14: 46099 | N14: 46095 | Q14: PASS | R14: 3/24 出货 | T14: 1700 | U14: =T14-I14 -> 0 | V14: 无 | W14: 46044 | X14: 无 | Y14: 无 | Z14: 移除#21唱片 | AC14: 日期码格式：ZURU INC(BVI) 标准格式 日期：按实际生产日期 Packaging Info: 77772GQ2客版5L(英法德意荷)配套包装=MA PDQ (优先多语)+客版3L-5Lwarning收缩膜(翻PO#4500191961)+客版5L收藏指南(翻PO#4500191961)+MA 23L组装说明+MA 复合袋 EAN#4894680051133 77772GQ2必须移除Messy Lola Young (VINYL-S1-021) 这个唱片 ,比例按Una 更新的安排，如未按要求做货被客罚由工厂承担责任。 RECHARGEABLE LITHIUM BATTERY(INCLUDED) Remark: Smyths 德国 1. 请准时出货，推期会有罚款； 2. 所有产品按符合欧洲标准走货，需要是不含微塑料版本。 3. 所有电子产品身上需要加字唛，为ZURU FRANCE 地址 (如无电子产品，产品布标有此地址，或产品太小无法增加可忽略此信息)，新地址ZURU FRANCE.33 rue Pa ul Meurice 75020 Paris, France. 4. 电子产品需增加一张WEEE声明30L通用黑白说明书(不接受A版本，翻译有误)，区分带电池和不带电池出货版本, 如已做客版说明书可忽略此要求； 5.所有出往德国市场有关slime和带香味的都需要出无硼无香版本； 6.订单备注显示有分批的（不同仓库/订单号） ，注意分开做货出货，否则会导致罚款 。 7.包装日期码按ZURU格式即可，请确保不迟于外箱日期码，可等于或者早于外箱日期码，必须为法定工作日。 8.做货前请先复核包装条码与订单是否一致再安排，对不上的需与ZURU跟单确认再安排。 | AD14: Sherry Lu | AE14: 1.007 | AF14: =I14*AE14 -> 1711.9 | AH14: 77772GQ2-S001-PRODCC | AI14: 已入 | AJ14: 系统入单 | AK14: =I14 -> 1700 | AV14: =I14*0.06 -> 102 | BG14: =I14 -> 1700 | BH14: =I14 -> 1700 | BO14: =I14/25 -> 68 | CD14: =BN14+BO14+BQ14+BS14+BR14 -> 68 | CE14: =BU14 -> 0 | CF14: =CC14 -> 0 | CG14: =BV14+BW14+BX14 -> 0
A15: 46044 | B15: SMYTHS TOYS EU HQ UC | C15: 德国 | D15: 4500191996 | E15: 4400528771 | F15: 4500191996-60 | G15: 77772GQ2-S001-PRODCC | H15: 唱片球50 pcs/2PDQ/箱 | I15: 1300 | J15: 0 | K15: 50 | L15: =I15/K15 -> 26 | M15: 46099 | N15: 46095 | Q15: PASS | R15: 3/24 出货 | T15: 1300 | U15: =T15-I15 -> 0 | V15: 无 | W15: 46044 | X15: 无 | Y15: 无 | Z15: 移除#21唱片 | AC15: 日期码格式：ZURU INC(BVI) 标准格式 日期：按实际生产日期 Packaging Info: 77772GQ2客版5L(英法德意荷)配套包装=MA PDQ (优先多语)+客版3L-5Lwarning收缩膜(翻PO#4500191961)+客版5L收藏指南(翻PO#4500191961)+MA 23L组装说明+MA 复合袋 EAN#4894680051133 77772GQ2必须移除Messy Lola Young (VINYL-S1-021) 这个唱片 ,比例按Una 更新的安排，如未按要求做货被客罚由工厂承担责任。 RECHARGEABLE LITHIUM BATTERY(INCLUDED) Remark: Smyths 德国 1. 请准时出货，推期会有罚款； 2. 所有产品按符合欧洲标准走货，需要是不含微塑料版本。 3. 所有电子产品身上需要加字唛，为ZURU FRANCE 地址 (如无电子产品，产品布标有此地址，或产品太小无法增加可忽略此信息)，新地址ZURU FRANCE.33 rue Pa ul Meurice 75020 Paris, France. 4. 电子产品需增加一张WEEE声明30L通用黑白说明书(不接受A版本，翻译有误)，区分带电池和不带电池出货版本, 如已做客版说明书可忽略此要求； 5.所有出往德国市场有关slime和带香味的都需要出无硼无香版本； 6.订单备注显示有分批的（不同仓库/订单号） ，注意分开做货出货，否则会导致罚款 。 7.包装日期码按ZURU格式即可，请确保不迟于外箱日期码，可等于或者早于外箱日期码，必须为法定工作日。 8.做货前请先复核包装条码与订单是否一致再安排，对不上的需与ZURU跟单确认再安排。 | AD15: Sherry Lu | AE15: 1.007 | AF15: =I15*AE15 -> 1309.1 | AH15: 77772GQ2-S001-PRODCC | AI15: 已入 | AJ15: 系统入单 | AK15: =I15 -> 1300 | AV15: =I15*0.06 -> 78 | BG15: =I15 -> 1300 | BH15: =I15 -> 1300 | BO15: =I15/25 -> 52 | CD15: =BN15+BO15+BQ15+BS15+BR15 -> 52 | CE15: =BU15 -> 0 | CF15: =CC15 -> 0 | CG15: =BV15+BW15+BX15 -> 0
A16: 46044 | B16: SMYTHS TOYS EU HQ UC | C16: 德国 | D16: 4500191997 | E16: 4400528770 | F16: 4500191997-10 | G16: MEC457-77772-S001 | H16: 唱片机+唱片球混装展示架 | I16: 4872 | J16: 0 | K16: 84 | L16: =I16/K16 -> 58 | M16: 46100 | N16: 46097 | Q16: PASS | T16: 4872 | U16: =T16-I16 -> 0 | W16: 46044 | X16: 有 | Y16: UN3481锂电池运输标签 | Z16: 移除#21唱片 | AC16: 日期码格式：ZURU INC(BVI) 标准格式 日期：按实际生产日期 Packaging Info: MEC457: 客版5L(英法德意荷)展示架[84pcs#77772+48pcs#77794; 所有客版资料翻PO#4500191961] 77772: 客版3L-5Lwarning收缩膜+客版5L收藏指南+MA 23L组装说明+MA复合袋 EAN#4894680051133 77794: 客版3L-5Lwarning纸盒底座+客版3L镭射贴纸+客版3L单铜纸贴纸+MA23L游戏说明书+MA23L warning说明书+1张WEEE声明(带电池)走货欧洲通用29L-C版说明 书 EAN#4894680051430 做货前请先核对条码无误 RECHARGEABLE LITHIUM BATTERY(INCLUDED) *#77772必须移除Messy Lola Young (VINYL-S1-021) 这个唱片, 比例按PM更新的安排* *展架上的Demo Box的唱片需要用"A Little Too Much"(VINYL-S1-025)替代原来的"Messy"(VINYL-S1-021)* *外箱需加一张UN3481锂电池运输标签* Remark: Smyths 德国 1. 请准时出货，推期会有罚款； 2. 所有产品按符合欧洲标准走货，需要是不含微塑料版本。 3. 所有电子产品身上需要加字唛，为ZURU FRANCE 地址 (如无电子产品，产品布标有此地址，或产品太小无法增加可忽略此信息)，新地址ZURU FRANCE.33 rue Pa ul Meurice 75020 Paris, France. 4. 电子产品需增加一张WEEE声明30L通用黑白说明书(不接受A版本，翻译有误)，区分带电池和不带电池出货版本, 如已做客版说明书可忽略此要求； 5.所有出往德国市场有关slime和带香味的都需要出无硼无香版本； 6.订单备注显示有分批的（不同仓库/订单号） ，注意分开做货出货，否则会导致罚款 。 7.包装日期码按ZURU格式即可，请确保不迟于外箱日期码，可等于或者早于外箱日期码，必须为法定工作日。 8.做货前请先复核包装条码与订单是否一致再安排，对不上的需与ZURU跟单确认再安排。 | AD16: Sherry Lu | AE16: 306.676 | AF16: =L16*AE16 -> 17787.208 | AH16: MEC457-S001-77772 | AI16: 已入 | AJ16: 系统入单 | AK16: =I16 -> 4872 | AV16: =I16*0.06 -> 292.32 | BG16: =I16 -> 4872 | BH16: =I16 -> 4872 | BV16: =I16/K16 -> 58 | CD16: =BN16+BO16+BQ16+BS16+BR16 -> 0 | CE16: =BU16 -> 0 | CF16: =CC16 -> 0 | CG16: =BV16+BW16+BX16 -> 58
A17: 46044 | B17: SMYTHS TOYS EU HQ UC | C17: 德国 | D17: 4500191997 | E17: 4400528771 | F17: 4500191997-20 | G17: MEC457-77772-S001 | H17: 唱片机+唱片球混装展示架 | I17: 5628 | J17: 0 | K17: 84 | L17: =I17/K17 -> 67 | M17: 46100 | N17: 46097 | Q17: PASS | R17: 4/6 出货 | T17: 5628 | U17: =T17-I17 -> 0 | W17: 46044 | X17: 有 | Y17: UN3481锂电池运输标签 | Z17: 移除#21唱片 | AC17: 日期码格式：ZURU INC(BVI) 标准格式 日期：按实际生产日期 Packaging Info: MEC457: 客版5L(英法德意荷)展示架[84pcs#77772+48pcs#77794; 所有客版资料翻PO#4500191961] 77772: 客版3L-5Lwarning收缩膜+客版5L收藏指南+MA 23L组装说明+MA复合袋 EAN#4894680051133 77794: 客版3L-5Lwarning纸盒底座+客版3L镭射贴纸+客版3L单铜纸贴纸+MA23L游戏说明书+MA23L warning说明书+1张WEEE声明(带电池)走货欧洲通用29L-C版说明 书 EAN#4894680051430 做货前请先核对条码无误 RECHARGEABLE LITHIUM BATTERY(INCLUDED) *#77772必须移除Messy Lola Young (VINYL-S1-021) 这个唱片, 比例按PM更新的安排* *展架上的Demo Box的唱片需要用"A Little Too Much"(VINYL-S1-025)替代原来的"Messy"(VINYL-S1-021)* *外箱需加一张UN3481锂电池运输标签* Remark: Smyths 德国 1. 请准时出货，推期会有罚款； 2. 所有产品按符合欧洲标准走货，需要是不含微塑料版本。 3. 所有电子产品身上需要加字唛，为ZURU FRANCE 地址 (如无电子产品，产品布标有此地址，或产品太小无法增加可忽略此信息)，新地址ZURU FRANCE.33 rue Pa ul Meurice 75020 Paris, France. 4. 电子产品需增加一张WEEE声明30L通用黑白说明书(不接受A版本，翻译有误)，区分带电池和不带电池出货版本, 如已做客版说明书可忽略此要求； 5.所有出往德国市场有关slime和带香味的都需要出无硼无香版本； 6.订单备注显示有分批的（不同仓库/订单号） ，注意分开做货出货，否则会导致罚款 。 7.包装日期码按ZURU格式即可，请确保不迟于外箱日期码，可等于或者早于外箱日期码，必须为法定工作日。 8.做货前请先复核包装条码与订单是否一致再安排，对不上的需与ZURU跟单确认再安排。 | AD17: Sherry Lu | AE17: 306.676 | AF17: =L17*AE17 -> 20547.292 | AH17: MEC457-S001-77772 | AI17: 已入 | AJ17: 系统入单 | AK17: =I17 -> 5628 | AV17: =I17*0.06 -> 337.68 | BG17: =I17 -> 5628 | BH17: =I17 -> 5628 | BV17: =I17/K17 -> 67 | CD17: =BN17+BO17+BQ17+BS17+BR17 -> 0 | CE17: =BU17 -> 0 | CF17: =CC17 -> 0 | CG17: =BV17+BW17+BX17 -> 67
A18: 46045 | B18: UPD, INC. | C18: 美国 | D18: 4500192208 | E18: 36244 | F18: 4500192208-10 | G18: 77772GQ1-S001 | H18: 唱片球52pcs/4PDQ/箱 | I18: 936 | J18: 0 | K18: 52 | L18: =I18/K18 -> 18 | M18: 46108 | N18: 46104 | Q18: PASS | R18: 3/30 出货 | T18: 936 | U18: =T18-I18 -> 0 | V18: 无 | W18: 46078 | X18: 无 | Y18: 无 | AC18: 日期码格式：ZURU INC(BVI) 标准格式 日期：按实际生产日期 Packaging Info: 1. 包装方式：MA UPC 优先1L 最新包装，出口美国 Remark: 2. 外箱箱唛红色和黑色双色印刷 3. 产品和包装上印刷tracking code信息，格式为ZURU常规 | AD18: Angel Lin | AE18: 0.6198 | AF18: =I18*AE18 -> 580.1328 | AG18: ZB04945-8.17 | AH18: 77772GQ1-S001 | AI18: 已入 | AJ18: 系统入单 | AK18: =I18 -> 936 | AN18: =I18 -> 936 | AU18: =I18 -> 936 | AV18: =I18*0.06 -> 56.16 | BK18: =I18/13 -> 72 | CD18: =BN18+BO18+BQ18+BS18+BR18 -> 0 | CE18: =BU18 -> 0 | CF18: =CC18 -> 0 | CG18: =BV18+BW18+BX18 -> 0
A19: 46062 | B19: ZURU LLC | C19: 美国 | D19: 4500193475 | E19: 5200009006 | F19: 4500193475-30 | G19: 77772GQ2-S001-FS | H19: 唱片球50 pcs/2PDQ/箱 | I19: 750 | J19: 0 | K19: 50 | L19: =I19/K19 -> 15 | M19: 46108 | N19: 46104 | Q19: PASS | R19: 4/4 出货 | T19: 750 | U19: =T19-I19 -> 0 | V19: OK | W19: 46062 | X19: 有 | Y19: 2/12客版UPC贴纸 | AC19: 日期码格式：ZURU DGYYYYMMDD CHINA(日期避开周末和法定节假日即可） 日期：按实际生产日期 Packaging Info: 1.产品包装要求： 77772GQ2：MA 1L收缩膜+MA 1L PDQ+MA收藏指南+客版UPC贴纸 2.NO RFID – 不需要RFID NEW UPC 与STD 不同， 需加贴NEW UPC贴纸。贴前须用黑色笔将原 UPC 码完全涂黑，使其无法扫描，再粘贴新 UPC 贴纸。 Remark: FAST START 项目要求 1.产品包装要求： 77772GQ2：MA 1L收缩膜+MA 1L PDQ+MA收藏指南+客版UPC贴纸 2.NO RFID – 不需要RFID NEW UPC 与STD 不同， 需加贴NEW UPC贴纸。贴前须用黑色笔将原 UPC 码完全涂黑，使其无法扫描，再粘贴新 UPC 贴纸。 新UPC 如下： SKU Fast Start SPEC# Description UPC GTIN 77772 77772GQ2-S001-FS MINI BRANDS VINYL S1 193052110282 10193052110289 3.外箱唛参考提供的模版，排版供确认后，才能生产。 4.此MTS订单不需要第三方抽板验货，但是要通过ZURU QC验货PASS后才能出货。 空运到3PL仓库。 | AD19: SD62 | AE19: 0.6042 | AF19: =I19*AE19 -> 453.15 | AG19: ZB05281-8.17 | AH19: 77772GQ2-S001 | AI19: 已入 | AJ19: 系统入单 | AK19: =I19 -> 750 | AN19: =I19 -> 750 | AU19: =I19 -> 750 | AV19: =I19*0.06 -> 45 | BN19: =I19/25 -> 30 | CD19: =BN19+BO19+BQ19+BS19+BR19 -> 30 | CE19: =BU19 -> 0 | CF19: =CC19 -> 0 | CG19: =BV19+BW19+BX19 -> 0
A20: 46044 | B20: SMYTHS TOYS HQ UC UK | C20: 英国 | D20: 4500192013 | E20: 4400530471 | F20: 4500192013-20 | G20: 77772GQ2-S001-PRODCC | H20: 唱片球50 pcs/2PDQ/箱 | I20: 10000 | J20: 0 | K20: 50 | L20: =I20/K20 -> 200 | M20: 46112 | N20: 46108 | Q20: PASS | R20: 4/6 出货 | T20: 10000 | U20: =T20-I20 -> 0 | V20: 无 | W20: 46044 | X20: 无 | Y20: 无 | Z20: 移除#21唱片 | AC20: 日期码格式：ZURU INC(BVI) 标准格式 日期：按实际生产日期 Packaging Info: 77772GQ2客版5L(英法德意荷)配套包装=MA PDQ (优先多语)+客版3L-5Lwarning收缩膜(翻PO#4500191961)+客版5L收藏指南(翻PO#4500191961)+MA 23L组装说明+MA 复合袋 EAN#4894680051133 77772GQ2必须移除Messy Lola Young (VINYL-S1-021) 这个唱片 ,比例按Una 更新的安排，如未按要求做货被客罚由工厂承担责任。 Remark: Smyths 英国/爱尔兰 1. 请准时出货，推期会有罚款； 2. 所有产品按符合欧洲标准走货，需要是不含微塑料版本。 3.包装日期码按ZURU格式即可，请确保不迟于外箱日期码，可等于或者早于外箱日期码，必须为法定工作日，印刷前请先检查外箱日期码。 4.请注意检查产品及包装应带UKCA图标（14+产品除外），包装显示ZURU UK LTD/ZURU France地址信息，QC部门请查核，如有问题与跟单确认 5.电子产品需增加一张WEEE声明30L通用黑白说明书(不接受A版本，翻译有误)，区分带电池和不带电池出货版本, 如已做客版说明书可忽略此要求； 6.订单备注显示有分批的（不同仓库/订单号） ，注意分开做货出货，否则会导致罚款 。 7.做货前请先复核包装条码与订单是否一致再安排，对不上的需与ZURU跟单确认再安排。 | AD20: Sherry Lu | AE20: 1.007 | AF20: =I20*AE20 -> 10070 | AH20: 77772GQ2-S001-PRODCC | AI20: 已入 | AJ20: 系统入单 | AK20: =I20 -> 10000 | AV20: =I20*0.06 -> 600 | BG20: =I20 -> 10000 | BH20: =I20 -> 10000 | BO20: =I20/25 -> 400 | CD20: =BN20+BO20+BQ20+BS20+BR20 -> 400 | CE20: =BU20 -> 0 | CF20: =CC20 -> 0 | CG20: =BV20+BW20+BX20 -> 0
A21: 46045 | B21: ZURU GERMANY GMBH | C21: 德国 | D21: 4500192187 | E21: 5200008729 | F21: 4500192187-10 | G21: 77772GQ1-S002-MTS | H21: 唱片球13 pcs/PDQ/箱 | I21: 15600 | J21: 0 | K21: 13 | L21: =I21/K21 -> 1200 | M21: 46112 | N21: 46108 | Q21: PASS | R21: 4/2 出货 | T21: 15600 | U21: =T21-I21 -> 0 | W21: 46364 | X21: 无 | Y21: 46092 | Z21: 外箱日期码要晚于或等于产品日期码，不能早于产品的日期码 | AC21: 日期码格式：ZURU INC(BVI) 标准格式 日期：按实际生产日期 Packaging Info: 77772GQ1：MA 3L PDQ+MA 3L EAN收缩膜+1*多语警语折叠贴纸+MA 23L拼装说明书+MA 5L收藏指南+MA纸卡/复合袋 Remark: 1.德国内销单，需要通过ZURU 验货结果后才能出货 (工厂需要主动提前同ZURU QC预约验货避免延期出货造成不必要麻烦)； 2.产品如含有化学品（slime 等），需要无硼无香。需要无微塑料版本。 3.所有出口欧洲的产品, 法规规定禁止在包装和共公众用的印刷品中使用矿物油中含有的物质, 包装印刷油墨中含有的MOAH/MOSH的质量浓度不能超过1%, 否则出货 到法国被抽检出现问题, 供应商需要对此负责; 4. date code: 外箱日期码要晚于或等于产品日期码，不能早于产品的日期码； 5. 所有出往德国的电子产品身上需要加字唛，为ZURU FRANCE 地址，需跟包装上的地址一致 (如无电子产品，产品布标有此地址，或产品太小无法增加可忽略此信 息。如产品无法加字唛，需让对应跟单提供产品贴纸资料) 新地址：ZURU France 33 rue Paul Meurice 75020 Paris, France 旧地址：ZURU France 1/3, Rue d'Argenteuil 95210 SAINT-GRATIEN, FRANCE 6.所有出往德国订单的电子产品需增加一张欧洲通用WEEE声明说明书，区分带电池和不带电池版本, 如已做客版说明书可忽略此要求。 7.装柜时需要按照款式号码从小到大一款款依次装,避免终端仓库卸货混乱.若一个柜子涉及到几个不同国家内销单,装柜时需要一个国家装完后再装另一个国家的 产品,依次装柜,避免终端仓库因不同国家不同库位位置卸货混乱. (此点需要同工厂装柜人员强调)" 8.ratio 同MA 9. 若有特定款有特殊外箱条码要求时,需要明确列出产品款对应的具体外箱条码号码/条码类型 (若无,可以忽略此需求). | AD21: SD04 | AE21: 2.02 | AF21: =I21*AE21 -> 31512 | AH21: 77772GQ1-S002-3L | AI21: 已入 | AJ21: 系统入单 | AK21: =I21 -> 15600 | AP21: =I21 -> 15600 | AU21: =I21 -> 15600 | AV21: =I21*0.06 -> 936 | BL21: =I21/13 -> 1200 | CD21: =BN21+BO21+BQ21+BS21+BR21 -> 0 | CE21: =BU21 -> 0 | CF21: =CC21 -> 0 | CG21: =BV21+BW21+BX21 -> 0
A22: 46057 | B22: INDIGO CANADA | C22: 加拿大 | D22: 4500193076 | E22: 4552042232 | F22: 4500193076-10 | G22: 77772GQ2-S002 | H22: 唱片球25 pcs/PDQ/箱 | I22: 7500 | J22: 0 | K22: 25 | L22: =I22/K22 -> 300 | M22: 46114 | N22: 46111 | Q22: PASS | R22: 4/6 出货 | S22: 1903076 | T22: 7500 | U22: =T22-I22 -> 0 | V22: OK | W22: 46097 | X22: 有 | Y22: 46098 | AC22: 日期码格式： 标准格式 日期：按实际生产日期 Packaging Info: 77772GQ2 MA 3L EAN版本+UPC贴纸193052090065 Remark: 出加拿大 有价格贴纸 (Low Tack ,must peel off easily without leaving adhesive residue) 有shipping label (贴4面） Zuru验货.日期跟踪码：产品外包装及产品本身都必须有日期跟踪码，ZURU标准格式日期码。 | AD22: Bella Tan | AE22: 1.094 | AF22: =I22*AE22 -> 8205 | AH22: 77772GQ2-S002-3L | AI22: 已入 | AJ22: 系统入单 | AK22: =I22 -> 7500 | AP22: =I22 -> 7500 | AU22: =I22 -> 7500 | AV22: =I22*0.06 -> 450 | BO22: =I22/25 -> 300 | CD22: =BN22+BO22+BQ22+BS22+BR22 -> 300 | CE22: =BU22 -> 0 | CF22: =CC22 -> 0 | CG22: =BV22+BW22+BX22 -> 0
A23: 46081 | B23: TARGET US | C23: 美国 | D23: 4500194699 | E23: 10001764946-0 581 | F23: 4500194699-10 | G23: 77772GQ5-S001 | H23: 唱片球25 pcs/PDQ/箱 | I23: 55000 | J23: 0 | K23: 25 | L23: =I23/K23 -> 2200 | M23: 46118 | N23: 46114 | Q23: PASS | T23: 55000 | U23: =T23-I23 -> 0 | V23: OK | W23: 3/13确认 | X23: 有 | Y23: 3/25寄出 | AC23: 日期码格式：ZURU INC(BVI) 标准格式 日期：按实际生产日期 Packaging Info: 产品包装MA 1L 收缩膜+MA 5L 收藏指南+MA 23L 组装说明+客版PDQ；客版PDQ翻单4500189603 Remark: 1.77772GQ5-S001-MINI BRANDS-VINYL-SERIES 1-CAPSULE,WITH DEMO,25PCS/GRAVITY PDQ,25PCS/PDQ/CTN; 2.产品包装MA 1L 收缩膜+MA 5L 收藏指南+MA 23L 组装说明+客版PDQ；客版PDQ翻单4500189603；收缩膜上的UPC显示193052090065; 4 mini vinyls(1 Target US Exclusive),1 accessory; 3. 外箱正唛左上角位置粘贴条码箱贴纸，每箱只贴一张，由ZURU订购。来料贴纸上显示的客户DPCI# 086-02-8931, UPC显示10193052090062; 4. 产品和包装上均要印刷tracking code信息，格式为ZURU常规格式; 5. 需要我司QC验货之后才能安排出货; 6. 出货方式： 货代自提 | AD23: Holly Zheng | AE23: 1.29 | AF23: =I23*AE23 -> 70950 | AG23: ZB05068-8.17 | AH23: 77772GQ5-S001 | AI23: 已入 | AJ23: 系统入单 | AM23: =I23 -> 55000 | AN23: =I23 -> 55000 | AU23: =I23 -> 55000 | AV23: =I23*0.06 -> 3300 | BU23: =I23/25 -> 2200 | CD23: =BN23+BO23+BQ23+BS23+BR23 -> 0 | CE23: =BU23 -> 2200 | CF23: =CC23 -> 0 | CG23: =BV23+BW23+BX23 -> 0
A24: 46059 | B24: TARGET US | C24: 美国 | D24: 4500190738 | E24: 10001661694-3891 | F24: 4500190738-50 | G24: 77772GQ5-S001 | H24: 唱片球25 pcs/PDQ/箱 | I24: 21375 | J24: 0 | K24: 25 | L24: =I24/K24 -> 855 | M24: 46119 | N24: 46115 | Q24: PASS | T24: 21375 | U24: =T24-I24 -> 0 | W24: 3/2确认 | X24: 有 | Y24: 3/25寄出 | AC24: 日期码格式：ZURU INC(BVI) 标准格式 日期：按实际生产日期 Packaging Info: 77772GQ5：产品包装MA 1L 收缩膜+MA 5L 收藏指南+MA 23L 组装说明+客版PDQ；客版PDQ翻单4500189603；收缩膜上的UPC显示193052090065; 77794UQ1：产品包装 MA 1L黑白警告语说明书+MA 1L 彩盒+MA 1L PDQ; 彩盒上的UPC显示193052090409; Remark: 77772GQ5： 1.77772GQ5-S001-MINI BRANDS-VINYL-SERIES 1-CAPSULE,WITH DEMO,25PCS/GRAVITY PDQ,25PCS/PDQ/CTN; 2.产品包装MA 1L 收缩膜+MA 5L 收藏指南+MA 23L 组装说明+客版PDQ；客版PDQ翻单4500189603；收缩膜上的UPC显示193052090065; 4 mini vinyls(1 Target US Exclusive),1 accessory; 3. 外箱正唛左上角位置粘贴条码箱贴纸，每箱只贴一张，由ZURU订购。来料贴纸上显示的客户DPCI# 086-02-8931, UPC显示10193052090062; 4. 外箱正唛箱唛内容右侧需贴一张EVENT LABEL，内容显示 7/19 TRANSITION TOYS Set Date 7/19/2026，由工厂自行订购； 以上Items： 1. 产品和包装上均要印刷tracking code信息，格式为ZURU常规格式； 2. 需要我司QC验货之后才能安排出货 3. 出货方式： 货代自提 | AD24: Holly Zheng | AE24: 1.29 | AF24: =I24*AE24 -> 27573.75 | AG24: ZB05310-8.17 | AH24: 77772GQ5-S001 | AI24: 已入 | AJ24: 系统入单 | AM24: =I24 -> 21375 | AN24: =I24 -> 21375 | AU24: =I24 -> 21375 | AV24: =I24*0.06 -> 1282.5 | BU24: =I24/25 -> 855 | CD24: =BN24+BO24+BQ24+BS24+BR24 -> 0 | CE24: =BU24 -> 855 | CF24: =CC24 -> 0 | CG24: =BV24+BW24+BX24 -> 0
A25: 46061 | B25: ASIA GOAL LIMITED TAIWAN BRANCH (H. | C25: 台湾 | D25: 4500193384 | E25: AG250405-TW | F25: 4500193384-10 | G25: 77772GQ1-S001 | H25: 唱片球52pcs/4PDQ/箱 | I25: 780 | J25: 0 | K25: 52 | L25: =I25/K25 -> 15 | M25: 46120 | N25: 46116 | Q25: PASS | T25: 780 | U25: =T25-I25 -> 0 | V25: OK | W25: 46067 | X25: 无 | Y25: 3/23 警语贴纸 | AC25: 日期码格式：ZURU INC(BVI) 标准格式 日期：按实际生产日期 Packaging Info: 此单出TW 77772GQ1/77794UQ1: MA PKG,优先1L + 1张警语贴纸 Remark: | AD25: Chelsea Luo | AE25: 1.033 | AF25: =I25*AE25 -> 805.74 | AH25: 77772GQ1-S001 | AI25: 已入 | AJ25: 系统入单 | AK25: =I25 -> 780 | AN25: =I25 -> 780 | AU25: =I25 -> 780 | AV25: =I25*0.06 -> 46.8 | BK25: =I25/13 -> 60 | CD25: =BN25+BO25+BQ25+BS25+BR25 -> 0 | CE25: =BU25 -> 0 | CF25: =CC25 -> 0 | CG25: =BV25+BW25+BX25 -> 0
A26: 46061 | B26: ASIA GOAL LIMITED | C26: 台湾 | D26: 4500193379 | E26: AG250404-HK | F26: 4500193379-10 | G26: 77772GQ1-S001 | H26: 唱片球52pcs/4PDQ/箱 | I26: 780 | J26: 0 | K26: 52 | L26: =I26/K26 -> 15 | M26: 46120 | N26: 46116 | Q26: PASS | T26: 780 | U26: =T26-I26 -> 0 | V26: OK | W26: 46067 | X26: 无 | Y26: 3/23 警语贴纸 | AC26: 日期码格式：ZURU INC(BVI) 标准格式 日期：按实际生产日期 Packaging Info: 77772GQ1: MA 1L PKG ，PDQ , MA 收藏指南，说明书+HK 客供警语贴纸 Remark: 此单出HK | AD26: Chelsea Luo | AE26: 1.033 | AF26: =I26*AE26 -> 805.74 | AH26: 77772GQ1-S001 | AI26: 已入 | AJ26: 系统入单 | AK26: =I26 -> 780 | AN26: =I26 -> 780 | AU26: =I26 -> 780 | AV26: =I26*0.06 -> 46.8 | BK26: =I26/13 -> 60 | CD26: =BN26+BO26+BQ26+BS26+BR26 -> 0 | CE26: =BU26 -> 0 | CF26: =CC26 -> 0 | CG26: =BV26+BW26+BX26 -> 0
A27: 46081 | B27: TARGET US | C27: 美国 | D27: 4500194700 | E27: 10001764947-0 581 | F27: 4500194700-10 | G27: 77772GQ5-S001 | H27: 唱片球25 pcs/PDQ/箱 | I27: 55000 | J27: 0 | K27: 25 | L27: =I27/K27 -> 2200 | M27: 46125 | N27: 46121 | Q27: PASS | T27: 55000 | U27: =T27-I27 -> 0 | W27: 46094 | X27: 有 | Y27: 3/24外箱条码箱贴纸贴纸，2/10提供EVENT LABEL | AC27: 日期码格式：ZURU INC(BVI) 标准格式 日期：按实际生产日期 Packaging Info: 产品包装MA 1L 收缩膜+MA 5L 收藏指南+MA 23L 组装说明+客版PDQ；客版PDQ翻单4500189603 Remark: 1.77772GQ5-S001-MINI BRANDS-VINYL-SERIES 1-CAPSULE,WITH DEMO,25PCS/GRAVITY PDQ,25PCS/PDQ/CTN; 2.产品包装MA 1L 收缩膜+MA 5L 收藏指南+MA 23L 组装说明+客版PDQ；客版PDQ翻单4500189603；收缩膜上的UPC显示193052090065; 4 mini vinyls(1 Target US Exclusive),1 accessory; 3. 外箱正唛左上角位置粘贴条码箱贴纸，每箱只贴一张，由ZURU订购。来料贴纸上显示的客户DPCI# 086-02-8931, UPC显示10193052090062; 4. 产品和包装上均要印刷tracking code信息，格式为ZURU常规格式; 5. 需要我司QC验货之后才能安排出货; 6. 出货方式： 货代自提 | AD27: Holly Zheng | AE27: 1.29 | AF27: =I27*AE27 -> 70950 | AH27: 77772GQ5-S001 | AI27: 已入 | AJ27: 系统入单 | AM27: =I27 -> 55000 | AN27: =I27 -> 55000 | AU27: =I27 -> 55000 | AV27: =I27*0.06 -> 3300 | BU27: =I27/25 -> 2200 | CD27: =BN27+BO27+BQ27+BS27+BR27 -> 0 | CE27: =BU27 -> 2200 | CF27: =CC27 -> 0 | CG27: =BV27+BW27+BX27 -> 0
A28: 46065 | B28: KANDYTOYS LIMITED | C28: 英国 | D28: 4500193688 | E28: AS191225ZUR15 274 | F28: 4500193688-20 | G28: 77772GQ2-S001-PRODCC | H28: 唱片球50 pcs/2PDQ/箱 | I28: 3750 | J28: 0 | K28: 50 | L28: =I28/K28 -> 75 | M28: 46125 | N28: 46121 | Q28: PASS | T28: 3750 | U28: =T28-I28 -> 0 | V28: OK | W28: 3/23确认 | X28: 无 | Y28: 3/25PDQ条码贴纸 | Z28: 移除#21唱片 | AC28: 日期码格式：ZURU INC(BVI) 标准格式 日期：按实际生产日期 Packaging Info: 77772GQ2-S001:MA UPC包装+MA PDQ+一张PDQ条码贴纸(位置:PDQ底部贴一张可扫描的条码贴纸(ZURU 跟单提供模板) 77772GQ2 出UK，配比：4 mini vinyls(去掉 Lola Young vinyl),1 accessory； 其他款配比按MA标准 Remark: 1.订单出英国，请注意检查产品及包装应带UKCA图标，包装需要显示ZURU UK LTD/ZURU France地址信息，QC同事请查核，如有问题与跟单确认。 2.生产日期按实际的（法定工作日），按ZURU标准格式即可 ，并需要在出货前提供每个产品外包上对应的生产日期明细 3.请注意所有订单都需要经过ZURU QC验货并且通过后方可出货 4.一个产品一个条码，单款有多个子件条码的请让跟单提供贴纸覆盖。 5.外箱上的条码请确保清晰可扫描，有PDQ， 需要在PDQ底部贴一张带条码并可扫描的贴纸(ZURU 跟单提供模板）。 6.所有产品按符合欧洲标准走货，微塑料需合规并增加IFUD声明，含电池的需要增加WEEE说明书。 | AD28: Zoe Zhou | AE28: 1.007 | AF28: =I28*AE28 -> 3776.25 | AH28: 77772GQ2-S001 | AI28: 已入 | AJ28: 系统入单 | AK28: =I28 -> 3750 | AN28: =I28 -> 3750 | AU28: =I28 -> 3750 | AV28: =I28*0.06 -> 225 | BN28: =I28/25 -> 150 | CD28: =BN28+BO28+BQ28+BS28+BR28 -> 150 | CE28: =BU28 -> 0 | CF28: =CC28 -> 0 | CG28: =BV28+BW28+BX28 -> 0
A29: 46079 | B29: MINISO DEPOT CA INC. | C29: 美国 | D29: 4500194334 | E29: 4360138834 | F29: 4500194334-60 | G29: 77772GQ2-S002 | H29: 唱片球25 pcs/PDQ/箱 | I29: 9100 | J29: 0 | K29: 25 | L29: =I29/K29 -> 364 | M29: 46126 | N29: 46122 | Q29: PASS | T29: 9100 | U29: =T29-I29 -> 0 | V29: OK | W29: 46094 | X29: 无 | Y29: 3/13提供PDQUPC 条码贴纸 | AC29: 日期码格式：ZURU INC(BVI) 标准格式 日期：按实际生产日期 Packaging Info: 1. 包装方式：MA UPC优先1L最新包装，出口美国； 2. 产品和包装上印刷tracking code信息，格式为ZURU常规； 3. ZURU QC 验货合格后即可出货. Remark: 6. 77772GQ2-S002 PDQ上需要贴一张UPC 条码贴纸,UPC显示：193052090065，贴纸AW跟单提供，工厂自行采购; | AD29: Iris Yuan | AE29: 0.762 | AF29: =I29*AE29 -> 6934.2 | AG29: ZB05283-8.17 | AH29: 77772GQ2-S002 | AI29: 已入 | AJ29: 系统入单 | AK29: =I29 -> 9100 | AN29: =I29 -> 9100 | AU29: =I29 -> 9100 | AV29: =I29*0.06 -> 546 | BN29: =I29/25 -> 364 | CD29: =BN29+BO29+BQ29+BS29+BR29 -> 364 | CE29: =BU29 -> 0 | CF29: =CC29 -> 0 | CG29: =BV29+BW29+BX29 -> 0
A30: 46079 | B30: MINISO DEPOT CA INC. | C30: 美国 | D30: 4500194341 | E30: 4360138853 | F30: 4500194341-60 | G30: 77772GQ2-S002 | H30: 唱片球25 pcs/PDQ/箱 | I30: 7275 | J30: 0 | K30: 25 | L30: =I30/K30 -> 291 | M30: 46126 | N30: 46122 | Q30: PASS | T30: 7275 | U30: =T30-I30 -> 0 | V30: OK | W30: 46094 | X30: 无 | Y30: 3/13提供PDQUPC 条码贴纸 | AC30: 日期码格式：ZURU INC(BVI) 标准格式 日期：按实际生产日期 Packaging Info: 1. 包装方式：MA UPC优先1L最新包装，出口美国； 2. 产品和包装上印刷tracking code信息，格式为ZURU常规； 3. ZURU QC 验货合格后即可出货. Remark: 7. 77772GQ2-S002 PDQ上需要贴一张UPC 条码贴纸,UPC显示：193052090065，贴纸AW跟单提供，工厂自行采购; | AD30: Iris Yuan | AE30: 0.762 | AF30: =I30*AE30 -> 5543.55 | AG30: ZB05205-8.17 | AH30: 77772GQ2-S002 | AI30: 已入 | AJ30: 系统入单 | AK30: =I30 -> 7275 | AN30: =I30 -> 7275 | AU30: =I30 -> 7275 | AV30: =I30*0.06 -> 436.5 | BN30: =I30/25 -> 291 | CD30: =BN30+BO30+BQ30+BS30+BR30 -> 291 | CE30: =BU30 -> 0 | CF30: =CC30 -> 0 | CG30: =BV30+BW30+BX30 -> 0
A31: 46030 | B31: CRACKER BARREL | C31: 美国 | D31: 4500188838 | E31: 277707 | F31: 4500188838-20 | G31: 77772GQ4-S001 | H31: 唱片球6 pcs/PDQ/箱 | I31: 4002 | J31: 0 | K31: 6 | L31: =I31/K31 -> 667 | M31: 46127 | N31: 46123 | P31: 4/3完成25%大货包装第三方抽板测试，4/15完成100%大货 | Q31: PASS | T31: =1008+2958+36 -> 4002 | U31: =T31-I31 -> 0 | V31: OK | W31: 3/5 确认 | X31: 无 | Y31: 3/3客供价格贴纸 | AB31: A.样板抽取12pcs/每款/每色（带包装，大货中抽取）。 B.产品上有涂层的，需额外准备足够的干油墨（每个颜色2个A4尺寸的喷涂样本，涂层喷到同底材，涂满涂厚，至少能刮取30mg的量）。 4. 外箱贴打印常规 4"x6" Standard Label Stock, 只需贴一面(正唛）, 优先贴在纸箱的右上方空白处，不可以盖住外箱上的其他信息及标签，可适当调整位置。 5. 样板需求（77794UQ1 & 77772GQ4）： 1)产前样+Model Store Sample: 请在4/1前寄出每款每色各8pcs大货样（不带PDQ，需贴客版价格贴纸）并寄给深圳跟单Emily Wu/Irene Wang, 我们需寄给客户审 批和拍照。 2)满箱样：请在4/15前寄出各一箱大货满箱样（产品需贴客版价格贴纸，并带大货外箱）寄给深圳跟单Emily Wu/Irene Wang。 Remark：以上所有样板数量不包含在订单数量里，做货需预备样板数量。 | AC31: 日期码格式：ZURU INC(BVI) 标准格式 日期：按实际生产日期 Packaging Info: 1. item#77772GQ4: MA UPC最新版本包装（优先1L) + 客版PDQ + 客版价格贴纸 + 外箱贴； 客版价格贴纸和外箱贴都是跟单提供，工厂自行订购。出口美国。 2. 产品及包装上都要有日期码，日期码是一致的（但不能为周末)，格式为ZURU标准格式。 Remark: 3. 此两款都需在4/2前完成至少25%大货包装，4/3早上进行ITS的25%大货抽样验货。 100%大货可以在4/15前完成。收到PASS的测试报告后，才可安排出货。 25%抽样由客人指定的第三方ITS进行，现场在大货中抽样，具体要求如下所列： A.样板抽取12pcs/每款/每色（带包装，大货中抽取）。 B.产品上有涂层的，需额外准备足够的干油墨（每个颜色2个A4尺寸的喷涂样本，涂层喷到同底材，涂满涂厚，至少能刮取30mg的量）。 4. 外箱贴打印常规 4"x6" Standard Label Stock, 只需贴一面(正唛）, 优先贴在纸箱的右上方空白处，不可以盖住外箱上的其他信息及标签，可适当调整位置。 5. 样板需求（77794UQ1 <(>&<)> 77772GQ4）： 1)产前样+Model Store Sample: 请在4/1前寄出每款每色各8pcs大货样（不带PDQ，需贴客版价格贴纸）并寄给深圳跟单Emily Wu/Irene Wang, 我们需寄给客户审 批和拍照。 2)满箱样：请在4/15前寄出各一箱大货满箱样（产品需贴客版价格贴纸，并带大货外箱）寄给深圳跟单Emily Wu/Irene Wang。 Remark：以上所有样板数量不包含在订单数量里，做货需预备样板数量。 | AD31: Emily Wu | AE31: 1.248 | AF31: =I31*AE31 -> 4994.496 | AG31: ZB05480-8.17 | AH31: 77772GQ2-S001 | AI31: 已入 | AJ31: 系统入单 | AK31: =I31 -> 4002 | AN31: =I31 -> 4002 | AU31: =I31 -> 4002 | AV31: =I31*0.06 -> 240.12 | BT31: =I31/6 -> 667 | CD31: =BN31+BO31+BQ31+BS31+BR31 -> 0 | CE31: =BU31 -> 0 | CF31: =CC31 -> 0 | CG31: =BV31+BW31+BX31 -> 0
A32: 46086 | B32: SIDJ JOUECLUB | C32: 法国 | D32: 4500195260 | F32: 4500195260-10 | G32: 77772GQ2-S001 | H32: 唱片球50 pcs/2PDQ/箱 | I32: 8750 | J32: 0 | K32: 50 | L32: =I32/K32 -> 175 | M32: 46127 | N32: 46123 | P32: 此票无需客户验货，需2套完整大货样球，出货前一周提供给跟单; | Q32: PASS | T32: 8750 | U32: =T32-I32 -> 0 | W32: 3/23确认 | X32: 无 | Y32: 3/31贴纸(含IT<(>&<)>NL<(>&<)>AR警示语+客户订单信息+意大利回收标+CMIM logo) | Z32: 日期码格式：2041526 | AC32: 日期码格式：2041526 日期： Packaging Info: 77772GQ2-S001:MA3L EAN 吸塑膜+1张贴纸(含IT<(>&<)>NL<(>&<)>AR警示语+客户订单信息+意大利回收标+CMIM logo)+MA配件袋子+MA5L收藏指南+MA23L组装说明书 +MA 3L展示盒 Remark: 1.此票无需客户验货，请多备料1套左右 2.请准备每款5pcs包装备品（客版彩盒），和大货一起出（以备到客户仓库后有破损的包装） 3.所有出口法国的产品, 法规规定禁止在包装和共公众用的印刷品中使用矿物油中含有的物质, 包装印刷油墨中含有的MOAH/MOSH的质量浓度不能超过1%, 否则出货 到法国被抽检出现问题, 供应商需要对此负责; 4.出口法国请确保产品符合EU微塑料法规，包装需显示法国回收logo; | AD32: Ula Zhao | AE32: 1.007 | AF32: =I32*AE32 -> 8811.25 | AH32: 77772GQ2-S001 | AI32: 已入 | AJ32: 系统入单 | AK32: =I32 -> 8750 | AP32: =I32 -> 8750 | AU32: =I32 -> 8750 | AV32: =I32*0.06 -> 525 | BO32: =I32/25 -> 350 | CD32: =BN32+BO32+BQ32+BS32+BR32 -> 350 | CE32: =BU32 -> 0 | CF32: =CC32 -> 0 | CG32: =BV32+BW32+BX32 -> 0
A33: 46044 | B33: SMYTHS TOYS HQ UC IE | C33: 爱尔兰 | D33: 4500192014 | E33: 4400530472 | F33: 4500192014-20 | G33: 77772GQ2-S001-PRODCC | H33: 唱片球50 pcs/2PDQ/箱 | I33: 2000 | J33: 0 | K33: 50 | L33: =I33/K33 -> 40 | M33: 46127 | N33: 46123 | Q33: AOD | T33: 2000 | U33: =T33-I33 -> 0 | W33: 46044 | X33: 无 | Y33: 无 | Z33: 移除#21唱片 | AC33: 日期码格式：ZURU INC(BVI) 标准格式 日期：按实际生产日期 Packaging Info: 77772GQ2客版5L(英法德意荷)配套包装=MA PDQ (优先多语)+客版3L-5Lwarning收缩膜(翻PO#4500191961)+客版5L收藏指南(翻PO#4500191961)+MA 23L组装说明+MA 复合袋 EAN#4894680051133 77772GQ2必须移除Messy Lola Young (VINYL-S1-021) 这个唱片 ,比例按Una 更新的安排，如未按要求做货被客罚由工厂承担责任。 Remark: Smyths 英国/爱尔兰 1. 请准时出货，推期会有罚款； 2. 所有产品按符合欧洲标准走货，需要是不含微塑料版本。 3.包装日期码按ZURU格式即可，请确保不迟于外箱日期码，可等于或者早于外箱日期码，必须为法定工作日，印刷前请先检查外箱日期码。 4.请注意检查产品及包装应带UKCA图标（14+产品除外），包装显示ZURU UK LTD/ZURU France地址信息，QC部门请查核，如有问题与跟单确认 5.电子产品需增加一张WEEE声明30L通用黑白说明书(不接受A版本，翻译有误)，区分带电池和不带电池出货版本, 如已做客版说明书可忽略此要求； 6.订单备注显示有分批的（不同仓库/订单号） ，注意分开做货出货，否则会导致罚款 。 7.做货前请先复核包装条码与订单是否一致再安排，对不上的需与ZURU跟单确认再安排。 | AD33: Sherry Lu | AE33: 1.007 | AF33: =I33*AE33 -> 2014 | AH33: 77772GQ2-S001-PRODCC | AI33: 已入 | AJ33: 系统入单 | AK33: =I33 -> 2000 | AV33: =I33*0.06 -> 120 | BG33: =I33 -> 2000 | BH33: =I33 -> 2000 | BO33: =I33/25 -> 80 | CD33: =BN33+BO33+BQ33+BS33+BR33 -> 80 | CE33: =BU33 -> 0 | CF33: =CC33 -> 0 | CG33: =BV33+BW33+BX33 -> 0
A34: 46122 | D34: ZMPO260373 | F34: ZMPO260373-10 | G34: 77772GQ2-S002-PRODCC | I34: 40 | M34: 46127 | N34: 46123 | T34: 40 | U34: =T34-I34 -> 0 | W34: 46122 | X34: 无 | Y34: 无 | AC34: 备注：收到样品订单后尽快安排 ，注意样板品质质量要求要高于大货品质要求 ，送货时必须要附带送货单(没有送货单和QC检验合格报告的仓库一律拒绝收货)，请知悉，谢谢！Remark只需要40个成品球，不需要PDQ,不需要光碟 | AD34: Angus | AH34: 77772GQ2-S002 | AI34: * | AK34: =I34 -> 40 | AN34: =I34 -> 40 | AU34: =I34 -> 40 | AV34: =I34*0.06 -> 2.4 | BN34: 2 | CD34: =BN34+BO34+BQ34+BS34+BR34 -> 2 | CE34: =BU34 -> 0 | CF34: =CC34 -> 0 | CG34: =BV34+BW34+BX34 -> 0
A35: 46080 | B35: UPD, INC. | C35: 美国 | D35: 4500194415 | E35: 36405 | F35: 4500194415-20 | G35: 77772GQ1-S001 | H35: 唱片球52pcs/4PDQ/箱 | I35: 468 | J35: 0 | K35: 52 | L35: =I35/K35 -> 9 | M35: 46128 | N35: 46125 | Q35: PASS | T35: 468 | U35: =T35-I35 -> 0 | W35: 3/17 确认 | X35: 无 | Y35: 无 | AC35: 日期码格式：ZURU INC(BVI) 标准格式 日期：按实际生产日期 Packaging Info: 1. 包装方式：MA UPC 优先1L 最新包装，出口美国 Remark: 2. 外箱箱唛红色和黑色双色印刷 3. 产品和包装上印刷tracking code信息，格式为ZURU常规 | AD35: Angel Lin | AE35: 0.6198 | AF35: =I35*AE35 -> 290.0664 | AG35: ZB05228-8.17 | AH35: 77772GQ1-S001 | AI35: 已入 | AJ35: 系统入单 | AK35: =I35 -> 468 | AN35: =I35 -> 468 | AU35: =I35 -> 468 | AV35: =I35*0.06 -> 28.08 | BK35: =I35/13 -> 36 | CD35: =BN35+BO35+BQ35+BS35+BR35 -> 0 | CE35: =BU35 -> 0 | CF35: =CC35 -> 0 | CG35: =BV35+BW35+BX35 -> 0
A36: 46113 | D36: ZMPO260330 | F36: ZMPO260330-10 | G36: 77772-S001 | H36: 唱片球24 pcs/箱 | I36: 3000 | J36: 0 | K36: 24 | L36: =I36/K36 -> 125 | M36: 46129 | N36: 46125 | Q36: PASS | T36: 3000 | U36: =T36-I36 -> 0 | W36: 46113 | X36: 无 | Y36: 无 | AC36: Remark：大货最新版本/款号平均/麻烦按款号装箱/并在外箱上注明款号/大货标准箱装箱/箱唛参照邮件附件 备注：收到样品订单后尽快安排 ，注意样板品质质量要求要高于大货品质要求 ，送货时必须要附带送货单(没有送货单和QC检验合格报告的仓库一律拒绝收货)，请知悉，谢谢！ | AH36: 77772-S001 | AI36: 已入 | AJ36: 系统入单 | AK36: =I36 -> 3000 | AN36: =I36 -> 3000 | AU36: =I36 -> 3000 | AV36: =I36*0.06*2 -> 360 | CD36: =BN36+BO36+BQ36+BS36+BR36 -> 0 | CE36: =BU36 -> 0 | CF36: =CC36 -> 0 | CG36: =BV36+BW36+BX36 -> 0
A37: 46080 | B37: THE ENTERTAINER | C37: 英国 | D37: 4500194581 | E37: FB14473 | F37: 4500194581-100 | G37: 77772GQ1-S002-PRODCC | H37: 唱片球13 pcs/PDQ/箱 | I37: 15496 | J37: 0 | K37: 13 | L37: =I37/K37 -> 1192 | M37: 46129 | N37: 46125 | P37: 新款请在CRD前10天寄出每款2整套大货样到罗湖办公室7B Meyya Liu 收，翻单不用寄。" | Q37: AOD | R37: 4/29 出货 | T37: =6240+9256 -> 15496 | U37: =T37-I37 -> 0 | W37: 46100 | X37: 无 | Y37: 客户EAN条码贴纸+PDQ数量贴纸 | Z37: 移除#21唱片 | AB37: 新款请在CRD前10天寄出每款2整套大货样到罗湖办公室7B Meyya Liu 收，翻单不用寄。" | AC37: 日期码格式：ZURU INC(BVI) 标准格式 日期：按实际生产日期 Packaging Info: 77772GQ1-S002-PRODCC：1L PDQ+MA A版UPC收缩膜 注意，此为去掉LOLA YANG的特殊版本。请不要出错。 Remark: "MA版本按工厂现有最新库存即可，订单出英国，请注意检查产品及包装应带UKCA以及CE图标，包装显示ZURU UK LTD信息，QC同事请查核，如有问题与跟单确认 *生产日期按实际（法定工作日），按ZURU标准格式即可 ，但是请知悉包装日期码需要早于或者等于外箱日期码 ，不能晚于外箱日期码 *请注意所有订单都需要经过ZURU QC验货并且通过后方可出货 *所有产品按符合欧洲标准走货，需要是不含微塑料版本 。 *涉及到硼的，如可选择情况下应使用低硼版本 （slime 类别低硼一般低于300ppm)，无选择的应与跟单复核再安排 。 *如果出运产品属于电子类产品需要在ZURU 包装基础上额外添加一张ZURU 标准30L通用WEEE 电子产品说明书,带电池出货的加带电池出货版本通用30L的说明书，不 带电池出货的产品用不带电池出货版本的说明书. *根据客人最新的包装要求，所有多个PDQ盒子(TQ,UQ,GQ）入1外箱的都需要在PDQ顶部右上角加上数量贴纸标明里面的数量。最小字体：36pts, 字体：Calibri（bo ld), 具体要求以及位置见文件. *订单对应客户PO号 ，备注有显示 ，注意分开做货/验货/装柜 ，混装有罚款。 * 大货样： 新款请在CRD前10天寄出每款2整套大货样到罗湖办公室7B Meyya Liu 收，翻单不用寄。" | AD37: Meyya Liu | AE37: 1.2 | AF37: =AE37*I37 -> 18595.2 | AH37: 77772GQ1-S002 | AI37: 已入 | AJ37: 系统入单 | AK37: =I37 -> 15496 | AN37: =I37 -> 15496 | AU37: =I37 -> 15496 | AV37: =I37*0.06 -> 929.76 | BK37: =I37/13 -> 1192 | CD37: =BN37+BO37+BQ37+BS37+BR37 -> 0 | CE37: =BU37 -> 0 | CF37: =CC37 -> 0 | CG37: =BV37+BW37+BX37 -> 0
A38: 46078 | B38: DISTRIBUIDORA JUGUETRON S.A. DE C.V | C38: 墨西哥 | D38: 4500194136 | E38: 50212600321 | F38: 4500194136-40 | G38: 77772GQ2-S002 | H38: 唱片球25 pcs/PDQ/箱 | I38: 10000 | J38: 0 | K38: 25 | L38: =I38/K38 -> 400 | M38: 46132 | N38: 46128 | Q38: PASS | T38: 10000 | U38: =T38-I38 -> 0 | V38: OK | W38: 46093 | X38: 有 | Y38: 4/1 进口商贴纸+UPC贴纸+外箱贴纸 | AC38: 日期码格式：ZURU INC(BVI) 标准格式 日期：按实际生产日期 Packaging Info: 77772GQ2:MA 多语包装+进口商贴纸+UPC贴纸+外箱贴纸+箱唛 Remark: 1.此单有第三方监柜，需要每款多备1套完整物料 2.外箱贴纸只要一张，位置是正唛和侧唛的交接处 | AD38: Ava Liang | AE38: 1.27 | AF38: =I38*AE38 -> 12700 | AH38: 77772GQ2-S002-3L | AI38: 已入 | AJ38: 系统入单 | AK38: =I38 -> 10000 | AP38: =I38 -> 10000 | AU38: =I38 -> 10000 | AV38: =I38*0.06 -> 600 | BO38: =I38/25 -> 400 | CD38: =BN38+BO38+BQ38+BS38+BR38 -> 400 | CE38: =BU38 -> 0 | CF38: =CC38 -> 0 | CG38: =BV38+BW38+BX38 -> 0
A39: 46080 | B39: MEIJER DISTRIBUTION, INC. | C39: 美国 | D39: 4500194435 | E39: 219021595 | G39: 77772GQ1-S002 | H39: 唱片球13 pcs/PDQ/箱 | I39: 2964 | J39: 0 | K39: 13 | L39: =I39/K39 -> 228 | M39: 46132 | N39: 46128 | Q39: PASS | T39: 2964 | U39: =T39-I39 -> 0 | V39: 无 | W39: 2/28 确认 | X39: 无 | Y39: 无 | AC39: 日期码格式：ZURU INC(BVI) 标准格式 日期： Packaging Info: 1. 产品MA UPC包装（优先1L）出美国 2. 客人指定箱唛排版 3. 77772GQ1-S002 4 mini vinyls,1 accessory Remark: 出货前 Zuru QC 验货 | AD39: Agnes Zheng | AE39: 0.72 | AF39: =I39*AE39 -> 2134.08 | AG39: ZB05284-8.17 | AH39: 77772GQ1-S002 | AI39: 已入 | AJ39: 系统入单 | AK39: =I39 -> 2964 | AN39: =I39 -> 2964 | AU39: =I39 -> 2964 | AV39: =I39*0.06 -> 177.84 | BK39: =I39/13 -> 228 | CD39: =BN39+BO39+BQ39+BS39+BR39 -> 0 | CE39: =BU39 -> 0 | CF39: =CC39 -> 0 | CG39: =BV39+BW39+BX39 -> 0
A40: 46080 | B40: MEIJER DISTRIBUTION, INC. | C40: 美国 | D40: 4500194435 | E40: 219021651 | F40: 4500194435-20 | G40: 77772GQ1-S002 | H40: 唱片球13 pcs/PDQ/箱 | I40: 1729 | J40: 0 | K40: 13 | L40: =I40/K40 -> 133 | M40: 46132 | N40: 46128 | Q40: PASS | T40: =1729 -> 1729 | U40: =T40-I40 -> 0 | V40: 无 | W40: 2/28 确认 | X40: 无 | Y40: 无 | AC40: 日期码格式：ZURU INC(BVI) 标准格式 日期： Packaging Info: 1. 产品MA UPC包装（优先1L）出美国 2. 客人指定箱唛排版 3. 77772GQ1-S002 4 mini vinyls,1 accessory Remark: 出货前 Zuru QC 验货 | AD40: Agnes Zheng | AE40: 0.72 | AF40: =I40*AE40 -> 1244.88 | AG40: ZB05284-8.17 | AH40: 77772GQ1-S002 | AI40: 已入 | AJ40: 系统入单 | AK40: =I40 -> 1729 | AN40: =I40 -> 1729 | AU40: =I40 -> 1729 | AV40: =I40*0.06 -> 103.74 | BK40: =I40/13 -> 133 | CD40: =BN40+BO40+BQ40+BS40+BR40 -> 0 | CE40: =BU40 -> 0 | CF40: =CC40 -> 0 | CG40: =BV40+BW40+BX40 -> 0
...

Sheet 77794
A1: 香港接单日期 | B1: 第三方客户名称 | C1: 走货国家 | D1: ZURU PO NO# | E1: 第三方客户 PO NO# | F1: SKU | G1: ITEM# | H1: 货品名称 | I1: PO数量(只) | J1: 内箱装箱数量(只) | K1: 外箱装箱数量(只) | L1: 总箱数 | M1: 计划出货期 | N1: 计划验货期 | O1: 第三方客户公证行验货 | P1: 验货结果 | Q1: S/O(截仓期) | R1: 箱唛 (收到日期) | S1: 外箱贴纸 | T1: 贴纸资料 (收到日期及订购日期) | U1: 额外说明书/保证书 | V1: 其他物料 | W1: 样办 | X1: 备注 | Y1: ZURU跟单组员 | Z1: 单价USD | AA1: 金额USD | AB1: 发票号 | AC1: 系统货号 | AD1: 是否入系统 | AE1: 订单数 | AF1: 生产情况 | AG1: 已回数量 | AH1: 欠数 | AI1: 贴纸 | AJ1: 下单情况 | AK1: MA 1L A彩盒 | AL1: MA 3L A彩盒 | AM1: 客版彩盒 | AN1: MA 5L 说明书 | AO1: 客版说明书 | AP1: 中文说明书 | AQ1: COSTCO 客版说明书 | AR1: COSTCO 客版彩盒 | AS1: COSTCO 客版PDQ | AT1: UQ1 1L 8pcs | AU1: UQ1 3L 8pcs | AV1: UQ3客版PDQ | AW1: UQ1 客版PDQ 取消17款唱片 | AX1: UQ1 8pcs 客版 PDQ 取消21/23唱片 | AY1: UQ2 6pcs 客版 PDQ | AZ1: UQ3 2pcs 客版 PDQ | BA1: MEC426 （MA 1L） | BB1: 胶袋 | BC1: MEC457 | BD1: MEC473 | BE1: MSLD188 | BF1: MSLD182 | BG1: SK-S001 | BH1: 77897-S001 | BI1: 77869彩盒
A2: 45989 | B2: 库有 | C2: PP | D2: ZPO2511015 | F2: ZPO2511015-20 | G2: 77794-S001 | H2: 唱片机16pcs/箱 | I2: 424 | J2: 0 | K2: 16 | L2: =I2/K2 -> 26.5 | M2: 46048 | N2: 46044 | Y2: Fiona Ouyang | AD2: # | AE2: =I2 -> 424
A3: 46031 | D3: ZMPO260027 | F3: ZMPO260027-10 | G3: 77794-S001 | H3: 唱片机16pcs/箱 | I3: 240 | J3: 0 | K3: 16 | L3: =I3/K3 -> 15 | M3: 46048 | N3: 46044 | P3: PASS | R3: 46031 | S3: 有 | T3: 无 | X3: Remark:大货最新版本/麻烦按款号装箱/并在外箱上注明款号/大货标准箱装箱/箱唛参照邮件附件 备注：收到样品订单后尽快安排 ，注意样板品质质量要求要高于大货品质要求 ，送货时必须要附带送货单(没有送货单和QC检验合格报告的仓库一律拒绝收货)，请知悉，谢谢！ | AD3: # | AE3: =I3 -> 240 | AG3: 240 | AH3: =AG3-I3 -> 0 | AN3: =I3 -> 240
A4: 46031 | D4: ZMPO260027 | F4: ZMPO260027-20 | G4: 77794UQ1-S001 | H4: 唱片机空PDQ | I4: 100个空PDQ | J4: 0 | K4: 16 | M4: 46048 | N4: 46044 | P4: PASS | R4: 46031 | S4: 有 | T4: 无 | X4: Remark:大货最新版本/只需要空PDQ/PDQ可打平包寄出 备注：收到样品订单后尽快安排 ，注意样板品质质量要求要高于大货品质要求 ，送货时必须要附带送货单(没有送货单和QC检验合格报告的仓库一律拒绝收货)，请知悉，谢谢！ | AB4: -9 | AD4: # | AH4: =AG4-I4 -> #VALUE! | AT4: 100
A5: 46029 | B5: ZURU NEW ZEALAND LIMITED | C5: 新西兰 | D5: 4500190798 | E5: 5200008655 | F5: 4500190798-20 | G5: 77794UQ1-S002-FS | H5: 唱片机8pcs/UQ1/箱 | I5: 32 | J5: 0 | K5: 8 | L5: =I5/K5 -> 4 | M5: 46059 | N5: 46055 | O5: 试销单 | R5: 46029 | S5: 有 | T5: 箱需要增加一张黄色A4贴纸，印“fast start"。 | X5: 日期码格式：ZURU INC(BVI) 标准格式 日期：按实际生产日期 Packaging Info: Remark: NZ Fast start order, 从PP PO中扣除，每款需要更换UPC贴纸，除常规箱唛外，每箱需要增加一张黄色A4贴纸，印“fast start"。 | Y5: Holly Zheng | Z5: 5 | AA5: =Z5*I5 -> 160 | AC5: 77794UQ1-S002 | AD5: 已入 | AH5: =AG5-I5 -> -32 | AJ5: 系统出单
A6: 46014 | B6: TARGET US | C6: 美国 | D6: 4500189603 | E6: 10001643491-3 890 | F6: 4500189603-20 | G6: 77794UQ1-S002 | H6: 唱片机8pcs/UQ1/箱 | I6: 15600 | J6: 0 | K6: 8 | L6: =I6/K6 -> 1950 | M6: 46085 | N6: =M6-4 -> 46081 | P6: PASS | Q6: 3/17 出货 | R6: 46027 | S6: 有 | T6: 1/22 寄出 | V6: 客版PDQ | X6: 日期码格式：ZURU INC(BVI) 标准格式 日期：按实际生产日期 Packaging Info: 77794UQ1：产品包装 MA 1L包装，MA 1L PDQ Remark: 77794UQ1： 1.77794UQ1-S002-MINI BRANDS-VINYL-PLAYSET-SERIES 1-CUBE,8PCS/PDQ,8PCS/PDQ/CTN； 2.产品包装 MA 1L包装，MA 1L PDQ； 3.产品UPC显示193052090409； 4. 外箱正唛左上角位置粘贴条码箱贴纸，每箱只贴一张，由ZURU订购。来料贴纸上显示的客户DPCI# 086-02-4085, UPC显示10193052090406; 5. 外箱正唛箱唛内容右侧需贴一张EVENT LABEL，内容显示：TOYS SET DATE: 5/31/2026，由工厂自行订购； 6. 产品和包装上印刷 tracking code信息，格式为ZURU常规格式; 7. 出货方式：货代自提； 8. 带锂电池出货，需在外箱正面或者侧面合适位置上加贴一张贴锂电池标签纸，由工厂订购 | Y6: Holly Zheng | Z6: 2.88 | AA6: =Z6*I6 -> 44928 | AB6: ZB04936/ZB04937 | AC6: 77794UQ1-S002 | AD6: 已入 | AE6: =I6 -> 15600 | AF6: 东莞生产 | AH6: =AG6-I6 -> -15600 | AI6: OK | AJ6: 系统出单 | AK6: =I6 -> 15600 | AN6: =I6 -> 15600 | AT6: =I6/8 -> 1950
A7: 46013 | B7: TARGET US | C7: 美国 | D7: 4500189608 | E7: 10001643496-3 890 | F7: 4500189608-20 | G7: 77794UQ1-S002 | H7: 唱片机8pcs/UQ1/箱 | I7: 34400 | J7: 0 | K7: 8 | L7: =I7/K7 -> 4300 | M7: 46091 | N7: 46087 | P7: PASS | R7: 46027 | S7: 有 | T7: 1/22 寄出 | V7: 客版PDQ | X7: 日期码格式：ZURU INC(BVI) 标准格式 日期：按实际生产日期 Packaging Info: 77794UQ1：产品包装 MA 1L包装，MA 1L PDQ Remark: 77794UQ1： 1.77794UQ1-S002-MINI BRANDS-VINYL-PLAYSET-SERIES 1-CUBE,8PCS/PDQ,8PCS/PDQ/CTN； 2.产品包装 MA 1L包装，MA 1L PDQ； 3.产品UPC显示193052090409； 4. 外箱正唛左上角位置粘贴条码箱贴纸，每箱只贴一张，由ZURU订购。来料贴纸上显示的客户DPCI# 086-02-4085, UPC显示10193052090406; 5. 产品和包装上印刷 tracking code信息，格式为ZURU常规格式; 6. 出货方式：货代自提 7. 带锂电池出货，需在外箱正面或者侧面合适位置上加贴一张贴锂电池标签纸，由工厂订购 | Y7: Holly Zheng | Z7: 2.88 | AA7: =Z7*I7 -> 99072 | AB7: ZB04934/ZB04935 | AC7: 77794UQ1-S002 | AD7: 已入 | AE7: =I7 -> 34400 | AG7: =34400+12296+4848+17856 -> 69400 | AH7: =AG7-I7 -> 35000 | AI7: OK | AJ7: 系统出单 | AK7: =I7 -> 34400 | AN7: =I7 -> 34400 | AT7: =I7/8 -> 4300
A8: 46044 | B8: SMYTHS TOYS EU HQ UNLIMITED COMPANY | C8: 法国 | D8: 4500191989 | E8: 4400528766 | F8: 4500191989-10 | G8: MEC457-77794-S001 | H8: 唱片机+唱片球混装展示架 | I8: 2016 | J8: 0 | K8: 48 | L8: =I8/K8 -> 42 | M8: 46097 | N8: 46093 | P8: PASS | Q8: 4/6 出货 | R8: 46044 | S8: 有 | T8: UN3481锂电池运输标签 | X8: 日期码格式：ZURU INC(BVI) 标准格式 日期：按实际生产日期 Packaging Info: MEC457: 客版5L(英法德意荷)展示架[84pcs#77772+48pcs#77794; 所有客版资料翻PO#4500191961] 77772: 客版3L-5Lwarning收缩膜+客版5L收藏指南+MA 23L组装说明+MA复合袋 EAN#4894680051133 77794: 客版3L-5Lwarning纸盒底座+客版3L镭射贴纸+客版3L单铜纸贴纸+MA23L游戏说明书+MA23L warning说明书+1张WEEE声明(带电池)走货欧洲通用29L-C版说明 书 EAN#4894680051430 做货前请先核对条码无误 RECHARGEABLE LITHIUM BATTERY(INCLUDED) *#77772必须移除Messy Lola Young (VINYL-S1-021) 这个唱片, 比例按PM更新的安排* *展架上的Demo Box的唱片需要用"A Little Too Much"(VINYL-S1-025)替代原来的"Messy"(VINYL-S1-021)* *外箱需加一张UN3481锂电池运输标签* Remark: Smyths 法国 1. 请准时出货，推期会有罚款； 2. 所有产品按符合欧洲标准走货，需要是不含微塑料版本。 3. 电子产品需增加一张WEEE声明30L通用黑白说明书(不接受A版本，翻译有误)，区分带电池和不带电池出货版本, 如已做客版说明书可忽略此要求； 4. 出口法国的产品, 法规规定禁止在包装和共公众用的印刷品中使用矿物油中含有的物质, 包装印刷油墨中含有的MOAH/MOSH的质量浓度不能超过1%, 否则出货到 法国被抽检出现问题, 供应商需要对此负责; 5.订单备注显示有分批的（不同仓库/订单号） ，注意分开做货出货，否则会导致罚款 。 6.包装日期码按ZURU格式即可，请确保不迟于外箱日期码，可等于或者早于外箱日期码，必须为法定工作日。 7.做货前请先复核包装条码与订单是否一致再安排，对不上的需与ZURU跟单确认再安排。 | Y8: Sherry Lu | Z8: 306.676 | AA8: =L8*Z8 -> 12880.392 | AC8: MEC457-S001-77794 | AD8: 已入 | AE8: =I8 -> 2016 | AG8: 2016 | AH8: =AG8-I8 -> 0 | AJ8: 系统出单 | AM8: =I8 -> 2016 | AN8: =I8 -> 2016 | BA8: =I8/K8 -> 42
A9: 46044 | B9: SMYTHS TOYS EU HQ UNLIMITED COMPANY | C9: 法国 | D9: 4500191989 | E9: 4400528767 | F9: 4500191989-20 | G9: MEC457-77794-S001 | H9: 唱片机+唱片球混装展示架 | I9: 864 | J9: 0 | K9: 48 | L9: =I9/K9 -> 18 | M9: 46097 | N9: 46093 | P9: PASS | Q9: 4/7 出货 | R9: 46044 | S9: 有 | T9: UN3481锂电池运输标签 | X9: 日期码格式：ZURU INC(BVI) 标准格式 日期：按实际生产日期 Packaging Info: MEC457: 客版5L(英法德意荷)展示架[84pcs#77772+48pcs#77794; 所有客版资料翻PO#4500191961] 77772: 客版3L-5Lwarning收缩膜+客版5L收藏指南+MA 23L组装说明+MA复合袋 EAN#4894680051133 77794: 客版3L-5Lwarning纸盒底座+客版3L镭射贴纸+客版3L单铜纸贴纸+MA23L游戏说明书+MA23L warning说明书+1张WEEE声明(带电池)走货欧洲通用29L-C版说明 书 EAN#4894680051430 做货前请先核对条码无误 RECHARGEABLE LITHIUM BATTERY(INCLUDED) *#77772必须移除Messy Lola Young (VINYL-S1-021) 这个唱片, 比例按PM更新的安排* *展架上的Demo Box的唱片需要用"A Little Too Much"(VINYL-S1-025)替代原来的"Messy"(VINYL-S1-021)* *外箱需加一张UN3481锂电池运输标签* Remark: Smyths 法国 1. 请准时出货，推期会有罚款； 2. 所有产品按符合欧洲标准走货，需要是不含微塑料版本。 3. 电子产品需增加一张WEEE声明30L通用黑白说明书(不接受A版本，翻译有误)，区分带电池和不带电池出货版本, 如已做客版说明书可忽略此要求； 4. 出口法国的产品, 法规规定禁止在包装和共公众用的印刷品中使用矿物油中含有的物质, 包装印刷油墨中含有的MOAH/MOSH的质量浓度不能超过1%, 否则出货到 法国被抽检出现问题, 供应商需要对此负责; 5.订单备注显示有分批的（不同仓库/订单号） ，注意分开做货出货，否则会导致罚款 。 6.包装日期码按ZURU格式即可，请确保不迟于外箱日期码，可等于或者早于外箱日期码，必须为法定工作日。 7.做货前请先复核包装条码与订单是否一致再安排，对不上的需与ZURU跟单确认再安排。 | Y9: Sherry Lu | Z9: 306.676 | AA9: =L9*Z9 -> 5520.168 | AC9: MEC457-S001-77794 | AD9: 已入 | AE9: =I9 -> 864 | AG9: 864 | AH9: =AG9-I9 -> 0 | AJ9: 系统出单 | AM9: =I9 -> 864 | AN9: =I9 -> 864 | BA9: =I9/K9 -> 18
A10: 46043 | B10: SMYTHS TOYS HQ UC UK | C10: 英国 | D10: 4500191960 | E10: 4400528768 | F10: 4500191960-20 | G10: 77794UQ1-S001 | H10: 唱片机16pcs/2 UQ1/箱 | I10: 5008 | J10: 0 | K10: 16 | L10: =I10/K10 -> 313 | M10: 46097 | N10: 46093 | P10: PASS | Q10: 3/22 截SI | R10: 46044 | S10: 有 | T10: 新地址贴纸ZURU FRANCE.33 rue Paul Meurice 75020 Paris, France.+WEEE声明29L通用黑白说明书+UN3481锂电池运输标签 | X10: 日期码格式：ZURU INC(BVI) 标准格式 日期：按实际生产日期 Packaging Info: 77794UQ1客版5L(英法德意荷)配套包装=MA PDQ (优先多语)+客版3L-5Lwarning纸盒底座(翻PO#4500191961)+MA23L游戏说明书+MA23L warning说明书+1张WEEE声明( 带电池)走货欧洲通用30L-B版说明书 EAN#4894680051430 RECHARGEABLE LITHIUM BATTERY(INCLUDED) Remark: Smyths 英国/爱尔兰 1. 请准时出货，推期会有罚款； 2. 所有产品按符合欧洲标准走货，需要是不含微塑料版本。 3.包装日期码按ZURU格式即可，请确保不迟于外箱日期码，可等于或者早于外箱日期码，必须为法定工作日，印刷前请先检查外箱日期码。 4.请注意检查产品及包装应带UKCA图标（14+产品除外），包装显示ZURU UK LTD/ZURU France地址信息，QC部门请查核，如有问题与跟单确认 5.电子产品需增加一张WEEE声明30L通用黑白说明书(不接受A版本，翻译有误)，区分带电池和不带电池出货版本, 如已做客版说明书可忽略此要求； 6.订单备注显示有分批的（不同仓库/订单号） ，注意分开做货出货，否则会导致罚款 。 7.做货前请先复核包装条码与订单是否一致再安排，对不上的需与ZURU跟单确认再安排。 | Y10: Sherry Lu | Z10: 4.355 | AA10: =I10*Z10 -> 21809.84 | AC10: 77794UQ1-S001-客版 | AD10: 已入 | AE10: =I10 -> 5008 | AG10: 5008 | AH10: =AG10-I10 -> 0 | AI10: OK | AJ10: 系统出单 | AM10: =I10 -> 5008 | AN10: =I10 -> 5008 | AU10: =I10/8 -> 626
A11: 46043 | B11: SMYTHS TOYS HQ UC IE | C11: 爱尔兰 | D11: 4500191968 | E11: 4400528769 | F11: 4500191968-10 | G11: 77794UQ1-S001 | H11: 唱片机16pcs/2 UQ1/箱 | I11: 2512 | J11: 0 | K11: 16 | L11: =I11/K11 -> 157 | M11: 46097 | N11: 46093 | P11: PASS | Q11: 3/18 截SI | R11: 46044 | S11: 有 | T11: UN3481锂电池运输标签 | X11: 日期码格式：ZURU INC(BVI) 标准格式 日期：按实际生产日期 Packaging Info: 77794UQ1客版5L(英法德意荷)配套包装=MA PDQ (优先多语)+客版3L-5Lwarning纸盒底座(翻PO#4500191961)+MA23L游戏说明书+MA23L warning说明书+1张WEEE声明( 带电池)走货欧洲通用30L-B版说明书 EAN#4894680051430 RECHARGEABLE LITHIUM BATTERY(INCLUDED) Remark: Smyths 英国/爱尔兰 1. 请准时出货，推期会有罚款； 2. 所有产品按符合欧洲标准走货，需要是不含微塑料版本。 3.包装日期码按ZURU格式即可，请确保不迟于外箱日期码，可等于或者早于外箱日期码，必须为法定工作日，印刷前请先检查外箱日期码。 4.请注意检查产品及包装应带UKCA图标（14+产品除外），包装显示ZURU UK LTD/ZURU France地址信息，QC部门请查核，如有问题与跟单确认 5.电子产品需增加一张WEEE声明30L通用黑白说明书(不接受A版本，翻译有误)，区分带电池和不带电池出货版本, 如已做客版说明书可忽略此要求； 6.订单备注显示有分批的（不同仓库/订单号） ，注意分开做货出货，否则会导致罚款 。 7.做货前请先复核包装条码与订单是否一致再安排，对不上的需与ZURU跟单确认再安排。 | Y11: Sherry Lu | Z11: 4.355 | AA11: =I11*Z11 -> 10939.76 | AC11: 77794UQ1-S001-客版 | AD11: 已入 | AE11: =I11 -> 2512 | AG11: 2512 | AH11: =AG11-I11 -> 0 | AI11: OK | AJ11: 系统出单 | AM11: =I11 -> 2512 | AN11: =I11 -> 2512 | AU11: =I11/8 -> 314
A12: 46084 | B12: ZURU NEW ZEALAND LIMITED | C12: 新西兰 | D12: 4500194964 | E12: 5200009119 | F12: 4500194964-20 | G12: 77794UQ1-S002-FS | H12: 唱片机8pcs/UQ1/箱 | I12: 32 | J12: 0 | K12: 8 | L12: =I12/K12 -> 4 | M12: 46097 | N12: 46093 | P12: PASS | R12: 46029 | S12: 有 | T12: 箱需要增加一张黄色A4贴纸，印“fast start"。 | X12: 日期码格式：ZURU INC(BVI) 标准格式 日期：按实际生产日期 Packaging Info: Remark: NZ Fast start order, 每款需要更换UPC贴纸，除常规箱唛外，每箱需要增加一张黄色A4贴纸，印"fast start"。 | Y12: SD92 | Z12: 5 | AA12: =I12*Z12 -> 160 | AC12: 77794UQ1-S002 | AD12: 已入 | AE12: =I12 -> 32 | AG12: 32 | AH12: =AG12-I12 -> 0 | AJ12: 系统出单 | AK12: =I12 -> 32 | AN12: =I12 -> 32 | AT12: =I12/8 -> 4
A13: 46044 | B13: SMYTHS TOYS HQ UC | C13: 法国 | D13: 4500191990 | E13: 4400528766 | F13: 4500191990-20 | G13: 77794UQ1-S001 | H13: 唱片机16pcs/2 UQ1/箱 | I13: 560 | J13: 0 | K13: 16 | L13: =I13/K13 -> 35 | M13: 46098 | N13: 46094 | P13: PASS | R13: 46044 | S13: 有 | T13: UN3481锂电池运输标签 | X13: 日期码格式：ZURU INC(BVI) 标准格式 日期：按实际生产日期 Packaging Info: 77794UQ1: MA PDQ (优先多语)+客版5L(英法德意荷)配套包装 (翻PO#4500191961) EAN#4894680051430 RECHARGEABLE LITHIUM BATTERY(INCLUDED) Remark: Smyths 法国 1. 请准时出货，推期会有罚款； 2. 所有产品按符合欧洲标准走货，需要是不含微塑料版本。 3. 电子产品需增加一张WEEE声明30L通用黑白说明书(不接受A版本，翻译有误)，区分带电池和不带电池出货版本, 如已做客版说明书可忽略此要求； 4. 出口法国的产品, 法规规定禁止在包装和共公众用的印刷品中使用矿物油中含有的物质, 包装印刷油墨中含有的MOAH/MOSH的质量浓度不能超过1%, 否则出货到 法国被抽检出现问题, 供应商需要对此负责; 5.订单备注显示有分批的（不同仓库/订单号） ，注意分开做货出货，否则会导致罚款 。 6.包装日期码按ZURU格式即可，请确保不迟于外箱日期码，可等于或者早于外箱日期码，必须为法定工作日。 7.做货前请先复核包装条码与订单是否一致再安排，对不上的需与ZURU跟单确认再安排。 | Y13: Sherry Lu | Z13: 4.355 | AA13: =I13*Z13 -> 2438.8 | AC13: 77794UQ1-S001-客版 | AD13: 已入 | AE13: =I13 -> 560 | AG13: 560 | AH13: =AG13-I13 -> 0 | AI13: OK | AJ13: 系统出单 | AM13: =I13 -> 560 | AN13: =I13 -> 560 | AU13: =I13/8 -> 70
A14: 46044 | B14: SMYTHS TOYS HQ UC | C14: 法国 | D14: 4500191990 | E14: 4400528767 | F14: 4500191990-40 | G14: 77794UQ1-S001 | H14: 唱片机16pcs/2 UQ1/箱 | I14: 240 | J14: 0 | K14: 16 | L14: =I14/K14 -> 15 | M14: 46098 | N14: 46094 | P14: PASS | Q14: 4/6 出货 | R14: 46044 | S14: 有 | T14: UN3481锂电池运输标签 | X14: 日期码格式：ZURU INC(BVI) 标准格式 日期：按实际生产日期 Packaging Info: 77794UQ1: MA PDQ (优先多语)+客版5L(英法德意荷)配套包装 (翻PO#4500191961) EAN#4894680051430 RECHARGEABLE LITHIUM BATTERY(INCLUDED) Remark: Smyths 法国 1. 请准时出货，推期会有罚款； 2. 所有产品按符合欧洲标准走货，需要是不含微塑料版本。 3. 电子产品需增加一张WEEE声明30L通用黑白说明书(不接受A版本，翻译有误)，区分带电池和不带电池出货版本, 如已做客版说明书可忽略此要求； 4. 出口法国的产品, 法规规定禁止在包装和共公众用的印刷品中使用矿物油中含有的物质, 包装印刷油墨中含有的MOAH/MOSH的质量浓度不能超过1%, 否则出货到 法国被抽检出现问题, 供应商需要对此负责; 5.订单备注显示有分批的（不同仓库/订单号） ，注意分开做货出货，否则会导致罚款 。 6.包装日期码按ZURU格式即可，请确保不迟于外箱日期码，可等于或者早于外箱日期码，必须为法定工作日。 7.做货前请先复核包装条码与订单是否一致再安排，对不上的需与ZURU跟单确认再安排。 | Y14: Sherry Lu | Z14: 4.355 | AA14: =I14*Z14 -> 1045.2 | AC14: 77794UQ1-S001-客版 | AD14: 已入 | AE14: =I14 -> 240 | AG14: 240 | AH14: =AG14-I14 -> 0 | AI14: OK | AJ14: 系统出单 | AM14: =I14 -> 240 | AN14: =I14 -> 240 | AU14: =I14/8 -> 30
A15: 46043 | B15: SMYTHS TOYS HQ UC UK | C15: 英国 | D15: 4500191961 | E15: 4400528768 | F15: 4500191961-10 | G15: MEC457-77794-S001 | H15: 唱片机+唱片球混装展示架 | I15: 6384 | J15: 0 | K15: 48 | L15: =I15/K15 -> 133 | M15: 46098 | N15: 46094 | P15: PASS | Q15: 4/6 出货 | R15: 46044 | S15: 有 | T15: 新地址贴纸ZURU FRANCE.33 rue Paul Meurice 75020 Paris, France.+WEEE声明29L通用黑白说明书+UN3481锂电池运输标签 | X15: 日期码格式：ZURU INC(BVI) 标准格式 日期：按实际生产日期 Packaging Info: MEC457: 客版5L(英法德意荷)展示架[84pcs#77772+48pcs#77794; 所有客版资料翻PO#4500191961] 77772: 客版3L-5Lwarning收缩膜+客版5L收藏指南+MA 23L组装说明+MA复合袋 EAN#4894680051133 77794: 客版3L-5Lwarning纸盒底座+客版3L镭射贴纸+客版3L单铜纸贴纸+MA23L游戏说明书+MA23L warning说明书+1张WEEE声明(带电池)走货欧洲通用29L-C版说明 书 EAN#4894680051430 做货前请先核对条码无误 RECHARGEABLE LITHIUM BATTERY(INCLUDED) *#77772必须移除Messy Lola Young (VINYL-S1-021) 这个唱片, 比例按PM更新的安排* *展架上的Demo Box的唱片需要用"A Little Too Much"(VINYL-S1-025)替代原来的"Messy"(VINYL-S1-021)* *外箱需加一张UN3481锂电池运输标签* Remark: Smyths 英国/爱尔兰 1. 请准时出货，推期会有罚款； 2. 所有产品按符合欧洲标准走货，需要是不含微塑料版本。 3.包装日期码按ZURU格式即可，请确保不迟于外箱日期码，可等于或者早于外箱日期码，必须为法定工作日，印刷前请先检查外箱日期码。 4.请注意检查产品及包装应带UKCA图标（14+产品除外），包装显示ZURU UK LTD/ZURU France地址信息，QC部门请查核，如有问题与跟单确认 5.电子产品需增加一张WEEE声明30L通用黑白说明书(不接受A版本，翻译有误)，区分带电池和不带电池出货版本, 如已做客版说明书可忽略此要求； 6.订单备注显示有分批的（不同仓库/订单号） ，注意分开做货出货，否则会导致罚款 。 7.做货前请先复核包装条码与订单是否一致再安排，对不上的需与ZURU跟单确认再安排。 | Y15: Sherry Lu | Z15: 306.676 | AA15: =L15*Z15 -> 40787.908 | AC15: MEC457-S001-77794 | AD15: 已入 | AE15: =I15 -> 6384 | AG15: =3442+2741+201 -> 6384 | AH15: =AG15-I15 -> 0 | AI15: OK | AJ15: 系统出单 | AM15: =I15 -> 6384 | AN15: =I15 -> 6384 | BA15: =I15/K15 -> 133
