Workbook

Sheet 9283
A1: ZURU Rainbocorn 美人鱼毛絨公仔生产排期表 #9283
A2: 44982 | G2: （黃色表示更改或增加） | J2: （蓝色表示已完货） | M2: （綠色表示調整貨期） | AE2: 收縮膜 | AL2: 收藏指南 | AP2: 贴纸 | BH2: 无闪粉毛绒比例 | BN2: 有闪粉毛绒
A3: 接单期 | B3: 第三方客户名称 | C3: 走货国家 | D3: PO号 | E3: 客户 PO 号 | F3: SKU | G3: ITEM# | H3: 中文名 | I3: PO数量 (pcs) | J3: 内箱装箱数量(pcs) | K3: 外箱装箱数量(pcs) | L3: 总箱数 | M3: 计划出货期 | N3: 计划验货期 | O3: 第三方验货日期 | P3: 驗貨結果 | Q3: 船期SO | R3: 箱唛资料 | S3: 是否有外箱贴 | T3: PMC订购 说明书纸 | U3: 贴纸资料 | V3: 客供物料 | W3: 日期码 | X3: 备注 | Y3: ZURU 跟单 | Z3: 单价USD | AA3: 金额USD | AB3: 發票號 | AC3: 系统货号 | AD3: 是否入系统 | AE3: MA 1語收縮膜 A版本 | AF3: MA 1語收縮膜 B版本 | AG3: MA 1語收縮膜 C版本无闪粉 | AH3: MA 3語收縮膜 A版本 | AI3: MA 3語收縮膜 B版本 | AJ3: MA 3語收縮膜 C版本无闪粉 | AK3: 客版收縮膜 | AL3: 5语 收藏指南 A版本 | AM3: 5语 收藏指南 B版本 | AN3: 5语 收藏指南 C版本无闪粉 | AO3: 客版收藏指南 | AP3: Try Me-1L贴纸 | AQ3: Try Me-1L贴纸-B版本 | AR3: Try Me-1L贴纸-C版本无闪粉 | AS3: Try Me-3L贴纸 | AT3: Try Me-3L贴纸-B版本 | AU3: Try Me-3L贴纸-C版本无闪粉 | AV3: Try Me-客办 | AW3: 藏宝图-C版本无闪粉 | AX3: 藏宝图-客版 | AY3: 9283 MA1L展示架 | AZ3: 9283 MA3L展示架 | BA3: 9283SLT-托盘 | BB3: MEC222展示架 | BC3: 客办展示架 | BD3: 客办PDQ | BE3: 旧布标+布标贴纸+新布标 | BF3: 布標 | BG3: 无闪粉毛绒 | BH3: A 小猫 Kitten | BI3: B 兔子 Bunny | BJ3: D 小狗 Puppy | BK3: E 奶牛 Cow | BL3: G 大象 Elephant | BM3: H 火烈鸟 Flamingo | BN3: A 小猫 Kitten | BO3: B 兔子 Bunny | BP3: D 小狗 Puppy | BQ3: E 奶牛 Cow | BR3: G 大象 Elephant | BS3: H 火烈鸟 Flamingo | BT3: 总数 | BU3: 相差 | BV3: 客户回复
A4: 45455 | B4: B&M RETAIL LIMITED | C4: 英国 | D4: 4500135559 | E4: 4500135559-5 01424822/1 | F4: 4500135559-60 | G4: 9283-S001 | H4: 美人鱼6只装（无闪粉） | I4: 2898 | J4: 0 | K4: 6 | L4: =I4/K4 -> 483 | M4: 45492 | N4: 45488 | P4: PASS | Q4: 7/29出 | R4: 6/13收到. | U4: 无 | X4: 日期码格式：ZURU INC(BVI) 标准格式 日期：按实际生产日期 Packaging Info: 9283:MA-1L 配套包装 Kitten:Bunny:Puppy:Cow:Elephant:Flamingo=1:1:1:1:1:1; 订单对应客户9个PO号 ，备注有显示 ，注意分开做货/验货/装柜 ，混装有罚款。 Remark: *MA版本按工厂现有最新库存即可，订单出英国，请注意检查产品及包装应带UKCA图标，包装显示ZURU UK LTD信息，QC同事请查核，如有问题与跟单确认。 *生产日期按实际的（法定工作日），按ZURU标准格式即可 ，但是请知悉包装日期码需要早于或者等于外箱日期码 ，不能晚于外箱日期码 *请注意所有订单都需要经过ZURU QC验货并且通过后方可出货 *条码以订单显示为准 ，请安排生产前先核对 ，有问题请提出。 *所有产品按符合欧洲标准走货，不能出带闪粉版本 ，需要是不含微塑料版本 。 | Y4: Sherry Lu | Z4: 5.8973 | AA4: =Z4*I4 -> 17090.375 | AC4: 9283-S001 | AD4: 已入 | AG4: =I4 -> 2898 | AN4: =I4 -> 2898 | AR4: =I4 -> 2898 | AW4: =I4 -> 2898 | BF4: MA布标 | BG4: =I4 -> 2898 | BH4: =I4/6 -> 483 | BI4: =I4/6 -> 483 | BJ4: =I4/6 -> 483 | BK4: =I4/6 -> 483 | BL4: =I4/6 -> 483 | BM4: =I4/6 -> 483 | BT4: =SUM(BH4:BS4) -> 2898 | BU4: =I4-BT4 -> 0
A5: 45600 | B5: TARGET US | C5: 美国 | D5: 4500150025 | E5: 10001106171-3890 | F5: 4500150025-10 | G5: 9283-S001 | H5: 美人鱼6只装 | I5: 3486 | J5: 0 | K5: 6 | L5: =I5/K5 -> 581 | M5: 45645 | N5: 45642 | P5: PASS | Q5: 收到SO | R5: 11/18收到 | U5: 无 | V5: 11/29-客供外箱贴纸 | X5: 日期码格式：ZURU INC(BVI) 标准格式 日期：按实际生产日期 Packaging Info: MA 包装, MA 1L 收缩膜(UPC版); Remark: 1. 9283-S001-RAINBOCORNS-MERMAIDCORN SURPRISE-SERIES 7 Plush Medium,Bulk,6pcs,No Inner,STD Color Assortment 2. MA 包装, MA 1L 收缩膜(UPC版); 收缩膜上的UPC显示193052050106； Kitten:Bunny:Puppy:Cow:Elephant:Flamingo=1:1:1:1:1:1; 3.外箱正唛左上角位置粘贴条码箱贴纸，每箱只贴一张，由ZURU订购。来料贴纸上显示的客户DPCI# 086-08-6431，UPC显示10193052050103; 4.产品和包装上印刷 tracking code信息，格式为ZURU常规格式; 5.出货方式：货代自提。 | Y5: Holly Zheng | Z5: 5.701 | AA5: =Z5*I5 -> 19873.686 | AB5: 88830-1.2 | AC5: 9283-S001 | AD5: 已入 | AG5: =I5 -> 3486 | AN5: =I5 -> 3486 | AR5: =I5 -> 3486 | AW5: =I5 -> 3486 | BF5: MA布标 | BH5: =I5/6 -> 581 | BI5: =I5/6 -> 581 | BJ5: =I5/6 -> 581 | BK5: =I5/6 -> 581 | BL5: =I5/6 -> 581 | BM5: =I5/6 -> 581 | BT5: =SUM(BH5:BS5) -> 3486 | BU5: =I5-BT5 -> 0
A6: 45586 | B6: TJX COMPANIES, INC | C6: 美国 | D6: 4500147789 | E6: Marshalls DC#881-372PCS , DC#884-288PCS , DC#886-420PCS , DC#887-354PCS , DC#888-366PCS | F6: 4500147789-10 | G6: 9283-S001 | H6: 美人鱼6只装 | I6: 1800 | J6: 0 | K6: 6 | L6: =I6/K6 -> 300 | M6: 45649 | N6: 45645 | P6: PASS | Q6: 1/2出 | R6: 11/4收到 | U6: 无 | V6: 11/19-价格贴纸 | X6: 日期码格式：ZURU INC(BVI) 标准格式 日期：按实际生产日期 Packaging Info: MA UPC包装+价格贴纸，价格贴纸客供。 Remark: 1. 产品和包装上印刷tracking code信息，格式为ZURU常规格式。 2. 分5个DC出货，每款产品每个DC的箱唛资料不同。具体分DC数量，请参考后面行项目备注。 3. ZURU QC验货。 | Y6: Emily Wu | Z6: 5.712 | AA6: =Z6*I6 -> 10281.6 | AB6: 94169-1.23 | AC6: 9283-S001 | AD6: 已入 | AG6: =I6 -> 1800 | AN6: =I6 -> 1800 | AR6: =I6 -> 1800 | AW6: =I6 -> 1800 | BF6: MA布标 | BH6: =I6/6 -> 300 | BI6: =I6/6 -> 300 | BJ6: =I6/6 -> 300 | BK6: =I6/6 -> 300 | BL6: =I6/6 -> 300 | BM6: =I6/6 -> 300 | BT6: =SUM(BH6:BS6) -> 1800 | BU6: =I6-BT6 -> 0
A7: 45587 | B7: PT. EMWAY GLOBALINDO | C7: 印度尼西亚 | D7: 4500148621 | E7: 24000405 | F7: 4500148621-30 | G7: 9283-S001 | H7: 美人鱼6只装 | I7: 252 | J7: 0 | K7: 6 | L7: =I7/K7 -> 42 | M7: 45651 | N7: 45647 | P7: PASS | Q7: 1/2出 | R7: 10/31收到 | U7: 无 | X7: 日期码格式：ZURU INC(BVI) 标准格式 日期：按实际生产日期 Packaging Info: 1.MA UPC包装(优先1L) 3.有第三方验货，将于CRD前一周提供验货员信息，请按订单CRD准时完货。 Remark:9283-Kitten:Bunny:Puppy:Cow:Elephant:Flamingo=1:1:1:1:1:1; | Y7: Emma Wu | Z7: 5.7196 | AA7: =Z7*I7 -> 1441.3392 | AB7: 88865-1.4 | AC7: 9283-S001 | AD7: 已入 | AG7: =I7 -> 252 | AN7: =I7 -> 252 | AR7: =I7 -> 252 | AW7: =I7 -> 252 | BF7: MA布标 | BH7: =I7/6 -> 42 | BI7: =I7/6 -> 42 | BJ7: =I7/6 -> 42 | BK7: =I7/6 -> 42 | BL7: =I7/6 -> 42 | BM7: =I7/6 -> 42 | BT7: =SUM(BH7:BS7) -> 252 | BU7: =I7-BT7 -> 0
A8: 45590 | B8: Amazon EU SARL, Ndl Deutschland | C8: 德国 | D8: 4500148999 | E8: 5WJDQBAA | F8: 4500148999-40 | G8: 9283B-S003 | H8: 兔子 | I8: 500 | J8: 0 | K8: 4 | L8: =I8/K8 -> 125 | M8: 45651 | N8: 45647 | P8: PASS | Q8: 1/4-1/8出 | R8: 空白外箱（加印带Zuru字样的最新logo，除了邮包盒直接做外箱的产品） + SSCC LABEL一张, 无箱唛’MADE IN CHINA 外箱只印一正一侧。 | U8: UPC+IT sorting labe翻4500139313+ZURU邮箱贴纸翻单4500149035 | V8: 11/21收到客供外箱贴纸 | X8: 日期码格式：ZURU INC(BVI) 标准格式 日期：按实际生产日期 Packaging Info: Amazon DE 9283B 4.9283B: 9283B Plush Medium Bunny, 4pcs/ctn,no inner; MA 3L(9L warning, EAN#)C收缩膜+3张贴纸（1张UPC#+IT环保标，参考翻单PO#4500139313；1张ES回 收标，参考翻单PO#4500149035；1张ZURU邮箱，参考翻单PO#4500149035）+MA 5L(9L warning)C收藏指南+其他最新MA配套包装; 5. ZURU 验货最迟不得晚于2024/12/26 Remark: 1.空白外箱（加印带Zuru字样的最新logo，除了邮包盒直接做外箱的产品） + SSCC LABEL一张, 无箱唛. (SSCC LABEL贴在外箱正面的正中间，贴一面即可,贴纸离外箱边距必须至少3.2CM),SSCC贴纸由工厂直接跟勤得采购或者工厂自行采购，每一张SSCC Label都是唯一 且有不同流水及条码，且需要检查条码是否能正常扫描，另外，此贴纸印刷不可出现模糊，溢出及粘胶不牢易脱落等现象，如工厂不按此要求导致贴纸有任何问题产 生的罚款将由工厂承担一切责任 。’MADE IN CHINA 外箱只印一正一侧。 2. 出往UK的产品+包装务必打上UKCA logo ，否则客人会退货且当地会有罚款。 3.订单必须经过ZURU QC验货并且通过后方可出货。 4.法国订单要求包装不使用矿物油，请按要求提供以下其中一份文件再出货 ，产品出到法国被相关部门抽检出现包装不符合此要求的，供应商需要为此承担责任， 故此请严格把关 。 -油墨物质""由1 ~ 7个芳香环组成的MOAH""的包装检测报告，要求限值≤1.0%; -包装材料清单，包括包装油墨或物质的信息 -油墨制造商的证书。 5 . 每一批次出货只能有一个生产日期，不可多个生产日期混在同一批次出货；且邮包盒上必须统一加上日期码； 6. 涉及到相关款式会有闪粉的或 者微塑料的，请统一默认出无闪粉或者不含微塑料 版本; 7 .邮包盒及外箱封箱必须是工字型封箱方式； 8 . 5 Surprise or Mini Brands涉及包装是2个及2个以上的球入PVC桶包装时，单个球上若有UPC#或者EAN#，请用白色贴纸覆盖住； | Y8: Zoe Chen | Z8: 5.8612 | AA8: =Z8*I8 -> 2930.6 | AB8: 88946-1.8 | AC8: 9283B-S003 | AD8: 已入 | AJ8: =I8 -> 500 | AN8: =I8 -> 500 | AU8: =I8 -> 500 | AW8: =I8 -> 500 | BF8: MA布标 | BI8: =I8 -> 500 | BT8: =SUM(BH8:BS8) -> 500 | BU8: =I8-BT8 -> 0
A9: 45595 | B9: AMAZON UK | C9: 英国 | D9: 4500149496 | E9: Amazon UK: 5J18RF7X | F9: 4500149496-20 | G9: 9283B-S003 | H9: 兔子 | I9: 500 | J9: 0 | K9: 4 | L9: =I9/K9 -> 125 | M9: 45651 | N9: 45647 | P9: PASS | R9: 空白外箱（加印带Zuru字样的最新logo，除了邮包盒直接做外箱的产品） + SSCC LABEL一张, 无箱唛。MADE IN CHINA 外箱只印一正一侧。 | U9: UPC+IT环保标翻4500139313+ES回收标翻4500149035 | V9: 11/29-客供外箱贴纸 | X9: 日期码格式：ZURU INC(BVI) 标准格式 日期：按实际生产日期 Packaging Info: Amazon UK(9279H, 9283B, 9281A, 9298B, 71109B) 2. 9283B：9283B Plush Medium Bunny, 4pcs/ctn,no inner; MA 3L(9L warning, EAN#)C收缩膜+2张贴纸（1张UPC#+IT环保标，参考翻单PO#4500139313；1张ES回 收标，参考翻单PO#4500149035）+MA 5L(9L warning)C收藏指南+其他最新MA配套包装; 6. 最迟验货不得晚于2024/12/26; Remark: 1.空白外箱（加印带Zuru字样的最新logo，除了邮包盒直接做外箱的产品） + SSCC LABEL一张, 无箱唛。 (SSCC LABEL贴在外箱正面的正中间，贴一面即可,贴纸离外箱边距必须至少3.2CM), SSCC贴纸由工厂直接跟勤得采购或者工厂自行采购，每一张SSCC Label都是唯一 且有不同流水及条码，且需要检查条码是否能正常扫描，另外，此贴纸印刷不可出现模糊，溢出及粘胶不牢易脱落等现象，如工厂不按此要求导致贴纸有任何问题产 生的罚款将由工厂承担一切责任 。’MADE IN CHINA 外箱只印一正一侧。 2.出往UK的产品+包装务必打上UKCA logo ，否则客人会退货且当地会有罚款。 3.订单必须经过ZURU QC验货并且通过后方可出货。 4.法国订单要求包装不使用矿物油，请按要求提供以下其中一份文件再出货 ，产品出到法国被相关部门抽检出现包装不符合此要求的，供应商需要为此承担责任， 故此请严格把关。 -油墨物质""由1 ~ 7个芳香环组成的MOAH""的包装检测报告，要求限值≤1.0%； -包装材料清单，包括包装油墨或物质的信息； -油墨制造商的证书； 5.每一批次出货只能有一个生产日期，不可多个生产日期混在同一批次出货；且邮包盒上必须统一加上日期码； 6.涉及到相关款式会有闪粉的或者微塑料的，请统一默认出无闪粉或者不含微塑料版本； 7.邮包盒及外箱封箱必须是工字型封箱方式； 8.5 Surprise or Mini Brands涉及包装是2个及2个以上的球入PVC桶包装时，单个球上若有UPC#或者EAN#，请用白色贴纸覆盖住； 9.箱唛资料按照给定的标准去做即可，无需发回我方再行审批(新标准将另行通知); | Y9: Crystal Chen | Z9: 5.8612 | AA9: =Z9*I9 -> 2930.6 | AB9: 88934-1.8 | AC9: 9283B-S003 | AD9: 已入 | AJ9: =I9 -> 500 | AN9: =I9 -> 500 | AU9: =I9 -> 500 | AW9: =I9 -> 500 | BF9: MA布标 | BI9: =I9 -> 500 | BT9: =SUM(BH9:BS9) -> 500 | BU9: =I9-BT9 -> 0
A10: 45621 | B10: Zhuyu(Shenzhen)Trading Co.,Ltd. | C10: 中国 | D10: 4500152175 | E10: 5000001714 | F10: 4500152175-50 | G10: 9283-S001 | H10: 美人鱼6只装 | I10: 8004 | J10: 0 | K10: 6 | L10: =I10/K10 -> 1334 | M10: 45651 | N10: 45647 | P10: PASS | Q10: 12/24出 | R10: 翻单4500150993 | U10: 中文3C贴纸+中文布标(可用布标贴纸)+年龄贴纸翻单4500150993 | V10: 12/2-芯片码（客供） | X10: 日期码格式：ZURU INC(BVI) 标准格式 日期：按实际生产日期 Tracking Code: Packaging Info: 物料要求 SKU 所有款号务必使用带有CCC 标识的AW 翻单： 5 9283 MA+中文3C贴纸 +中文收藏指南+中文布标(可用布标贴纸)+中文领养卡 +年龄贴纸+芯片码（客供） 翻单： 4500150993 Remark: 2.外箱材质如下： 1）毛重小于5kg 外箱纸质 K=B 爆破:1000Kpa 边压:4400N/M; 2）毛重大于5kg 外箱纸质 K636K 爆破:1400Kpa 边压:6300N/M; 3. 产品/销售包装/外箱日期码要一致， 4.芯片码横向平贴在上半部分蛋壳/彩盒内侧立面处，注意事项请见跟单提供文档资料。 5.此产品务必满足国内6P 测试标准，因为可能会被市场监督局抽查，如有问题产生，工厂要负全责 6. 这张订单做出厂价，我司自行安排车辆去贵司提货，贵司需要配合提供出口报关 | Y10: Tina Chen | Z10: 5.6846 | AA10: =Z10*I10 -> 45499.538 | AB10: 94157-1.23 | AC10: 9283-S001-6 | AD10: 已入 | AG10: =I10 -> 8004 | AO10: =I10 -> 8004 | AR10: =I10 -> 8004 | AW10: =I10 -> 8004 | BF10: MA布标 | BH10: =I10/6 -> 1334 | BI10: =I10/6 -> 1334 | BJ10: =I10/6 -> 1334 | BK10: =I10/6 -> 1334 | BL10: =I10/6 -> 1334 | BM10: =I10/6 -> 1334 | BT10: =SUM(BH10:BS10) -> 8004 | BU10: =I10-BT10 -> 0
A11: 45623 | B11: Zhuyu(Shenzhen)Trading Co.,Ltd. | C11: 中国 | D11: 4500152175 | E11: 5000001714 | F11: 4500152175-60 | G11: 9283-S001 | H11: 美人鱼6只装 | I11: 2400 | J11: 0 | K11: 6 | L11: =I11/K11 -> 400 | M11: 45653 | N11: 45649 | P11: PASS | Q11: 12/24出 | R11: 翻单4500150993 | U11: 中文3C贴纸+中文布标(可用布标贴纸)+年龄贴纸翻单4500150993 | V11: 12/6-芯片码（客供） | X11: 日期码格式：ZURU INC(BVI) 标准格式 日期：按实际生产日期 Packaging Info: 物料要求 SKU 所有款号务必使用带有CCC 标识的AW 翻单： 5 9283 MA+中文3C贴纸 +中文收藏指南+中文布标(可用布标贴纸)+中文领养卡 +年龄贴纸+芯片码（客供） 翻单： 4500150993 Remark: 2.外箱材质如下： 1）毛重小于5kg 外箱纸质 K=B 爆破:1000Kpa 边压:4400N/M; 2）毛重大于5kg 外箱纸质 K636K 爆破:1400Kpa 边压:6300N/M; 3. 产品/销售包装/外箱日期码要一致， 4.芯片码横向平贴在上半部分蛋壳/彩盒内侧立面处，注意事项请见跟单提供文档资料。 5.此产品务必满足国内6P 测试标准，因为可能会被市场监督局抽查，如有问题产生，工厂要负全责 6. 这张订单做出厂价，我司自行安排车辆去贵司提货，贵司需要配合提供出口报关 | Y11: Tina Chen | Z11: 5.6684 | AA11: =Z11*I11 -> 13604.16 | AB11: 94157-1.23 | AC11: 9283-S001-6 | AD11: 已入 | AG11: =I11 -> 2400 | AO11: =I11 -> 2400 | AR11: =I11 -> 2400 | AW11: =I11 -> 2400 | BF11: MA布标 | BH11: =I11/6 -> 400 | BI11: =I11/6 -> 400 | BJ11: =I11/6 -> 400 | BK11: =I11/6 -> 400 | BL11: =I11/6 -> 400 | BM11: =I11/6 -> 400 | BT11: =SUM(BH11:BS11) -> 2400 | BU11: =I11-BT11 -> 0
A12: 45618 | B12: WAL-MART STORES INC. USA | C12: 美国 | D12: 4500152092 | E12: 877286412 | F12: 4500152092-20 | G12: 9283SLB-S002 | H12: 美人鱼卡板装 | I12: 540 | J12: 0 | K12: 108 | L12: =I12/K12 -> 5 | M12: 45650 | N12: 45646 | O12: 12/25 BV | P12: PASS | Q12: 12/30出 | R12: 外箱四面印刷RFID箱唛，正唛左前下角印刷ITF-14格式条码的艾利替代标箱唛，只印刷正唛一面，Z URU logo跟MADE IN CHINA四面右下角印刷 | U12: 消耗4500132388客版布标贴纸 | V12: 消耗4500132388客供RFID贴纸 | X12: 日期码格式：ZURU DGYYYYMMDD CHINA(日期避开周末和法定节假日即可） 日期：按实际生产日期 Tracking Code: Packaging Info: 1.包装信息：MA C版 UPC版 1L收缩膜，MA C版 5L收藏指南，MA B版 1L Try Me贴纸，MA A版 3L贴纸，MA B版 5L配件袋，MA B版 5L泡泡水袋，MA B版 5L魔力沙袋 ，MA B版 5L领养卡，MA C版 5L藏宝图（原刮刮卡），MA B版车缝布标，客版布标贴纸，客供RFID贴纸（标贴位置严格按照我们签板的位置图，不可擅自调整位置， 贴纸不能有任何破损或折坏，不可淋湿）。 2.外箱四面印刷RFID箱唛，正唛左前下角印刷ITF-14格式条码的艾利替代标箱唛，只印刷正唛一面，整个内容尺寸最小10*10cm，加印时需确保条形码能扫描出来，Z URU logo跟MADE IN CHINA四面右下角印刷，外箱印刷日期码，每个slip sheet上面贴一张10*10cm艾利替代标（工厂自行用不干胶打印）和一张普通贴纸（可A4纸 打印），slip sheet打印的普通贴纸的尺寸不能比艾利替代标小。 3.在产品上和包装上要有日期码（避开周末和节假日），以及要有MADE IN CHINA和ZURU字样。 4.产品如有扎带口要剪平，不能刮手。 5.此单需要第三方验货，请自行多备物料。 6.此单打卡板出货（18x6H=108carton=108pcs/Slip Sheet）。 7.其它信息：Kitten : Bunny : Puppy : Cow : Elephant : Flamingo=1:1:1:1:1:1。 | Y12: Effy Li | Z12: 658.0781 | AA12: =L12*Z12 -> 3290.3905 | AB12: 88866-1.4 | AC12: 9283SLB-S002 | AD12: 已入 | AG12: =I12 -> 540 | AN12: =I12 -> 540 | AR12: =I12 -> 540 | AW12: =I12 -> 540 | BF12: MA布标新日期格式 | BG12: =I12 -> 540 | BH12: =I12/6 -> 90 | BI12: =I12/6 -> 90 | BJ12: =I12/6 -> 90 | BK12: =I12/6 -> 90 | BL12: =I12/6 -> 90 | BM12: =I12/6 -> 90 | BT12: =SUM(BH12:BS12) -> 540 | BU12: =I12-BT12 -> 0
A13: 45587 | B13: ROSS PROCUREMENT.INC | C13: 美国 | D13: 4500147716 | E13: 60190663 | F13: 4500147716-20 | G13: 9283-S001 | H13: 美人鱼6只装 | I13: 2004 | J13: 0 | K13: 6 | L13: =I13/K13 -> 334 | M13: 45653 | N13: 45649 | P13: PASS | Q13: 1/3出 | R13: 指定箱唛格式 | U13: 无 | V13: 11/20-客供价格贴纸 | X13: 日期码格式： 标准格式 日期：按实际生产日期 Packaging Info: 1.ZURU MA UPC 现有版本包装 + 客供价格贴纸，出口美国 , 优先使用MA 1L 最新版本 。 Remark: 1.ZURU MA UPC 现有版本包装 + 客供价格贴纸，出口美国 , 优先使用MA 1L 最新版本 。 2.价格贴纸位于包装正面右下角，不挡住重要信息即可，可适当调整 ，价格贴纸由跟单提供。 3.标准日期码格式，产品和包装必须有日期码 。 4.同个产品同个货期不可出现不同的包装。 5. 跟单提供ROSS通用的箱唛模版，工厂按实际45 PO上客户PO/Item号/装箱数 提供箱唛排版来确认 | Y13: Sophia Zhou | Z13: 5.712 | AA13: =Z13*I13 -> 11446.848 | AB13: 88881-1.6 | AC13: 9283-S001 | AD13: 已入 | AG13: =I13 -> 2004 | AN13: =I13 -> 2004 | AR13: =I13 -> 2004 | AW13: =I13 -> 2004 | BF13: MA布标 | BH13: =I13/6 -> 334 | BI13: =I13/6 -> 334 | BJ13: =I13/6 -> 334 | BK13: =I13/6 -> 334 | BL13: =I13/6 -> 334 | BM13: =I13/6 -> 334 | BT13: =SUM(BH13:BS13) -> 2004 | BU13: =I13-BT13 -> 0
A14: 45611 | B14: GP TURKEY | C14: 土耳其 | D14: 4500151435 | E14: 83721 | F14: 4500151435-30 | G14: 9283-S001 | H14: 美人鱼6只装 | I14: 1302 | J14: 0 | K14: 6 | L14: =I14/K14 -> 217 | M14: 45656 | N14: 45652 | P14: PASS | Q14: 1/2出 | R14: 11/28收到 | U14: 11/28-进口商贴纸（含客户条码 | W14: ZUR4365 | X14: 日期码格式：ZUR4365 日期： Packaging Info: 9283：MA 1L 收缩膜+进口商贴纸（含客户条码）; MA收藏指南 2.客户日期码：ZUR4365, 产品/包装/外箱请保持一致。产品蛋壳需要印日期和item号码 3.大货样版3套寄到客户香港办公室，请多备料 4.大货验货需要由ZURU QC抽1pc样板寄到广州ITS做EN 71-3测试 Remark: 9283:Kitten:Bunny:Puppy:Cow:Elephant:Flamingo=1:1:1:1:1:1; Bubble water;NO Boron; One plastic horn filled in water mixture; A pack of sand(60g) | Y14: Lena Huang | Z14: 5.8973 | AA14: =Z14*I14 -> 7678.2846 | AB14: 94160-1.23 | AC14: 9283-S001 | AD14: 已入 | AG14: =I14 -> 1302 | AN14: =I14 -> 1302 | AR14: =I14 -> 1302 | AW14: =I14 -> 1302 | BF14: MA布标 | BH14: =I14/6 -> 217 | BI14: =I14/6 -> 217 | BJ14: =I14/6 -> 217 | BK14: =I14/6 -> 217 | BL14: =I14/6 -> 217 | BM14: =I14/6 -> 217 | BT14: =SUM(BH14:BS14) -> 1302 | BU14: =I14-BT14 -> 0
A15: 45586 | B15: TJX COMPANIES, INC | C15: 美国 | D15: 4500147796 | E15: TJ MAXX DC#891-396PCS , DC#894-342PCS , DC#896-318PCS , DC#897-624PCS , DC#898-318PCS | F15: 4500147796-20 | G15: 9283-S001 | H15: 美人鱼6只装 | I15: 1998 | J15: 0 | K15: 6 | L15: =I15/K15 -> 333 | M15: 45656 | N15: 45652 | P15: PASS | Q15: 1/8出 | R15: 11/4收到 | U15: 无 | V15: 12/6-价格贴纸 | X15: 日期码格式：ZURU INC(BVI) 标准格式 日期：按实际生产日期 Packaging Info: MA UPC包装+价格贴纸，价格贴纸客供。 Remark: 1. 产品和包装上印刷tracking code信息，格式为ZURU常规格式。 2. 分5个DC出货，每款产品每个DC的箱唛资料不同。具体分DC数量，请参考后面行项目备注。 3. ZURU QC验货。 | Y15: Emily Wu | Z15: 5.8973 | AA15: =Z15*I15 -> 11782.805 | AB15: 94170-1.23 | AC15: 9283-S001 | AD15: 已入 | AG15: =I15 -> 1998 | AN15: =I15 -> 1998 | AR15: =I15 -> 1998 | AW15: =I15 -> 1998 | BF15: MA布标 | BH15: =I15/6 -> 333 | BI15: =I15/6 -> 333 | BJ15: =I15/6 -> 333 | BK15: =I15/6 -> 333 | BL15: =I15/6 -> 333 | BM15: =I15/6 -> 333 | BT15: =SUM(BH15:BS15) -> 1998 | BU15: =I15-BT15 -> 0
A16: 45586 | B16: TJX COMPANIES, INC | C16: 美国 | D16: 4500147793 | E16: Marshalls DC#881-372PCS , DC#884-288PCS , DC#886-414PCS , DC#887-348PCS , DC#888-378PCS | F16: 4500147793-20 | G16: 9283-S001 | H16: 美人鱼6只装 | I16: 1800 | J16: 0 | K16: 6 | L16: =I16/K16 -> 300 | M16: 45656 | N16: 45652 | P16: PASS | Q16: 1/4出 | R16: 11/4收到 | U16: 无 | V16: 12/6-价格贴纸 | X16: 日期码格式：ZURU INC(BVI) 标准格式 日期：按实际生产日期 Packaging Info: MA UPC包装+价格贴纸，价格贴纸客供。 Remark: 1. 产品和包装上印刷tracking code信息，格式为ZURU常规格式。 2. 分5个DC出货，每款产品每个DC的箱唛资料不同。具体分DC数量，请参考后面行项目备注。 3. ZURU QC验货。 | Y16: Emily Wu | Z16: 5.8973 | AA16: =Z16*I16 -> 10615.14 | AB16: 94171-1.23 | AC16: 9283-S001 | AD16: 已入 | AG16: =I16 -> 1800 | AN16: =I16 -> 1800 | AR16: =I16 -> 1800 | AW16: =I16 -> 1800 | BF16: MA布标 | BH16: =I16/6 -> 300 | BI16: =I16/6 -> 300 | BJ16: =I16/6 -> 300 | BK16: =I16/6 -> 300 | BL16: =I16/6 -> 300 | BM16: =I16/6 -> 300 | BT16: =SUM(BH16:BS16) -> 1800 | BU16: =I16-BT16 -> 0
A17: 45586 | B17: TJX COMPANIES, INC | C17: 美国 | D17: 4500147795 | E17: TJ MAXX DC#891-396PCS , DC#894-342PCS , DC#896-312PCS , DC#897-624PCS , DC#898-324PCS | F17: 4500147795-20 | G17: 9283-S001 | H17: 美人鱼6只装 | I17: 1998 | J17: 0 | K17: 6 | L17: =I17/K17 -> 333 | M17: 45656 | N17: 45652 | P17: PASS | Q17: 1/8出 | R17: 11/4收到 | U17: 无 | V17: 12/6-价格贴纸 | X17: 日期码格式：ZURU INC(BVI) 标准格式 日期：按实际生产日期 Packaging Info: MA UPC包装+价格贴纸，价格贴纸客供。 Remark: 1. 产品和包装上印刷tracking code信息，格式为ZURU常规格式。 2. 分5个DC出货，每款产品每个DC的箱唛资料不同。具体分DC数量，请参考后面行项目备注。 3. ZURU QC验货。 | Y17: Emily Wu | Z17: 5.8973 | AA17: =Z17*I17 -> 11782.805 | AB17: 94175-1.23 | AC17: 9283-S001 | AD17: 已入 | AG17: =I17 -> 1998 | AN17: =I17 -> 1998 | AR17: =I17 -> 1998 | AW17: =I17 -> 1998 | BF17: MA布标 | BH17: =I17/6 -> 333 | BI17: =I17/6 -> 333 | BJ17: =I17/6 -> 333 | BK17: =I17/6 -> 333 | BL17: =I17/6 -> 333 | BM17: =I17/6 -> 333 | BT17: =SUM(BH17:BS17) -> 1998 | BU17: =I17-BT17 -> 0
A18: 45586 | B18: TJX COMPANIES, INC | C18: 美国 | D18: 4500147792 | E18: Marshalls DC#881-372PCS , DC#884-288PCS , DC#886-420PCS , DC#887-354PCS , DC#888-366PCS | F18: 4500147792-20 | G18: 9283-S001 | H18: 美人鱼6只装 | I18: 1800 | J18: 0 | K18: 6 | L18: =I18/K18 -> 300 | M18: 45656 | N18: 45652 | P18: PASS | Q18: 1/14出 | R18: 11/4收到 | U18: 无 | V18: 12/6-价格贴纸 | X18: 日期码格式：ZURU INC(BVI) 标准格式 日期：按实际生产日期 Packaging Info: MA UPC包装+价格贴纸，价格贴纸客供。 Remark: 1. 产品和包装上印刷tracking code信息，格式为ZURU常规格式。 2. 分5个DC出货，每款产品每个DC的箱唛资料不同。具体分DC数量，请参考后面行项目备注。 3. ZURU QC验货。 | Y18: Emily Wu | Z18: 5.8973 | AA18: =Z18*I18 -> 10615.14 | AB18: 94166-1.23 | AC18: 9283-S001 | AD18: 已入 | AG18: =I18 -> 1800 | AN18: =I18 -> 1800 | AR18: =I18 -> 1800 | AW18: =I18 -> 1800 | BF18: MA布标 | BH18: =I18/6 -> 300 | BI18: =I18/6 -> 300 | BJ18: =I18/6 -> 300 | BK18: =I18/6 -> 300 | BL18: =I18/6 -> 300 | BM18: =I18/6 -> 300 | BT18: =SUM(BH18:BS18) -> 1800 | BU18: =I18-BT18 -> 0
A19: 45586 | B19: TJX COMPANIES, INC | C19: 美国 | D19: 4500147798 | E19: TJ MAXX DC#891-396PCS , DC#894-342PCS , DC#896-312PCS , DC#897-624PCS , DC#898-324PCS | F19: 4500147798-20 | G19: 9283-S001 | H19: 美人鱼6只装 | I19: 1998 | J19: 0 | K19: 6 | L19: =I19/K19 -> 333 | M19: 45657 | N19: 45653 | P19: PASS | Q19: 1/8出 | R19: 11/4收到 | U19: 无 | V19: 12/6-价格贴纸 | X19: 日期码格式：ZURU INC(BVI) 标准格式 日期：按实际生产日期 Packaging Info: MA UPC包装+价格贴纸，价格贴纸客供。 Remark: 1. 产品和包装上印刷tracking code信息，格式为ZURU常规格式。 2. 分5个DC出货，每款产品每个DC的箱唛资料不同。具体分DC数量，请参考后面行项目备注。 3. ZURU QC验货。 | Y19: Emily Wu | Z19: 5.8973 | AA19: =Z19*I19 -> 11782.805 | AB19: 94174-1.23 | AC19: 9283-S001 | AD19: 已入 | AG19: =I19 -> 1998 | AN19: =I19 -> 1998 | AR19: =I19 -> 1998 | AW19: =I19 -> 1998 | BF19: MA布标 | BH19: =I19/6 -> 333 | BI19: =I19/6 -> 333 | BJ19: =I19/6 -> 333 | BK19: =I19/6 -> 333 | BL19: =I19/6 -> 333 | BM19: =I19/6 -> 333 | BT19: =SUM(BH19:BS19) -> 1998 | BU19: =I19-BT19 -> 0
A20: 45586 | B20: TJX COMPANIES, INC | C20: 美国 | D20: 4500147794 | E20: Marshalls DC#881-372PCS , DC#884-288PCS , DC#886-420PCS , DC#887-354PCS , DC#888-366PCS | F20: 4500147794-20 | G20: 9283-S001 | H20: 美人鱼6只装 | I20: 1800 | J20: 0 | K20: 6 | L20: =I20/K20 -> 300 | M20: 45657 | N20: 45653 | P20: PASS | Q20: 1/10出 | R20: 11/4收到 | U20: 无 | V20: 12/6-价格贴纸 | X20: 日期码格式：ZURU INC(BVI) 标准格式 日期：按实际生产日期 Packaging Info: MA UPC包装+价格贴纸，价格贴纸客供。 Remark: 1. 产品和包装上印刷tracking code信息，格式为ZURU常规格式。 2. 分5个DC出货，每款产品每个DC的箱唛资料不同。具体分DC数量，请参考后面行项目备注。 3. ZURU QC验货。 | Y20: Emily Wu | Z20: 5.8973 | AA20: =Z20*I20 -> 10615.14 | AB20: 94176-1.23 | AC20: 9283-S001 | AD20: 已入 | AG20: =I20 -> 1800 | AN20: =I20 -> 1800 | AR20: =I20 -> 1800 | AW20: =I20 -> 1800 | BF20: MA布标 | BH20: =I20/6 -> 300 | BI20: =I20/6 -> 300 | BJ20: =I20/6 -> 300 | BK20: =I20/6 -> 300 | BL20: =I20/6 -> 300 | BM20: =I20/6 -> 300 | BT20: =SUM(BH20:BS20) -> 1800 | BU20: =I20-BT20 -> 0
A21: 45604 | B21: ASDA STORES LTD | C21: 英国 | D21: 4500150696 | E21: 2950866090 | F21: 4500150696-20 | G21: 9283SLB-S001 | H21: 美人鱼卡板装（无闪粉） | I21: 1040 | J21: 1 | K21: 80 | L21: =I21/K21 -> 13 | M21: 45656 | N21: 45652 | P21: PASS | Q21: 1/8出 | R21: 11/29收到 | U21: 11/29-卡板贴纸 | X21: 日期码格式：ZURU INC(BVI) 标准格式 日期：按实际生产日期 Packaging Info: 6.9283SLB 9283-S002:MA 1L最新UPC包装； UPC#193052050106，请先检查条码是否正确再安排做货； Kitten:Bunny:Puppy:Cow:Elephant:Flamingo=1:1:1:1:1:1; Slip Sheet: 1 PCS/CTN, 22*4=88ctn=88pcs/slip sheet, 一共需要13套slip sheet; Slip Sheet打包好后，需要在正唛、侧唛右下角各贴一张slip sheet贴纸，直接用A4纸打印出来即可，贴纸尺寸160mm width x 140mm high； Slip Sheet尺寸限制为100*115*130CM，一旦实际SLIP SHEET尺寸超过这个尺寸，请提前通知ZURU跟单，需同客人确 认才能量产和出货; Remark: 1. 产品及包装需要印UKCA图标，包装需要有ZURU UK LTD/ZURU France地址信息，QC同事请核查，如有问题与跟单确认 2. 产品/包装/外箱都需要打ZURU格式日期码，日期必须为法定工作日。 3. 需要符合欧洲标准不能含有闪粉和微塑料，否则不合法规会有客诉产生 | Y21: Amy Ding | Z21: 482.4908 | AA21: =Z21*L21 -> 6272.3804 | AB21: 88944-1.8 | AC21: 9283SLB-S001 | AD21: 已入 | AG21: =I21 -> 1040 | AN21: =I21 -> 1040 | AR21: =I21 -> 1040 | AW21: =I21 -> 1040 | BF21: MA布标 | BG21: =I21 -> 1040 | BH21: =I21/6 -> 173.33333 | BI21: =I21/6 -> 173.33333 | BJ21: =I21/6 -> 173.33333 | BK21: =I21/6 -> 173.33333 | BL21: =I21/6 -> 173.33333 | BM21: =I21/6 -> 173.33333 | BT21: =SUM(BH21:BS21) -> 1040 | BU21: =I21-BT21 -> 0
A22: 45617 | B22: TARGET US | C22: 美国 | D22: 4500151914 | E22: 10001106177-3890 | F22: 4500151914-10 | G22: 9283-S001 | H22: 美人鱼6只装 | I22: 3030 | J22: 0 | K22: 6 | L22: =I22/K22 -> 505 | M22: 45657 | N22: 45654 | P22: PASS | Q22: 1/6出 | R22: 11/28收到 | U22: 无 | V22: 12/6-外箱贴纸 | X22: 日期码格式：ZURU INC(BVI) 标准格式 日期：按实际生产日期 Tracking Code: Packaging Info: MA 包装, MA 1L 收缩膜(UPC版); Remark: 1. 9283-S001-RAINBOCORNS-MERMAIDCORN SURPRISE-SERIES 7 Plush Medium,Bulk,6pcs,No Inner,STD Color Assortment 2. MA 包装, MA 1L 收缩膜(UPC版); 收缩膜上的UPC显示193052050106； Kitten:Bunny:Puppy:Cow:Elephant:Flamingo=1:1:1:1:1:1; 3.外箱正唛左上角位置粘贴条码箱贴纸，每箱只贴一张，由ZURU订购。来料贴纸上显示的客户DPCI# 086-08-6431，UPC显示10193052050103; 4.产品和包装上印刷 tracking code信息，格式为ZURU常规格式; 5.出货方式：货代自提。 | Y22: Holly Zheng | Z22: 5.701 | AA22: =Z22*I22 -> 17274.03 | AB22: 88882-1.6 | AC22: 9283-S001 | AD22: 已入 | AG22: =I22 -> 3030 | AN22: =I22 -> 3030 | AR22: =I22 -> 3030 | AW22: =I22 -> 3030 | BF22: MA布标 | BH22: =I22/6 -> 505 | BI22: =I22/6 -> 505 | BJ22: =I22/6 -> 505 | BK22: =I22/6 -> 505 | BL22: =I22/6 -> 505 | BM22: =I22/6 -> 505 | BT22: =SUM(BH22:BS22) -> 3030 | BU22: =I22-BT22 -> 0
A23: 45614 | B23: BURLINGTON COAT FACTORY | C23: 美国 | D23: 4500151472 | E23: 客户PO#383017 503 | F23: 4500151472-20 | G23: 9283-S001 | H23: 美人鱼6只装 | I23: 2400 | J23: 0 | K23: 6 | L23: =I23/K23 -> 400 | M23: 45663 | N23: 45659 | P23: PASS | Q23: 1/10出 | R23: 11/18收到 | U23: 12/13-客供价格贴纸+12/12-外箱贴纸 | X23: 日期码格式：ZURU INC(BVI) 标准格式 日期：按实际生产日期 Packaging Info: 1，ZURU MA （首选1L）UPC版本+客供价格贴纸+外箱贴纸，出口美国 有PVC桶的价格贴纸贴在PVC桶上面 Remark: 2，产品和包装上印刷ZURU 标准日期码； 3，纸箱中间靠上沿印刷ZURU LOGO，见箱唛资料 4、外箱UCC 条码贴纸，尺寸: 4*6inch，贴在其中一面正唛右下角，贴纸距离外箱底部3.5cm, 侧边距离3.5cm。外箱贴纸由跟单提供电子版, 工厂自行安排，不可用 封箱胶覆盖贴纸条码，贴纸需要可以扫描且无损坏. 5，每个产品有一个价格贴纸， 价格贴纸覆盖UPC条码上 （若UPC 条码太大，可以露出ITEM#, 覆盖条码即可），若价格贴纸覆盖UPC 会挡住文字/图案，在产品背面 找空白处粘贴价格贴纸即可。贴的时候要是会覆盖包装上重要的信息和图案，需要告知跟单。 | Y23: Jessi Xu | Z23: 5.8973 | AA23: =Z23*I23 -> 14153.52 | AB23: 88981-1.10 | AC23: 9283-S001 | AD23: 已入 | AG23: =I23 -> 2400 | AN23: =I23 -> 2400 | AR23: =I23 -> 2400 | AW23: =I23 -> 2400 | BF23: MA布标 | BH23: =I23/6 -> 400 | BI23: =I23/6 -> 400 | BJ23: =I23/6 -> 400 | BK23: =I23/6 -> 400 | BL23: =I23/6 -> 400 | BM23: =I23/6 -> 400 | BT23: =SUM(BH23:BS23) -> 2400 | BU23: =I23-BT23 -> 0
A24: 45614 | B24: BURLINGTON COAT FACTORY | C24: 美国 | D24: 4500151472 | E24: 客户PO#383019 403 | F24: 4500151472-70 | G24: 9283-S001 | H24: 美人鱼6只装 | I24: 2400 | J24: 0 | K24: 6 | L24: =I24/K24 -> 400 | M24: 45663 | N24: 45659 | P24: PASS | Q24: 1/10出 | R24: 11/18收到 | U24: 12/13-客供价格贴纸+12/12-外箱贴纸 | X24: 日期码格式：ZURU INC(BVI) 标准格式 日期：按实际生产日期 Packaging Info: 1，ZURU MA （首选1L）UPC版本+客供价格贴纸+外箱贴纸，出口美国 有PVC桶的价格贴纸贴在PVC桶上面 Remark: 2，产品和包装上印刷ZURU 标准日期码； 3，纸箱中间靠上沿印刷ZURU LOGO，见箱唛资料 4、外箱UCC 条码贴纸，尺寸: 4*6inch，贴在其中一面正唛右下角，贴纸距离外箱底部3.5cm, 侧边距离3.5cm。外箱贴纸由跟单提供电子版, 工厂自行安排，不可用 封箱胶覆盖贴纸条码，贴纸需要可以扫描且无损坏. 5，每个产品有一个价格贴纸， 价格贴纸覆盖UPC条码上 （若UPC 条码太大，可以露出ITEM#, 覆盖条码即可），若价格贴纸覆盖UPC 会挡住文字/图案，在产品背面 找空白处粘贴价格贴纸即可。贴的时候要是会覆盖包装上重要的信息和图案，需要告知跟单。 | Y24: Jessi Xu | Z24: 5.8973 | AA24: =Z24*I24 -> 14153.52 | AB24: 88988-1.11 | AC24: 9283-S001 | AD24: 已入 | AG24: =I24 -> 2400 | AN24: =I24 -> 2400 | AR24: =I24 -> 2400 | AW24: =I24 -> 2400 | BF24: MA布标 | BH24: =I24/6 -> 400 | BI24: =I24/6 -> 400 | BJ24: =I24/6 -> 400 | BK24: =I24/6 -> 400 | BL24: =I24/6 -> 400 | BM24: =I24/6 -> 400 | BT24: =SUM(BH24:BS24) -> 2400 | BU24: =I24-BT24 -> 0
A25: 45617 | B25: N.V. DREAMLAND | C25: 比利时 | D25: 4500151910 | E25: 450054548 | F25: 4500151910-20 | G25: 9283-S001 | H25: 美人鱼6只装 | I25: 1596 | J25: 0 | K25: 6 | L25: =I25/K25 -> 266 | M25: 45663 | N25: 45659 | P25: PASS | R25: 11/21收到 | U25: 无 | X25: 日期码格式：ZURU INC(BVI) 标准格式 日期：按实际生产日期 Tracking Code: Packaging Info: 9283: MA C版 3L EAN收缩膜（含NL警语），MA B版 3L Try Me 贴纸，MA C版 5L收藏指南（含NL警语），MA C版 5L地图（含NL警语），MA B版 5L配件袋，MA B版 5L证书，MA B版布标，MA B版贴纸 Remark: 1.外箱需要印条码，请确保条码可以清晰扫描，且条码内容正确 2.出欧洲，微塑料需合规（如item本身不含微塑料,则忽略此要求） 3.STD配比 4. 所有产品符合REACH申明 | Y25: Amber Zhang | Z25: 5.712 | AA25: =Z25*I25 -> 9116.352 | AB25: 94005-1.13 | AC25: 9283-S001-1 | AD25: 已入 | AJ25: =I25 -> 1596 | AN25: =I25 -> 1596 | AU25: =I25 -> 1596 | AW25: =I25 -> 1596 | BF25: MA布标 | BH25: =I25/6 -> 266 | BI25: =I25/6 -> 266 | BJ25: =I25/6 -> 266 | BK25: =I25/6 -> 266 | BL25: =I25/6 -> 266 | BM25: =I25/6 -> 266 | BT25: =SUM(BH25:BS25) -> 1596 | BU25: =I25-BT25 -> 0
A26: 45622 | B26: MCD BRANDS SAS | C26: 乌拉圭 | D26: 4500152326 | F26: 4500152326-60 | G26: 9283-S001 | H26: 美人鱼6只装 | I26: 120 | J26: 0 | K26: 6 | L26: =I26/K26 -> 20 | M26: 45663 | N26: 45659 | P26: PASS | Q26: 1/9出 | R26: 翻单4500108308 | U26: 进口商贴纸/EAN贴纸翻单4500108308 | X26: 日期码格式：ZURU INC(BVI) 标准格式 日期：按实际生产日期 Packaging Info: 9283：MA 3L包装+进口商贴纸+箱唛 +EAN贴纸，进口商贴纸/箱唛/EAN贴纸翻单PO4500108308 Remark: 进口商贴纸请多备料5pcs,出货后需要寄给客户 | Y26: Ava Liang | Z26: 5.905 | AA26: =Z26*I26 -> 708.6 | AB26: 88941-1.8 | AC26: 9283-S001-1 | AD26: 已入 | AJ26: =I26 -> 120 | AN26: =I26 -> 120 | AU26: =I26 -> 120 | AW26: =I26 -> 120 | BF26: MA布标 | BH26: =I26/6 -> 20 | BI26: =I26/6 -> 20 | BJ26: =I26/6 -> 20 | BK26: =I26/6 -> 20 | BL26: =I26/6 -> 20 | BM26: =I26/6 -> 20 | BT26: =SUM(BH26:BS26) -> 120 | BU26: =I26-BT26 -> 0
A27: 45618 | B27: KMART AUSTRALIA LTD(NEW ZEALAND) | C27: 新西兰 | D27: 4500152016 | E27: 20478298 | F27: 4500152016-20 | G27: 9283-S001 | H27: 美人鱼6只装 | I27: 42 | J27: 0 | K27: 6 | L27: =I27/K27 -> 7 | M27: 45663 | N27: 45659 | P27: PASS | Q27: 1/8-1/10出 | R27: 11/22收到 | U27: 12/13-防盗贴纸+12/16-外箱贴纸 | X27: 日期码格式：ZURU INC(BVI) 标准格式 日期：按实际生产日期 Tracking Code: Packaging Info: 9283: MA英语UPC版本包装（收缩膜和说明书, MA首选1L，如无1L可用多语且含英语的配套多语包装) + 1张防盗贴纸 (贴纸以及位置图翻单PO#4500095104）+ 箱唛 + 外箱SSCC Label Remark: 1.请务必按时完货，验货。并且按期送货入货代指定仓库，如果晚了导致船期Delay将会有罚金产生或者客户要求空运，所产生的罚金和空运费由工厂承担。 2.SSCC 外箱贴纸请同纸箱瓦楞纸方向（竖纹向）垂直，即外箱贴纸横着贴(注意条码不要被胶带粘住），贴1pc，贴1面正唛，封箱胶纸不能挡住贴纸内容。外箱贴纸 离外箱边距离不少于2cm。 3.外箱材质为ZURU标准； 4.此单需使用KMART封箱胶上下工字型封箱;从2019年6月开始，要用KMART 新版封箱胶带，此单要用"ANKO"封箱胶带 5.此单出口新西兰，请按相应的澳新标准生产； 6.产品和包装上生产批号的显示格式ZURU标准日期码格式 7.外箱信息不可手写，重量和体积需要与实际的一致(不可手写） 8. 每款item装箱后的G.W.超过10KG或者CBM超过0.13,(9.5KG或者以上，四舍五入后也属于10KG) 需在外箱上加印超 重或者Bulky LOGO，若发现我们资料没有，请 帮忙提醒 1)重量超过10kg但不超过16kg且CBM不超过0.13,10-16kg 超重logo 2）CBM超过0.13且重量少于17kg，bulky logo 3）不属于以上两种情况，需要使用相应重量范围内的超重logo 4）超重logo需要在外箱四面都印刷(箱唛右上角，两面侧唛超重logo需要尽量靠近毛重)，尺寸为:110mm height* 95mm width 9. 实际外箱重量跟印在箱唛上的数据差异不能超3%，尺寸按实际数据印刷 | Y27: Lydia Wu | Z27: 6.2984 | AA27: =Z27*I27 -> 264.5328 | AB27: 88967-1.10 | AC27: 9283-S001 | AD27: 已入 | AG27: =I27 -> 42 | AN27: =I27 -> 42 | AR27: =I27 -> 42 | AW27: =I27 -> 42 | BF27: MA布标 | BH27: =I27/6 -> 7 | BI27: =I27/6 -> 7 | BJ27: =I27/6 -> 7 | BK27: =I27/6 -> 7 | BL27: =I27/6 -> 7 | BM27: =I27/6 -> 7 | BT27: =SUM(BH27:BS27) -> 42 | BU27: =I27-BT27 -> 0
A28: 45618 | B28: KMART AUSTRALIA LTD | C28: 澳大利亚 | D28: 4500152006 | E28: 20357441 | F28: 4500152006-30 | G28: 9283-S001 | H28: 美人鱼6只装 | I28: 1458 | J28: 0 | K28: 6 | L28: =I28/K28 -> 243 | M28: 45663 | N28: 45659 | P28: PASS | Q28: 1/8-1/10出 | R28: 11/22收到 | U28: 12/13-防盗贴纸+12/16-外箱贴纸 | X28: 日期码格式：ZURU INC(BVI) 标准格式 日期：按实际生产日期 Tracking Code: Packaging Info: 9283: MA英语UPC版本包装（收缩膜和说明书, MA首选1L，如无1L可用多语且含英语的配套多语包装) + 1张防盗贴纸 (贴纸以及位置图翻单PO#4500095104）+ 箱唛 + 外箱SSCC Label Remark: 1.请务必按时完货，验货。并且按期送货入货代指定仓库，如果晚了导致船期Delay将会有罚金产生或者客户要求空运，所产生的罚金和空运费由工厂承担。 2.SSCC 外箱贴纸请同纸箱瓦楞纸方向（竖纹向）垂直，即外箱贴纸横着贴(注意条码不要被胶带粘住），贴1pc，贴1面正唛，封箱胶纸不能挡住贴纸内容。外箱贴纸 离外箱边距离不少于2cm。 3.外箱材质为ZURU标准； 4.此单需使用KMART封箱胶上下工字型封箱;从2019年6月开始，要用KMART 新版封箱胶带，此单要用"ANKO"封箱胶带 5.此单出口澳大利亚，请按相应的澳新标准生产； 6.产品和包装上生产批号的显示格式ZURU标准日期码格式 7.外箱信息不可手写，重量和体积需要与实际的一致(不可手写） 8. 每款item装箱后的G.W.超过10KG或者CBM超过0.13,(9.5KG或者以上，四舍五入后也属于10KG) 需在外箱上加印超 重或者Bulky LOGO，若发现我们资料没有，请 帮忙提醒 1)重量超过10kg但不超过16kg且CBM不超过0.13,10-16kg 超重logo 2）CBM超过0.13且重量少于17kg，bulky logo 3）不属于以上两种情况，需要使用相应重量范围内的超重logo 4）超重logo需要在外箱四面都印刷(箱唛右上角，两面侧唛超重logo需要尽量靠近毛重)，尺寸为:110mm height* 95mm width 9. 实际外箱重量跟印在箱唛上的数据差异不能超3%，尺寸按实际数据印刷 | Y28: Lydia Wu | Z28: 6.2908 | AA28: =Z28*I28 -> 9171.9864 | AB28: 88966-1.10 | AC28: 9283-S001 | AD28: 已入 | AG28: =I28 -> 1458 | AN28: =I28 -> 1458 | AR28: =I28 -> 1458 | AW28: =I28 -> 1458 | BF28: MA布标 | BH28: =I28/6 -> 243 | BI28: =I28/6 -> 243 | BJ28: =I28/6 -> 243 | BK28: =I28/6 -> 243 | BL28: =I28/6 -> 243 | BM28: =I28/6 -> 243 | BT28: =SUM(BH28:BS28) -> 1458 | BU28: =I28-BT28 -> 0
A29: 45621 | B29: KMART AUSTRALIA LTD | C29: 澳大利亚 | D29: 4500152292 | E29: 20357441 | F29: 4500152292-40 | G29: 9283-S001 | H29: 美人鱼6只装 | I29: 1362 | J29: 0 | K29: 6 | L29: =I29/K29 -> 227 | M29: 45663 | N29: 45659 | P29: PASS | Q29: 1/8-1/10出 | R29: 12/3收到 | U29: 12/13-防盗贴纸+12/16-外箱贴纸 | X29: 日期码格式：ZURU INC(BVI) 标准格式 日期：按实际生产日期 Tracking Code: Packaging Info: 9283: MA英语UPC版本包装（收缩膜和说明书, MA首选1L，如无1L可用多语且含英语的配套多语包装) + 1张防盗贴纸 (贴纸以及位置图翻单PO#4500095104）+ 箱唛 + 外箱SSCC Label Remark: 1.请务必按时完货，验货。并且按期送货入货代指定仓库，如果晚了导致船期Delay将会有罚金产生或者客户要求空运，所产生的罚金和空运费由工厂承担。 2.SSCC 外箱贴纸请同纸箱瓦楞纸方向（竖纹向）垂直，即外箱贴纸横着贴(注意条码不要被胶带粘住），贴1pc，贴1面正唛，封箱胶纸不能挡住贴纸内容。外箱贴纸 离外箱边距离不少于2cm。 3.外箱材质为ZURU标准； 4.此单需使用KMART封箱胶上下工字型封箱;从2019年6月开始，要用KMART 新版封箱胶带，此单要用"ANKO"封箱胶带 5.此单出口澳大利亚，请按相应的澳新标准生产； 6.产品和包装上生产批号的显示格式ZURU标准日期码格式 7.外箱信息不可手写，重量和体积需要与实际的一致(不可手写） 8. 每款item装箱后的G.W.超过10KG或者CBM超过0.13,(9.5KG或者以上，四舍五入后也属于10KG) 需在外箱上加印超 重或者Bulky LOGO，若发现我们资料没有，请 帮忙提醒 1)重量超过10kg但不超过16kg且CBM不超过0.13,10-16kg 超重logo 2）CBM超过0.13且重量少于17kg，bulky logo 3）不属于以上两种情况，需要使用相应重量范围内的超重logo 4）超重logo需要在外箱四面都印刷(箱唛右上角，两面侧唛超重logo需要尽量靠近毛重)，尺寸为:110mm height* 95mm width 9. 实际外箱重量跟印在箱唛上的数据差异不能超3%，尺寸按实际数据印刷 | Y29: Lydia Wu | Z29: 6.2908 | AA29: =Z29*I29 -> 8568.0696 | AB29: 88993-1.11 | AC29: 9283-S001 | AD29: 已入 | AG29: =I29 -> 1362 | AN29: =I29 -> 1362 | AR29: =I29 -> 1362 | AW29: =I29 -> 1362 | BF29: MA布标 | BH29: =I29/6 -> 227 | BI29: =I29/6 -> 227 | BJ29: =I29/6 -> 227 | BK29: =I29/6 -> 227 | BL29: =I29/6 -> 227 | BM29: =I29/6 -> 227 | BT29: =SUM(BH29:BS29) -> 1362 | BU29: =I29-BT29 -> 0
A30: 45621 | B30: SUCKOT SAC | C30: 秘鲁 | D30: 4500152261 | F30: 45000152261-70 | G30: 9283-S001 | H30: 美人鱼6只装 | I30: 600 | J30: 0 | K30: 6 | L30: =I30/K30 -> 100 | M30: 45663 | N30: 45659 | P30: PASS | Q30: 1/6出 | R30: 11/26出 | U30: 12/19-UPC贴纸+进口商贴纸 | X30: 日期码格式：ZURU INC(BVI) 标准格式 日期：按实际生产日期 Tracking Code: Packaging Info: 9283：MA 3L EAN包装+UPC贴纸+MA 多语收藏指南+进口商贴纸+箱唛 Remark: 9283: Kitten:Bunny:Puppy:Cow:Elephant:Flamingo=1:1:1:1:1:1; 出货前要提供大货照片给客户确认后才能出货，请按期完货 | Y30: Zoe Luo | Z30: 5.905 | AA30: =Z30*I30 -> 3543 | AB30: 88921-1.7 | AC30: 9283-S001-1 | AD30: 已入 | AJ30: =I30 -> 600 | AN30: =I30 -> 600 | AU30: =I30 -> 600 | AW30: =I30 -> 600 | BF30: MA布标 | BH30: =I30/6 -> 100 | BI30: =I30/6 -> 100 | BJ30: =I30/6 -> 100 | BK30: =I30/6 -> 100 | BL30: =I30/6 -> 100 | BM30: =I30/6 -> 100 | BT30: =SUM(BH30:BS30) -> 600 | BU30: =I30-BT30 -> 0
A31: 45624 | B31: WABRO | C31: 阿根廷 | D31: 4500152720 | F31: 4500152720-160 | G31: 9283-S001 | H31: 美人鱼6只装 | I31: 900 | J31: 0 | K31: 6 | L31: =I31/K31 -> 150 | M31: 45663 | N31: 45659 | P31: PASS | Q31: 1/8出 | R31: 12/3收到 | U31: 12/6-进口商贴纸 | X31: 日期码格式：ZURU INC(BVI) 标准格式 日期：按实际生产日期 Packaging Info: 9283:MA 3L包装+进口商贴纸+箱唛 Remark: LR44 电池品牌为ONLY | Y31: Ava Liang | Z31: 5.905 | AA31: =Z31*I31 -> 5314.5 | AB31: 88958-1.9 | AC31: 9283-S001-1 | AD31: 已入 | AJ31: =I31 -> 900 | AN31: =I31 -> 900 | AU31: =I31 -> 900 | AW31: =I31 -> 900 | BF31: MA布标 | BH31: =I31/6 -> 150 | BI31: =I31/6 -> 150 | BJ31: =I31/6 -> 150 | BK31: =I31/6 -> 150 | BL31: =I31/6 -> 150 | BM31: =I31/6 -> 150 | BT31: =SUM(BH31:BS31) -> 900 | BU31: =I31-BT31 -> 0
A32: 45623 | B32: AMAZON.COM.DEDC,LLC | C32: 美国 | D32: 4500152379 | E32: 24XZNY6S | F32: 4500152379-340 | G32: 9283D-S002 | H32: 小狗（邮包盒） | I32: 36 | J32: 1 | K32: 4 | L32: =I32/K32 -> 9 | M32: 45664 | N32: 45660 | P32: PASS | Q32: 2/7出 | R32: 11/27收到 | U32: 无 | V32: 12/20-客供外箱贴纸 | W32: 9283D邮包盒图稿跟返单4500139401 | X32: 日期码格式： 标准格式 日期：按实际生产日期 Packaging Info: #9283: MA 1L入邮包盒，9283A邮包盒图稿跟翻单#4500135161，9283D邮包盒图稿跟返单4500139401。 Remark: 1. Amazon FOB订单，出口US。 2. 日期码使用ZURU标准版本。 3. 如果大货有要求入邮包盒，则对应的邮包盒上面要打上日期码。 4. 箱尺寸要求：外箱最长边不能超过25" （超过了，case pack只能为1），不符合要求的大货，一律不接受。 5. 外箱箱唛要求： ①外箱正面印ZURU Logo+SSCC Label（客供贴纸，由跟单订购)。关于 SSCC Label 请注意： SSCC Label 显示的是客人自己的item#。每一张SSCC label 都是唯一且有不同流水及条码的，没有损耗，绝对不可贴错 。如果贴错或损坏任何一张，都会导致全 部都错，千万要注意！ SSCC Label 必须贴在外箱正面的正中间位置（贴一面即可），并且贴纸离外箱边距必须至少3cm(可以覆盖Logo<(>&<)>箱唛)，否则会影响到客户那边仓库的扫描识 别。 ②外箱侧面印item#（订单上显示的SKU#)+carton size(以工厂实际尺寸为准,单位: inch) +MADE IN CHINA,日期使用ZURU 标准版本。 6. 装柜要求：按照客户PO# 装柜/箱号顺序装柜，跟单会提前给到装柜计划。 在大货生产/仓库存放时，请留意该装柜要求，以便装柜时不混乱（避免装错/装漏/找不到货号等）。 | Y32: Kelly Shen | Z32: 6.1693 | AA32: =Z32*I32 -> 222.0948 | AB32: 94201-2.10 | AC32: 9283D-S002 | AD32: 已入 | AG32: =I32 -> 36 | AN32: =I32 -> 36 | AR32: =I32 -> 36 | AW32: =I32 -> 36 | BF32: MA布标 | BJ32: =I32 -> 36 | BT32: =SUM(BH32:BS32) -> 36 | BU32: =I32-BT32 -> 0
A33: 45623 | B33: AMAZON.COM.DEDC,LLC | C33: 美国 | D33: 4500152379 | E33: 1776T8ZG | F33: 4500152379-350 | G33: 9283D-S002 | H33: 小狗（邮包盒） | I33: 116 | J33: 1 | K33: 4 | L33: =I33/K33 -> 29 | M33: 45664 | N33: 45660 | P33: PASS | Q33: 2/7出 | R33: 11/27收到 | U33: 无 | V33: 12/20-客供外箱贴纸 | W33: 9283D邮包盒图稿跟返单4500139401 | X33: 日期码格式： 标准格式 日期：按实际生产日期 Packaging Info: #9283: MA 1L入邮包盒，9283A邮包盒图稿跟翻单#4500135161，9283D邮包盒图稿跟返单4500139401。 Remark: 1. Amazon FOB订单，出口US。 2. 日期码使用ZURU标准版本。 3. 如果大货有要求入邮包盒，则对应的邮包盒上面要打上日期码。 4. 箱尺寸要求：外箱最长边不能超过25" （超过了，case pack只能为1），不符合要求的大货，一律不接受。 5. 外箱箱唛要求： ①外箱正面印ZURU Logo+SSCC Label（客供贴纸，由跟单订购)。关于 SSCC Label 请注意： SSCC Label 显示的是客人自己的item#。每一张SSCC label 都是唯一且有不同流水及条码的，没有损耗，绝对不可贴错 。如果贴错或损坏任何一张，都会导致全 部都错，千万要注意！ SSCC Label 必须贴在外箱正面的正中间位置（贴一面即可），并且贴纸离外箱边距必须至少3cm(可以覆盖Logo<(>&<)>箱唛)，否则会影响到客户那边仓库的扫描识 别。 ②外箱侧面印item#（订单上显示的SKU#)+carton size(以工厂实际尺寸为准,单位: inch) +MADE IN CHINA,日期使用ZURU 标准版本。 6. 装柜要求：按照客户PO# 装柜/箱号顺序装柜，跟单会提前给到装柜计划。 在大货生产/仓库存放时，请留意该装柜要求，以便装柜时不混乱（避免装错/装漏/找不到货号等）。 | Y33: Kelly Shen | Z33: 6.1693 | AA33: =Z33*I33 -> 715.6388 | AB33: 94201-2.10 | AC33: 9283D-S002 | AD33: 已入 | AG33: =I33 -> 116 | AN33: =I33 -> 116 | AR33: =I33 -> 116 | AW33: =I33 -> 116 | BF33: MA布标 | BJ33: =I33 -> 116 | BT33: =SUM(BH33:BS33) -> 116 | BU33: =I33-BT33 -> 0
A34: 45623 | B34: AMAZON.COM.DEDC,LLC | C34: 美国 | D34: 4500152657 | E34: 5JF5W6AV | F34: 4500152657-100 | G34: 9283D-S002 | H34: 小狗（邮包盒） | I34: 172 | J34: 1 | K34: 4 | L34: =I34/K34 -> 43 | M34: 45664 | N34: 45660 | P34: PASS | Q34: 1/14出 | R34: 11/27收到 | U34: 无 | V34: 12/20-客供外箱贴纸 | W34: 9283D邮包盒图稿跟返单4500139401 | X34: 日期码格式： 标准格式 日期：按实际生产日期 Packaging Info: #9283: MA 1L入邮包盒，9283A邮包盒图稿跟翻单#4500135161，9283D邮包盒图稿跟返单4500139401。 Remark: 1. Amazon FOB订单，出口US。 2. 日期码使用ZURU标准版本。 3. 如果大货有要求入邮包盒，则对应的邮包盒上面要打上日期码。 4. 箱尺寸要求：外箱最长边不能超过25" （超过了，case pack只能为1），不符合要求的大货，一律不接受。 5. 外箱箱唛要求： ①外箱正面印ZURU Logo+SSCC Label（客供贴纸，由跟单订购)。关于 SSCC Label 请注意： SSCC Label 显示的是客人自己的item#。每一张SSCC label 都是唯一且有不同流水及条码的，没有损耗，绝对不可贴错 。如果贴错或损坏任何一张，都会导致全 部都错，千万要注意！ SSCC Label 必须贴在外箱正面的正中间位置（贴一面即可），并且贴纸离外箱边距必须至少3cm(可以覆盖Logo<(>&<)>箱唛)，否则会影响到客户那边仓库的扫描识 别。 ②外箱侧面印item#（订单上显示的SKU#)+carton size(以工厂实际尺寸为准,单位: inch) +MADE IN CHINA,日期使用ZURU 标准版本。 6. 装柜要求：按照客户PO# 装柜/箱号顺序装柜，跟单会提前给到装柜计划。 在大货生产/仓库存放时，请留意该装柜要求，以便装柜时不混乱（避免装错/装漏/找不到货号等）。 | Y34: Kelly Shen | Z34: 6.1693 | AA34: =Z34*I34 -> 1061.1196 | AB34: 94001-1.13 | AC34: 9283D-S002 | AD34: 已入 | AG34: =I34 -> 172 | AN34: =I34 -> 172 | AR34: =I34 -> 172 | AW34: =I34 -> 172 | BF34: MA布标 | BJ34: =I34 -> 172 | BT34: =SUM(BH34:BS34) -> 172 | BU34: =I34-BT34 -> 0
A35: 45623 | B35: AMAZON.COM.DEDC,LLC | C35: 美国 | D35: 4500152472 | E35: 8M75H1DC | F35: 4500152472-50 | G35: 9283A-S002 | H35: 小猫（邮包盒） | I35: 548 | J35: 1 | K35: 4 | L35: =I35/K35 -> 137 | M35: 45666 | N35: 45663 | P35: PASS | Q35: 1/20出 | R35: 11/27收到 | U35: 无 | V35: 12/20-客供外箱贴纸 | W35: 9283A邮包盒图稿跟翻单#4500135161 | X35: 日期码格式：ZURU INC(BVI) 标准格式 日期：按实际生产日期 Packaging Info: #9283：MA 1L入邮包盒，9283A邮包盒图稿跟翻单#4500135161，9283D邮包盒图稿跟返单4500139401。 Remark: 1. Amazon FOB订单，出口US。 2. 日期码使用ZURU标准版本。 3. 如果大货有要求入邮包盒，则对应的邮包盒上面要打上日期码。 4. 箱尺寸要求：外箱最长边不能超过25"(超过了，case pack只能为1)，不符合要求的大货，一律不接受。 5. 外箱箱唛要求： ①外箱正面印ZURU Logo+SSCC Label(客供贴纸，由跟单订购)。关于 SSCC Label 请注意： SSCC Label显示的是客人自己的item#。每一张SSCC label都是唯一且有不同流水及条码的，没有损耗，绝对不可贴错。如果贴错或损坏任何一张，都会导致全部都 错，千万要注意！SSCC Label必须贴在外箱正面的正中间位置(贴一面即可)，并且贴纸离外箱边距必须至少3cm(可以覆盖Logo<(>&<)>箱唛)，否则会影响到客户那边 仓库的扫描识别。 ②外箱侧面印item#(订单上显示的SKU#)+carton size(以工厂实际尺寸为准，单位: inch)+MADE IN CHINA，日期使用ZURU 标准版本。 6. 装柜要求：按照客户PO#装柜/箱号顺序装柜，跟单会提前给到装柜计划。 在大货生产/仓库存放时，请留意该装柜要求，以便装柜时不混乱(避免装错/装漏/找不到货号等)。 | Y35: Kelly Shen | Z35: 6.1693 | AA35: =Z35*I35 -> 3380.7764 | AB35: 94109-1.18 | AC35: 9283A-S002 | AD35: 已入 | AG35: =I35 -> 548 | AN35: =I35 -> 548 | AR35: =I35 -> 548 | AW35: =I35 -> 548 | BF35: MA布标 | BH35: =I35 -> 548 | BT35: =SUM(BH35:BS35) -> 548 | BU35: =I35-BT35 -> 0
A36: 45618 | B36: CRG | C36: 哥斯达黎加 | D36: 4500152087 | E36: ZU01-25 | F36: 4500152087-70 | G36: 9283-S001 | H36: 美人鱼6只装 | I36: 504 | J36: 0 | K36: 6 | L36: =I36/K36 -> 84 | M36: 45660 | N36: 45656 | P36: PASS | Q36: 1/8出 | R36: 11/27收到 | U36: 进口商贴纸翻4500098650 | X36: 日期码格式：ZURU INC(BVI) 标准格式 日期：按实际生产日期 Packaging Info: 9283:MA 1L包装+进口商贴纸+箱唛，进口商贴纸翻单PO4500098650 Remark: | Y36: Ava Liang | Z36: 5.905 | AA36: =Z36*I36 -> 2976.12 | AB36: 88961-1.9 | AC36: 9283-S001 | AD36: 已入 | AG36: =I36 -> 504 | AN36: =I36 -> 504 | AR36: =I36 -> 504 | AW36: =I36 -> 504 | BF36: MA布标 | BH36: =I36/6 -> 84 | BI36: =I36/6 -> 84 | BJ36: =I36/6 -> 84 | BK36: =I36/6 -> 84 | BL36: =I36/6 -> 84 | BM36: =I36/6 -> 84 | BT36: =SUM(BH36:BS36) -> 504 | BU36: =I36-BT36 -> 0
A37: 45625 | B37: TJX UK | C37: 英国 | D37: 4500152937 | E37: TJX UK: PO#50343294 | F37: 4500152937-10 | G37: 9283-S001 | H37: 美人鱼6只装 | I37: 900 | J37: 0 | K37: 6 | L37: =I37/K37 -> 150 | M37: 45660 | N37: 45656 | P37: PASS | Q37: 1/9出 | R37: 12/5收到 | U37: 12/6-客供价格贴纸 | X37: 日期码格式：ZURU INC(BVI) 标准格式 日期：按实际生产日期 Tracking Code: Packaging Info: TJX UK: PO#50343294(9283) <(>&<)> PO#50343296(9258) <(>&<)> PO#50343296(9281) <(>&<)> PO#50343305(9298) <(>&<)> PO#50343349(7132) <(>&<)> PO#503 43349(92107) <(>&<)> PO#50343392(9279) <(>&<)> PO#50343399(9279) 1) 9283: MA 3L(9Lwarning) C版收缩膜+ 其他最新MA配套包装+1张客供价格贴纸 8) 最迟验货时间不得晚于1/4 Remark: 1. 出往UK的产品+包装务必打上UKCA logo ，否则客人会退货且当地会有罚款； 2. 订单必须经过ZURU QC验货并且通过后方可出货； 3. 订单每行对应客人不同的PO， 箱唛也有不同，做货的时候请分开堆放； 4. 订单每行对应客人不同的PO，即同款item的价格贴纸都不相同，请注意收到贴纸后不要弄混!（客人PO号请参考PO最后一栏remark）； 5. 价格贴纸位置为产品正面右上角，不能遮住产品信息，大货生产前，请把贴纸位置先发给跟单确认 6. 涉及到相关款式会有闪粉的或 者微塑料的，请统一默认出无闪粉或者不含微塑料 版本; 7. 外箱封箱必须是工字型封箱方式； | Y37: Zoe Chen | Z37: 5.905 | AA37: =Z37*I37 -> 5314.5 | AB37: 88953-1.9 | AC37: 9283-S001-1 | AD37: 已入 | AJ37: =I37 -> 900 | AN37: =I37 -> 900 | AU37: =I37 -> 900 | AW37: =I37 -> 900 | BF37: MA布标 | BH37: =I37/6 -> 150 | BI37: =I37/6 -> 150 | BJ37: =I37/6 -> 150 | BK37: =I37/6 -> 150 | BL37: =I37/6 -> 150 | BM37: =I37/6 -> 150 | BT37: =SUM(BH37:BS37) -> 900 | BU37: =I37-BT37 -> 0
A38: 45625 | B38: TJX UK c/o TJX Distribution Ltd & C | C38: 英国 | D38: 4500152906 | E38: TJX Europe(DE): PO#55343895 | F38: 4500152906-10 | G38: 9283-S001 | H38: 美人鱼6只装 | I38: 900 | J38: 0 | K38: 6 | L38: =I38/K38 -> 150 | M38: 45660 | N38: 45656 | P38: PASS | Q38: 1/10出 | R38: 12/5收到 | U38: 12/6-客供价格贴纸+含波兰警示语翻4500150830 | X38: 日期码格式：ZURU INC(BVI) 标准格式 日期：按实际生产日期 Packaging Info: TJX Europe(DE): PO#55343895(9283) <(>&<)> PO#55343898(9258) <(>&<)> PO#55343898(9281) <(>&<)> PO#55343901(9281) <(>&<)> PO#55343906(9298) <(>& <)> PO#55343909(9298) <(>&<)> PO#55343918(7132) <(>&<)> PO#55343920(7132) <(>&<)> PO#55343920(92107) <(>&<)> PO#55343844(9279) <(>&<)> PO#553438 77(9279) 1) 9283: MA 3L(9Lwarning) C版收缩膜+ 其他最新MA配套包装+1张客供价格贴纸+1张贴纸（含波兰警示语） 8) 最迟验货时间不得晚于1/4 Remark: 1. 出往UK的产品+包装务必打上UKCA logo ，否则客人会退货且当地会有罚款； 2.订单必须经过ZURU QC验货并且通过后方可出货； 3. 订单每行对应客人不同的PO， 箱唛也有不同，做货的时候请分开堆放； 4. 订单每行对应客人不同的PO，即同款item的价格贴纸都不相同，请注意收到贴纸后不要弄混!（客人PO号请参考PO最后一栏remark）； 5. 价格贴纸位置为产品正面右上角，不能遮住产品信息，大货生产前，请把贴纸位置先发给跟单确认 6. 涉及到相关款式会有闪粉的或者微塑料的，请统一默认出无闪粉或者不含微塑料版本; 7. 外箱封箱必须是工字型封箱方式； | Y38: Zoe Chen | Z38: 5.905 | AA38: =Z38*I38 -> 5314.5 | AB38: 88968-1.10 | AC38: 9283-S001-1 | AD38: 已入 | AJ38: =I38 -> 900 | AN38: =I38 -> 900 | AU38: =I38 -> 900 | AW38: =I38 -> 900 | BF38: MA布标 | BH38: =I38/6 -> 150 | BI38: =I38/6 -> 150 | BJ38: =I38/6 -> 150 | BK38: =I38/6 -> 150 | BL38: =I38/6 -> 150 | BM38: =I38/6 -> 150 | BT38: =SUM(BH38:BS38) -> 900 | BU38: =I38-BT38 -> 0
A39: 45623 | B39: HEB GROCERY COMPANY, LP | C39: 美国 | D39: 4500152429 | E39: PO#60X356210 | F39: 4500152429-20 | G39: 9283-S003 | H39: 美人鱼2只装(无闪粉） | I39: 1344 | J39: 0 | K39: 2 | L39: =I39/K39 -> 672 | M39: 45665 | N39: 45661 | O39: 1/9第三方 | P39: PASS | Q39: 1/19出 | R39: 11/27收到 | U39: 无 | X39: 日期码格式：ZURU INC(BVI) 标准格式 日期：按实际生产日期 Packaging Info: 1. ZURU MA UPC版本，出口美国. Remark: 2. 日期跟踪码：ZURU标准格式日期码，产品包装及产品本身都必须有ZURU标准格式日期码，并且确保两者格式和时间保持一致(请自行调整具体年月日生产期，但不能为周末）。 针对你们目前没办法保持日期码一致的做法是： * 大货：可以按照实际生产的日期码打，毛绒布标和蛋壳上的日期码格式和时间这次特例可以不保持一致出货；但到时需手动贴一套公仔的布标贴纸，使布标跟蛋壳 日期码格式和时间一样，拍照给我们发给实验室review 日期码，让实验室知道订单大货出的日期码格式和时间是跟抽板指定款的保持一样。 * 指定款抽板：需手动贴布标贴纸，保证布标跟蛋壳上的日期码格式和时间都一样，且这个时间要跟大货的时间一样。 3. 大货样 #9283签样同旧单4500105770, 但如订单最终出货有物料变更，须提前告知跟单决定是否重新寄签样。 4. 验货+ 抽板 （同一天进行） 预约1月9日第三方（利丰）到工厂做100%大货现场验货和抽板，验货需打印EPM出来跟客户回签样板供第三方验货参考。 PS:EPM是跟单提供。 抽板： 因#9283的ZURU测试报告上被客户指定实验室发现产品和产品包装上的日期码不一致，所以这款寄样给实验室的是按照 利丰验货员现场针对指定款随机抽板6PCS（须带包装）;其他利丰验货员现场针对指定款随机抽板6PCS。 工厂需把抽板寄到以下MTS 地址做测试，测试通过后才能出货；如产品有油漆的工厂需额外准备5G/色的油漆涂在同材质胶件上(面积类似A4纸大小)一并寄出； 实验室收件地址： 东莞现代产品整理服务有限公司（MTS） 广东省东莞市寮步镇新旧围村良平路76号 收件人：Cherry Wang （汪单） Tel: +86 769- 8112 0818 ext.893 抽板有随样文件TRF（跟单提供），工厂在寄样时打印出来放纸箱内随样寄走。 5. 出货配比：ZURU 标版配比 6. ZURU QA 验货时需拍齐每款角色的产品和产品包装上的日期码照片（供实验室review） | Y39: Elsa Zheng | Z39: 5.8775 | AA39: =Z39*I39 -> 7899.36 | AB39: 94212-2.11 | AC39: 9283-S003 | AD39: 已入 | AG39: =I39 -> 1344 | AN39: =I39 -> 1344 | AR39: =I39 -> 1344 | AW39: =I39 -> 1344 | BF39: MA布标 | BH39: =I39/6 -> 224 | BI39: =I39/6 -> 224 | BJ39: =I39/6 -> 224 | BK39: =I39/6 -> 224 | BL39: =I39/6 -> 224 | BM39: =I39/6 -> 224 | BT39: =SUM(BH39:BS39) -> 1344 | BU39: =I39-BT39 -> 0
A40: 45625 | B40: TIENDAS CHEDRAUI, S.A. DE C.V. | C40: 墨西哥 | D40: 4500153048 | F40: 4500153048-30 | G40: 9283-S001 | H40: 美人鱼6只装 | I40: 906 | J40: 0 | K40: 6 | L40: =I40/K40 -> 151 | M40: 45667 | N40: 45663 | P40: PASS | Q40: 1/15出 | R40: 12/13收到 | U40: 12/12-UPC条码贴纸+进口商贴纸 | X40: 日期码格式：ZURU INC(BVI) 标准格式 日期：按实际生产日期 Packaging Info: 2. 9283: MA 3L EAN包装+MA 5L收藏指南+MA 3L try me sticker+进口商贴纸(已包含UPC条码）+箱唛 Remark: 3. 9283：Kitten:Bunny:Puppy:Cow:Elephant:Flamingo=1:1:1:1:1:1; | Y40: Ever Li | Z40: 5.7196 | AA40: =Z40*I40 -> 5181.9576 | AB40: 94048-1.15 | AC40: 9283-S001-1 | AD40: 已入 | AJ40: =I40 -> 906 | AN40: =I40 -> 906 | AU40: =I40 -> 906 | AW40: =I40 -> 906 | BF40: MA布标 | BH40: =I40/6 -> 151 | BI40: =I40/6 -> 151 | BJ40: =I40/6 -> 151 | BK40: =I40/6 -> 151 | BL40: =I40/6 -> 151 | BM40: =I40/6 -> 151 | BT40: =SUM(BH40:BS40) -> 906 | BU40: =I40-BT40 -> 0
...

Sheet MA包裝
A1: #9283美人鱼系列MA 包装扣数表
A2: 日期 | B2: MA PO | C2: 負責 | D2: MA收缩膜
D3: MA 1语收缩膜 | E3: MA 1语收缩膜 | F3: MA 1语收缩膜 | G3: MA 3语收缩膜 | H3: MA 3语收缩膜 | I3: MA 3语收缩膜 | J3: 5语收藏指南 | K3: 5语收藏指南 | L3: 5语收藏指南 | M3: 客版收缩膜 | N3: 客版收藏指南 | O3: 藏宝图 | P3: 藏宝图 | Q3: 领养卡 | R3: MEC展示架-1L | S3: EC展示架-1L | T3: 9283SLT-托盘
D4: A版本 | E4: B版本 | F4: C版本-无闪粉 | G4: A版本 | H4: B版本 | I4: C版本-无闪粉 | J4: A版本 | K4: B版本 | L4: C版本-无闪粉 | O4: B版本 | P4: C版本-无闪粉
A5: 44931 | B5: 1000012986 | C5: Amy | D5: 150000
A6: 44931 | B6: 1000012987 | C6: Amy | G6: 30000
A7: 44931 | B7: 1000012988 | C7: Amy | J7: 150000 | O7: 50000 | Q7: 50000
A8: 45001 | B8: 1000013497 | C8: Mona | M8: 30000 | U8: @Emma Chen 4500092956-9804pcs 4500116561-2100pcs 4500122428-3000pcs 4500123591-3600pcs 4500128665-3000PCS 4500129356-1002pcs 4500136786-2100pcs | V8: =M8-9804-2100-3000-3600-3000-1002-2100 -> 5394
A9: 45020 | B9: 1000013757 | C9: Mona | M9: 30000 | U9: 4500097084-15000pcs 4500101379-10002pcs 4500137318-2580pcs | V9: =M9-15000-10002-2580 -> 2418
A10: 2023/4/11 | B10: 1000013809 | C10: Charine Chen | M10: 39984 | U10: Smyths客使用 Linda 4500094401 | V10: 翻单 4500094401扣数
A11: 45037 | B11: 1000014019 | R11: 4000 | U11: Effy用于4500100631 4500100632 4500100633 4500100635（543座 剩3457座）1L
A12: 45039 | B12: 1000014039 | C12: Amy | D12: 100000
A13: 45039 | B13: 1000014040 | C13: Amy | G13: 30000
A14: 45039 | B14: 1000014041 | C14: Amy | J14: 150000
A15: 45043 | B15: 1000014119 | C15: Amy | O15: 250000
A16: 45043 | B16: 1000014120 | C16: Amy | Q16: 250000
A17: 45043 | B17: 1000014121 | C17: Amy | S17: 300
A18: 45056 | B18: 1000014350 | C18: Amy | D18: 100000
A19: 45056 | B19: 1000014351 | C19: Amy | J19: 150000
A20: 45056 | B20: 1000014352 | C20: Amy | O20: 150000
A21: 45056 | B21: 1000014353 | C21: Amy | Q21: 150000
A22: 45068 | B22: 1000014511 | C22: Daisy.Li | T22: =197 -> 197 | U22: Willow用于订单 4500104331
A23: 45090 | B23: 1000014795 | C23: Charine Chen | M23: 20000 | U23: 4500105312 4500100289 4500100344 | V23: 翻单 4500094401扣数
A24: 45091 | B24: 1000014896 | C24: Amy | D24: 70000
A25: 45091 | B25: 1000014897 | C25: Amy | G25: 60000
A26: 45091 | B26: 1000014898 | C26: Amy | J26: 140000
A27: 45091 | B27: 1000014899 | C27: Amy | O27: 140000
A28: 45091 | B28: 100014900 | C28: Amy | Q28: 140000
A29: 45107 | B29: 1000015170 | C29: Amy | D29: 120000
A30: 45107 | B30: 1000015171 | C30: Amy | J30: 130000
A31: 45107 | B31: 1000015174 | C31: Amy | O31: 140000
A32: 45107 | B32: 1000015176 | C32: Amy | Q32: 140000
A33: 45125 | B33: 1000015477 | C33: Daisy.Li | M33: 30000 | U33: Linda Smyths EU:4500108836 334PCS Sherry Smyths 4500108866 2406pcs | V33: 翻单 4500094401扣数
A34: 45127 | B34: 1000015544 | C34: Amy | D34: 100000
A35: 45127 | B35: 1000015545 | C35: Amy | K35: 100000
A36: 45127 | B36: 1000015546 | C36: Amy | O36: 100000
A37: 45127 | B37: 1000015547 | C37: Amy | Q37: 100000
A38: 45166 | B38: 1000016178 | C38: Amy | E38: 150000
A39: 45166 | B39: 1000016179 | C39: Amy | G39: 30000
A40: 45166 | B40: 1000016180 | C40: Amy | K40: 200000
...

Sheet 布料MA
A1: Item | B1: Character | C1: Ratio | D1: Materials Description | F1: MOQ | G1: 产品用量 | H1: MOQ生产数量 | I1: MA-RR-747 | J1: MA-RR-783 | K1: MA-RR-804 | L1: MA-RR-849 | M1: MA-RR-880 | N1: MA-RR-930 | O1: MA-RR-947 | P1: MA-RR-968 （共用布料挪给无闪粉用） | Q1: MA-RR-986 (无闪粉) | R1: MA-RR-1044 (补放有闪粉的共用布料) | S1: MA-RR-1067 (无闪粉) | T1: MA-RR-1162 (无闪粉) | U1: MA-RR-1206 (无闪粉) | V1: MA-RR-1292 (无闪粉) | W1: MA-RR-1389 (无闪粉) | X1: MA-RR-1472 (无闪粉) | Y1: MA-RR-1873 (无闪粉) | Z1: MA-RR-1996 (无闪粉) | AA1: MA-RR-2103 (无闪粉) | AB1: Grand Total | AC1: MA可生产数量
A2: Order Date | I2: 44825 | J2: 44897 | K2: 44966 | L2: 45029 | M2: 45056 | N2: 45128 | O2: 45149 | P2: 45190 | Q2: 45217 | R2: 45217 | S2: 45310 | T2: 45392 | U2: 45422 | V2: 45468 | W2: 45558 | X2: 45629 | Y2: 45902 | Z2: 46000 | AA2: 46055
A3: Delivery Date | I3: =I2+35 -> 44860 | J3: =J2+35 -> 44932 | K3: 45001 | L3: =L2+35 -> 45064 | M3: =M2+35 -> 45091 | N3: =N2+35 -> 45163 | O3: =O2+35 -> 45184 | P3: =P2+35 -> 45225 | Q3: =Q2+35 -> 45252 | R3: =R2+35 -> 45252 | S3: 45388 | T3: =T2+35 -> 45427 | U3: 45457 | V3: 45503 | W3: 45593 | X3: 45664 | Y3: 45942 | Z3: =Z2+35+5 -> 46040 | AA3: =AA2+35+30 -> 46120
A4: Rainbocorn Mermaidcorn Surprise 9283# | B4: 小猫/Kitten | C4: 1 | D4: 10mm白色兔毛 | E4: 共用物料1 | F4: 0 | G4: 0.106605 | H4: =F4/G4 -> 0 | I4: 3198.15 | J4: 3199 | K4: 3198 | L4: 4264 | M4: 3198 | N4: 3198 | O4: 3198 | P4: 4265 | R4: 4264 | S4: 3198 | T4: 3198 | U4: 3198 | V4: 3198 | W4: 4478 | X4: 4264 | Y4: 2132 | Z4: 2132 | AA4: 2132 | AB4: =SUM(I4:AA4) -> 59912.15 | AC4: =ROUND(AB4/G4,-1) -> 562000
D5: 10mm粉色小兔毛/烫银色镭射鱼尾纹 | F5: 800 | G5: 0.087653 | H5: =F5/G5 -> 9126.8981 | I5: 2629.59 | J5: 2630 | K5: 2630 | L5: 3506 | M5: 2629 | N5: 2630 | O5: 2630 | P5: 3506 | R5: 3506 | S5: 2629 | T5: 2630 | U5: 2630 | V5: 2629 | W5: 3682 | X5: 3506 | Y5: 1753 | Z5: 1753 | AA5: 1753 | AB5: =SUM(I5:AA5) -> 49261.59 | AC5: =ROUND(AB5/G5,-1) -> 562010
D6: 紫色闪粉边伦布 | F6: 500 | G6: 0.074675 | H6: =F6/G6 -> 6695.6813 | I6: 2240.25 | J6: 2241 | K6: 2240 | L6: 2987 | M6: 2240 | N6: 2240 | O6: 2241 | P6: 2987 | AB6: =SUM(I6:AA6) -> 19416.25 | AC6: =ROUND(AB6/G6,-1) -> 260010
D7: 粉紫色幻彩PU | F7: 500 | G7: 0.0665 | H7: 7518.797 | Q7: 2660 | R7: 0 | S7: 1995 | T7: 1995 | U7: 1995 | V7: 1995 | W7: 2793 | X7: 2660 | Y7: 1330 | Z7: 1330 | AA7: 1330 | AB7: =SUM(I7:AA7) -> 20083 | AC7: =ROUND(AB7/G7,-1) -> 302000
D8: 1MM紫色戟绒 | F8: 0 | G8: 0.015141 | H8: =F8/G8 -> 0 | I8: 454.23 | J8: 455 | K8: 455 | L8: 605 | M8: 454 | N8: 454 | O8: 454 | P8: 606 | R8: 606 | S8: 454 | T8: 454 | U8: 454 | V8: 454 | W8: 636 | X8: 606 | Y8: 303 | Z8: 303 | AA8: 303 | AB8: =SUM(I8:AA8) -> 8510.23 | AC8: =ROUND(AB8/G8,-1) -> 562070
D9: 110mm粉色长毛绒 | F9: 300 | G9: 0.006489 | H9: =F9/G9 -> 46232.085 | I9: 300 | J9: 300 | L9: 300 | M9: 300 | N9: 300 | P9: 300 | R9: 147 | S9: 195 | T9: 195 | U9: 194 | V9: 195 | W9: 272 | X9: 260 | Y9: 130 | Z9: 130 | AA9: 129 | AB9: =SUM(I9:AA9) -> 3647 | AC9: =ROUND(AB9/G9,-1) -> 562030
D10: 1.5MM漂白水晶超柔 | E10: 共用物料3 | F10: 0 | G10: 0.005253 | H10: =F10/G10 -> 0 | I10: 157.59 | J10: 158 | K10: 158 | L10: 210 | M10: 157 | N10: 158 | O10: 158 | P10: 210 | R10: 210 | S10: 157 | T10: 158 | U10: 158 | V10: 157 | W10: 221 | X10: 210 | Y10: 105 | Z10: 105 | AA10: 105 | AB10: =SUM(I10:AA10) -> 2952.59 | AC10: =ROUND(AB10/G10,-1) -> 562080
D11: 白色边伦布 | E11: 共用物料4 | F11: 0 | G11: 0.004429 | H11: =F11/G11 -> 0 | I11: 132.87 | J11: 133 | K11: 133 | L11: 178 | M11: 132 | N11: 133 | O11: 133 | P11: 177 | R11: 177 | S11: 133 | T11: 133 | U11: 133 | V11: 133 | W11: 186 | X11: 177 | Y11: 89 | Z11: 88 | AA11: 89 | AB11: =SUM(I11:AA11) -> 2489.87 | AC11: =ROUND(AB11/G11,-1) -> 562170
D12: 紫色巴黎之星 | F12: 500 | G12: 0.061079 | H12: =F12/G12 -> 8186.1196 | I12: 1832.37 | J12: 1833 | K12: 1832 | L12: 2443 | M12: 1833 | N12: 1832 | O12: 1833 | P12: 2443 | R12: 2443 | S12: 1832 | T12: 1833 | U12: 1832 | V12: 1832 | W12: 2566 | X12: 2443 | Y12: 1221 | Z12: 1222 | AA12: 1222 | AB12: =SUM(I12:AA12) -> 34327.37 | AC12: =ROUND(AB12/G12,-1) -> 562020
D13: 白色喷棉 | E13: 共用物料5 | F13: 0 | G13: 0.023896 | H13: =F13/G13 -> 0 | I13: 716.88 | J13: 717 | K13: 717 | L13: 956 | M13: 717 | N13: 717 | O13: 717 | P13: 956 | R13: 955 | S13: 717 | T13: 717 | U13: 717 | V13: 717 | W13: 1004 | X13: 955 | Y13: 478 | Z13: 478 | AA13: 478 | AB13: =SUM(I13:AA13) -> 13429.88 | AC13: =ROUND(AB13/G13,-1) -> 562010
D14: 紫色闪粉PU | F14: 300 | G14: 0.001957 | H14: =F14/G14 -> 153295.86 | I14: 300 | M14: 300 | S14: 46 | T14: 59 | U14: 59 | V14: 58 | W14: 83 | X14: 78 | Y14: 39 | Z14: 39 | AA14: 39 | AB14: =SUM(I14:AA14) -> 1100 | AC14: =ROUND(AB14/G14,-1) -> 562080
D15: 6mm宽棉带 | E15: 共用物料6 | F15: 0 | G15: 4.635 | H15: =F15/G15 -> 0 | I15: 139050 | J15: 139050 | K15: 139050 | L15: 185400 | M15: 139050 | N15: 139050 | O15: 139050 | P15: 185400 | R15: 185400 | S15: 139050 | T15: 139050 | U15: 139050 | V15: 139050 | W15: 194670 | X15: 185400 | Y15: 92700 | Z15: 92700 | AA15: 92700 | AB15: =SUM(I15:AA15) -> 2604870 | AC15: =ROUND(AB15/G15,-1) -> 562000
D16: 车缝线 | E16: 共用物料7 | F16: 0 | G16: 28.634 | H16: =F16/G16 -> 0 | I16: 859020 | J16: 859020 | K16: 859020 | L16: 1145360 | M16: 859020 | N16: 859020 | O16: 859020 | P16: 1145360 | R16: 1145360 | S16: 859020 | T16: 859020 | U16: 859020 | V16: 859020 | W16: 1202628 | X16: 1145360 | Y16: 572680 | Z16: 572680 | AA16: 572680 | AB16: =SUM(I16:AA16) -> 16092308 | AC16: =ROUND(AB16/G16,-1) -> 562000
D17: 32MM直径全包扣水晶眼/介子 | E17: 共用物料8 | F17: 0 | G17: 2 | H17: =F17/G17 -> 0 | I17: 60000 | J17: 60000 | K17: 60000 | L17: 80000 | M17: 60000 | N17: 60000 | O17: 60000 | P17: 80000 | R17: 80000 | S17: 60000 | T17: 60000 | U17: 60000 | V17: 60000 | W17: 84000 | X17: 80000 | Y17: 40000 | Z17: 40000 | AA17: 40000 | AB17: =SUM(I17:AA17) -> 1124000 | AC17: =ROUND(AB17/G17,-1) -> 562000
D18: 棉花 | E18: 共用物料9 | F18: 0 | G18: 120 | H18: =F18/G18 -> 0 | I18: 3600000 | J18: 3600000 | K18: 3600000 | L18: 4800000 | M18: 3600000 | N18: 3600000 | O18: 3600000 | P18: 4800000 | R18: 4800000 | S18: 3600000 | T18: 3600000 | U18: 3600000 | V18: 3600000 | W18: 5040000 | X18: 4800000 | Y18: 2400000 | Z18: 2400000 | AA18: 2400000 | AB18: =SUM(I18:AA18) -> 67440000 | AC18: =ROUND(AB18/G18,-1) -> 562000
D19: 布标 | E19: 共用物料10 | F19: 0 | G19: 1 | H19: =F19/G19 -> 0 | I19: 30000 | J19: 30000 | K19: 30000 | L19: 40000 | M19: 30000 | N19: 30000 | O19: 30000 | P19: 40000 | R19: 40000 | S19: 30000 | T19: 30000 | U19: 30000 | V19: 30000 | W19: 42000 | X19: 40000 | Y19: 20000 | Z19: 20000 | AA19: 20000 | AB19: =SUM(I19:AA19) -> 562000 | AC19: =ROUND(AB19/G19,-1) -> 562000
D20: 丝印/电绣 | F20: 0 | G20: 1 | H20: =F20/G20 -> 0 | I20: 30000 | J20: 30000 | K20: 30000 | L20: 40000 | M20: 30000 | N20: 30000 | O20: 30000 | P20: 40000 | R20: 40000 | S20: 30000 | T20: 30000 | U20: 30000 | V20: 30000 | W20: 42000 | X20: 40000 | Y20: 20000 | Z20: 20000 | AA20: 20000 | AB20: =SUM(I20:AA20) -> 562000 | AC20: =ROUND(AB20/G20,-1) -> 562000
B21: 兔子/Bunny | C21: 1 | D21: 10mm粉色兔毛 | F21: 800 | G21: 0.139668 | H21: =F21/G21 -> 5727.8689 | I21: 4190.04 | J21: 4191 | K21: 4190 | L21: 4190 | M21: 5586 | N21: 4190 | O21: 4190 | P21: 4470 | R21: 4469 | S21: 4889 | T21: 5586 | U21: 4889 | V21: 4190 | W21: 5307 | X21: 4190 | Y21: 2793 | Z21: 2794 | AA21: 2793 | AB21: =SUM(I21:AA21) -> 77097.04 | AC21: =ROUND(AB21/G21,-1) -> 552000
D22: 10mm紫色小兔毛/烫银色镭射鱼尾纹 | F22: 800 | G22: 0.087653 | H22: =F22/G22 -> 9126.8981 | I22: 2629.59 | J22: 2630 | K22: 2630 | L22: 2630 | M22: 3505 | N22: 2630 | O22: 2630 | P22: 2804 | R22: 2805 | S22: 3068 | T22: 3506 | U22: 3068 | V22: 2630 | W22: 3331 | X22: 2629 | Y22: 1753 | Z22: 1753 | AA22: 1753 | AB22: =SUM(I22:AA22) -> 48384.59 | AC22: =ROUND(AB22/G22,-1) -> 552000
D23: 蓝色闪粉边伦布 | F23: 500 | G23: 0.069216 | H23: =F23/G23 -> 7223.7633 | I23: 2076.48 | J23: 2077 | K23: 2076 | L23: 2076 | M23: 2770 | N23: 2076 | O23: 2077 | P23: 2214 | W23: -1 | AB23: =SUM(I23:AA23) -> 17441.48 | AC23: =ROUND(AB23/G23,-1) -> 251990
D24: 蓝色幻彩PU | F24: 500 | G24: 0.0603 | H24: 8291.874 | Q24: 1930 | S24: 2111 | T24: 2412 | U24: 2110 | V24: 1809 | W24: 2291 | X24: 1809 | Y24: 1206 | Z24: 1206 | AA24: 1206 | AB24: =SUM(I24:AA24) -> 18090 | AC24: =ROUND(AB24/G24,-1) -> 300000
D25: 1MM蓝色戟绒 | F25: 0 | G25: 0.015141 | H25: =F25/G25 -> 0 | I25: 454.23 | J25: 455 | K25: 455 | L25: 454 | M25: 605 | N25: 454 | O25: 454 | P25: 485 | R25: 484 | S25: 530 | T25: 606 | U25: 530 | V25: 454 | W25: 575 | X25: 455 | Y25: 302 | Z25: 303 | AA25: 303 | AB25: =SUM(I25:AA25) -> 8358.23 | AC25: =ROUND(AB25/G25,-1) -> 552030
D26: 110mm紫色长毛绒 | F26: 300 | G26: 0.006489 | H26: =F26/G26 -> 46232.085 | I26: 300 | J26: 300 | L26: 300 | M26: 300 | N26: 300 | P26: 300 | R26: 43 | S26: 227 | T26: 300 | U26: 187 | V26: 195 | W26: 246 | X26: 195 | Y26: 130 | Z26: 130 | AA26: 129 | AB26: =SUM(I26:AA26) -> 3582 | AC26: =ROUND(AB26/G26,-1) -> 552010
D27: 1.5MM漂白水晶超柔 | E27: 共用物料3 | F27: 0 | G27: 0.004223 | H27: =F27/G27 -> 0 | I27: 126.69 | J27: 127 | K27: 127 | L27: 127 | M27: 168 | N27: 127 | O27: 127 | P27: 135 | R27: 135 | S27: 148 | T27: 169 | U27: 148 | V27: 126 | W27: 161 | X27: 127 | Y27: 84 | Z27: 84 | AA27: 85 | AB27: =SUM(I27:AA27) -> 2331.69 | AC27: =ROUND(AB27/G27,-1) -> 552140
D28: 白色边伦布 | E28: 共用物料4 | F28: 0 | G28: 0.004429 | H28: =F28/G28 -> 0 | I28: 132.87 | J28: 133 | K28: 133 | L28: 133 | M28: 177 | N28: 133 | O28: 133 | P28: 142 | R28: 141 | S28: 155 | T28: 178 | U28: 155 | V28: 133 | W28: 168 | X28: 133 | Y28: 88 | Z28: 89 | AA28: 88 | AB28: =SUM(I28:AA28) -> 2444.87 | AC28: =ROUND(AB28/G28,-1) -> 552010
D29: 蓝色巴黎之星 | F29: 500 | G29: 0.061079 | H29: =F29/G29 -> 8186.1196 | I29: 1832.37 | J29: 1833 | K29: 1832 | L29: 1832 | M29: 2444 | N29: 1832 | O29: 1833 | P29: 1954 | R29: 1955 | S29: 2137 | T29: 2443 | U29: 2138 | V29: 1833 | W29: 2321 | X29: 1832 | Y29: 1222 | Z29: 1221 | AA29: 1222 | AB29: =SUM(I29:AA29) -> 33716.37 | AC29: =ROUND(AB29/G29,-1) -> 552010
D30: 白色喷棉 | E30: 共用物料5 | F30: 0 | G30: 0.023896 | H30: =F30/G30 -> 0 | I30: 716.88 | J30: 717 | K30: 717 | L30: 717 | M30: 956 | N30: 717 | O30: 717 | P30: 764 | R30: 765 | S30: 836 | T30: 956 | U30: 837 | V30: 717 | W30: 908 | X30: 716 | Y30: 478 | Z30: 478 | AA30: 478 | AB30: =SUM(I30:AA30) -> 13190.88 | AC30: =ROUND(AB30/G30,-1) -> 552010
D31: 3MM白色戟绒 | F31: 0 | G31: 0.01957 | H31: =F31/G31 -> 0 | I31: 587.1 | J31: 588 | K31: 587 | L31: 587 | M31: 783 | N31: 587 | O31: 587 | P31: 626 | R31: 626 | S31: 685 | T31: 783 | U31: 685 | V31: 587 | W31: 744 | X31: 587 | Y31: 391 | Z31: 392 | AA31: 391 | AB31: =SUM(I31:AA31) -> 10803.1 | AC31: =ROUND(AB31/G31,-1) -> 552020
D32: 蓝色闪粉PU | F32: 300 | G32: 0.001957 | H32: =F32/G32 -> 153295.86 | I32: 300 | M32: 300 | S32: 25 | T32: 78 | U32: 69 | V32: 58 | W32: 75 | X32: 58 | Y32: 39 | Z32: 40 | AA32: 39 | AB32: =SUM(I32:AA32) -> 1081 | AC32: =ROUND(AB32/G32,-1) -> 552380
D33: 6mm宽棉带 | E33: 共用物料6 | F33: 0 | G33: 4.635 | H33: =F33/G33 -> 0 | I33: 139050 | J33: 139050 | K33: 139050 | L33: 139050 | M33: 185400 | N33: 139050 | O33: 139050 | P33: 148320 | R33: 148320 | S33: 162225 | T33: 185400 | U33: 162225 | V33: 139050 | W33: 176130 | X33: 139050 | Y33: 92700 | Z33: 92700 | AA33: 92700 | AB33: =SUM(I33:AA33) -> 2558520 | AC33: =ROUND(AB33/G33,-1) -> 552000
D34: 车缝线 | E34: 共用物料7 | F34: 0 | G34: 28.634 | H34: =F34/G34 -> 0 | I34: 859020 | J34: 859020 | K34: 859020 | L34: 859020 | M34: 1145360 | N34: 859020 | O34: 859020 | P34: 916288 | R34: 916288 | S34: 1002190 | T34: 1145360 | U34: 1002190 | V34: 859020 | W34: 1088092 | X34: 859020 | Y34: 572680 | Z34: 572680 | AA34: 572680 | AB34: =SUM(I34:AA34) -> 15805968 | AC34: =ROUND(AB34/G34,-1) -> 552000
D35: 32MM直径全包扣水晶眼/介子 | E35: 共用物料8 | F35: 0 | G35: 2 | H35: =F35/G35 -> 0 | I35: 60000 | J35: 60000 | K35: 60000 | L35: 60000 | M35: 80000 | N35: 60000 | O35: 60000 | P35: 64000 | R35: 64000 | S35: 70000 | T35: 80000 | U35: 70000 | V35: 60000 | W35: 76000 | X35: 60000 | Y35: 40000 | Z35: 40000 | AA35: 40000 | AB35: =SUM(I35:AA35) -> 1104000 | AC35: =ROUND(AB35/G35,-1) -> 552000
D36: 棉花 | E36: 共用物料9 | F36: 0 | G36: 120 | H36: =F36/G36 -> 0 | I36: 3600000 | J36: 3600000 | K36: 3600000 | L36: 3600000 | M36: 4800000 | N36: 3600000 | O36: 3600000 | P36: 3840000 | R36: 3840000 | S36: 4200000 | T36: 4800000 | U36: 4200000 | V36: 3600000 | W36: 4560000 | X36: 3600000 | Y36: 2400000 | Z36: 2400000 | AA36: 2400000 | AB36: =SUM(I36:AA36) -> 66240000 | AC36: =ROUND(AB36/G36,-1) -> 552000
D37: 布标 | E37: 共用物料10 | F37: 0 | G37: 1 | H37: =F37/G37 -> 0 | I37: 30000 | J37: 30000 | K37: 30000 | L37: 30000 | M37: 40000 | N37: 30000 | O37: 30000 | P37: 32000 | R37: 32000 | S37: 35000 | T37: 40000 | U37: 35000 | V37: 30000 | W37: 38000 | X37: 30000 | Y37: 20000 | Z37: 20000 | AA37: 20000 | AB37: =SUM(I37:AA37) -> 552000 | AC37: =ROUND(AB37/G37,-1) -> 552000
D38: 丝印/电绣 | F38: 0 | G38: 1 | H38: =F38/G38 -> 0 | I38: 30000 | J38: 30000 | K38: 30000 | L38: 30000 | M38: 40000 | N38: 30000 | O38: 30000 | P38: 32000 | R38: 32000 | S38: 35000 | T38: 40000 | U38: 35000 | V38: 30000 | W38: 38000 | X38: 30000 | Y38: 20000 | Z38: 20000 | AA38: 20000 | AB38: =SUM(I38:AA38) -> 552000 | AC38: =ROUND(AB38/G38,-1) -> 552000
B39: 小狗/Puppy | C39: 1 | D39: 10mm深蓝色兔毛 | F39: 800 | G39: 0.095172 | H39: =F39/G39 -> 8405.8336 | I39: 2855.16 | J39: 2856 | K39: 2855 | L39: 4758 | M39: 2856 | N39: 2855 | O39: 2855 | P39: 2855 | R39: 2855 | S39: 2855 | T39: 2856 | U39: 2855 | V39: 2855 | W39: 3045 | X39: 2856 | Y39: 1903 | Z39: 1903 | AA39: 1904 | AB39: =SUM(I39:AA39) -> 50632.16 | AC39: =ROUND(AB39/G39,-1) -> 532010
