Workbook
Name bos: #REF!
Name Code: '[1]CQS Code(rev 38)'!$B$7:$E$1000
Name bos: #REF!
Name bos: #REF!

Sheet 9259
AZ1: 1-2前入单配比： | BC1: 8 | BD1: 1 | BE1: 3 | BF1: 19 | BG1: 8 | BH1: 18 | BI1: 3 | BJ1: =SUBTOTAL(9,BC1:BI1) -> 60
A2: ZURU Rainbocorn 猫蛋毛絨公仔生产排期表 #9259 | AZ2: 1-2后入单新配比： | BC2: 20 | BD2: 12 | BE2: 1 | BF2: 25 | BG2: 20 | BH2: 25 | BI2: 17 | BJ2: =SUBTOTAL(9,BC2:BI2) -> 120
A3: =#REF! -> #REF! | I3: （黃色表示更改或增加） | L3: （蓝色表示已完货） | P3: （綠色表示調整貨期） | AG3: 收縮膜 | AK3: 說明書 | BC3: A | BD3: E | BE3: B | BF3: D | BG3: G | BI3: H
A4: 接单期 | B4: 第三方客户名称 | C4: 国家 | D4: PO号 | E4: 客户PO号 | F4: SKU号 | G4: 系统货号 | H4: 货号 | I4: 名称 | J4: 数量 | K4: 内箱装箱数量(pcs) | L4: 装箱数（PCS） | M4: 总箱数 | N4: 计划出货期 | O4: 计划验货期 | P4: 第三方验货期 | Q4: 驗貨結果 | R4: 送货情况 | S4: 欠数 | T4: 船期SO | U4: 箱唛资料(收到日期) | V4: 外箱贴纸 | W4: 贴纸AI(收到日期) | Y4: 客供物料 | Z4: 日期码 | AA4: 备注 | AB4: ZURU 跟单 | AC4: 单价USD | AD4: 金额USD | AE4: 發票號 | AF4: 是否入系统 | AG4: MA 1語收縮膜 A版本 | AH4: MA 3语收缩膜 | AI4: EU 5L 收缩膜 | AJ4: 客版收縮膜 | AK4: MA 1語收藏指南 A版本 | AL4: MA 3语 收藏指南 A版本 | AM4: EU 5L 收藏指南 | AN4: 客版收藏指南 | AO4: MA口水胶 | AP4: 客版口水胶 | AQ4: 无闪粉口水胶 | AR4: PDQ SQ1-S001-S002 IL | AS4: PDQ SQ1-S001 3L | AT4: PDQ TQ1-S001 WM客版 1L | AU4: PDQ TQ1-S001-CA客版 2L | AV4: PDQ TQ2-S001 -S002 客版 | AW4: PDQ TQ3-S001 TG客版 | AX4: EC 展示架 | AY4: 中国单客办PDQ | AZ4: 客办PDQ | BA4: 无闪粉毛绒 | BB4: 布標 | BC4: 暹罗猫SIAMESE CAT | BD4: 孟加拉猫BENAL CAT | BE4: 美国猫AMERICAN SHORTHIR | BF4: 花斑猫CALICO CAT | BG4: 加菲猫EXOTIC CAT | BH4: 黑猫BLKCK CAT | BI4: 白猫CHNCHILLA CAT | BJ4: 总数 | BK4: 相差 | BL4: 入共享
A5: 45506 | B5: ACTION SERVICE & DISTRIBUTIE B.V. | C5: 荷兰 | D5: 4500141955 | E5: 4400438266 | F5: 4500141955-170 | H5: MB83-S002-9259 | I5: 混装（9259+9269各6PCS） | J5: 11280 | K5: 0 | L5: 6 | M5: =J5/L5 -> 1880 | N5: 45625 | O5: 45621 | Q5: PASS | U5: 8/2收到 | W5: 8/8收到 15L 黑白书纸 for slime bag+9/5收到西班牙环保标贴纸 | Y5: 8/8已收到客办包装资料 | AA5: 日期码格式：ZURU INC(BVI) 标准格式 日期：按实际生产日期 Packaging Info: 客版15L包装（收缩膜+西班牙环保标贴纸，收藏指南，15L 黑白书纸 for slime bag）+MA布标 Remark: 客人款号：3009949 1. 此单是子母件，贵司是母件工厂，需要负责组装入箱：一共2款，每款6pcs ，共12pcs 入一外箱。子件9259 工厂是兴信，子件9269 工厂是华康。子件CRD 是贵 司CRD -7天，会按时/提前送货到贵司组装。 2. 订单总数量496,320 pcs, 共分为22个柜子，请按期完货. 3. 所有产品按符合欧洲标准走货，微塑料需合规。 4. 所有包装材料都不允许PVC, 请用PET代替 5. 此单需要4套产前样及4套大货样，样板请寄到罗湖办公室Eddie收。 | AB5: Sandy Shao | AC5: 1.646 | AD5: =AC5*J5 -> 18566.88 | AE5: 88828-1.2 | AJ5: =J5 -> 11280 | AN5: =J5 -> 11280 | AQ5: =J5 -> 11280 | BB5: MA布标 | BC5: =J5/4 -> 2820 | BD5: =J5/4 -> 2820 | BE5: =J5/4 -> 2820 | BG5: =J5/4 -> 2820 | BJ5: =SUM(BC5:BI5) -> 11280 | BK5: =J5-BJ5 -> 0
A6: 45586 | B6: TJX COMPANIES, INC | C6: 美国 | D6: 4500147789 | E6: Marshalls DC#881-120PCS , DC#884-96PCS, DC#886-144PCS , DC#887-120PCS , DC#888-120PCS | F6: 4500147789-60 | H6: 9259-S001 | I6: 猫蛋 | J6: 600 | K6: 0 | L6: 24 | M6: =J6/L6 -> 25 | N6: 45649 | O6: 45645 | Q6: PASS | T6: 1/2出 | U6: 11/4收到 | W6: 无 | Y6: 11/16收到客供价格贴纸 | AA6: 日期码格式：ZURU INC(BVI) 标准格式 日期：按实际生产日期 Packaging Info: MA UPC包装+价格贴纸，价格贴纸客供。 Remark: 1. 产品和包装上印刷tracking code信息，格式为ZURU常规格式。 2. 分5个DC出货，每款产品每个DC的箱唛资料不同。具体分DC数量，请参考后面行项目备注。 3. ZURU QC验货。 | AB6: Emily Wu | AC6: 2.2472 | AD6: =J6*AC6 -> 1348.32 | AE6: 94169-1.23 | AG6: =J6 -> 600 | AL6: =J6 -> 600 | AQ6: =J6 -> 600 | BB6: MA布标 | BC6: =J6/4 -> 150 | BD6: =J6/4 -> 150 | BE6: =J6/4 -> 150 | BG6: =J6/4 -> 150 | BJ6: =SUM(BC6:BI6) -> 600 | BK6: =J6-BJ6 -> 0
A7: 45506 | B7: ACTION SERVICE & DISTRIBUTIE B.V. | C7: 荷兰 | D7: 4500141955 | E7: 4400926975 | F7: 4500141955-180 | H7: MB83-S002-9259 | I7: 混装（9259+9269各6PCS） | J7: 11280 | K7: 0 | L7: 6 | M7: =J7/L7 -> 1880 | N7: 45650 | O7: 45646 | Q7: PASS | T7: 12/30出 | U7: 8/2收到 | W7: 8/8收到 15L 黑白书纸 for slime bag+9/5收到西班牙环保标贴纸 | Y7: 8/8已收到客办包装资料 | AA7: 日期码格式：ZURU INC(BVI) 标准格式 日期：按实际生产日期 Packaging Info: 客版15L包装（收缩膜+西班牙环保标贴纸，收藏指南，15L 黑白书纸 for slime bag）+MA布标 Remark: 客人款号：3009949 1. 此单是子母件，贵司是母件工厂，需要负责组装入箱：一共2款，每款6pcs ，共12pcs 入一外箱。子件9259 工厂是兴信，子件9269 工厂是华康。子件CRD 是贵 司CRD -7天，会按时/提前送货到贵司组装。 2. 订单总数量496,320 pcs, 共分为22个柜子，请按期完货. 3. 所有产品按符合欧洲标准走货，微塑料需合规。 4. 所有包装材料都不允许PVC, 请用PET代替 5. 此单需要4套产前样及4套大货样，样板请寄到罗湖办公室Eddie收。 | AB7: Sandy Shao | AC7: 1.646 | AD7: =AC7*J7 -> 18566.88 | AE7: 94228-2.12 | AJ7: =J7 -> 11280 | AN7: =J7 -> 11280 | AQ7: =J7 -> 11280 | BB7: MA布标 | BC7: =J7/4 -> 2820 | BD7: =J7/4 -> 2820 | BE7: =J7/4 -> 2820 | BG7: =J7/4 -> 2820 | BJ7: =SUM(BC7:BI7) -> 11280 | BK7: =J7-BJ7 -> 0
A8: 45506 | B8: ACTION SERVICE & DISTRIBUTIE B.V. | C8: 荷兰 | D8: 4500141955 | E8: 4400909714 | F8: 4500141955-210 | H8: MB83-S002-9259 | I8: 混装（9259+9269各6PCS） | J8: 11280 | K8: 0 | L8: 6 | M8: =J8/L8 -> 1880 | N8: 45653 | O8: 45649 | Q8: PASS | T8: 1/3出 | U8: 8/2收到 | W8: 8/8收到 15L 黑白书纸 for slime bag+9/5收到西班牙环保标贴纸 | Y8: 8/8已收到客办包装资料 | AA8: 日期码格式：ZURU INC(BVI) 标准格式 日期：按实际生产日期 Packaging Info: 客版15L包装（收缩膜+西班牙环保标贴纸，收藏指南，15L 黑白书纸 for slime bag）+MA布标 Remark: 客人款号：3009949 1. 此单是子母件，贵司是母件工厂，需要负责组装入箱：一共2款，每款6pcs ，共12pcs 入一外箱。子件9259 工厂是兴信，子件9269 工厂是华康。子件CRD 是贵 司CRD -7天，会按时/提前送货到贵司组装。 2. 订单总数量496,320 pcs, 共分为22个柜子，请按期完货. 3. 所有产品按符合欧洲标准走货，微塑料需合规。 4. 所有包装材料都不允许PVC, 请用PET代替 5. 此单需要4套产前样及4套大货样，样板请寄到罗湖办公室Eddie收。 | AB8: Sandy Shao | AC8: 1.646 | AD8: =AC8*J8 -> 18566.88 | AJ8: =J8 -> 11280 | AN8: =J8 -> 11280 | AQ8: =J8 -> 11280 | BB8: MA布标 | BC8: =J8/4 -> 2820 | BD8: =J8/4 -> 2820 | BE8: =J8/4 -> 2820 | BG8: =J8/4 -> 2820 | BJ8: =SUM(BC8:BI8) -> 11280 | BK8: =J8-BJ8 -> 0
A9: 45586 | B9: TJX COMPANIES, INC | C9: 美国 | D9: 4500147796 | E9: TJ MAXX DC#891-168PCS , DC#894-144PCS , DC#896-120PCS , DC#897-240PCS , DC#898-120PCS | F9: 4500147796-80 | H9: 9259-S001 | I9: 猫蛋 | J9: 792 | K9: 0 | L9: 24 | M9: =J9/L9 -> 33 | N9: 45656 | O9: 45652 | Q9: PASS | T9: 1/8出 | U9: 11/4收到 | W9: 无 | Y9: 12-6客供价格贴纸 | AA9: 日期码格式：ZURU INC(BVI) 标准格式 日期：按实际生产日期 Packaging Info: MA UPC包装+价格贴纸，价格贴纸客供。 Remark: 1. 产品和包装上印刷tracking code信息，格式为ZURU常规格式。 2. 分5个DC出货，每款产品每个DC的箱唛资料不同。具体分DC数量，请参考后面行项目备注。 3. ZURU QC验货。 | AB9: Emily Wu | AC9: 2.2472 | AD9: =J9*AC9 -> 1779.7824 | AE9: 94170-1.23 | AG9: =J9 -> 792 | AL9: =J9 -> 792 | AQ9: =J9 -> 792 | BB9: MA布标 | BC9: =J9/4 -> 198 | BD9: =J9/4 -> 198 | BE9: =J9/4 -> 198 | BG9: =J9/4 -> 198 | BJ9: =SUM(BC9:BI9) -> 792 | BK9: =J9-BJ9 -> 0
A10: 45586 | B10: TJX COMPANIES, INC | C10: 美国 | D10: 4500147795 | E10: TJ MAXX DC#891-168PCS , DC#894-144PCS , DC#896-120PCS , DC#897-240PCS , DC#898-120PCS | F10: 4500147795-60 | H10: 9259-S001 | I10: 猫蛋 | J10: 792 | K10: 0 | L10: 24 | M10: =J10/L10 -> 33 | N10: 45656 | O10: 45652 | Q10: PASS | T10: 1/8出 | U10: 11/4收到 | W10: 无 | Y10: 12-6客供价格贴纸 | AA10: 日期码格式：ZURU INC(BVI) 标准格式 日期：按实际生产日期 Packaging Info: MA UPC包装+价格贴纸，价格贴纸客供。 Remark: 1. 产品和包装上印刷tracking code信息，格式为ZURU常规格式。 2. 分5个DC出货，每款产品每个DC的箱唛资料不同。具体分DC数量，请参考后面行项目备注。 3. ZURU QC验货。 | AB10: Emily Wu | AC10: 2.2472 | AD10: =J10*AC10 -> 1779.7824 | AE10: 94175-1.23 | AG10: =J10 -> 792 | AL10: =J10 -> 792 | AQ10: =J10 -> 792 | BB10: MA布标 | BC10: =J10/4 -> 198 | BD10: =J10/4 -> 198 | BE10: =J10/4 -> 198 | BG10: =J10/4 -> 198 | BJ10: =SUM(BC10:BI10) -> 792 | BK10: =J10-BJ10 -> 0
A11: 45586 | B11: TJX COMPANIES, INC | C11: 美国 | D11: 4500147793 | E11: Marshalls DC#881-120PCS , DC#884-96PCS, DC#886-144PCS , DC#887-120PCS , DC#888-120PCS | F11: 4500147793-80 | H11: 9259-S001 | I11: 猫蛋 | J11: 600 | K11: 0 | L11: 24 | M11: =J11/L11 -> 25 | N11: 45656 | O11: 45652 | Q11: PASS | T11: 1/9出 | U11: 11/4收到 | W11: 无 | Y11: 12-6客供价格贴纸 | AA11: 日期码格式：ZURU INC(BVI) 标准格式 日期：按实际生产日期 Packaging Info: MA UPC包装+价格贴纸，价格贴纸客供。 Remark: 1. 产品和包装上印刷tracking code信息，格式为ZURU常规格式。 2. 分5个DC出货，每款产品每个DC的箱唛资料不同。具体分DC数量，请参考后面行项目备注。 3. ZURU QC验货。 | AB11: Emily Wu | AC11: 2.2472 | AD11: =J11*AC11 -> 1348.32 | AE11: 94171-1.23 | AG11: =J11 -> 600 | AL11: =J11 -> 600 | AQ11: =J11 -> 600 | BB11: MA布标 | BC11: =J11/4 -> 150 | BD11: =J11/4 -> 150 | BE11: =J11/4 -> 150 | BG11: =J11/4 -> 150 | BJ11: =SUM(BC11:BI11) -> 600 | BK11: =J11-BJ11 -> 0
A12: 45586 | B12: TJX COMPANIES, INC | C12: 美国 | D12: 4500147792 | E12: Marshalls DC#881-120PCS , DC#884-96PCS, DC#886-144PCS , DC#887-120PCS , DC#888-120PCS | F12: 4500147792-60 | H12: 9259-S001 | I12: 猫蛋 | J12: 600 | K12: 0 | L12: 24 | M12: =J12/L12 -> 25 | N12: 45656 | O12: 45652 | Q12: PASS | T12: 1/9出 | U12: 11/4收到 | W12: 无 | Y12: 12-6客供价格贴纸 | AA12: 日期码格式：ZURU INC(BVI) 标准格式 日期：按实际生产日期 Packaging Info: MA UPC包装+价格贴纸，价格贴纸客供。 Remark: 1. 产品和包装上印刷tracking code信息，格式为ZURU常规格式。 2. 分5个DC出货，每款产品每个DC的箱唛资料不同。具体分DC数量，请参考后面行项目备注。 3. ZURU QC验货。 | AB12: Emily Wu | AC12: 2.2472 | AD12: =J12*AC12 -> 1348.32 | AE12: 94166-1.23 | AG12: =J12 -> 600 | AL12: =J12 -> 600 | AQ12: =J12 -> 600 | BB12: MA布标 | BC12: =J12/4 -> 150 | BD12: =J12/4 -> 150 | BE12: =J12/4 -> 150 | BG12: =J12/4 -> 150 | BJ12: =SUM(BC12:BI12) -> 600 | BK12: =J12-BJ12 -> 0
A13: 45586 | B13: TJX COMPANIES, INC | C13: 美国 | D13: 4500147798 | E13: TJ MAXX DC#891-240PCS , DC#894-192PCS , DC#896-192PCS , DC#897-384PCS , DC#898-192PCS | F13: 4500147798-90 | H13: 9259-S001 | I13: 猫蛋 | J13: 1200 | K13: 0 | L13: 24 | M13: =J13/L13 -> 50 | N13: 45657 | O13: 45653 | Q13: PASS | T13: 1/8出 | U13: 11/4收到 | W13: 无 | Y13: 12-6客供价格贴纸 | AA13: 日期码格式：ZURU INC(BVI) 标准格式 日期：按实际生产日期 Packaging Info: MA UPC包装+价格贴纸，价格贴纸客供。 Remark: 1. 产品和包装上印刷tracking code信息，格式为ZURU常规格式。 2. 分5个DC出货，每款产品每个DC的箱唛资料不同。具体分DC数量，请参考后面行项目备注。 3. ZURU QC验货。 | AB13: Emily Wu | AC13: 2.2427 | AD13: =J13*AC13 -> 2691.24 | AE13: 94174-1.23 | AG13: =J13 -> 1200 | AL13: =J13 -> 1200 | AQ13: =J13 -> 1200 | BB13: MA布标 | BC13: =J13/4 -> 300 | BD13: =J13/4 -> 300 | BE13: =J13/4 -> 300 | BG13: =J13/4 -> 300 | BJ13: =SUM(BC13:BI13) -> 1200 | BK13: =J13-BJ13 -> 0
A14: 45586 | B14: TJX COMPANIES, INC | C14: 美国 | D14: 4500147794 | E14: Marshalls DC#881-216PCS , DC#884-168PCS , DC#886-240PCS , DC#887-192PCS , DC#888-192PCS | F14: 4500147794-90 | H14: 9259-S001 | I14: 猫蛋 | J14: 1008 | K14: 0 | L14: 24 | M14: =J14/L14 -> 42 | N14: 45657 | O14: 45653 | Q14: PASS | T14: 1/9出 | U14: 11/4收到 | W14: 无 | Y14: 12-6客供价格贴纸 | AA14: 日期码格式：ZURU INC(BVI) 标准格式 日期：按实际生产日期 Packaging Info: MA UPC包装+价格贴纸，价格贴纸客供。 Remark: 1. 产品和包装上印刷tracking code信息，格式为ZURU常规格式。 2. 分5个DC出货，每款产品每个DC的箱唛资料不同。具体分DC数量，请参考后面行项目备注。 3. ZURU QC验货。 | AB14: Emily Wu | AC14: 2.2427 | AD14: =J14*AC14 -> 2260.6416 | AE14: 94176-1.23 | AG14: =J14 -> 1008 | AL14: =J14 -> 1008 | AQ14: =J14 -> 1008 | BB14: MA布标 | BC14: =J14/4 -> 252 | BD14: =J14/4 -> 252 | BE14: =J14/4 -> 252 | BG14: =J14/4 -> 252 | BJ14: =SUM(BC14:BI14) -> 1008 | BK14: =J14-BJ14 -> 0
A15: 45574 | B15: ACTION SERVICE & DISTRIBUTIE B.V. | C15: 荷兰 | D15: 4500146851 | E15: 4400925116 | F15: 4500146851-260 | H15: MB83-S002-9259 | I15: 混装（9259+9269各6PCS） | J15: 11862 | K15: 0 | L15: 6 | M15: =J15/L15 -> 1977 | N15: 45661 | O15: 45657 | Q15: PASS | T15: 1/16出 | U15: 10/9收到 | W15: 黑白书纸 for slime bag | AA15: 日期码格式：ZURU INC(BVI) 标准格式 日期：按实际生产日期 Packaging Info: 客版15L包装（收缩膜，收藏指南，15L 黑白书纸 for slime bag）+MA布标 Remark: 客人款号：3009949 1. 此单是子母件，贵司是母件工厂，需要负责组装入箱：一共2款，每款6pcs ，共12pcs 入一外箱。子件9259 工厂是兴信，子件9269 工厂是华康。子件CRD 是贵司CRD -7天，会按时/提前送货到贵司组装。 2. 订单总数量782,892 pcs, 共分为33个柜子，请按期完货. 3. 所有产品按符合欧洲标准走货，微塑料需合规。 4. 所有包装材料都不允许PVC, 请用PET代替 5. 此单需要4套产前样及4套大货样，样板请寄到罗湖办公室Eddie收。 | AB15: Becky Yang | AC15: 14.5047 | AD15: =AC15*M15 -> 28675.792 | AE15: 88972-1.10 | AJ15: =J15 -> 11862 | AN15: =J15 -> 11862 | AQ15: =J15 -> 11862 | BB15: MA布标 | BC15: =J15/4 -> 2965.5 | BD15: =J15/4 -> 2965.5 | BE15: =J15/4 -> 2965.5 | BG15: =J15/4 -> 2965.5 | BJ15: =SUM(BC15:BI15) -> 11862 | BK15: =J15-BJ15 -> 0
A16: 45574 | B16: ACTION SERVICE & DISTRIBUTIE B.V. | C16: 荷兰 | D16: 4500146851 | E16: 4400923138 | F16: 4500146851-240 | H16: MB83-S002-9259 | I16: 混装（9259+9269各6PCS） | J16: 11862 | K16: 0 | L16: 6 | M16: =J16/L16 -> 1977 | N16: 45661 | O16: 45657 | Q16: PASS | T16: 1/8出 | U16: 10/9收到 | W16: 黑白书纸 for slime bag | AA16: 日期码格式：ZURU INC(BVI) 标准格式 日期：按实际生产日期 Packaging Info: 客版15L包装（收缩膜，收藏指南，15L 黑白书纸 for slime bag）+MA布标 Remark: 客人款号：3009949 1. 此单是子母件，贵司是母件工厂，需要负责组装入箱：一共2款，每款6pcs ，共12pcs 入一外箱。子件9259 工厂是兴信，子件9269 工厂是华康。子件CRD 是贵司CRD -7天，会按时/提前送货到贵司组装。 2. 订单总数量782,892 pcs, 共分为33个柜子，请按期完货. 3. 所有产品按符合欧洲标准走货，微塑料需合规。 4. 所有包装材料都不允许PVC, 请用PET代替 5. 此单需要4套产前样及4套大货样，样板请寄到罗湖办公室Eddie收。 | AB16: Becky Yang | AC16: 14.8323 | AD16: =AC16*M16 -> 29323.457 | AE16: 88987-1.11 | AJ16: =J16 -> 11862 | AN16: =J16 -> 11862 | AQ16: =J16 -> 11862 | BB16: MA布标 | BC16: =J16/4 -> 2965.5 | BD16: =J16/4 -> 2965.5 | BE16: =J16/4 -> 2965.5 | BG16: =J16/4 -> 2965.5 | BJ16: =SUM(BC16:BI16) -> 11862 | BK16: =J16-BJ16 -> 0
A17: 45574 | B17: ACTION SERVICE & DISTRIBUTIE B.V. | C17: 荷兰 | D17: 4500146851 | E17: 4400952460 | F17: 4500146851-280 | H17: MB83-S002-9259 | I17: 混装（9259+9269各6PCS） | J17: 11862 | K17: 0 | L17: 6 | M17: =J17/L17 -> 1977 | N17: 45666 | O17: 45663 | Q17: PASS | U17: 10/9收到 | W17: 黑白书纸 for slime bag | AA17: 日期码格式：ZURU INC(BVI) 标准格式 日期：按实际生产日期 Packaging Info: 客版15L包装（收缩膜，收藏指南，15L 黑白书纸 for slime bag）+MA布标 Remark: 客人款号：3009949 1. 此单是子母件，贵司是母件工厂，需要负责组装入箱：一共2款，每款6pcs ，共12pcs 入一外箱。子件9259 工厂是兴信，子件9269 工厂是华康。子件CRD 是贵司CRD -7天，会按时/提前送货到贵司组装。 2. 订单总数量782,892 pcs, 共分为33个柜子，请按期完货. 3. 所有产品按符合欧洲标准走货，微塑料需合规。 4. 所有包装材料都不允许PVC, 请用PET代替 5. 此单需要4套产前样及4套大货样，样板请寄到罗湖办公室Eddie收。 | AB17: Becky Yang | AC17: 14.5074 | AD17: =AC17*M17 -> 28681.13 | AE17: 94026-1.14 | AJ17: =J17 -> 11862 | AN17: =J17 -> 11862 | AQ17: =J17 -> 11862 | BB17: MA布标 | BC17: =J17/4 -> 2965.5 | BD17: =J17/4 -> 2965.5 | BE17: =J17/4 -> 2965.5 | BG17: =J17/4 -> 2965.5 | BJ17: =SUM(BC17:BI17) -> 11862 | BK17: =J17-BJ17 -> 0
A18: 45574 | B18: ACTION SERVICE & DISTRIBUTIE B.V. | C18: 荷兰 | D18: 4500146851 | E18: 4400631850 | F18: 4500146851-110 | H18: MB83-S002-9259 | I18: 混装（9259+9269各6PCS） | J18: 11862 | K18: 0 | L18: 6 | M18: =J18/L18 -> 1977 | N18: 45668 | O18: 45664 | Q18: PASS | T18: 1/20出 | U18: 10/9收到 | W18: 黑白书纸 for slime bag | AA18: 日期码格式：ZURU INC(BVI) 标准格式 日期：按实际生产日期 Packaging Info: 客版15L包装（收缩膜，收藏指南，15L 黑白书纸 for slime bag）+MA布标 Remark: 客人款号：3009949 1. 此单是子母件，贵司是母件工厂，需要负责组装入箱：一共2款，每款6pcs ，共12pcs 入一外箱。子件9259 工厂是兴信，子件9269 工厂是华康。子件CRD 是贵司CRD -7天，会按时/提前送货到贵司组装。 2. 订单总数量782,892 pcs, 共分为33个柜子，请按期完货. 3. 所有产品按符合欧洲标准走货，微塑料需合规。 4. 所有包装材料都不允许PVC, 请用PET代替 5. 此单需要4套产前样及4套大货样，样板请寄到罗湖办公室Eddie收。 | AB18: Becky Yang | AC18: 14.541 | AD18: =AC18*M18 -> 28747.557 | AE18: 94091-1.18 | AJ18: =J18 -> 11862 | AN18: =J18 -> 11862 | AQ18: =J18 -> 11862 | BB18: MA布标 | BC18: =J18/4 -> 2965.5 | BD18: =J18/4 -> 2965.5 | BE18: =J18/4 -> 2965.5 | BG18: =J18/4 -> 2965.5 | BJ18: =SUM(BC18:BI18) -> 11862 | BK18: =J18-BJ18 -> 0
A19: 45586 | B19: TJX COMPANIES, INC | C19: 美国 | D19: 4500147799 | E19: Marshalls DC#881-120PCS , DC#884-96PCS, DC#886-144PCS , DC#887-120PCS , DC#888-120PCS | F19: 4500147799-70 | H19: 9259-S001 | I19: 猫蛋 | J19: 600 | K19: 0 | L19: 24 | M19: =J19/L19 -> 25 | N19: 45677 | O19: 45673 | Q19: PASS | T19: 2/14出 | U19: 11/4收到 | W19: 无 | Y19: 12/20-客供价格贴纸 | AA19: 日期码格式：ZURU INC(BVI) 标准格式 日期：按实际生产日期 Packaging Info: MA UPC包装+价格贴纸，价格贴纸客供。 Remark: 1. 产品和包装上印刷tracking code信息，格式为ZURU常规格式。 2. 分5个DC出货，每款产品每个DC的箱唛资料不同。具体分DC数量，请参考后面行项目备注。 3. ZURU QC验货。 | AB19: Emily Wu | AC19: 2.2421 | AD19: =J19*AC19 -> 1345.26 | AG19: =J19 -> 600 | AL19: =J19 -> 600 | AQ19: =J19 -> 600 | BB19: MA布标 | BC19: =J19/4 -> 150 | BD19: =J19/4 -> 150 | BE19: =J19/4 -> 150 | BG19: =J19/4 -> 150 | BJ19: =SUM(BC19:BI19) -> 600 | BK19: =J19-BJ19 -> 0
A20: 45586 | B20: TJX COMPANIES, INC | C20: 美国 | D20: 4500147801 | E20: TJ MAXX DC#891-168PCS , DC#894-144PCS , DC#896-120PCS , DC#897-240PCS , DC#898-120PCS | F20: 4500147801-70 | H20: 9259-S001 | I20: 猫蛋 | J20: 792 | K20: 0 | L20: 24 | M20: =J20/L20 -> 33 | N20: 45677 | O20: 45673 | Q20: PASS | T20: 2/11出 | U20: 11/4收到 | W20: 无 | Y20: 12/20-客供价格贴纸 | AA20: 日期码格式：ZURU INC(BVI) 标准格式 日期：按实际生产日期 Packaging Info: MA UPC包装+价格贴纸，价格贴纸客供。 Remark: 1. 产品和包装上印刷tracking code信息，格式为ZURU常规格式。 2. 分5个DC出货，每款产品每个DC的箱唛资料不同。具体分DC数量，请参考后面行项目备注。 3. ZURU QC验货。 | AB20: Emily Wu | AC20: 2.2472 | AD20: =J20*AC20 -> 1779.7824 | AG20: =J20 -> 792 | AL20: =J20 -> 792 | AQ20: =J20 -> 792 | BB20: MA布标 | BC20: =J20/4 -> 198 | BD20: =J20/4 -> 198 | BE20: =J20/4 -> 198 | BG20: =J20/4 -> 198 | BJ20: =SUM(BC20:BI20) -> 792 | BK20: =J20-BJ20 -> 0
A21: 45586 | B21: TJX COMPANIES, INC | C21: 美国 | D21: 4500147803 | E21: TJ MAXX DC#891-240PCS , DC#894-216PCS , DC#896-192PCS , DC#897-360PCS , DC#898-192PCS | F21: 4500147803-90 | H21: 9259-S001 | I21: 猫蛋 | J21: 1200 | K21: 0 | L21: 24 | M21: =J21/L21 -> 50 | N21: 45677 | O21: 45673 | Q21: PASS | T21: 2/13出 | U21: 11/4收到 | W21: 无 | Y21: 12/20-客供价格贴纸 | AA21: 日期码格式：ZURU INC(BVI) 标准格式 日期：按实际生产日期 Packaging Info: MA UPC包装+价格贴纸，价格贴纸客供。 Remark: 1. 产品和包装上印刷tracking code信息，格式为ZURU常规格式。 2. 分5个DC出货，每款产品每个DC的箱唛资料不同。具体分DC数量，请参考后面行项目备注。 3. ZURU QC验货。 | AB21: Emily Wu | AC21: 2.2427 | AD21: =J21*AC21 -> 2691.24 | AG21: =J21 -> 1200 | AL21: =J21 -> 1200 | AQ21: =J21 -> 1200 | BB21: MA布标 | BC21: =J21/4 -> 300 | BD21: =J21/4 -> 300 | BE21: =J21/4 -> 300 | BG21: =J21/4 -> 300 | BJ21: =SUM(BC21:BI21) -> 1200 | BK21: =J21-BJ21 -> 0
A22: 45586 | B22: TJX COMPANIES, INC | C22: 美国 | D22: 4500147800 | E22: Marshalls DC#881-216PCS , DC#884-168PCS , DC#886-216PCS , DC#887-192PCS , DC#888-216PCS | F22: 4500147800-90 | H22: 9259-S001 | I22: 猫蛋 | J22: 1008 | K22: 0 | L22: 24 | M22: =J22/L22 -> 42 | N22: 45677 | O22: 45673 | Q22: PASS | T22: 2/14出 | U22: 11/4收到 | W22: 无 | Y22: 12/20-客供价格贴纸 | AA22: 日期码格式：ZURU INC(BVI) 标准格式 日期：按实际生产日期 Packaging Info: MA UPC包装+价格贴纸，价格贴纸客供。 Remark: 1. 产品和包装上印刷tracking code信息，格式为ZURU常规格式。 2. 分5个DC出货，每款产品每个DC的箱唛资料不同。具体分DC数量，请参考后面行项目备注。 3. ZURU QC验货。 | AB22: Emily Wu | AC22: 2.2427 | AD22: =J22*AC22 -> 2260.6416 | AG22: =J22 -> 1008 | AL22: =J22 -> 1008 | AQ22: =J22 -> 1008 | BB22: MA布标 | BC22: =J22/4 -> 252 | BD22: =J22/4 -> 252 | BE22: =J22/4 -> 252 | BG22: =J22/4 -> 252 | BJ22: =SUM(BC22:BI22) -> 1008 | BK22: =J22-BJ22 -> 0
A23: 45574 | B23: ACTION SERVICE & DISTRIBUTIE B.V. | C23: 荷兰 | D23: 4500146851 | E23: 4400923139 | F23: 4500146851-250 | H23: MB83-S002-9259 | I23: 混装（9259+9269各6PCS） | J23: 11862 | K23: 0 | L23: 6 | M23: =J23/L23 -> 1977 | N23: 45677 | O23: 45673 | Q23: PASS | T23: 1/26出 | U23: 10/9收到 | W23: 黑白书纸 for slime bag | AA23: 日期码格式：ZURU INC(BVI) 标准格式 日期：按实际生产日期 Packaging Info: 客版15L包装（收缩膜，收藏指南，15L 黑白书纸 for slime bag）+MA布标 Remark: 客人款号：3009949 1. 此单是子母件，贵司是母件工厂，需要负责组装入箱：一共2款，每款6pcs ，共12pcs 入一外箱。子件9259 工厂是兴信，子件9269 工厂是华康。子件CRD 是贵司CRD -7天，会按时/提前送货到贵司组装。 2. 订单总数量782,892 pcs, 共分为33个柜子，请按期完货. 3. 所有产品按符合欧洲标准走货，微塑料需合规。 4. 所有包装材料都不允许PVC, 请用PET代替 5. 此单需要4套产前样及4套大货样，样板请寄到罗湖办公室Eddie收。 | AB23: Becky Yang | AC23: 14.541 | AD23: =AC23*M23 -> 28747.557 | AE23: 94091-1.18 | AJ23: =J23 -> 11862 | AN23: =J23 -> 11862 | AQ23: =J23 -> 11862 | BB23: MA布标 | BC23: =J23/4 -> 2965.5 | BD23: =J23/4 -> 2965.5 | BE23: =J23/4 -> 2965.5 | BG23: =J23/4 -> 2965.5 | BJ23: =SUM(BC23:BI23) -> 11862 | BK23: =J23-BJ23 -> 0
A24: 45574 | B24: ACTION SERVICE & DISTRIBUTIE B.V. | C24: 荷兰 | D24: 4500146851 | E24: 4400393637 | F24: 4500146851-70 | H24: MB83-S002-9259 | I24: 混装（9259+9269各6PCS） | J24: 11862 | K24: 0 | L24: 6 | M24: =J24/L24 -> 1977 | N24: 45691 | O24: 45687 | Q24: PASS | T24: 2/6出 | U24: 10/9收到 | W24: 黑白书纸 for slime bag | AA24: 日期码格式：ZURU INC(BVI) 标准格式 日期：按实际生产日期 Packaging Info: 客版15L包装（收缩膜，收藏指南，15L 黑白书纸 for slime bag）+MA布标 Remark: 客人款号：3009949 1. 此单是子母件，贵司是母件工厂，需要负责组装入箱：一共2款，每款6pcs ，共12pcs 入一外箱。子件9259 工厂是兴信，子件9269 工厂是华康。子件CRD 是贵司CRD -7天，会按时/提前送货到贵司组装。 2. 订单总数量782,892 pcs, 共分为33个柜子，请按期完货. 3. 所有产品按符合欧洲标准走货，微塑料需合规。 4. 所有包装材料都不允许PVC, 请用PET代替 5. 此单需要4套产前样及4套大货样，样板请寄到罗湖办公室Eddie收。 | AB24: Becky Yang | AC24: 14.541 | AD24: =AC24*M24 -> 28747.557 | AE24: 94182-2.6 | AJ24: =J24 -> 11862 | AN24: =J24 -> 11862 | AQ24: =J24 -> 11862 | BB24: MA布标 | BC24: =J24/4 -> 2965.5 | BD24: =J24/4 -> 2965.5 | BE24: =J24/4 -> 2965.5 | BG24: =J24/4 -> 2965.5 | BJ24: =SUM(BC24:BI24) -> 11862 | BK24: =J24-BJ24 -> 0
A25: 45586 | B25: TJX COMPANIES, INC | C25: 美国 | D25: 4500147804 | E25: Marshalls DC#881-120PCS , DC#884-96PCS, DC#886-144PCS , DC#887-120PCS , DC#888-120PCS | F25: 4500147804-80 | H25: 9259-S001 | I25: 猫蛋 | J25: 600 | K25: 0 | L25: 24 | M25: =J25/L25 -> 25 | N25: 45698 | O25: 45694 | Q25: PASS | T25: 2/18出 | U25: 11/4收到 | W25: 无 | Y25: 12/20-客供价格贴纸 | AA25: 日期码格式：ZURU INC(BVI) 标准格式 日期：按实际生产日期 Packaging Info: MA UPC包装+价格贴纸，价格贴纸客供。 Remark: 1. 产品和包装上印刷tracking code信息，格式为ZURU常规格式。 2. 分5个DC出货，每款产品每个DC的箱唛资料不同。具体分DC数量，请参考后面行项目备注。 3. ZURU QC验货。 | AB25: Emily Wu | AC25: 2.2472 | AD25: =J25*AC25 -> 1348.32 | AE25: 94381-2.27 | AG25: =J25 -> 600 | AL25: =J25 -> 600 | AQ25: =J25 -> 600 | BB25: MA布标 | BC25: =J25/4 -> 150 | BD25: =J25/4 -> 150 | BE25: =J25/4 -> 150 | BG25: =J25/4 -> 150 | BJ25: =SUM(BC25:BI25) -> 600 | BK25: =J25-BJ25 -> 0
A26: 45586 | B26: TJX COMPANIES, INC | C26: 美国 | D26: 4500147806 | E26: TJ MAXX DC#891-168PCS , DC#894-144PCS , DC#896-120PCS , DC#897-240PCS , DC#898-120PCS | F26: 4500147806-80 | H26: 9259-S001 | I26: 猫蛋 | J26: 792 | K26: 0 | L26: 24 | M26: =J26/L26 -> 33 | N26: 45698 | O26: 45694 | Q26: PASS | T26: 2/21出 | U26: 11/4收到 | W26: 无 | Y26: 12/20-客供价格贴纸 | AA26: 日期码格式：ZURU INC(BVI) 标准格式 日期：按实际生产日期 Packaging Info: MA UPC包装+价格贴纸，价格贴纸客供。 Remark: 1. 产品和包装上印刷tracking code信息，格式为ZURU常规格式。 2. 分5个DC出货，每款产品每个DC的箱唛资料不同。具体分DC数量，请参考后面行项目备注。 3. ZURU QC验货。 | AB26: Emily Wu | AC26: 2.2472 | AD26: =J26*AC26 -> 1779.7824 | AE26: 94380-2.27 | AG26: =J26 -> 792 | AL26: =J26 -> 792 | AQ26: =J26 -> 792 | BB26: MA布标 | BC26: =J26/4 -> 198 | BD26: =J26/4 -> 198 | BE26: =J26/4 -> 198 | BG26: =J26/4 -> 198 | BJ26: =SUM(BC26:BI26) -> 792 | BK26: =J26-BJ26 -> 0
A27: 45506 | B27: ACTION SERVICE & DISTRIBUTIE B.V. | C27: 荷兰 | D27: 4500141955 | E27: 4400919336 | F27: 4500141955-220 | H27: MB83-S002-9259 | I27: 混装（9259+9269各6PCS） | J27: 11280 | K27: 0 | L27: 6 | M27: =J27/L27 -> 1880 | N27: 45692 | O27: 45322 | Q27: PASS | T27: 2/12出 | U27: 8/2收到 | W27: 8/8收到 15L 黑白书纸 for slime bag+9/5收到西班牙环保标贴纸 | Y27: 8/8已收到客办包装资料 | AA27: 日期码格式：ZURU INC(BVI) 标准格式 日期：按实际生产日期 Packaging Info: 客版15L包装（收缩膜+西班牙环保标贴纸，收藏指南，15L 黑白书纸 for slime bag）+MA布标 Remark: 客人款号：3009949 1. 此单是子母件，贵司是母件工厂，需要负责组装入箱：一共2款，每款6pcs ，共12pcs 入一外箱。子件9259 工厂是兴信，子件9269 工厂是华康。子件CRD 是贵 司CRD -7天，会按时/提前送货到贵司组装。 2. 订单总数量496,320 pcs, 共分为22个柜子，请按期完货. 3. 所有产品按符合欧洲标准走货，微塑料需合规。 4. 所有包装材料都不允许PVC, 请用PET代替 5. 此单需要4套产前样及4套大货样，样板请寄到罗湖办公室Eddie收。 | AB27: Sandy Shao | AC27: 1.646 | AD27: =AC27*J27 -> 18566.88 | AJ27: =J27 -> 11280 | AN27: =J27 -> 11280 | AQ27: =J27 -> 11280 | BB27: MA布标 | BC27: =J27/4 -> 2820 | BD27: =J27/4 -> 2820 | BE27: =J27/4 -> 2820 | BG27: =J27/4 -> 2820 | BJ27: =SUM(BC27:BI27) -> 11280 | BK27: =J27-BJ27 -> 0
A28: 45574 | B28: ACTION SERVICE & DISTRIBUTIE B.V. | C28: 荷兰 | D28: 4500146851 | E28: 4400907403 | F28: 4500146851-190 | H28: MB83-S002-9259 | I28: 混装（9259+9269各6PCS） | J28: 11862 | K28: 0 | L28: 6 | M28: =J28/L28 -> 1977 | N28: 45696 | O28: 45692 | Q28: PASS | T28: 2/11出 | U28: 10/9收到 | W28: 黑白书纸 for slime bag | AA28: 日期码格式：ZURU INC(BVI) 标准格式 日期：按实际生产日期 Packaging Info: 客版15L包装（收缩膜，收藏指南，15L 黑白书纸 for slime bag）+MA布标 Remark: 客人款号：3009949 1. 此单是子母件，贵司是母件工厂，需要负责组装入箱：一共2款，每款6pcs ，共12pcs 入一外箱。子件9259 工厂是兴信，子件9269 工厂是华康。子件CRD 是贵司CRD -7天，会按时/提前送货到贵司组装。 2. 订单总数量782,892 pcs, 共分为33个柜子，请按期完货. 3. 所有产品按符合欧洲标准走货，微塑料需合规。 4. 所有包装材料都不允许PVC, 请用PET代替 5. 此单需要4套产前样及4套大货样，样板请寄到罗湖办公室Eddie收。 | AB28: Becky Yang | AC28: 14.5074 | AD28: =M28*AC28 -> 28681.13 | AE28: 94211-2.11 | AJ28: =J28 -> 11862 | AN28: =J28 -> 11862 | AQ28: =J28 -> 11862 | BB28: MA布标 | BC28: =J28/4 -> 2965.5 | BD28: =J28/4 -> 2965.5 | BE28: =J28/4 -> 2965.5 | BG28: =J28/4 -> 2965.5 | BJ28: =SUM(BC28:BI28) -> 11862 | BK28: =J28-BJ28 -> 0
A29: 45574 | B29: ACTION SERVICE & DISTRIBUTIE B.V. | C29: 荷兰 | D29: 4500146851 | E29: 4400328861 | F29: 4500146851-30 | H29: MB83-S002-9259 | I29: 混装（9259+9269各6PCS） | J29: 11862 | K29: 0 | L29: 6 | M29: =J29/L29 -> 1977 | N29: 45724 | O29: 45720 | Q29: PASS | T29: 3/18出 | U29: 10/9收到 | W29: 黑白书纸 for slime bag | AA29: 日期码格式：ZURU INC(BVI) 标准格式 日期：按实际生产日期 Packaging Info: 客版15L包装（收缩膜，收藏指南，15L 黑白书纸 for slime bag）+MA布标 Remark: 客人款号：3009949 1. 此单是子母件，贵司是母件工厂，需要负责组装入箱：一共2款，每款6pcs ，共12pcs 入一外箱。子件9259 工厂是兴信，子件9269 工厂是华康。子件CRD 是贵司CRD -7天，会按时/提前送货到贵司组装。 2. 订单总数量782,892 pcs, 共分为33个柜子，请按期完货. 3. 所有产品按符合欧洲标准走货，微塑料需合规。 4. 所有包装材料都不允许PVC, 请用PET代替 5. 此单需要4套产前样及4套大货样，样板请寄到罗湖办公室Eddie收。 | AB29: Becky Yang | AC29: 0.4654 | AD29: =AC29*M29 -> 920.0958 | AE29: 94584-3.20 | AJ29: =J29 -> 11862 | AN29: =J29 -> 11862 | AQ29: =J29 -> 11862 | BB29: MA布标 | BC29: =J29/4 -> 2965.5 | BD29: =J29/4 -> 2965.5 | BE29: =J29/4 -> 2965.5 | BG29: =J29/4 -> 2965.5 | BJ29: =SUM(BC29:BI29) -> 11862 | BK29: =J29-BJ29 -> 0
A30: 45574 | B30: ACTION SERVICE & DISTRIBUTIE B.V. | C30: 荷兰 | D30: 4500146851 | E30: 4400393638 | F30: 4500146851-80 | H30: MB83-S002-9259 | I30: 混装（9259+9269各6PCS） | J30: 11862 | K30: 0 | L30: 6 | M30: =J30/L30 -> 1977 | N30: 45736 | O30: 45731 | Q30: PASS | T30: 3/22出 | U30: 10/9收到 | W30: 黑白书纸 for slime bag | AA30: 日期码格式：ZURU INC(BVI) 标准格式 日期：按实际生产日期 Packaging Info: 客版15L包装（收缩膜，收藏指南，15L 黑白书纸 for slime bag）+MA布标 Remark: 客人款号：3009949 1. 此单是子母件，贵司是母件工厂，需要负责组装入箱：一共2款，每款6pcs ，共12pcs 入一外箱。子件9259 工厂是兴信，子件9269 工厂是华康。子件CRD 是贵司CRD -7天，会按时/提前送货到贵司组装。 2. 订单总数量782,892 pcs, 共分为33个柜子，请按期完货. 3. 所有产品按符合欧洲标准走货，微塑料需合规。 4. 所有包装材料都不允许PVC, 请用PET代替 5. 此单需要4套产前样及4套大货样，样板请寄到罗湖办公室Eddie收。 | AB30: Becky Yang | AC30: 1.6548 | AD30: =AC30*M30 -> 3271.5396 | AE30: 94627-3.25 | AJ30: =J30 -> 11862 | AN30: =J30 -> 11862 | AQ30: =J30 -> 11862 | BB30: MA布标 | BC30: =J30/4 -> 2965.5 | BD30: =J30/4 -> 2965.5 | BE30: =J30/4 -> 2965.5 | BG30: =J30/4 -> 2965.5 | BJ30: =SUM(BC30:BI30) -> 11862 | BK30: =J30-BJ30 -> 0
A31: 45574 | B31: ACTION SERVICE & DISTRIBUTIE B.V. | C31: 荷兰 | D31: 4500146851 | E31: 4400650967 | F31: 4500146851-130 | H31: MB83-S002-9259 | I31: 混装（9259+9269各6PCS） | J31: 11862 | K31: 0 | L31: 6 | M31: =J31/L31 -> 1977 | N31: 45738 | O31: 45734 | Q31: PASS | T31: 3/25出 | U31: 10/9收到 | W31: 黑白书纸 for slime bag | AA31: 日期码格式：ZURU INC(BVI) 标准格式 日期：按实际生产日期 Packaging Info: 客版15L包装（收缩膜，收藏指南，15L 黑白书纸 for slime bag）+MA布标 Remark: 客人款号：3009949 1. 此单是子母件，贵司是母件工厂，需要负责组装入箱：一共2款，每款6pcs ，共12pcs 入一外箱。子件9259 工厂是兴信，子件9269 工厂是华康。子件CRD 是贵司CRD -7天，会按时/提前送货到贵司组装。 2. 订单总数量782,892 pcs, 共分为33个柜子，请按期完货. 3. 所有产品按符合欧洲标准走货，微塑料需合规。 4. 所有包装材料都不允许PVC, 请用PET代替 5. 此单需要4套产前样及4套大货样，样板请寄到罗湖办公室Eddie收。 | AB31: Becky Yang | AC31: 1.6548 | AD31: =AC31*M31 -> 3271.5396 | AE31: 94668-3.29 | AJ31: =J31 -> 11862 | AN31: =J31 -> 11862 | AQ31: =J31 -> 11862 | BB31: MA布标 | BC31: =J31/4 -> 2965.5 | BD31: =J31/4 -> 2965.5 | BE31: =J31/4 -> 2965.5 | BG31: =J31/4 -> 2965.5 | BJ31: =SUM(BC31:BI31) -> 11862 | BK31: =J31-BJ31 -> 0
A32: 45574 | B32: ACTION SERVICE & DISTRIBUTIE B.V. | C32: 荷兰 | D32: 4500146851 | E32: 4400393639 | F32: 4500146851-90 | H32: MB83-S002-9259 | I32: 混装（9259+9269各6PCS） | J32: 11862 | K32: 0 | L32: 6 | M32: =J32/L32 -> 1977 | N32: 45745 | O32: 45741 | Q32: PASS | T32: 3/31出 | U32: 10/9收到 | W32: 黑白书纸 for slime bag | AA32: 日期码格式：ZURU INC(BVI) 标准格式 日期：按实际生产日期 Packaging Info: 客版15L包装（收缩膜，收藏指南，15L 黑白书纸 for slime bag）+MA布标 Remark: 客人款号：3009949 1. 此单是子母件，贵司是母件工厂，需要负责组装入箱：一共2款，每款6pcs ，共12pcs 入一外箱。子件9259 工厂是兴信，子件9269 工厂是华康。子件CRD 是贵司CRD -7天，会按时/提前送货到贵司组装。 2. 订单总数量782,892 pcs, 共分为33个柜子，请按期完货. 3. 所有产品按符合欧洲标准走货，微塑料需合规。 4. 所有包装材料都不允许PVC, 请用PET代替 5. 此单需要4套产前样及4套大货样，样板请寄到罗湖办公室Eddie收。 | AB32: Becky Yang | AC32: 0.4654 | AD32: =AC32*M32 -> 920.0958 | AE32: 94919-5.5 | AJ32: =J32 -> 11862 | AN32: =J32 -> 11862 | AQ32: =J32 -> 11862 | BB32: MA布标 | BC32: =J32/4 -> 2965.5 | BD32: =J32/4 -> 2965.5 | BE32: =J32/4 -> 2965.5 | BG32: =J32/4 -> 2965.5 | BJ32: =SUM(BC32:BI32) -> 11862 | BK32: =J32-BJ32 -> 0
A33: 45574 | B33: ACTION SERVICE & DISTRIBUTIE B.V. | C33: 荷兰 | D33: 4500146851 | E33: 4400631849 | F33: 4500146851-100 | H33: MB83-S002-9259 | I33: 混装（9259+9269各6PCS） | J33: 11862 | K33: 0 | L33: 6 | M33: =J33/L33 -> 1977 | N33: 45753 | O33: 45749 | Q33: PASS | U33: 10/9收到 | W33: 黑白书纸 for slime bag | AA33: 日期码格式：ZURU INC(BVI) 标准格式 日期：按实际生产日期 Packaging Info: 客版15L包装（收缩膜，收藏指南，15L 黑白书纸 for slime bag）+MA布标 Remark: 客人款号：3009949 1. 此单是子母件，贵司是母件工厂，需要负责组装入箱：一共2款，每款6pcs ，共12pcs 入一外箱。子件9259 工厂是兴信，子件9269 工厂是华康。子件CRD 是贵司CRD -7天，会按时/提前送货到贵司组装。 2. 订单总数量782,892 pcs, 共分为33个柜子，请按期完货. 3. 所有产品按符合欧洲标准走货，微塑料需合规。 4. 所有包装材料都不允许PVC, 请用PET代替 5. 此单需要4套产前样及4套大货样，样板请寄到罗湖办公室Eddie收。 | AB33: Becky Yang | AC33: 1.6548 | AD33: =AC33*M33 -> 3271.5396 | AE33: 94927-5.6 | AJ33: =J33 -> 11862 | AN33: =J33 -> 11862 | AQ33: =J33 -> 11862 | BB33: MA布标 | BC33: =J33/4 -> 2965.5 | BD33: =J33/4 -> 2965.5 | BE33: =J33/4 -> 2965.5 | BG33: =J33/4 -> 2965.5 | BJ33: =SUM(BC33:BI33) -> 11862 | BK33: =J33-BJ33 -> 0
A34: 45574 | B34: ACTION SERVICE & DISTRIBUTIE B.V. | C34: 荷兰 | D34: 4500146851 | E34: 4400952458 | F34: 4500146851-270 | H34: MB83-S002-9259 | I34: 混装（9259+9269各6PCS） | J34: 11862 | K34: 0 | L34: 6 | M34: =J34/L34 -> 1977 | N34: 45758 | O34: 45754 | Q34: PASS | T34: 4/15出 | U34: 10/9收到 | W34: 黑白书纸 for slime bag | AA34: 日期码格式：ZURU INC(BVI) 标准格式 日期：按实际生产日期 Packaging Info: 客版15L包装（收缩膜，收藏指南，15L 黑白书纸 for slime bag）+MA布标 Remark: 客人款号：3009949 1. 此单是子母件，贵司是母件工厂，需要负责组装入箱：一共2款，每款6pcs ，共12pcs 入一外箱。子件9259 工厂是兴信，子件9269 工厂是华康。子件CRD 是贵司CRD -7天，会按时/提前送货到贵司组装。 2. 订单总数量782,892 pcs, 共分为33个柜子，请按期完货. 3. 所有产品按符合欧洲标准走货，微塑料需合规。 4. 所有包装材料都不允许PVC, 请用PET代替 5. 此单需要4套产前样及4套大货样，样板请寄到罗湖办公室Eddie收。 | AB34: Becky Yang | AC34: 14.6964 | AD34: =AC34*M34 -> 29054.783 | AE34: 94766-4.15 | AJ34: =J34 -> 11862 | AN34: =J34 -> 11862 | AQ34: =J34 -> 11862 | BB34: MA布标 | BC34: =J34/4 -> 2965.5 | BD34: =J34/4 -> 2965.5 | BE34: =J34/4 -> 2965.5 | BG34: =J34/4 -> 2965.5 | BJ34: =SUM(BC34:BI34) -> 11862 | BK34: =J34-BJ34 -> 0
A35: 45574 | B35: ACTION SERVICE & DISTRIBUTIE B.V. | C35: 荷兰 | D35: 4500146851 | E35: 4400902197 | F35: 4500146851-180 | H35: MB83-S002-9259 | I35: 混装（9259+9269各6PCS） | J35: 11862 | K35: 0 | L35: 6 | M35: =J35/L35 -> 1977 | N35: 45762 | O35: 45758 | Q35: PASS | T35: 4/19出 | U35: 10/9收到 | W35: 黑白书纸 for slime bag | AA35: 日期码格式：ZURU INC(BVI) 标准格式 日期：按实际生产日期 Packaging Info: 客版15L包装（收缩膜，收藏指南，15L 黑白书纸 for slime bag）+MA布标 Remark: 客人款号：3009949 1. 此单是子母件，贵司是母件工厂，需要负责组装入箱：一共2款，每款6pcs ，共12pcs 入一外箱。子件9259 工厂是兴信，子件9269 工厂是华康。子件CRD 是贵司CRD -7天，会按时/提前送货到贵司组装。 2. 订单总数量782,892 pcs, 共分为33个柜子，请按期完货. 3. 所有产品按符合欧洲标准走货，微塑料需合规。 4. 所有包装材料都不允许PVC, 请用PET代替 5. 此单需要4套产前样及4套大货样，样板请寄到罗湖办公室Eddie收。 | AB35: Becky Yang | AC35: 1.6548 | AD35: =AC35*M35 -> 3271.5396 | AE35: 94766-4.15 | AJ35: =J35 -> 11862 | AN35: =J35 -> 11862 | AQ35: =J35 -> 11862 | BB35: MA布标 | BC35: =J35/4 -> 2965.5 | BD35: =J35/4 -> 2965.5 | BE35: =J35/4 -> 2965.5 | BG35: =J35/4 -> 2965.5 | BJ35: =SUM(BC35:BI35) -> 11862 | BK35: =J35-BJ35 -> 0
A36: 45574 | B36: ACTION SERVICE & DISTRIBUTIE B.V. | C36: 荷兰 | D36: 4500146851 | E36: 4400907404 | F36: 4500146851-200 | H36: MB83-S002-9259 | I36: 混装（9259+9269各6PCS） | J36: 11862 | K36: 0 | L36: 6 | M36: =J36/L36 -> 1977 | N36: 45776 | O36: 45772 | Q36: PASS | T36: 5/5出 | U36: 10/9收到 | W36: 黑白书纸 for slime bag | AA36: 日期码格式：ZURU INC(BVI) 标准格式 日期：按实际生产日期 Packaging Info: 客版15L包装（收缩膜，收藏指南，15L 黑白书纸 for slime bag）+MA布标 Remark: 客人款号：3009949 1. 此单是子母件，贵司是母件工厂，需要负责组装入箱：一共2款，每款6pcs ，共12pcs 入一外箱。子件9259 工厂是兴信，子件9269 工厂是华康。子件CRD 是贵司CRD -7天，会按时/提前送货到贵司组装。 2. 订单总数量782,892 pcs, 共分为33个柜子，请按期完货. 3. 所有产品按符合欧洲标准走货，微塑料需合规。 4. 所有包装材料都不允许PVC, 请用PET代替 5. 此单需要4套产前样及4套大货样，样板请寄到罗湖办公室Eddie收。 | AB36: Becky Yang | AC36: 1.6548 | AD36: =AC36*M36 -> 3271.5396 | AE36: 94565-3.17 | AJ36: =J36 -> 11862 | AN36: =J36 -> 11862 | AQ36: =J36 -> 11862 | BB36: MA布标 | BC36: =J36/4 -> 2965.5 | BD36: =J36/4 -> 2965.5 | BE36: =J36/4 -> 2965.5 | BG36: =J36/4 -> 2965.5 | BJ36: =SUM(BC36:BI36) -> 11862 | BK36: =J36-BJ36 -> 0
A37: 45574 | B37: ACTION SERVICE & DISTRIBUTIE B.V. | C37: 荷兰 | D37: 4500146851 | E37: 4400908273 | F37: 4500146851-220 | H37: MB83-S002-9259 | I37: 混装（9259+9269各6PCS） | J37: 11862 | K37: 0 | L37: 6 | M37: =J37/L37 -> 1977 | N37: 45782 | O37: 45778 | Q37: PASS | T37: 5/6出 | U37: 10/9收到 | W37: 黑白书纸 for slime bag | AA37: 日期码格式：ZURU INC(BVI) 标准格式 日期：按实际生产日期 Packaging Info: 客版15L包装（收缩膜，收藏指南，15L 黑白书纸 for slime bag）+MA布标 Remark: 客人款号：3009949 1. 此单是子母件，贵司是母件工厂，需要负责组装入箱：一共2款，每款6pcs ，共12pcs 入一外箱。子件9259 工厂是兴信，子件9269 工厂是华康。子件CRD 是贵司CRD -7天，会按时/提前送货到贵司组装。 2. 订单总数量782,892 pcs, 共分为33个柜子，请按期完货. 3. 所有产品按符合欧洲标准走货，微塑料需合规。 4. 所有包装材料都不允许PVC, 请用PET代替 5. 此单需要4套产前样及4套大货样，样板请寄到罗湖办公室Eddie收。 | AB37: Becky Yang | AC37: 1.6548 | AD37: =AC37*M37 -> 3271.5396 | AE37: 94803-4.21 | AJ37: =J37 -> 11862 | AN37: =J37 -> 11862 | AQ37: =J37 -> 11862 | BB37: MA布标 | BC37: =J37/4 -> 2965.5 | BD37: =J37/4 -> 2965.5 | BE37: =J37/4 -> 2965.5 | BG37: =J37/4 -> 2965.5 | BJ37: =SUM(BC37:BI37) -> 11862 | BK37: =J37-BJ37 -> 0
A38: 45574 | B38: ACTION SERVICE & DISTRIBUTIE B.V. | C38: 荷兰 | D38: 4500146851 | E38: 4400341178 | F38: 4500146851-40 | H38: MB83-S002-9259 | I38: 混装（9259+9269各6PCS） | J38: 11862 | K38: 0 | L38: 6 | M38: =J38/L38 -> 1977 | N38: 45810 | O38: =N38-4 -> 45806 | Q38: PASS | T38: 6/12出 | U38: 10/9收到 | W38: 黑白书纸 for slime bag | AA38: 日期码格式：ZURU INC(BVI) 标准格式 日期：按实际生产日期 Packaging Info: 客版15L包装（收缩膜，收藏指南，15L 黑白书纸 for slime bag）+MA布标 Remark: 客人款号：3009949 1. 此单是子母件，贵司是母件工厂，需要负责组装入箱：一共2款，每款6pcs ，共12pcs 入一外箱。子件9259 工厂是兴信，子件9269 工厂是华康。子件CRD 是贵司CRD -7天，会按时/提前送货到贵司组装。 2. 订单总数量782,892 pcs, 共分为33个柜子，请按期完货. 3. 所有产品按符合欧洲标准走货，微塑料需合规。 4. 所有包装材料都不允许PVC, 请用PET代替 5. 此单需要4套产前样及4套大货样，样板请寄到罗湖办公室Eddie收。 | AB38: Becky Yang | AC38: 14.6964 | AD38: =AC38*M38 -> 29054.783 | AE38: 95517-7.1 | AJ38: =J38 -> 11862 | AN38: =J38 -> 11862 | AQ38: =J38 -> 11862 | BB38: MA布标 | BC38: =J38/4 -> 2965.5 | BD38: =J38/4 -> 2965.5 | BE38: =J38/4 -> 2965.5 | BG38: =J38/4 -> 2965.5 | BJ38: =SUM(BC38:BI38) -> 11862 | BK38: =J38-BJ38 -> 0
A39: 45574 | B39: ACTION SERVICE & DISTRIBUTIE B.V. | C39: 荷兰 | D39: 4500146851 | E39: 4400982509 | F39: 4500146851-320 | H39: MB83-S002-9259 | I39: 混装（9259+9269各6PCS） | J39: 11862 | K39: 0 | L39: 6 | M39: =J39/L39 -> 1977 | N39: 45818 | O39: 45814 | Q39: PASS | T39: 6/13出 | U39: 10/9收到 | W39: 黑白书纸 for slime bag | AA39: 日期码格式：ZURU INC(BVI) 标准格式 日期：按实际生产日期 Packaging Info: 客版15L包装（收缩膜，收藏指南，15L 黑白书纸 for slime bag）+MA布标 Remark: 客人款号：3009949 1. 此单是子母件，贵司是母件工厂，需要负责组装入箱：一共2款，每款6pcs ，共12pcs 入一外箱。子件9259 工厂是兴信，子件9269 工厂是华康。子件CRD 是贵司CRD -7天，会按时/提前送货到贵司组装。 2. 订单总数量782,892 pcs, 共分为33个柜子，请按期完货. 3. 所有产品按符合欧洲标准走货，微塑料需合规。 4. 所有包装材料都不允许PVC, 请用PET代替 5. 此单需要4套产前样及4套大货样，样板请寄到罗湖办公室Eddie收。 | AB39: Becky Yang | AC39: 1.6548 | AD39: =AC39*M39 -> 3271.5396 | AE39: 95579-7.7 | AJ39: =J39 -> 11862 | AN39: =J39 -> 11862 | AQ39: =J39 -> 11862 | BB39: MA布标 | BC39: =J39/4 -> 2965.5 | BD39: =J39/4 -> 2965.5 | BE39: =J39/4 -> 2965.5 | BG39: =J39/4 -> 2965.5 | BJ39: =SUM(BC39:BI39) -> 11862 | BK39: =J39-BJ39 -> 0
A40: 45574 | B40: ACTION SERVICE & DISTRIBUTIE B.V. | C40: 荷兰 | D40: 4500146851 | E40: 4400974042 | F40: 4500146851-290 | H40: MB83-S002-9259 | I40: 混装（9259+9269各6PCS） | J40: 11862 | K40: 0 | L40: 6 | M40: =J40/L40 -> 1977 | N40: 45824 | O40: 45820 | Q40: PASS | T40: 6/28出 | U40: 10/9收到 | W40: 黑白书纸 for slime bag | AA40: 日期码格式：ZURU INC(BVI) 标准格式 日期：按实际生产日期 Packaging Info: 客版15L包装（收缩膜，收藏指南，15L 黑白书纸 for slime bag）+MA布标 Remark: 客人款号：3009949 1. 此单是子母件，贵司是母件工厂，需要负责组装入箱：一共2款，每款6pcs ，共12pcs 入一外箱。子件9259 工厂是兴信，子件9269 工厂是华康。子件CRD 是贵司CRD -7天，会按时/提前送货到贵司组装。 2. 订单总数量782,892 pcs, 共分为33个柜子，请按期完货. 3. 所有产品按符合欧洲标准走货，微塑料需合规。 4. 所有包装材料都不允许PVC, 请用PET代替 5. 此单需要4套产前样及4套大货样，样板请寄到罗湖办公室Eddie收。 | AB40: Becky Yang | AC40: 1.6548 | AD40: =AC40*M40 -> 3271.5396 | AE40: 95647-7.15 | AJ40: =J40 -> 11862 | AN40: =J40 -> 11862 | AQ40: =J40 -> 11862 | BB40: MA布标 | BC40: =J40/4 -> 2965.5 | BD40: =J40/4 -> 2965.5 | BE40: =J40/4 -> 2965.5 | BG40: =J40/4 -> 2965.5 | BJ40: =SUM(BC40:BI40) -> 11862 | BK40: =J40-BJ40 -> 0
...

Sheet 9279
A1: ZURU Rainbocorn 猫蛋二代毛絨公仔生产排期表 #9279 | BL1: 无闪粉毛绒 | BS1: 有闪粉毛绒
A2: =#REF! -> #REF! | F2: 0 | I2: （黃色表示更改或增加） | L2: （蓝色表示已完货） | P2: （綠色表示調整貨期） | AH2: 收縮膜 | AN2: 收藏指南 | AQ2: 口水胶 | BL2: 1 | BM2: 9 | BN2: 10 | BO2: 10 | BP2: 10 | BQ2: 10 | BR2: 10 | BT2: 9 | BU2: 10 | BV2: 10 | BW2: 10 | BX2: 10 | BY2: 10
A3: 接单期 | B3: 第三方客户名称 | C3: 国家 | D3: PO号 | E3: 客户PO号 | F3: SKU号 | G3: 系统货号 | H3: 货号 | I3: 名称 | J3: 数量 | K3: 内箱装箱数量(pcs) | L3: 装箱数（PCS） | M3: 总箱数 | N3: 计划出货期 | O3: 计划验货期 | P3: 第三方验货期 | Q3: 驗貨結果 | R3: 送货情况 | S3: 欠数 | T3: 贴纸 | U3: 船期SO | V3: 箱唛资料(收到日期) | W3: 外箱贴纸 | X3: 贴纸AI(收到日期) | Y3: 贴纸订购与回货时间 | Z3: 客供物料 | AA3: 日期码 | AB3: 备注 | AC3: ZURU 跟单 | AD3: 单价USD | AE3: 金额USD | AF3: 發票號 | AG3: 是否入系统 | AH3: MA 1語收縮膜 A版本 | AI3: MA 1語收縮膜 B版本 | AJ3: MA 3语收缩膜 A版本 | AK3: MA 3语收缩膜 B版本 | AL3: EU-3L收缩膜 | AM3: 客版收縮膜 | AN3: MA 5语 收藏指南 A版本 | AO3: MA 5语 收藏指南 B版本 | AP3: 客版收藏指南 | AQ3: MA口水胶-A版本 | AR3: MA口水胶-B版本 | AS3: MA口水胶-无闪粉有硼 | AT3: MA口水胶-无闪粉无硼 | AU3: 客版无硼口水胶 | AV3: PDQ SQ1-S001-S002 IL | AW3: PDQ SQ1-S001 3L | AX3: SQ1-PDQ-1L-3L （共用） | AY3: PDQ TQ1-1L | AZ3: PDQ TQ1-3L | BA3: PDQ TQ1-1L-3L B版本 (通用） | BB3: PDQ TQ2-WM单 | BC3: PDQ TQ3-WM莫里森-A版本 | BD3: PDQ TQ3-WM莫里森-B版本 | BE3: PDQ TQ5-1L | BF3: PDQ TQ5-WMCA-2L | BG3: F 展示架 1L | BH3: 客办PDQ | BI3: 客办展示架 | BJ3: 无闪粉毛绒 | BK3: 布標 | BL3: 布偶猫/Ragdoll cat | BM3: 美国猫/American Cat(A) | BN3: 孟加拉猫/Bengal cat（E) | BO3: 加菲猫EXOTIC CAT(G) | BP3: 花斑猫CALICO CAT(B) | BQ3: 黑猫BLKCK CAT(D) | BR3: 粉色猫/Chinchilla cat(H) | BS3: 布偶猫/Ragdoll cat | BT3: 美国猫/American Cat(A) | BU3: 孟加拉猫/Bengal cat（E) | BV3: 加菲猫EXOTIC CAT(G) | BW3: 花斑猫CALICO CAT(B) | BX3: 黑猫BLKCK CAT(D) | BY3: 粉色猫/Chinchilla cat(H) | BZ3: 总数 | CA3: 相差 | CB3: 客户回复最晚货期 | CC3: 测试口水胶问题批次 | CD3: 送货情况 | CE3: 系统出单 | CF3: 贴纸情况
A4: 45454 | B4: ZURU | C4: 库有 | D4: ZMPO24455 | G4: 过渡 | H4: 9279SQ1-S001 | I4: 猫蛋二代 | J4: 50个空PDQ | K4: 0 | L4: 12 | M4: 0 | N4: 45462 | O4: 45458 | V4: 无 | X4: 无 | AB4: 大货最新版本/可打平包;备注： 收到样品订单后尽快安排 ，注意样板品质质量要求要高于大货品质要求 ，送货时必须要附带送货单(没有送货单和QC检验合格报告的仓库一律拒绝收货)，请知悉，谢谢！ | AG4: 过渡 | AX4: =50 -> 50
A5: 45594 | B5: TESCO CE | D5: MPO02973 | G5: 9279-S001 | H5: 9279-S001 | I5: 猫蛋二代 | J5: 2080 | K5: 0 | L5: 8 | M5: =J5/L5 -> 260 | N5: 45632 | O5: 45628 | Q5: PASS | U5: 12/6送外厂 | V5: 周转箱 | X5: 10/30收到CZ/HU/PL/SK警语贴纸 | AB5: Remark: 1. 此单出EU，需满足EU测试标准要求，不含微塑料。 2. 产品及包装需要印UKCA图标，包装需要有ZURU UK LTD/ZURU France地址信息，QC同事请核查，如有问题与跟单确认。 3.可用空白周转箱 4. 如含硼的话， 需用低硼版本(小于300ppm),硼含量需要符合欧洲标准,否则客人会退货有罚款产生 5. 子件送泰亨组装 9279：最新版MA 1L UPC收缩膜+一张CZ/HU/PL/SK警语贴纸 | AC5: Eddie Huang | AD5: 2.0411 | AE5: =J5*AD5 -> 4245.488 | AF5: 94204-2.10 | AI5: =J5 -> 2080 | AO5: =J5 -> 2080 | AS5: =J5 -> 2080 | BK5: MA布标 | BL5: =J5/60*1 -> 34.666667 | BM5: =J5/60*9 -> 312 | BN5: =J5/60*10 -> 346.66667 | BO5: =J5/60*10 -> 346.66667 | BP5: =J5/60*10 -> 346.66667 | BQ5: =J5/60*10 -> 346.66667 | BR5: =J5/60*10 -> 346.66667 | BZ5: =SUM(BL5:BY5) -> 2080 | CA5: =J5-BZ5 -> 0
A6: 45597 | B6: ARGOS LIMITED | C6: 英国 | D6: 4500149875 | E6: PO#361490-SKU #2259433 | F6: 4500149875-10 | G6: 9279-S001 | H6: 9279-S001 | I6: 猫蛋二代 | J6: 1512 | K6: 0 | L6: 24 | M6: =J6/L6 -> 63 | N6: 45644 | O6: 45640 | Q6: PASS | U6: 12/18出 | V6: 11/5收到 | X6: 11/6收到客人白色Cat.label | AB6: 日期码格式：ZURU INC(BVI) 标准格式 日期：按实际生产日期 Packaging Info: -MA -1L 包装+客人白色Cat.label 1张覆盖ZURU条码 -注意Cat.label (要求易撕类贴纸，但是粘性不能过低），同时此贴纸每个订单都是不相同的(会显示客户对应的订单号），切勿翻旧订单购买，该贴纸由工厂自行 购买。 -订单对应客户2个PO号 ，备注有显示 ，注意分开做货/验货/装柜 ，混装有罚款。 Remark: *MA包装按最新版本安排即可 *包装日期码按ZURU格式即可，请确保不迟于外箱日期码，可等于或者早于外箱日期码，必须为法定工作日。 *外箱尺寸任何一条边长度超过75cm或者每箱重量超过10KG,需要在外箱上加三脚架符号，有问题请与ZURU跟单同事核实。 *订单必须经过ZURU QC验货并且通过后方可出货。 *订单出英国，请注意检查产品及包装应带UKCA图标，包装显示ZURU UK LTD信息，QC同事请查核，如有问题与跟单确认。 *条码扫描会显示客户7位数产品号 ，忽略订单显示的MA条码 *所有产品按符合欧洲标准走货，需要是不含微塑料版本 。 *涉及到硼的，请使用低硼版本 *客户不接受PVC材质包装 | AC6: Zoe Chen | AD6: 2.1295 | AE6: =J6*AD6 -> 3219.804 | AF6: 88854-1.3 | AI6: =J6 -> 1512 | AO6: =J6 -> 1512 | AS6: =J6 -> 1512 | BK6: MA布标 | BL6: =J6/60*1 -> 25.2 | BM6: =J6/60*9 -> 226.8 | BN6: =J6/60*10 -> 252 | BO6: =J6/60*10 -> 252 | BP6: =J6/60*10 -> 252 | BQ6: =J6/60*10 -> 252 | BR6: =J6/60*10 -> 252 | BZ6: =SUM(BL6:BY6) -> 1512 | CA6: =J6-BZ6 -> 0
A7: 45604 | B7: Inventive Toys | C7: 俄罗斯联邦 | D7: 4500150797 | F7: 4500150797-30 | G7: 9279-S001 | H7: 9279-S001 | I7: 猫蛋二代 | J7: 5040 | K7: 0 | L7: 24 | M7: =J7/L7 -> 210 | N7: 45649 | O7: 45645 | Q7: PASS | U7: 1/3出 | V7: 11/26收到 | X7: 12/9-进口商贴纸+ EAN 条码贴纸 | AA7: 外包装/外箱不要打ZURU标准日期码 | AB7: 日期码格式：外包装/外箱不要打ZURU标准日期码 日期： Packaging Info: 注意 ：外包装 (指: 收缩膜/彩卡/铝箔袋/挂卡/PDQ) /外箱不要打ZURU标准日期码！胶件可以打日期码。 外包装（包括收缩膜/彩卡/PDQ）都不能含Instagram and facebook logo等社交logo; 1L MA 收缩膜+ 进口商贴纸； MA PDQ+ EAN 条码贴纸 ， MA 指南/说明书（如有） Remark: 标准配比 ； | AC7: Ann Zhang | AD7: 2.0623 | AE7: =J7*AD7 -> 10393.992 | AF7: 94064-1.16 | AI7: =J7 -> 5040 | AO7: =J7 -> 5040 | AS7: =J7 -> 5040 | BK7: MA布标 | BL7: =J7/60*1 -> 84 | BM7: =J7/60*9 -> 756 | BN7: =J7/60*10 -> 840 | BO7: =J7/60*10 -> 840 | BP7: =J7/60*10 -> 840 | BQ7: =J7/60*10 -> 840 | BR7: =J7/60*10 -> 840 | BZ7: =SUM(BL7:BY7) -> 5040 | CA7: =J7-BZ7 -> 0
A8: 45604 | B8: Inventive Toys | C8: 俄罗斯联邦 | D8: 4500150797 | F8: 4500150797-80 | G8: 9279SQ1-S001-1L | H8: 9279SQ1-S001 | I8: 猫蛋二代 | J8: 2400 | K8: 0 | L8: 12 | M8: =J8/L8 -> 200 | N8: 45649 | O8: 45645 | Q8: PASS | U8: 1/3出 | V8: 11/26收到 | X8: 12/9-进口商贴纸+ EAN 条码贴纸 | AA8: 外包装/外箱不要打ZURU标准日期码 | AB8: 日期码格式：外包装/外箱不要打ZURU标准日期码 日期： Packaging Info: 注意 ：外包装 (指: 收缩膜/彩卡/铝箔袋/挂卡/PDQ) /外箱不要打ZURU标准日期码！胶件可以打日期码。 外包装（包括收缩膜/彩卡/PDQ）都不能含Instagram and facebook logo等社交logo; 1L MA 收缩膜+ 进口商贴纸； MA PDQ+ EAN 条码贴纸 ， MA 指南/说明书（如有） Remark: 标准配比 ； | AC8: Ann Zhang | AD8: 2.2044 | AE8: =J8*AD8 -> 5290.56 | AF8: 94064-1.16 | AI8: =J8 -> 2400 | AO8: =J8 -> 2400 | AS8: =J8 -> 2400 | AX8: =J8/6 -> 400 | BK8: MA布标 | BL8: =J8/60*1 -> 40 | BM8: =J8/60*9 -> 360 | BN8: =J8/60*10 -> 400 | BO8: =J8/60*10 -> 400 | BP8: =J8/60*10 -> 400 | BQ8: =J8/60*10 -> 400 | BR8: =J8/60*10 -> 400 | BZ8: =SUM(BL8:BY8) -> 2400 | CA8: =J8-BZ8 -> 0
A9: 45604 | B9: AMAZON.COM.DEDC,LLC | C9: 美国 | D9: 4500150761 | E9: 647ZE1UJ | F9: 4500150761-70 | G9: 9279G-S001 | H9: 9279G-S001 | I9: 猫蛋二代 | J9: 144 | K9: 0 | L9: 12 | M9: =J9/L9 -> 12 | N9: 45650 | O9: 45646 | Q9: PASS | U9: 12/30出 | V9: 11/8收到 | X9: UPC贴纸翻4500097545 | Z9: 12/2-外箱贴纸 | AB9: 日期码格式：ZURU INC(BVI) 标准格式 日期：按实际生产日期 Packaging Info: #9279：MA 1L 加UPC贴纸, UPC贴纸图稿跟返单4500097545.9279G: 193052054753. Remark: 1. Amazon FOB订单，出口US。 2. 日期码使用ZURU标准版本。 3. 如果大货有要求入邮包盒，则对应的邮包盒上面要打上日期码。 4. 箱尺寸要求：外箱最长边不能超过25" （超过了，case pack只能为1），不符合要求的大货，一律不接受。 5. 外箱箱唛要求： ①外箱正面印ZURU Logo+SSCC Label（客供贴纸，由跟单订购)。关于 SSCC Label 请注意： SSCC Label 显示的是客人自己的item#。每一张SSCC label 都是唯一且有不同流水及条码的，没有损耗，绝对不可贴错 。如果贴错或损坏任何一张，都会导致全 部都错，千万要注意！ SSCC Label 必须贴在外箱正面的正中间位置（贴一面即可），并且贴纸离外箱边距必须至少3cm(可以覆盖Logo<(>&<)>箱唛)，否则会影响到客户那边仓库的扫描识 别。 ②外箱侧面印item#（订单上显示的SKU#)+carton size(以工厂实际尺寸为准,单位: inch) +MADE IN CHINA,日期使用ZURU 标准版本。 6. 装柜要求：按照客户PO# 装柜/箱号顺序装柜，跟单会提前给到装柜计划。 在大货生产/仓库存放时，请留意该装柜要求，以便装柜时不混乱（避免装错/装漏/找不到货号等）。 | AC9: Kelly Shen | AD9: 2.139 | AE9: =J9*AD9 -> 308.016 | AF9: 88846-1.2 | AI9: =J9 -> 144 | AO9: =J9 -> 144 | AS9: =J9 -> 144 | BK9: MA布标 | BO9: =J9 -> 144 | BZ9: =SUM(BL9:BY9) -> 144 | CA9: =J9-BZ9 -> 0
A10: 45595 | B10: AMAZON UK | C10: 英国 | D10: 4500149496 | E10: Amazon UK: 5J18RF7X | F10: 4500149496-10 | G10: 9279H-S001-3L | H10: 9279H-S001 | I10: 猫蛋二代 | J10: 912 | K10: 0 | L10: 12 | M10: =J10/L10 -> 76 | N10: 45651 | O10: 45647 | Q10: PASS | V10: 空白外箱（加印带Zuru字样的最新logo，除了邮包盒直接做外箱的产品） + SSCC LABEL一张, 无箱唛。MADE IN CHINA 外箱只印一正一侧 | X10: UPC#+IT sorting label翻4500124528+ES回收标翻单4500149035 | Z10: 11/29-外箱贴纸 | AB10: 日期码格式：ZURU INC(BVI) 标准格式 日期：按实际生产日期 Packaging Info: Amazon UK(9279H, 9283B, 9281A, 9298B, 71109B) 1. 9279H：9279H 12pcs/ctn, no inner,CHINCHILLA CAT; CTN Loading: 4W*3D=12pcs/CTN; MA 3L(23L warning)B收缩膜+ 2张贴纸(1张UPC#+IT sorting label <(>,<)>参考翻单PO#4500124528；1张ES回收标，参考翻单PO#4500149035)+MA 最新版布标+MA 5L(23L warning) C收藏指南+其他MA最新版包装； 6. 最迟验货不得晚于2024/12/26; Remark: 1.空白外箱（加印带Zuru字样的最新logo，除了邮包盒直接做外箱的产品） + SSCC LABEL一张, 无箱唛。 (SSCC LABEL贴在外箱正面的正中间，贴一面即可,贴纸离外箱边距必须至少3.2CM), SSCC贴纸由工厂直接跟勤得采购或者工厂自行采购，每一张SSCC Label都是唯一 且有不同流水及条码，且需要检查条码是否能正常扫描，另外，此贴纸印刷不可出现模糊，溢出及粘胶不牢易脱落等现象，如工厂不按此要求导致贴纸有任何问题产 生的罚款将由工厂承担一切责任 。’MADE IN CHINA 外箱只印一正一侧。 2.出往UK的产品+包装务必打上UKCA logo ，否则客人会退货且当地会有罚款。 3.订单必须经过ZURU QC验货并且通过后方可出货。 4.法国订单要求包装不使用矿物油，请按要求提供以下其中一份文件再出货 ，产品出到法国被相关部门抽检出现包装不符合此要求的，供应商需要为此承担责任， 故此请严格把关。 -油墨物质""由1 ~ 7个芳香环组成的MOAH""的包装检测报告，要求限值≤1.0%； -包装材料清单，包括包装油墨或物质的信息； -油墨制造商的证书； 5.每一批次出货只能有一个生产日期，不可多个生产日期混在同一批次出货；且邮包盒上必须统一加上日期码； 6.涉及到相关款式会有闪粉的或者微塑料的，请统一默认出无闪粉或者不含微塑料版本； 7.邮包盒及外箱封箱必须是工字型封箱方式； 8.5 Surprise or Mini Brands涉及包装是2个及2个以上的球入PVC桶包装时，单个球上若有UPC#或者EAN#，请用白色贴纸覆盖住； 9.箱唛资料按照给定的标准去做即可，无需发回我方再行审批(新标准将另行通知); | AC10: Crystal Chen | AD10: 2.139 | AE10: =J10*AD10 -> 1950.768 | AF10: 88934-1.8 | AK10: =J10 -> 912 | AO10: =J10 -> 912 | AS10: =J10 -> 912 | BK10: MA布标 | BR10: =J10-BS10 -> 912 | BZ10: =SUM(BL10:BY10) -> 912 | CA10: =J10-BZ10 -> 0
A11: 45623 | B11: TJX COMPANIES, INC | C11: 美国 | D11: 4500152570 | E11: Marshalls DC#881-384PCS , DC#884-288PCS , DC#886-408PCS , DC#887-360PCS , DC#888-360PCS | F11: 4500152570-30 | G11: 9279-S001 | H11: 9279-S001 | I11: 猫蛋二代 | J11: 1800 | K11: 0 | L11: 24 | M11: 75 | N11: 45651 | O11: 45647 | Q11: PASS | U11: 1/2出 | V11: 11/27收到 | X11: 无 | Z11: 12/6-价格贴纸 | AB11: 日期码格式：ZURU INC(BVI) 标准格式 日期：按实际生产日期 Packaging Info: MA UPC包装+价格贴纸，价格贴纸客供。 Remark: 1. 产品和包装上印刷tracking code信息，格式为ZURU常规格式。 2. 分5个DC出货，每款产品每个DC的箱唛资料不同。具体分DC数量，请参考后面行项目备注。 3. ZURU QC验货。 | AC11: Emily Wu | AD11: 2.1295 | AE11: 3833.1 | AF11: 94168-1.23 | AI11: 1800 | AO11: 1800 | AS11: =J11 -> 1800 | BK11: MA布标 | BM11: =J11/60*9 -> 270 | BN11: =J11/60*10 -> 300 | BO11: =J11/60*10 -> 300 | BP11: =J11/60*10 -> 300 | BQ11: =J11/60*10 -> 300 | BR11: =J11/60*10 -> 300 | BS11: =J11/60*1 -> 30 | BZ11: =SUM(BL11:BY11) -> 1800 | CA11: =J11-BZ11 -> 0
A12: 45601 | B12: DD’S DISCOUNTS | C12: 美国 | D12: 4500150187 | E12: 70054066 | F12: 4500150187-20 | G12: 9279-S001 | H12: 9279-S001 | I12: 猫蛋二代 | J12: 360 | K12: 0 | L12: 24 | M12: =J12/L12 -> 15 | N12: 45653 | O12: 45649 | Q12: PASS | U12: 1/7出 | V12: ROSS指定箱唛格式 | X12: 无 | Z12: 11/20-客供价格贴纸 | AB12: 日期码格式：ZURU INC(BVI) 标准格式 日期：按实际生产日期 Packaging Info: 1.ZURU MA UPC 现有版本包装 + 客供价格贴纸，出口美国 , 优先使用MA 1L 最新版本 。 Remark: 1.ZURU MA UPC 现有版本包装 + 客供价格贴纸，出口美国 , 优先使用MA 1L 最新版本 。 2.价格贴纸位于包装正面右下角，不挡住重要信息即可，可适当调整 ，价格贴纸由跟单提供。 3.标准日期码格式，产品和包装必须有日期码 。 4.同个产品同个货期不可出现不同的包装。 5. 跟单提供ROSS通用的箱唛模版，工厂按实际45 PO上客户PO/Item号/装箱数 提供箱唛排版来确认。 | AC12: Taylor Liao | AD12: 2.1341 | AE12: =J12*AD12 -> 768.276 | AF12: 88917-1.7 | AI12: =J12 -> 360 | AO12: =J12 -> 360 | AS12: =J12 -> 360 | BK12: MA布标 | BL12: =J12/60*1 -> 6 | BM12: =J12/60*9 -> 54 | BN12: =J12/60*10 -> 60 | BO12: =J12/60*10 -> 60 | BP12: =J12/60*10 -> 60 | BQ12: =J12/60*10 -> 60 | BR12: =J12/60*10 -> 60 | BZ12: =SUM(BL12:BY12) -> 360 | CA12: =J12-BZ12 -> 0
A13: 45608 | B13: CMS FAMOUS TOYS | C13: 加拿大 | D13: 4500151018 | E13: PO0000475 | F13: 4500151018-10 | G13: 9279SQ1-S002-NB | H13: 9279SQ1-S002-NB | I13: 猫蛋二代（无闪粉) | J13: 372 | K13: 0 | L13: 6 | M13: =J13/L13 -> 62 | N13: 45651 | O13: 45647 | Q13: PASS | U13: 收到SO | V13: 11/25收到 | X13: 11/19收到进口商贴纸 | AB13: 日期码格式： 标准格式 日期：按实际生产日期 Packaging Info:9279SQ1 MA 3L UPC包装 ,无硼版本。UPC号码193052050014 Remark: 出加拿大 每款产品都需要加进口商贴纸 Zuru验货.日期跟踪码：产品外包装及产品本身都必须有日期跟踪码，ZURU标准格式日期码 | AC13: Summer Mo | AD13: 2.1581 | AE13: =J13*AD13 -> 802.8132 | AF13: 88842-1.2 | AK13: =J13 -> 372 | AO13: =J13 -> 372 | AT13: =J13 -> 372 | AX13: =J13/6 -> 62 | BK13: MA布标 | BL13: =J13/60*1 -> 6.2 | BM13: =J13/60*9 -> 55.8 | BN13: =J13/60*10 -> 62 | BO13: =J13/60*10 -> 62 | BP13: =J13/60*10 -> 62 | BQ13: =J13/60*10 -> 62 | BR13: =J13/60*10 -> 62 | BZ13: =SUM(BL13:BY13) -> 372 | CA13: =J13-BZ13 -> 0
A14: 45587 | B14: ROSS PROCUREMENT.INC | C14: 美国 | D14: 4500147716 | E14: 60190663 | F14: 4500147716-80 | G14: 92114-S001 | H14: 92114-S001 | I14: 猫蛋二代(9279+9269)组装 | J14: 2796 | K14: 0 | L14: 12 | M14: =J14/L14 -> 233 | N14: 45653 | O14: 45649 | Q14: PASS | U14: 1/3出 | V14: 指定箱唛格式 | X14: 无 | Z14: 11/20-客供价格贴纸 | AA14: DG20241120 | AB14: 日期码格式： 标准格式 日期：按实际生产日期 Packaging Info: 1.ZURU MA UPC 现有版本包装 + 客供价格贴纸，出口美国 , 优先使用MA 1L 最新版本 。 Remark: 1.ZURU MA UPC 现有版本包装 + 客供价格贴纸，出口美国 , 优先使用MA 1L 最新版本 。 2.价格贴纸位于包装正面右下角，不挡住重要信息即可，可适当调整 ，价格贴纸由跟单提供。 3.标准日期码格式，产品和包装必须有日期码 。 4.同个产品同个货期不可出现不同的包装。 5. 跟单提供ROSS通用的箱唛模版，工厂按实际45 PO上客户PO/Item号/装箱数 提供箱唛排版来确认 | AC14: Sophia Zhou | AD14: 2.7175 | AE14: =J14*AD14 -> 7598.13 | AF14: 88881-1.6 | AG14: 已入 | AI14: =J14 -> 2796 | AO14: =J14 -> 2796 | AS14: =J14 -> 2796 | BH14: =J14 -> 2796 | BK14: MA布标 | BM14: =J14/60*9 -> 419.4 | BN14: =J14/60*10 -> 466 | BO14: =J14/60*10 -> 466 | BP14: =J14/60*10 -> 466 | BQ14: =J14/60*10 -> 466 | BR14: =J14/60*10 -> 466 | BS14: =J14/60*1 -> 46.6 | BZ14: =SUM(BL14:BY14) -> 2796 | CA14: =J14-BZ14 -> 0
A15: 45594 | B15: ALDI UK | C15: 英国 | D15: 4500149353 | F15: 4500149353-10 | G15: MFD154-S001 | H15: MFD154-S001 | I15: 猫蛋二代 | J15: 19242 | K15: 0 | L15: 18 | M15: =J15/L15 -> 1069 | N15: 45653 | O15: 45649 | P15: 1/8 第三方 | Q15: PASS | U15: 1/16出 | V15: 11/15收到 | X15: UPC条码翻4500117789 | AB15: 日期码格式：ZURU INC(BVI) 标准格式 日期：按实际生产日期 Packaging Info: 1.MFD154: 客版展示架 9269 Puppycorn 3W*3D*1H=9pcs ratio ：Husky：Dalmatian：Labrador：Chihuahua=1：1：1：1 9279 Kittycorn 3W*3D*2H=18pcs ratio ：同MA 7456 Mini Ice Age 3W*3D*1H=9pcs ratio ：同MA 74107 Mini Jurassic 3W*3D*1H=9pcs ratio ：同MA Total: 45pcs/FSDU 请务必按照上面列出的配比装箱，否则第三方验货会不合格不能安排出货； 2. 子件7456 和 74107 :泰亨客供带包装成品给兴信组装，子件9269: 华康客供带包装成品给兴信组装，由ZURU DCP下单给泰亨/华康，预计12月16日送货到兴信厂 ； 包装版本: 兴信子件①：9279 MA 1L B版收缩膜+一张符合客户要求的UPC条码(UPC#193052050014)贴在原条码上（原条码请打叉）+MA 收藏指南5L C版+MA B版布标+MA 5L C版 poop polybag, 贴纸翻PO#4500117789 华康子件②：9269 MA 1L 无闪粉版收缩膜+一张符合客户要求的UPC条码(UPC#193052043252)贴在原条码上（原条码请打叉）+MA 收藏指南5L B版+MA B版布标+MA 5L B版 poop polybag 泰亨子件③：7456 MA 1L C版收缩膜+ 一张符合客户要求的UPC条码(UPC#193052018083)贴在原条码上（原条码请打叉）+MA收藏指南D 5L版+MA 说明书 C 版本, 贴 纸翻PO#4500117789 泰亨子件④：74107 MA 1L B版收缩膜+一张符合客户要求的UPC条码(UPC#193052051363)贴在原条码上（原条码请打叉）+MA 说明书 B 版本+MA B bag, 贴纸翻PO#45 00117789 Remark: 1.展示架需要加塑料托盘出货，托盘尺寸600*400*120mm； 2.每座展示架一共需要5个价格牌贴在展示架上； 3.第三方验货时间: 12/31日，请多备料； 4.请在10/29日寄1套带包装的产前样板+1套完整assortment的散配件装在袋子里面，给客人审批了才能做大货，包装版本需要同大货一致，请按时寄出； 5.请在11/11提供一箱完整的展示架大货样给我们寄给英国，装在UK订单箱唛的箱子上，外面还需要另外再套一个箱子保护这箱大货样； 6.请在11/4提供1个空展示架+各5套带包装的样板+5整套所有assortment公仔，每一套assortment装在一个袋子中给客人审批了才能安排验货，所有样板需要同大货 一致，否则第三方验货会不合格，请务必按时寄出所有样板； 所有样板需要同大货一致，否则第三方验货会不合格，请务必按时寄出所有样板； 7.上下工字型封箱 8.整柜需要加白色安全网，具体数量以船务通知为准，一般会提前一个月通知，需要一并提供装柜图片给客人参考； 9.Stick a completed "Container Loading Plan form" at the container door（船务需要提醒装柜人员需要在柜门出贴一张container loading plan form) 10.产品及包装需要印UKCA图标，包装需要有ZURU UK LTD/ZURU France地址信息，QC同事请核查，如有问题与跟单确认。 11.需要符合欧洲标准不能含有闪粉和微塑料，否则不符合法规会有客诉产生 12.行项目10出英国，行项目20出爱尔兰，两者的箱唛不一样请不要混淆 | AC15: Sheba Ye | AD15: 54.8797 | AE15: =AD15*M15 -> 58666.399 | AF15: 94037-1.15 | AI15: =J15 -> 19242 | AO15: =J15 -> 19242 | AS15: =J15 -> 19242 | BI15: =J15/18 -> 1069 | BK15: MA布标 | BL15: =J15/60*1 -> 320.7 | BM15: =J15/60*9 -> 2886.3 | BN15: =J15/60*10 -> 3207 | BO15: =J15/60*10 -> 3207 | BP15: =J15/60*10 -> 3207 | BQ15: =J15/60*10 -> 3207 | BR15: =J15/60*10 -> 3207 | BZ15: =SUM(BL15:BY15) -> 19242 | CA15: =J15-BZ15 -> 0
A16: 45594 | B16: ALDI UK | C16: 英国 | D16: 4500149354 | F16: 4500149354-10 | G16: MFD154-S001 | H16: MFD154-S001 | I16: 猫蛋二代 | J16: 3240 | K16: 0 | L16: 18 | M16: =J16/L16 -> 180 | N16: 45653 | O16: 45649 | P16: 1/8 第三方 | Q16: PASS | U16: 1/13出 | V16: 11/15收到 | X16: UPC条码翻4500117789 | AB16: 日期码格式：ZURU INC(BVI) 标准格式 日期：按实际生产日期 Packaging Info: 1.MFD154: 客版展示架 9269 Puppycorn 3W*3D*1H=9pcs ratio ：Husky：Dalmatian：Labrador：Chihuahua=1：1：1：1 9279 Kittycorn 3W*3D*2H=18pcs ratio ：同MA 7456 Mini Ice Age 3W*3D*1H=9pcs ratio ：同MA 74107 Mini Jurassic 3W*3D*1H=9pcs ratio ：同MA Total: 45pcs/FSDU 请务必按照上面列出的配比装箱，否则第三方验货会不合格不能安排出货； 2. 子件7456 和 74107 :泰亨客供带包装成品给兴信组装，子件9269: 华康客供带包装成品给兴信组装，由ZURU DCP下单给泰亨/华康，预计12月16日送货到兴信厂 ； 包装版本: 兴信子件①：9279 MA 1L B版收缩膜+一张符合客户要求的UPC条码(UPC#193052050014)贴在原条码上（原条码请打叉）+MA 收藏指南5L C版+MA B版布标+MA 5L C版 poop polybag, 贴纸翻PO#4500117789 华康子件②：9269 MA 1L 无闪粉版收缩膜+一张符合客户要求的UPC条码(UPC#193052043252)贴在原条码上（原条码请打叉）+MA 收藏指南5L B版+MA B版布标+MA 5L B版 poop polybag 泰亨子件③：7456 MA 1L C版收缩膜+ 一张符合客户要求的UPC条码(UPC#193052018083)贴在原条码上（原条码请打叉）+MA收藏指南D 5L版+MA 说明书 C 版本, 贴 纸翻PO#4500117789 泰亨子件④：74107 MA 1L B版收缩膜+一张符合客户要求的UPC条码(UPC#193052051363)贴在原条码上（原条码请打叉）+MA 说明书 B 版本+MA B bag, 贴纸翻PO#45 00117789 Remark: 1.展示架需要加塑料托盘出货，托盘尺寸600*400*120mm； 2.每座展示架一共需要5个价格牌贴在展示架上； 3.第三方验货时间: 12/31日，请多备料； 4.请在10/29日寄1套带包装的产前样板+1套完整assortment的散配件装在袋子里面，给客人审批了才能做大货，包装版本需要同大货一致，请按时寄出； 5.请在11/11提供一箱完整的展示架大货样给我们寄给英国，装在UK订单箱唛的箱子上，外面还需要另外再套一个箱子保护这箱大货样； 6.请在11/4提供1个空展示架+各5套带包装的样板+5整套所有assortment公仔，每一套assortment装在一个袋子中给客人审批了才能安排验货，所有样板需要同大货 一致，否则第三方验货会不合格，请务必按时寄出所有样板； 所有样板需要同大货一致，否则第三方验货会不合格，请务必按时寄出所有样板； 7.上下工字型封箱 8.整柜需要加白色安全网，具体数量以船务通知为准，一般会提前一个月通知，需要一并提供装柜图片给客人参考； 9.Stick a completed "Container Loading Plan form" at the container door（船务需要提醒装柜人员需要在柜门出贴一张container loading plan form) 10.产品及包装需要印UKCA图标，包装需要有ZURU UK LTD/ZURU France地址信息，QC同事请核查，如有问题与跟单确认。 11.需要符合欧洲标准不能含有闪粉和微塑料，否则不符合法规会有客诉产生 12.出爱尔兰，两者的箱唛不一样请不要混淆 | AC16: Sheba Ye | AD16: 55.1281 | AE16: =AD16*M16 -> 9923.058 | AF16: 94004-1.13 | AI16: =J16 -> 3240 | AO16: =J16 -> 3240 | AS16: =J16 -> 3240 | BI16: =J16/18 -> 180 | BK16: MA布标 | BL16: =J16/60*1 -> 54 | BM16: =J16/60*9 -> 486 | BN16: =J16/60*10 -> 540 | BO16: =J16/60*10 -> 540 | BP16: =J16/60*10 -> 540 | BQ16: =J16/60*10 -> 540 | BR16: =J16/60*10 -> 540 | BZ16: =SUM(BL16:BY16) -> 3240 | CA16: =J16-BZ16 -> 0
A17: 45586 | B17: TJX COMPANIES, INC | C17: 美国 | D17: 4500147792 | E17: Marshalls DC#881-120PCS , DC#884-96PCS, DC#886-144PCS , DC#887-120PCS , DC#888-120PCS | F17: 4500147792-50 | G17: 92114-S001 | H17: 92114-S001 | I17: 猫蛋二代(9279+9269)组装 | J17: 600 | K17: 0 | L17: 12 | M17: =J17/L17 -> 50 | N17: 45656 | O17: 45652 | Q17: PASS | U17: 1/9出 | V17: 11/4收到 | X17: 无 | Z17: 12/6-客供价格贴纸 | AB17: 日期码格式：ZURU INC(BVI) 标准格式 日期：按实际生产日期 Packaging Info: MA UPC包装+价格贴纸，价格贴纸客供。 #92114 是combo pack, 混装了 9269（华康生产）+9279（兴信生产），在兴信组装 。 Remark: 1. 产品和包装上印刷tracking code信息，格式为ZURU常规格式。 2. 分5个DC出货，每款产品每个DC的箱唛资料不同。具体分DC数量，请参考后面行项目备注。 3. ZURU QC验货。 | AC17: Emily Wu | AD17: 2.8218 | AE17: =J17*AD17 -> 1693.08 | AF17: 94166-1.23 | AG17: 已入 | AI17: =J17 -> 600 | AO17: =J17 -> 600 | AS17: =J17 -> 600 | BH17: =J17 -> 600 | BK17: MA布标 | BM17: =J17/60*9 -> 90 | BN17: =J17/60*10 -> 100 | BO17: =J17/60*10 -> 100 | BP17: =J17/60*10 -> 100 | BQ17: =J17/60*10 -> 100 | BR17: =J17/60*10 -> 100 | BS17: =J17/60*1 -> 10 | BZ17: =SUM(BL17:BY17) -> 600 | CA17: =J17-BZ17 -> 0
A18: 45586 | B18: TJX COMPANIES, INC | C18: 美国 | D18: 4500147793 | E18: Marshalls DC#881-120PCS , DC#884-96PCS, DC#886-132PCS , DC#887-120PCS , DC#888-132PCS | F18: 4500147793-60 | G18: 92114-S001 | H18: 92114-S001 | I18: 猫蛋二代(9279+9269)组装 | J18: 600 | K18: 0 | L18: 12 | M18: =J18/L18 -> 50 | N18: 45656 | O18: 45652 | Q18: PASS | U18: 1/9出 | V18: 11/4收到 | X18: 无 | Z18: 12/6-客供价格贴纸 | AB18: 日期码格式：ZURU INC(BVI) 标准格式 日期：按实际生产日期 Packaging Info: MA UPC包装+价格贴纸，价格贴纸客供。 #92114 是combo pack, 混装了 9269（华康生产）+9279（兴信生产），在兴信组装 。 Remark: 1. 产品和包装上印刷tracking code信息，格式为ZURU常规格式。 2. 分5个DC出货，每款产品每个DC的箱唛资料不同。具体分DC数量，请参考后面行项目备注。 3. ZURU QC验货。 | AC18: Emily Wu | AD18: 2.8218 | AE18: =J18*AD18 -> 1693.08 | AF18: 94171-1.23 | AG18: 已入 | AI18: =J18 -> 600 | AO18: =J18 -> 600 | AS18: =J18 -> 600 | BH18: =J18 -> 600 | BK18: MA布标 | BM18: =J18/60*9 -> 90 | BN18: =J18/60*10 -> 100 | BO18: =J18/60*10 -> 100 | BP18: =J18/60*10 -> 100 | BQ18: =J18/60*10 -> 100 | BR18: =J18/60*10 -> 100 | BS18: =J18/60*1 -> 10 | BZ18: =SUM(BL18:BY18) -> 600 | CA18: =J18-BZ18 -> 0
A19: 45586 | B19: TJX COMPANIES, INC | C19: 美国 | D19: 4500147795 | E19: TJ MAXX DC#891-156PCS , DC#894-132PCS , DC#896-132PCS , DC#897-252PCS , DC#898-132PCS | F19: 4500147795-50 | G19: 92114-S001 | H19: 92114-S001 | I19: 猫蛋二代(9279+9269)组装 | J19: 804 | K19: 0 | L19: 12 | M19: =J19/L19 -> 67 | N19: 45656 | O19: 45652 | Q19: PASS | U19: 1/8出 | V19: 11/4收到 | X19: 无 | Z19: 12-6客供价格贴纸 | AB19: 日期码格式：ZURU INC(BVI) 标准格式 日期：按实际生产日期 Packaging Info: MA UPC包装+价格贴纸，价格贴纸客供。 #92114 是combo pack, 混装了 9269（华康生产）+9279（兴信生产），在兴信组装 。 Remark: 1. 产品和包装上印刷tracking code信息，格式为ZURU常规格式。 2. 分5个DC出货，每款产品每个DC的箱唛资料不同。具体分DC数量，请参考后面行项目备注。 3. ZURU QC验货。 | AC19: Emily Wu | AD19: 2.8218 | AE19: =J19*AD19 -> 2268.7272 | AF19: 94175-1.23 | AG19: 已入 | AI19: =J19 -> 804 | AO19: =J19 -> 804 | AS19: =J19 -> 804 | BH19: =J19 -> 804 | BK19: MA布标 | BM19: =J19/60*9 -> 120.6 | BN19: =J19/60*10 -> 134 | BO19: =J19/60*10 -> 134 | BP19: =J19/60*10 -> 134 | BQ19: =J19/60*10 -> 134 | BR19: =J19/60*10 -> 134 | BS19: =J19/60*1 -> 13.4 | BZ19: =SUM(BL19:BY19) -> 804 | CA19: =J19-BZ19 -> 0
A20: 45586 | B20: TJX COMPANIES, INC | C20: 美国 | D20: 4500147796 | E20: TJ MAXX DC#891-168PCS , DC#894-144PCS , DC#896-120PCS , DC#897-240PCS , DC#898-120PCS | F20: 4500147796-60 | G20: 92114-S001 | H20: 92114-S001 | I20: 猫蛋二代(9279+9269)组装 | J20: 804 | K20: 0 | L20: 12 | M20: =J20/L20 -> 67 | N20: 45656 | O20: 45652 | Q20: PASS | U20: 1/8出 | V20: 11/4收到 | X20: 无 | Z20: 12-6客供价格贴纸 | AB20: 日期码格式：ZURU INC(BVI) 标准格式 日期：按实际生产日期 Packaging Info: MA UPC包装+价格贴纸，价格贴纸客供。 #92114 是combo pack, 混装了 9269（华康生产）+9279（兴信生产），在兴信组装 。 Remark: 1. 产品和包装上印刷tracking code信息，格式为ZURU常规格式。 2. 分5个DC出货，每款产品每个DC的箱唛资料不同。具体分DC数量，请参考后面行项目备注。 3. ZURU QC验货。 | AC20: Emily Wu | AD20: 2.8218 | AE20: =J20*AD20 -> 2268.7272 | AF20: 94170-1.23 | AG20: 已入 | AI20: =J20 -> 804 | AO20: =J20 -> 804 | AS20: =J20 -> 804 | BH20: =J20 -> 804 | BK20: MA布标 | BM20: =J20/60*9 -> 120.6 | BN20: =J20/60*10 -> 134 | BO20: =J20/60*10 -> 134 | BP20: =J20/60*10 -> 134 | BQ20: =J20/60*10 -> 134 | BR20: =J20/60*10 -> 134 | BS20: =J20/60*1 -> 13.4 | BZ20: =SUM(BL20:BY20) -> 804 | CA20: =J20-BZ20 -> 0
A21: 45622 | B21: I-VISION TOYS.INC | C21: 韩国 | D21: 4500152350 | E21: IVI-1114EK | F21: 4500152350-10 | G21: 9279SQ1-S001-1L-NB-1 | H21: 9279SQ1-S001-NB | I21: 猫蛋二代 | J21: 5340 | K21: 0 | L21: 12 | M21: =J21/L21 -> 445 | N21: 45656 | O21: 45652 | Q21: PASS | U21: 1/3出 | V21: 箱唛翻单4500144362 | X21: 11/26-韩语贴纸（新稿） + 蛋壳底部彩色圆贴翻4500121660 | AA21: 客版收藏指南（翻单4500144362） | AB21: 日期码格式：ZURU INC(BVI) 标准格式 日期：按实际生产日期 Tracking Code: Packaging Info: （1）9279SQ1的口水胶必须出无硼，无MIT 版本。产品需符合韩国KC测试标准。 （2）9279SQ1: MA PKG(优先1L）+1张韩语贴纸（新稿） + 蛋壳底部按客户要求需加1张彩色圆贴（翻单4500121660），箱唛翻单4500144362；客版收藏指南（翻单4 500144362） Remark: 由于韩国法律法规要求，吸塑需PET材质，产品需符合韩国KC测试标准。 9279SQ1:9279SQ1的口水胶必须出无硼，无MIT 版本 | AC21: Doris Shou | AD21: 2.1849 | AE21: =J21*AD21 -> 11667.366 | AF21: 88826-1.2 | AI21: 5340 | AP21: =J21 -> 5340 | AT21: =J21 -> 5340 | AX21: =J21/6 -> 890 | BK21: MA布标 | BL21: =J21/60*1 -> 89 | BM21: =J21/60*9 -> 801 | BN21: =J21/60*10 -> 890 | BO21: =J21/60*10 -> 890 | BP21: =J21/60*10 -> 890 | BQ21: =J21/60*10 -> 890 | BR21: =J21/60*10 -> 890 | BZ21: =SUM(BL21:BY21) -> 5340 | CA21: =J21-BZ21 -> 0
A22: 45586 | B22: TJX COMPANIES, INC | C22: 美国 | D22: 4500147798 | E22: TJ MAXX DC#891-156PCS , DC#894-132PCS , DC#896-132PCS , DC#897-252PCS , DC#898-132PCS | F22: 4500147798-50 | G22: 92114-S001 | H22: 92114-S001 | I22: 猫蛋二代(9279+9269)组装 | J22: 804 | K22: 0 | L22: 12 | M22: =J22/L22 -> 67 | N22: 45657 | O22: 45653 | Q22: PASS | U22: 1/8出 | V22: 11/4收到 | X22: 无 | Z22: 12-6客供价格贴纸 | AB22: 日期码格式：ZURU INC(BVI) 标准格式 日期：按实际生产日期 Packaging Info: MA UPC包装+价格贴纸，价格贴纸客供。 #92114 是combo pack, 混装了 9269（华康生产）+9279（兴信生产），在兴信组装 。 Remark: 1. 产品和包装上印刷tracking code信息，格式为ZURU常规格式。 2. 分5个DC出货，每款产品每个DC的箱唛资料不同。具体分DC数量，请参考后面行项目备注。 3. ZURU QC验货。 | AC22: Emily Wu | AD22: 2.8218 | AE22: =J22*AD22 -> 2268.7272 | AF22: 94174-1.23 | AG22: 已入 | AI22: =J22 -> 804 | AO22: =J22 -> 804 | AS22: =J22 -> 804 | BH22: =J22 -> 804 | BK22: MA布标 | BM22: =J22/60*9 -> 120.6 | BN22: =J22/60*10 -> 134 | BO22: =J22/60*10 -> 134 | BP22: =J22/60*10 -> 134 | BQ22: =J22/60*10 -> 134 | BR22: =J22/60*10 -> 134 | BS22: =J22/60*1 -> 13.4 | BZ22: =SUM(BL22:BY22) -> 804 | CA22: =J22-BZ22 -> 0
A23: 45586 | B23: TJX COMPANIES, INC | C23: 美国 | D23: 4500147794 | E23: Marshalls DC#881-120PCS , DC#884-96PCS, DC#886-144PCS , DC#887-120PCS , DC#888-120PCS | F23: 4500147794-50 | G23: 92114-S001 | H23: 92114-S001 | I23: 猫蛋二代(9279+9269)组装 | J23: 600 | K23: 0 | L23: 12 | M23: =J23/L23 -> 50 | N23: 45657 | O23: 45653 | Q23: PASS | U23: 1/9出 | V23: 11/4收到 | X23: 无 | Z23: 12-6客供价格贴纸 | AB23: 日期码格式：ZURU INC(BVI) 标准格式 日期：按实际生产日期 Packaging Info: MA UPC包装+价格贴纸，价格贴纸客供。 #92114 是combo pack, 混装了 9269（华康生产）+9279（兴信生产），在兴信组装 。 Remark: 1. 产品和包装上印刷tracking code信息，格式为ZURU常规格式。 2. 分5个DC出货，每款产品每个DC的箱唛资料不同。具体分DC数量，请参考后面行项目备注。 3. ZURU QC验货。 | AC23: Emily Wu | AD23: 2.8218 | AE23: =J23*AD23 -> 1693.08 | AF23: 94176-1.23 | AG23: 已入 | AI23: =J23 -> 600 | AO23: =J23 -> 600 | AS23: =J23 -> 600 | BH23: =J23 -> 600 | BK23: MA布标 | BM23: =J23/60*9 -> 90 | BN23: =J23/60*10 -> 100 | BO23: =J23/60*10 -> 100 | BP23: =J23/60*10 -> 100 | BQ23: =J23/60*10 -> 100 | BR23: =J23/60*10 -> 100 | BS23: =J23/60*1 -> 10 | BZ23: =SUM(BL23:BY23) -> 600 | CA23: =J23-BZ23 -> 0
