Workbook

Sheet 77858厨房套装
A1: ZURU （77858 厨房套装）生产排期表
A3: 香港接单日期 | B3: 第三方客户名称 | C3: 走货国家 | D3: ZURU PO NO# | E3: 第三方客户 PO NO# | F3: SKU | G3: ITEM# | H3: 中文名 | I3: PO数量 (pcs) | J3: 内箱装箱数量(pcs) | K3: 外箱装箱数量(pcs) | L3: 总箱数 | M3: 客PO期 | N3: 验货期 | O3: 第三方验货期 | P3: 验货结果 | Q3: S/0船期 | R3: 箱唛确认 | S3: 箱唛资料(收到日期) | T3: 外箱贴纸 | U3: 客供贴纸AI(收到日期) | V3: 客供物料 | W3: 备注 | X3: ZURU 跟单 | Y3: 单价USD | Z3: 金额USD | AA3: 發票號 | AB3: 系统货号 | AC3: 是否入系统 | AD3: 系统出单 | AE3: 送货情况 | AF3: 欠数 | AG3: 贴纸 | AH3: 生产地 | AI3: MA 1L彩盒 | AJ3: 客版 3L彩盒 | AK3: 客版 3L彩盒（COSTCO AU/NA） | AL3: MA 3L彩盒 | AM3: 黑白警语说明书 | AN3: 客版黑白警语说明书 | AO3: 不带电WEE说明书 | AP3: 客版5L 收藏指南 | AQ3: 5L A版收藏指南 | AR3: 5L B版收藏指南 | AS3: 客版PDQ
A4: 45989 | B4: ZURU | C4: 中国 | D4: #ZPO2511013 | E4: 工程安排 | G4: 77858-S001 | H4: 厨房套装 | I4: 300 | J4: 0 | K4: 3 | L4: =I4/K4 -> 100 | M4: 45666 | N4: 45666 | P4: OK | S4: 空白箱 | T4: 无 | U4: 无 | W4: PP 样品：QA Testing Samples ，数量：6，地址：深圳市罗湖区东门南路1006号口岸大楼17B.Sally ,13418550560 备注2箱bulk pack需正确纸箱做运输测试+8套散件。 PP 样品：UL SZ Sample，数量：6，地址：Joyce Yao 电话：+ 86 755 8120 2849 优力胜邦质量检测（上海）有限公司深圳分公司 深圳市宝安区西乡街道航城大道一号中德欧产业园B 栋4 楼， 邮编：518126（寄出时请告知快递单号方便快速处理）包装完整成品 PP 样品：Internal Samples/Sample，数量：8/12,地址：深圳市罗湖区东门南路1006号口岸大楼A栋3楼，Shirley 18819441898 PP 样品：Signed Sample room/show room,数量：220/24,东莞市库有实业有限公司, 地址：东莞市清溪镇香芒西路213号 收件人：Jessica,电话：15999542773 PP 样品：Fast star sample,数量：24，地址：TBD （请留意保留好此PP 样板，跟单会补下PO 单扣减此数量），需空运到新西兰做上架试卖，务必保证外观功能ok | AB4: 77858-S001 | AC4: 已入
A5: 46021 | D5: ZMPO251171 | G5: 77858-S001 | H5: 厨房套装 | I5: 498 | J5: 0 | K5: 3 | L5: =I5/K5 -> 166 | M5: 46038 | N5: 46038 | P5: OK | S5: 46386 | T5: 无 | U5: 无 | W5: Remark:跟PP订单一起安排/大货标准箱装箱/箱唛请参照邮件附件 备注：收到样品订单后尽快安排 ，注意样板品质质量要求要高于大货品质要求 ，送货时必须要附带送货单(没有送货单和QC检验合格报告的仓库一律拒绝收货)，请知悉，谢谢！ | AB5: 77858-S001 | AC5: 已入 | AE5: 车间生产+包装
A6: 46045 | B6: ZURU NEW ZEALAND LIMITED | C6: 新西兰 | D6: 4500192110 | E6: 从PP中扣数 | F6: 4500192110-10 | G6: 77858-S001-FS | H6: 厨房套装 | I6: 24 | J6: 0 | K6: 3 | L6: =I6/K6 -> 8 | M6: 46052 | N6: 46048 | R6: 是 | S6: 46045 | T6: 有 | U6: 1/23黄色贴纸 | W6: 日期码格式：ZURU INC(BVI) 标准格式 日期：按实际生产日期 Packaging Info: Remark: NZ Fast Start Order, 从PP PO中扣数，需要更换为fast start专属UPC，外箱除常规箱唛外，还需要加贴一张黄色贴纸，印“fast start". | X6: Ivy Li | Y6: 8.5 | Z6: =I6*Y6 -> 204 | AB6: 77858-S001 | AC6: 已入 | AE6: 车间生产+包装
A7: 46059 | B7: TARGET US | C7: 美国 | D7: 4500190738 | E7: 10001661694-3891 | F7: 4500190738-30 | G7: 77858-S001 | H7: 厨房套装 | I7: 2442 | J7: 0 | K7: 3 | L7: =I7/K7 -> 814 | M7: 46119 | N7: 46118 | P7: OK | Q7: 46133 | R7: 是 | S7: 46081 | T7: 有 | U7: 3/25条码箱贴纸+2/10Event label | W7: 日期码格式：ZURU INC(BVI) 标准格式 日期：按实际生产日期 Packaging Info: 77858： 产品包装 MA 1L 彩盒，彩盒上的UPC显示193052100238; Remark: 77858： 1. 77858-S001-MINI BRANDS-MAGIC COOK KITCHEN PLAYSET-SERIES 1-WINDOW BOX,3PCS/CTN; 2. 产品包装 MA 1L 彩盒，彩盒上的UPC显示193052100238; 3. 外箱正唛左上角位置粘贴条码箱贴纸，每箱只贴一张，由ZURU订购。来料贴纸上显示的客户DPCI: 086-02-5654, UPC显示10193052100235; 4. 每个外箱正唛箱唛内容右侧需贴一张Event label，内容显示 7/19 TRANSITION TOYS Set Date 7/19/2026，工厂自行订购; 以上Items： 1. 产品和包装上均要印刷tracking code信息，格式为ZURU常规格式； 2. 需要我司QC验货之后才能安排出货 3. 出货方式： 货代自提 | X7: Holly Zheng | Y7: 5.9383 | Z7: =I7*Y7 -> 14501.329 | AB7: 77858-S001 | AC7: 已入 | AE7: 车间生产+包装 | AI7: =I7 -> 2442 | AM7: =I7 -> 2442 | AQ7: =I7 -> 2442
A8: 46055 | B8: SMYTHS TOYS HQ UC UK | C8: 英国 | D8: 4500192931 | E8: 4400537129 | F8: 4500192931-10 | G8: 77858-S001 | H8: 厨房套装 | I8: 3000 | J8: 0 | K8: 3 | L8: =I8/K8 -> 1000 | M8: 46122 | N8: 46120 | P8: OK | Q8: 46125 | R8: 是 | S8: 46083 | T8: 无 | U8: MA蔬菜盒子贴纸 | W8: 日期码格式：ZURU INC(BVI) 标准格式 日期：按实际生产日期 Packaging Info: "77858: 最新MA3L-23Lwarning EAN彩盒+MA蔬菜盒子贴纸+MA复合袋+MA23L说明书+MA5L收藏指南+B版WEEE声明(不带电池)走货欧洲通用30L说明书 EAN#4894680058729" "92146TQ1: MA3L-13Lwarning收缩膜+MA布标+MA贴纸+MA5L-19L收藏指南 Ratio: Cat:Raccoon:Deer:Tiger:Pigeon:Owl=1:1:1:1:1:1" 25282D: 最新MA3L+23L警告语 MA彩盒+一张新的UPC条码贴纸(25282D#193052063199; 翻PO#4500116913)+MA 9L说明书+WEEE声明通用30L-B版说明书（带电池） 25282A: 最新MA3L+23L警告语 MA彩盒+一张新的UPC条码贴纸(25282A#193052062611; 本单放稿)+MA 9L说明书+WEEE声明通用30L-B版说明书（带电池） 25282B: 最新MA3L+23L警告语 MA彩盒+一张新的UPC条码贴纸(25282B#193052063182; 翻PO#4500116913)+MA 9L说明书+WEEE声明通用30L-B版说明书（带电池） "15788B: 最新MA 5L UPC彩盒+MA布标 UPC#193052099600 *外箱四面需要贴一张限制上架日期贴纸(GLOBAL ONSHELF DATE:2026/7/9), 翻PO#4500192931*" "15788D: 最新MA 5L UPC彩盒+MA布标 UPC#193052099617 *外箱四面需要贴一张限制上架日期贴纸(GLOBAL ONSHELF DATE:2026/7/9), 翻PO#4500192931*" "15788G: 最新MA 5L UPC彩盒+MA布标 UPC#193052099631 *外箱四面需要贴一张限制上架日期贴纸(GLOBAL ONSHELF DATE:2026/7/9), 翻PO#4500192931*" "15788H: 最新MA 5L UPC彩盒+MA布标 UPC#193052099648 *外箱四面需要贴一张限制上架日期贴纸(GLOBAL ONSHELF DATE:2026/7/9), 翻PO#4500192931*" "15783UQ1: MA 5L PDQ+MA 5L UPC彩盒+MA 角色卡+MA通用纸袋+MA布标 UPC#193052099693 7 Assortments; Rare assortment 1/24, others even ratio *外箱四面需要贴一张限制上架日期贴纸(GLOBAL ONSHELF DATE:2026/6/14)*" Remark: Smyths 英国/爱尔兰 1. 请准时出货，推期会有罚款； 2. 所有产品按符合欧洲标准走货，需要是不含微塑料版本。 3.包装日期码按ZURU格式即可，请确保不迟于外箱日期码，可等于或者早于外箱日期码，必须为法定工作日，印刷前请先检查外箱日期码。 4.请注意检查产品及包装应带UKCA图标（14+产品除外），包装显示ZURU UK LTD/ZURU France地址信息，QC部门请查核，如有问题与跟单确认 5.电子产品需增加一张WEEE声明30L通用黑白说明书(不接受A版本，翻译有误)，区分带电池和不带电池出货版本, 如已做客版说明书可忽略此要求； 6.订单备注显示有分批的（不同仓库/订单号） ，注意分开做货出货，否则会导致罚款 。 7.做货前请先复核包装条码与订单是否一致再安排，对不上的需与ZURU跟单确认再安排。 | X8: Sherry Lu | Y8: 8.8 | Z8: =I8*Y8 -> 26400 | AB8: 77858-S001-1 | AC8: 已入 | AE8: 车间生产+包装 | AL8: =I8 -> 3000 | AM8: =I8 -> 3000 | AO8: 30L | AQ8: =I8 -> 3000
A9: 46055 | B9: SMYTHS TOYS EU HQ UC | C9: 德国 | D9: 4500192949 | E9: 4400537136 | F9: 4500192949-10 | G9: 77858-S001 | H9: 厨房套装 | I9: 840 | J9: 0 | K9: 3 | L9: =I9/K9 -> 280 | M9: 46122 | N9: 46120 | P9: OK | Q9: 46133 | R9: 是 | S9: 46083 | T9: 无 | U9: 2/10德语callout贴纸(本单放稿)+MA蔬菜盒子贴纸 | V9: 需要加字唛 | W9: 日期码格式：ZURU INC(BVI) 标准格式 日期：按实际生产日期 Packaging Info: "77858: 最新MA3L-23Lwarning EAN彩盒+1张德语callout贴纸(本单放稿)+MA蔬菜盒子贴纸+MA复合袋+MA23L说明书+MA5L收藏指南+B版WEEE声明(不带电池)走货欧洲 通用30L说明书 EAN#4894680058729" Remark: Smyths 德国 1. 请准时出货，推期会有罚款； 2. 所有产品按符合欧洲标准走货，需要是不含微塑料版本。 3. 所有电子产品身上需要加字唛，为ZURU FRANCE 地址 (如无电子产品，产品布标有此地址，或产品太小无法增加可忽略此信息)，新地址ZURU FRANCE.33 rue Pa ul Meurice 75020 Paris, France. 4. 电子产品需增加一张WEEE声明30L通用黑白说明书(不接受A版本，翻译有误)，区分带电池和不带电池出货版本, 如已做客版说明书可忽略此要求； 5.所有出往德国市场有关slime和带香味的都需要出无硼无香版本； 6.订单备注显示有分批的（不同仓库/订单号） ，注意分开做货出货，否则会导致罚款 。 7.包装日期码按ZURU格式即可，请确保不迟于外箱日期码，可等于或者早于外箱日期码，必须为法定工作日。 8.做货前请先复核包装条码与订单是否一致再安排，对不上的需与ZURU跟单确认再安排。 9.包装必须含法国Sorting Label信息，如没有，请提醒跟单提供贴纸资料。 | X9: Sherry Lu | Y9: 8.8 | Z9: =I9*Y9 -> 7392 | AB9: 77858-S001-1 | AC9: 已入 | AE9: 车间生产+包装 | AL9: =I9 -> 840 | AM9: =I9 -> 840 | AO9: 30L | AQ9: =I9 -> 840
A10: 46055 | B10: SMYTHS TOYS EU HQ UC | C10: 德国 | D10: 4500192949 | E10: 4400537151 | F10: 4500192949-20 | G10: 77858-S001 | H10: 厨房套装 | I10: 660 | J10: 0 | K10: 3 | L10: =I10/K10 -> 220 | M10: 46122 | N10: 46120 | P10: OK | Q10: 46133 | R10: 是 | S10: 46083 | T10: 无 | U10: 2/10德语callout贴纸(本单放稿)+MA蔬菜盒子贴纸 | V10: 需要加字唛 | W10: 日期码格式：ZURU INC(BVI) 标准格式 日期：按实际生产日期 Packaging Info: "77858: 最新MA3L-23Lwarning EAN彩盒+1张德语callout贴纸(本单放稿)+MA蔬菜盒子贴纸+MA复合袋+MA23L说明书+MA5L收藏指南+B版WEEE声明(不带电池)走货欧洲 通用30L说明书 EAN#4894680058729" Remark: Smyths 德国 1. 请准时出货，推期会有罚款； 2. 所有产品按符合欧洲标准走货，需要是不含微塑料版本。 3. 所有电子产品身上需要加字唛，为ZURU FRANCE 地址 (如无电子产品，产品布标有此地址，或产品太小无法增加可忽略此信息)，新地址ZURU FRANCE.33 rue Pa ul Meurice 75020 Paris, France. 4. 电子产品需增加一张WEEE声明30L通用黑白说明书(不接受A版本，翻译有误)，区分带电池和不带电池出货版本, 如已做客版说明书可忽略此要求； 5.所有出往德国市场有关slime和带香味的都需要出无硼无香版本； 6.订单备注显示有分批的（不同仓库/订单号） ，注意分开做货出货，否则会导致罚款 。 7.包装日期码按ZURU格式即可，请确保不迟于外箱日期码，可等于或者早于外箱日期码，必须为法定工作日。 8.做货前请先复核包装条码与订单是否一致再安排，对不上的需与ZURU跟单确认再安排。 9.包装必须含法国Sorting Label信息，如没有，请提醒跟单提供贴纸资料。 | X10: Sherry Lu | Y10: 8.8 | Z10: =I10*Y10 -> 5808 | AB10: 77858-S001-1 | AC10: 已入 | AE10: 车间生产+包装 | AL10: =I10 -> 660 | AM10: =I10 -> 660 | AO10: 30L | AQ10: =I10 -> 660
A11: 46080 | B11: THE ENTERTAINER | C11: 英国 | D11: 4500194581 | E11: FB14546 | F11: 4500194581-10 | G11: 77858-S001 | H11: 厨房套装 | I11: 975 | J11: 0 | K11: 3 | L11: =I11/K11 -> 325 | M11: 46122 | N11: 46120 | P11: OK | Q11: 46194 | R11: 自行排版 | S11: 46093 | T11: 无 | U11: 无 | W11: 日期码格式：ZURU INC(BVI) 标准格式 日期：按实际生产日期 Packaging Info: 77858-S001：MA A版1L UPC包装+C版29L不含电池出货版本WEEE说明书 Remark: "MA版本按工厂现有最新库存即可，订单出英国，请注意检查产品及包装应带UKCA以及CE图标，包装显示ZURU UK LTD信息，QC同事请查核，如有问题与跟单确认 *生产日期按实际（法定工作日），按ZURU标准格式即可 ，但是请知悉包装日期码需要早于或者等于外箱日期码 ，不能晚于外箱日期码 *请注意所有订单都需要经过ZURU QC验货并且通过后方可出货 *所有产品按符合欧洲标准走货，需要是不含微塑料版本 。 *涉及到硼的，如可选择情况下应使用低硼版本 （slime 类别低硼一般低于300ppm)，无选择的应与跟单复核再安排 。 *如果出运产品属于电子类产品需要在ZURU 包装基础上额外添加一张ZURU 标准30L通用WEEE 电子产品说明书,带电池出货的加带电池出货版本通用30L的说明书，不 带电池出货的产品用不带电池出货版本的说明书. *根据客人最新的包装要求，所有多个PDQ盒子(TQ,UQ,GQ）入1外箱的都需要在PDQ顶部右上角加上数量贴纸标明里面的数量。最小字体：36pts, 字体：Calibri（bo ld), 具体要求以及位置见文件. *订单对应客户PO号 ，备注有显示 ，注意分开做货/验货/装柜 ，混装有罚款。 * 大货样： 新款请在CRD前10天寄出每款2整套大货样到罗湖办公室7B Meyya Liu 收，翻单不用寄。" | X11: Meyya Liu | Y11: 10.2316 | Z11: =I11*Y11 -> 9975.81 | AB11: 77858-S001 | AC11: 已入 | AE11: 车间生产+包装 | AI11: =I11 -> 975 | AM11: =I11 -> 975 | AO11: 29L | AQ11: =I11 -> 975
A12: 46055 | B12: SMYTHS TOYS HQ UC IE | C12: 爱尔兰 | D12: 4500192938 | E12: 4400537132 | F12: 4500192938-10 | G12: 77858-S001 | H12: 厨房套装 | I12: 1002 | J12: 0 | K12: 3 | L12: =I12/K12 -> 334 | M12: 46122 | N12: 46120 | P12: OK | Q12: 46127 | R12: 是 | S12: 46083 | T12: 无 | U12: MA蔬菜盒子贴纸 | W12: 日期码格式：ZURU INC(BVI) 标准格式 日期：按实际生产日期 Packaging Info: "77858: 最新MA3L-23Lwarning EAN彩盒+MA蔬菜盒子贴纸+MA复合袋+MA23L说明书+MA5L收藏指南+B版WEEE声明(不带电池)走货欧洲通用30L说明书 EAN#4894680058729" Remark: Smyths 英国/爱尔兰 1. 请准时出货，推期会有罚款； 2. 所有产品按符合欧洲标准走货，需要是不含微塑料版本。 3.包装日期码按ZURU格式即可，请确保不迟于外箱日期码，可等于或者早于外箱日期码，必须为法定工作日，印刷前请先检查外箱日期码。 4.请注意检查产品及包装应带UKCA图标（14+产品除外），包装显示ZURU UK LTD/ZURU France地址信息，QC部门请查核，如有问题与跟单确认 5.电子产品需增加一张WEEE声明30L通用黑白说明书(不接受A版本，翻译有误)，区分带电池和不带电池出货版本, 如已做客版说明书可忽略此要求； 6.订单备注显示有分批的（不同仓库/订单号） ，注意分开做货出货，否则会导致罚款 。 7.做货前请先复核包装条码与订单是否一致再安排，对不上的需与ZURU跟单确认再安排。 | X12: Sherry Lu | Y12: 8.8 | Z12: =I12*Y12 -> 8817.6 | AB12: 77858-S001-1 | AC12: 已入 | AE12: 车间生产+包装 | AL12: =I12 -> 1002 | AM12: =I12 -> 1002 | AO12: 30L | AQ12: =I12 -> 1002
A13: 46055 | B13: SMYTHS TOYS EU HQ UNLIMITED COMPANY | C13: 法国 | D13: 4500192944 | E13: 4400536944 | F13: 4500192944-10 | G13: 77858-S001 | H13: 厨房套装 | I13: 561 | J13: 0 | K13: 3 | L13: =I13/K13 -> 187 | M13: 46122 | N13: 46120 | P13: OK | Q13: 46132 | R13: 是 | S13: 46083 | T13: 无 | U13: MA蔬菜盒子贴纸 | W13: 日期码格式：ZURU INC(BVI) 标准格式 日期：按实际生产日期 Packaging Info: "77858: 最新MA3L-23Lwarning EAN彩盒+MA蔬菜盒子贴纸+MA复合袋+MA23L说明书+MA5L收藏指南+B版WEEE声明(不带电池)走货欧洲通用30L说明书 EAN#4894680058729" "15788B: 最新MA 5L UPC彩盒+MA布标 UPC#193052099600 *外箱四面需要贴一张限制上架日期贴纸(GLOBAL ONSHELF DATE:2026/7/9), 翻PO#4500192931*" "15788D: 最新MA 5L UPC彩盒+MA布标 UPC#193052099617 *外箱四面需要贴一张限制上架日期贴纸(GLOBAL ONSHELF DATE:2026/7/9), 翻PO#4500192931*" "15788H: 最新MA 5L UPC彩盒+MA布标 UPC#193052099648 *外箱四面需要贴一张限制上架日期贴纸(GLOBAL ONSHELF DATE:2026/7/9), 翻PO#4500192931*" "15788G: 最新MA 5L UPC彩盒+MA布标 UPC#193052099631 *外箱四面需要贴一张限制上架日期贴纸(GLOBAL ONSHELF DATE:2026/7/9), 翻PO#4500192931*" "77711GQ2: 最新MA PDQ(优先3L)+MA-3L EAN收缩膜+1张法国sorting label贴纸(翻PO#4500182619) + MA-23L说明书 + MA-5-23L警语收藏指南 + MA-5L creative 说明书 EAN: 4894680043350" "77673TQ1: 最新MA 3L EAN配套包装+WEEE声明(带电池)走货欧洲通用30L-B版说明书 EAN: 4894680042773" Remark: Smyths 法国 1. 请准时出货，推期会有罚款； 2. 所有产品按符合欧洲标准走货，需要是不含微塑料版本。 3. 电子产品需增加一张WEEE声明30L通用黑白说明书(不接受A版本，翻译有误)，区分带电池和不带电池出货版本, 如已做客版说明书可忽略此要求； 4. 出口法国的产品, 法规规定禁止在包装和共公众用的印刷品中使用矿物油中含有的物质, 包装印刷油墨中含有的MOAH/MOSH的质量浓度不能超过1%, 否则出货到 法国被抽检出现问题, 供应商需要对此负责; 5.订单备注显示有分批的（不同仓库/订单号） ，注意分开做货出货，否则会导致罚款 。 6.包装日期码按ZURU格式即可，请确保不迟于外箱日期码，可等于或者早于外箱日期码，必须为法定工作日。 7.做货前请先复核包装条码与订单是否一致再安排，对不上的需与ZURU跟单确认再安排。 | X13: Sherry Lu | Y13: 8.8 | Z13: =I13*Y13 -> 4936.8 | AB13: 77858-S001-1 | AC13: 已入 | AE13: 车间生产+包装 | AL13: =I13 -> 561 | AM13: =I13 -> 561 | AO13: 30L | AQ13: =I13 -> 561
A14: 46055 | B14: SMYTHS TOYS EU HQ UNLIMITED COMPANY | C14: 法国 | D14: 4500192944 | E14: 4400536950 | F14: 4500192944-20 | G14: 77858-S001 | H14: 厨房套装 | I14: 240 | J14: 0 | K14: 3 | L14: =I14/K14 -> 80 | M14: 46122 | N14: 46120 | P14: OK | Q14: 46132 | R14: 是 | S14: 46083 | T14: 无 | U14: MA蔬菜盒子贴纸 | W14: 日期码格式：ZURU INC(BVI) 标准格式 日期：按实际生产日期 Packaging Info: "77858: 最新MA3L-23Lwarning EAN彩盒+MA蔬菜盒子贴纸+MA复合袋+MA23L说明书+MA5L收藏指南+B版WEEE声明(不带电池)走货欧洲通用30L说明书 EAN#4894680058729" "15788B: 最新MA 5L UPC彩盒+MA布标 UPC#193052099600 *外箱四面需要贴一张限制上架日期贴纸(GLOBAL ONSHELF DATE:2026/7/9), 翻PO#4500192931*" "15788D: 最新MA 5L UPC彩盒+MA布标 UPC#193052099617 *外箱四面需要贴一张限制上架日期贴纸(GLOBAL ONSHELF DATE:2026/7/9), 翻PO#4500192931*" "15788H: 最新MA 5L UPC彩盒+MA布标 UPC#193052099648 *外箱四面需要贴一张限制上架日期贴纸(GLOBAL ONSHELF DATE:2026/7/9), 翻PO#4500192931*" "15788G: 最新MA 5L UPC彩盒+MA布标 UPC#193052099631 *外箱四面需要贴一张限制上架日期贴纸(GLOBAL ONSHELF DATE:2026/7/9), 翻PO#4500192931*" "77711GQ2: 最新MA PDQ(优先3L)+MA-3L EAN收缩膜+1张法国sorting label贴纸(翻PO#4500182619) + MA-23L说明书 + MA-5-23L警语收藏指南 + MA-5L creative 说明书 EAN: 4894680043350" "77673TQ1: 最新MA 3L EAN配套包装+WEEE声明(带电池)走货欧洲通用30L-B版说明书 EAN: 4894680042773" Remark: Smyths 法国 1. 请准时出货，推期会有罚款； 2. 所有产品按符合欧洲标准走货，需要是不含微塑料版本。 3. 电子产品需增加一张WEEE声明30L通用黑白说明书(不接受A版本，翻译有误)，区分带电池和不带电池出货版本, 如已做客版说明书可忽略此要求； 4. 出口法国的产品, 法规规定禁止在包装和共公众用的印刷品中使用矿物油中含有的物质, 包装印刷油墨中含有的MOAH/MOSH的质量浓度不能超过1%, 否则出货到 法国被抽检出现问题, 供应商需要对此负责; 5.订单备注显示有分批的（不同仓库/订单号） ，注意分开做货出货，否则会导致罚款 。 6.包装日期码按ZURU格式即可，请确保不迟于外箱日期码，可等于或者早于外箱日期码，必须为法定工作日。 7.做货前请先复核包装条码与订单是否一致再安排，对不上的需与ZURU跟单确认再安排。 | X14: Sherry Lu | Y14: 8.8 | Z14: =I14*Y14 -> 2112 | AB14: 77858-S001-1 | AC14: 已入 | AE14: 车间生产+包装 | AL14: =I14 -> 240 | AM14: =I14 -> 240 | AO14: 30L | AQ14: =I14 -> 240
A15: 46064 | B15: LEKIA AB | C15: 瑞典 | D15: 4500193679 | F15: 4500193679-10 | G15: 77858-S001 | H15: 厨房套装 | I15: 2502 | J15: 0 | K15: 3 | L15: =I15/K15 -> 834 | M15: 46128 | N15: 46126 | P15: OK | Q15: 46133 | R15: 是 | S15: 46093 | T15: 无 | U15: 无 | W15: 日期码格式：ZURU INC(BVI) 标准格式 日期：按实际生产日期 Packaging Info: 1. 77858: MA A3L(23L warning) EAN版彩盒+MA A23L黑白电池说明书+MA A版收藏指南+WEEE_不带电池走货 _ 说明书欧洲EN+29L_C版 Remark: 1. 包装如含PVC,请改为PET 2. 产品/包装要求无硼无香； 3. 出欧洲，微塑料需合规。 4.带电池出货的产品所用到的电池需要符合欧洲电池新规(EU) 2023-1542 5.产品/包装不含PFAS and/or Bisfenol成分 6. 产品条码如下: 请先检查条码是否正确再安排做货，如有问题请告知: 77858-S001:4894680058729 | X15: Sheba Ye | Y15: 8.8 | Z15: =I15*Y15 -> 22017.6 | AB15: 77858-S001-1 | AC15: 已入 | AE15: 湖南提供半成品 | AL15: =I15 -> 2502 | AM15: =I15 -> 2502 | AO15: 29L | AQ15: =I15 -> 2502
A16: 46079 | B16: TARGET US | C16: 美国 | D16: 4500194297 | E16: 10001661693-3890 | F16: 4500194297-30 | G16: 77858-S001 | H16: 厨房套装 | I16: 3366 | J16: 0 | K16: 3 | L16: =I16/K16 -> 1122 | M16: 46132 | N16: 46129 | P16: OK | Q16: 46142 | R16: 是 | S16: 46101 | T16: 有 | U16: 3/31条码箱贴纸+2/26 Event label | W16: 日期码格式：ZURU INC(BVI) 标准格式 日期：按实际生产日期 Packaging Info: 77858：产品包装 MA 1L 彩盒； Remark: 77858： 1. 77858-S001-MINI BRANDS-MAGIC COOK KITCHEN PLAYSET-SERIES 1-WINDOW BOX,3PCS/CTN; 2. 产品包装 MA 1L 彩盒，彩盒上的UPC显示193052100238; 3. 外箱正唛左上角位置粘贴条码箱贴纸，每箱只贴一张，由ZURU订购。来料贴纸上显示的客户DPCI: 086-02-5654, UPC显示10193052100235; 4. 每个外箱正唛箱唛内容右侧需贴一张Event label，内容显示 7/19 TRANSITION TOYS Set Date 7/19/2026，工厂自行订购; 以上Items： 1. 产品和包装上均要印刷tracking code信息，格式为ZURU常规格式； 2. 需要我司QC验货之后才能安排出货 3. 出货方式： 货代自提 | X16: Holly Zheng | Y16: 5.28 | Z16: =I16*Y16 -> 17772.48 | AB16: 77858-S001 | AC16: 已入 | AE16: 湖南提供半成品 | AI16: =I16 -> 3366 | AM16: =I16 -> 3366 | AQ16: =I16 -> 3366
A17: 46087 | B17: WALMART INC. | C17: 美国 | D17: 4500195615 | E17: 0983717776 | F17: 4500195615-10 | G17: 77858-S002 | H17: 厨房套装 | I17: 500 | J17: 0 | K17: 2 | L17: =I17/K17 -> 250 | M17: 46135 | N17: 46133 | O17: 5/11第三方 4/23抽板 | P17: OK | Q17: 46174 | R17: 是 | S17: 46087 | T17: 无 | U17: 3/6RFID贴纸 | W17: 日期码格式：ZURU DGYYYYMMDD CHINA(日期避开周末和法定节假日即可） 日期：按实际生产日期 Packaging Info: 77858-S002 1. 包装要求： 77858：MA 1L A版 playset +MA 5L A版收藏指南+MA 23L A版说明书+MA A版纸袋+MA 贴纸 每pcs产品要贴一张RFID贴纸，RFID贴纸由ZURU提供，贴纸位置要严格按照客人签板 Remark: 77858-S002 1. 包装要求： 77858：MA 1L A版 playset +MA 5L A版收藏指南+MA 23L A版说明书+MA A版纸袋+MA 贴纸 每pcs产品要贴一张RFID贴纸，RFID贴纸由ZURU提供，贴纸位置要严格按照客人签板 2. 外箱印刷带条码的RFID箱唛：RFID紫色色带+WM Dept.图标+RFID图标+ITF-14条码，四面右下角印刷ZURU logo, ITFF条码只印刷在正唛一面，在加印的时候确保 条形码能扫描出来，外箱侧面任一角落加印："MADE IN CHINA" 字样； 3. 在产品上和包装上要有日期码、以及要有MADE IN CHINA和ZURU字样； 4. 产品如有扎带口要剪平，不能刮手。 5. 此单需要抽板和验货，抽板时间预计4/23，请多备料 6. 此单以loose carton出货，2pcs/CTN | X17: Maggie Xie | Y17: 6.5485 | Z17: =Y17*I17 -> 3274.25 | AB17: 77858-S002 | AC17: 已入 | AE17: 湖南提供半成品 | AI17: =I17 -> 500 | AM17: =I17 -> 500 | AQ17: =I17 -> 500
A18: 46079 | B18: TARGET US | C18: 美国 | D18: 4500194290 | E18: 10001708292-0 581 | F18: 4500194290-10 | G18: 77858-S001 | H18: 厨房套装 | I18: 375 | J18: 0 | K18: 3 | L18: =I18/K18 -> 125 | M18: 46136 | N18: 46132 | P18: OK | Q18: 46143 | R18: 是 | S18: 46105 | T18: 有 | U18: 4/2 条码箱贴纸 | W18: 日期码格式：ZURU INC(BVI) 标准格式 日期：按实际生产日期 Packaging Info: 77858：产品包装 MA 1L 彩盒； Remark: 77858： 1. 77858-S001-MINI BRANDS-MAGIC COOK KITCHEN PLAYSET-SERIES 1-WINDOW BOX,3PCS/CTN; 2. 产品包装 MA 1L 彩盒，彩盒上的UPC显示193052100238; 3. 外箱正唛左上角位置粘贴条码箱贴纸，每箱只贴一张，由ZURU订购。来料贴纸上显示的客户DPCI: 086-02-5654, UPC显示10193052100235; 以上Items： 1. 产品和包装上均要印刷tracking code信息，格式为ZURU常规格式； 2. 需要我司QC验货之后才能安排出货 3. 出货方式： 货代自提 | X18: Holly Zheng | Y18: 5.28 | Z18: =I18*Y18 -> 1980 | AB18: 77858-S001 | AC18: 已入 | AE18: 湖南提供半成品 | AI18: =I18 -> 375 | AM18: =I18 -> 375 | AQ18: =I18 -> 375
A19: 46079 | B19: TARGET US | C19: 美国 | D19: 4500194303 | E19: 10001661762-3 891 | F19: 4500194303-20 | G19: 77858-S001 | H19: 厨房套装 | I19: 1764 | J19: 0 | K19: 3 | L19: =I19/K19 -> 588 | M19: 46141 | N19: 46139 | P19: OK | Q19: 46153 | R19: 是 | S19: 46108 | T19: 有 | U19: 4/8条码箱贴纸 | W19: 日期码格式：ZURU INC(BVI) 标准格式 日期：按实际生产日期 Packaging Info: 77858：产品包装 MA 1L 彩盒； Remark: 77858： 1. 77858-S001-MINI BRANDS-MAGIC COOK KITCHEN PLAYSET-SERIES 1-WINDOW BOX,3PCS/CTN; 2. 产品包装 MA 1L 彩盒，彩盒上的UPC显示193052100238; 3. 外箱正唛左上角位置粘贴条码箱贴纸，每箱只贴一张，由ZURU订购。来料贴纸上显示的客户DPCI: 086-02-5654, UPC显示10193052100235; 以上Items： 1. 产品和包装上均要印刷tracking code信息，格式为ZURU常规格式； 2. 需要我司QC验货之后才能安排出货 3. 出货方式： 货代自提 | X19: Holly Zheng | Y19: 5.9555 | Z19: =I19*Y19 -> 10505.502 | AB19: 77858-S001 | AC19: 已入 | AE19: 湖南提供半成品 | AI19: =I19 -> 1764 | AM19: =I19 -> 1764 | AQ19: =I19 -> 1764
A20: 46080 | B20: MEIJER DISTRIBUTION, INC. | C20: 美国 | D20: 4500194442 | E20: 219072775 | F20: 4500194442-70 | G20: 77858-S001 | H20: 厨房套装 | I20: 570 | J20: 0 | K20: 3 | L20: =I20/K20 -> 190 | M20: 46142 | N20: 46140 | P20: OK | Q20: 46152 | R20: 是 | S20: 46098 | T20: 无 | U20: 无 | W20: 日期码格式：ZURU INC(BVI) 标准格式 日期： Packaging Info: 1. 通用PDQ, 产品MA UPC包装（优先1L）出美国 2. 客人指定箱唛排版 Remark: 出货前 Zuru QC 验货 | X20: Agnes Zheng | Y20: 5.28 | Z20: =I20*Y20 -> 3009.6 | AB20: 77858-S001 | AC20: 已入 | AE20: 湖南提供半成品 | AI20: =I20 -> 570 | AM20: =I20 -> 570 | AQ20: =I20 -> 570
A21: 46080 | B21: MEIJER DISTRIBUTION, INC. | C21: 美国 | D21: 4500194442 | E21: 219072771 | F21: 4500194442-80 | G21: 77858-S001 | H21: 厨房套装 | I21: 402 | J21: 0 | K21: 3 | L21: =I21/K21 -> 134 | M21: 46142 | N21: 46140 | P21: OK | Q21: 46152 | R21: 是 | S21: 46098 | T21: 无 | U21: 无 | W21: 日期码格式：ZURU INC(BVI) 标准格式 日期： Packaging Info: 1. 通用PDQ, 产品MA UPC包装（优先1L）出美国 2. 客人指定箱唛排版 Remark: 出货前 Zuru QC 验货 | X21: Agnes Zheng | Y21: 5.28 | Z21: =I21*Y21 -> 2122.56 | AB21: 77858-S001 | AC21: 已入 | AE21: 湖南提供半成品 | AI21: =I21 -> 402 | AM21: =I21 -> 402 | AQ21: =I21 -> 402
A22: 46093 | B22: WONDERLAND TOYS, INC. | C22: 美国 | D22: 4500196264 | E22: 5167 | F22: 4500196264-40 | G22: 77858-S001 | H22: 厨房套装 | I22: 144 | J22: 0 | K22: 3 | L22: =I22/K22 -> 48 | M22: 46142 | N22: 46140 | P22: OK | Q22: 46154 | R22: 是 | S22: 46098 | T22: 无 | U22: 无 | W22: 日期码格式：ZURU INC(BVI) 标准格式 日期：按实际生产日期 Packaging Info: 1. 出口美国，MA UPC 版本包装，优先1L。 5. Item 77858 UPC#193052100238. 出货不含电池。 Remark: 8. ZURU QC 验货即可。 | X22: Abby Mai,Lluvia Zeng | Y22: 6.139 | Z22: =I22*Y22 -> 884.016 | AB22: 77858-S001 | AC22: 已入 | AE22: 湖南提供半成品 | AI22: =I22 -> 144 | AM22: =I22 -> 144 | AQ22: =I22 -> 144
A23: 46094 | B23: KANDYTOYS LIMITED | C23: 英国 | D23: 4500196850 | E23: AS191225ZUR15 274 | F23: 4500196850-20 | G23: 77858-S001 | H23: 厨房套装 | I23: 750 | J23: 0 | K23: 3 | L23: =I23/K23 -> 250 | M23: 46147 | N23: 46143 | P23: OK | Q23: 46160 | R23: 是 | S23: 46115 | T23: 无 | U23: 无 | W23: 日期码格式：ZURU INC(BVI) 标准格式 日期：按实际生产日期 Packaging Info: 77858: MA UPC 1L+WEEE 30L B 不含电池说明书 Remark: 1.订单出英国，请注意检查产品及包装应带UKCA图标，包装需要显示ZURU UK LTD/ZURU France地址信息，QC同事请查核，如有问题与跟单确认。 2.生产日期按实际的（法定工作日），按ZURU标准格式即可 ，并需要在出货前提供每个产品外包上对应的生产日期明细 3.请注意所有订单都需要经过ZURU QC验货并且通过后方可出货 4.一个产品的条码请允许有一个，混款并每个款不同条码的需要加条码贴纸覆盖 5.外箱上的条码请确保清晰可扫描，有PDQ， 需要在PDQ底部贴一张带条码并可扫描的贴纸(ZURU 跟单提供模板）。 6.所有产品按符合欧洲标准走货，微塑料需合规并增加IFUD声明，含电池的需要增加WEEE说明书。 7.硼限值要低于300ppm | X23: Zoe Zhou | Y23: 9.9425 | Z23: =I23*Y23 -> 7456.875 | AB23: 77858-S001 | AC23: 已入 | AI23: =I23 -> 750 | AM23: =I23 -> 750 | AO23: 30L | AQ23: =I23 -> 750
A24: 46106 | B24: WALMART INC. | C24: 美国 | D24: 4500197934 | E24: 0983717796 | F24: 4500197934-20 | G24: 77858-S002 | H24: 厨房套装 | I24: 500 | J24: 0 | K24: 2 | L24: =I24/K24 -> 250 | M24: 46149 | N24: 46146 | O24: 46153 | P24: OK | Q24: 46160 | R24: 是 | S24: 翻4500195615 | T24: 无 | U24: 4/8RFID贴纸 | W24: 日期码格式：ZURU DGYYMMDD CHINA(日期避开周末和法定节假日即可） 日期：按实际生产日期 Packaging Info: 77843SLB-S001 1. 包装要求： 77858-S002 1. 包装要求： 77858：MA 1L A版 playset +MA 5L A版收藏指南+MA 23L A版说明书+MA A版纸袋+MA 贴纸 每pcs产品要贴一张RFID贴纸，RFID贴纸由ZURU提供，贴纸位置要严格按照客人签板 77858-S002 1. 包装要求： 77858：MA 1L A版 playset +MA 5L A版收藏指南+MA 23L A版说明书+MA A版纸袋+MA 贴纸 每pcs产品要贴一张RFID贴纸，RFID贴纸由ZURU提供，贴纸位置要严格按照客人签板 2. 外箱印刷带条码的RFID箱唛：RFID紫色色带+WM Dept.图标+RFID图标+ITF-14条码，四面右下角印刷ZURU logo, ITFF条码只印刷在正唛一面，在加印的时候确保 条形码能扫描出来，外箱侧面任一角落加印："MADE IN CHINA" 字样； 3. 在产品上和包装上要有日期码、以及要有MADE IN CHINA和ZURU字样； 4. 产品如有扎带口要剪平，不能刮手。 5. 此单需要验货，请多备料 6. 此单以loose carton出货，2pcs/CTN | X24: Maggie Xie | Y24: 6.5485 | Z24: =I24*Y24 -> 3274.25 | AB24: 77858-S002 | AC24: 已入 | AI24: =I24 -> 500 | AM24: =I24 -> 500 | AQ24: =I24 -> 500
A25: 46112 | B25: ZURU LLC | C25: 美国 | D25: 4500199495 | E25: 5200009500 | F25: 4500199495-10 | G25: 77858-S003-MB-MTS | H25: 厨房套装 | I25: 480 | J25: 0 | K25: 3 | L25: =I25/K25 -> 160 | M25: 46149 | N25: 46147 | P25: OK | Q25: 46157 | R25: 是 | S25: 46113 | T25: 无 | U25: 无 | V25: 邮包盒图稿翻单4500194000 | W25: 日期码格式：ZURU INC(BVI) 标准格式 日期：按实际生产日期 Packaging Info: #77858: STD 77858带MA包装入邮包盒，邮包盒图稿翻单4500194000。 Remark: 1.TikTok US订单。出口美国。外箱尺寸不能超过26*26*26" ，不符合要求的大货，一律不接受。 2.无第三方验货/测试要求。 3. 日期码使用ZURU标准版本。 4.如果大货有要求入邮包盒，则对应的邮包盒上面要打上日期码。 | X25: Kelly Shen | Y25: 7.3813 | Z25: =Y25*L25 -> 1181.008 | AB25: 77858-S003-MB | AC25: 已入 | AI25: =I25 -> 480 | AM25: =I25 -> 480 | AQ25: =I25 -> 480
A26: 46108 | B26: TARGET US | C26: 美国 | D26: 4500199055 | E26: 10001661761-3890 | F26: 4500199055-20 | G26: 77858-S001 | H26: 厨房套装 | I26: 2430 | J26: 0 | K26: 3 | L26: =I26/K26 -> 810 | M26: 46150 | N26: 46148 | P26: OK | Q26: 46163 | R26: 是 | S26: 46120 | T26: 有 | U26: 4/23条码箱贴纸 | W26: 日期码格式：ZURU INC(BVI) 标准格式 日期：按实际生产日期 Packaging Info: 77673TQ1：产品包装 客版收缩膜(C版)+客版收藏指南+MA说明书+ MA 1L PDQ；客版收缩膜(C版）翻单4500183607；客版收藏指南翻单4500174008； 77858：产品包装 MA 1L 彩盒； 77772GQ5：产品包装MA 1L 收缩膜+MA 5L 收藏指南+MA 23L 组装说明+客版PDQ；客版PDQ翻单4500189603； 77794UQ1：产品包装 MA 1L黑白警告语说明书+MA 1L 彩盒+MA 1L PDQ+锂电池标签纸 Remark: 77673TQ1： 1. 77673TQ1-S001-CC-MINI BRANDS-FILL THE FRIDGE PLAYSET-SERIES 1-SHRINK WRAP,4PCS/PDQ,4PCS/PDQ/CTN; 2. 产品包装 客版收缩膜(C版)+客版收藏指南+MA说明书+ MA 1L PDQ；客版收缩膜上的UPC显示193052079404；客版收缩膜(C版）翻单4500183607；客版收藏指南翻 单4500174008； 3. 外箱正唛左上角位置粘贴条码箱贴纸，每箱只贴一张，由ZURU订购。来料贴纸上显示的客户DPCI# 086-02-3468， UPC显示10193052079401; 77858： 1. 77858-S001-MINI BRANDS-MAGIC COOK KITCHEN PLAYSET-SERIES 1-WINDOW BOX,3PCS/CTN; 2. 产品包装 MA 1L 彩盒，彩盒上的UPC显示193052100238; 3. 外箱正唛左上角位置粘贴条码箱贴纸，每箱只贴一张，由ZURU订购。来料贴纸上显示的客户DPCI: 086-02-5654, UPC显示10193052100235; 77772GQ5： 1.77772GQ5-S001-MINI BRANDS-VINYL-SERIES 1-CAPSULE,WITH DEMO,25PCS/GRAVITY PDQ,25PCS/PDQ/CTN; 2.产品包装MA 1L 收缩膜+MA 5L 收藏指南+MA 23L 组装说明+客版PDQ；客版PDQ翻单4500189603；收缩膜上的UPC显示193052090065; 4 mini vinyls(1 Target US Exclusive),1 accessory; 3. 外箱正唛左上角位置粘贴条码箱贴纸，每箱只贴一张，由ZURU订购。来料贴纸上显示的客户DPCI# 086-02-8931, UPC显示10193052090062; 77794UQ1： 1.77794UQ1-S002-MINI BRANDS-VINYL-PLAYSET-SERIES 1-CUBE,8PCS/PDQ,8PCS/PDQ/CTN; 2. 产品包装 MA 1L黑白警告语说明书+MA 1L 彩盒+MA 1L PDQ+锂电池标签纸; 彩盒上的UPC显示193052090409; 3. 外箱正唛左上角位置粘贴条码箱贴纸，每箱只贴一张，由ZURU订购。来料贴纸上显示的客户DPCI# 086-02-4085, UPC显示10193052090406; 4. 带锂电池出货，需在外箱正面或者侧面合适位置上加贴一张贴锂电池标签纸，由工厂订购 以上Items： 1. 产品和包装上均要印刷tracking code信息，格式为ZURU常规格式； 2. 需要我司QC验货之后才能安排出货 3. 出货方式： 货代自提 | X26: Holly Zheng | Y26: 5.9383 | Z26: =I26*Y26 -> 14430.069 | AB26: 77858-S001 | AC26: 已入 | AI26: =I26 -> 2430 | AM26: =I26 -> 2430 | AQ26: =I26 -> 2430
A27: 46108 | B27: AMAZON EU SARL, NDL DEUTSCHLAND | C27: 西班牙 | D27: 4500198640 | E27: 53YR16IV | F27: 4500198640-100 | G27: 77858-S003-MB | H27: 厨房套装 | I27: 501 | J27: 0 | K27: 3 | L27: =I27/K27 -> 167 | M27: 46150 | N27: 46148 | P27: OK | Q27: 46159 | S27: 空白外箱（加印带Zuru字样的最新logo，除了邮包盒直接做外箱的产品） | T27: 有 | U27: 4/24条码箱贴纸 | V27: 客版邮包盒翻单4500192979 | W27: 日期码格式：ZURU INC(BVI) 标准格式 日期：按实际生产日期 Packaging Info: Amazon UK: 5TKIJIXX/3O77XWME/2EIMZ29W/1VCZUJZI/7N1D8FUG/5Z2UXPOL/5PNQ9H8L Amazon DE: 4EO3QWQS/3LFCI9MA/115AX8DW Amazon FR: 6VRKJU2V Amazon ES: 53YR16IV Amazon IT: 5D2ZS8EV Amazon UK(157114DG/157140/157143/15780ABD/15788G/71172/77878/92146BDG/92147E)/DE(157114G/15788BG/92146GH/92147E)/FR(92146G)/ES(157143/77858)/IT( 157140/157143/92146G) 10. 77858: 1pc 77858 playset into mailbox, 3mailboxes/ctn; Including magnets; 3PCS AA BATTERIES(NOT INCLUDED); MA 3L(23L warning EAN)A 透明PVC窗 彩盒+MA 23L warning A 电池黑白说明书+MA 5L A收藏指南+MA其它最新配套包装+客版邮包盒(参考Amazon US翻单PO#4500192979)+WEEE_不带电池走货 _ 说明书欧 洲EN+30L_B版 11.验货时间不迟于2026/5/11. 注意：77858需将邮包盒尺寸图<(>&<)>重量图放进验货报告； Remark: 1.空白外箱（加印带Zuru字样的最新logo，除了邮包盒直接做外箱的产品） + SSCC LABEL一张, 无箱唛，MADE IN CHINA 外箱只印一正一侧。箱唛资料按照给定的 标准去做即可，无需发回我方再行审批(新标准将另行通知)。 (SSCC LABEL竖贴在外箱正面的正中间，贴一面即可,贴纸离外箱边距必须至少3.2CM。如竖贴无法满足要求，则横贴。如横贴也无法满足要求，则竖贴，遮到ZURU lo go无影响), SSCC贴纸由工厂直接跟勤得采购或者工厂自行采购，每一张SSCC Label都是唯一且有不同流水及条码，且需要检查条码是否能正常扫描，另外，此贴纸 印刷不可出现模糊，溢出及粘胶不牢易脱落等现象，如工厂不按此要求导致贴纸有任何问题产生的罚款将由工厂承担一切责任 ,<(>,<)> 此要求只适用Amazon UK/DE /FR/ES/IT,不适用Amazon GPE，Amazon GPE无SSCC label, 但是有对应箱唛，需印刷到外箱 。 2.出往UK的产品+包装务必打上UKCA logo ，否则客人会退货且当地会有罚款。 3.订单必须经过ZURU QC验货或者工厂自检通过后方可出货，不涉及第三方验货。 4.法国订单要求包装不使用矿物油，请按要求提供以下其中一份文件再出货 ，产品出到法国被相关部门抽检出现包装不符合此要求的，供应商需要为此承担责任， 故此请严格把关。 -油墨物质""""由1 ~ 7个芳香环组成的MOAH""""的包装检测报告，要求限值≤1.0%； -包装材料清单，包括包装油墨或物质的信息； -油墨制造商的证书； 5.每一批次出货只能有一个生产日期，不可多个生产日期混在同一批次出货；且零售包装上必须统一加上日期码；外箱对于日期码没有硬性规定； 6.涉及到相关款式会有闪粉的或者微塑料的，请统一默认出无闪粉或者不含微塑料版本； 7.邮包盒及外箱封箱必须是工字型封箱方式； 8.5 Surprise or Mini Brands涉及包装是2个及2个以上的球入PVC桶包装时，单个球上若有UPC#或者EAN#，请用空白贴纸覆盖住，贴纸尺寸自行测量能覆盖原条码即 可； 9. 无论是工厂自检还是ZURU验货，验货报告中必须有产品6面图(正面/背面/左面/右面/顶部/底部，不带包装); 10. 按空海运鉴定报告的要求，只要带锂电池出货，都需要加贴UN贴纸； 11. 所有出往GAS市场(德国/奥地利/瑞士)的电子产品身上需要加字唛，为ZURU FRANCE 地址，需跟包装上的地址一致 (如无电子产品，产品布标有此地址，或产品 太小无法增加可忽略此信息。如产品无法加字唛，需让对应跟单提供产品贴纸资料); 12. 所有出往GAS德国 (瑞士，奥地利)。水弹枪系列必须使用EN71版本（电子和非电子水弹枪系列都需要符合); 护目镜需打日期码, 格式跟ZURU标准格式一样; 枪 身上增加ZURU FRANCE公司名和地址。使用贴纸和辐射上去都可以。如果有位置，最好增加ZURU Represented by: (此最好翻译德语，如果位置不允许，那么就只增 加ZURU法国和地址)。使用最新的EN71版包装和说明书）. | X27: Luna Lin | Y27: 12.65 | Z27: =Y27*I27 -> 6337.65 | AB27: 77858-S003-MB-1 | AC27: 已入 | AL27: =I27 -> 501 | AM27: =I27 -> 501 | AO27: 29L | AQ27: =I27 -> 501
A28: 46106 | B28: WALMART INC. | C28: 美国 | D28: 4500198118 | E28: 0983717761 | F28: 4500198118-20 | G28: 77858-S002 | H28: 厨房套装 | I28: 500 | J28: 0 | K28: 2 | L28: =I28/K28 -> 250 | M28: 46153 | N28: 46149 | O28: 46156 | P28: OK | Q28: 46174 | R28: 是 | S28: 翻4500195615 | T28: 无 | U28: 4/8RFID贴纸 | W28: 日期码格式：ZURU DGYYMMDD CHINA(日期避开周末和法定节假日即可） 日期：按实际生产日期 Packaging Info: 77843SLB-S001 1. 包装要求： 77858-S002 1. 包装要求： 77858：MA 1L A版 playset +MA 5L A版收藏指南+MA 23L A版说明书+MA A版纸袋+MA 贴纸 每pcs产品要贴一张RFID贴纸，RFID贴纸由ZURU提供，贴纸位置要严格按照客人签板 77858-S002 1. 包装要求： 77858：MA 1L A版 playset +MA 5L A版收藏指南+MA 23L A版说明书+MA A版纸袋+MA 贴纸 每pcs产品要贴一张RFID贴纸，RFID贴纸由ZURU提供，贴纸位置要严格按照客人签板 2. 外箱印刷带条码的RFID箱唛：RFID紫色色带+WM Dept.图标+RFID图标+ITF-14条码，四面右下角印刷ZURU logo, ITFF条码只印刷在正唛一面，在加印的时候确保 条形码能扫描出来，外箱侧面任一角落加印："MADE IN CHINA" 字样； 3. 在产品上和包装上要有日期码、以及要有MADE IN CHINA和ZURU字样； 4. 产品如有扎带口要剪平，不能刮手。 5. 此单需要验货，请多备料 6. 此单以loose carton出货，2pcs/CTN | X28: Maggie Xie | Y28: 6.5485 | Z28: =I28*Y28 -> 3274.25 | AB28: 77858-S002 | AC28: 已入 | AI28: =I28 -> 500 | AM28: =I28 -> 500 | AQ28: =I28 -> 500
A29: 46106 | B29: WALMART INC. | C29: 美国 | D29: 4500198126 | E29: 0983717783 | F29: 4500198126-20 | G29: 77858-S002 | H29: 厨房套装 | I29: 500 | J29: 0 | K29: 2 | L29: =I29/K29 -> 250 | M29: 46153 | N29: 46149 | O29: 46156 | P29: OK | Q29: 46163 | R29: 是 | S29: 翻4500195615 | T29: 无 | U29: 4/8RFID贴纸 | W29: 日期码格式：ZURU DGYYMMDD CHINA(日期避开周末和法定节假日即可） 日期：按实际生产日期 Packaging Info: 77843SLB-S001 1. 包装要求： 77858-S002 1. 包装要求： 77858：MA 1L A版 playset +MA 5L A版收藏指南+MA 23L A版说明书+MA A版纸袋+MA 贴纸 每pcs产品要贴一张RFID贴纸，RFID贴纸由ZURU提供，贴纸位置要严格按照客人签板 77858-S002 1. 包装要求： 77858：MA 1L A版 playset +MA 5L A版收藏指南+MA 23L A版说明书+MA A版纸袋+MA 贴纸 每pcs产品要贴一张RFID贴纸，RFID贴纸由ZURU提供，贴纸位置要严格按照客人签板 2. 外箱印刷带条码的RFID箱唛：RFID紫色色带+WM Dept.图标+RFID图标+ITF-14条码，四面右下角印刷ZURU logo, ITFF条码只印刷在正唛一面，在加印的时候确保 条形码能扫描出来，外箱侧面任一角落加印："MADE IN CHINA" 字样； 3. 在产品上和包装上要有日期码、以及要有MADE IN CHINA和ZURU字样； 4. 产品如有扎带口要剪平，不能刮手。 5. 此单需要验货，请多备料 6. 此单以loose carton出货，2pcs/CTN | X29: Maggie Xie | Y29: 6.5485 | Z29: =I29*Y29 -> 3274.25 | AB29: 77858-S002 | AC29: 已入 | AI29: =I29 -> 500 | AM29: =I29 -> 500 | AQ29: =I29 -> 500
A30: 46095 | B30: TARGET AUSTRALIA PTY LTD | C30: 澳大利亚 | D30: 4500196881 | E30: 2599186 | F30: 4500196881-20 | G30: 77858-S001 | H30: 厨房套装 | I30: 1500 | J30: 0 | K30: 3 | L30: =I30/K30 -> 500 | M30: 46153 | N30: 46150 | P30: OK | Q30: 46155 | R30: 是 | S30: 46097 | T30: 有 | U30: 4/22外箱贴纸SSCC label | W30: 日期码格式：ZURU INC(BVI) 标准格式 日期：按实际生产日期 Packaging Info: 2. 77858：英文MA包装UPC版本（首选1L，无1L可选多语）+箱唛+ 外箱贴纸SSCC label； Remark: 1. 客人要求箱唛不可出现任何手写内容，重量与实际一致且不可手写; 2. 此单去澳大利亚，请按相应澳新标准生产; 3. 取消使用TARGET新版封箱胶封顶，外箱全部使用普通透明封箱胶纸(客版胶纸如还有库存，可先消耗库存)； 4. 外箱需要贴Target SSCC LABEL,客供PDF文档，工厂自行订购。请贴在正唛右下角（一箱一张，贴1面正唛右下角,封箱胶纸不能挡住贴纸内容。)；外箱贴纸距离 外箱边缘应在2cm以上。如果正唛无位置可以贴在侧唛； 5. SSCC LABEL要求：贴纸内容，条形码印刷不完整/不清晰或有划痕/缺失，贴纸脏污、破损、条形码折叠、翘起、重复或者丢失，以及封箱胶盖住贴纸任何位置的 ，客户都不能接受，如有发现以上异常，须返工重新贴； 6. 外箱材质为ZURU标准； 7. 产品和包装上要有tracking label信息：格式为Zuru标准格式（可以自行调整具体年月日生产日期,避开节假期日）； 8. SSCC Label 尺寸更新为：4x4 inch。 | X30: Christine Liao | Y30: 9.9259 | Z30: =I30*Y30 -> 14888.85 | AB30: 77858-S001 | AC30: 已入 | AI30: =I30 -> 1500 | AM30: =I30 -> 1500 | AQ30: =I30 -> 1500
A31: 46094 | B31: WALMART INC. | C31: 美国 | D31: 4500196792 | E31: 0980444054 | F31: 4500196792-10 | G31: 77858-S002 | H31: 厨房套装 | I31: 1216 | J31: 0 | K31: 2 | L31: =I31/K31 -> 608 | M31: 46153 | N31: 46150 | O31: 46156 | P31: OK | Q31: 46174 | R31: 是 | S31: 46094 | T31: 有 | U31: 3/24RFID贴纸+粉色艾利贴纸+MA 贴纸 | W31: 日期码格式：ZURU DGMMDD CHINA(日期避开周末和法定节假日即可） 日期：按实际生产日期 Packaging Info: 77858-S002 1. 包装要求： 77858：MA 1L A版 playset +MA 5L A版收藏指南+MA 23L A版说明书+MA A版纸袋+MA 贴纸 每pcs产品要贴一张RFID贴纸，RFID贴纸由ZURU提供，贴纸位置要严格按照客人签板 Remark: 77858-S002 1. 包装要求： 77858：MA 1L A版 playset +MA 5L A版收藏指南+MA 23L A版说明书+MA A版纸袋+MA 贴纸 每pcs产品要贴一张RFID贴纸，RFID贴纸由ZURU提供，贴纸位置要严格按照客人签板 2. 外箱印刷带条码的RFID箱唛：RFID紫色色带+WM Dept.图标+RFID图标+ITF-14条码+粉色艾利贴纸（不干胶打印），四面右下角印刷ZURU logo, ITFF条码只印刷在 正唛一面，在加印的时候确保条形码能扫描出来，1张粉红色贴纸贴在正唛对角线，外箱侧面任一角落加印："MADE IN CHINA" 字样； 3. 在产品上和包装上要有日期码、以及要有MADE IN CHINA和ZURU字样； 4. 产品如有扎带口要剪平，不能刮手。 5. 此单需要验货，请多备料 6. 此单以loose carton出货，2pcs/CTN | X31: Maggie Xie | Y31: 6.5485 | Z31: =I31*Y31 -> 7962.976 | AB31: 77858-S002 | AC31: 已入 | AI31: =I31 -> 1216 | AM31: =I31 -> 1216 | AQ31: =I31 -> 1216
A32: 46094 | B32: WALMART INC. | C32: 美国 | D32: 4500196792 | E32: 0980444062 | F32: 4500196792-20 | G32: 77858-S002 | H32: 厨房套装 | I32: 1264 | J32: 0 | K32: 2 | L32: =I32/K32 -> 632 | M32: 46153 | N32: 46150 | O32: 46156 | P32: OK | Q32: 46174 | R32: 是 | S32: 46094 | T32: 有 | U32: 3/24RFID贴纸+粉色艾利贴纸+MA 贴纸 | W32: 日期码格式：ZURU DGMMDD CHINA(日期避开周末和法定节假日即可） 日期：按实际生产日期 Packaging Info: 77858-S002 1. 包装要求： 77858：MA 1L A版 playset +MA 5L A版收藏指南+MA 23L A版说明书+MA A版纸袋+MA 贴纸 每pcs产品要贴一张RFID贴纸，RFID贴纸由ZURU提供，贴纸位置要严格按照客人签板 Remark: 77858-S002 1. 包装要求： 77858：MA 1L A版 playset +MA 5L A版收藏指南+MA 23L A版说明书+MA A版纸袋+MA 贴纸 每pcs产品要贴一张RFID贴纸，RFID贴纸由ZURU提供，贴纸位置要严格按照客人签板 2. 外箱印刷带条码的RFID箱唛：RFID紫色色带+WM Dept.图标+RFID图标+ITF-14条码+粉色艾利贴纸（不干胶打印），四面右下角印刷ZURU logo, ITFF条码只印刷在 正唛一面，在加印的时候确保条形码能扫描出来，1张粉红色贴纸贴在正唛对角线，外箱侧面任一角落加印："MADE IN CHINA" 字样； 3. 在产品上和包装上要有日期码、以及要有MADE IN CHINA和ZURU字样； 4. 产品如有扎带口要剪平，不能刮手。 5. 此单需要验货，请多备料 6. 此单以loose carton出货，2pcs/CTN | X32: Maggie Xie | Y32: 6.5485 | Z32: =I32*Y32 -> 8277.304 | AB32: 77858-S002 | AC32: 已入 | AI32: =I32 -> 1264 | AM32: =I32 -> 1264 | AQ32: =I32 -> 1264
A33: 46108 | B33: ASIA GOAL LIMITED | C33: 香港 | D33: 4500198855 | E33: AG250415-HK | F33: 4500198855-10 | G33: 77858-S001 | H33: 厨房套装 | I33: 120 | J33: 0 | K33: 3 | L33: =I33/K33 -> 40 | M33: 46154 | N33: 46153 | P33: OK | Q33: 46164 | R33: 是 | S33: 46108 | T33: 无 | U33: 4/10 HK客供警语贴纸（2 张HK客供警语贴纸，1张贴彩盒背面，1张贴说明书，贴纸内容不一样,详情参考HK客供警语贴纸位置图） | W33: 日期码格式：ZURU INC(BVI) 标准格式 日期：按实际生产日期 Packaging Info: 此单出HK, 77858: MA PKG , 优先1L+ HK客供警语贴纸（2 张HK客供警语贴纸，1张贴彩盒背面，1张贴说明书，贴纸内容不一样,详情参考HK客供警语贴纸位置图） Remark: | X33: Chelsea Luo | Y33: 9.9425 | Z33: =Y33*I33 -> 1193.1 | AB33: 77858-S001 | AC33: 已入 | AI33: =I33 -> 120 | AM33: =I33 -> 120 | AQ33: =I33 -> 120
A34: 46108 | B34: ASIA GOAL LIMITED TAIWAN BRANCH (H. | C34: 台湾 | D34: 4500198860 | E34: AG250416-TW | F34: 4500198860-10 | G34: 77858-S001 | H34: 厨房套装 | I34: 120 | J34: 0 | K34: 3 | L34: =I34/K34 -> 40 | M34: 46154 | N34: 46153 | P34: OK | Q34: 46172 | R34: 是 | S34: 46108 | T34: 无 | U34: 4/21警语贴纸 | W34: 日期码格式：ZURU INC(BVI) 标准格式 日期：按实际生产日期 Packaging Info: 此单出TW 77858: MA PKG , 优先1L+ 1张警语贴纸 Remark: | X34: Chelsea Luo | Y34: 10.2316 | Z34: =Y34*I34 -> 1227.792 | AB34: 77858-S001 | AC34: 已入 | AI34: =I34 -> 120 | AM34: =I34 -> 120 | AQ34: =I34 -> 120
A35: 46106 | B35: WALMART INC. | C35: 美国 | D35: 4500198129 | E35: 0983717723 | F35: 4500198129-20 | G35: 77858-S002 | H35: 厨房套装 | I35: 500 | J35: 0 | K35: 2 | L35: =I35/K35 -> 250 | M35: 46156 | N35: 46154 | O35: 5/18自检 | P35: OK | Q35: 46179 | R35: 是 | S35: 翻4500195615 | T35: 无 | U35: 4/8RFID贴纸 | W35: 日期码格式：ZURU DGYYMMDD CHINA(日期避开周末和法定节假日即可） 日期：按实际生产日期 77858-S002 1. 包装要求： 77858：MA 1L A版 playset +MA 5L A版收藏指南+MA 23L A版说明书+MA A版纸袋+MA 贴纸 每pcs产品要贴一张RFID贴纸，RFID贴纸由ZURU提供，贴纸位置要严格按照客人签板 77858-S002 1. 包装要求： 77858：MA 1L A版 playset +MA 5L A版收藏指南+MA 23L A版说明书+MA A版纸袋+MA 贴纸 每pcs产品要贴一张RFID贴纸，RFID贴纸由ZURU提供，贴纸位置要严格按照客人签板 2. 外箱印刷带条码的RFID箱唛：RFID紫色色带+WM Dept.图标+RFID图标+ITF-14条码，四面右下角印刷ZURU logo, ITFF条码只印刷在正唛一面，在加印的时候确保 条形码能扫描出来，外箱侧面任一角落加印："MADE IN CHINA" 字样； 3. 在产品上和包装上要有日期码、以及要有MADE IN CHINA和ZURU字样； 4. 产品如有扎带口要剪平，不能刮手。 5. 此单需要验货，请多备料 6. 此单以loose carton出货，2pcs/CTN | X35: Maggie Xie | Y35: 6.5485 | Z35: =I35*Y35 -> 3274.25 | AB35: 77858-S002 | AC35: 已入 | AI35: =I35 -> 500 | AM35: =I35 -> 500 | AQ35: =I35 -> 500
A36: 46101 | B36: HARVEY WHOLESALE LTD | C36: 新西兰 | D36: 4500197606 | E36: 3108 | F36: 4500197606-10 | G36: 77858-S001 | H36: 厨房套装 | I36: 168 | J36: 0 | K36: 3 | L36: =I36/K36 -> 56 | M36: 46156 | N36: 46154 | P36: OK | Q36: 46165 | R36: 是 | S36: 46101 | T36: 无 | U36: 无 | W36: 日期码格式：ZURU INC(BVI) 标准格式 日期：按实际生产日期 Packaging Info: MA UPC 包装（优先1L，3L/5L也可） Remark: 3PCS AA BATTERIES(NOT INCLUDED) | X36: Ivy Li | Y36: 10.2316 | Z36: =I36*Y36 -> 1718.9088 | AB36: 77858-S001 | AC36: 已入 | AI36: =I36 -> 168 | AM36: =I36 -> 168 | AQ36: =I36 -> 168
A37: 46094 | B37: WALMART INC. | C37: 美国 | D37: 4500196793 | E37: 0980444051 | F37: 4500196793-10 | G37: 77858-S002 | H37: 厨房套装 | I37: 960 | J37: 0 | K37: 2 | L37: =I37/K37 -> 480 | M37: 46156 | N37: 46154 | O37: 5/18自检 | P37: OK | Q37: 46165 | R37: 是 | S37: 46094 | T37: 有 | U37: 3/24RFID贴纸+粉色艾利贴纸+MA 贴纸 | W37: 日期码格式：ZURU DGMMDD CHINA(日期避开周末和法定节假日即可） 日期：按实际生产日期 Packaging Info: 77858-S002 1. 包装要求： 77858：MA 1L A版 playset +MA 5L A版收藏指南+MA 23L A版说明书+MA A版纸袋+MA 贴纸 每pcs产品要贴一张RFID贴纸，RFID贴纸由ZURU提供，贴纸位置要严格按照客人签板 Remark: 77858-S002 1. 包装要求： 77858：MA 1L A版 playset +MA 5L A版收藏指南+MA 23L A版说明书+MA A版纸袋+MA 贴纸 每pcs产品要贴一张RFID贴纸，RFID贴纸由ZURU提供，贴纸位置要严格按照客人签板 2. 外箱印刷带条码的RFID箱唛：RFID紫色色带+WM Dept.图标+RFID图标+ITF-14条码+粉色艾利贴纸（不干胶打印），四面右下角印刷ZURU logo, ITFF条码只印刷在 正唛一面，在加印的时候确保条形码能扫描出来，1张粉红色贴纸贴在正唛对角线，外箱侧面任一角落加印："MADE IN CHINA" 字样； 3. 在产品上和包装上要有日期码、以及要有MADE IN CHINA和ZURU字样； 4. 产品如有扎带口要剪平，不能刮手。 5. 此单需要验货，请多备料 6. 此单以loose carton出货，2pcs/CTN | X37: Maggie Xie | Y37: 6.5485 | Z37: =I37*Y37 -> 6286.56 | AB37: 77858-S002 | AC37: 已入 | AI37: =I37 -> 960 | AM37: =I37 -> 960 | AQ37: =I37 -> 960
A38: 46112 | B38: AMAZON UK | C38: 英国 | D38: 4500198642 | E38: 3UI85QUZ | F38: 4500198642-150 | G38: 77858-S003 -MB | H38: 厨房套装 | I38: 978 | J38: 0 | K38: 3 | L38: =I38/K38 -> 326 | M38: 46156 | N38: 46154 | P38: OK | Q38: 46158 | S38: 空白外箱（加印带Zuru字样的最新logo，除了邮包盒直接做外箱的产品） | T38: 有 | U38: 4/24外箱贴纸SSCC label | V38: 客版邮包盒(参考翻单PO#4500198640) | W38: 日期码格式：ZURU INC(BVI) 标准格式 日期：按实际生产日期 Packaging Info: Amazon UK: 5TKIJIXX/3O77XWME/7N1D8FUG/7H6BABTK/5Z2UXPOL/3UI85QUZ Amazon UK(77858/77876/77878/157124/157142) 1. 77858: 1pc 77858 playset into mailbox, 3mailboxes/ctn; Including magnets; 3PCS AA BATTERIES(NOT INCLUDED); MA 3L(23L warning EAN)A 透明PVC窗 彩盒+MA 23L warning A 电池黑白说明书+MA 5L A收藏指南+MA其它最新配套包装+客版邮包盒(Amazon US PO#4500192979)+WEEE_不带电池走货 _ 说明书欧洲EN+29L _C版 6.验货时间不迟于2026/5/15. 注意：77858需将邮包盒尺寸图片<(>&<)>重量图片放进验货报告。 Remark: 1.空白外箱（加印带Zuru字样的最新logo，除了邮包盒直接做外箱的产品） + SSCC LABEL一张, 无箱唛，MADE IN CHINA 外箱只印一正一侧。箱唛资料按照给定的 标准去做即可，无需发回我方再行审批(新标准将另行通知)。 (SSCC LABEL竖贴在外箱正面的正中间，贴一面即可,贴纸离外箱边距必须至少3.2CM。如竖贴无法满足要求，则横贴。如横贴也无法满足要求，则竖贴，遮到ZURU lo go无影响), SSCC贴纸由工厂直接跟勤得采购或者工厂自行采购，每一张SSCC Label都是唯一且有不同流水及条码，且需要检查条码是否能正常扫描，另外，此贴纸 印刷不可出现模糊，溢出及粘胶不牢易脱落等现象，如工厂不按此要求导致贴纸有任何问题产生的罚款将由工厂承担一切责任 ,<(>,<)> 此要求只适用Amazon UK/DE /FR/ES/IT,不适用Amazon GPE，Amazon GPE无SSCC label, 但是有对应箱唛，需印刷到外箱 。 2.出往UK的产品+包装务必打上UKCA logo ，否则客人会退货且当地会有罚款。 3.订单必须经过ZURU QC验货或者工厂自检通过后方可出货，不涉及第三方验货。 4.法国订单要求包装不使用矿物油，请按要求提供以下其中一份文件再出货 ，产品出到法国被相关部门抽检出现包装不符合此要求的，供应商需要为此承担责任， 故此请严格把关。 -油墨物质""""由1 ~ 7个芳香环组成的MOAH""""的包装检测报告，要求限值≤1.0%； -包装材料清单，包括包装油墨或物质的信息； -油墨制造商的证书； 5.每一批次出货只能有一个生产日期，不可多个生产日期混在同一批次出货；且零售包装上必须统一加上日期码；外箱对于日期码没有硬性规定； 6.涉及到相关款式会有闪粉的或者微塑料的，请统一默认出无闪粉或者不含微塑料版本； 7.邮包盒及外箱封箱必须是工字型封箱方式； 8.5 Surprise or Mini Brands涉及包装是2个及2个以上的球入PVC桶包装时，单个球上若有UPC#或者EAN#，请用空白贴纸覆盖住，贴纸尺寸自行测量能覆盖原条码即 可； 9. 无论是工厂自检还是ZURU验货，验货报告中必须有产品6面图(正面/背面/左面/右面/顶部/底部，不带包装); 10. 按空海运鉴定报告的要求，只要带锂电池出货，都需要加贴UN贴纸； 11. 所有出往GAS市场(德国/奥地利/瑞士)的电子产品身上需要加字唛，为ZURU FRANCE 地址，需跟包装上的地址一致 (如无电子产品，产品布标有此地址，或产品 太小无法增加可忽略此信息。如产品无法加字唛，需让对应跟单提供产品贴纸资料); 12. 所有出往GAS德国 (瑞士，奥地利)。水弹枪系列必须使用EN71版本（电子和非电子水弹枪系列都需要符合); 护目镜需打日期码, 格式跟ZURU标准格式一样; 枪 身上增加ZURU FRANCE公司名和地址。使用贴纸和辐射上 | X38: Luna Lin | Y38: 12.65 | Z38: =Y38*I38 -> 12371.7 | AB38: 77858-S003-MB-1 | AC38: 已入 | AL38: =I38 -> 978 | AM38: =I38 -> 978 | AO38: 29L | AQ38: =I38 -> 978
A39: 46094 | B39: WALMART INC. | C39: 美国 | D39: 4500196793 | E39: 0980444049 | F39: 4500196793-20 | G39: 77858-S002 | H39: 厨房套装 | I39: 1356 | J39: 0 | K39: 2 | L39: =I39/K39 -> 678 | M39: 46156 | N39: 46154 | O39: 5/18自检 | P39: OK | Q39: 46165 | R39: 是 | S39: 46094 | T39: 有 | U39: 3/24RFID贴纸+粉色艾利贴纸+MA 贴纸 | W39: 日期码格式：ZURU DGMMDD CHINA(日期避开周末和法定节假日即可） 日期：按实际生产日期 Packaging Info: 77858-S002 1. 包装要求： 77858：MA 1L A版 playset +MA 5L A版收藏指南+MA 23L A版说明书+MA A版纸袋+MA 贴纸 每pcs产品要贴一张RFID贴纸，RFID贴纸由ZURU提供，贴纸位置要严格按照客人签板 Remark: 77858-S002 1. 包装要求： 77858：MA 1L A版 playset +MA 5L A版收藏指南+MA 23L A版说明书+MA A版纸袋+MA 贴纸 每pcs产品要贴一张RFID贴纸，RFID贴纸由ZURU提供，贴纸位置要严格按照客人签板 2. 外箱印刷带条码的RFID箱唛：RFID紫色色带+WM Dept.图标+RFID图标+ITF-14条码+粉色艾利贴纸（不干胶打印），四面右下角印刷ZURU logo, ITFF条码只印刷在 正唛一面，在加印的时候确保条形码能扫描出来，1张粉红色贴纸贴在正唛对角线，外箱侧面任一角落加印："MADE IN CHINA" 字样； 3. 在产品上和包装上要有日期码、以及要有MADE IN CHINA和ZURU字样； 4. 产品如有扎带口要剪平，不能刮手。 5. 此单需要验货，请多备料 6. 此单以loose carton出货，2pcs/CTN | X39: Maggie Xie | Y39: 6.5485 | Z39: =I39*Y39 -> 8879.766 | AB39: 77858-S002 | AC39: 已入 | AI39: =I39 -> 1356 | AM39: =I39 -> 1356 | AQ39: =I39 -> 1356
A40: 46107 | B40: CONTINENTE S.A. | C40: 哥伦比亚 | D40: 4500198705 | F40: 4500198705-90 | G40: 77858-S001 | H40: 厨房套装 | I40: 801 | J40: 0 | K40: 3 | L40: =I40/K40 -> 267 | M40: 46157 | N40: 46155 | P40: OK | Q40: 46187 | R40: 是 | S40: 46127 | T40: 无 | U40: 4/29进口商贴纸+UPC贴纸 | W40: 日期码格式：DG20260515 日期： Packaging Info: 7132:MA 多语包装+ UPC贴纸+进口商贴纸+箱唛 15789UQ1、15782UQ1:MA 多语包装+进口商贴纸+箱唛 15750、15788、15746:MA 多语包装+进口商贴纸+箱唛（进口商贴纸和mother UPC贴纸合并为一张） 其余item：MA 多语包装+进口商贴纸+UPC贴纸+箱唛 Remark: 1.包装/产品/外箱/进口商贴纸 指定日期码为DG20260515 .所有item包装上的条码必须是UPC，如果已将进口商贴纸和UPC条码合并到一张，则不需再订购UPC贴纸，仅订购一张进口商贴纸即可。 | X40: Ava Liang | Y40: 10.2316 | Z40: =I40*Y40 -> 8195.5116 | AB40: 77858-S001-1 | AC40: 已入 | AL40: =I40 -> 801 | AM40: =I40 -> 801 | AQ40: =I40 -> 801
A41: 46105 | B41: ASIA GOAL LIMITED | C41: 香港 | D41: 4500198401 | E41: AG250501-HK | F41: 4500198401-10 | G41: 77858-S001 | H41: 厨房套装 | I41: 120 | J41: 0 | K41: 3 | L41: =I41/K41 -> 40 | M41: 46157 | N41: 46155 | P41: OK | Q41: 46164 | R41: 是 | S41: 46105 | T41: 无 | U41: 4/3 HK客供警语贴纸（2 张HK客供警语贴纸，1张贴彩盒背面，1张贴说明书，贴纸内容不一样） | W41: 日期码格式：ZURU INC(BVI) 标准格式 日期：按实际生产日期 Packaging Info: 此单出HK, 77858: MA PKG , 优先1L+ HK客供警语贴纸（2 张HK客供警语贴纸，1张贴彩盒背面，1张贴说明书，贴纸内容不一样） | X41: Chelsea Luo | Y41: 9.9425 | Z41: =I41*Y41 -> 1193.1 | AB41: 77858-S001 | AC41: 已入 | AI41: =I41 -> 120 | AM41: =I41 -> 120 | AQ41: =I41 -> 120
...

Sheet 生产MA
A1: MA Order No. : | D1: MA-RR-2075 | E1: MA-RR-2166 | F1: MA-RR-2400 | G1: MA-RR-2477 | H1: MA-RR- | I1: MA-RR- | J1: Grand Total | K1: 实际订单 | L1: 剩余MA
A2: Order Date: | D2: 46041 | E2: 46113 | F2: 46203 | G2: 46246
A3: Required CRD: | D3: 46101 | E3: 46155 | F3: 46241 | G3: 46288
A4: Capsule 77858 | D4: 78000 | E4: 242000 | F4: 160000 | G4: 40000 | J4: =SUM(D4:I4) -> 520000 | K4: ='77858厨房套装'!I379 -> 377830 | L4: =J4-K4 -> 142170

Sheet 布料 IC MA
A1: MA NO. | B1: IC No. | C1: IC Supplier | D1: IC Wafer | E1: L/T | F1: MOQ | G1: Unit Price | H1: MFQ QTY | I1: MA-RR-1983 | J1: MA-RR-2025 | K1: MA-RR-2045 | L1: MA-RR-2119 | M1: MA-RR-2171 | N1: MA-RR-2227 | O1: MA-RR-2377 | P1: MA-RR-2403 | Q1: MA_RR_2445母体IC | R1: MA订单累计 Cumulative Total
A2: Ordered Date | I2: 45989 | J2: 46016 | K2: 46031 | L2: 46056 | M2: 46090 | N2: 46113 | O2: 46190 | P2: 46204 | Q2: 46231
A3: Required Delivery Date | I3: 46041 | J3: =J2+25 -> 46041 | K3: =K2+25 -> 46056 | L3: 46084 | M3: 46135 | N3: 46158 | O3: 46235 | P3: 46249
A4: 供应商回复货期
A6: MB-Magic Cook Kitchen Playset S1 #77858 | B6: HY2409148-6 | C6: 华远科创 | E6: 15 | F6: 4000 | G6: 0.46 | I6: 80000 | K6: 64000 | L6: 24000 | M6: 140000 | N6: 100000 | O6: 72000 | P6: 120000 | Q6: 124000 | R6: =SUM(I6:Q6) -> 724000
A7: MB-Magic Cook Kitchen Playset S1 #77858 | B7: ZJ-3718L-1511 (安规雾化片) | C7: 东莞市智杰电子科技有限公司 | E7: 25 | F7: 1000 | G7: 2.49 | I7: 0 | J7: 80000 | K7: 64000 | L7: 24000 | M7: 140000 | N7: 100000 | O7: 72000 | P7: 120000 | Q7: 0 | R7: =SUM(I7:Q7) -> 600000
B8: Running Sum | I8: =SUM(I6:I7) -> 80000 | J8: =SUM(J6:J7) -> 80000 | K8: =SUM(K6:K7) -> 128000 | L8: =SUM(L6:L7) -> 48000 | M8: =SUM(M6:M7) -> 280000 | N8: =SUM(N6:N7) -> 200000 | O8: =SUM(O6:O7) -> 144000 | P8: =SUM(P6:P7) -> 240000 | ... R8: =SUM(R6:R7) -> 1324000
L20: 放定日期 | M20: 45961 | N20: 46014 | O20: 46050 | P20: 46113 | Q20: 46203 | R20: 46246
L21: 到料日期 | M21: =M20+35 -> 45996 | N21: =N20+35 -> 46049 | O21: 46105 | P21: 46173 | Q21: 46241 | R21: 46288
I22: Damand FCST by 2025-10-27 | K22: 265611 | L22: MA No. | M22: MA-RR-1957 | O22: MA-RR-2089 | P22: MA-RR-2172 | Q22: MA-RR-2399 | R22: MA-RR-2476 | W22: MA | X22: 39183.673
A23: 图片 | B23: 名称 | C23: Ratio | D23: 布料名称 | E23: 部位 | F23: MOQ | G23: 用量 | H23: 可生产item数量(PCS) | I23: 单价 (RMB) | J23: 布料生產期單位(天)+测试 | K23: MOQ可生产球的数量 | L23: FCST布料需求量 | M23: 新购买 | N23: 新购买 | O23: 新购买 | P23: 新购买 | Q23: 新购买 | R23: 新购买 | T23: 累计购买金额 | U23: 总放定布料数 | V23: 总放定布料可生产数 | W23: 此款需求数(按Playset MA数量) | X23: 此款布料需求(按球MA数量) | Y23: 库存剩余数量 | Z23: 剩余布料可生产球数
B24: 橙色格子帘布 | C24: 1 | D24: 60"200G不防水白色四面弹斜纹布+数码满地印红橙格子+正反折皱 | E24: 帘子 | F24: 500 | G24: 0.012760417 | H24: =F24/G24 -> 39183.673 | I24: 22.1 | J24: 35+7天 | K24: =F24/G24/C24 -> 39183.673 | L24: =C24*K22*G24 -> 3389.307 | M24: 500 | N24: 500 | O24: 532 | P24: 2552 | Q24: 2042 | R24: 511 | T24: =SUM(M24:S24)*I24 -> 146677.7 | U24: =SUM(M24:Q24) -> 6126 | V24: =U24/G24 -> 480078.37 | W24: =X22*C24 -> 39183.673 | X24: =W24*G24 -> 500 | Y24: =U24-X24 -> 5626 | Z24: =Y24/G24/C24 -> 440894.69

Sheet 包材MA
A1: 77858包装MA
A2: 放MA日期 | B2: 货号 | C2: 负责 | D2: MA订单号码 | E2: 彩盒 | F2: 彩盒 | G2: 收藏指南 | I2: 客版彩盒 | J2: 客版PDQ | K2: 客版收藏指南 | L2: 客版黑白警语说明书 | M2: 备注
E3: 1L A版 | F3: 3L A版 | G3: 5L A版 | H3: 5L B版 | I3: 3L | J3: 3L | K3: 5L | L3: 3L
A5: 46081 | B5: 77858 | C5: Jasmine Huang | D5: 1000036716 | E5: 30000
A6: 46081 | B6: 77858 | C6: Jasmine Huang | D6: 1000036717 | F6: 15000
A7: 46081 | B7: 77858 | C7: Jasmine Huang | D7: 1000036718 | G7: 50000
A8: 46127 | B8: 77858 | C8: Jasmine Huang | D8: 1000038697 | E8: 20000
A9: 46127 | B9: 77858 | C9: Jasmine Huang | D9: 1000038698 | F9: 20000
A10: 46127 | B10: 77858 | C10: Jasmine Huang | D10: 1000038699 | G10: 30000
A11: 46134 | B11: 77889SLT | C11: Violet Chen | D11: 1000039096 | I11: =36*54*7+36*54*10 -> 33048 | M11: Cherish用于Costco USA 订单明细如下, 一共10张单, CRD 6/18-6/29；Costco CA 订单明细如下, 一共7张单, CRD 6/29-7/9 4500199798/4500199804/4500199805 4500199806 4500199807 4500199809 4500199810 4500199811 4500199814 4500199817/4500199850 4500199853 4500199854 4500199855 4500199856 4500199857 4500199858
A12: 46134 | B12: 77889SLT | C12: Violet Chen | D12: 1000039098 | J12: =36*17*18 -> 11016 | M12: 4500199798 4500199804 4500199805 4500199806 4500199807 4500199809 4500199810 4500199811 4500199814 4500199817/4500199850 4500199853 4500199854 4500199855 4500199856 4500199857 4500199858
A13: 46134 | B13: 77889SLT | C13: Violet Chen | D13: 1000039099 | K13: =36*54*7+36*54*10 -> 33048 | M13: 4500199798 4500199804 4500199805 4500199806 4500199807 4500199809 4500199810 4500199811 4500199814 4500199817/4500199850 4500199853 4500199854 4500199855 4500199856 4500199857 4500199858
A14: 46134 | B14: 77889SLT | C14: Violet Chen | D14: 1000039100 | L14: =36*54*7+36*54*10 -> 33048 | M14: 4500199798 4500199804 4500199805 4500199806 4500199807 4500199809 4500199810 4500199811 4500199814 4500199817/4500199850 4500199853 4500199854 4500199855 4500199856 4500199857 4500199858
A15: 46142 | B15: 77858 | C15: Jasmine Huang | D15: 1000039528 | E15: 20000
A16: 46142 | B16: 77858 | C16: Jasmine Huang | D16: 1000039529 | F16: 20000
A17: 46142 | B17: 77858 | C17: Jasmine Huang | D17: 1000039530 | G17: 50000
A18: 46156 | B18: 77889SLT | C18: Violet Chen | D18: 1000040017 | I18: =17*54*36 -> 33048 | M18: Cynthia用于Costco USA 订单明细如下, 一共14张单, CRD2026/7/1—2026/7/15；Costco CA 订单明细如下, 一共3张单,4500206634 4500206635 4500206637 4500206638 4500206639 4500206641 4500206643 4500206645 4500206646 4500206648 4500206650 4500206651 4500206652 4500206653/4500199859 4500199860 4500199861
A19: 46156 | B19: 77889SLT | C19: Violet Chen | D19: 1000040018 | J19: =17*18*36 -> 11016 | M19: Cynthia用于Costco USA 订单明细如下, 一共14张单, CRD2026/7/1—2026/7/15；Costco CA 订单明细如下, 一共3张单,4500206634 4500206635 4500206637 4500206638 4500206639 4500206641 4500206643 4500206645 4500206646 4500206648 4500206650 4500206651 4500206652 4500206653/4500199859 4500199860 4500199861
A20: 46156 | B20: 77889SLT | C20: Violet Chen | D20: 1000040019 | K20: =17*54*36 -> 33048 | M20: Cynthia用于Costco USA 订单明细如下, 一共14张单, CRD2026/7/1—2026/7/15；Costco CA 订单明细如下, 一共3张单,4500206634 4500206635 4500206637 4500206638 4500206639 4500206641 4500206643 4500206645 4500206646 4500206648 4500206650 4500206651 4500206652 4500206653/4500199859 4500199860 4500199861
A21: 46156 | B21: 77889SLT | C21: Violet Chen | D21: 1000040020 | L21: =17*54*36 -> 33048 | M21: Cynthia用于Costco USA 订单明细如下, 一共14张单, CRD2026/7/1—2026/7/15；Costco CA 订单明细如下, 一共3张单,4500206634 4500206635 4500206637 4500206638 4500206639 4500206641 4500206643 4500206645 4500206646 4500206648 4500206650 4500206651 4500206652 4500206653/4500199859 4500199860 4500199861
A22: 46182 | B22: 77889SLT | C22: Violet Chen | D22: 1000041170 | I22: =17*54*36 -> 33048 | M22: 4500208877/4500208878/4500208879/4500208880/4500208881/4500208882/4500208883/4500208884/4500208885/4500208886/4500208887/4500208888/4500208889/4500208890/4500199862/4500199863/4500199864
A23: 46182 | B23: 77889SLT | C23: Violet Chen | D23: 1000041171 | J23: =17*18*36 -> 11016 | M23: 4500208877/4500208878/4500208879/4500208880/4500208881/4500208882/4500208883/4500208884/4500208885/4500208886/4500208887/4500208888/4500208889/4500208890/4500199862/4500199863/4500199864
A24: 46182 | B24: 77889SLT | C24: Violet Chen | D24: 1000041172 | K24: =17*54*36 -> 33048 | M24: 4500208877/4500208878/4500208879/4500208880/4500208881/4500208882/4500208883/4500208884/4500208885/4500208886/4500208887/4500208888/4500208889/4500208890/4500199862/4500199863/4500199864
A25: 46182 | B25: 77889SLT | C25: Violet Chen | D25: 1000041173 | L25: =17*54*36 -> 33048 | M25: 4500208877/4500208878/4500208879/4500208880/4500208881/4500208882/4500208883/4500208884/4500208885/4500208886/4500208887/4500208888/4500208889/4500208890/4500199862/4500199863/4500199864
A26: 46188 | B26: 77858 | C26: Jasmine Huang | D26: 1000041485 | E26: 30000 | M26: A版本
A27: 46188 | B27: 77858 | C27: Jasmine Huang | D27: 1000041486 | F27: 20000 | M27: A版本
A28: 46188 | B28: 77858 | C28: Jasmine Huang | D28: 1000041487 | H28: 40000 | M28: B版本
A29: 46205 | B29: 77889SLT | C29: Ariel Peng | D29: 1000042123 | I29: 11664 | M29: Eva 用于COSTCO MX 4500198844+4500198845+4500198846+4500198848+4500198849+4500198850
A30: 46205 | B30: 77889SLT | C30: Ariel Peng | D30: 1000042124 | J30: 3888 | M30: Eva 用于COSTCO MX 4500198844+4500198845+4500198846+4500198848+4500198849+4500198850
A31: 46205 | B31: 77889SLT | C31: Ariel Peng | D31: 1000042125 | K31: 11664 | M31: Eva 用于COSTCO MX 4500198844+4500198845+4500198846+4500198848+4500198849+4500198850
A32: 46205 | B32: 77889SLT | C32: Ariel Peng | D32: 1000042126 | L32: 11664 | M32: Eva 用于COSTCO MX 4500198844+4500198845+4500198846+4500198848+4500198849+4500198850
A33: 46205 | B33: 77889SLT | C33: Babbit Zhong | D33: 1000042139 | I33: 7560 | M33: Zoe-4500208477&4500206719
A34: 46205 | B34: 77889SLT | C34: Babbit Zhong | D34: 1000042140 | J34: 140 | M34: Zoe-4500208477&4500206719
A35: 46205 | B35: 77889SLT | C35: Babbit Zhong | D35: 1000042141 | K35: 7560 | M35: Zoe-4500208477&4500206719
A36: 46205 | B36: 77889SLT | C36: Babbit Zhong | D36: 1000042142 | L36: 7560 | M36: Zoe-4500208477&4500206719
A37: 46220 | B37: 77858 | C37: Jasmine Huang | D37: 1000042812 | E37: 20000 | M37: A版本
A38: 46220 | B38: 77858 | C38: Jasmine Huang | D38: 1000042813 | F38: 10000 | M38: A版本
A39: 46220 | B39: 77858 | C39: Jasmine Huang | D39: 1000042814 | H39: 30000 | M39: B版本
A40: 46232 | B40: 77858 | C40: Jasmine Huang | D40: 1000043316 | E40: 20000 | M40: A版本
A41: 46245 | B41: 77858 | C41: Chelsie Chen | D41: 1000043884 | E41: 20000
...

Sheet 取消单
A1: 香港接单日期 | B1: 第三方客户名称 | C1: 走货国家 | D1: ZURU PO NO# | E1: 第三方客户 PO NO# | F1: SKU | G1: ITEM# | H1: 中文名 | I1: PO数量 (pcs) | J1: 内箱装箱数量(pcs) | K1: 外箱装箱数量(pcs) | L1: 总箱数 | M1: 客PO期 | N1: 验货期 | O1: 第三方验货期 | P1: 验货结果 | Q1: S/0船期 | R1: 箱唛确认 | S1: 箱唛资料(收到日期) | T1: 外箱贴纸 | U1: 客供贴纸AI(收到日期) | V1: 客供物料 | W1: 备注 | X1: ZURU 跟单 | Y1: 单价USD | Z1: 金额USD | AA1: 發票號 | AB1: 系统货号 | AC1: 是否入系统 | AD1: 系统出单 | AE1: 送货情况 | AF1: 欠数 | AG1: 贴纸 | AH1: MA 1L彩盒 | AI1: 客版 3L彩盒 | AJ1: 客版 3L彩盒（COSTCO AU/NA） | AK1: MA 3L彩盒 | AL1: 黑白警语说明书 | AM1: 客版黑白警语说明书 | AN1: 不带电WEE说明书 | AO1: 客版5L 收藏指南 | AP1: 5L 收藏指南 | AQ1: 客版PDQ
A2: 46056 | B2: ZURU LLC | C2: ZURU LLC | D2: 美国 | E2: 4500192979 | F2: 5200008906 | G2: 4500192979-120 | H2: 77858-S003-MB-MTS | J2: 3999 | K2: 0 | L2: 3 | M2: =J2/L2 -> 1333 | N2: 46132 | O2: 46128 | P2: 转单4500192979 | T2: 46056 | U2: 无 | V2: 无 | W2: 邮包盒 | X2: 日期码格式：ZURU INC(BVI) 标准格式 日期：按实际生产日期 Packaging Info: #77858: STD 77858带MA包装入邮包盒，邮包盒图稿跟单提供。首单需要提供大货样1PC(含邮包盒+产品)，测试样规格和大货一样，用于测ISTA6. Remark: 1.Amazon domestic 订单。出口美国。外箱最长边不能超过25" （超过了，case pack只能为1），不符合要求的大货，一律不接受。 2.无第三方验货/测试要求。 3.日期码使用ZURU标准版本。 4.如果大货有要求入邮包盒，则对应的邮包盒上面要打上日期码。 | Y2: Kelly Shen/Mia Pan/P | Z2: 7.59 | AA2: =J2*Z2 -> 30352.41 | AC2: 77858-S003-MB-MTS | AD2: 无bom
A3: 46067 | C3: AMAZON.COM SERVICES LLC | D3: 美国 | E3: 4500193997 | F3: 6FOAAL4E | G3: 4500193997-10 | H3: 77858-S003-MB | J3: 192 | K3: 0 | L3: 3 | M3: =J3/L3 -> 64 | N3: 46125 | O3: 46121 | T3: 46067 | U3: 有 | V3: 欠SSCC Label | W3: 邮包盒图稿翻单4500192979 | X3: 日期码格式：ZURU INC(BVI) 标准格式 日期：按实际生产日期 Packaging Info: #77858: STD 77858带MA包装入邮包盒，邮包盒图稿翻单4500192979。 Remark: 1. Amazon MDDP订单，出口US。 2. 日期码使用ZURU标准版本。 3. 如果大货有要求入邮包盒，则对应的邮包盒上面要打上日期码。 4. 箱尺寸要求：外箱最长边不能超过25"(超过了，case pack只能为1)，不符合要求的大货，一律不接受。 5. 外箱箱唛要求： ①外箱正面印ZURU Logo+SSCC Label(客供贴纸，由跟单订购)。关于 SSCC Label 请注意： SSCC Label显示的是客人自己的item#。每一张SSCC label都是唯一且有不同流水及条码的，没有损耗，绝对不可贴错。如果贴错或损坏任何一张，都会导致全部都 错，千万要注意！SSCC Label必须贴在外箱正面的正中间位置(贴一面即可)，并且贴纸离外箱边距必须至少3cm(可以覆盖Logo<(>&<)>箱唛)，否则会影响到客户那边 仓库的扫描识别。 ②外箱侧面印item#(订单上显示的SKU#)+carton size(以工厂实际尺寸为准，单位: inch)+MADE IN CHINA，日期使用ZURU 标准版本。 6. 装柜要求：按照客户PO#装柜/箱号顺序装柜，跟单会提前给到装柜计划。 在大货生产/仓库存放时，请留意该装柜要求，以便装柜时不混乱(避免装错/装漏/找不到货号等)。 | Y3: Kelly Shen/Mia Pan/P | Z3: 7.3813 | AA3: =J3*Z3 -> 1417.2096
A4: 46067 | C4: AMAZON.COM SERVICES LLC | D4: 美国 | E4: 4500194000 | F4: 2FJ8CEIC | G4: 4500194000-10 | H4: 77858-S003-MB | J4: 96 | K4: 0 | L4: 3 | M4: =J4/L4 -> 32 | N4: 46125 | O4: 46121 | T4: 46067 | U4: 有 | V4: 欠SSCC Label | W4: 邮包盒图稿翻单4500192979 | X4: 日期码格式：ZURU INC(BVI) 标准格式 日期：按实际生产日期 Packaging Info: #77858: STD 77858带MA包装入邮包盒，邮包盒图稿翻单4500192979。 Remark: 1. Amazon MDDP订单，出口US。 2. 日期码使用ZURU标准版本。 3. 如果大货有要求入邮包盒，则对应的邮包盒上面要打上日期码。 4. 箱尺寸要求：外箱最长边不能超过25"(超过了，case pack只能为1)，不符合要求的大货，一律不接受。 5. 外箱箱唛要求： ①外箱正面印ZURU Logo+SSCC Label(客供贴纸，由跟单订购)。关于 SSCC Label 请注意： SSCC Label显示的是客人自己的item#。每一张SSCC label都是唯一且有不同流水及条码的，没有损耗，绝对不可贴错。如果贴错或损坏任何一张，都会导致全部都 错，千万要注意！SSCC Label必须贴在外箱正面的正中间位置(贴一面即可)，并且贴纸离外箱边距必须至少3cm(可以覆盖Logo<(>&<)>箱唛)，否则会影响到客户那边 仓库的扫描识别。 ②外箱侧面印item#(订单上显示的SKU#)+carton size(以工厂实际尺寸为准，单位: inch)+MADE IN CHINA，日期使用ZURU 标准版本。 6. 装柜要求：按照客户PO#装柜/箱号顺序装柜，跟单会提前给到装柜计划。 在大货生产/仓库存放时，请留意该装柜要求，以便装柜时不混乱(避免装错/装漏/找不到货号等)。 | Y4: Kelly Shen/Mia Pan/P | Z4: 7.59 | AA4: =J4*Z4 -> 728.64
A5: 46087 | C5: AMAZON.COM SERVICES LLC | D5: 美国 | E5: 4500195252 | F5: 4ZTS3SGW | G5: 4500195252-170 | H5: 77858-S003-MB | I5: 厨房套装 | J5: 3402 | K5: 0 | L5: 3 | M5: =J5/L5 -> 1134 | N5: 46136 | O5: 46132 | P5: 3402PCS由Domestic PO4500192979转单 | S5: 自行排版 | T5: 46087 | U5: 有 | V5: 欠SSCC Label | W5: 邮包盒图稿翻单4500194000 | X5: 日期码格式：ZURU INC(BVI) 标准格式 日期：按实际生产日期 Packaging Info: #77858: STD 77858带MA包装入邮包盒，邮包盒图稿翻单4500194000。 其中207PCS由Domestic PO4500192979转单. Remark: 1. Amazon MDDP订单，出口US。 2. 日期码使用ZURU标准版本。 3. 如果大货有要求入邮包盒，则对应的邮包盒上面要打上日期码。 4. 箱尺寸要求：外箱最长边不能超过25"(超过了，case pack只能为1)，不符合要求的大货，一律不接受。 5. 外箱箱唛要求： ①外箱正面印ZURU Logo+SSCC Label(客供贴纸，由跟单订购)。关于 SSCC Label 请注意： SSCC Label显示的是客人自己的item#。每一张SSCC label都是唯一且有不同流水及条码的，没有损耗，绝对不可贴错。如果贴错或损坏任何一张，都会导致全部都 错，千万要注意！SSCC Label必须贴在外箱正面的正中间位置(贴一面即可)，并且贴纸离外箱边距必须至少3cm(可以覆盖Logo<(>&<)>箱唛)，否则会影响到客户那边 仓库的扫描识别。 ②外箱侧面印item#(订单上显示的SKU#)+carton size(以工厂实际尺寸为准，单位: inch)+MADE IN CHINA，日期使用ZURU 标准版本。 6. 装柜要求：按照客户PO#装柜/箱号顺序装柜，跟单会提前给到装柜计划。 在大货生产/仓库存放时，请留意该装柜要求，以便装柜时不混乱(避免装错/装漏/找不到货号等)。 | Y5: Kelly Shen/Mia Pan/P | Z5: 7.59 | AA5: =J5*Z5 -> 25821.18 | AC5: 77858-S003-MB | AD5: 已入 | AF5: 湖南提供半成品 | AI5: =J5 -> 3402
A6: 46087 | C6: AMAZON.COM SERVICES LLC | D6: 美国 | E6: 4500195258 | F6: 1HDMJUXJ | G6: 4500195258-130 | H6: 77858-S003-MB | I6: 厨房套装 | J6: 1800 | K6: 0 | L6: 3 | M6: =J6/L6 -> 600 | N6: 46136 | O6: 46132 | P6: 207PCS 由Domestic PO4500192979转单 | S6: 自行排版 | T6: 46087 | U6: 有 | V6: 欠SSCC Label | W6: 邮包盒图稿翻单4500194000 | X6: 日期码格式：ZURU INC(BVI) 标准格式 日期：按实际生产日期 Packaging Info: #77858: STD 77858带MA包装入邮包盒，邮包盒图稿翻单4500194000。 其中207PCS由Domestic PO4500192979转单. Remark: 1. Amazon MDDP订单，出口US。 2. 日期码使用ZURU标准版本。 3. 如果大货有要求入邮包盒，则对应的邮包盒上面要打上日期码。 4. 箱尺寸要求：外箱最长边不能超过25"(超过了，case pack只能为1)，不符合要求的大货，一律不接受。 5. 外箱箱唛要求： ①外箱正面印ZURU Logo+SSCC Label(客供贴纸，由跟单订购)。关于 SSCC Label 请注意： SSCC Label显示的是客人自己的item#。每一张SSCC label都是唯一且有不同流水及条码的，没有损耗，绝对不可贴错。如果贴错或损坏任何一张，都会导致全部都 错，千万要注意！SSCC Label必须贴在外箱正面的正中间位置(贴一面即可)，并且贴纸离外箱边距必须至少3cm(可以覆盖Logo<(>&<)>箱唛)，否则会影响到客户那边 仓库的扫描识别。 ②外箱侧面印item#(订单上显示的SKU#)+carton size(以工厂实际尺寸为准，单位: inch)+MADE IN CHINA，日期使用ZURU 标准版本。 6. 装柜要求：按照客户PO#装柜/箱号顺序装柜，跟单会提前给到装柜计划。 在大货生产/仓库存放时，请留意该装柜要求，以便装柜时不混乱(避免装错/装漏/找不到货号等)。 | Y6: Kelly Shen/Mia Pan/P | Z6: 7.59 | AA6: =J6*Z6 -> 13662 | AC6: 77858-S003-MB | AD6: 已入 | AF6: 湖南提供半成品 | AI6: =J6 -> 1800
A7: 46087 | C7: AMAZON.COM SERVICES LLC | D7: 美国 | E7: 4500195261 | F7: 4R27O4WC | G7: 4500195261-130 | H7: 77858-S003-MB | I7: 厨房套装 | J7: 2478 | K7: 0 | L7: 3 | M7: =J7/L7 -> 826 | N7: 46136 | O7: 46132 | S7: 自行排版 | T7: 46087 | U7: 有 | V7: 欠SSCC Label | W7: 邮包盒图稿翻单4500194000 | X7: 日期码格式：ZURU INC(BVI) 标准格式 日期：按实际生产日期 Packaging Info: #77858: STD 77858带MA包装入邮包盒，邮包盒图稿翻单4500194000。 其中207PCS由Domestic PO4500192979转单. Remark: 1. Amazon MDDP订单，出口US。 2. 日期码使用ZURU标准版本。 3. 如果大货有要求入邮包盒，则对应的邮包盒上面要打上日期码。 4. 箱尺寸要求：外箱最长边不能超过25"(超过了，case pack只能为1)，不符合要求的大货，一律不接受。 5. 外箱箱唛要求： ①外箱正面印ZURU Logo+SSCC Label(客供贴纸，由跟单订购)。关于 SSCC Label 请注意： SSCC Label显示的是客人自己的item#。每一张SSCC label都是唯一且有不同流水及条码的，没有损耗，绝对不可贴错。如果贴错或损坏任何一张，都会导致全部都 错，千万要注意！SSCC Label必须贴在外箱正面的正中间位置(贴一面即可)，并且贴纸离外箱边距必须至少3cm(可以覆盖Logo<(>&<)>箱唛)，否则会影响到客户那边 仓库的扫描识别。 ②外箱侧面印item#(订单上显示的SKU#)+carton size(以工厂实际尺寸为准，单位: inch)+MADE IN CHINA，日期使用ZURU 标准版本。 6. 装柜要求：按照客户PO#装柜/箱号顺序装柜，跟单会提前给到装柜计划。 在大货生产/仓库存放时，请留意该装柜要求，以便装柜时不混乱(避免装错/装漏/找不到货号等)。 | Y7: Kelly Shen/Mia Pan/P | Z7: 7.59 | AA7: =J7*Z7 -> 18808.02 | AC7: 77858-S003-MB | AD7: 已入 | AF7: 湖南提供半成品 | AI7: =J7 -> 2478
A8: 46087 | C8: AMAZON.COM SERVICES LLC | D8: 美国 | E8: 4500195264 | F8: 4IV6J1AO | G8: 4500195264-140 | H8: 77858-S003-MB | I8: 厨房套装 | J8: 2748 | K8: 0 | L8: 3 | M8: =J8/L8 -> 916 | N8: 46136 | O8: 46132 | S8: 自行排版 | T8: 46087 | U8: 有 | V8: 欠SSCC Label | W8: 邮包盒图稿翻单4500194000 | X8: 日期码格式：ZURU INC(BVI) 标准格式 日期：按实际生产日期 Packaging Info: #77858: STD 77858带MA包装入邮包盒，邮包盒图稿翻单4500194000。 其中207PCS由Domestic PO4500192979转单. Remark: 1. Amazon MDDP订单，出口US。 2. 日期码使用ZURU标准版本。 3. 如果大货有要求入邮包盒，则对应的邮包盒上面要打上日期码。 4. 箱尺寸要求：外箱最长边不能超过25"(超过了，case pack只能为1)，不符合要求的大货，一律不接受。 5. 外箱箱唛要求： ①外箱正面印ZURU Logo+SSCC Label(客供贴纸，由跟单订购)。关于 SSCC Label 请注意： SSCC Label显示的是客人自己的item#。每一张SSCC label都是唯一且有不同流水及条码的，没有损耗，绝对不可贴错。如果贴错或损坏任何一张，都会导致全部都 错，千万要注意！SSCC Label必须贴在外箱正面的正中间位置(贴一面即可)，并且贴纸离外箱边距必须至少3cm(可以覆盖Logo<(>&<)>箱唛)，否则会影响到客户那边 仓库的扫描识别。 ②外箱侧面印item#(订单上显示的SKU#)+carton size(以工厂实际尺寸为准，单位: inch)+MADE IN CHINA，日期使用ZURU 标准版本。 6. 装柜要求：按照客户PO#装柜/箱号顺序装柜，跟单会提前给到装柜计划。 在大货生产/仓库存放时，请留意该装柜要求，以便装柜时不混乱(避免装错/装漏/找不到货号等)。 | Y8: Kelly Shen/Mia Pan/P | Z8: 7.59 | AA8: =J8*Z8 -> 20857.32 | AC8: 77858-S003-MB | AD8: 已入 | AF8: 湖南提供半成品 | AI8: =J8 -> 2748
A9: 46087 | C9: AMAZON.COM SERVICES LLC | D9: 美国 | E9: 4500195266 | F9: 84NHDFGJ | G9: 4500195266-90 | H9: 77858-S003-MB | I9: 厨房套装 | J9: 339 | K9: 0 | L9: 3 | M9: =J9/L9 -> 113 | N9: 46136 | O9: 46132 | P9: 390PCS 由Domestic PO4500192979转单 | S9: 自行排版 | T9: 46087 | U9: 有 | V9: 欠SSCC Label | W9: 邮包盒图稿翻单4500194000 | X9: 日期码格式：ZURU INC(BVI) 标准格式 日期：按实际生产日期 Packaging Info: #77858: STD 77858带MA包装入邮包盒，邮包盒图稿翻单4500194000。 其中207PCS由Domestic PO4500192979转单. Remark: 1. Amazon MDDP订单，出口US。 2. 日期码使用ZURU标准版本。 3. 如果大货有要求入邮包盒，则对应的邮包盒上面要打上日期码。 4. 箱尺寸要求：外箱最长边不能超过25"(超过了，case pack只能为1)，不符合要求的大货，一律不接受。 5. 外箱箱唛要求： ①外箱正面印ZURU Logo+SSCC Label(客供贴纸，由跟单订购)。关于 SSCC Label 请注意： SSCC Label显示的是客人自己的item#。每一张SSCC label都是唯一且有不同流水及条码的，没有损耗，绝对不可贴错。如果贴错或损坏任何一张，都会导致全部都 错，千万要注意！SSCC Label必须贴在外箱正面的正中间位置(贴一面即可)，并且贴纸离外箱边距必须至少3cm(可以覆盖Logo<(>&<)>箱唛)，否则会影响到客户那边 仓库的扫描识别。 ②外箱侧面印item#(订单上显示的SKU#)+carton size(以工厂实际尺寸为准，单位: inch)+MADE IN CHINA，日期使用ZURU 标准版本。 6. 装柜要求：按照客户PO#装柜/箱号顺序装柜，跟单会提前给到装柜计划。 在大货生产/仓库存放时，请留意该装柜要求，以便装柜时不混乱(避免装错/装漏/找不到货号等)。 | Y9: Kelly Shen/Mia Pan/P | Z9: 7.59 | AA9: =J9*Z9 -> 2573.01 | AC9: 77858-S003-MB | AD9: 已入 | AF9: 湖南提供半成品 | AI9: =J9 -> 339
A10: 46087 | C10: AMAZON.COM SERVICES LLC | D10: 美国 | E10: 4500195266 | F10: 8B57DIII | G10: 4500195266-160 | H10: 77858-S003-MB | I10: 厨房套装 | J10: 51 | K10: 0 | L10: 3 | M10: =J10/L10 -> 17 | N10: 46136 | O10: 46132 | S10: 自行排版 | T10: 46087 | U10: 有 | V10: 欠SSCC Label | W10: 邮包盒图稿翻单4500194000 | X10: 日期码格式：ZURU INC(BVI) 标准格式 日期：按实际生产日期 Packaging Info: #77858: STD 77858带MA包装入邮包盒，邮包盒图稿翻单4500194000。 其中207PCS由Domestic PO4500192979转单. Remark: 1. Amazon MDDP订单，出口US。 2. 日期码使用ZURU标准版本。 3. 如果大货有要求入邮包盒，则对应的邮包盒上面要打上日期码。 4. 箱尺寸要求：外箱最长边不能超过25"(超过了，case pack只能为1)，不符合要求的大货，一律不接受。 5. 外箱箱唛要求： ①外箱正面印ZURU Logo+SSCC Label(客供贴纸，由跟单订购)。关于 SSCC Label 请注意： SSCC Label显示的是客人自己的item#。每一张SSCC label都是唯一且有不同流水及条码的，没有损耗，绝对不可贴错。如果贴错或损坏任何一张，都会导致全部都 错，千万要注意！SSCC Label必须贴在外箱正面的正中间位置(贴一面即可)，并且贴纸离外箱边距必须至少3cm(可以覆盖Logo<(>&<)>箱唛)，否则会影响到客户那边 仓库的扫描识别。 ②外箱侧面印item#(订单上显示的SKU#)+carton size(以工厂实际尺寸为准，单位: inch)+MADE IN CHINA，日期使用ZURU 标准版本。 6. 装柜要求：按照客户PO#装柜/箱号顺序装柜，跟单会提前给到装柜计划。 在大货生产/仓库存放时，请留意该装柜要求，以便装柜时不混乱(避免装错/装漏/找不到货号等)。 | Y10: Kelly Shen/Mia Pan/P | Z10: 7.59 | AA10: =J10*Z10 -> 387.09 | AC10: 77858-S003-MB | AD10: 已入 | AF10: 湖南提供半成品 | AI10: =J10 -> 51
