Workbook

Sheet 71172大脑
A1: 接单期 | B1: 第三方客户名称 | C1: 国家 | D1: PO号 | E1: 第三方客户 PO NO# | F1: SKU | G1: 货号 | H1: 名称 | I1: PO数量(只) | J1: 内箱装箱数量(只) | K1: 外箱装箱数量(只) | L1: 总箱数 | M1: 客PO期 | N1: 计划验货期 | O1: 第三方验货期 | P1: 验货结果 | Q1: 船期SO | R1: 蓝色表示寄出 黄色表示出单 | S1: 是否有外箱贴纸 | T1: 箱唛资料 | U1: 客贴纸 | V1: 其他物料 | W1: 日期码 | X1: 额外黑白书纸 | Y1: 备注 | Z1: 客跟单 | AA1: 单价USD | AB1: 金额USD | AC1: 发票号 | AD1: 系统货号 | AE1: 是否已入系统 | AF1: 已完成数量 | AG1: 欠数 | AH1: 贴纸情况 | AI1: 是否已入系统 | AJ1: 包装 | AK1: 标准=0,客版=1 | AL1: 说明书 | AM1: 标准=0,客版=1 | AN1: 走货情况(离厂日期) | AO1: 71172 产品数 | AP1: 71172 MA 1L彩盒 | AQ1: 71172 MA 3L彩盒 | AR1: 71172 MA 15L说明书A版 | AS1: 71172 MA15L说明书B版 | AT1: 客版MA 2L(ES+PT) | AU1: 客版
A2: 46016 | B2: ZURU NEW ZEALAND LIMITED | C2: 新西兰 | D2: 4500189979 | E2: 5200008513 | F2: 4500189979-10 | G2: 71172-S001-FS | H2: 大脑 | I2: 32 | J2: 0 | K2: 4 | L2: =I2/K2 -> 8 | M2: 46041 | N2: 46037 | O2: N/A | P2: PASS | Q2: 46111 | R2: 需要增加隔电片和加工电池盖做货 | Y2: 日期码格式：ZURU INC(BVI) 标准格式 日期：按实际生产日期 Packaging Info: Remark: NZ Fast Start Order, MA 1L UPC包装，用fast start专用UPC贴纸，外箱除常规箱唛印刷四面外，还需要贴一张黄色A4纸，印"fast start"内容。 旧桶身小硅胶管柱未加高：打防水胶+产线现有硅胶套 | Z2: SD92 | AA2: 9.86 | AB2: =I2*AA2 -> 315.52 | AD2: 71172-S001-1L | AE2: 已入 | AO2: =I2 -> 32
A3: 46078 | B3: KMART AUSTRALIA LTD(NEW ZEALAND) | C3: 新西兰 | D3: 4500193541 | E3: 21431981 | F3: 4500193541-40 | G3: 71172-S001 | H3: 大脑 | I3: 108 | J3: 0 | K3: 4 | L3: =I3/K3 -> 27 | M3: 46121 | N3: 46123 | O3: N/A | P3: PASS | Q3: 4/13上午入仓 | S3: 有 | T3: 46088 | U3: 46099 | Y3: 日期码格式：ZURU INC(BVI) 标准格式 日期：按实际生产日期 Packaging Info: 77772GQ1:MA英语UPC版本包装（收缩膜和说明书, MA首选1L，如无1L可用多语且含英语的配套多语包装) +防盜贴纸(贴纸以及防盜贴纸位置图翻单PO#4500193539)+ 两张张覆盖PDQ上唱片的贴纸+两张张覆盖收藏指南上唱片的贴纸+一张覆盖PDQ上数字"45"的贴纸+一张覆盖收藏指南上数字"45"的贴纸+箱唛+外箱贴纸SSCC Label 配比信息：4 mini vinyls,1 accessory Removed了 ""Messy <(>&<)> Delicious""两张唱片 77794UQ1:MA英语UPC版本包装（收缩膜和说明书, MA首选1L，如无1L可用多语且含英语的配套多语包装) +1张锂电池黑白警语书纸 + 1张防盗贴纸 (贴纸以及位置图 翻单PO#4500193539）+ 箱唛 + 外箱SSCC Label 77843GQ1：MA英语UPC版本包装（MA首选1L，如无1L可用多语且含英语的配套多语包装) +箱唛 + 外箱SSCC Label 77843-sushi <(>&<)> rainbow cake: MA sushi <(>&<)> rainbow cake专用黑白说明书+ 1张防盗贴纸 77843-其他款:MA UV灯说明书+1张防盗贴纸+1张说明书上面加警告语贴纸+1张收缩膜纽扣电池警告语贴纸 （贴纸资料以及位置图翻单PO#4500193539） 配比信息：Ratio: PIZZA: HAMBURGER: PANCAKES: BUBBLE TEA: Matcha TEA: TACO: SUSHI: DONUT: Charcuterie Board: RAINBOW CAKE(Rare)=10.88%: 10.88%: 10.88%: 10.88%: 10.88%: 10.88%: 10.88%: 10.88%: 10.88%: 2.08%=68:68:68:68:68:68:68:68:68:13 71172：MA英语UPC版本包装（收缩膜和说明书, MA首选1L，如无1L可用多语且含英语的配套多语包装) + 一张防盗贴纸（贴纸资料及位置图翻单PO#4500193539）+箱 唛 + 外箱SSCC Label 3PCS AA BATTERIES(INCLUDED) Remark: 1.请务必按时完货，验货。并且按期送货入货代指定仓库，如果晚了导致船期Delay将会有罚金产生或者客户要求空运，所产生的罚金和空运费由工厂承担。 2.SSCC 外箱贴纸请同纸箱瓦楞纸方向（竖纹向）垂直，即外箱贴纸横着贴(注意条码不要被胶带粘住），贴1pc，贴1面正唛，封箱胶纸不能挡住贴纸内容。外箱贴纸 离外箱边距离不少于2cm。 3.外箱材质为ZURU标准； 4.此单需使用KMART封箱胶上下工字型封箱;从2019年6月开始，要用KMART 新版封箱胶带，此单要用"ANKO"封箱胶带 5.此单出口新西兰，请按相应的澳新标准生产； 6.产品和包装上生产批号的显示格式ZURU标准日期码格式 7.外箱信息不可手写，重量和体积需要与实际的一致(不可手写） 8. 每款item装箱后的G.W.超过10KG或者CBM超过0.13,(9.5KG或者以上，四舍五入后也属于10KG) 需在外箱上加印超 重或者Bulky LOGO，若发现我们资料没有，请 帮忙提醒 1)重量超过10kg但不超过16kg且CBM不超过0.13,10-16kg 超重logo 2）CBM超过0.13且重量少于17kg，bulky logo 3）不属于以上两种情况，需要使用相应重量范围内的超重logo 4）超重logo需要在外箱四面都印刷(箱唛右上角，两面侧唛超重logo需要尽量靠近毛重)，尺寸为:110mm height* 95mm width 9. 实际外箱重量跟印在箱唛上的数据差异不能超3%，尺寸按实际数据印刷 71172实际上为LCL散货出柜，请注意此订单与AU po#4500193539一起合并计算 77772务必赶最晚5/11上午交仓 旧桶身小硅胶管柱未加高：打防水胶+产线现有硅胶套 | Z3: Louise Lu | AA3: 9.86 | AB3: =I3*AA3 -> 1064.88 | AD3: 71172-S001-1L | AE3: 已入 | AO3: =I3 -> 108 | AP3: =I3 -> 108 | AR3: =I3 -> 108
A4: 46078 | B4: KMART AUSTRALIA LTD | C4: 澳大利亚 | D4: 4500193539 | E4: 21431979 | F4: 4500193539-40 | G4: 71172-S001 | H4: 大脑 | I4: 1392 | J4: 0 | K4: 4 | L4: =I4/K4 -> 348 | M4: 46121 | N4: 46123 | O4: N/A | P4: PASS | Q4: 4/13上午入仓 | S4: 有 | T4: 46088 | U4: 46099 | Y4: 日期码格式：ZURU INC(BVI) 标准格式 日期：按实际生产日期 Packaging Info: 77772GQ1:MA英语UPC版本包装（收缩膜和说明书, MA首选1L，如无1L可用多语且含英语的配套多语包装) +防盜贴纸(贴纸以及防盜贴纸位置图翻单PO#4500193539)+ 两张张覆盖PDQ上唱片的贴纸+两张张覆盖收藏指南上唱片的贴纸+一张覆盖PDQ上数字"45"的贴纸+一张覆盖收藏指南上数字"45"的贴纸+箱唛+外箱贴纸SSCC Label 配比信息：4 mini vinyls,1 accessory Removed了 ""Messy <(>&<)> Delicious""两张唱片 77794UQ1:MA英语UPC版本包装（收缩膜和说明书, MA首选1L，如无1L可用多语且含英语的配套多语包装) +1张锂电池黑白书纸 + 1张防盗贴纸+ 箱唛 + 外箱SSCC La bel 77843GQ1：MA英语UPC版本包装（MA首选1L，如无1L可用多语且含英语的配套多语包装) +箱唛 + 外箱SSCC Label 77843-sushi <(>&<)> rainbow cake: MA sushi <(>&<)> rainbow cake专用黑白说明书+ 1张防盗贴纸 77843-其他款:MA UV灯说明书+1张防盗贴纸+1张说明书上面加警告语贴纸+1张收缩膜纽扣电池警告语贴纸 配比信息：Ratio: PIZZA: HAMBURGER: PANCAKES: BUBBLE TEA: Matcha TEA: TACO: SUSHI: DONUT: Charcuterie Board: RAINBOW CAKE(Rare)=10.88%: 10.88%: 10.88%: 10.88%: 10.88%: 10.88%: 10.88%: 10.88%: 10.88%: 2.08%=68:68:68:68:68:68:68:68:68:13 71172：MA英语UPC版本包装（收缩膜和说明书, MA首选1L，如无1L可用多语且含英语的配套多语包装) + 一张防盗贴纸+箱唛 + 外箱SSCC Label 3PCS AA BATTERIES(INCLUDED) Remark: 1.请务必按时完货，验货。并且按期送货入货代指定仓库，如果晚了导致船期Delay将会有罚金产生或者客户要求空运，所产生的罚金和空运费由工厂承担。 2.SSCC 外箱贴纸请同纸箱瓦楞纸方向（竖纹向）垂直，即外箱贴纸横着贴(注意条码不要被胶带粘住），贴1pc，贴1面正唛，封箱胶纸不能挡住贴纸内容。外箱贴纸 离外箱边距离不少于2cm。 3.外箱材质为ZURU标准； 4.此单需使用KMART封箱胶上下工字型封箱;从2019年6月开始，要用KMART 新版封箱胶带，此单要用"ANKO"封箱胶带 5.此单出口澳大利亚，请按相应的澳新标准生产； 6.产品和包装上生产批号的显示格式ZURU标准日期码格式 7.外箱信息不可手写，重量和体积需要与实际的一致(不可手写） 8. 每款item装箱后的G.W.超过10KG或者CBM超过0.13,(9.5KG或者以上，四舍五入后也属于10KG) 需在外箱上加印超 重或者Bulky LOGO，若发现我们资料没有，请 帮忙提醒 1)重量超过10kg但不超过16kg且CBM不超过0.13,10-16kg 超重logo 2）CBM超过0.13且重量少于17kg，bulky logo 3）不属于以上两种情况，需要使用相应重量范围内的超重logo 4）超重logo需要在外箱四面都印刷(箱唛右上角，两面侧唛超重logo需要尽量靠近毛重)，尺寸为:110mm height* 95mm width 9. 实际外箱重量跟印在箱唛上的数据差异不能超3%，尺寸按实际数据印刷 71172实际上走LCL散货出柜，请注意此订单与NZ po#4500193541一起合并计算 77772务必赶最晚5/11上午交仓 旧桶身小硅胶管柱未加高：打防水胶+产线现有硅胶套 | Z4: Louise Lu | AA4: 9.86 | AB4: =I4*AA4 -> 13725.12 | AD4: 71172-S001-1L | AE4: 已入 | AO4: =I4 -> 1392 | AP4: =I4 -> 1392 | AR4: =I4 -> 1392
A5: 46065 | B5: KANDYTOYS LIMITED | C5: 英国 | D5: 4500193688 | E5: AS191225ZUR15 274 | F5: 4500193688-100 | G5: 71172-S001 | H5: 大脑 | I5: 500 | J5: 0 | K5: 4 | L5: =I5/K5 -> 125 | M5: 46125 | N5: 46125 | O5: N/A | P5: PASS | Q5: 计划4/18装柜 | S5: 无 | T5: 46091 | U5: 46125 | Y5: 日期码格式：ZURU INC(BVI) 标准格式 日期：按实际生产日期 Packaging Info: 71172-S001:MA UPC包装+WEEE 30L 带电池说明书 B Remark: 1.订单出英国，请注意检查产品及包装应带UKCA图标，包装需要显示ZURU UK LTD/ZURU France地址信息，QC同事请查核，如有问题与跟单确认。 2.生产日期按实际的（法定工作日），按ZURU标准格式即可 ，并需要在出货前提供每个产品外包上对应的生产日期明细 3.请注意所有订单都需要经过ZURU QC验货并且通过后方可出货 4.一个产品一个条码，单款有多个子件条码的请让跟单提供贴纸覆盖。 5.外箱上的条码请确保清晰可扫描，有PDQ， 需要在PDQ底部贴一张带条码并可扫描的贴纸(ZURU 跟单提供模板）。 6.所有产品按符合欧洲标准走货，微塑料需合规并增加IFUD声明，含电池的需要增加WEEE说明书。 旧桶身小硅胶管柱未加高：打防水胶+产线现有硅胶套 | Z5: Zoe Zhou | AA5: 9.86 | AB5: =I5*AA5 -> 4930 | AD5: 71172-S001-1L | AE5: 已入 | AO5: =I5 -> 500 | AP5: =I5 -> 500 | AR5: =I5 -> 500
A6: 46059 | B6: ZURU LLC | C6: 美国 | D6: 4500193356 | E6: 5200008960 | F6: 4500193356-10 | G6: 71172-S001-FS | H6: 大脑 | I6: 20 | J6: 0 | K6: 4 | L6: =I6/K6 -> 5 | M6: 46118 | N6: 46126 | O6: N/A | P6: PASS | S6: 无 | T6: 3/17更新 | U6: 46060 | Y6: 日期码格式：DGYYYYMMDD(日期避开周末和法定节假日) 日期：按实际生产日期 Packaging Info: WMUS FAST START 项目要求: 1. 包装要求：MA 1L包装+MA说明书 (不需要客供RFID贴纸) Remark: 2. 此单New UPC与STD不同，需加贴New UPC贴纸。贴前须用黑色笔将原UPC条码完全涂黑，使其无法扫描，再粘贴新UPC贴纸。 3.#71172——71172-S001-FS UPC：193052109309 GTIN：10193052109306 4. 外箱印四面唛头信息，默认正唛和侧唛各两面。参考提供模版，排版供确认后，才能生产。 外箱需印刷外箱GTIN barcode（格式：ITF-14） ，确保清晰可见，可正常扫描。 MFG：DGYYYYMMDD（两面正唛打日期码） Gross weight/lbs: 可手写上去 5. 此MTS订单不需要第三方抽板验货，但是要通过ZURU QC验货PASS后才能出货。 空运到3PL仓库。 旧桶身小硅胶管柱未加高：打防水胶+产线现有硅胶套 | Z6: Nikki Mo | AA6: 5.916 | AB6: =I6*AA6 -> 118.32 | AC6: ZB05678-8.17 | AD6: 71172-S001-1L | AE6: 已入 | AO6: =I6 -> 20 | AP6: =I6 -> 20 | AR6: =I6 -> 20
A7: 46094 | B7: ZURU NEW ZEALAND LIMITED | C7: 新西兰 | D7: 4500196745 | E7: 5200009279 | F7: 4500196745-50 | G7: 71172-S001-FS | H7: 大脑 | I7: 20 | J7: 0 | K7: 4 | L7: =I7/K7 -> 5 | M7: 46121 | N7: 46126 | O7: N/A | P7: PASS | Q7: 46128 | R7: 需要增加隔电片和加工电池盖做货 | S7: 无 | T7: 46094 | U7: 46104 | Y7: 日期码格式：ZURU INC(BVI) 标准格式 日期：按实际生产日期 Packaging Info: 71172：MA英语UPC版本包装（收缩膜和说明书, MA首选1L，如无1L可用多语且含英语的配套多语包装) + 1张fast start专用UPC贴纸+贴一张黄色A4纸，印"fast sta rt"内容。（两张贴纸及位置图翻单4500189979)+箱唛 3PCS AA BATTERIES(INCLUDED) Remark: 1.请务必按时完货，验货。并且按期送货入货代指定仓库，如果晚了导致船期Delay将会有罚金产生或者客户要求空运，所产生的罚金和空运费由工厂承担。 2.外箱材质为ZURU标准； 3.此单需使用KMART封箱胶上下工字型封箱;从2019年6月开始，要用KMART 新版封箱胶带，此单要用"ANKO"封箱胶带 4.此单出口新西兰，请按相应的澳新标准生产； 5.产品和包装上生产批号的显示格式ZURU标准日期码格式 6.外箱信息不可手写，重量和体积需要与实际的一致(不可手写） 7. 实际外箱重量跟印在箱唛上的数据差异不能超3%，尺寸按实际数据印刷 旧桶身小硅胶管柱未加高：打防水胶+产线现有硅胶套 | Z7: Louise Lu | AA7: 9.86 | AB7: =I7*AA7 -> 197.2 | AD7: 71172-S001-1L | AE7: 已入 | AO7: =I7 -> 20 | AP7: =I7 -> 20 | AR7: =I7 -> 20
A8: 46065 | B8: TARGET US | C8: 美国 | D8: 4500193071 | E8: 10001662903-3890 | F8: 4500193071-10 | G8: 71172-S001 | H8: 大脑 | I8: 188 | J8: 0 | K8: 4 | L8: =I8/K8 -> 47 | M8: 46119 | N8: 46127 | O8: N/A | P8: PASS | Q8: 4/16客上柜 | S8: 有 | T8: 46085 | U8: 2/7收到Event Label,3/12收外箱贴纸 | Y8: 日期码格式：ZURU INC(BVI) 标准格式 日期：按实际生产日期 Packaging Info: 产品包装MA 1L彩盒 Remark: 1. 71172-S001-ROBO ALIVE-BRAIN-SERIES 1-BRIAN THE BRAIN-OPEN BOX-4PCS/CTN 2. 产品包装MA 1L彩盒；彩盒上的UPC显示193052098443； 3. 每个外箱正唛箱唛信息左上方位置粘贴条码箱贴纸，每箱只贴一张; 由ZURU向艾利订购， 对应的外箱贴DPCI：087-02-9468, UPC显示10193052098440 ； 4. 每个外箱正唛信息的右侧需要贴一张Event Label，贴纸内容显示 7/19 TRANSITION TOYS Set Date 7/19/2026，工厂自行订购； 5. 产品和包装上要印刷tracking code信息，格式为ZURU常规； 6. 出货方式：货代自提 旧桶身小硅胶管柱未加高：打防水胶+产线现有硅胶套 | Z8: Holly Zheng | AA8: 5.82 | AB8: =I8*AA8 -> 1094.16 | AC8: ZB05677-8.17 | AD8: 71172-S001-1L | AE8: 已入 | AO8: =I8 -> 188 | AP8: =I8 -> 188 | AR8: =I8 -> 188
A9: 46079 | B9: TARGET US | C9: 美国 | D9: 4500194286 | E9: 10001662883-3 890 | F9: 4500194286-10 | G9: 71172-S001 | H9: 大脑 | I9: 3828 | J9: 0 | K9: 4 | L9: =I9/K9 -> 957 | M9: 46119 | N9: 46127 | O9: N/A | P9: PASS | Q9: 4/16客上柜-168PCS,4/18客上柜-3660PCS | S9: 有 | T9: 46085 | U9: 2/7收到Event Label,3/12收外箱贴纸 | Y9: 日期码格式：ZURU INC(BVI) 标准格式 日期：按实际生产日期 Packaging Info: 产品包装MA 1L彩盒 Remark: 1. 71172-S001-ROBO ALIVE-BRAIN-SERIES 1-BRIAN THE BRAIN-OPEN BOX-4PCS/CTN 2. 产品包装MA 1L彩盒；彩盒上的UPC显示193052098443； 3. 每个外箱正唛箱唛信息左上方位置粘贴条码箱贴纸，每箱只贴一张; 由ZURU向艾利订购， 对应的外箱贴DPCI：087-02-9468, UPC显示10193052098440 ； 4. 每个外箱正唛信息的右侧需要贴一张Event Label，贴纸内容显示 7/19 TRANSITION TOYS Set Date 7/19/2026，工厂自行订购；贴纸资料翻单4500193070； 5. 产品和包装上要印刷tracking code信息，格式为ZURU常规； 6. 出货方式：货代自提 此PO有新旧桶，新桶有打A | Z9: Holly Zheng | AA9: 5.82 | AB9: =I9*AA9 -> 22278.96 | AC9: ZB05675/ZB05676 | AD9: 71172-S001-1L | AE9: 已入 | AO9: =I9 -> 3828 | AP9: =I9 -> 3828 | AR9: =I9 -> 3828
A10: 46086 | B10: KMART AUSTRALIA LTD | C10: 澳大利亚 | D10: 4500193164 | E10: 21570516 | F10: 4500193164-30 | G10: 71172-S001 | H10: 大脑 | I10: 1320 | J10: 0 | K10: 4 | L10: =I10/K10 -> 330 | M10: 46125 | N10: 46129 | O10: N/A | P10: PASS | Q10: 4/15-4/17入仓，在申请4/18上午入仓 | S10: 有 | T10: 46093 | U10: 46105 | Y10: 日期码格式：ZURU INC(BVI) 标准格式 日期：按实际生产日期 Packaging Info: 71172：MA英语UPC版本包装（收缩膜和说明书, MA首选1L，如无1L可用多语且含英语的配套多语包装) + 一张防盗贴纸（贴纸资料及位置图翻单PO#4500193539）+箱 唛 + 外箱SSCC Label 3PCS AA BATTERIES(INCLUDED) Remark: 1.请务必按时完货，验货。并且按期送货入货代指定仓库，如果晚了导致船期Delay将会有罚金产生或者客户要求空运，所产生的罚金和空运费由工厂承担。 2.SSCC 外箱贴纸请同纸箱瓦楞纸方向（竖纹向）垂直，即外箱贴纸横着贴(注意条码不要被胶带粘住），贴1pc，贴1面正唛，封箱胶纸不能挡住贴纸内容。外箱贴纸 离外箱边距离不少于2cm。 3.外箱材质为ZURU标准； 4.此单需使用KMART封箱胶上下工字型封箱;从2019年6月开始，要用KMART 新版封箱胶带，此单要用"ANKO"封箱胶带 5.此单出口澳大利亚，请按相应的澳新标准生产； 6.产品和包装上生产批号的显示格式ZURU标准日期码格式 7.外箱信息不可手写，重量和体积需要与实际的一致(不可手写） 8. 每款item装箱后的G.W.超过10KG或者CBM超过0.13,(9.5KG或者以上，四舍五入后也属于10KG) 需在外箱上加印超 重或者Bulky LOGO，若发现我们资料没有，请 帮忙提醒 1)重量超过10kg但不超过16kg且CBM不超过0.13,10-16kg 超重logo 2）CBM超过0.13且重量少于17kg，bulky logo 3）不属于以上两种情况，需要使用相应重量范围内的超重logo 4）超重logo需要在外箱四面都印刷(箱唛右上角，两面侧唛超重logo需要尽量靠近毛重)，尺寸为:110mm height* 95mm width 9. 实际外箱重量跟印在箱唛上的数据差异不能超3%，尺寸按实际数据印刷 请注意此订单与NZ PO#4500193165一起合并计算，71172实际上是LCL散货出柜 旧桶身小硅胶管柱未加高：打防水胶+产线现有硅胶套 | Z10: Louise Lu | AA10: 9.86 | AB10: =I10*AA10 -> 13015.2 | AD10: 71172-S001-1L | AE10: 已入 | AO10: =I10 -> 1320 | AP10: =I10 -> 1320 | AR10: =I10 -> 1320
A11: 46086 | B11: KMART AUSTRALIA LTD(NEW ZEALAND) | C11: 新西兰 | D11: 4500193165 | E11: 21570517 | F11: 4500193165-40 | G11: 71172-S001 | H11: 大脑 | I11: 180 | J11: 0 | K11: 4 | L11: =I11/K11 -> 45 | M11: 46125 | N11: 46129 | O11: N/A | P11: PASS | Q11: 4/15-4/17入仓，在申请4/18上午入仓 | S11: 有 | T11: 46093 | U11: 46105 | Y11: 日期码格式：ZURU INC(BVI) 标准格式 日期：按实际生产日期 Packaging Info: 71172：MA英语UPC版本包装（收缩膜和说明书, MA首选1L，如无1L可用多语且含英语的配套多语包装) + 一张防盗贴纸（贴纸资料及位置图翻单PO#4500193539）+箱 唛 + 外箱SSCC Label 3PCS AA BATTERIES(INCLUDED) Remark: 1.请务必按时完货，验货。并且按期送货入货代指定仓库，如果晚了导致船期Delay将会有罚金产生或者客户要求空运，所产生的罚金和空运费由工厂承担。 2.SSCC 外箱贴纸请同纸箱瓦楞纸方向（竖纹向）垂直，即外箱贴纸横着贴(注意条码不要被胶带粘住），贴1pc，贴1面正唛，封箱胶纸不能挡住贴纸内容。外箱贴纸 离外箱边距离不少于2cm。 3.外箱材质为ZURU标准； 4.此单需使用KMART封箱胶上下工字型封箱;从2019年6月开始，要用KMART 新版封箱胶带，此单要用"ANKO"封箱胶带 5.此单出口新西兰，请按相应的澳新标准生产； 6.产品和包装上生产批号的显示格式ZURU标准日期码格式 7.外箱信息不可手写，重量和体积需要与实际的一致(不可手写） 8. 每款item装箱后的G.W.超过10KG或者CBM超过0.13,(9.5KG或者以上，四舍五入后也属于10KG) 需在外箱上加印超 重或者Bulky LOGO，若发现我们资料没有，请 帮忙提醒 1)重量超过10kg但不超过16kg且CBM不超过0.13,10-16kg 超重logo 2）CBM超过0.13且重量少于17kg，bulky logo 3）不属于以上两种情况，需要使用相应重量范围内的超重logo 4）超重logo需要在外箱四面都印刷(箱唛右上角，两面侧唛超重logo需要尽量靠近毛重)，尺寸为:110mm height* 95mm width 9. 实际外箱重量跟印在箱唛上的数据差异不能超3%，尺寸按实际数据印刷 请注意此订单与AU PO#4500193164一起合并计算，71172实际上为LCL散货出柜 新桶身小硅胶管柱加高：未打防水胶+新开小一点有硅胶套 | Z11: Louise Lu | AA11: 9.86 | AB11: =I11*AA11 -> 1774.8 | AD11: 71172-S001-1L | AE11: 已入 | AO11: =I11 -> 180 | AP11: =I11 -> 180 | AR11: =I11 -> 180
A12: 46022 | D12: ZPO2512023 | G12: 71172-S001 | H12: 大脑 | I12: 500 | J12: 0 | K12: 4 | L12: =I12/K12 -> 125 | M12: 46042 | N12: 46133 | O12: N/A | P12: PASS | R12: 用第二次PP阶段订购的彩盒包装 | S12: N/A | T12: 空白箱 | U12: 无 | Y12: 新桶身小硅胶管柱加高：未打防水胶+新开小一点有硅胶套 | AD12: 71172-S001-1L | AE12: 已入
A13: 46091 | B13: SMYTHS TOYS EU HQ UC | C13: 德国 | D13: 4500195772 | E13: 4400545646 | F13: 4500195772-70 | G13: 71172-S001 | H13: 大脑 | I13: 1800 | J13: 0 | K13: 4 | L13: =I13/K13 -> 450 | M13: 46127 | N13: 46133 | O13: N/A | P13: PASS | Q13: 4/21截SI | S13: 无 | T13: 46095 | U13: 46100 | Y13: 日期码格式：ZURU INC(BVI) 标准格式 日期：按实际生产日期 Packaging Info: 71172: MA3L-23Lwarning彩盒+1张德语callout贴纸(本单放稿)+C版WEEE声明(带电池)走货欧洲通用29L说明书 EAN#4894680057272 3PCS AA BATTERIES(INCLUDED) Remark: Smyths 德国 1. 请准时出货，推期会有罚款； 2. 所有产品按符合欧洲标准走货，需要是不含微塑料版本。 3. 所有电子产品身上需要加字唛，为ZURU FRANCE 地址 (如无电子产品，产品布标有此地址，或产品太小无法增加可忽略此信息)，新地址ZURU FRANCE.33 rue Pa ul Meurice 75020 Paris, France. 4. 电子产品需增加一张C版WEEE声明29L通用黑白说明书(不接受A版本，翻译有误)，区分带电池和不带电池出货版本, 如已做客版说明书可忽略此要求；如包装备注 上缺少此部分信息，请提醒跟单更新备注。 5.所有出往德国市场有关slime和带香味的都需要出无硼无香版本； 6.订单备注显示有分批的(不同仓库/订单号), 一定要区分客户订单号做货出货，否则会导致罚款 。 7.包装日期码按ZURU格式即可，请确保不迟于外箱日期码，可等于或者早于外箱日期码，必须为法定工作日。 8.做货前请先复核包装条码与订单是否一致再安排，对不上的需与ZURU跟单确认再安排。 9.包装必须含法国回收标(Sorting Label)，如没有，请提醒跟单提供贴纸资料。 新桶身小硅胶管柱加高：未打防水胶+新开小一点有硅胶套 | Z13: Sherry Lu | AA13: 9.86 | AB13: =I13*AA13 -> 17748 | AD13: 71172-S001-3L | AE13: 已入 | AO13: =I13 -> 1800 | AQ13: =I13 -> 1800 | AR13: =I13 -> 1800
A14: 46093 | B14: SMYTHS TOYS HQ UC UK | C14: 英国 | D14: 4500196579 | E14: 4400544507 | F14: 4500196579-10 | G14: 71172-S001 | H14: 大脑 | I14: 2500 | J14: 0 | K14: 4 | L14: =I14/K14 -> 625 | M14: 46125 | N14: 46134 | O14: N/A | P14: PASS | Q14: 4/24截SI | S14: 无 | T14: 46094 | U14: 46093 | Y14: 日期码格式：ZURU INC(BVI) 标准格式 日期：按实际生产日期 Packaging Info: "71172: MA3L-23Lwarning彩盒(含法国sorting label)+C版WEEE声明(带电池)走货欧洲通用29L说明书 EAN#4894680057272 3PCS AA BATTERIES(INCLUDED)" Remark: Smyths 英国/爱尔兰 1. 请准时出货，推期会有罚款； 2. 所有产品按符合欧洲标准走货，需要是不含微塑料版本。 3.包装日期码按ZURU格式即可，请确保不迟于外箱日期码，可等于或者早于外箱日期码，必须为法定工作日，印刷前请先检查外箱日期码。 4.请注意检查产品及包装应带UKCA图标（14+产品除外），包装显示ZURU UK LTD/ZURU France地址信息，QC部门请查核，如有问题与跟单确认 5.电子产品需增加一张C版WEEE声明29L通用黑白说明书(不接受A版本，翻译有误)，区分带电池和不带电池出货版本, 如已做客版说明书可忽略此要求；如包装备注 上缺少此部分信息，请提醒跟单更新备注。 6.订单备注显示有分批的(不同仓库/订单号), 一定要区分客户订单号做货出货，否则会导致罚款 。 7.做货前请先复核包装条码与订单是否一致再安排，对不上的需与ZURU跟单确认再安排。 8.包装必须含法国回收标(Sorting Label)，如没有，请提醒跟单提供贴纸资料。 新桶身小硅胶管柱加高：未打防水胶+新开小一点有硅胶套 | Z14: Sherry Lu | AA14: 9.86 | AB14: =I14*AA14 -> 24650 | AD14: 71172-S001-3L | AE14: 已入 | AO14: =I14 -> 2500 | AQ14: =I14 -> 2500 | AR14: =I14 -> 2500
A15: 46091 | B15: SMYTHS TOYS HQ UC IE | C15: 爱尔兰 | D15: 4500195833 | E15: 4400544510 | F15: 4500195833-40 | G15: 71172-S001 | H15: 大脑 | I15: 500 | J15: 0 | K15: 4 | L15: =I15/K15 -> 125 | M15: 46129 | N15: 46136 | O15: N/A | P15: PASS | Q15: 4/27截SI | S15: 无 | T15: 46095 | U15: 46093 | Y15: 日期码格式：ZURU INC(BVI) 标准格式 日期：按实际生产日期 Packaging Info: 71172: MA3L-23Lwarning彩盒(含法国sorting label)+C版WEEE声明(带电池)走货欧洲通用29L说明书 EAN#4894680057272 3PCS AA BATTERIES(INCLUDED) Remark: Smyths 英国/爱尔兰 1. 请准时出货，推期会有罚款； 2. 所有产品按符合欧洲标准走货，需要是不含微塑料版本。 3.包装日期码按ZURU格式即可，请确保不迟于外箱日期码，可等于或者早于外箱日期码，必须为法定工作日，印刷前请先检查外箱日期码。 4.请注意检查产品及包装应带UKCA图标（14+产品除外），包装显示ZURU UK LTD/ZURU France地址信息，QC部门请查核，如有问题与跟单确认 5.电子产品需增加一张C版WEEE声明29L通用黑白说明书(不接受A版本，翻译有误)，区分带电池和不带电池出货版本, 如已做客版说明书可忽略此要求；如包装备注 上缺少此部分信息，请提醒跟单更新备注。 6.订单备注显示有分批的(不同仓库/订单号), 一定要区分客户订单号做货出货，否则会导致罚款 。 7.做货前请先复核包装条码与订单是否一致再安排，对不上的需与ZURU跟单确认再安排。 8.包装必须含法国回收标(Sorting Label)，如没有，请提醒跟单提供贴纸资料。 新桶身小硅胶管柱加高：未打防水胶+新开小一点有硅胶套 | Z15: Sherry Lu | AA15: 9.86 | AB15: =I15*AA15 -> 4930 | AD15: 71172-S001-3L | AE15: 已入 | AO15: =I15 -> 500 | AQ15: =I15 -> 500 | AR15: =I15 -> 500
A16: 46061 | B16: ASIA GOAL LIMITED TAIWAN BRANCH (H. | C16: 台湾 | D16: 4500193394 | E16: AG250407-TW | F16: 4500193394-20 | G16: 71172-S001 | H16: 大脑 | I16: 120 | J16: 0 | K16: 4 | L16: =I16/K16 -> 30 | M16: 46134 | N16: 46136 | O16: N/A | P16: PASS | S16: 无 | T16: 46067 | U16: 无 | Y16: 日期码格式：ZURU INC(BVI) 标准格式 日期：按实际生产日期 Packaging Info: 此单出TW 71172：MA 1L PKG , MA 说明书 （该款无需贴纸，出ZURU 标准包装即可） Remark: 新桶身小硅胶管柱加高：未打防水胶+新开小一点有硅胶套 | Z16: Chelsea Luo | AA16: 9.86 | AB16: =I16*AA16 -> 1183.2 | AD16: 71172-S001-1L | AE16: 已入 | AO16: =I16 -> 120 | AP16: =I16 -> 120 | AR16: =I16 -> 120
A17: 46094 | B17: ARGOS LIMITED | C17: 英国 | D17: 4500196827 | F17: 4500196827-20 | G17: 71172-S001 | H17: 大脑 | I17: 500 | J17: 0 | K17: 4 | L17: =I17/K17 -> 125 | M17: 46133 | N17: 46139 | O17: N/A | P17: PASS | Q17: 4/27截SI | S17: 无 | T17: 46106 | U17: 46106 | Y17: 日期码格式：ZURU INC(BVI) 标准格式 日期：按实际生产日期 Packaging Info: 71172： MA 包装+客人白色Cat.label 1张; MA说明书+WEEE带电池说明书 2.注意Cat.label （要求易撕类贴纸，但是粘性不能过低），同时此贴纸每个订单都是不相同的（会显示客户对应的订单号），切勿翻旧订单购买。此贴纸由ZURU提 供贴纸图稿和贴纸位置图给工厂后，工厂自行购买。 3.请先检查条码是否正确再安排做，标签上的目录编号数字高度必须至少为5mm （14.17pt） Remark: 新桶身小硅胶管柱加高：未打防水胶+新开小一点有硅胶套 | Z17: Lena Huang | AA17: 9.86 | AB17: =I17*AA17 -> 4930 | AD17: 71172-S001-1L | AE17: 已入 | AO17: =I17 -> 500 | AP17: =I17 -> 500 | AR17: =I17 -> 500
A18: 46083 | B18: AMAZON.COM SERVICES LLC | C18: 美国 | D18: 4500194918 | E18: 8V4WFTAX | F18: 4500194918-10 | G18: 71172-S003-MB | H18: 大脑（邮包盒装） | I18: 84 | J18: 0 | K18: 4 | L18: =I18/K18 -> 21 | M18: 46140 | N18: 46140 | O18: N/A | P18: PASS | Q18: 4/29截SI | S18: 有 | T18: 46084 | U18: 46123 | Y18: 日期码格式：ZURU INC(BVI) 标准格式 日期：按实际生产日期 Packaging Info: #71172:MA 1L UPC版本 #71172带MA包装入邮包盒，邮包盒图稿翻单4500192525。 Remark: 1. Amazon MDDP订单，出口US。 2. 日期码使用ZURU标准版本。 3. 如果大货有要求入邮包盒，则对应的邮包盒上面要打上日期码。 4. 箱尺寸要求：外箱最长边不能超过25"(超过了，case pack只能为1)，不符合要求的大货，一律不接受。 5. 外箱箱唛要求： ①外箱正面印ZURU Logo+SSCC Label(客供贴纸，由跟单订购)。关于 SSCC Label 请注意： SSCC Label显示的是客人自己的item#。每一张SSCC label都是唯一且有不同流水及条码的，没有损耗，绝对不可贴错。如果贴错或损坏任何一张，都会导致全部都 错，千万要注意！SSCC Label必须贴在外箱正面的正中间位置(贴一面即可)，并且贴纸离外箱边距必须至少3cm(可以覆盖Logo<(>&<)>箱唛)，否则会影响到客户那边 仓库的扫描识别。 ②外箱侧面印item#(订单上显示的SKU#)+carton size(以工厂实际尺寸为准，单位: inch)+MADE IN CHINA，日期使用ZURU 标准版本。 6. 装柜要求：按照客户PO#装柜/箱号顺序装柜，跟单会提前给到装柜计划。 在大货生产/仓库存放时，请留意该装柜要求，以便装柜时不混乱(避免装错/装漏/找不到货号等)。 新桶身小硅胶管柱加高：未打防水胶+新开小一点有硅胶套 | Z18: Kelly Shen/Mia Pan/P | AA18: 5.916 | AB18: =I18*AA18 -> 496.944 | AC18: ZB05653-8.17 | AD18: 71172-S003-MB-1L | AE18: 已入 | AO18: =I18 -> 84 | AP18: =I18 -> 84 | AR18: =I18 -> 84
A19: 46091 | B19: SMYTHS TOYS EU HQ UNLIMITED COMPANY | C19: 法国 | D19: 4500195839 | E19: 4400544509 | F19: 4500195839-40 | G19: 71172-S001 | H19: 大脑 | I19: 216 | J19: 0 | K19: 4 | L19: =I19/K19 -> 54 | M19: 46129 | N19: 46141 | O19: N/A | P19: PASS | Q19: 4/30送库有拼柜 | S19: 无 | T19: 46095 | U19: 46093 | Y19: 日期码格式：ZURU INC(BVI) 标准格式 日期：按实际生产日期 Packaging Info: 71172: MA3L-23Lwarning彩盒(含法国sorting label)+C版WEEE声明(带电池)走货欧洲通用29L说明书 EAN#4894680057272 3PCS AA BATTERIES(INCLUDED) Remark: Smyths 法国 1. 请准时出货，推期会有罚款； 2. 所有产品按符合欧洲标准走货，需要是不含微塑料版本。 3. 电子产品需增加一张C版WEEE声明29L通用黑白说明书(不接受A版本，翻译有误)，区分带电池和不带电池出货版本, 如已做客版说明书可忽略此要求；如包装备注 上缺少此部分信息，请提醒跟单更新备注。 4. 出口法国的产品, 法规规定禁止在包装和共公众用的印刷品中使用矿物油中含有的物质, 包装印刷油墨中含有的MOAH/MOSH的质量浓度不能超过0.1%, 否则出货 到法国被抽检出现问题, 供应商需要对此负责; 5.订单备注显示有分批的(不同仓库/订单号), 一定要区分客户订单号做货出货，否则会导致罚款 。 6.包装日期码按ZURU格式即可，请确保不迟于外箱日期码，可等于或者早于外箱日期码，必须为法定工作日。 7.做货前请先复核包装条码与订单是否一致再安排，对不上的需与ZURU跟单确认再安排。 8.包装必须含法国回收标(Sorting Label)，如没有，请提醒跟单提供贴纸资料。 新桶身小硅胶管柱加高：未打防水胶+新开小一点有硅胶套 | Z19: Sherry Lu | AA19: 9.86 | AB19: =I19*AA19 -> 2129.76 | AD19: 71172-S001-3L | AE19: 已入 | AO19: =I19 -> 216 | AQ19: =I19 -> 216 | AR19: =I19 -> 216
A20: 46061 | B20: ASIA GOAL LIMITED TAIWAN BRANCH (H. | C20: 香港 | D20: 4500193390 | E20: AG250406-HK | F20: 4500193390-20 | G20: 71172-S001 | H20: 大脑 | I20: 120 | J20: 0 | K20: 4 | L20: =I20/K20 -> 30 | M20: 46134 | N20: 46141 | O20: N/A | P20: PASS | Q20: 4/30客上柜 | S20: 无 | T20: 46067 | U20: 46105 | Y20: 日期码格式：ZURU INC(BVI) 标准格式 日期：按实际生产日期 Packaging Info: 此单出HK 71172：MA 1L PKG, MA 说明书+ HK客供警语贴纸 ， 1张贴彩盒底部，1张客供电池警语贴纸贴彩盒底部，1张贴说明书 新桶身小硅胶管柱加高：未打防水胶+新开小一点有硅胶套 新桶身小硅胶管柱加高：未打防水胶+新开小一点有硅胶套 | Z20: Chelsea Luo | AA20: 9.86 | AB20: =I20*AA20 -> 1183.2 | AD20: 71172-S001-1L | AE20: 已入 | AO20: =I20 -> 120 | AP20: =I20 -> 120 | AR20: =I20 -> 120
A21: 46091 | B21: SMYTHS TOYS EU HQ UNLIMITED COMPANY | C21: 法国 | D21: 4500195839 | E21: 4400544508 | F21: 4500195839-30 | G21: 71172-S001 | H21: 大脑 | I21: 444 | J21: 0 | K21: 4 | L21: =I21/K21 -> 111 | M21: 46129 | N21: 46142 | O21: N/A | P21: PASS | Q21: 5/4截SI | S21: 无 | T21: 46095 | U21: 46093 | Y21: 日期码格式：ZURU INC(BVI) 标准格式 日期：按实际生产日期 Packaging Info: 71172: MA3L-23Lwarning彩盒(含法国sorting label)+C版WEEE声明(带电池)走货欧洲通用29L说明书 EAN#4894680057272 3PCS AA BATTERIES(INCLUDED) Remark: Smyths 法国 1. 请准时出货，推期会有罚款； 2. 所有产品按符合欧洲标准走货，需要是不含微塑料版本。 3. 电子产品需增加一张C版WEEE声明29L通用黑白说明书(不接受A版本，翻译有误)，区分带电池和不带电池出货版本, 如已做客版说明书可忽略此要求；如包装备注 上缺少此部分信息，请提醒跟单更新备注。 4. 出口法国的产品, 法规规定禁止在包装和共公众用的印刷品中使用矿物油中含有的物质, 包装印刷油墨中含有的MOAH/MOSH的质量浓度不能超过0.1%, 否则出货 到法国被抽检出现问题, 供应商需要对此负责; 5.订单备注显示有分批的(不同仓库/订单号), 一定要区分客户订单号做货出货，否则会导致罚款 。 6.包装日期码按ZURU格式即可，请确保不迟于外箱日期码，可等于或者早于外箱日期码，必须为法定工作日。 7.做货前请先复核包装条码与订单是否一致再安排，对不上的需与ZURU跟单确认再安排。 8.包装必须含法国回收标(Sorting Label)，如没有，请提醒跟单提供贴纸资料。 新桶身小硅胶管柱加高：未打防水胶+新开小一点有硅胶套 | Z21: Sherry Lu | AA21: 9.86 | AB21: =I21*AA21 -> 4377.84 | AD21: 71172-S001-3L | AE21: 已入 | AO21: =I21 -> 444 | AQ21: =I21 -> 444 | AR21: =I21 -> 444
A22: 46083 | B22: AMAZON.COM SERVICES LLC | C22: 美国 | D22: 4500194919 | E22: 2ZFDDQ7I | F22: 4500194919-10 | G22: 71172-S003-MB | H22: 大脑（邮包盒装） | I22: 268 | J22: 0 | K22: 4 | L22: =I22/K22 -> 67 | M22: 46140 | N22: 46142 | O22: N/A | P22: PASS | Q22: 5/5截SI | S22: 有 | T22: 46084 | U22: 46123 | Y22: 日期码格式：ZURU INC(BVI) 标准格式 日期：按实际生产日期 Packaging Info: #71172:MA 1L UPC版本 #71172带MA包装入邮包盒，邮包盒图稿翻单4500192525。 Remark: 1. Amazon MDDP订单，出口US。 2. 日期码使用ZURU标准版本。 3. 如果大货有要求入邮包盒，则对应的邮包盒上面要打上日期码。 4. 箱尺寸要求：外箱最长边不能超过25"(超过了，case pack只能为1)，不符合要求的大货，一律不接受。 5. 外箱箱唛要求： ①外箱正面印ZURU Logo+SSCC Label(客供贴纸，由跟单订购)。关于 SSCC Label 请注意： SSCC Label显示的是客人自己的item#。每一张SSCC label都是唯一且有不同流水及条码的，没有损耗，绝对不可贴错。如果贴错或损坏任何一张，都会导致全部都 错，千万要注意！SSCC Label必须贴在外箱正面的正中间位置(贴一面即可)，并且贴纸离外箱边距必须至少3cm(可以覆盖Logo<(>&<)>箱唛)，否则会影响到客户那边 仓库的扫描识别。 ②外箱侧面印item#(订单上显示的SKU#)+carton size(以工厂实际尺寸为准，单位: inch)+MADE IN CHINA，日期使用ZURU 标准版本。 6. 装柜要求：按照客户PO#装柜/箱号顺序装柜，跟单会提前给到装柜计划。 在大货生产/仓库存放时，请留意该装柜要求，以便装柜时不混乱(避免装错/装漏/找不到货号等)。 新桶身小硅胶管柱加高：未打防水胶+新开小一点有硅胶套 | Z22: Kelly Shen/Mia Pan/P | AA22: 5.916 | AB22: =I22*AA22 -> 1585.488 | AC22: ZB05654-8.17 | AD22: 71172-S003-MB-1L | AE22: 已入 | AO22: =I22 -> 268 | AP22: =I22 -> 268 | AR22: =I22 -> 268
A23: 46065 | B23: TARGET US | C23: 美国 | D23: 4500193070 | E23: 10001662884-3891 | F23: 4500193070-10 | G23: 71172-S001 | H23: 大脑 | I23: 2500 | J23: 0 | K23: 4 | L23: =I23/K23 -> 625 | M23: 46135 | N23: 46148 | O23: N/A | P23: PASS | Q23: 5/6客上柜 | S23: 有 | T23: 46085 | U23: 2/7收到Event Label,3/12收外箱贴纸 | Y23: 日期码格式：ZURU INC(BVI) 标准格式 日期：按实际生产日期 Packaging Info: 产品包装MA 1L彩盒 Remark: 1. 71172-S001-ROBO ALIVE-BRAIN-SERIES 1-BRIAN THE BRAIN-OPEN BOX-4PCS/CTN 2. 产品包装MA 1L彩盒；彩盒上的UPC显示193052098443； 3. 每个外箱正唛箱唛信息左上方位置粘贴条码箱贴纸，每箱只贴一张; 由ZURU向艾利订购， 对应的外箱贴DPCI：087-02-9468, UPC显示10193052098440 ； 4. 每个外箱正唛信息的右侧需要贴一张Event Label，贴纸内容显示 7/19 TRANSITION TOYS Set Date 7/19/2026，工厂自行订购； 5. 产品和包装上要印刷tracking code信息，格式为ZURU常规； 6. 出货方式：货代自提 | Z23: Holly Zheng | AA23: 5.82 | AB23: =I23*AA23 -> 14550 | AC23: ZB05674-8.17 | AD23: 71172-S001 | AE23: 已入 | AO23: =I23 -> 2500 | AP23: =I23 -> 2500 | AR23: =I23 -> 2500
A24: 46104 | B24: MEIJER DISTRIBUTION, INC. | C24: 美国 | D24: 4500198132 | E24: 219222806 | F24: 4500198132-10 | G24: 71172-S004 | H24: 大脑 | I24: 976 | J24: 0 | K24: 2 | L24: =I24/K24 -> 488 | M24: 46148 | N24: 46148 | O24: N/A | P24: PASS | Q24: 5/7截仓 | S24: 无 | T24: 46104 | U24: 无 | Y24: 日期码格式：ZURU INC(BVI) 标准格式 日期： Packaging Info: 1. MA UPC包装（优先1L） 2. 客人指定箱唛排版 Remark: 出货前 Zuru QC 验货 | Z24: Agnes Zheng | AA24: 5.82 | AB24: =I24*AA24 -> 5680.32 | AC24: ZB05652-8.17 | AD24: 71172-S004-1L | AE24: 已入 | AO24: =I24 -> 976 | AP24: =I24 -> 976 | AR24: =I24 -> 976
A25: 46104 | B25: MEIJER DISTRIBUTION, INC. | C25: 美国 | D25: 4500198132 | E25: 219222804 | F25: 4500198132-20 | G25: 71172-S004 | H25: 大脑 | I25: 526 | J25: 0 | K25: 2 | L25: =I25/K25 -> 263 | M25: 46148 | N25: 46148 | O25: N/A | P25: PASS | Q25: 5/8截仓 | S25: 无 | T25: 46104 | U25: 无 | Y25: 日期码格式：ZURU INC(BVI) 标准格式 日期： Packaging Info: 1. MA UPC包装（优先1L） 2. 客人指定箱唛排版 Remark: 出货前 Zuru QC 验货 | Z25: Agnes Zheng | AA25: 5.916 | AB25: =I25*AA25 -> 3111.816 | AC25: ZB05652-8.17 | AD25: 71172-S004-1L | AE25: 已入 | AO25: =I25 -> 526 | AP25: =I25 -> 526 | AR25: =I25 -> 526
A26: 46122 | B26: BIG W | C26: 澳大利亚 | D26: 4500201310 | E26: 47948601 | F26: 4500201310-10 | G26: 71172-S001 | H26: 大脑 | I26: 600 | J26: 0 | K26: 4 | L26: =I26/K26 -> 150 | M26: 46151 | N26: 46149 | O26: N/A | P26: PASS | Q26: 5/7装柜 | S26: 无 | T26: 46122 | U26: 46122 | Y26: 日期码格式：ZURU INC(BVI) 标准格式 日期：按实际生产日期 Packaging Info: 1. 包装 71172: 英文MA包装 (UPC版本，首选1L，无1L可用多L含英语)+1张进口商贴纸 2. 产品和包装上的日期码一致，请按要求在包装上打日期码（进口商贴纸不覆盖日期码） 3. 使用ZURU标准日期码 Remark: 1. 共出4港口 (SYD, BNE, MEL, FRE)，不同港口数量信息请见订单行项目，并请参考箱唛资料，港口不同，箱唛资料也不同； 2. 箱唛不可出现任何手写内容（箱数除外），重量与实际一致且不可手写； 3. 此单出澳大利亚，请按澳洲标准生产并满足当地法规要求； 4. 出无闪粉版本，需符合欧洲微塑料法规； 5. 确保所出货的产品及包装不含PFAS（全氟/多氟烷基化合物）及其盐类和其相关物质，特别留意 PFOA、PFOS、PFHxS 不得检出。 | Z26: Christine Liao | AA26: 9.7 | AB26: =I26*AA26 -> 5820 | AD26: 71172-S001-1L | AE26: 已入 | AO26: =I26 -> 600 | AP26: =I26 -> 600 | AR26: =I26 -> 600
A27: 46022 | D27: ZMPO251178 | G27: 71172-S001 | H27: 大脑 | I27: 200 | J27: 0 | K27: 4 | L27: =I27/K27 -> 50 | M27: 46042 | N27: 46150 | O27: N/A | P27: PASS | R27: 用第二次PP阶段订购的彩盒包装 | S27: N/A | T27: 空白箱 | U27: 无 | Y27: Remark:跟PP订单一起安排/大货标准箱装箱/箱唛请参照邮件附件 备注：收到样品订单后尽快安排 ，注意样板品质质量要求要高于大货品质要求 ，送货时必须要附带送货单(没有送货单和QC检验合格报告的仓库一律拒绝收货)，请知悉，谢谢！ | AD27: 71172-S001-1L | AE27: 已入 | AO27: =I27 -> 200 | AP27: =I27 -> 200 | AR27: =I27 -> 200
A28: 46051 | B28: ZURU LLC | C28: 美国 | D28: 4500192525 | E28: 5200008815 | F28: 4500192525-10 | G28: 71172-S003-MB-MTS | H28: 大脑（邮包盒装） | I28: 1000 | J28: 0 | K28: 4 | L28: =I28/K28 -> 250 | M28: 46148 | N28: 46150 | O28: N/A | P28: PASS | Q28: 5/22 SI | S28: 无 | T28: 46059 | U28: 无 | Y28: 日期码格式：ZURU INC(BVI) 标准格式 日期：按实际生产日期 Packaging Info: #71172:MA 1L UPC版本 #71172带MA包装入邮包盒，邮包盒图稿跟单提供。 Remark: 1.Amazon domestic 订单。出口美国。外箱最长边不能超过25" （超过了，case pack只能为1），不符合要求的大货，一律不接受。 2.无第三方验货/测试要求。 3.日期码使用ZURU标准版本。 4.如果大货有要求入邮包盒，则对应的邮包盒上面要打上日期码。 | Z28: SD24 | AA28: 5.916 | AB28: =I28*AA28 -> 5916 | AC28: ZB05746-8.17 | AD28: 71172-S003-MB-MTS | AE28: 已入 | AO28: =I28 -> 1000 | AP28: =I28 -> 1000 | AR28: =I28 -> 1000
A29: 46108 | B29: AMAZON EU SARL, NDL DEUTSCHLAND | C29: 英国 | D29: 4500198640 | E29: 1VCZUJZI | F29: 4500198640-280 | G29: 71172-S003-MB | H29: 大脑（邮包盒装） | I29: 712 | J29: 0 | K29: 4 | L29: =I29/K29 -> 178 | M29: 46150 | N29: 46150 | O29: N/A | P29: PASS | Q29: 46161 | S29: 有 | T29: 46108 | U29: 46139 | Y29: 日期码格式：ZURU INC(BVI) 标准格式 日期：按实际生产日期 Packaging Info: Amazon UK: 5TKIJIXX/3O77XWME/2EIMZ29W/1VCZUJZI/7N1D8FUG/5Z2UXPOL/5PNQ9H8L Amazon DE: 4EO3QWQS/3LFCI9MA/115AX8DW Amazon FR: 6VRKJU2V Amazon ES: 53YR16IV Amazon IT: 5D2ZS8EV Amazon UK(157114DG/157140/157143/15780ABD/15788G/71172/77878/92146BDG/92147E)/DE(157114G/15788BG/92146GH/92147E)/FR(92146G)/ES(157143/77858)/IT( 157140/157143/92146G) 1. 157114DG ---157114D: 1pc 15787D 9"(Rabid Rabbit) into mailbox, 12mailboxes/ctn; 客版邮包盒(参考Amazon US翻单PO#4500192979); ---157114G: 1pc 15787G 9"(Mr Screech) into mailbox, 12mailboxes/ctn; 客版邮包盒(参考Amazon US翻单PO#4500192979); 2. 157140: 2PK 15774 into window box respectively, then into polybag, 6polybags/ctn, MA 5L(5L warning UPC)B 开窗彩盒+1张贴纸(含IT环保标+西班牙洗 涤说明,参考翻单PO#4500198613)+客版透明胶袋(双面打孔+含英法德意西警告语+塑料循环标, 参考翻单PO#4500166364)+1张UPC#贴纸(贴在胶袋上,参考翻单PO#450 0198613)+1张空白贴纸(贴在彩盒条码位置, 参考翻单PO#4500198613); 3. 157143: 8PK 157117 IN MAIL BOX,12mailboxes/ctn; 8 Assortment=1:1:1:1:1:1:1:1; 客版邮包盒(参考Amazon US翻单PO#4500195274); 4. 15780ABD: ---15780A: 1pc 15780A(Rabid Rabbit/Sir Nobbynuts/Nobbybits) in window box, then into polybag,12polybags/ctn; MA 5L(5L warning UPC)B开窗彩盒+MA其 它最新配套包装+客版透明胶袋(含英法德意西荷兰警告语+双面打孔+塑料循环标)+1张贴纸(含UPC#+IT环保标+ES洗涤说明); ---15780B: 1pc 15780B(Sasquoosh/Stinkface/Squooshface) in window box, then into polybag,12polybags/ctn; MA 5L(5L warning UPC)B开窗彩盒+MA其它最 新配套包装+客版透明胶袋(含英法德意西荷兰警告语+双面打孔+塑料循环标)+1张贴纸(含UPC#+IT环保标+ES洗涤说明); ---15780D: 1pc 15780D(Munch Munch/Reek-o/Munch-o) in window box, then into polybag,12polybags/ctn; MA 5L(5L warning UPC)B开窗彩盒+MA其它最新配套 包装+客版透明胶袋(含英法德意西荷兰警告语+双面打孔+塑料循环标)+1张贴纸(含UPC#+IT环保标+ES洗涤说明); 5. 15788BG: ---15788B: 1pc 15788B 9"(Sir Nobbynuts) in window box,then into polybag, 12polybags/ctn; Global onshelf date after 2026/7/9; MA 5L(5L warning UP C)A开窗彩盒+MA其它最新配套包装+客版胶袋(含英法德意西荷兰警告语+双面打孔+塑料循环标,参考翻单PO#4500164364)+2张贴纸(1张含UPC#<(>&<)>IT环保标<(>& <)>ES洗涤说明贴纸+1张上架日期贴纸) ---15788G: 1pc 15788G 9"(Sir Belch) in window box,then into polybag, 12polybags/ctn; Global onshelf date after 2026/7/9; MA 5L(5L warning UPC)A 开窗彩盒+MA其它最新配套包装+客版胶袋(含英法德意西荷兰警告语+双面打孔+塑料循环标,参考翻单PO#4500164364)+2张贴纸(1张含UPC#<(>&<)>IT环保标<(>&<)>E S洗涤说明贴纸+1张上架日期贴纸) 6.71172: 1pc 71172 BRIAN THE BRAIN into open box, then into mailbox, 4mailboxes/ctn; 3PCS AA BATTERIES(INCLUDED); MA 1L(23L warning UPC)A开口彩 盒+MA 15L A说明书+客版邮包盒(参考Amazon US翻单PO#4500192525)+WEEE_带电池走货 _ 说明书欧洲EN+30L_B版; 7. 77878: 2pk 77843 in PVC tube,12tubes/ctn;Contain Sand, UV Glue and Cream Glue; SUSHI and RAINBOW CAKE(Rare) without batteries, other assortme nts: 6PCS AG13 BATTERIES(INCLUDED); Ratio: PIZZA: HAMBURGER: PANCAKES: BUBBLE TEA: Matcha TEA: TACO: SUSHI: DONUT: Charcuterie Board: RAINBOW C AKE(Rare)=10.88%: 10.88%: 10.88%: 10.88%: 10.88%: 10.88%: 10.88%: 10.88%: 10.88%: 2.08%=68:68:68:68:68:68:68:68:68:13; MA 1L(1L Warning UPC)A收 缩膜+1张空白贴纸(覆盖收缩上条码, 参考Amazon US翻单PO#4500192514)+MA 5L A收藏指南+MA 23L warning A SUSHI <(>&<)> RAINBOW CAKE说明书+MA 23L warni ng A UV Glue说明书+客版3L(3L warning UPC)A彩卡(参考Amazon US翻单PO#4500192514，新UK地址)+1张贴纸(含DE/IT警告语+IT环保标)+WEEE_带电池走货 _ 说明 书欧洲EN+30L_B版; 8. 92146BDGH: ---92146B: 1pc 92146B SMALL(Raccoon) into shrink wraps,24pcs/ctn;Bubble powder;NO Boron; MA 3L(8L warning EAN)A收缩膜+MA其它最新配套包装+MA 5L( 19L warning)A收藏指南+1张贴纸(含UPC+IT环保标+ES洗涤说明贴纸); ---92146D: 1pc 92146D SMALL(Deer) into shrink wraps,24pcs/ctn;Bubble powder;NO Boron; MA 3L(8L warning EAN)A收缩膜+MA其它最新配套包装+MA 5L(19L warning)A收藏指南+1张贴纸(含UPC+IT环保标+ES洗涤说明贴纸); ---92146G: 1pc 92146G SMALL(Pigeon) into shrink wraps,24pcs/ctn;Bubble powder;NO Boron; MA 3L(8L warning EAN)A收缩膜+MA其它最新配套包装+MA 5L(19 L warning)A收藏指南+1张贴纸(含UPC+IT环保标+ES洗涤说明贴纸); ---92146H: 1pc 92146H SMALL(Owl) into shrink wraps,24pcs/ctn;Bubble powder;NO Boron; MA 3L(8L warning EAN)A收缩膜+MA其它最新配套包装+MA 5L(19L w arning)A收藏指南+1张贴纸(含UPC+IT环保标+ES洗涤说明贴纸); 9. 92147E: 1pc 92147E LARGE(Unicorn) into shrink wrap, then into mailbox, 4mailboxes/ctn; MA 3L(8L warning EAN)A收缩膜+MA 5L(19L warning)A收藏指 南+MA 5L(19L warning)A Magic guide book说明书+MA其它最新配套包装+客版邮包盒; 10. 77858: 1pc 77858 playset into mailbox, 3mailboxes/ctn; Including magnets; 3PCS AA BATTERIES(NOT INCLUDED); MA 3L(23L warning EAN)A 透明PVC窗 彩盒+MA 23L warning A 电池黑白说明书+MA 5L A收藏指南+MA其它最新配套包装+客版邮包盒(参考Amazon US翻单PO#4500192979)+WEEE_不带电池走货 _ 说明书欧 洲EN+30L_B版 11.验货时间不迟于2026/5/11. 注意：77858需将邮包盒尺寸图<(>&<)>重量图放进验货报告； Remark: 1.空白外箱（加印带Zuru字样的最新logo，除了邮包盒直接做外箱的产品） + SSCC LABEL一张, 无箱唛，MADE IN CHINA 外箱只印一正一侧。箱唛资料按照给定的 标准去做即可，无需发回我方再行审批(新标准将另行通知)。 (SSCC LABEL竖贴在外箱正面的正中间，贴一面即可,贴纸离外箱边距必须至少3.2CM。如竖贴无法满足要求，则横贴。如横贴也无法满足要求，则竖贴，遮到ZURU lo go无影响), SSCC贴纸由工厂直接跟勤得采购或者工厂自行采购，每一张SSCC Label都是唯一且有不同流水及条码，且需要检查条码是否能正常扫描，另外，此贴纸 印刷不可出现模糊，溢出及粘胶不牢易脱落等现象，如工厂不按此要求导致贴纸有任何问题产生的罚款将由工厂承担一切责任 ,<(>,<)> 此要求只适用Amazon UK/DE /FR/ES/IT,不适用Amazon GPE，Amazon GPE无SSCC label, 但是有对应箱唛，需印刷到外箱 。 2.出往UK的产品+包装务必打上UKCA logo ，否则客人会退货且当地会有罚款。 3.订单必须经过ZURU QC验货或者工厂自检通过后方可出货，不涉及第三方验货。 4.法国订单要求包装不使用矿物油，请按要求提供以下其中一份文件再出货 ，产品出到法国被相关部门抽检出现包装不符合此要求的，供应商需要为此承担责任， 故此请严格把关。 -油墨物质""""由1 ~ 7个芳香环组成的MOAH""""的包装检测报告，要求限值≤1.0%； -包装材料清单，包括包装油墨或物质的信息； -油墨制造商的证书； 5.每一批次出货只能有一个生产日期，不可多个生产日期混在同一批次出货；且零售包装上必须统一加上日期码；外箱对于日期码没有硬性规定； 6.涉及到相关款式会有闪粉的或者微塑料的，请统一默认出无闪粉或者不含微塑料版本； 7.邮包盒及外箱封箱必须是工字型封箱方式； 8.5 Surprise or Mini Brands涉及包装是2个及2个以上的球入PVC桶包装时，单个球上若有UPC#或者EAN#，请用空白贴纸覆盖住，贴纸尺寸自行测量能覆盖原条码即 可； 9. 无论是工厂自检还是ZURU验货，验货报告中必须有产品6面图(正面/背面/左面/右面/顶部/底部，不带包装); 10. 按空海运鉴定报告的要求，只要带锂电池出货，都需要加贴UN贴纸； 11. 所有出往GAS市场(德国/奥地利/瑞士)的电子产品身上需要加字唛，为ZURU FRANCE 地址，需跟包装上的地址一致 (如无电子产品，产品布标有此地址，或产品 太小无法增加可忽略此信息。如产品无法加字唛，需让对应跟单提供产品贴纸资料); 12. 所有出往GAS德国 (瑞士，奥地利)。水弹枪系列必须使用EN71版本（电子和非电子水弹枪系列都需要符合); 护目镜需打日期码, 格式跟ZURU标准格式一样; 枪 身上增加ZURU FRANCE公司名和地址。使用贴纸和辐射上去都可以。如果有位置，最好增加ZURU Represented by: (此最好翻译德语，如果位置不允许，那么就只增 加ZURU法国和地址)。使用最新的EN71版包装和说明书）. | Z29: Luna Lin | AA29: 9.86 | AB29: =I29*AA29 -> 7020.32 | AD29: 71172-S003-MB-1L | AE29: 已入 | AO29: =I29 -> 712 | AP29: =I29 -> 712 | AR29: =I29 -> 712
A30: 46122 | B30: BIG W | C30: 澳大利亚 | D30: 4500201310 | E30: 47948602 | F30: 4500201310-20 | G30: 71172-S001 | H30: 大脑 | I30: 520 | J30: 0 | K30: 4 | L30: =I30/K30 -> 130 | M30: 46151 | N30: 46150 | O30: N/A | P30: PASS | Q30: 5/9入仓 | S30: 无 | T30: 46122 | U30: 46122 | Y30: 日期码格式：ZURU INC(BVI) 标准格式 日期：按实际生产日期 Packaging Info: 1. 包装 71172: 英文MA包装 (UPC版本，首选1L，无1L可用多L含英语)+1张进口商贴纸 2. 产品和包装上的日期码一致，请按要求在包装上打日期码（进口商贴纸不覆盖日期码） 3. 使用ZURU标准日期码 Remark: 1. 共出4港口 (SYD, BNE, MEL, FRE)，不同港口数量信息请见订单行项目，并请参考箱唛资料，港口不同，箱唛资料也不同； 2. 箱唛不可出现任何手写内容（箱数除外），重量与实际一致且不可手写； 3. 此单出澳大利亚，请按澳洲标准生产并满足当地法规要求； 4. 出无闪粉版本，需符合欧洲微塑料法规； 5. 确保所出货的产品及包装不含PFAS（全氟/多氟烷基化合物）及其盐类和其相关物质，特别留意 PFOA、PFOS、PFHxS 不得检出。 | Z30: Christine Liao | AA30: 9.7 | AB30: =I30*AA30 -> 5044 | AD30: 71172-S001-1L | AE30: 已入 | AO30: =I30 -> 520 | AP30: =I30 -> 520 | AR30: =I30 -> 520
A31: 46122 | B31: BIG W | C31: 澳大利亚 | D31: 4500201310 | E31: 47948603 | F31: 4500201310-30 | G31: 71172-S001 | H31: 大脑 | I31: 488 | J31: 0 | K31: 4 | L31: =I31/K31 -> 122 | M31: 46151 | N31: 46150 | O31: N/A | P31: PASS | Q31: 5/9入仓 | S31: 无 | T31: 46122 | U31: 46122 | Y31: 日期码格式：ZURU INC(BVI) 标准格式 日期：按实际生产日期 Packaging Info: 1. 包装 71172: 英文MA包装 (UPC版本，首选1L，无1L可用多L含英语)+1张进口商贴纸 2. 产品和包装上的日期码一致，请按要求在包装上打日期码（进口商贴纸不覆盖日期码） 3. 使用ZURU标准日期码 Remark: 1. 共出4港口 (SYD, BNE, MEL, FRE)，不同港口数量信息请见订单行项目，并请参考箱唛资料，港口不同，箱唛资料也不同； 2. 箱唛不可出现任何手写内容（箱数除外），重量与实际一致且不可手写； 3. 此单出澳大利亚，请按澳洲标准生产并满足当地法规要求； 4. 出无闪粉版本，需符合欧洲微塑料法规； 5. 确保所出货的产品及包装不含PFAS（全氟/多氟烷基化合物）及其盐类和其相关物质，特别留意 PFOA、PFOS、PFHxS 不得检出。 | Z31: Christine Liao | AA31: 10.75 | AB31: =I31*AA31 -> 5246 | AD31: 71172-S001-1L | AE31: 已入 | AO31: =I31 -> 488 | AP31: =I31 -> 488 | AR31: =I31 -> 488
A32: 46122 | B32: BIG W | C32: 澳大利亚 | D32: 4500201310 | E32: 47948604 | F32: 4500201310-40 | G32: 71172-S001 | H32: 大脑 | I32: 192 | J32: 0 | K32: 4 | L32: =I32/K32 -> 48 | M32: 46151 | N32: 46150 | O32: N/A | P32: PASS | Q32: 5/9入仓 | S32: 无 | T32: 46122 | U32: 46122 | Y32: 日期码格式：ZURU INC(BVI) 标准格式 日期：按实际生产日期 Packaging Info: 1. 包装 71172: 英文MA包装 (UPC版本，首选1L，无1L可用多L含英语)+1张进口商贴纸 2. 产品和包装上的日期码一致，请按要求在包装上打日期码（进口商贴纸不覆盖日期码） 3. 使用ZURU标准日期码 Remark: 1. 共出4港口 (SYD, BNE, MEL, FRE)，不同港口数量信息请见订单行项目，并请参考箱唛资料，港口不同，箱唛资料也不同； 2. 箱唛不可出现任何手写内容（箱数除外），重量与实际一致且不可手写； 3. 此单出澳大利亚，请按澳洲标准生产并满足当地法规要求； 4. 出无闪粉版本，需符合欧洲微塑料法规； 5. 确保所出货的产品及包装不含PFAS（全氟/多氟烷基化合物）及其盐类和其相关物质，特别留意 PFOA、PFOS、PFHxS 不得检出。 | Z32: Christine Liao | AA32: 10.75 | AB32: =I32*AA32 -> 2064 | AD32: 71172-S001-1L | AE32: 已入 | AO32: =I32 -> 192 | AP32: =I32 -> 192 | AR32: =I32 -> 192
A33: 46112 | B33: 360 SALES SOLUTIONS INC | C33: 加拿大 | D33: 4500199523 | E33: 2026ZURU09 | F33: 4500199523-20 | G33: 71172-S001 | H33: 大脑 | I33: 320 | J33: 0 | K33: 4 | L33: =I33/K33 -> 80 | M33: 46154 | N33: 46154 | O33: N/A | P33: PASS | Q33: 5/14 12:00前交仓 | S33: 无 | T33: 46119 | U33: 46122 | Y33: 日期码格式： 标准格式 日期：按实际生产日期 Packaging Info: 71172 MA 多语EAN+UPC贴纸193052098443 Remark: 出加拿大 Zuru验货. 日期跟踪码：产品外包装及产品本身都必须有日期跟踪码，ZURU标准格式日期码。（箱唛日期码按跟单提供格式） | Z33: Katrina | AA33: 9.86 | AB33: =I33*AA33 -> 3155.2 | AD33: 71172-S001-3L | AE33: 已入 | AO33: =I33 -> 320 | AQ33: =I33 -> 320 | AR33: =I33 -> 320
A34: 46090 | B34: LLC SALUS | C34: 俄罗斯联邦 | D34: 4500195784 | F34: 4500195784-80 | G34: 71172-S001 | H34: 大脑 | I34: 100 | J34: 0 | K34: 4 | L34: =I34/K34 -> 25 | M34: 46154 | N34: 46156 | O34: N/A | P34: PASS | S34: 有 | T34: 46098 | U34: 46113 | Y34: 日期码格式：ZURU INC(BVI) 标准格式 日期：按实际生产日期 Packaging Info: 71172: 1L MA UPC 彩卡+ 进口商贴纸+QR code (一物一码) ，MA 说明书。 Remark: 出厂价 ； 注意： 1. QR 贴纸要求： 需包含产品型号（item）+ 序列号，二维码（QR code）正方形边长 1.5cm 。 材质与粘性：采用与进口商贴纸一致的材质，强粘性、不易脱落/掉色。 印刷与尺寸：印刷质量不低于 1.5c，整体贴纸尺寸为 3×3cm（正方形）。 2. 二维码贴纸位置要远离包装上的条码及其他二维码， 贴在背面。 3. QR code贴纸（要求一物一码，每PCS的二维码不一样）; 4. QR code 格式 ：DATA MATRIX GS1 ； | Z34: Ann | AA34: 9.7 | AB34: =I34*AA34 -> 970 | AD34: 71172-S001-1L | AE34: 已入 | AO34: =I34 -> 100 | AP34: =I34 -> 100 | AR34: =I34 -> 100
A35: 46113 | B35: PT.MAP AKTIF ADIPERKASA, TBK | C35: 印度尼西亚 | D35: 4500199667 | F35: 4500199667-10 | G35: 71172-S001 | H35: 大脑 | I35: 208 | J35: 0 | K35: 4 | L35: =I35/K35 -> 52 | M35: 46154 | N35: 46156 | O35: 有 | P35: 第三方抽样，需提前准备多7套样办 | Q35: 6/4交仓 | S35: 无 | T35: 46120 | U35: 46128 | Y35: 日期码格式：ZURU INC(BVI) 标准格式 日期：按实际生产日期 Packaging Info: MA UPC包装（优先1L)+1张进口商贴纸,待提供9574/71172的贴纸资料 Remark: 9574-2pcs baby capybara: 3pcs baby capybara= 5:1 | Z35: Emma Wu | AA35: 9.7 | AB35: =I35*AA35 -> 2017.6 | AD35: 71172-S001-1L | AE35: 已入 | AO35: =I35 -> 208 | AP35: =I35 -> 208 | AR35: =I35 -> 208
A36: 46115 | B36: T. PLANET SHOPS SL | C36: 西班牙 | D36: 4500200070 | E36: 22362602 | F36: 4500200070-10 | G36: 71172-S001 | H36: 大脑 | I36: 1200 | J36: 0 | K36: 4 | L36: =I36/K36 -> 300 | M36: 46160 | N36: 46157 | O36: N/A | P36: PASS | Q36: 46184 | S36: 无 | T36: 46126 | U36: 46136 | W36: 202602 | Y36: 日期码格式：202602 日期： Packaging Info: 1.71172:【最新MA 3L EAN版本包装+一张客户进口商内容贴纸】+最新MA 15L说明书+一张产品贴纸+WEEE带电池走货欧洲29L通用黑白说明书； 2.9574:【最新MA 3L EAN版本包装+一张客户进口商内容贴纸】+最新MA 5L说明书+WEEE不带电池走货欧洲29L通用黑白说明书； 3.77711SK1:【MA 3L EAN版本包装+一张客户进口商贴纸（含西班牙环保标)】+MA 收藏指南+MA 23L说明书+MA 3L 展示架； 4.77843GQ2:【MA 3L EAN版本包装+一张客户进口商贴纸（含西班牙环保标)】+MA 收藏指南+MA 23L说明书+MA 3L PDQ+WEEE带电池走货欧洲29L通用黑白说明书； 5.77843SK1:【MA 3L EAN版本包装+一张客户进口商贴纸（含西班牙环保标)】+MA 收藏指南+MA 23L说明书+MA 3L 展示架+WEEE带电池走货欧洲29L通用黑白说明书 ； 6.157117UQ1:【MA 3L包装+一张客户进口商贴纸+一张Mother EAN条码贴纸】+MA PDQ； 7.15788:【MA 5L包装+一张客户进口商贴纸+一张Mother EAN条码贴纸】； 8.15783UQ1:【最新MA 5L包装+一张客户进口商贴纸+一张EAN条码贴纸】+MA PDQ； 9.92146TQ1:【MA 3L EAN版本包装+一张客户进口商内容贴纸】+MA 5L收藏指南+一张产品贴纸； 10.92147:【MA 3L EAN版本包装+一张客户进口商内容贴纸】+MA 5L说明书+一张产品贴纸； Remark: 1. 此单出西班牙，需满足EU测试标准要求，另外微塑料需符合EU法规； 2. 标准配比； 3.根据新电池法规（EU） 2023/1542，所有走欧洲市场的电子产品，都需要增加WEEE通用29L说明书（分带电池走货和不带电池走货两种），如工厂没有此文件，可 以找我们跟单提供； 4. 准时完货，需安排ZURU OQC验货并要求提供客户格式的自检报告给到客户审批放货。 另外，包装贴纸上面的警告语不可以覆盖西班牙警告语。 5. 此单需要每款准备3套大货样，请注意备料； 6.注意： 同款产品含PDQ /展示架的外箱条码需要跟item包装条码不一样; 7.此单客户指定日期码：202602 | Z36: Mary Zhong | AA36: 9.86 | AB36: =I36*AA36 -> 11832 | AD36: 71172-S001-3L | AE36: 已入 | AO36: =I36 -> 1200 | AQ36: =I36 -> 1200 | AR36: =I36 -> 1200
A37: 46114 | B37: NUEVOS ALMACENES, S.A. | C37: 危地马拉 | D37: 4500199843 | E37: 4504719305 | F37: 4500199843-10 | G37: 71172-S001 | H37: 大脑 | I37: 240 | J37: 0 | K37: 4 | L37: =I37/K37 -> 60 | M37: 46162 | N37: 46157 | O37: N/A | P37: PASS | S37: 无 | T37: 46127 | U37: 46137 | Y37: 日期码格式：ZURU INC(BVI) 标准格式 日期： Packaging Info: MA 多语包装+UPC贴纸+箱唛，无客户贴纸 Remark: 订单需提交自检报告，客户审核通过才可以出货。 外箱上的箱唛资料显示客户指定日期30-MAY-2026,产品/包装/外箱可以按ZURU 标准日期码打，也可以跟回外箱日期码，工厂自行选择,两者均可接受 | Z37: Ava Liang | AA37: 9.86 | AB37: =I37*AA37 -> 2366.4 | AD37: 71172-S001-3L | AE37: 已入 | AO37: =I37 -> 240 | AQ37: =I37 -> 240 | AR37: =I37 -> 240
A38: 46129 | D38: ZMPO260410 | F38: ZMPO260410-10 | G38: 71172-S001 | H38: 大脑 | I38: 200 | J38: 0 | K38: 4 | L38: =I38/K38 -> 50 | M38: 46162 | N38: 46157 | O38: N/A | P38: PASS | S38: 无 | T38: 46129 | U38: 无 | Y38: Remark大货版本/大货标准箱装箱/箱唛请参照邮件附件 备注：收到样品订单后尽快安排 ，注意样板品质质量要求要高于大货品质要求 ，送货时必须要附带送货单(没有送货单和QC检验合格报告的仓库一律拒绝收货)，请知悉，谢谢！ | Z38: Angus | AD38: 71172-S001-1L | AE38: 已入 | AO38: =I38 -> 200 | AP38: =I38 -> 200
A39: 46121 | B39: WALMART INC. | C39: 美国 | D39: 4500200590 | E39: 0988641197 | F39: 4500200590-40 | G39: 71172-S002 | H39: 大脑 | I39: 976 | J39: 0 | K39: 1 | L39: =I39/K39 -> 976 | M39: 46163 | N39: 46162 | O39: 6/3 BV公证行验货+抽办,6/8 | P39: PASS | S39: 有 | T39: 46121 | U39: 4/9-粉色MOD艾利贴纸,4/22收RFID贴纸 | Y39: 日期码格式：DGYYYYMMDD(日期避开周末和法定节假日) 日期：按实际生产日期 Packaging Info: 此单为WMUS首单，需安排产中抽板，抽板时间：2026/5/21，抽板WMPO: 0988641197，抽板需完成订单数量506PCS，抽走6PCS给到测试行，请自行多备包装物料。请 于抽板前寄出5PCS样板给到我签板。 1.包装方式： 71172: MA 1L彩盒包装+MA 15L警告语 A版说明书+ RFID贴纸 Remark: 2. 外箱四面印刷紫色RFID箱唛 主唛左前下角印刷艾利贴纸替代标箱唛(ITF-14格式)，条码只印刷一面 主唛右下角加印 MADE IN CHINA以及ZURU LOGO，对角线位置加贴一张粉色MOD艾利贴纸（工厂自行打印或订购贴纸） 3. 71172 UPC：193052098443 4.此批单散箱出货，1PCS/CTN 5.此单需要验货，请自行多备包装物料。 6.产品和包装上要有日期码、MADE IN CHINA和ZURU字样。 7.每PCS要加RFID 贴纸(ZURU提供)，严格按照我们提供的位置图，不可擅自调整位置，贴纸也不可有任何破损或折坏，不可淋湿（如缺数请及时告知） | Z39: Nikki Mo | AA39: 5.916 | AB39: =I39*AA39 -> 5774.016 | AC39: ZB06229-8.17 | AD39: 71172-S002-1L | AE39: 已入 | AO39: =I39 -> 976 | AP39: =I39 -> 976 | AR39: =I39 -> 976
A40: 46121 | B40: WALMART INC. | C40: 美国 | D40: 4500200590 | E40: 0988641171 | F40: 4500200590-30 | G40: 71172-S002 | H40: 大脑 | I40: 1102 | J40: 0 | K40: 1 | L40: =I40/K40 -> 1102 | M40: 46163 | N40: 46162 | O40: 46181 | P40: PASS | S40: 有 | T40: 46121 | U40: 4/9-粉色MOD艾利贴纸,4/22收RFID贴纸 | Y40: 日期码格式：DGYYYYMMDD(日期避开周末和法定节假日) 日期：按实际生产日期 Packaging Info: 此单为WMUS首单，需安排产中抽板，抽板时间：2026/5/21，抽板WMPO: 0988641197，抽板需完成订单数量506PCS，抽走6PCS给到测试行，请自行多备包装物料。请 于抽板前寄出5PCS样板给到我签板。 1.包装方式： 71172: MA 1L彩盒包装+MA 15L警告语 A版说明书+ RFID贴纸 Remark: 2. 外箱四面印刷紫色RFID箱唛 主唛左前下角印刷艾利贴纸替代标箱唛(ITF-14格式)，条码只印刷一面 主唛右下角加印 MADE IN CHINA以及ZURU LOGO，对角线位置加贴一张粉色MOD艾利贴纸（工厂自行打印或订购贴纸） 3. 71172 UPC：193052098443 4.此批单散箱出货，1PCS/CTN 5.此单需要验货，请自行多备包装物料。 6.产品和包装上要有日期码、MADE IN CHINA和ZURU字样。 7.每PCS要加RFID 贴纸(ZURU提供)，严格按照我们提供的位置图，不可擅自调整位置，贴纸也不可有任何破损或折坏，不可淋湿（如缺数请及时告知） | Z40: Nikki Mo | AA40: 5.82 | AB40: =I40*AA40 -> 6413.64 | AC40: ZB06425-8.17 | AD40: 71172-S002-1L | AE40: 已入 | AO40: =I40 -> 1102 | AP40: =I40 -> 1102 | AR40: =I40 -> 1102
...

Sheet 彩盒MA
B2: 71172大脑 彩盒、说明书MA剩余表
A3: 放订人 | B3: 放MA日期 | C3: PO号码 | D3: MA订单号码 | E3: 货号 | F3: 数量 | G3: 名称 | H3: 版本号 | I3: 语言 | J3: MA 1L彩盒 | K3: MA 3L彩盒 | L3: 15L说明书A | M3: 15L说明书B | N3: 客版说明书 | O3: 71172EC展示架24个装 | P3: 客版包材 | Q3: 备注
A4: Minny | B4: 46080 | D4: 1000036614 | E4: 71172 | F4: 50000 | G4: 彩盒 | H4: A | I4: 1L | J4: =F4 -> 50000
A5: Minny | B5: 46080 | D5: 1000036615 | E5: 71172 | F5: 20000 | G5: 彩盒 | H5: A | I5: 3L | K5: =F5 -> 20000
A6: Minny | B6: 46080 | D6: 1000036616 | E6: 71172 | F6: 70000 | G6: 说明书 | H6: A | I6: 5L | L6: =F6 -> 70000
A7: Minny | B7: 46154 | D7: 1000039941 | E7: 71172 | F7: 40000 | G7: 彩盒 | H7: A | I7: 1L | J7: =F7 -> 40000
A8: Minny | B8: 46154 | D8: 1000039942 | E8: 71172 | F8: 20000 | G8: 彩盒 | H8: A | I8: 3L | K8: =F8 -> 20000
A9: Minny | B9: 46154 | D9: 1000039943 | E9: 71172 | F9: 60000 | G9: 说明书 | H9: B | I9: 2L+5L | M9: =F9 -> 60000
A10: Minny | B10: 46184 | D10: 1000041297 | E10: 71172 | F10: 11216 | G10: 说明书 | H10: A | I10: 2L(ES+PT) | N10: =F10 -> 11216 | Q10: 1.Eva4392PCS 用于CANDIDE PO 4500206011-1000PCS/4500210935-3152PCS/UNIVERSA PO 4500203841 -240PCS 2.Lilly Xiao 5536PCS用于 ARCHIBRAND PO4500210225-200PCS/4500210228-116PCS/ 4500210229-300PCS/SEARS PO 4500207499- 420PCS/WM MX PO-4500210269 4500PCS 3.Sandy 340PCS 用于LIVERPOOL PO 4500199969-300pcs，4500205041-40pcs 4.Aimee 948PCS 用于 EL ROSADO PO4500208470-400PCS /NASA PO 4500203219-116PCS/4500203233-60PCS/CHEDRAUI PO待定-372PCS
A11: Minny | B11: 46190 | D11: 1000041517 | E11: 71172 | F11: 50000 | G11: 彩盒 | H11: A | I11: 1L | J11: 50000
A12: Minny | B12: 46190 | D12: 1000041518 | E12: 71172 | F12: 30000 | G12: 说明书 | H12: B | I12: 2L+5L | M12: 30000
A13: Minny | B13: 46230 | D13: 1000043203 | E13: 71172 | F13: 20000 | G13: 彩盒 | I13: 1L | J13: =F13 -> 20000
A14: Minny | B14: 46230 | D14: 1000043204 | E14: 71172 | F14: 20000 | G14: 说明书 | I14: 2L+5L | M14: =F14 -> 20000
G17: 合计 | J17: =SUM(J4:J16) -> 160000 | K17: =SUM(K4:K16) -> 40000 | L17: =SUM(L4:L16) -> 70000 | M17: =SUM(M4:M16) -> 110000 | N17: =SUM(N4:N16) -> 11216 | O17: =SUM(O4:O16) -> 0
G18: 接单总数 | J18: ='71172大脑'!AP298 -> 148256 | K18: ='71172大脑'!AQ298 -> 36304 | L18: ='71172大脑'!AR298 -> 69892 | M18: ='71172大脑'!AS298 -> 95732 | N18: ='71172大脑'!AT298 -> 10668 | O18: =SUM(O5:O17) -> 0
G19: 彩盒MA剩余 | J19: =J17-J18 -> 11744 | K19: =K17-K18 -> 3696 | L19: =L17-L18 -> 108 | M19: =M17-M18 -> 14268 | N19: =N17-N18 -> 548 | O19: =O17-O18 -> 0

Sheet 产品MA
B1: 大脑半成品生产MA
B2: 日期 | C2: MA订单号码 | D2: ITEM | E2: 名称 | F2: 数量 | G2: 要求完成日期 | H2: 备注
B4: 46036 | C4: MA_RR_2073 | D4: 71172 | E4: 大脑 | F4: 60000 | G4: 46150
B5: 46093 | C5: MA_RR_2191 | D5: 71172 | E5: 大脑 | F5: 60000 | G5: 46148
B6: 46169 | C6: MA_RR_2319 | D6: 71172 | E6: 大脑 | F6: 80000 | G6: 46265
B7: 46233 | C7: MA_RR_2441 | D7: 71172 | E7: 大脑 | F7: 50000 | G7: 46288
E9: MA合计 | F9: =SUM(F4:F8) -> 250000
E10: 接单总数 | F10: ='71172大脑'!I298 -> 185092
E11: MA剩余 | F11: =F9-F10 -> 64908
B15: 大脑IC MA
B16: 日期 | C16: MA订单号码 | D16: ITEM | E16: 名称 | F16: 71172 | G16: 要求完成日期 | H16: 备注
F17: 大脑
B18: 45975 | C18: MA_RR_1967 | D18: 71172 | E18: 大脑 | F18: 4000 | G18: 45990 | H18: HY2410082-30/HY2410082-F9 华远科创
B19: 45989 | C19: MA_RR_1985 | D19: 71172 | E19: 大脑 | F19: 40000 | G19: 46004 | H19: HY2410082-30/HY2410082-F9 华远科创
B20: 46016 | C20: MA_RR_2023 | D20: 71172 | E20: 大脑 | F20: 12000 | G20: 46051 | H20: HY2410082-30/HY2410082-F9 华远科创
B21: 46031 | C21: MA_RR_2046 | D21: 71172 | E21: 大脑 | F21: 72000 | G21: 46046 | H21: HY2410082-30/HY2410082-F9 华远科创
B22: 46062 | C22: MA_RR_2120 | D22: 71172 | E22: 大脑 | F22: 12000 | G22: 46112 | H22: HY2410082-30/HY2410082-F9 华远科创
B23: 46090 | C23: MA_RR_2166 | D23: 71172 | E23: 大脑 | F23: 20000 | G23: 3/24,4/15 | H23: HY2410082-30/HY2410082-F9 华远科创
B24: 46125 | C24: MA_RR_2246 | D24: 71172 | E24: 大脑 | F24: 52000 | G24: 5/18,4/28 | H24: HY2410082-30/HY2410082-F9 华远科创
B25: 46157 | C25: MA-RR-2302 | D25: 71172 | E25: 大脑 | F25: 20000 | G25: 6/19,5/30 | H25: HY2410082-30/HY2410082-F9 华远科创
B26: 46169 | C26: MA_RR_2329 | D26: 71172 | E26: 大脑 | F26: 20000 | G26: 46184 | H26: HY2410082-30/HY2410082-F9 华远科创
B27: 46189 | C27: MA_RR_2375 | D27: 71172 | E27: 大脑 | F27: 20000 | G27: 7/21,7/1 | H27: HY2410082-30/HY2410082-F9 华远科创
B28: 46205 | C28: MA_RR_2407 | D28: 71172 | E28: 大脑 | F28: 60000 | G28: 8/6,7/17 | H28: HY2410082-30/HY2410082-F9 华远科创
B29: 46232 | C29: MA_RR_2443 | D29: 71172 | E29: 大脑 | F29: 48000 | G29: 未经烧录的IC空白片 | H29: HY2410082-30(IC母体:DSP-QFN32)/HY2410082-F9(IC母体:Flash-8Mb) 华远科创
F32: =SUM(F18:F31) -> 380000
B33: 接单总数 | F33: =F10 -> 185092
B34: 按接单IC 剩余数 | F34: =F32-F33 -> 194908
B35: 除去MA半成品 剩余数 | F35: =F32-F9 -> 130000

Sheet 客版MA

Sheet 取消单
A1: 接单期 | B1: 第三方客户名称 | C1: 国家 | D1: PO号 | E1: 第三方客户 PO NO# | F1: SKU | G1: 货号 | H1: 名称 | I1: PO数量(只) | J1: 内箱装箱数量(只) | K1: 外箱装箱数量(只) | L1: 总箱数 | M1: 客PO期 | N1: 计划验货期 | O1: 第三方验货期 | P1: 验货结果 | Q1: 船期SO | R1: 蓝色表示寄出 黄色表示出单 | S1: 是否有外箱贴纸 | T1: 箱唛资料 | U1: 客贴纸 | V1: 其他物料 | W1: 日期码 | Y1: 备注 | Z1: 客跟单 | AA1: 单价USD | AB1: 金额USD | AC1: 发票号 | AD1: 系统货号 | AE1: 是否已入系统 | AF1: 已完成数量 | AG1: 欠数 | AH1: 贴纸情况 | AI1: 是否已入系统 | AJ1: 包装 | AK1: 标准=0,客版=1 | AL1: 说明书 | AM1: 标准=0,客版=1 | AN1: 走货情况(离厂日期) | AO1: 71172 产品数 | AP1: 71172 MA 1L彩盒 | AQ1: 71172 MA 3L彩盒 | AR1: 71172 MA 15L说明书A版 | AS1: 71172 MA15L说明书B版 | AT1: 客版 | AU1: 取消日期
A2: 46122 | B2: DM LLC | C2: 俄罗斯 | D2: 4500200893 | E2: order 5377Bekasovo 2 | F2: 4500200893-80 | G2: 71172-S001 | H2: 大脑 | I2: 936 | J2: 0 | K2: 4 | L2: =I2/K2 -> 234 | M2: 46202 | N2: 46198 | T2: 46127 | U2: 46135 | Y2: 日期码格式：外包装/外箱不要打ZURU标准日期 日期： Packaging Info: 注意: 除了71172 ，其他item的进口商贴纸，EAN条码贴纸（如有）翻4500200846 。 1. 外包装(指:收缩膜/彩卡/铝箔袋/挂卡/PDQ)/外箱不要打ZURU标准日期码!胶件可以打日期码。 2. 零售包装上的QR code贴纸（要求一物一码，每PCS的二维码不一样，二维码可扫描区域尺寸要大于15x15mm ， 整张贴纸尺寸25X40MM <(><<)>含二维码下序列号 /Art/size等,可以按包装需求自行调整-确保可扫>,白底黑字，分辨率要大于300dpi，位置要远离条码。 可贴零售包装的侧面右下角/背面的右上角/挂卡的背面/正 面的右上角，距离边距5mm）; 3 .外箱四面右上角需要加SSCC label （标准尺寸是16X5CM,可调整但是需要确保可扫）； 4. MA UPC 彩卡或者收缩膜+进口商贴纸+EAN条码贴纸+QR code 贴纸 （一物一码），MA 说明书/指南（如有） Remark: 客户DM订单注意事项: 1. 标准配比 2. 请按期完货， 会有罚金。 3. 出仓库-Bekasovo 2 。 4. 外包装(指:收缩膜/彩卡/铝箔袋/挂卡/PDQ)/外箱不要打ZURU标准日期码!胶件可以打日期码。 5. 零售包装上的QR code贴纸（要求一物一码，每PCS的二维码不一样，二维码可扫描区域尺寸要大于15x15mm ， 整张贴纸尺寸25X40MM <(><<)>含二维码下序列号 /Art/size等>,白底黑字，分辨率要大于300dpi，位置要远离条码。 可贴零售 包装的侧面右下角/背面的右上角/挂卡的背面/正面的右上角，距离边距5mm）; ----QR 二维码格式要求： DATA MATRIX GS1 . 6 .外箱四面左下角需要加SSCC label （标准尺寸是16X5CM,可调整但是需要确保可扫）； 7. 出货前需要按船务的指示提供零售包装上QR CODE 入外箱以及入货柜的明细清单供客户清关使用--用客户的模板（追踪到箱/到柜）； 8. 需要通过ZURU 验货结果后才能出货 (工厂需要主动提前同ZURU QC预约验货避免延期出货造成不必要麻烦)； | Z2: Amy xiao | AA2: 9.86 | AB2: =I2*AA2 -> 9228.96 | AO2: =I2 -> 936 | AP2: =I2 -> 936 | AR2: =I2 -> 936 | AU2: 46162
A3: 46122 | B3: DM LLC | C3: 俄罗斯 | D3: 4500200937 | E3: order 5377Ural | F3: 4500200937-80 | G3: 71172-S001 | H3: 大脑 | I3: 368 | J3: 0 | K3: 4 | L3: =I3/K3 -> 92 | M3: 46202 | N3: 46198 | T3: 46127 | U3: 46135 | Y3: 日期码格式：外包装/外箱不要打ZURU标准日期 日期： Packaging Info: 注意: 71172 的进口商贴纸，EAN条码贴纸（如有）翻4500200893； 其他 item 的进口商贴纸，EAN条码贴纸（如有）翻4500200846 。 1. 外包装(指:收缩膜/彩卡/铝箔袋/挂卡/PDQ)/外箱不要打ZURU标准日期码!胶件可以打日期码。 2. 零售包装上的QR code贴纸（要求一物一码，每PCS的二维码不一样，二维码可扫描区域尺寸要大于15x15mm ， 整张贴纸尺寸25X40MM <(><<)>含二维码下序列号 /Art/size等,可以按包装需求自行调整-确保可扫>,白底黑字，分辨率要大于300dpi，位置要远离条码。 可贴零售包装的侧面右下角/背面的右上角/挂卡的背面/正 面的右上角，距离边距5mm）; 3 .外箱四面右上角需要加SSCC label （标准尺寸是16X5CM,可调整但是需要确保可扫）； 4. MA UPC 彩卡或者收缩膜+进口商贴纸+EAN条码贴纸+QR code 贴纸 （一物一码），MA 说明书/指南（如有） Remark: 客户DM订单注意事项: 1. 标准配比 2. 请按期完货， 会有罚金。 3. 出仓库- Ural 。 4. 外包装(指:收缩膜/彩卡/铝箔袋/挂卡/PDQ)/外箱不要打ZURU标准日期码!胶件可以打日期码。 5. 零售包装上的QR code贴纸（要求一物一码，每PCS的二维码不一样，二维码可扫描区域尺寸要大于15x15mm ， 整张贴纸尺寸25X40MM <(><<)>含二维码下序列号 /Art/size等>,白底黑字，分辨率要大于300dpi，位置要远离条码。 可贴零售 包装的侧面右下角/背面的右上角/挂卡的背面/正面的右上角，距离边距5mm）; ----QR 二维码格式要求： DATA MATRIX GS1 . 6 .外箱四面左下角需要加SSCC label （标准尺寸是16X5CM,可调整但是需要确保可扫）； 7. 出货前需要按船务的指示提供零售包装上QR CODE 入外箱以及入货柜的明细清单供客户清关使用--用客户的模板（追踪到箱/到柜）； 8. 需要通过ZURU 验货结果后才能出货 (工厂需要主动提前同ZURU QC预约验货避免延期出货造成不必要麻烦)； | Z3: Amy xiao | AA3: 9.86 | AB3: =I3*AA3 -> 3628.48 | AO3: =I3 -> 368 | AP3: =I3 -> 368 | AR3: =I3 -> 368 | AU3: 46162
A4: 46122 | B4: DM LLC | C4: 俄罗斯 | D4: 4500200968 | E4: order 5377Bekasovo 2 | F4: 4500200968-80 | G4: 71172-S001 | H4: 大脑 | I4: 468 | J4: 0 | K4: 4 | L4: =I4/K4 -> 117 | M4: 46227 | N4: 46223 | T4: 46127 | U4: 46135 | Y4: 日期码格式：外包装/外箱不要打ZURU标准日期 日期： Packaging Info: 注意: 71172 的进口商贴纸，EAN条码贴纸（如有）翻4500200893； 其他 item 的进口商贴纸，EAN条码贴纸（如有）翻4500200846 。 1. 外包装(指:收缩膜/彩卡/铝箔袋/挂卡/PDQ)/外箱不要打ZURU标准日期码!胶件可以打日期码。 2. 零售包装上的QR code贴纸（要求一物一码，每PCS的二维码不一样，二维码可扫描区域尺寸要大于15x15mm ， 整张贴纸尺寸25X40MM <(><<)>含二维码下序列号 /Art/size等,可以按包装需求自行调整-确保可扫>,白底黑字，分辨率要大于300dpi，位置要远离条码。 可贴零售包装的侧面右下角/背面的右上角/挂卡的背面/正 面的右上角，距离边距5mm）; 3 .外箱四面右上角需要加SSCC label （标准尺寸是16X5CM,可调整但是需要确保可扫）； 4. MA UPC 彩卡或者收缩膜+进口商贴纸+EAN条码贴纸+QR code 贴纸 （一物一码），MA 说明书/指南（如有） Remark: 客户DM订单注意事项: 1. 标准配比 2. 请按期完货， 会有罚金。 3. 出仓库-Bekasovo 2。 4. 外包装(指:收缩膜/彩卡/铝箔袋/挂卡/PDQ)/外箱不要打ZURU标准日期码!胶件可以打日期码。 5. 零售包装上的QR code贴纸（要求一物一码，每PCS的二维码不一样，二维码可扫描区域尺寸要大于15x15mm ， 整张贴纸尺寸25X40MM <(><<)>含二维码下序列号 /Art/size等>,白底黑字，分辨率要大于300dpi，位置要远离条码。 可贴零售 包装的侧面右下角/背面的右上角/挂卡的背面/正面的右上角，距离边距5mm）; ----QR 二维码格式要求： DATA MATRIX GS1 . 6 .外箱四面左下角需要加SSCC label （标准尺寸是16X5CM,可调整但是需要确保可扫）； 7. 出货前需要按船务的指示提供零售包装上QR CODE 入外箱以及入货柜的明细清单供客户清关使用--用客户的模板（追踪到箱/到柜）； 8. 需要通过ZURU 验货结果后才能出货 (工厂需要主动提前同ZURU QC预约验货避免延期出货造成不必要麻烦)； | Z4: Amy xiao | AA4: 9.86 | AB4: =I4*AA4 -> 4614.48 | AO4: =I4 -> 468 | AP4: =I4 -> 468 | AR4: =I4 -> 468 | AU4: 46162
A5: 46122 | B5: DM LLC | C5: 俄罗斯 | D5: 4500201001 | E5: order 5377Ural | F5: 4500201001-80 | G5: 71172-S001 | H5: 大脑 | I5: 184 | J5: 0 | K5: 4 | L5: =I5/K5 -> 46 | M5: 46227 | N5: 46223 | T5: 46127 | U5: 46135 | Y5: 日期码格式：外包装/外箱不要打ZURU标准日期 日期： Packaging Info: 注意: 71172 的进口商贴纸，EAN条码贴纸（如有）翻4500200893； 其他 item 的进口商贴纸，EAN条码贴纸（如有）翻4500200846 。 1. 外包装(指:收缩膜/彩卡/铝箔袋/挂卡/PDQ)/外箱不要打ZURU标准日期码!胶件可以打日期码。 2. 零售包装上的QR code贴纸（要求一物一码，每PCS的二维码不一样，二维码可扫描区域尺寸要大于15x15mm ， 整张贴纸尺寸25X40MM <(><<)>含二维码下序列号 /Art/size等,可以按包装需求自行调整-确保可扫>,白底黑字，分辨率要大于300dpi，位置要远离条码。 可贴零售包装的侧面右下角/背面的右上角/挂卡的背面/正 面的右上角，距离边距5mm）; 3 .外箱四面右上角需要加SSCC label （标准尺寸是16X5CM,可调整但是需要确保可扫）； 4. MA UPC 彩卡或者收缩膜+进口商贴纸+EAN条码贴纸+QR code 贴纸 （一物一码），MA 说明书/指南（如有） Remark: 客户DM订单注意事项: 1. 标准配比 2. 请按期完货， 会有罚金。 3. 出仓库- Ural 。 4. 外包装(指:收缩膜/彩卡/铝箔袋/挂卡/PDQ)/外箱不要打ZURU标准日期码!胶件可以打日期码。 5. 零售包装上的QR code贴纸（要求一物一码，每PCS的二维码不一样，二维码可扫描区域尺寸要大于15x15mm ， 整张贴纸尺寸25X40MM <(><<)>含二维码下序列号 /Art/size等>,白底黑字，分辨率要大于300dpi，位置要远离条码。 可贴零售 包装的侧面右下角/背面的右上角/挂卡的背面/正面的右上角，距离边距5mm）; ----QR 二维码格式要求： DATA MATRIX GS1 . 6 .外箱四面左下角需要加SSCC label （标准尺寸是16X5CM,可调整但是需要确保可扫）； 7. 出货前需要按船务的指示提供零售包装上QR CODE 入外箱以及入货柜的明细清单供客户清关使用--用客户的模板（追踪到箱/到柜）； 8. 需要通过ZURU 验货结果后才能出货 (工厂需要主动提前同ZURU QC预约验货避免延期出货造成不必要麻烦)； | Z5: Ann | AA5: 9.86 | AB5: =I5*AA5 -> 1814.24 | AO5: =I5 -> 184 | AP5: =I5 -> 184 | AR5: =I5 -> 184 | AU5: 46162
A6: 46112 | B6: AMAZON UK | C6: 英国 | D6: 4500199193 | E6: 6MTFVO4E | F6: 4500199193-40 | G6: 71172-S003-MB | H6: 大脑（邮包盒装） | I6: 532 | J6: 0 | K6: 4 | L6: =I6/K6 -> 133 | M6: 46240 | N6: 46237 | O6: N/A | S6: 有 | T6: 46112 | U6: 无 | Y6: 日期码格式：ZURU INC(BVI) 标准格式 日期：按实际生产日期 Packaging Info: Amazon UK: 8WX462WO/6MTFVO4E/795E945F Amazon UK(15780BD/71172/77876/77878/92146BG) 1. 15780BD: ---15780B: 1pc 15780B(Sasquoosh/Stinkface/Squooshface) in window box, then into polybag,12polybags/ctn; MA 5L(5L warning UPC)B开窗彩盒+MA其它最 新配套包装+客版透明胶袋(含英法德意西荷兰警告语+双面打孔+塑料循环标,参考翻单PO#4500198640)+1张贴纸(含UPC#+IT环保标+ES洗涤说明, 参考翻单PO#450019 8640); ---15780D: 1pc 15780D(Munch Munch/Reek-o/Munch-o) in window box, then into polybag,12polybags/ctn; MA 5L(5L warning UPC)B开窗彩盒+MA其它最新配套 包装+客版透明胶袋(含英法德意西荷兰警告语+双面打孔+塑料循环标,参考翻单PO#4500198640)+1张贴纸(含UPC#+IT环保标+ES洗涤说明, 参考翻单PO#4500198640); 2. 92146BG: ---92146B: 1pc 92146B SMALL(Raccoon) into shrink wraps,24pcs/ctn;Bubble powder;NO Boron; MA 3L(8L warning EAN)A收缩膜+MA其它最新配套包装+MA 5L( 19L warning)A收藏指南+1张贴纸(1张UPC+IT环保标+ES洗涤说明贴纸，参考翻单PO#4500198640); ---92146G: 1pc 92146G SMALL(Pigeon) into shrink wraps,24pcs/ctn;Bubble powder;NO Boron; MA 3L(8L warning EAN)A收缩膜+MA其它最新配套包装+MA 5L(19 L warning)A收藏指南+1张贴纸(1张UPC+IT环保标+ES洗涤说明贴纸，参考翻单PO#4500198640); 3. 71172: 1pc 71172 BRIAN THE BRAIN into open box, then into mailbox, 4mailboxes/ctn; 3PCS AA BATTERIES(INCLUDED); MA 1L(23L warning UPC)A开口彩 盒+MA 15L A说明书+客版邮包盒(参考Amazon US翻单PO#4500192525)+WEEE_带电池走货 _ 说明书欧洲EN+30L_B版; 4. 77876: 2pk 77772 VINYL into PVC tube,12tubes/ctn; 77772: 4 mini vinyls,1 accessory; 客版 3L(3L warning 无条码)A收缩膜(参考翻单PO#4500198642, 新UK地址)+MA 23L warning A组装黑白说明书+MA其它最新配套包装+客版3L(3L warning UPC)A彩卡(参考翻单PO#4500198642，新UK地址)+1张贴纸(含DE/IT警告语+ IT环保标, 参考翻单PO#4500198642); 5. 77878: 2pk 77843 in PVC tube,12tubes/ctn;Contain Sand, UV Glue and Cream Glue; SUSHI and RAINBOW CAKE(Rare) without batteries, other assortme nts: 6PCS AG13 BATTERIES(INCLUDED); Ratio: PIZZA: HAMBURGER: PANCAKES: BUBBLE TEA: Matcha TEA: TACO: SUSHI: DONUT: Charcuterie Board: RAINBOW C AKE(Rare)=10.88%: 10.88%: 10.88%: 10.88%: 10.88%: 10.88%: 10.88%: 10.88%: 10.88%: 2.08%=68:68:68:68:68:68:68:68:68:13; MA 1L(1L Warning UPC)A收 缩膜+1张空白贴纸(覆盖收缩上条码, 参考Amazon US翻单PO#4500192514)+MA 5L A收藏指南+MA 23L warning A SUSHI <(>&<)> RAINBOW CAKE说明书+MA 23L warni ng A UV Glue说明书+客版3L(3L warning UPC)A彩卡(参考Amazon US翻单PO#4500192514.,新UK地址)+1张贴纸(含DE/IT警告语+IT环保标,参考翻单PO#4500198640)+W EEE_带电池走货 _ 说明书欧洲EN+30L_B版; 6. 验货时间不迟于2026/8/7. Remark: 1.空白外箱（加印带Zuru字样的最新logo，除了邮包盒直接做外箱的产品） + SSCC LABEL一张, 无箱唛，MADE IN CHINA 外箱只印一正一侧。箱唛资料按照给定的 标准去做即可，无需发回我方再行审批(新标准将另行通知)。 (SSCC LABEL竖贴在外箱正面的正中间，贴一面即可,贴纸离外箱边距必须至少3.2CM。如竖贴无法满足要求，则横贴。如横贴也无法满足要求，则竖贴，遮到ZURU lo go无影响), SSCC贴纸由工厂直接跟勤得采购或者工厂自行采购，每一张SSCC Label都是唯一且有不同流水及条码，且需要检查条码是否能正常扫描，另外，此贴纸 印刷不可出现模糊，溢出及粘胶不牢易脱落等现象，如工厂不按此要求导致贴纸有任何问题产生的罚款将由工厂承担一切责任 ,<(>,<)> 此要求只适用Amazon UK/DE /FR/ES/IT,不适用Amazon GPE，Amazon GPE无SSCC label, 但是有对应箱唛，需印刷到外箱 。 2.出往UK的产品+包装务必打上UKCA logo ，否则客人会退货且当地会有罚款。Amazon GPE（包含UK/FR/ES/DE/IT）的订单也需满足此要求。 3.订单必须经过ZURU QC验货或者工厂自检通过后方可出货，不涉及第三方验货。 4.法国订单要求包装不使用矿物油，请按要求提供以下其中一份文件再出货 ，产品出到法国被相关部门抽检出现包装不符合此要求的，供应商需要为此承担责任， 故此请严格把关。Amazon GPE（包含UK/FR/ES/DE/IT）的订单也需满足此要求。 -油墨物质""""""""由1 ~ 7个芳香环组成的MOAH""""""""的包装检测报告，要求限值≤1.0%； -包装材料清单，包括包装油墨或物质的信息； -油墨制造商的证书； 5.每一批次出货只能有一个生产日期，不可多个生产日期混在同一批次出货；且零售包装上必须统一加上日期码；外箱对于日期码没有硬性规定； 6.涉及到相关款式会有闪粉的或者微塑料的，请统一默认出无闪粉或者不含微塑料版本； 7.邮包盒及外箱封箱必须是工字型封箱方式； 8.5 Surprise or Mini Brands涉及包装是2个及2个以上的球入PVC桶包装时，单个球上若有UPC#或者EAN#，请用空白贴纸覆盖住，贴纸尺寸自行测量能覆盖原条码即 可； 9. 无论是工厂自检还是ZURU验货，验货报告中必须有产品6面图(正面/背面/左面/右面/顶部/底部，不带包装); 10. 按空海运鉴定报告的要求，只要带锂电池出货，都需要加贴UN贴纸； 11. 所有出往GAS市场(德国/奥地利/瑞士)的电子产品身上需要加字唛，为ZURU FRANCE 地址，需跟包装上的地址一致 (如无电子产品，产品布标有此地址，或产品 太小无法增加可忽略此信息。如产品无法加字唛，需让对应跟单提供产品贴纸资料);（Amazon GPE的订单也需满足此要求） 12. 所有出往GAS德国 (瑞士，奥地利)。水弹枪系列必须使用EN71版本（电子和非电子水弹枪系列都需要符合); 护目镜需打日期码, 格式跟ZURU标准格式一样; 枪 身上增加ZURU FRANCE公司名和地址。使用贴纸和辐射上去都可以。如果有位置，最好增加ZURU Represented by: (此最好翻译德语，如果位置不允许，那么就只增 加ZURU法国和地址)。使用最新的EN71版包装和说明书）。Amazon GPE（包含UK/FR/ES/DE/IT）的订单也需满足此要求。 | Z6: Luna Lin | AA6: 9.86 | AB6: =I6*AA6 -> 5245.52 | AD6: 71172-S003-MB-1L | AE6: 已入 | AO6: =I6 -> 532 | AP6: =I6 -> 532 | AR6: =I6 -> 532 | AU6: 46185
