Workbook

Sheet 名称
A1: 货号 | B1: 贴纸用量 | C1: 装箱数 | D1: 系列 | E1: 名称 | F1: 车间
A2: SR000 | B2: 3 | C2: 360 | D2: 二代
A3: SR100 | B3: 7 | C3: 12 | D3: 二代 | F3: 湖南
A4: SR100CDU-16 | B4: 7 | C4: 16 | D4: 二代 | F4: 湖南
A5: SR100CDU-24 | B5: 7 | C5: 24 | D5: 二代 | F5: 湖南
A6: SR101CDU | B6: 5 | C6: 24 | D6: 二代 | F6: 湖南
A7: SR160 | B7: 5 | C7: 24 | D7: 二代 | F7: 湖南
A8: SR200 | B8: 12 | C8: 6 | D8: 二代 | F8: 湖南
A9: SR200CO | B9: 12 | C9: 6 | D9: 二代 | F9: 湖南
A10: SR300 | B10: 32 | C10: 4 | D10: 二代 | F10: 湖南
A11: SR460 | B11: 12 | C11: 6 | D11: 二代 | F11: 湖南
A12: SR600 | B12: 16 | C12: 6 | D12: 二代 | F12: 湖南
A13: SR100CDU-9 | B13: 7 | C13: 9 | D13: 二代 | F13: 湖南
A14: SR100- | B14: 7 | C14: 144 | D14: 二代 | E14: 密封盒 | F14: 湖南
A15: SR200- | B15: 12 | C15: 24 | D15: 二代 | E15: 密封盒 | F15: 湖南
A16: SR001 | B16: 3 | C16: 250 | D16: 二代 | F16: 湖南
A17: SR102C | B17: 10 | C17: 16 | D17: 二代 | F17: 湖南
A18: SR102CDU-16 | B18: 7 | C18: 16 | D18: 二代 | F18: 湖南
A19: SR201C | B19: 15 | C19: 6 | D19: 二代 | F19: 湖南
A20: SR301C | B20: 35 | C20: 4 | D20: 二代 | F20: 湖南
A21: JS300 | B21: 3 | C21: 12 | D21: 二代 | F21: 东莞
A22: SR103 | B22: 5 | C22: 24 | D22: 二代 | F22: 湖南
A23: SR103CDU-12 | B23: 5 | C23: 12 | D23: 二代 | F23: 湖南
A24: JS100 | B24: 24 | C24: 24 | D24: 二代 | F24: 东莞
A25: SR130 | B25: 5 | C25: 24 | D25: 二代 | F25: 湖南
A26: SR430 | B26: 12 | C26: 6 | D26: 二代 | F26: 湖南
A27: SR102CDU-24 | B27: 7 | C27: 24 | D27: 二代 | F27: 湖南
... A43: JC140 | B43: 0 | C43: 4 | D43: 蛋糕 | F43: 东莞
A44: JS100CDU-24 | C44: 24 | D44: 二代 | F44: 东莞
A45: JS100CDU-9 | C45: 9 | D45: 二代 | F45: 东莞
A46: SR1023CDU-16 | B46: 7 | C46: 16 | D46: 三代 | F46: 湖南
A47: SR102C-CDU-16 | B47: 10 | C47: 16 | D47: 二代 | F47: 湖南
A48: SR102-F-EC | B48: 7 | C48: 144 | D48: 二代 | F48: 湖南
A49: SR1033CDU-24 | B49: 5 | C49: 24 | D49: 三代 | F49: 湖南
A50: SR1602CDU-12 | B50: 5 | C50: 12 | D50: 三代 | F50: 湖南
A51: SR1602CDU-24 | B51: 5 | C51: 24 | D51: 三代 | F51: 湖南
A52: SR160CDU-24 | B52: 5 | C52: 24 | D52: 二代 | F52: 湖南
A53: SR1802CDU-24 | B53: 5 | C53: 24 | D53: 三代 | F53: 湖南
A54: SR180CDU-24 | B54: 5 | C54: 24 | D54: 二代 | F54: 湖南
A55: SR181CDU-24 | B55: 5 | C55: 24 | D55: 二代 | F55: 湖南
...

Sheet 总接单
A1: 产品名称 | I1: =TRIM(LEFT(LEFT(LEFT(I2,IFERROR(FIND("/",I2)-1,LEN(I2))),IFERROR(FIND("CDU",I2)-1,LEN(I2))),IFERROR(FIND("-",I2)-1,LEN(I2)))) -> SR001 | J1: =TRIM(LEFT(LEFT(LEFT(J2,IFERROR(FIND("/",J2)-1,LEN(J2))),IFERROR(FIND("CDU",J2)-1,LEN(J2))),IFERROR(FIND("-",J2)-1,LEN(J2)))) -> SR020 | K1: =TRIM(LEFT(LEFT(LEFT(K2,IFERROR(FIND("/",K2)-1,LEN(K2))),IFERROR(FIND("CDU",K2)-1,LEN(K2))),IFERROR(FIND("-",K2)-1,LEN(K2)))) -> SR102 | L1: =TRIM(LEFT(LEFT(LEFT(L2,IFERROR(FIND("/",L2)-1,LEN(L2))),IFERROR(FIND("CDU",L2)-1,LEN(L2))),IFERROR(FIND("-",L2)-1,LEN(L2)))) -> SR102C | M1: =TRIM(LEFT(LEFT(LEFT(M2,IFERROR(FIND("/",M2)-1,LEN(M2))),IFERROR(FIND("CDU",M2)-1,LEN(M2))),IFERROR(FIND("-",M2)-1,LEN(M2)))) -> SR103 | N1: =TRIM(LEFT(LEFT(LEFT(N2,IFERROR(FIND("/",N2)-1,LEN(N2))),IFERROR(FIND("CDU",N2)-1,LEN(N2))),IFERROR(FIND("-",N2)-1,LEN(N2)))) -> SR130 | O1: =TRIM(LEFT(LEFT(LEFT(O2,IFERROR(FIND("/",O2)-1,LEN(O2))),IFERROR(FIND("CDU",O2)-1,LEN(O2))),IFERROR(FIND("-",O2)-1,LEN(O2)))) -> SR160 | P1: =TRIM(LEFT(LEFT(LEFT(P2,IFERROR(FIND("/",P2)-1,LEN(P2))),IFERROR(FIND("CDU",P2)-1,LEN(P2))),IFERROR(FIND("-",P2)-1,LEN(P2)))) -> SR180 | ... BU1: =TRIM(LEFT(LEFT(LEFT(BU2,IFERROR(FIND("/",BU2)-1,LEN(BU2))),IFERROR(FIND("CDU",BU2)-1,LEN(BU2))),IFERROR(FIND("-",BU2)-1,LEN(BU2)))) -> 散装手链
A2: 接单期 | B2: 出货期 | C2: CUSTOMER PO | D2: PO号 | E2: 货号 | F2: 数量 | G2: 包装版 | H2: =VLOOKUP(E2,名称!A:E,4,0) -> 系列 | I2: SR001 | J2: SR020 | K2: SR102/SR102CDU-9/SR102CDU-16/SR102CDU-24/SR102-F-EC | L2: SR102C/SR102C-CDU-16 | M2: SR103CDU-12/SR103CDU-24 | N2: SR130CDU-12/SR130CDU-24 | O2: SR160CDU-24 | P2: SR180CDU-24 | Q2: SR181CDU-24 | R2: SR201 | S2: SR201C/SR201C-CDU-5 | T2: SR301 | U2: SR320 | V2: SR370 | W2: SR400/SR400CDU-6/SR400CDU-12 | X2: SR430/SR430CDU-6/SR430CDU-12/SR430-ECOMM-C1/SR430-ECOMM-C2/SR430-ECOMM-C3 | Y2: SR460/SR460CDU-6/SR460CDU-12/SR460-EC | Z2: SR600/SR600CDU-6 | AA2: JS100CDU-9/JS100CDU-24 | AB2: JS300 | AC2: SR1023/SR1023CDU-9/SR1023CDU-16/SR1023CDU-24 | AD2: SR1033CDU-12/SR1033CDU-24 | AE2: SR1602CDU-12/SR1602CDU-24 | AF2: SR1802CDU-12/SR1802CDU-24 | AG2: SR2013/SR2013BULK-6/SR2013CDU-5 | AH2: SR3013 | AI2: SR3203/SR3203BULK-2/SR3203-COFP | AJ2: SR3703 | AK2: SR3703QP-12 | AL2: SR4003CDU-12 | AM2: SR4602CDU-6/SR4602CDU-12 | AN2: SR8003CDU-12/SR8003CDU-18/SR8003CDU-24 | AO2: SRAE101CDU-12 | AP2: SRAP1302CDU-24 | AQ2: SRAP3202 | AR2: SRAP4302CDU-6/SRAP4302CDU-12 | AS2: SRBFF3703 | AT2: SRMC103CDU-24 | AU2: SRMC201 | AV2: SRMC302 | AW2: SRMC400CDU-6/SRMC400CDU-12 | AX2: SRSM102CDU-9/SRSM102CDU-16 | AY2: SRSM103CDU-12/SRSM103CDU-24 | AZ2: SRSM301 | BA2: SRTD103CDU-12/SRTD103CDU-24 | BB2: SRTD400CDU-12 | BC2: JS1003CDU-9/JS1003CDU-24 | BD2: JS3003CDU-12 | BE2: JSSM100CDU-24 | BF2: JC100CDU-24 | BG2: JC120CDU-9/JC120CDU-18 | BH2: JC140 | BI2: SRSM400CDU-12 | BJ2: SRAP3203-ECOMM | BK2: SRCRP4202-ECOMM | BL2: SRAP8003CDU-18/CDU-24 | BM2: JS6003-ECOMM | BN2: SRBFF1812CDU-12 | BO2: SRSM103SK-72 | BP2: SRAP8002CDU-24 | BQ2: SRSC101CDU-24 | BR2: SR5163-ECOMM | BS2: JCV120CDU-18 （JC120CDU-18） | BU2: 散装手链 | BV2: 单价USD | BW2: 金额USD | BX2: 金额HKD | BY2: 系列
A3: 45744 | B3: 45816 | D3: BO#0001/2025 | E3: SR370 | F3: =150000-90000-5440-5440-5440-5440-5440-5440-5440-5440 -> 16480 | G3: 客版 | H3: =IFERROR(VLOOKUP(E3,名称!A:E,4,0),"") -> 二代 | I3: =IF(OR($E3="",I$1=""),"",IF(TRIM(LEFT($E3,MIN(IFERROR(FIND("CDU",UPPER($E3)),999),IFERROR(FIND("BULK",UPPER($E3)),999),IFERROR(FIND("-",$E3),999),IFERROR(FIND("（",$E3),999))-1))=I$1,$F3,"")) | J3: =IF(OR($E3="",J$1=""),"",IF(TRIM(LEFT($E3,MIN(IFERROR(FIND("CDU",UPPER($E3)),999),IFERROR(FIND("BULK",UPPER($E3)),999),IFERROR(FIND("-",$E3),999),IFERROR(FIND("（",$E3),999))-1))=J$1,$F3,"")) | K3: =IF(OR($E3="",K$1=""),"",IF(TRIM(LEFT($E3,MIN(IFERROR(FIND("CDU",UPPER($E3)),999),IFERROR(FIND("BULK",UPPER($E3)),999),IFERROR(FIND("-",$E3),999),IFERROR(FIND("（",$E3),999))-1))=K$1,$F3,"")) | L3: =IF(OR($E3="",L$1=""),"",IF(TRIM(LEFT($E3,MIN(IFERROR(FIND("CDU",UPPER($E3)),999),IFERROR(FIND("BULK",UPPER($E3)),999),IFERROR(FIND("-",$E3),999),IFERROR(FIND("（",$E3),999))-1))=L$1,$F3,"")) | M3: =IF(OR($E3="",M$1=""),"",IF(TRIM(LEFT($E3,MIN(IFERROR(FIND("CDU",UPPER($E3)),999),IFERROR(FIND("BULK",UPPER($E3)),999),IFERROR(FIND("-",$E3),999),IFERROR(FIND("（",$E3),999))-1))=M$1,$F3,"")) | N3: =IF(OR($E3="",N$1=""),"",IF(TRIM(LEFT($E3,MIN(IFERROR(FIND("CDU",UPPER($E3)),999),IFERROR(FIND("BULK",UPPER($E3)),999),IFERROR(FIND("-",$E3),999),IFERROR(FIND("（",$E3),999))-1))=N$1,$F3,"")) | O3: =IF(OR($E3="",O$1=""),"",IF(TRIM(LEFT($E3,MIN(IFERROR(FIND("CDU",UPPER($E3)),999),IFERROR(FIND("BULK",UPPER($E3)),999),IFERROR(FIND("-",$E3),999),IFERROR(FIND("（",$E3),999))-1))=O$1,$F3,"")) | P3: =IF(OR($E3="",P$1=""),"",IF(TRIM(LEFT($E3,MIN(IFERROR(FIND("CDU",UPPER($E3)),999),IFERROR(FIND("BULK",UPPER($E3)),999),IFERROR(FIND("-",$E3),999),IFERROR(FIND("（",$E3),999))-1))=P$1,$F3,"")) | ... BU3: =IF(OR($E3="",BU$1=""),"",IF(TRIM(LEFT($E3,MIN(IFERROR(FIND("CDU",UPPER($E3)),999),IFERROR(FIND("BULK",UPPER($E3)),999),IFERROR(FIND("-",$E3),999),IFERROR(FIND("（",$E3),999))-1))=BU$1,$F3,"")) | BV3: 6.93 | BW3: =SUM(I3:BU3)*BV3 -> 114206.4 | BX3: =BW3*7.75 -> 885099.6 | BY3: =MID(E3,1,2) -> SR
A4: 45749 | B4: 45758 | C4: OC00004813 | D4: MXFM002 | E4: SR001 | F4: 5000 | G4: 美文版 | H4: =IFERROR(VLOOKUP(E4,名称!A:E,4,0),"") -> 二代 | I4: =IF(OR($E4="",I$1=""),"",IF(TRIM(LEFT($E4,MIN(IFERROR(FIND("CDU",UPPER($E4)),999),IFERROR(FIND("BULK",UPPER($E4)),999),IFERROR(FIND("-",$E4),999),IFERROR(FIND("（",$E4),999))-1))=I$1,$F4,"")) -> 5000 | J4: =IF(OR($E4="",J$1=""),"",IF(TRIM(LEFT($E4,MIN(IFERROR(FIND("CDU",UPPER($E4)),999),IFERROR(FIND("BULK",UPPER($E4)),999),IFERROR(FIND("-",$E4),999),IFERROR(FIND("（",$E4),999))-1))=J$1,$F4,"")) | K4: =IF(OR($E4="",K$1=""),"",IF(TRIM(LEFT($E4,MIN(IFERROR(FIND("CDU",UPPER($E4)),999),IFERROR(FIND("BULK",UPPER($E4)),999),IFERROR(FIND("-",$E4),999),IFERROR(FIND("（",$E4),999))-1))=K$1,$F4,"")) | L4: =IF(OR($E4="",L$1=""),"",IF(TRIM(LEFT($E4,MIN(IFERROR(FIND("CDU",UPPER($E4)),999),IFERROR(FIND("BULK",UPPER($E4)),999),IFERROR(FIND("-",$E4),999),IFERROR(FIND("（",$E4),999))-1))=L$1,$F4,"")) | M4: =IF(OR($E4="",M$1=""),"",IF(TRIM(LEFT($E4,MIN(IFERROR(FIND("CDU",UPPER($E4)),999),IFERROR(FIND("BULK",UPPER($E4)),999),IFERROR(FIND("-",$E4),999),IFERROR(FIND("（",$E4),999))-1))=M$1,$F4,"")) | N4: =IF(OR($E4="",N$1=""),"",IF(TRIM(LEFT($E4,MIN(IFERROR(FIND("CDU",UPPER($E4)),999),IFERROR(FIND("BULK",UPPER($E4)),999),IFERROR(FIND("-",$E4),999),IFERROR(FIND("（",$E4),999))-1))=N$1,$F4,"")) | O4: =IF(OR($E4="",O$1=""),"",IF(TRIM(LEFT($E4,MIN(IFERROR(FIND("CDU",UPPER($E4)),999),IFERROR(FIND("BULK",UPPER($E4)),999),IFERROR(FIND("-",$E4),999),IFERROR(FIND("（",$E4),999))-1))=O$1,$F4,"")) | P4: =IF(OR($E4="",P$1=""),"",IF(TRIM(LEFT($E4,MIN(IFERROR(FIND("CDU",UPPER($E4)),999),IFERROR(FIND("BULK",UPPER($E4)),999),IFERROR(FIND("-",$E4),999),IFERROR(FIND("（",$E4),999))-1))=P$1,$F4,"")) | ... BU4: =IF(OR($E4="",BU$1=""),"",IF(TRIM(LEFT($E4,MIN(IFERROR(FIND("CDU",UPPER($E4)),999),IFERROR(FIND("BULK",UPPER($E4)),999),IFERROR(FIND("-",$E4),999),IFERROR(FIND("（",$E4),999))-1))=BU$1,$F4,"")) | BV4: 0.1 | BW4: =SUM(I4:BU4)*BV4 -> 500 | BX4: =BW4*7.75 -> 3875 | BY4: =MID(E4,1,2) -> SR
A5: 45807 | B5: 45863 | C5: JAZ254714 | D5: CAJZ039 | E5: SR201 | F5: 1002 | G5: Jazwares客版（2L） | H5: =IFERROR(VLOOKUP(E5,名称!A:E,4,0),"") -> 二代 | I5: =IF(OR($E5="",I$1=""),"",IF(TRIM(LEFT($E5,MIN(IFERROR(FIND("CDU",UPPER($E5)),999),IFERROR(FIND("BULK",UPPER($E5)),999),IFERROR(FIND("-",$E5),999),IFERROR(FIND("（",$E5),999))-1))=I$1,$F5,"")) | J5: =IF(OR($E5="",J$1=""),"",IF(TRIM(LEFT($E5,MIN(IFERROR(FIND("CDU",UPPER($E5)),999),IFERROR(FIND("BULK",UPPER($E5)),999),IFERROR(FIND("-",$E5),999),IFERROR(FIND("（",$E5),999))-1))=J$1,$F5,"")) | K5: =IF(OR($E5="",K$1=""),"",IF(TRIM(LEFT($E5,MIN(IFERROR(FIND("CDU",UPPER($E5)),999),IFERROR(FIND("BULK",UPPER($E5)),999),IFERROR(FIND("-",$E5),999),IFERROR(FIND("（",$E5),999))-1))=K$1,$F5,"")) | L5: =IF(OR($E5="",L$1=""),"",IF(TRIM(LEFT($E5,MIN(IFERROR(FIND("CDU",UPPER($E5)),999),IFERROR(FIND("BULK",UPPER($E5)),999),IFERROR(FIND("-",$E5),999),IFERROR(FIND("（",$E5),999))-1))=L$1,$F5,"")) | M5: =IF(OR($E5="",M$1=""),"",IF(TRIM(LEFT($E5,MIN(IFERROR(FIND("CDU",UPPER($E5)),999),IFERROR(FIND("BULK",UPPER($E5)),999),IFERROR(FIND("-",$E5),999),IFERROR(FIND("（",$E5),999))-1))=M$1,$F5,"")) | N5: =IF(OR($E5="",N$1=""),"",IF(TRIM(LEFT($E5,MIN(IFERROR(FIND("CDU",UPPER($E5)),999),IFERROR(FIND("BULK",UPPER($E5)),999),IFERROR(FIND("-",$E5),999),IFERROR(FIND("（",$E5),999))-1))=N$1,$F5,"")) | O5: =IF(OR($E5="",O$1=""),"",IF(TRIM(LEFT($E5,MIN(IFERROR(FIND("CDU",UPPER($E5)),999),IFERROR(FIND("BULK",UPPER($E5)),999),IFERROR(FIND("-",$E5),999),IFERROR(FIND("（",$E5),999))-1))=O$1,$F5,"")) | P5: =IF(OR($E5="",P$1=""),"",IF(TRIM(LEFT($E5,MIN(IFERROR(FIND("CDU",UPPER($E5)),999),IFERROR(FIND("BULK",UPPER($E5)),999),IFERROR(FIND("-",$E5),999),IFERROR(FIND("（",$E5),999))-1))=P$1,$F5,"")) | ... BU5: =IF(OR($E5="",BU$1=""),"",IF(TRIM(LEFT($E5,MIN(IFERROR(FIND("CDU",UPPER($E5)),999),IFERROR(FIND("BULK",UPPER($E5)),999),IFERROR(FIND("-",$E5),999),IFERROR(FIND("（",$E5),999))-1))=BU$1,$F5,"")) | BV5: 2.1 | BW5: =SUM(I5:BU5)*BV5 -> 2104.2 | BX5: =BW5*7.75 -> 16307.55 | BY5: =MID(E5,1,2) -> SR
A6: 45807 | B6: 45863 | C6: JAZ254715 | D6: CAJZ040 | E6: SR201 | F6: =1800-1500 -> 300 | G6: Jazwares客版（2L） | H6: =IFERROR(VLOOKUP(E6,名称!A:E,4,0),"") -> 二代 | I6: =IF(OR($E6="",I$1=""),"",IF(TRIM(LEFT($E6,MIN(IFERROR(FIND("CDU",UPPER($E6)),999),IFERROR(FIND("BULK",UPPER($E6)),999),IFERROR(FIND("-",$E6),999),IFERROR(FIND("（",$E6),999))-1))=I$1,$F6,"")) | J6: =IF(OR($E6="",J$1=""),"",IF(TRIM(LEFT($E6,MIN(IFERROR(FIND("CDU",UPPER($E6)),999),IFERROR(FIND("BULK",UPPER($E6)),999),IFERROR(FIND("-",$E6),999),IFERROR(FIND("（",$E6),999))-1))=J$1,$F6,"")) | K6: =IF(OR($E6="",K$1=""),"",IF(TRIM(LEFT($E6,MIN(IFERROR(FIND("CDU",UPPER($E6)),999),IFERROR(FIND("BULK",UPPER($E6)),999),IFERROR(FIND("-",$E6),999),IFERROR(FIND("（",$E6),999))-1))=K$1,$F6,"")) | L6: =IF(OR($E6="",L$1=""),"",IF(TRIM(LEFT($E6,MIN(IFERROR(FIND("CDU",UPPER($E6)),999),IFERROR(FIND("BULK",UPPER($E6)),999),IFERROR(FIND("-",$E6),999),IFERROR(FIND("（",$E6),999))-1))=L$1,$F6,"")) | M6: =IF(OR($E6="",M$1=""),"",IF(TRIM(LEFT($E6,MIN(IFERROR(FIND("CDU",UPPER($E6)),999),IFERROR(FIND("BULK",UPPER($E6)),999),IFERROR(FIND("-",$E6),999),IFERROR(FIND("（",$E6),999))-1))=M$1,$F6,"")) | N6: =IF(OR($E6="",N$1=""),"",IF(TRIM(LEFT($E6,MIN(IFERROR(FIND("CDU",UPPER($E6)),999),IFERROR(FIND("BULK",UPPER($E6)),999),IFERROR(FIND("-",$E6),999),IFERROR(FIND("（",$E6),999))-1))=N$1,$F6,"")) | O6: =IF(OR($E6="",O$1=""),"",IF(TRIM(LEFT($E6,MIN(IFERROR(FIND("CDU",UPPER($E6)),999),IFERROR(FIND("BULK",UPPER($E6)),999),IFERROR(FIND("-",$E6),999),IFERROR(FIND("（",$E6),999))-1))=O$1,$F6,"")) | P6: =IF(OR($E6="",P$1=""),"",IF(TRIM(LEFT($E6,MIN(IFERROR(FIND("CDU",UPPER($E6)),999),IFERROR(FIND("BULK",UPPER($E6)),999),IFERROR(FIND("-",$E6),999),IFERROR(FIND("（",$E6),999))-1))=P$1,$F6,"")) | ... BU6: =IF(OR($E6="",BU$1=""),"",IF(TRIM(LEFT($E6,MIN(IFERROR(FIND("CDU",UPPER($E6)),999),IFERROR(FIND("BULK",UPPER($E6)),999),IFERROR(FIND("-",$E6),999),IFERROR(FIND("（",$E6),999))-1))=BU$1,$F6,"")) | BV6: 2.1 | BW6: =SUM(I6:BU6)*BV6 -> 630 | BX6: =BW6*7.75 -> 4882.5 | BY6: =MID(E6,1,2) -> SR
A7: 45807 | B7: 45863 | C7: JAZ254716 | D7: CAJZ041 | E7: SR201 | F7: 2004 | G7: Jazwares客版（2L） | H7: =IFERROR(VLOOKUP(E7,名称!A:E,4,0),"") -> 二代 | I7: =IF(OR($E7="",I$1=""),"",IF(TRIM(LEFT($E7,MIN(IFERROR(FIND("CDU",UPPER($E7)),999),IFERROR(FIND("BULK",UPPER($E7)),999),IFERROR(FIND("-",$E7),999),IFERROR(FIND("（",$E7),999))-1))=I$1,$F7,"")) | J7: =IF(OR($E7="",J$1=""),"",IF(TRIM(LEFT($E7,MIN(IFERROR(FIND("CDU",UPPER($E7)),999),IFERROR(FIND("BULK",UPPER($E7)),999),IFERROR(FIND("-",$E7),999),IFERROR(FIND("（",$E7),999))-1))=J$1,$F7,"")) | K7: =IF(OR($E7="",K$1=""),"",IF(TRIM(LEFT($E7,MIN(IFERROR(FIND("CDU",UPPER($E7)),999),IFERROR(FIND("BULK",UPPER($E7)),999),IFERROR(FIND("-",$E7),999),IFERROR(FIND("（",$E7),999))-1))=K$1,$F7,"")) | L7: =IF(OR($E7="",L$1=""),"",IF(TRIM(LEFT($E7,MIN(IFERROR(FIND("CDU",UPPER($E7)),999),IFERROR(FIND("BULK",UPPER($E7)),999),IFERROR(FIND("-",$E7),999),IFERROR(FIND("（",$E7),999))-1))=L$1,$F7,"")) | M7: =IF(OR($E7="",M$1=""),"",IF(TRIM(LEFT($E7,MIN(IFERROR(FIND("CDU",UPPER($E7)),999),IFERROR(FIND("BULK",UPPER($E7)),999),IFERROR(FIND("-",$E7),999),IFERROR(FIND("（",$E7),999))-1))=M$1,$F7,"")) | N7: =IF(OR($E7="",N$1=""),"",IF(TRIM(LEFT($E7,MIN(IFERROR(FIND("CDU",UPPER($E7)),999),IFERROR(FIND("BULK",UPPER($E7)),999),IFERROR(FIND("-",$E7),999),IFERROR(FIND("（",$E7),999))-1))=N$1,$F7,"")) | O7: =IF(OR($E7="",O$1=""),"",IF(TRIM(LEFT($E7,MIN(IFERROR(FIND("CDU",UPPER($E7)),999),IFERROR(FIND("BULK",UPPER($E7)),999),IFERROR(FIND("-",$E7),999),IFERROR(FIND("（",$E7),999))-1))=O$1,$F7,"")) | P7: =IF(OR($E7="",P$1=""),"",IF(TRIM(LEFT($E7,MIN(IFERROR(FIND("CDU",UPPER($E7)),999),IFERROR(FIND("BULK",UPPER($E7)),999),IFERROR(FIND("-",$E7),999),IFERROR(FIND("（",$E7),999))-1))=P$1,$F7,"")) | ... BU7: =IF(OR($E7="",BU$1=""),"",IF(TRIM(LEFT($E7,MIN(IFERROR(FIND("CDU",UPPER($E7)),999),IFERROR(FIND("BULK",UPPER($E7)),999),IFERROR(FIND("-",$E7),999),IFERROR(FIND("（",$E7),999))-1))=BU$1,$F7,"")) | BV7: 2.1 | BW7: =SUM(I7:BU7)*BV7 -> 4208.4 | BX7: =BW7*7.75 -> 32615.1 | BY7: =MID(E7,1,2) -> SR
A8: 45807 | B8: 45863 | C8: JAZ254716 | D8: CAJZ041 | E8: SR201 | F8: 1200 | G8: Jazwares客版（2L） | H8: =IFERROR(VLOOKUP(E8,名称!A:E,4,0),"") -> 二代 | I8: =IF(OR($E8="",I$1=""),"",IF(TRIM(LEFT($E8,MIN(IFERROR(FIND("CDU",UPPER($E8)),999),IFERROR(FIND("BULK",UPPER($E8)),999),IFERROR(FIND("-",$E8),999),IFERROR(FIND("（",$E8),999))-1))=I$1,$F8,"")) | J8: =IF(OR($E8="",J$1=""),"",IF(TRIM(LEFT($E8,MIN(IFERROR(FIND("CDU",UPPER($E8)),999),IFERROR(FIND("BULK",UPPER($E8)),999),IFERROR(FIND("-",$E8),999),IFERROR(FIND("（",$E8),999))-1))=J$1,$F8,"")) | K8: =IF(OR($E8="",K$1=""),"",IF(TRIM(LEFT($E8,MIN(IFERROR(FIND("CDU",UPPER($E8)),999),IFERROR(FIND("BULK",UPPER($E8)),999),IFERROR(FIND("-",$E8),999),IFERROR(FIND("（",$E8),999))-1))=K$1,$F8,"")) | L8: =IF(OR($E8="",L$1=""),"",IF(TRIM(LEFT($E8,MIN(IFERROR(FIND("CDU",UPPER($E8)),999),IFERROR(FIND("BULK",UPPER($E8)),999),IFERROR(FIND("-",$E8),999),IFERROR(FIND("（",$E8),999))-1))=L$1,$F8,"")) | M8: =IF(OR($E8="",M$1=""),"",IF(TRIM(LEFT($E8,MIN(IFERROR(FIND("CDU",UPPER($E8)),999),IFERROR(FIND("BULK",UPPER($E8)),999),IFERROR(FIND("-",$E8),999),IFERROR(FIND("（",$E8),999))-1))=M$1,$F8,"")) | N8: =IF(OR($E8="",N$1=""),"",IF(TRIM(LEFT($E8,MIN(IFERROR(FIND("CDU",UPPER($E8)),999),IFERROR(FIND("BULK",UPPER($E8)),999),IFERROR(FIND("-",$E8),999),IFERROR(FIND("（",$E8),999))-1))=N$1,$F8,"")) | O8: =IF(OR($E8="",O$1=""),"",IF(TRIM(LEFT($E8,MIN(IFERROR(FIND("CDU",UPPER($E8)),999),IFERROR(FIND("BULK",UPPER($E8)),999),IFERROR(FIND("-",$E8),999),IFERROR(FIND("（",$E8),999))-1))=O$1,$F8,"")) | P8: =IF(OR($E8="",P$1=""),"",IF(TRIM(LEFT($E8,MIN(IFERROR(FIND("CDU",UPPER($E8)),999),IFERROR(FIND("BULK",UPPER($E8)),999),IFERROR(FIND("-",$E8),999),IFERROR(FIND("（",$E8),999))-1))=P$1,$F8,"")) | ... BU8: =IF(OR($E8="",BU$1=""),"",IF(TRIM(LEFT($E8,MIN(IFERROR(FIND("CDU",UPPER($E8)),999),IFERROR(FIND("BULK",UPPER($E8)),999),IFERROR(FIND("-",$E8),999),IFERROR(FIND("（",$E8),999))-1))=BU$1,$F8,"")) | BV8: 2.1 | BW8: =SUM(I8:BU8)*BV8 -> 2520 | BX8: =BW8*7.75 -> 19530 | BY8: =MID(E8,1,2) -> SR
A9: 45807 | B9: 45863 | C9: JAZ254717 | D9: CAJZ042 | E9: SR102C-CDU-16 | F9: 2000 | G9: Jazwares客版（2L） | H9: =IFERROR(VLOOKUP(E9,名称!A:E,4,0),"") -> 二代 | I9: =IF(OR($E9="",I$1=""),"",IF(TRIM(LEFT($E9,MIN(IFERROR(FIND("CDU",UPPER($E9)),999),IFERROR(FIND("BULK",UPPER($E9)),999),IFERROR(FIND("-",$E9),999),IFERROR(FIND("（",$E9),999))-1))=I$1,$F9,"")) | J9: =IF(OR($E9="",J$1=""),"",IF(TRIM(LEFT($E9,MIN(IFERROR(FIND("CDU",UPPER($E9)),999),IFERROR(FIND("BULK",UPPER($E9)),999),IFERROR(FIND("-",$E9),999),IFERROR(FIND("（",$E9),999))-1))=J$1,$F9,"")) | K9: =IF(OR($E9="",K$1=""),"",IF(TRIM(LEFT($E9,MIN(IFERROR(FIND("CDU",UPPER($E9)),999),IFERROR(FIND("BULK",UPPER($E9)),999),IFERROR(FIND("-",$E9),999),IFERROR(FIND("（",$E9),999))-1))=K$1,$F9,"")) | L9: =IF(OR($E9="",L$1=""),"",IF(TRIM(LEFT($E9,MIN(IFERROR(FIND("CDU",UPPER($E9)),999),IFERROR(FIND("BULK",UPPER($E9)),999),IFERROR(FIND("-",$E9),999),IFERROR(FIND("（",$E9),999))-1))=L$1,$F9,"")) -> 2000 | M9: =IF(OR($E9="",M$1=""),"",IF(TRIM(LEFT($E9,MIN(IFERROR(FIND("CDU",UPPER($E9)),999),IFERROR(FIND("BULK",UPPER($E9)),999),IFERROR(FIND("-",$E9),999),IFERROR(FIND("（",$E9),999))-1))=M$1,$F9,"")) | N9: =IF(OR($E9="",N$1=""),"",IF(TRIM(LEFT($E9,MIN(IFERROR(FIND("CDU",UPPER($E9)),999),IFERROR(FIND("BULK",UPPER($E9)),999),IFERROR(FIND("-",$E9),999),IFERROR(FIND("（",$E9),999))-1))=N$1,$F9,"")) | O9: =IF(OR($E9="",O$1=""),"",IF(TRIM(LEFT($E9,MIN(IFERROR(FIND("CDU",UPPER($E9)),999),IFERROR(FIND("BULK",UPPER($E9)),999),IFERROR(FIND("-",$E9),999),IFERROR(FIND("（",$E9),999))-1))=O$1,$F9,"")) | P9: =IF(OR($E9="",P$1=""),"",IF(TRIM(LEFT($E9,MIN(IFERROR(FIND("CDU",UPPER($E9)),999),IFERROR(FIND("BULK",UPPER($E9)),999),IFERROR(FIND("-",$E9),999),IFERROR(FIND("（",$E9),999))-1))=P$1,$F9,"")) | ... BU9: =IF(OR($E9="",BU$1=""),"",IF(TRIM(LEFT($E9,MIN(IFERROR(FIND("CDU",UPPER($E9)),999),IFERROR(FIND("BULK",UPPER($E9)),999),IFERROR(FIND("-",$E9),999),IFERROR(FIND("（",$E9),999))-1))=BU$1,$F9,"")) | BV9: 0.98 | BW9: =SUM(I9:BU9)*BV9 -> 1960 | BX9: =BW9*7.75 -> 15190 | BY9: =MID(E9,1,2) -> SR
A10: 45807 | B10: 45863 | C10: JAZ254717 | D10: CAJZ042 | E10: SR102C-CDU-16 | F10: 3600 | G10: Jazwares客版（2L） | H10: =IFERROR(VLOOKUP(E10,名称!A:E,4,0),"") -> 二代 | I10: =IF(OR($E10="",I$1=""),"",IF(TRIM(LEFT($E10,MIN(IFERROR(FIND("CDU",UPPER($E10)),999),IFERROR(FIND("BULK",UPPER($E10)),999),IFERROR(FIND("-",$E10),999),IFERROR(FIND("（",$E10),999))-1))=I$1,$F10,"")) | J10: =IF(OR($E10="",J$1=""),"",IF(TRIM(LEFT($E10,MIN(IFERROR(FIND("CDU",UPPER($E10)),999),IFERROR(FIND("BULK",UPPER($E10)),999),IFERROR(FIND("-",$E10),999),IFERROR(FIND("（",$E10),999))-1))=J$1,$F10,"")) | K10: =IF(OR($E10="",K$1=""),"",IF(TRIM(LEFT($E10,MIN(IFERROR(FIND("CDU",UPPER($E10)),999),IFERROR(FIND("BULK",UPPER($E10)),999),IFERROR(FIND("-",$E10),999),IFERROR(FIND("（",$E10),999))-1))=K$1,$F10,"")) | L10: =IF(OR($E10="",L$1=""),"",IF(TRIM(LEFT($E10,MIN(IFERROR(FIND("CDU",UPPER($E10)),999),IFERROR(FIND("BULK",UPPER($E10)),999),IFERROR(FIND("-",$E10),999),IFERROR(FIND("（",$E10),999))-1))=L$1,$F10,"")) -> 3600 | M10: =IF(OR($E10="",M$1=""),"",IF(TRIM(LEFT($E10,MIN(IFERROR(FIND("CDU",UPPER($E10)),999),IFERROR(FIND("BULK",UPPER($E10)),999),IFERROR(FIND("-",$E10),999),IFERROR(FIND("（",$E10),999))-1))=M$1,$F10,"")) | N10: =IF(OR($E10="",N$1=""),"",IF(TRIM(LEFT($E10,MIN(IFERROR(FIND("CDU",UPPER($E10)),999),IFERROR(FIND("BULK",UPPER($E10)),999),IFERROR(FIND("-",$E10),999),IFERROR(FIND("（",$E10),999))-1))=N$1,$F10,"")) | O10: =IF(OR($E10="",O$1=""),"",IF(TRIM(LEFT($E10,MIN(IFERROR(FIND("CDU",UPPER($E10)),999),IFERROR(FIND("BULK",UPPER($E10)),999),IFERROR(FIND("-",$E10),999),IFERROR(FIND("（",$E10),999))-1))=O$1,$F10,"")) | P10: =IF(OR($E10="",P$1=""),"",IF(TRIM(LEFT($E10,MIN(IFERROR(FIND("CDU",UPPER($E10)),999),IFERROR(FIND("BULK",UPPER($E10)),999),IFERROR(FIND("-",$E10),999),IFERROR(FIND("（",$E10),999))-1))=P$1,$F10,"")) | ... BU10: =IF(OR($E10="",BU$1=""),"",IF(TRIM(LEFT($E10,MIN(IFERROR(FIND("CDU",UPPER($E10)),999),IFERROR(FIND("BULK",UPPER($E10)),999),IFERROR(FIND("-",$E10),999),IFERROR(FIND("（",$E10),999))-1))=BU$1,$F10,"")) | BV10: 0.98 | BW10: =SUM(I10:BU10)*BV10 -> 3528 | BX10: =BW10*7.75 -> 27342 | BY10: =MID(E10,1,2) -> SR
A11: 45807 | B11: 45863 | C11: JAZ254723 | D11: CAJZ048 | E11: SR102 | F11: 1800 | G11: Jazwares客版（2L） | H11: =IFERROR(VLOOKUP(E11,名称!A:E,4,0),"") -> 二代 | I11: =IF(OR($E11="",I$1=""),"",IF(TRIM(LEFT($E11,MIN(IFERROR(FIND("CDU",UPPER($E11)),999),IFERROR(FIND("BULK",UPPER($E11)),999),IFERROR(FIND("-",$E11),999),IFERROR(FIND("（",$E11),999))-1))=I$1,$F11,"")) | J11: =IF(OR($E11="",J$1=""),"",IF(TRIM(LEFT($E11,MIN(IFERROR(FIND("CDU",UPPER($E11)),999),IFERROR(FIND("BULK",UPPER($E11)),999),IFERROR(FIND("-",$E11),999),IFERROR(FIND("（",$E11),999))-1))=J$1,$F11,"")) | K11: =IF(OR($E11="",K$1=""),"",IF(TRIM(LEFT($E11,MIN(IFERROR(FIND("CDU",UPPER($E11)),999),IFERROR(FIND("BULK",UPPER($E11)),999),IFERROR(FIND("-",$E11),999),IFERROR(FIND("（",$E11),999))-1))=K$1,$F11,"")) -> 1800 | L11: =IF(OR($E11="",L$1=""),"",IF(TRIM(LEFT($E11,MIN(IFERROR(FIND("CDU",UPPER($E11)),999),IFERROR(FIND("BULK",UPPER($E11)),999),IFERROR(FIND("-",$E11),999),IFERROR(FIND("（",$E11),999))-1))=L$1,$F11,"")) | M11: =IF(OR($E11="",M$1=""),"",IF(TRIM(LEFT($E11,MIN(IFERROR(FIND("CDU",UPPER($E11)),999),IFERROR(FIND("BULK",UPPER($E11)),999),IFERROR(FIND("-",$E11),999),IFERROR(FIND("（",$E11),999))-1))=M$1,$F11,"")) | N11: =IF(OR($E11="",N$1=""),"",IF(TRIM(LEFT($E11,MIN(IFERROR(FIND("CDU",UPPER($E11)),999),IFERROR(FIND("BULK",UPPER($E11)),999),IFERROR(FIND("-",$E11),999),IFERROR(FIND("（",$E11),999))-1))=N$1,$F11,"")) | O11: =IF(OR($E11="",O$1=""),"",IF(TRIM(LEFT($E11,MIN(IFERROR(FIND("CDU",UPPER($E11)),999),IFERROR(FIND("BULK",UPPER($E11)),999),IFERROR(FIND("-",$E11),999),IFERROR(FIND("（",$E11),999))-1))=O$1,$F11,"")) | P11: =IF(OR($E11="",P$1=""),"",IF(TRIM(LEFT($E11,MIN(IFERROR(FIND("CDU",UPPER($E11)),999),IFERROR(FIND("BULK",UPPER($E11)),999),IFERROR(FIND("-",$E11),999),IFERROR(FIND("（",$E11),999))-1))=P$1,$F11,"")) | ... BU11: =IF(OR($E11="",BU$1=""),"",IF(TRIM(LEFT($E11,MIN(IFERROR(FIND("CDU",UPPER($E11)),999),IFERROR(FIND("BULK",UPPER($E11)),999),IFERROR(FIND("-",$E11),999),IFERROR(FIND("（",$E11),999))-1))=BU$1,$F11,"")) | BV11: 0.87 | BW11: =SUM(I11:BU11)*BV11 -> 1566 | BX11: =BW11*7.75 -> 12136.5 | BY11: =MID(E11,1,2) -> SR
A12: 45807 | B12: 45863 | C12: JAZ254723 | D12: CAJZ048 | E12: SR102 | F12: 384 | G12: Jazwares客版（2L） | H12: =IFERROR(VLOOKUP(E12,名称!A:E,4,0),"") -> 二代 | I12: =IF(OR($E12="",I$1=""),"",IF(TRIM(LEFT($E12,MIN(IFERROR(FIND("CDU",UPPER($E12)),999),IFERROR(FIND("BULK",UPPER($E12)),999),IFERROR(FIND("-",$E12),999),IFERROR(FIND("（",$E12),999))-1))=I$1,$F12,"")) | J12: =IF(OR($E12="",J$1=""),"",IF(TRIM(LEFT($E12,MIN(IFERROR(FIND("CDU",UPPER($E12)),999),IFERROR(FIND("BULK",UPPER($E12)),999),IFERROR(FIND("-",$E12),999),IFERROR(FIND("（",$E12),999))-1))=J$1,$F12,"")) | K12: =IF(OR($E12="",K$1=""),"",IF(TRIM(LEFT($E12,MIN(IFERROR(FIND("CDU",UPPER($E12)),999),IFERROR(FIND("BULK",UPPER($E12)),999),IFERROR(FIND("-",$E12),999),IFERROR(FIND("（",$E12),999))-1))=K$1,$F12,"")) -> 384 | L12: =IF(OR($E12="",L$1=""),"",IF(TRIM(LEFT($E12,MIN(IFERROR(FIND("CDU",UPPER($E12)),999),IFERROR(FIND("BULK",UPPER($E12)),999),IFERROR(FIND("-",$E12),999),IFERROR(FIND("（",$E12),999))-1))=L$1,$F12,"")) | M12: =IF(OR($E12="",M$1=""),"",IF(TRIM(LEFT($E12,MIN(IFERROR(FIND("CDU",UPPER($E12)),999),IFERROR(FIND("BULK",UPPER($E12)),999),IFERROR(FIND("-",$E12),999),IFERROR(FIND("（",$E12),999))-1))=M$1,$F12,"")) | N12: =IF(OR($E12="",N$1=""),"",IF(TRIM(LEFT($E12,MIN(IFERROR(FIND("CDU",UPPER($E12)),999),IFERROR(FIND("BULK",UPPER($E12)),999),IFERROR(FIND("-",$E12),999),IFERROR(FIND("（",$E12),999))-1))=N$1,$F12,"")) | O12: =IF(OR($E12="",O$1=""),"",IF(TRIM(LEFT($E12,MIN(IFERROR(FIND("CDU",UPPER($E12)),999),IFERROR(FIND("BULK",UPPER($E12)),999),IFERROR(FIND("-",$E12),999),IFERROR(FIND("（",$E12),999))-1))=O$1,$F12,"")) | P12: =IF(OR($E12="",P$1=""),"",IF(TRIM(LEFT($E12,MIN(IFERROR(FIND("CDU",UPPER($E12)),999),IFERROR(FIND("BULK",UPPER($E12)),999),IFERROR(FIND("-",$E12),999),IFERROR(FIND("（",$E12),999))-1))=P$1,$F12,"")) | ... BU12: =IF(OR($E12="",BU$1=""),"",IF(TRIM(LEFT($E12,MIN(IFERROR(FIND("CDU",UPPER($E12)),999),IFERROR(FIND("BULK",UPPER($E12)),999),IFERROR(FIND("-",$E12),999),IFERROR(FIND("（",$E12),999))-1))=BU$1,$F12,"")) | BV12: 0.87 | BW12: =SUM(I12:BU12)*BV12 -> 334.08 | BX12: =BW12*7.75 -> 2589.12 | BY12: =MID(E12,1,2) -> SR
A13: 45807 | B13: 45863 | C13: JAZ254724 | D13: CAJZ049 | E13: SR102 | F13: 1800 | G13: Jazwares客版（2L） | H13: =IFERROR(VLOOKUP(E13,名称!A:E,4,0),"") -> 二代 | I13: =IF(OR($E13="",I$1=""),"",IF(TRIM(LEFT($E13,MIN(IFERROR(FIND("CDU",UPPER($E13)),999),IFERROR(FIND("BULK",UPPER($E13)),999),IFERROR(FIND("-",$E13),999),IFERROR(FIND("（",$E13),999))-1))=I$1,$F13,"")) | J13: =IF(OR($E13="",J$1=""),"",IF(TRIM(LEFT($E13,MIN(IFERROR(FIND("CDU",UPPER($E13)),999),IFERROR(FIND("BULK",UPPER($E13)),999),IFERROR(FIND("-",$E13),999),IFERROR(FIND("（",$E13),999))-1))=J$1,$F13,"")) | K13: =IF(OR($E13="",K$1=""),"",IF(TRIM(LEFT($E13,MIN(IFERROR(FIND("CDU",UPPER($E13)),999),IFERROR(FIND("BULK",UPPER($E13)),999),IFERROR(FIND("-",$E13),999),IFERROR(FIND("（",$E13),999))-1))=K$1,$F13,"")) -> 1800 | L13: =IF(OR($E13="",L$1=""),"",IF(TRIM(LEFT($E13,MIN(IFERROR(FIND("CDU",UPPER($E13)),999),IFERROR(FIND("BULK",UPPER($E13)),999),IFERROR(FIND("-",$E13),999),IFERROR(FIND("（",$E13),999))-1))=L$1,$F13,"")) | M13: =IF(OR($E13="",M$1=""),"",IF(TRIM(LEFT($E13,MIN(IFERROR(FIND("CDU",UPPER($E13)),999),IFERROR(FIND("BULK",UPPER($E13)),999),IFERROR(FIND("-",$E13),999),IFERROR(FIND("（",$E13),999))-1))=M$1,$F13,"")) | N13: =IF(OR($E13="",N$1=""),"",IF(TRIM(LEFT($E13,MIN(IFERROR(FIND("CDU",UPPER($E13)),999),IFERROR(FIND("BULK",UPPER($E13)),999),IFERROR(FIND("-",$E13),999),IFERROR(FIND("（",$E13),999))-1))=N$1,$F13,"")) | O13: =IF(OR($E13="",O$1=""),"",IF(TRIM(LEFT($E13,MIN(IFERROR(FIND("CDU",UPPER($E13)),999),IFERROR(FIND("BULK",UPPER($E13)),999),IFERROR(FIND("-",$E13),999),IFERROR(FIND("（",$E13),999))-1))=O$1,$F13,"")) | P13: =IF(OR($E13="",P$1=""),"",IF(TRIM(LEFT($E13,MIN(IFERROR(FIND("CDU",UPPER($E13)),999),IFERROR(FIND("BULK",UPPER($E13)),999),IFERROR(FIND("-",$E13),999),IFERROR(FIND("（",$E13),999))-1))=P$1,$F13,"")) | ... BU13: =IF(OR($E13="",BU$1=""),"",IF(TRIM(LEFT($E13,MIN(IFERROR(FIND("CDU",UPPER($E13)),999),IFERROR(FIND("BULK",UPPER($E13)),999),IFERROR(FIND("-",$E13),999),IFERROR(FIND("（",$E13),999))-1))=BU$1,$F13,"")) | BV13: 0.87 | BW13: =SUM(I13:BU13)*BV13 -> 1566 | BX13: =BW13*7.75 -> 12136.5 | BY13: =MID(E13,1,2) -> SR
A14: 45807 | B14: 45863 | C14: JAZ254725 | D14: CAJZ050 | E14: SR130CDU-24 | F14: =1800-1200 -> 600 | G14: Jazwares客版（2L） | H14: =IFERROR(VLOOKUP(E14,名称!A:E,4,0),"") -> 二代 | I14: =IF(OR($E14="",I$1=""),"",IF(TRIM(LEFT($E14,MIN(IFERROR(FIND("CDU",UPPER($E14)),999),IFERROR(FIND("BULK",UPPER($E14)),999),IFERROR(FIND("-",$E14),999),IFERROR(FIND("（",$E14),999))-1))=I$1,$F14,"")) | J14: =IF(OR($E14="",J$1=""),"",IF(TRIM(LEFT($E14,MIN(IFERROR(FIND("CDU",UPPER($E14)),999),IFERROR(FIND("BULK",UPPER($E14)),999),IFERROR(FIND("-",$E14),999),IFERROR(FIND("（",$E14),999))-1))=J$1,$F14,"")) | K14: =IF(OR($E14="",K$1=""),"",IF(TRIM(LEFT($E14,MIN(IFERROR(FIND("CDU",UPPER($E14)),999),IFERROR(FIND("BULK",UPPER($E14)),999),IFERROR(FIND("-",$E14),999),IFERROR(FIND("（",$E14),999))-1))=K$1,$F14,"")) | L14: =IF(OR($E14="",L$1=""),"",IF(TRIM(LEFT($E14,MIN(IFERROR(FIND("CDU",UPPER($E14)),999),IFERROR(FIND("BULK",UPPER($E14)),999),IFERROR(FIND("-",$E14),999),IFERROR(FIND("（",$E14),999))-1))=L$1,$F14,"")) | M14: =IF(OR($E14="",M$1=""),"",IF(TRIM(LEFT($E14,MIN(IFERROR(FIND("CDU",UPPER($E14)),999),IFERROR(FIND("BULK",UPPER($E14)),999),IFERROR(FIND("-",$E14),999),IFERROR(FIND("（",$E14),999))-1))=M$1,$F14,"")) | N14: =IF(OR($E14="",N$1=""),"",IF(TRIM(LEFT($E14,MIN(IFERROR(FIND("CDU",UPPER($E14)),999),IFERROR(FIND("BULK",UPPER($E14)),999),IFERROR(FIND("-",$E14),999),IFERROR(FIND("（",$E14),999))-1))=N$1,$F14,"")) -> 600 | O14: =IF(OR($E14="",O$1=""),"",IF(TRIM(LEFT($E14,MIN(IFERROR(FIND("CDU",UPPER($E14)),999),IFERROR(FIND("BULK",UPPER($E14)),999),IFERROR(FIND("-",$E14),999),IFERROR(FIND("（",$E14),999))-1))=O$1,$F14,"")) | P14: =IF(OR($E14="",P$1=""),"",IF(TRIM(LEFT($E14,MIN(IFERROR(FIND("CDU",UPPER($E14)),999),IFERROR(FIND("BULK",UPPER($E14)),999),IFERROR(FIND("-",$E14),999),IFERROR(FIND("（",$E14),999))-1))=P$1,$F14,"")) | ... BU14: =IF(OR($E14="",BU$1=""),"",IF(TRIM(LEFT($E14,MIN(IFERROR(FIND("CDU",UPPER($E14)),999),IFERROR(FIND("BULK",UPPER($E14)),999),IFERROR(FIND("-",$E14),999),IFERROR(FIND("（",$E14),999))-1))=BU$1,$F14,"")) | BV14: 0.62 | BW14: =SUM(I14:BU14)*BV14 -> 372 | BX14: =BW14*7.75 -> 2883 | BY14: =MID(E14,1,2) -> SR
A15: 45807 | B15: 45863 | C15: JAZ254725 | D15: CAJZ050 | E15: SR130CDU-24 | F15: 2280 | G15: Jazwares客版（2L） | H15: =IFERROR(VLOOKUP(E15,名称!A:E,4,0),"") -> 二代 | I15: =IF(OR($E15="",I$1=""),"",IF(TRIM(LEFT($E15,MIN(IFERROR(FIND("CDU",UPPER($E15)),999),IFERROR(FIND("BULK",UPPER($E15)),999),IFERROR(FIND("-",$E15),999),IFERROR(FIND("（",$E15),999))-1))=I$1,$F15,"")) | J15: =IF(OR($E15="",J$1=""),"",IF(TRIM(LEFT($E15,MIN(IFERROR(FIND("CDU",UPPER($E15)),999),IFERROR(FIND("BULK",UPPER($E15)),999),IFERROR(FIND("-",$E15),999),IFERROR(FIND("（",$E15),999))-1))=J$1,$F15,"")) | K15: =IF(OR($E15="",K$1=""),"",IF(TRIM(LEFT($E15,MIN(IFERROR(FIND("CDU",UPPER($E15)),999),IFERROR(FIND("BULK",UPPER($E15)),999),IFERROR(FIND("-",$E15),999),IFERROR(FIND("（",$E15),999))-1))=K$1,$F15,"")) | L15: =IF(OR($E15="",L$1=""),"",IF(TRIM(LEFT($E15,MIN(IFERROR(FIND("CDU",UPPER($E15)),999),IFERROR(FIND("BULK",UPPER($E15)),999),IFERROR(FIND("-",$E15),999),IFERROR(FIND("（",$E15),999))-1))=L$1,$F15,"")) | M15: =IF(OR($E15="",M$1=""),"",IF(TRIM(LEFT($E15,MIN(IFERROR(FIND("CDU",UPPER($E15)),999),IFERROR(FIND("BULK",UPPER($E15)),999),IFERROR(FIND("-",$E15),999),IFERROR(FIND("（",$E15),999))-1))=M$1,$F15,"")) | N15: =IF(OR($E15="",N$1=""),"",IF(TRIM(LEFT($E15,MIN(IFERROR(FIND("CDU",UPPER($E15)),999),IFERROR(FIND("BULK",UPPER($E15)),999),IFERROR(FIND("-",$E15),999),IFERROR(FIND("（",$E15),999))-1))=N$1,$F15,"")) -> 2280 | O15: =IF(OR($E15="",O$1=""),"",IF(TRIM(LEFT($E15,MIN(IFERROR(FIND("CDU",UPPER($E15)),999),IFERROR(FIND("BULK",UPPER($E15)),999),IFERROR(FIND("-",$E15),999),IFERROR(FIND("（",$E15),999))-1))=O$1,$F15,"")) | P15: =IF(OR($E15="",P$1=""),"",IF(TRIM(LEFT($E15,MIN(IFERROR(FIND("CDU",UPPER($E15)),999),IFERROR(FIND("BULK",UPPER($E15)),999),IFERROR(FIND("-",$E15),999),IFERROR(FIND("（",$E15),999))-1))=P$1,$F15,"")) | ... BU15: =IF(OR($E15="",BU$1=""),"",IF(TRIM(LEFT($E15,MIN(IFERROR(FIND("CDU",UPPER($E15)),999),IFERROR(FIND("BULK",UPPER($E15)),999),IFERROR(FIND("-",$E15),999),IFERROR(FIND("（",$E15),999))-1))=BU$1,$F15,"")) | BV15: 0.62 | BW15: =SUM(I15:BU15)*BV15 -> 1413.6 | BX15: =BW15*7.75 -> 10955.4 | BY15: =MID(E15,1,2) -> SR
A16: 45807 | B16: 45863 | C16: JAZ254726 | D16: CAJZ051 | E16: SR130CDU-24 | F16: 2400 | G16: Jazwares客版（2L） | H16: =IFERROR(VLOOKUP(E16,名称!A:E,4,0),"") -> 二代 | I16: =IF(OR($E16="",I$1=""),"",IF(TRIM(LEFT($E16,MIN(IFERROR(FIND("CDU",UPPER($E16)),999),IFERROR(FIND("BULK",UPPER($E16)),999),IFERROR(FIND("-",$E16),999),IFERROR(FIND("（",$E16),999))-1))=I$1,$F16,"")) | J16: =IF(OR($E16="",J$1=""),"",IF(TRIM(LEFT($E16,MIN(IFERROR(FIND("CDU",UPPER($E16)),999),IFERROR(FIND("BULK",UPPER($E16)),999),IFERROR(FIND("-",$E16),999),IFERROR(FIND("（",$E16),999))-1))=J$1,$F16,"")) | K16: =IF(OR($E16="",K$1=""),"",IF(TRIM(LEFT($E16,MIN(IFERROR(FIND("CDU",UPPER($E16)),999),IFERROR(FIND("BULK",UPPER($E16)),999),IFERROR(FIND("-",$E16),999),IFERROR(FIND("（",$E16),999))-1))=K$1,$F16,"")) | L16: =IF(OR($E16="",L$1=""),"",IF(TRIM(LEFT($E16,MIN(IFERROR(FIND("CDU",UPPER($E16)),999),IFERROR(FIND("BULK",UPPER($E16)),999),IFERROR(FIND("-",$E16),999),IFERROR(FIND("（",$E16),999))-1))=L$1,$F16,"")) | M16: =IF(OR($E16="",M$1=""),"",IF(TRIM(LEFT($E16,MIN(IFERROR(FIND("CDU",UPPER($E16)),999),IFERROR(FIND("BULK",UPPER($E16)),999),IFERROR(FIND("-",$E16),999),IFERROR(FIND("（",$E16),999))-1))=M$1,$F16,"")) | N16: =IF(OR($E16="",N$1=""),"",IF(TRIM(LEFT($E16,MIN(IFERROR(FIND("CDU",UPPER($E16)),999),IFERROR(FIND("BULK",UPPER($E16)),999),IFERROR(FIND("-",$E16),999),IFERROR(FIND("（",$E16),999))-1))=N$1,$F16,"")) -> 2400 | O16: =IF(OR($E16="",O$1=""),"",IF(TRIM(LEFT($E16,MIN(IFERROR(FIND("CDU",UPPER($E16)),999),IFERROR(FIND("BULK",UPPER($E16)),999),IFERROR(FIND("-",$E16),999),IFERROR(FIND("（",$E16),999))-1))=O$1,$F16,"")) | P16: =IF(OR($E16="",P$1=""),"",IF(TRIM(LEFT($E16,MIN(IFERROR(FIND("CDU",UPPER($E16)),999),IFERROR(FIND("BULK",UPPER($E16)),999),IFERROR(FIND("-",$E16),999),IFERROR(FIND("（",$E16),999))-1))=P$1,$F16,"")) | ... BU16: =IF(OR($E16="",BU$1=""),"",IF(TRIM(LEFT($E16,MIN(IFERROR(FIND("CDU",UPPER($E16)),999),IFERROR(FIND("BULK",UPPER($E16)),999),IFERROR(FIND("-",$E16),999),IFERROR(FIND("（",$E16),999))-1))=BU$1,$F16,"")) | BV16: 0.62 | BW16: =SUM(I16:BU16)*BV16 -> 1488 | BX16: =BW16*7.75 -> 11532 | BY16: =MID(E16,1,2) -> SR
A17: 45915 | B17: 46087 | C17: JAZ270135 | D17: USJZ141 | E17: SR130CDU-24 | F17: 6216 | G17: Jazwares客版（美文） | H17: =IFERROR(VLOOKUP(E17,名称!A:E,4,0),"") -> 二代 | I17: =IF(OR($E17="",I$1=""),"",IF(TRIM(LEFT($E17,MIN(IFERROR(FIND("CDU",UPPER($E17)),999),IFERROR(FIND("BULK",UPPER($E17)),999),IFERROR(FIND("-",$E17),999),IFERROR(FIND("（",$E17),999))-1))=I$1,$F17,"")) | J17: =IF(OR($E17="",J$1=""),"",IF(TRIM(LEFT($E17,MIN(IFERROR(FIND("CDU",UPPER($E17)),999),IFERROR(FIND("BULK",UPPER($E17)),999),IFERROR(FIND("-",$E17),999),IFERROR(FIND("（",$E17),999))-1))=J$1,$F17,"")) | K17: =IF(OR($E17="",K$1=""),"",IF(TRIM(LEFT($E17,MIN(IFERROR(FIND("CDU",UPPER($E17)),999),IFERROR(FIND("BULK",UPPER($E17)),999),IFERROR(FIND("-",$E17),999),IFERROR(FIND("（",$E17),999))-1))=K$1,$F17,"")) | L17: =IF(OR($E17="",L$1=""),"",IF(TRIM(LEFT($E17,MIN(IFERROR(FIND("CDU",UPPER($E17)),999),IFERROR(FIND("BULK",UPPER($E17)),999),IFERROR(FIND("-",$E17),999),IFERROR(FIND("（",$E17),999))-1))=L$1,$F17,"")) | M17: =IF(OR($E17="",M$1=""),"",IF(TRIM(LEFT($E17,MIN(IFERROR(FIND("CDU",UPPER($E17)),999),IFERROR(FIND("BULK",UPPER($E17)),999),IFERROR(FIND("-",$E17),999),IFERROR(FIND("（",$E17),999))-1))=M$1,$F17,"")) | N17: =IF(OR($E17="",N$1=""),"",IF(TRIM(LEFT($E17,MIN(IFERROR(FIND("CDU",UPPER($E17)),999),IFERROR(FIND("BULK",UPPER($E17)),999),IFERROR(FIND("-",$E17),999),IFERROR(FIND("（",$E17),999))-1))=N$1,$F17,"")) -> 6216 | O17: =IF(OR($E17="",O$1=""),"",IF(TRIM(LEFT($E17,MIN(IFERROR(FIND("CDU",UPPER($E17)),999),IFERROR(FIND("BULK",UPPER($E17)),999),IFERROR(FIND("-",$E17),999),IFERROR(FIND("（",$E17),999))-1))=O$1,$F17,"")) | P17: =IF(OR($E17="",P$1=""),"",IF(TRIM(LEFT($E17,MIN(IFERROR(FIND("CDU",UPPER($E17)),999),IFERROR(FIND("BULK",UPPER($E17)),999),IFERROR(FIND("-",$E17),999),IFERROR(FIND("（",$E17),999))-1))=P$1,$F17,"")) | ... BU17: =IF(OR($E17="",BU$1=""),"",IF(TRIM(LEFT($E17,MIN(IFERROR(FIND("CDU",UPPER($E17)),999),IFERROR(FIND("BULK",UPPER($E17)),999),IFERROR(FIND("-",$E17),999),IFERROR(FIND("（",$E17),999))-1))=BU$1,$F17,"")) | BV17: 0.61 | BW17: =SUM(I17:BU17)*BV17 -> 3791.76 | BX17: =BW17*7.75 -> 29386.14 | BY17: =MID(E17,1,2) -> SR
A18: 45915 | B18: 46045 | C18: JAZ270140 | D18: USJZ140 | E18: SR103CDU-24 | F18: 6048 | G18: Jazwares客版（美文） | H18: =IFERROR(VLOOKUP(E18,名称!A:E,4,0),"") -> 二代 | I18: =IF(OR($E18="",I$1=""),"",IF(TRIM(LEFT($E18,MIN(IFERROR(FIND("CDU",UPPER($E18)),999),IFERROR(FIND("BULK",UPPER($E18)),999),IFERROR(FIND("-",$E18),999),IFERROR(FIND("（",$E18),999))-1))=I$1,$F18,"")) | J18: =IF(OR($E18="",J$1=""),"",IF(TRIM(LEFT($E18,MIN(IFERROR(FIND("CDU",UPPER($E18)),999),IFERROR(FIND("BULK",UPPER($E18)),999),IFERROR(FIND("-",$E18),999),IFERROR(FIND("（",$E18),999))-1))=J$1,$F18,"")) | K18: =IF(OR($E18="",K$1=""),"",IF(TRIM(LEFT($E18,MIN(IFERROR(FIND("CDU",UPPER($E18)),999),IFERROR(FIND("BULK",UPPER($E18)),999),IFERROR(FIND("-",$E18),999),IFERROR(FIND("（",$E18),999))-1))=K$1,$F18,"")) | L18: =IF(OR($E18="",L$1=""),"",IF(TRIM(LEFT($E18,MIN(IFERROR(FIND("CDU",UPPER($E18)),999),IFERROR(FIND("BULK",UPPER($E18)),999),IFERROR(FIND("-",$E18),999),IFERROR(FIND("（",$E18),999))-1))=L$1,$F18,"")) | M18: =IF(OR($E18="",M$1=""),"",IF(TRIM(LEFT($E18,MIN(IFERROR(FIND("CDU",UPPER($E18)),999),IFERROR(FIND("BULK",UPPER($E18)),999),IFERROR(FIND("-",$E18),999),IFERROR(FIND("（",$E18),999))-1))=M$1,$F18,"")) -> 6048 | N18: =IF(OR($E18="",N$1=""),"",IF(TRIM(LEFT($E18,MIN(IFERROR(FIND("CDU",UPPER($E18)),999),IFERROR(FIND("BULK",UPPER($E18)),999),IFERROR(FIND("-",$E18),999),IFERROR(FIND("（",$E18),999))-1))=N$1,$F18,"")) | O18: =IF(OR($E18="",O$1=""),"",IF(TRIM(LEFT($E18,MIN(IFERROR(FIND("CDU",UPPER($E18)),999),IFERROR(FIND("BULK",UPPER($E18)),999),IFERROR(FIND("-",$E18),999),IFERROR(FIND("（",$E18),999))-1))=O$1,$F18,"")) | P18: =IF(OR($E18="",P$1=""),"",IF(TRIM(LEFT($E18,MIN(IFERROR(FIND("CDU",UPPER($E18)),999),IFERROR(FIND("BULK",UPPER($E18)),999),IFERROR(FIND("-",$E18),999),IFERROR(FIND("（",$E18),999))-1))=P$1,$F18,"")) | ... BU18: =IF(OR($E18="",BU$1=""),"",IF(TRIM(LEFT($E18,MIN(IFERROR(FIND("CDU",UPPER($E18)),999),IFERROR(FIND("BULK",UPPER($E18)),999),IFERROR(FIND("-",$E18),999),IFERROR(FIND("（",$E18),999))-1))=BU$1,$F18,"")) | BV18: 0.61 | BW18: =SUM(I18:BU18)*BV18 -> 3689.28 | BX18: =BW18*7.75 -> 28591.92 | BY18: =MID(E18,1,2) -> SR
A19: 45915 | B19: 46045 | C19: JAZ270141 | D19: USJZ139 | E19: SR201C | F19: 2400 | G19: Jazwares客版（美文） | H19: =IFERROR(VLOOKUP(E19,名称!A:E,4,0),"") -> 二代 | I19: =IF(OR($E19="",I$1=""),"",IF(TRIM(LEFT($E19,MIN(IFERROR(FIND("CDU",UPPER($E19)),999),IFERROR(FIND("BULK",UPPER($E19)),999),IFERROR(FIND("-",$E19),999),IFERROR(FIND("（",$E19),999))-1))=I$1,$F19,"")) | J19: =IF(OR($E19="",J$1=""),"",IF(TRIM(LEFT($E19,MIN(IFERROR(FIND("CDU",UPPER($E19)),999),IFERROR(FIND("BULK",UPPER($E19)),999),IFERROR(FIND("-",$E19),999),IFERROR(FIND("（",$E19),999))-1))=J$1,$F19,"")) | K19: =IF(OR($E19="",K$1=""),"",IF(TRIM(LEFT($E19,MIN(IFERROR(FIND("CDU",UPPER($E19)),999),IFERROR(FIND("BULK",UPPER($E19)),999),IFERROR(FIND("-",$E19),999),IFERROR(FIND("（",$E19),999))-1))=K$1,$F19,"")) | L19: =IF(OR($E19="",L$1=""),"",IF(TRIM(LEFT($E19,MIN(IFERROR(FIND("CDU",UPPER($E19)),999),IFERROR(FIND("BULK",UPPER($E19)),999),IFERROR(FIND("-",$E19),999),IFERROR(FIND("（",$E19),999))-1))=L$1,$F19,"")) | M19: =IF(OR($E19="",M$1=""),"",IF(TRIM(LEFT($E19,MIN(IFERROR(FIND("CDU",UPPER($E19)),999),IFERROR(FIND("BULK",UPPER($E19)),999),IFERROR(FIND("-",$E19),999),IFERROR(FIND("（",$E19),999))-1))=M$1,$F19,"")) | N19: =IF(OR($E19="",N$1=""),"",IF(TRIM(LEFT($E19,MIN(IFERROR(FIND("CDU",UPPER($E19)),999),IFERROR(FIND("BULK",UPPER($E19)),999),IFERROR(FIND("-",$E19),999),IFERROR(FIND("（",$E19),999))-1))=N$1,$F19,"")) | O19: =IF(OR($E19="",O$1=""),"",IF(TRIM(LEFT($E19,MIN(IFERROR(FIND("CDU",UPPER($E19)),999),IFERROR(FIND("BULK",UPPER($E19)),999),IFERROR(FIND("-",$E19),999),IFERROR(FIND("（",$E19),999))-1))=O$1,$F19,"")) | P19: =IF(OR($E19="",P$1=""),"",IF(TRIM(LEFT($E19,MIN(IFERROR(FIND("CDU",UPPER($E19)),999),IFERROR(FIND("BULK",UPPER($E19)),999),IFERROR(FIND("-",$E19),999),IFERROR(FIND("（",$E19),999))-1))=P$1,$F19,"")) | ... BU19: =IF(OR($E19="",BU$1=""),"",IF(TRIM(LEFT($E19,MIN(IFERROR(FIND("CDU",UPPER($E19)),999),IFERROR(FIND("BULK",UPPER($E19)),999),IFERROR(FIND("-",$E19),999),IFERROR(FIND("（",$E19),999))-1))=BU$1,$F19,"")) | BV19: 2.14 | BW19: =SUM(I19:BU19)*BV19 -> 5136 | BX19: =BW19*7.75 -> 39804 | BY19: =MID(E19,1,2) -> SR
A20: 45915 | B20: 46045 | C20: JAZ270136 | D20: USJZ138 | E20: SR130CDU-24 | F20: 6216 | G20: Jazwares客版（美文） | H20: =IFERROR(VLOOKUP(E20,名称!A:E,4,0),"") -> 二代 | I20: =IF(OR($E20="",I$1=""),"",IF(TRIM(LEFT($E20,MIN(IFERROR(FIND("CDU",UPPER($E20)),999),IFERROR(FIND("BULK",UPPER($E20)),999),IFERROR(FIND("-",$E20),999),IFERROR(FIND("（",$E20),999))-1))=I$1,$F20,"")) | J20: =IF(OR($E20="",J$1=""),"",IF(TRIM(LEFT($E20,MIN(IFERROR(FIND("CDU",UPPER($E20)),999),IFERROR(FIND("BULK",UPPER($E20)),999),IFERROR(FIND("-",$E20),999),IFERROR(FIND("（",$E20),999))-1))=J$1,$F20,"")) | K20: =IF(OR($E20="",K$1=""),"",IF(TRIM(LEFT($E20,MIN(IFERROR(FIND("CDU",UPPER($E20)),999),IFERROR(FIND("BULK",UPPER($E20)),999),IFERROR(FIND("-",$E20),999),IFERROR(FIND("（",$E20),999))-1))=K$1,$F20,"")) | L20: =IF(OR($E20="",L$1=""),"",IF(TRIM(LEFT($E20,MIN(IFERROR(FIND("CDU",UPPER($E20)),999),IFERROR(FIND("BULK",UPPER($E20)),999),IFERROR(FIND("-",$E20),999),IFERROR(FIND("（",$E20),999))-1))=L$1,$F20,"")) | M20: =IF(OR($E20="",M$1=""),"",IF(TRIM(LEFT($E20,MIN(IFERROR(FIND("CDU",UPPER($E20)),999),IFERROR(FIND("BULK",UPPER($E20)),999),IFERROR(FIND("-",$E20),999),IFERROR(FIND("（",$E20),999))-1))=M$1,$F20,"")) | N20: =IF(OR($E20="",N$1=""),"",IF(TRIM(LEFT($E20,MIN(IFERROR(FIND("CDU",UPPER($E20)),999),IFERROR(FIND("BULK",UPPER($E20)),999),IFERROR(FIND("-",$E20),999),IFERROR(FIND("（",$E20),999))-1))=N$1,$F20,"")) -> 6216 | O20: =IF(OR($E20="",O$1=""),"",IF(TRIM(LEFT($E20,MIN(IFERROR(FIND("CDU",UPPER($E20)),999),IFERROR(FIND("BULK",UPPER($E20)),999),IFERROR(FIND("-",$E20),999),IFERROR(FIND("（",$E20),999))-1))=O$1,$F20,"")) | P20: =IF(OR($E20="",P$1=""),"",IF(TRIM(LEFT($E20,MIN(IFERROR(FIND("CDU",UPPER($E20)),999),IFERROR(FIND("BULK",UPPER($E20)),999),IFERROR(FIND("-",$E20),999),IFERROR(FIND("（",$E20),999))-1))=P$1,$F20,"")) | ... BU20: =IF(OR($E20="",BU$1=""),"",IF(TRIM(LEFT($E20,MIN(IFERROR(FIND("CDU",UPPER($E20)),999),IFERROR(FIND("BULK",UPPER($E20)),999),IFERROR(FIND("-",$E20),999),IFERROR(FIND("（",$E20),999))-1))=BU$1,$F20,"")) | BV20: 0.61 | BW20: =SUM(I20:BU20)*BV20 -> 3791.76 | BX20: =BW20*7.75 -> 29386.14 | BY20: =MID(E20,1,2) -> SR
A21: 45915 | B21: 46045 | C21: JAZ270142 | D21: USJZ137 | E21: SR201C | F21: 2400 | G21: Jazwares客版（美文） | H21: =IFERROR(VLOOKUP(E21,名称!A:E,4,0),"") -> 二代 | I21: =IF(OR($E21="",I$1=""),"",IF(TRIM(LEFT($E21,MIN(IFERROR(FIND("CDU",UPPER($E21)),999),IFERROR(FIND("BULK",UPPER($E21)),999),IFERROR(FIND("-",$E21),999),IFERROR(FIND("（",$E21),999))-1))=I$1,$F21,"")) | J21: =IF(OR($E21="",J$1=""),"",IF(TRIM(LEFT($E21,MIN(IFERROR(FIND("CDU",UPPER($E21)),999),IFERROR(FIND("BULK",UPPER($E21)),999),IFERROR(FIND("-",$E21),999),IFERROR(FIND("（",$E21),999))-1))=J$1,$F21,"")) | K21: =IF(OR($E21="",K$1=""),"",IF(TRIM(LEFT($E21,MIN(IFERROR(FIND("CDU",UPPER($E21)),999),IFERROR(FIND("BULK",UPPER($E21)),999),IFERROR(FIND("-",$E21),999),IFERROR(FIND("（",$E21),999))-1))=K$1,$F21,"")) | L21: =IF(OR($E21="",L$1=""),"",IF(TRIM(LEFT($E21,MIN(IFERROR(FIND("CDU",UPPER($E21)),999),IFERROR(FIND("BULK",UPPER($E21)),999),IFERROR(FIND("-",$E21),999),IFERROR(FIND("（",$E21),999))-1))=L$1,$F21,"")) | M21: =IF(OR($E21="",M$1=""),"",IF(TRIM(LEFT($E21,MIN(IFERROR(FIND("CDU",UPPER($E21)),999),IFERROR(FIND("BULK",UPPER($E21)),999),IFERROR(FIND("-",$E21),999),IFERROR(FIND("（",$E21),999))-1))=M$1,$F21,"")) | N21: =IF(OR($E21="",N$1=""),"",IF(TRIM(LEFT($E21,MIN(IFERROR(FIND("CDU",UPPER($E21)),999),IFERROR(FIND("BULK",UPPER($E21)),999),IFERROR(FIND("-",$E21),999),IFERROR(FIND("（",$E21),999))-1))=N$1,$F21,"")) | O21: =IF(OR($E21="",O$1=""),"",IF(TRIM(LEFT($E21,MIN(IFERROR(FIND("CDU",UPPER($E21)),999),IFERROR(FIND("BULK",UPPER($E21)),999),IFERROR(FIND("-",$E21),999),IFERROR(FIND("（",$E21),999))-1))=O$1,$F21,"")) | P21: =IF(OR($E21="",P$1=""),"",IF(TRIM(LEFT($E21,MIN(IFERROR(FIND("CDU",UPPER($E21)),999),IFERROR(FIND("BULK",UPPER($E21)),999),IFERROR(FIND("-",$E21),999),IFERROR(FIND("（",$E21),999))-1))=P$1,$F21,"")) | ... BU21: =IF(OR($E21="",BU$1=""),"",IF(TRIM(LEFT($E21,MIN(IFERROR(FIND("CDU",UPPER($E21)),999),IFERROR(FIND("BULK",UPPER($E21)),999),IFERROR(FIND("-",$E21),999),IFERROR(FIND("（",$E21),999))-1))=BU$1,$F21,"")) | BV21: 2.14 | BW21: =SUM(I21:BU21)*BV21 -> 5136 | BX21: =BW21*7.75 -> 39804 | BY21: =MID(E21,1,2) -> SR
A22: 45915 | B22: 46045 | C22: JAZ270137 | D22: USJZ136 | E22: SR130CDU-24 | F22: 6216 | G22: Jazwares客版（美文） | H22: =IFERROR(VLOOKUP(E22,名称!A:E,4,0),"") -> 二代 | I22: =IF(OR($E22="",I$1=""),"",IF(TRIM(LEFT($E22,MIN(IFERROR(FIND("CDU",UPPER($E22)),999),IFERROR(FIND("BULK",UPPER($E22)),999),IFERROR(FIND("-",$E22),999),IFERROR(FIND("（",$E22),999))-1))=I$1,$F22,"")) | J22: =IF(OR($E22="",J$1=""),"",IF(TRIM(LEFT($E22,MIN(IFERROR(FIND("CDU",UPPER($E22)),999),IFERROR(FIND("BULK",UPPER($E22)),999),IFERROR(FIND("-",$E22),999),IFERROR(FIND("（",$E22),999))-1))=J$1,$F22,"")) | K22: =IF(OR($E22="",K$1=""),"",IF(TRIM(LEFT($E22,MIN(IFERROR(FIND("CDU",UPPER($E22)),999),IFERROR(FIND("BULK",UPPER($E22)),999),IFERROR(FIND("-",$E22),999),IFERROR(FIND("（",$E22),999))-1))=K$1,$F22,"")) | L22: =IF(OR($E22="",L$1=""),"",IF(TRIM(LEFT($E22,MIN(IFERROR(FIND("CDU",UPPER($E22)),999),IFERROR(FIND("BULK",UPPER($E22)),999),IFERROR(FIND("-",$E22),999),IFERROR(FIND("（",$E22),999))-1))=L$1,$F22,"")) | M22: =IF(OR($E22="",M$1=""),"",IF(TRIM(LEFT($E22,MIN(IFERROR(FIND("CDU",UPPER($E22)),999),IFERROR(FIND("BULK",UPPER($E22)),999),IFERROR(FIND("-",$E22),999),IFERROR(FIND("（",$E22),999))-1))=M$1,$F22,"")) | N22: =IF(OR($E22="",N$1=""),"",IF(TRIM(LEFT($E22,MIN(IFERROR(FIND("CDU",UPPER($E22)),999),IFERROR(FIND("BULK",UPPER($E22)),999),IFERROR(FIND("-",$E22),999),IFERROR(FIND("（",$E22),999))-1))=N$1,$F22,"")) -> 6216 | O22: =IF(OR($E22="",O$1=""),"",IF(TRIM(LEFT($E22,MIN(IFERROR(FIND("CDU",UPPER($E22)),999),IFERROR(FIND("BULK",UPPER($E22)),999),IFERROR(FIND("-",$E22),999),IFERROR(FIND("（",$E22),999))-1))=O$1,$F22,"")) | P22: =IF(OR($E22="",P$1=""),"",IF(TRIM(LEFT($E22,MIN(IFERROR(FIND("CDU",UPPER($E22)),999),IFERROR(FIND("BULK",UPPER($E22)),999),IFERROR(FIND("-",$E22),999),IFERROR(FIND("（",$E22),999))-1))=P$1,$F22,"")) | ... BU22: =IF(OR($E22="",BU$1=""),"",IF(TRIM(LEFT($E22,MIN(IFERROR(FIND("CDU",UPPER($E22)),999),IFERROR(FIND("BULK",UPPER($E22)),999),IFERROR(FIND("-",$E22),999),IFERROR(FIND("（",$E22),999))-1))=BU$1,$F22,"")) | BV22: 0.61 | BW22: =SUM(I22:BU22)*BV22 -> 3791.76 | BX22: =BW22*7.75 -> 29386.14 | BY22: =MID(E22,1,2) -> SR
A23: 45915 | B23: 46045 | C23: JAZ270143 | D23: USJZ135 | E23: SR201C | F23: 2400 | G23: Jazwares客版（美文） | H23: =IFERROR(VLOOKUP(E23,名称!A:E,4,0),"") -> 二代 | I23: =IF(OR($E23="",I$1=""),"",IF(TRIM(LEFT($E23,MIN(IFERROR(FIND("CDU",UPPER($E23)),999),IFERROR(FIND("BULK",UPPER($E23)),999),IFERROR(FIND("-",$E23),999),IFERROR(FIND("（",$E23),999))-1))=I$1,$F23,"")) | J23: =IF(OR($E23="",J$1=""),"",IF(TRIM(LEFT($E23,MIN(IFERROR(FIND("CDU",UPPER($E23)),999),IFERROR(FIND("BULK",UPPER($E23)),999),IFERROR(FIND("-",$E23),999),IFERROR(FIND("（",$E23),999))-1))=J$1,$F23,"")) | K23: =IF(OR($E23="",K$1=""),"",IF(TRIM(LEFT($E23,MIN(IFERROR(FIND("CDU",UPPER($E23)),999),IFERROR(FIND("BULK",UPPER($E23)),999),IFERROR(FIND("-",$E23),999),IFERROR(FIND("（",$E23),999))-1))=K$1,$F23,"")) | L23: =IF(OR($E23="",L$1=""),"",IF(TRIM(LEFT($E23,MIN(IFERROR(FIND("CDU",UPPER($E23)),999),IFERROR(FIND("BULK",UPPER($E23)),999),IFERROR(FIND("-",$E23),999),IFERROR(FIND("（",$E23),999))-1))=L$1,$F23,"")) | M23: =IF(OR($E23="",M$1=""),"",IF(TRIM(LEFT($E23,MIN(IFERROR(FIND("CDU",UPPER($E23)),999),IFERROR(FIND("BULK",UPPER($E23)),999),IFERROR(FIND("-",$E23),999),IFERROR(FIND("（",$E23),999))-1))=M$1,$F23,"")) | N23: =IF(OR($E23="",N$1=""),"",IF(TRIM(LEFT($E23,MIN(IFERROR(FIND("CDU",UPPER($E23)),999),IFERROR(FIND("BULK",UPPER($E23)),999),IFERROR(FIND("-",$E23),999),IFERROR(FIND("（",$E23),999))-1))=N$1,$F23,"")) | O23: =IF(OR($E23="",O$1=""),"",IF(TRIM(LEFT($E23,MIN(IFERROR(FIND("CDU",UPPER($E23)),999),IFERROR(FIND("BULK",UPPER($E23)),999),IFERROR(FIND("-",$E23),999),IFERROR(FIND("（",$E23),999))-1))=O$1,$F23,"")) | P23: =IF(OR($E23="",P$1=""),"",IF(TRIM(LEFT($E23,MIN(IFERROR(FIND("CDU",UPPER($E23)),999),IFERROR(FIND("BULK",UPPER($E23)),999),IFERROR(FIND("-",$E23),999),IFERROR(FIND("（",$E23),999))-1))=P$1,$F23,"")) | ... BU23: =IF(OR($E23="",BU$1=""),"",IF(TRIM(LEFT($E23,MIN(IFERROR(FIND("CDU",UPPER($E23)),999),IFERROR(FIND("BULK",UPPER($E23)),999),IFERROR(FIND("-",$E23),999),IFERROR(FIND("（",$E23),999))-1))=BU$1,$F23,"")) | BV23: 2.14 | BW23: =SUM(I23:BU23)*BV23 -> 5136 | BX23: =BW23*7.75 -> 39804 | BY23: =MID(E23,1,2) -> SR
A24: 45915 | B24: 46045 | C24: JAZ270138 | D24: USJZ134 | E24: SR130CDU-24 | F24: 6216 | G24: Jazwares客版（美文） | H24: =IFERROR(VLOOKUP(E24,名称!A:E,4,0),"") -> 二代 | I24: =IF(OR($E24="",I$1=""),"",IF(TRIM(LEFT($E24,MIN(IFERROR(FIND("CDU",UPPER($E24)),999),IFERROR(FIND("BULK",UPPER($E24)),999),IFERROR(FIND("-",$E24),999),IFERROR(FIND("（",$E24),999))-1))=I$1,$F24,"")) | J24: =IF(OR($E24="",J$1=""),"",IF(TRIM(LEFT($E24,MIN(IFERROR(FIND("CDU",UPPER($E24)),999),IFERROR(FIND("BULK",UPPER($E24)),999),IFERROR(FIND("-",$E24),999),IFERROR(FIND("（",$E24),999))-1))=J$1,$F24,"")) | K24: =IF(OR($E24="",K$1=""),"",IF(TRIM(LEFT($E24,MIN(IFERROR(FIND("CDU",UPPER($E24)),999),IFERROR(FIND("BULK",UPPER($E24)),999),IFERROR(FIND("-",$E24),999),IFERROR(FIND("（",$E24),999))-1))=K$1,$F24,"")) | L24: =IF(OR($E24="",L$1=""),"",IF(TRIM(LEFT($E24,MIN(IFERROR(FIND("CDU",UPPER($E24)),999),IFERROR(FIND("BULK",UPPER($E24)),999),IFERROR(FIND("-",$E24),999),IFERROR(FIND("（",$E24),999))-1))=L$1,$F24,"")) | M24: =IF(OR($E24="",M$1=""),"",IF(TRIM(LEFT($E24,MIN(IFERROR(FIND("CDU",UPPER($E24)),999),IFERROR(FIND("BULK",UPPER($E24)),999),IFERROR(FIND("-",$E24),999),IFERROR(FIND("（",$E24),999))-1))=M$1,$F24,"")) | N24: =IF(OR($E24="",N$1=""),"",IF(TRIM(LEFT($E24,MIN(IFERROR(FIND("CDU",UPPER($E24)),999),IFERROR(FIND("BULK",UPPER($E24)),999),IFERROR(FIND("-",$E24),999),IFERROR(FIND("（",$E24),999))-1))=N$1,$F24,"")) -> 6216 | O24: =IF(OR($E24="",O$1=""),"",IF(TRIM(LEFT($E24,MIN(IFERROR(FIND("CDU",UPPER($E24)),999),IFERROR(FIND("BULK",UPPER($E24)),999),IFERROR(FIND("-",$E24),999),IFERROR(FIND("（",$E24),999))-1))=O$1,$F24,"")) | P24: =IF(OR($E24="",P$1=""),"",IF(TRIM(LEFT($E24,MIN(IFERROR(FIND("CDU",UPPER($E24)),999),IFERROR(FIND("BULK",UPPER($E24)),999),IFERROR(FIND("-",$E24),999),IFERROR(FIND("（",$E24),999))-1))=P$1,$F24,"")) | ... BU24: =IF(OR($E24="",BU$1=""),"",IF(TRIM(LEFT($E24,MIN(IFERROR(FIND("CDU",UPPER($E24)),999),IFERROR(FIND("BULK",UPPER($E24)),999),IFERROR(FIND("-",$E24),999),IFERROR(FIND("（",$E24),999))-1))=BU$1,$F24,"")) | BV24: 0.61 | BW24: =SUM(I24:BU24)*BV24 -> 3791.76 | BX24: =BW24*7.75 -> 29386.14 | BY24: =MID(E24,1,2) -> SR
A25: 45915 | B25: 46031 | C25: JAZ270139 | D25: USJZ133 | E25: SR130CDU-24 | F25: 3000 | G25: Jazwares客版（美文） | H25: =IFERROR(VLOOKUP(E25,名称!A:E,4,0),"") -> 二代 | I25: =IF(OR($E25="",I$1=""),"",IF(TRIM(LEFT($E25,MIN(IFERROR(FIND("CDU",UPPER($E25)),999),IFERROR(FIND("BULK",UPPER($E25)),999),IFERROR(FIND("-",$E25),999),IFERROR(FIND("（",$E25),999))-1))=I$1,$F25,"")) | J25: =IF(OR($E25="",J$1=""),"",IF(TRIM(LEFT($E25,MIN(IFERROR(FIND("CDU",UPPER($E25)),999),IFERROR(FIND("BULK",UPPER($E25)),999),IFERROR(FIND("-",$E25),999),IFERROR(FIND("（",$E25),999))-1))=J$1,$F25,"")) | K25: =IF(OR($E25="",K$1=""),"",IF(TRIM(LEFT($E25,MIN(IFERROR(FIND("CDU",UPPER($E25)),999),IFERROR(FIND("BULK",UPPER($E25)),999),IFERROR(FIND("-",$E25),999),IFERROR(FIND("（",$E25),999))-1))=K$1,$F25,"")) | L25: =IF(OR($E25="",L$1=""),"",IF(TRIM(LEFT($E25,MIN(IFERROR(FIND("CDU",UPPER($E25)),999),IFERROR(FIND("BULK",UPPER($E25)),999),IFERROR(FIND("-",$E25),999),IFERROR(FIND("（",$E25),999))-1))=L$1,$F25,"")) | M25: =IF(OR($E25="",M$1=""),"",IF(TRIM(LEFT($E25,MIN(IFERROR(FIND("CDU",UPPER($E25)),999),IFERROR(FIND("BULK",UPPER($E25)),999),IFERROR(FIND("-",$E25),999),IFERROR(FIND("（",$E25),999))-1))=M$1,$F25,"")) | N25: =IF(OR($E25="",N$1=""),"",IF(TRIM(LEFT($E25,MIN(IFERROR(FIND("CDU",UPPER($E25)),999),IFERROR(FIND("BULK",UPPER($E25)),999),IFERROR(FIND("-",$E25),999),IFERROR(FIND("（",$E25),999))-1))=N$1,$F25,"")) -> 3000 | O25: =IF(OR($E25="",O$1=""),"",IF(TRIM(LEFT($E25,MIN(IFERROR(FIND("CDU",UPPER($E25)),999),IFERROR(FIND("BULK",UPPER($E25)),999),IFERROR(FIND("-",$E25),999),IFERROR(FIND("（",$E25),999))-1))=O$1,$F25,"")) | P25: =IF(OR($E25="",P$1=""),"",IF(TRIM(LEFT($E25,MIN(IFERROR(FIND("CDU",UPPER($E25)),999),IFERROR(FIND("BULK",UPPER($E25)),999),IFERROR(FIND("-",$E25),999),IFERROR(FIND("（",$E25),999))-1))=P$1,$F25,"")) | ... BU25: =IF(OR($E25="",BU$1=""),"",IF(TRIM(LEFT($E25,MIN(IFERROR(FIND("CDU",UPPER($E25)),999),IFERROR(FIND("BULK",UPPER($E25)),999),IFERROR(FIND("-",$E25),999),IFERROR(FIND("（",$E25),999))-1))=BU$1,$F25,"")) | BV25: 0.61 | BW25: =SUM(I25:BU25)*BV25 -> 1830 | BX25: =BW25*7.75 -> 14182.5 | BY25: =MID(E25,1,2) -> SR
A26: 45915 | B26: 46031 | C26: JAZ270144 | D26: USJZ132 | E26: SR201C | F26: 2400 | G26: Jazwares客版（美文） | H26: =IFERROR(VLOOKUP(E26,名称!A:E,4,0),"") -> 二代 | I26: =IF(OR($E26="",I$1=""),"",IF(TRIM(LEFT($E26,MIN(IFERROR(FIND("CDU",UPPER($E26)),999),IFERROR(FIND("BULK",UPPER($E26)),999),IFERROR(FIND("-",$E26),999),IFERROR(FIND("（",$E26),999))-1))=I$1,$F26,"")) | J26: =IF(OR($E26="",J$1=""),"",IF(TRIM(LEFT($E26,MIN(IFERROR(FIND("CDU",UPPER($E26)),999),IFERROR(FIND("BULK",UPPER($E26)),999),IFERROR(FIND("-",$E26),999),IFERROR(FIND("（",$E26),999))-1))=J$1,$F26,"")) | K26: =IF(OR($E26="",K$1=""),"",IF(TRIM(LEFT($E26,MIN(IFERROR(FIND("CDU",UPPER($E26)),999),IFERROR(FIND("BULK",UPPER($E26)),999),IFERROR(FIND("-",$E26),999),IFERROR(FIND("（",$E26),999))-1))=K$1,$F26,"")) | L26: =IF(OR($E26="",L$1=""),"",IF(TRIM(LEFT($E26,MIN(IFERROR(FIND("CDU",UPPER($E26)),999),IFERROR(FIND("BULK",UPPER($E26)),999),IFERROR(FIND("-",$E26),999),IFERROR(FIND("（",$E26),999))-1))=L$1,$F26,"")) | M26: =IF(OR($E26="",M$1=""),"",IF(TRIM(LEFT($E26,MIN(IFERROR(FIND("CDU",UPPER($E26)),999),IFERROR(FIND("BULK",UPPER($E26)),999),IFERROR(FIND("-",$E26),999),IFERROR(FIND("（",$E26),999))-1))=M$1,$F26,"")) | N26: =IF(OR($E26="",N$1=""),"",IF(TRIM(LEFT($E26,MIN(IFERROR(FIND("CDU",UPPER($E26)),999),IFERROR(FIND("BULK",UPPER($E26)),999),IFERROR(FIND("-",$E26),999),IFERROR(FIND("（",$E26),999))-1))=N$1,$F26,"")) | O26: =IF(OR($E26="",O$1=""),"",IF(TRIM(LEFT($E26,MIN(IFERROR(FIND("CDU",UPPER($E26)),999),IFERROR(FIND("BULK",UPPER($E26)),999),IFERROR(FIND("-",$E26),999),IFERROR(FIND("（",$E26),999))-1))=O$1,$F26,"")) | P26: =IF(OR($E26="",P$1=""),"",IF(TRIM(LEFT($E26,MIN(IFERROR(FIND("CDU",UPPER($E26)),999),IFERROR(FIND("BULK",UPPER($E26)),999),IFERROR(FIND("-",$E26),999),IFERROR(FIND("（",$E26),999))-1))=P$1,$F26,"")) | ... BU26: =IF(OR($E26="",BU$1=""),"",IF(TRIM(LEFT($E26,MIN(IFERROR(FIND("CDU",UPPER($E26)),999),IFERROR(FIND("BULK",UPPER($E26)),999),IFERROR(FIND("-",$E26),999),IFERROR(FIND("（",$E26),999))-1))=BU$1,$F26,"")) | BV26: 2.14 | BW26: =SUM(I26:BU26)*BV26 -> 5136 | BX26: =BW26*7.75 -> 39804 | BY26: =MID(E26,1,2) -> SR
... A43: 45953 | B43: 46107 | C43: JAZ275406 | D43: PO0000028-USJZ | E43: SR103CDU-24 | F43: 14016 | G43: Jazwares客版（美文） | H43: =IFERROR(VLOOKUP(E43,名称!A:E,4,0),"") -> 二代 | I43: =IF(OR($E43="",I$1=""),"",IF(TRIM(LEFT($E43,MIN(IFERROR(FIND("CDU",UPPER($E43)),999),IFERROR(FIND("BULK",UPPER($E43)),999),IFERROR(FIND("-",$E43),999),IFERROR(FIND("（",$E43),999))-1))=I$1,$F43,"")) | J43: =IF(OR($E43="",J$1=""),"",IF(TRIM(LEFT($E43,MIN(IFERROR(FIND("CDU",UPPER($E43)),999),IFERROR(FIND("BULK",UPPER($E43)),999),IFERROR(FIND("-",$E43),999),IFERROR(FIND("（",$E43),999))-1))=J$1,$F43,"")) | K43: =IF(OR($E43="",K$1=""),"",IF(TRIM(LEFT($E43,MIN(IFERROR(FIND("CDU",UPPER($E43)),999),IFERROR(FIND("BULK",UPPER($E43)),999),IFERROR(FIND("-",$E43),999),IFERROR(FIND("（",$E43),999))-1))=K$1,$F43,"")) | L43: =IF(OR($E43="",L$1=""),"",IF(TRIM(LEFT($E43,MIN(IFERROR(FIND("CDU",UPPER($E43)),999),IFERROR(FIND("BULK",UPPER($E43)),999),IFERROR(FIND("-",$E43),999),IFERROR(FIND("（",$E43),999))-1))=L$1,$F43,"")) | M43: =IF(OR($E43="",M$1=""),"",IF(TRIM(LEFT($E43,MIN(IFERROR(FIND("CDU",UPPER($E43)),999),IFERROR(FIND("BULK",UPPER($E43)),999),IFERROR(FIND("-",$E43),999),IFERROR(FIND("（",$E43),999))-1))=M$1,$F43,"")) -> 14016 | N43: =IF(OR($E43="",N$1=""),"",IF(TRIM(LEFT($E43,MIN(IFERROR(FIND("CDU",UPPER($E43)),999),IFERROR(FIND("BULK",UPPER($E43)),999),IFERROR(FIND("-",$E43),999),IFERROR(FIND("（",$E43),999))-1))=N$1,$F43,"")) | O43: =IF(OR($E43="",O$1=""),"",IF(TRIM(LEFT($E43,MIN(IFERROR(FIND("CDU",UPPER($E43)),999),IFERROR(FIND("BULK",UPPER($E43)),999),IFERROR(FIND("-",$E43),999),IFERROR(FIND("（",$E43),999))-1))=O$1,$F43,"")) | P43: =IF(OR($E43="",P$1=""),"",IF(TRIM(LEFT($E43,MIN(IFERROR(FIND("CDU",UPPER($E43)),999),IFERROR(FIND("BULK",UPPER($E43)),999),IFERROR(FIND("-",$E43),999),IFERROR(FIND("（",$E43),999))-1))=P$1,$F43,"")) | ... BU43: =IF(OR($E43="",BU$1=""),"",IF(TRIM(LEFT($E43,MIN(IFERROR(FIND("CDU",UPPER($E43)),999),IFERROR(FIND("BULK",UPPER($E43)),999),IFERROR(FIND("-",$E43),999),IFERROR(FIND("（",$E43),999))-1))=BU$1,$F43,"")) | BV43: 0.61 | BW43: =SUM(I43:BU43)*BV43 -> 8549.76 | BX43: =BW43*7.75 -> 66260.64 | BY43: =MID(E43,1,2) -> SR
A44: 45953 | B44: 46107 | C44: JAZ275410 | D44: PO0000029-USJZ | E44: SR201C | F44: =9000-1500+1500 -> 9000 | G44: Jazwares客版（美文） | H44: =IFERROR(VLOOKUP(E44,名称!A:E,4,0),"") -> 二代 | I44: =IF(OR($E44="",I$1=""),"",IF(TRIM(LEFT($E44,MIN(IFERROR(FIND("CDU",UPPER($E44)),999),IFERROR(FIND("BULK",UPPER($E44)),999),IFERROR(FIND("-",$E44),999),IFERROR(FIND("（",$E44),999))-1))=I$1,$F44,"")) | J44: =IF(OR($E44="",J$1=""),"",IF(TRIM(LEFT($E44,MIN(IFERROR(FIND("CDU",UPPER($E44)),999),IFERROR(FIND("BULK",UPPER($E44)),999),IFERROR(FIND("-",$E44),999),IFERROR(FIND("（",$E44),999))-1))=J$1,$F44,"")) | K44: =IF(OR($E44="",K$1=""),"",IF(TRIM(LEFT($E44,MIN(IFERROR(FIND("CDU",UPPER($E44)),999),IFERROR(FIND("BULK",UPPER($E44)),999),IFERROR(FIND("-",$E44),999),IFERROR(FIND("（",$E44),999))-1))=K$1,$F44,"")) | L44: =IF(OR($E44="",L$1=""),"",IF(TRIM(LEFT($E44,MIN(IFERROR(FIND("CDU",UPPER($E44)),999),IFERROR(FIND("BULK",UPPER($E44)),999),IFERROR(FIND("-",$E44),999),IFERROR(FIND("（",$E44),999))-1))=L$1,$F44,"")) | M44: =IF(OR($E44="",M$1=""),"",IF(TRIM(LEFT($E44,MIN(IFERROR(FIND("CDU",UPPER($E44)),999),IFERROR(FIND("BULK",UPPER($E44)),999),IFERROR(FIND("-",$E44),999),IFERROR(FIND("（",$E44),999))-1))=M$1,$F44,"")) | N44: =IF(OR($E44="",N$1=""),"",IF(TRIM(LEFT($E44,MIN(IFERROR(FIND("CDU",UPPER($E44)),999),IFERROR(FIND("BULK",UPPER($E44)),999),IFERROR(FIND("-",$E44),999),IFERROR(FIND("（",$E44),999))-1))=N$1,$F44,"")) | O44: =IF(OR($E44="",O$1=""),"",IF(TRIM(LEFT($E44,MIN(IFERROR(FIND("CDU",UPPER($E44)),999),IFERROR(FIND("BULK",UPPER($E44)),999),IFERROR(FIND("-",$E44),999),IFERROR(FIND("（",$E44),999))-1))=O$1,$F44,"")) | P44: =IF(OR($E44="",P$1=""),"",IF(TRIM(LEFT($E44,MIN(IFERROR(FIND("CDU",UPPER($E44)),999),IFERROR(FIND("BULK",UPPER($E44)),999),IFERROR(FIND("-",$E44),999),IFERROR(FIND("（",$E44),999))-1))=P$1,$F44,"")) | ... BU44: =IF(OR($E44="",BU$1=""),"",IF(TRIM(LEFT($E44,MIN(IFERROR(FIND("CDU",UPPER($E44)),999),IFERROR(FIND("BULK",UPPER($E44)),999),IFERROR(FIND("-",$E44),999),IFERROR(FIND("（",$E44),999))-1))=BU$1,$F44,"")) | BV44: 2.14 | BW44: =SUM(I44:BU44)*BV44 -> 19260 | BX44: =BW44*7.75 -> 149265 | BY44: =MID(E44,1,2) -> SR
