Workbook

Sheet 总接单
A1: 产品名称 | I1: 确认走货期 | J1: 车发公仔系列四代 | M1: 车发公仔系列三代HS | O1: 50124 | R1: 50074 | V1: 50216-50226 | X1: 50119 | AA1: 50171 | AB1: 50221 | AD1: 50212、50213 | AF1: 50186 | AH1: 14312/14764/14347/14765/14766/14767/14768/14769 | AS1: 50191、50190 | AX1: 七代公仔50238/八代50271 | BC1: 七代50242/八代50273 | BH1: 50247 | BI1: 50253 | BJ1: 50116 | BK1: 50040 | BL1: 14303 | BM1: 14344 | BN1: 14345 | BO1: 50263 | BP1: 50267/50279 | BT1: 50047 | BU1: 17337 | BV1: 17563 | BW1: 50276 | BX1: 13095 | BY1: 17513 | BZ1: 17389 | CA1: 50224 | CB1: 17345 | CC1: 七代17341/八代17527 | CH1: 17392 | CI1: 17529 | CJ1: 14349 | CK1: 17552 | CL1: 17588 | CM1: 17644 | CN1: 18060 | CO1: 单价USD | CP1: 金额USD | CQ1: HK金额 | CR1: 发票号 | CS1: 备注
A2: 接单期 | B2: 客名 | C2: 国家 | D2: Customer | E2: PO号 | F2: ItemCode | G2: 货号 | H2: 数量 | J2: 50060 | K2: 50116 | L2: 50061 | M2: 50064 | N2: 50065 | O2: 50125 | P2: 50127 | Q2: 50128 | R2: 50110小狗 | S2: 50111小猫 | T2: 50112考拉 | U2: 50113小兔 | V2: 50226 | W2: 50216 | X2: 50120 | Y2: 50122 | Z2: 50157 | AA2: 50171 | AB2: 50221 | AC2: 50222 | AD2: 50212 | AE2: 50213 | AF2: 50187 | AG2: 50188 | AH2: 14312 | AI2: 14311 | AJ2: 14300 | AK2: 14341 | AL2: 14302 | AM2: 14317 | AN2: 14305 | AO2: 14334 | AP2: 14335 | AQ2: 14343 | AR2: 14342 | AS2: 50190 | AT2: 50191 | AU2: 50252 | AV2: 50281 | AW2: 50282 | AX2: 50239 | AY2: 50240 | AZ2: 50241 | BA2: 50275 | BB2: 50272 | BC2: 50243 | BD2: 50244 | BE2: 50245 | BF2: 50246 | BG2: 50274 | BH2: 50247 | BI2: 50253 | BJ2: 50256 | BK2: 50040 | BL2: 14303 | BM2: 14344 | BN2: 14345 | BO2: 50263 | BP2: 50268 | BQ2: 50269 | BR2: 50270 | BS2: 50280 | BT2: 50047 | BU2: 17337 | BV2: 17563 | BW2: 50276 | BX2: 13095 | BY2: 17513 | BZ2: 17389 | CA2: 50224 | CB2: 17345 | CC2: 13084 | CD2: 17342 | CE2: 17343 | CF2: 17344 | CG2: 17528 | CH2: 17392 | CI2: 17529 | CJ2: 14349 | CK2: 17552 | CL2: 17588 | CM2: 17644 | CN2: 18060
A3: 45287 | D3: MA单可抵扣实单 | E3: MAR23-0563 | F3: 17389.AB0.0000 | G3: =TEXT(MID(F3,1,5),"00000") -> 17389 | H3: =3000-960-40-14-90-14-40-80-98-26-36-52-46-22-204 -> 1278 | I3: 45402 | BZ3: =H3 -> 1278 | CO3: 0 | CP3: =CO3*SUM(J3:CN3) -> 0 | CQ3: =CP3*7.75 -> 0
A4: 45953 | B4: SUCKOT S.A.C. | C4: 哥伦比亚 | D4: 291456 (O) | E4: 982441 (292209) | F4: 13095.AC0.005L | G4: =TEXT(MID(F4,1,5),"00000") -> 13095 | H4: 900 | I4: 46038 | BX4: =H4 -> 900 | CO4: 3.671 | CP4: =H4*CO4 -> 3303.9 | CQ4: =CP4*7.75 -> 25605.23 | CR4: FE54198
A5: 45959 | B5: BOING GLOBAL S. DE R.L | C5: 巴拿马 | D5: 292018 (O) | E5: 983480 (292842) | F5: 13095.AC0.0000 | G5: =TEXT(MID(F5,1,5),"00000") -> 13095 | H5: 501 | I5: 46031 | BX5: =H5 -> 501 | CO5: 3.641 | CP5: =H5*CO5 -> 1824.14 | CQ5: =CP5*7.75 -> 14137.09 | CR5: FE54196
A6: 45962 | B6: AMAZON.COM FOB | C6: 亚马逊 | D6: 293871 (O) | E6: 986311 (293990) | F6: 17563.AB0.0000 | G6: 17563 | H6: 330 | I6: 46026 | BV6: =H6 -> 330 | CO6: 5.942 | CP6: =H6*CO6 -> 1960.86 | CQ6: =CP6*7.75 -> 15196.67 | CR6: FE54193
A7: 45962 | B7: AMAZON.COM FOB | C7: 亚马逊 | D7: 293872 (O) | E7: 986312 (293991) | F7: 17563.AB0.0000 | G7: 17563 | H7: 378 | I7: 46026 | BV7: =H7 -> 378 | CO7: 5.942 | CP7: =H7*CO7 -> 2246.08 | CQ7: =CP7*7.75 -> 17407.12 | CR7: FE54194
A8: 45962 | B8: AMAZON.COM FOB | C8: 亚马逊 | D8: 293873 (O) | E8: 986313 (293992) | F8: 17563.AB0.0000 | G8: 17563 | H8: 1170 | I8: 46026 | BV8: =H8 -> 1170 | CO8: 5.942 | CP8: =H8*CO8 -> 6952.14 | CQ8: =CP8*7.75 -> 53879.09 | CR8: FE54195
A9: 45993 | B9: MOOSE AU WAREHOUSE | C9: 澳洲 | D9: 500633 | E9: 297464 OF | F9: 13095.AC0.0000 | G9: 13095 | H9: 3000 | I9: 46035 | BX9: =H9 -> 3000 | CO9: 3.641 | CP9: =H9*CO9 -> 10923 | CQ9: =CP9*7.75 -> 84653.25 | CR9: FE54197
A10: 45993 | B10: ROSS PROCUREMENT FOB | C10: 美国 | D10: 299320 (O) | E10: 997259 (299363) | F10: 18060.AB0.0000 | G10: 18060 | H10: 1600 | I10: 46041 | CN10: =H10 -> 1600 | CO10: 3.842 | CP10: =H10*CO10 -> 6147.2 | CQ10: =CP10*7.75 -> 47640.8 | CR10: FE54199
A11: 45993 | B11: ROSS PROCUREMENT FOB | C11: 美国 | D11: 299320 (O) | E11: 997259 (299363) | F11: 18060.AB0.0000 | G11: 18060 | H11: 1200 | I11: 46041 | CN11: =H11 -> 1200 | CO11: 3.842 | CP11: =H11*CO11 -> 4610.4 | CQ11: =CP11*7.75 -> 35730.6 | CR11: FE54199
A12: 45993 | B12: ROSS PROCUREMENT FOB | C12: 美国 | D12: 299320 (O) | E12: 997259 (299363) | F12: 18060.AB0.0000 | G12: 18060 | H12: 1600 | I12: 46041 | CN12: =H12 -> 1600 | CO12: 3.842 | CP12: =H12*CO12 -> 6147.2 | CQ12: =CP12*7.75 -> 47640.8 | CR12: FE54199
A13: 45993 | B13: ROSS PROCUREMENT FOB | C13: 美国 | D13: 299320 (O) | E13: 997259 (299363) | F13: 18060.AB0.0000 | G13: 18060 | H13: 1550 | I13: 46041 | CN13: =H13 -> 1550 | CO13: 3.842 | CP13: =H13*CO13 -> 5955.1 | CQ13: =CP13*7.75 -> 46152.03 | CR13: FE54199
A14: 46029 | B14: KMART AUSTRALIA LIMITED - FOB C | C14: 澳大利亚 | D14: 300092 (O) | E14: 999894 (300642) | F14: 17552.AB0.005L | G14: 17552 | H14: 600 | I14: 46108 | CK14: =H14 -> 600 | CO14: 13.059 | CP14: =H14*CO14 -> 7835.4 | CQ14: =CP14*7.75 -> 60724.35 | CR14: FE54200
A15: 46029 | B15: KMART AUSTRALIA LIMITED - FOB C | C15: 澳大利亚 | D15: 300096 (O) | E15: 999896 (300643) | F15: 17552.AB0.005L | G15: 17552 | H15: 4400 | I15: 46122 | CK15: =H15 -> 4400 | CO15: 13.059 | CP15: =H15*CO15 -> 57459.6 | CQ15: =CP15*7.75 -> 445311.9 | CR15: FE64211
A16: 46057 | B16: TJX UK (FOB-CLEAR) | C16: 英国 | D16: 301842 (O) | E16: 1003914 (303564) | F16: 13095.AC0.005L | G16: 13095 | H16: 402 | I16: 46113 | BX16: =H16 -> 402 | CO16: 3.671 | CP16: =H16*CO16 -> 1475.74 | CQ16: =CP16*7.75 -> 11436.99 | CR16: FE64209
A17: 46057 | B17: TJX UK (FOB-CLEAR) | C17: 英国 | D17: 301841 (O) | E17: 1003913 (303563) | F17: 13095.AC0.005L | G17: 13095 | H17: 600 | I17: 46113 | BX17: =H17 -> 600 | CO17: 3.671 | CP17: =H17*CO17 -> 2202.6 | CQ17: =CP17*7.75 -> 17070.15 | CR17: FE64208
A18: 46057 | B18: TJX UK (FOB-CLEAR) | C18: 英国 | D18: 301840 (O) | E18: 1003912 (303562) | F18: 13095.AC0.005L | G18: 13095 | H18: 402 | I18: 46113 | BX18: =H18 -> 402 | CO18: 3.671 | CP18: =H18*CO18 -> 1475.74 | CQ18: =CP18*7.75 -> 11436.99 | CR18: FE64207
A19: 46057 | B19: TJX UK (FOB-CLEAR) | C19: 英国 | D19: 301839 (O) | E19: 1003911 (303561) | F19: 13095.AC0.005L | G19: 13095 | H19: 801 | I19: 46113 | BX19: =H19 -> 801 | CO19: 3.671 | CP19: =H19*CO19 -> 2940.47 | CQ19: =CP19*7.75 -> 22788.64 | CR19: FE64206
A20: 46057 | B20: TJX UK (FOB-CLEAR) | C20: 英国 | D20: 301848 (O) | E20: 1003920 (303570) | F20: 13095.AC0.005L | G20: 13095 | H20: 600 | I20: 46113 | BX20: =H20 -> 600 | CO20: 3.671 | CP20: =H20*CO20 -> 2202.6 | CQ20: =CP20*7.75 -> 17070.15 | CR20: FE64205
A21: 46057 | B21: TJX UK (FOB-CLEAR) | C21: 英国 | D21: 301847 (O) | E21: 1003919 (303569) | F21: 13095.AC0.005L | G21: 13095 | H21: 402 | I21: 46113 | BX21: =H21 -> 402 | CO21: 3.671 | CP21: =H21*CO21 -> 1475.74 | CQ21: =CP21*7.75 -> 11436.99 | CR21: FE64204
A22: 46057 | B22: TJX UK (FOB-CLEAR) | C22: 英国 | D22: 301845 (O) | E22: 1003917 (303567) | F22: 13095.AC0.005L | G22: 13095 | H22: 402 | I22: 46113 | BX22: =H22 -> 402 | CO22: 3.671 | CP22: =H22*CO22 -> 1475.74 | CQ22: =CP22*7.75 -> 11436.99 | CR22: FE64202
A23: 46057 | B23: TJX UK (FOB-CLEAR) | C23: 英国 | D23: 301843 (O) | E23: 1003915 (303565) | F23: 13095.AC0.005L | G23: 13095 | H23: 600 | I23: 46113 | BX23: =H23 -> 600 | CO23: 3.671 | CP23: =H23*CO23 -> 2202.6 | CQ23: =CP23*7.75 -> 17070.15 | CR23: FE64210
A24: 46057 | B24: TJX UK (FOB-CLEAR) | C24: 英国 | D24: 301846 (O) | E24: 1003918 (303568) | F24: 13095.AC0.005L | G24: 13095 | H24: 600 | I24: 46113 | BX24: =H24 -> 600 | CO24: 3.671 | CP24: =H24*CO24 -> 2202.6 | CQ24: =CP24*7.75 -> 17070.15 | CR24: FE64203
A25: 46057 | B25: TJX UK (FOB-CLEAR) | C25: 英国 | D25: 301844 (O) | E25: 1003916 (303566) | F25: 13095.AC0.005L | G25: 13095 | H25: 801 | I25: 46113 | BX25: =H25 -> 801 | CO25: 3.671 | CP25: =H25*CO25 -> 2940.47 | CQ25: =CP25*7.75 -> 22788.64 | CR25: FE64201
A26: 46092 | B26: AMAZON.COM FOB | C26: 美国 | D26: 306420 (O) | E26: 1017910 (308293) | F26: 13095.AC0.0000 | G26: 13095 | H26: 102 | I26: 46154 | BX26: =H26 -> 102 | CO26: 3.641 | CP26: =H26*CO26 -> 371.38 | CQ26: =CP26*7.75 -> 2878.2 | CR26: FE64212
A27: 46092 | B27: AMAZON.COM FOB | C27: 亚马逊 | D27: 306421 (O) | E27: 1017911 (308294) | F27: 13095.AC0.0000 | G27: 13095 | H27: 270 | I27: 46154 | BX27: =H27 -> 270 | CO27: 3.641 | CP27: =H27*CO27 -> 983.07 | CQ27: =CP27*7.75 -> 7618.79 | CR27: FE64213
A28: 46092 | B28: AMAZON.COM FOB | C28: 亚马逊 | D28: 306422 (O) | E28: 1017912 (308295) | F28: 13095.AC0.0000 | G28: 13095 | H28: 486 | I28: 46154 | BX28: =H28 -> 486 | CO28: 3.641 | CP28: =H28*CO28 -> 1769.53 | CQ28: =CP28*7.75 -> 13713.86 | CR28: FE64214
A29: 46100 | B29: SUCKOT S.A.C. | C29: 秘鲁 | D29: 308285 (O) | E29: 1020855 (309910) | F29: 13095.AC0.0000 | G29: 13095 | H29: 1200 | I29: 46164 | BX29: =H29 -> 1200 | CO29: 3.641 | CP29: =H29*CO29 -> 4369.2 | CQ29: =CP29*7.75 -> 33861.3
A30: 46084 | D30: MA单可抵扣实单 | E30: OJ 306890 | F30: 13095.AC0.0000 | G30: 13095 | H30: =3000-(102+270+486+1200+48+105+90+63+72+564) -> 0 | I30: 46093 | BX30: =H30 -> 0 | CO30: 0 | CP30: =H30*CO30 -> 0 | CQ30: =CP30*7.75 -> 0
A31: 46122 | B31: AMAZON.COM FOB | C31: 美国 | D31: 314412 (O) | E31: 1028658 (315378) | F31: 13095.AC0.0000 | G31: 13095 | H31: 48 | I31: 46195 | BX31: =H31 -> 48 | CO31: 3.641 | CP31: =H31*CO31 -> 174.77 | CQ31: =CP31*7.75 -> 1354.47
A32: 46122 | B32: AMAZON.COM FOB | C32: 美国 | D32: 314413 (O) | E32: 1028659 (315380) | F32: 13095.AC0.0000 | G32: 13095 | H32: 105 | I32: 46230 | BX32: =H32 -> 105 | CO32: 3.641 | CP32: =H32*CO32 -> 382.31 | CQ32: =CP32*7.75 -> 2962.9
A33: 46122 | B33: AMAZON.COM FOB | C33: 美国 | D33: 314414 (O) | E33: 1028660 (315381) | F33: 13095.AC0.0000 | G33: 13095 | H33: 90 | I33: 46195 | BX33: =H33 -> 90 | CO33: 3.641 | CP33: =H33*CO33 -> 327.69 | CQ33: =CP33*7.75 -> 2539.6
A34: 46122 | B34: AMAZON.COM FOB | C34: 美国 | D34: 314415 (O) | E34: 1028661 (315382) | F34: 13095.AC0.0000 | G34: 13095 | H34: 63 | I34: 46195 | BX34: =H34 -> 63 | CO34: 3.641 | CP34: =H34*CO34 -> 229.38 | CQ34: =CP34*7.75 -> 1777.7
A35: 46122 | B35: AMAZON.COM FOB | C35: 美国 | D35: 314416 (O) | E35: 1028662 (315383) | F35: 13095.AC0.0000 | G35: 13095 | H35: 72 | I35: 46195 | BX35: =H35 -> 72 | CO35: 3.641 | CP35: =H35*CO35 -> 262.15 | CQ35: =CP35*7.75 -> 2031.66
A36: 46150 | D36: MA单可抵扣实单 | E36: OJ 325393 | F36: 13095.AC0.0000 | G36: 13095 | H36: =3000-(1203+162) -> 1635 | I36: 46209 | BX36: =H36 -> 1635 | CO36: 0 | CP36: =H36*CO36 -> 0 | CQ36: =CP36*7.75 -> 0
A37: 46150 | B37: Moose Toys Distribution MX | C37: 墨西哥 | D37: 323923 (O) | E37: 1040096 (325618) | F37: 13095.AC0.005L | G37: 13095 | H37: 1203 | I37: 46219 | BX37: =H37 -> 1203 | CO37: 3.671 | CP37: =H37*CO37 -> 4416.21 | CQ37: =CP37*7.75 -> 34225.63
A38: 46150 | B38: Moose Toys Distribution MX | C38: 墨西哥 | D38: 323940 (O) | E38: 1040103 (325620) | F38: 13095.AC0.005L | G38: 13095 | H38: 162 | I38: 46219 | BX38: =H38 -> 162 | CO38: 3.671 | CP38: =H38*CO38 -> 594.7 | CQ38: =CP38*7.75 -> 4608.93
A39: 46196 | B39: ROSS PROCUREMENT FOB | C39: 美国 | D39: 334843 (O) | E39: 1053032 (335280) | F39: 18060.AB0.0000 | G39: 18060 | H39: 6000 | I39: 46290 | CN39: =H39 -> 6000 | CO39: 3.842 | CP39: =H39*CO39 -> 23052 | CQ39: =CP39*7.75 -> 178653
A40: 46196 | B40: ROSS PROCUREMENT FOB | C40: 美国 | D40: 334845 (O) | E40: 1053034 (335282) | F40: 18060.AB0.0000 | G40: 18060 | H40: 2000 | I40: 2026/10/29周四 | CN40: =H40 -> 2000 | CO40: 3.842 | CP40: =H40*CO40 -> 7684 | CQ40: =CP40*7.75 -> 59551
...

Sheet 排期
A1: 接单期 | B1: 国家/客名 | C1: 国家 | D1: Customer | E1: PO号 | F1: ItemCode | G1: 货号 | H1: 名称 | I1: 数量 | J1: 装箱数 | K1: 总箱数 | L1: 客PO期 | M1: 计划验货期 | N1: 第三方验货 | O1: 验货时间 | P1: SI日期 | Q1: 验货 结果 | R1: 箱唛 资料 | S1: 外箱 贴纸 | T1: 客贴纸 | U1: 包装版本 | V1: 日期码 | W1: 是否扣FGMA | X1: 备注 | Y1: 单价 | Z1: 金额USD | AA1: 金额HKD | AB1: 发票号 | AC1: 是否 入系统 | AD1: 车间 | AE1: 下单明细 | AF1: 送回数量 | AG1: 欠数 | AH1: 贴纸 | AI1: 外箱 | AJ1: SY回复
A2: 46196 | B2: ROSS PROCUREMENT FOB | C2: 美国 | D2: 60308543 | E2: 1053032 (335280) | F2: 18060.AB0.0000 | G2: 18060 | H2: 车子+公仔 | I2: 6000 | J2: 2 | K2: =I2/J2 -> 3000 | L2: 46290 | M2: =L2-7 -> 46283 | N2: N | O2: 46283 | R2: ok | T2: Y | U2: MOOSE | V2: HS 25126 | X2: 翻单,替换PO 1048839(332168)，更改cust。订单号从602992543到60308543 | Y2: 3.842 | Z2: =I2*Y2 -> 23052 | AA2: =Z2*7.75 -> 178653 | AC2: 已入系统 | AD2: A | AE2: 系统出单
A3: 46196 | B3: ROSS PROCUREMENT FOB | C3: 美国 | D3: 60308546 | E3: 1053034 (335282) | F3: 18060.AB0.0000 | G3: 18060 | H3: 车子+公仔 | I3: 2000 | J3: 2 | K3: =I3/J3 -> 1000 | L3: 46324 | M3: =L3-7 -> 46317 | N3: N | O3: 46317 | R3: ok | T3: Y | U3: MOOSE | V3: HS 28826 | X3: 翻单,替换PO 1048815(332167)，更改cust。PO号从60299523到60308546.替换采购订单PO1048815(332167)，更改客户采购订 单号从60299523更改为60308546，R1:更新交货日期至10月29日 | Y3: 3.842 | Z3: =I3*Y3 -> 7684 | AA3: =Z3*7.75 -> 59551 | AC3: 已入系统 | AD3: A | AE3: 系统出单
A4: 46196 | B4: ROSS PROCUREMENT FOB | C4: 美国 | D4: 60308547 | E4: 1053035 (335283) | F4: 18060.AB0.0000 | G4: 18060 | H4: 车子+公仔 | I4: 5800 | J4: 2 | K4: =I4/J4 -> 2900 | L4: 46252 | M4: =L4-7 -> 46245 | N4: N | O4: 46245 | Q4: Pass | R4: ok | T4: Y | U4: MOOSE | V4: HS 21526 | X4: 翻单,替换PO 1048793(332166)，更改cust。PO号从60299490到60308547 | Y4: 3.842 | Z4: =I4*Y4 -> 22283.6 | AA4: =Z4*7.75 -> 172697.9 | AC4: 已入系统 | AD4: A | AE4: 系统出单
A5: 46199 | B5: MOOSE AU WAREHOUSE | C5: 澳洲 | E5: 336018 OF | F5: 13095.AC0.0000 | G5: 13095 | H5: 医药箱 | I5: 4002 | J5: 3 | K5: =I5/J5 -> 1334 | L5: 46275 | M5: =L5-7 -> 46268 | N5: N | O5: 46268 | R5: ok | T5: Y | U5: MOOSE | V5: HSXXXXX | W5: OJ306890 | X5: 翻单 | Y5: 3.641 | Z5: =I5*Y5 -> 14571.28 | AA5: =Z5*7.75 -> 112927.42 | AC5: 已入系统 | AD5: A
A6: 46225 | B6: Ross MDDP order - Change | C6: 美国 | D6: 60308546 | E6: 1064052 (339336) | F6: 18060.AB0.0000 | G6: 18060 | H6: 车子+公仔 | I6: 5400 | J6: 2 | K6: =I6/J6 -> 2700 | L6: 46324 | M6: =L6-7 -> 46317 | N6: N | O6: 46317 | R6: ok | T6: Y | U6: MOOSE | V6: HS 28826 | X6: 翻单，替换已取消的采购订单1053033(335281)，更新客户采购订单号# | Y6: 3.842 | Z6: =I6*Y6 -> 20746.8 | AA6: =Z6*7.75 -> 160787.7 | AC6: 翻单已入 | AD6: A | AE6: 系统出单
I10: =SUM(I1:I9) -> 23202 | Y10: =AA10=AA11+AA12 -> TRUE | Z10: =SUM(Z1:Z8) -> 88337.68 | AA10: =SUM(AA1:AA8) -> 684617.02
Z11: A | AA11: =SUMIF(AD1:AD9,Z11,AA1:AA9) -> 684617.02
Z12: B | AA12: =SUMIF(AD1:AD9,Z12,AA1:AA9) -> 0

Sheet 已走货
A1: 接单期 | B1: 国家/客名 | D1: Customer | E1: PO号 | F1: ItemCode | G1: 货号 | H1: 名称 | I1: 数量 | J1: 装箱数 | K1: 总箱数 | L1: 客PO期 | M1: 计划验货期 | N1: 第三方验货 | O1: 验货时间 | P1: SI日期 | Q1: 验货 结果 | R1: 箱唛 资料 | S1: 外箱 贴纸 | T1: 客贴纸 | U1: 包装版本 | V1: 日期码 | W1: 是否扣FGMA | X1: 备注 | Y1: 单价 | Z1: 金额USD | AA1: 金额HKD | AB1: 发票号 | AC1: 是否 入系统 | AD1: 车间 | AE1: 下单明细 | AF1: 送回数量 | AG1: 欠数 | AH1: 贴纸 | AI1: 外箱 | AJ1: SY回复 | AK1: 人民币单价 | AL1: 人民币总价
A2: 45962 | B2: AMAZON.COM FOB | C2: 亚马逊 | D2: 293871 (O) | E2: 986311 (293990) | F2: 17563.AB0.0000 | G2: 17563 | H2: 校巴邮购盒装 | I2: 330 | J2: 2 | K2: =I2/J2 -> 165 | L2: 46033 | M2: =L2-7 -> 46026 | N2: N | Q2: PASS | R2: ok | S2: 11-18提供给A车间 | T2: Y | U2: MOOSE | V2: HSXXXXX | Y2: 5.942 | Z2: =I2*Y2 -> 1960.86 | AA2: =Z2*7.75 -> 15196.67 | AB2: FE54193 | AC2: 已入系统 | AD2: =VLOOKUP(G2,☆!B:C,2,0) -> A
A3: 45962 | B3: AMAZON.COM FOB | C3: 亚马逊 | D3: 293872 (O) | E3: 986312 (293991) | F3: 17563.AB0.0000 | G3: 17563 | H3: 校巴邮购盒装 | I3: 378 | J3: 2 | K3: =I3/J3 -> 189 | L3: 46033 | M3: =L3-7 -> 46026 | N3: N | Q3: PASS | R3: ok | S3: 11-18提供给A车间 | T3: Y | U3: MOOSE | V3: HSXXXXX | Y3: 5.942 | Z3: =I3*Y3 -> 2246.08 | AA3: =Z3*7.75 -> 17407.12 | AB3: FE54194 | AC3: 已入系统 | AD3: =VLOOKUP(G3,☆!B:C,2,0) -> A
A4: 45962 | B4: AMAZON.COM FOB | C4: 亚马逊 | D4: 293873 (O) | E4: 986313 (293992) | F4: 17563.AB0.0000 | G4: 17563 | H4: 校巴邮购盒装 | I4: 1170 | J4: 2 | K4: =I4/J4 -> 585 | L4: 46033 | M4: =L4-7 -> 46026 | N4: N | Q4: PASS | R4: ok | S4: 11-18提供给A车间 | T4: Y | U4: MOOSE | V4: HSXXXXX | Y4: 5.942 | Z4: =I4*Y4 -> 6952.14 | AA4: =Z4*7.75 -> 53879.09 | AB4: FE54195 | AC4: 已入系统 | AD4: =VLOOKUP(G4,☆!B:C,2,0) -> A
A5: 45959 | B5: BOING GLOBAL S. DE R.L | C5: 巴拿马 | D5: 292018 (O) | E5: 983480 (292842) | F5: 13095.AC0.0000 | G5: =TEXT(MID(F5,1,5),"00000") -> 13095 | H5: =VLOOKUP(G5,☆!B:D,3,0) -> 医药箱 | I5: 501 | J5: 3 | K5: =I5/J5 -> 167 | L5: 46038 | M5: =L5-7 -> 46031 | N5: N | Q5: PASS | R5: ok | T5: Y | U5: MOOSE | V5: HSXXXXX | Y5: 3.641 | Z5: =I5*Y5 -> 1824.14 | AA5: =Z5*7.75 -> 14137.09 | AB5: FE54196 | AC5: 已入系统 | AD5: A
A6: 45993 | B6: MOOSE AU WAREHOUSE | C6: 澳洲 | D6: 500633 | E6: 297464 OF | F6: 13095.AC0.0000 | G6: =TEXT(MID(F6,1,5),"00000") -> 13095 | H6: =VLOOKUP(G6,☆!B:D,3,0) -> 医药箱 | I6: 3000 | J6: 3 | K6: =I6/J6 -> 1000 | L6: 46042 | M6: =L6-7 -> 46035 | N6: N | Q6: PASS | R6: ok | T6: N | U6: MOOSE | V6: HSXXXXX | Y6: 3.641 | Z6: =I6*Y6 -> 10923 | AA6: =Z6*7.75 -> 84653.25 | AB6: FE54197 | AC6: 已入系统 | AD6: A
A7: 45953 | B7: SUCKOT S.A.C. | C7: 哥伦比亚 | D7: 291456 (O) | E7: 982441 (292209) | F7: 13095.AC0.005L | G7: =TEXT(MID(F7,1,5),"00000") -> 13095 | H7: =VLOOKUP(G7,☆!B:D,3,0) -> 医药箱 | I7: 900 | J7: 3 | K7: =I7/J7 -> 300 | L7: 46045 | M7: =L7-7 -> 46038 | N7: N | Q7: PASS | R7: ok | T7: Y | U7: 5L | V7: HSXXXXX | Y7: 3.671 | Z7: =I7*Y7 -> 3303.9 | AA7: =Z7*7.75 -> 25605.23 | AB7: FE54198 | AC7: 已入系统 | AD7: A
A8: 45993 | B8: ROSS PROCUREMENT FOB | C8: 美国 | D8: 299320 (O) | E8: 997259 (299363) | F8: 18060.AB0.0000 | G8: 18060 | H8: 车子+公仔 | I8: 1600 | J8: 2 | K8: =I8/J8 -> 800 | L8: 46048 | M8: =L8-7 -> 46041 | N8: N | P8: HS01526 | Q8: PASS | R8: ok | T8: Y | U8: MOOSE | V8: HSXXXXX | Y8: 3.842 | Z8: =I8*Y8 -> 6147.2 | AA8: =Z8*7.75 -> 47640.8 | AB8: FE54199 | AC8: 已入系统 | AD8: A | AE8: 系统出单
A9: 45993 | B9: ROSS PROCUREMENT FOB | C9: 美国 | D9: 299320 (O) | E9: 997259 (299363) | F9: 18060.AB0.0000 | G9: 18060 | H9: 车子+公仔 | I9: 1200 | J9: 2 | K9: =I9/J9 -> 600 | L9: 46048 | M9: =L9-7 -> 46041 | N9: N | P9: HS01526 | Q9: PASS | R9: ok | T9: Y | U9: MOOSE | V9: HSXXXXX | Y9: 3.842 | Z9: =I9*Y9 -> 4610.4 | AA9: =Z9*7.75 -> 35730.6 | AB9: FE54199 | AC9: 已入系统 | AD9: A | AE9: 系统出单
A10: 45993 | B10: ROSS PROCUREMENT FOB | C10: 美国 | D10: 299320 (O) | E10: 997259 (299363) | F10: 18060.AB0.0000 | G10: 18060 | H10: 车子+公仔 | I10: 1600 | J10: 2 | K10: =I10/J10 -> 800 | L10: 46048 | M10: =L10-7 -> 46041 | N10: N | P10: HS01526 | Q10: PASS | R10: ok | T10: Y | U10: MOOSE | V10: HSXXXXX | Y10: 3.842 | Z10: =I10*Y10 -> 6147.2 | AA10: =Z10*7.75 -> 47640.8 | AB10: FE54199 | AC10: 已入系统 | AD10: A | AE10: 系统出单
A11: 45993 | B11: ROSS PROCUREMENT FOB | C11: 美国 | D11: 299320 (O) | E11: 997259 (299363) | F11: 18060.AB0.0000 | G11: 18060 | H11: 车子+公仔 | I11: 1550 | J11: 2 | K11: =I11/J11 -> 775 | L11: 46048 | M11: =L11-7 -> 46041 | N11: N | P11: HS01526 | Q11: PASS | R11: ok | T11: Y | U11: MOOSE | V11: HSXXXXX | Y11: 3.842 | Z11: =I11*Y11 -> 5955.1 | AA11: =Z11*7.75 -> 46152.03 | AB11: FE54199 | AC11: 已入系统 | AD11: A | AE11: 系统出单
A12: 46029 | B12: KMART AUSTRALIA LIMITED - FOB C | C12: 澳大利亚 | D12: 300092 (O) | E12: 999894 (300642) | F12: 17552.AB0.005L | G12: 17552 | H12: 玩具商场 | I12: 600 | J12: 2 | K12: =I12/J12 -> 300 | L12: 46108 | M12: =L12-7 -> 46101 | N12: N | O12: 46108 | Q12: PASS | R12: ok | T12: Y | U12: 5L | V12: HSXXXXX | Y12: 13.059 | Z12: =I12*Y12 -> 7835.4 | AA12: =Z12*7.75 -> 60724.35 | AB12: FE54200 | AC12: 已入系统 | AD12: A | AE12: 已下半成品
A13: 46057 | B13: TJX UK (FOB-CLEAR) | C13: 英国 | D13: 301844 (O) | E13: 1003916 (303566) | F13: 13095.AC0.005L | G13: 13095 | H13: 医药箱 | I13: 801 | J13: 3 | K13: =I13/J13 -> 267 | L13: 46113 | M13: =L13-7 -> 46106 | N13: N | O13: 46108 | Q13: PASS | R13: ok | T13: Y | U13: 5L | V13: HSXXXXX | Y13: 3.671 | Z13: =I13*Y13 -> 2940.47 | AA13: =Z13*7.75 -> 22788.64 | AB13: FE64201 | AC13: 已入系统 | AD13: A
A14: 46057 | B14: TJX UK (FOB-CLEAR) | C14: 英国 | D14: 301845 (O) | E14: 1003917 (303567) | F14: 13095.AC0.005L | G14: 13095 | H14: 医药箱 | I14: 402 | J14: 3 | K14: =I14/J14 -> 134 | L14: 46113 | M14: =L14-7 -> 46106 | N14: N | O14: 46108 | Q14: PASS | R14: ok | T14: Y | U14: 5L | V14: HSXXXXX | Y14: 3.671 | Z14: =I14*Y14 -> 1475.74 | AA14: =Z14*7.75 -> 11436.99 | AB14: FE64202 | AC14: 已入系统 | AD14: A
A15: 46057 | B15: TJX UK (FOB-CLEAR) | C15: 英国 | D15: 301846 (O) | E15: 1003918 (303568) | F15: 13095.AC0.005L | G15: 13095 | H15: 医药箱 | I15: 600 | J15: 3 | K15: =I15/J15 -> 200 | L15: 46113 | M15: =L15-7 -> 46106 | N15: N | O15: 46108 | Q15: PASS | R15: ok | T15: Y | U15: 5L | V15: HSXXXXX | Y15: 3.671 | Z15: =I15*Y15 -> 2202.6 | AA15: =Z15*7.75 -> 17070.15 | AB15: FE64203 | AC15: 已入系统 | AD15: A
A16: 46057 | B16: TJX UK (FOB-CLEAR) | C16: 英国 | D16: 301847 (O) | E16: 1003919 (303569) | F16: 13095.AC0.005L | G16: 13095 | H16: 医药箱 | I16: 402 | J16: 3 | K16: =I16/J16 -> 134 | L16: 46113 | M16: =L16-7 -> 46106 | N16: N | O16: 46108 | Q16: PASS | R16: ok | T16: Y | U16: 5L | V16: HSXXXXX | Y16: 3.671 | Z16: =I16*Y16 -> 1475.74 | AA16: =Z16*7.75 -> 11436.99 | AB16: FE64204 | AC16: 已入系统 | AD16: A
A17: 46057 | B17: TJX UK (FOB-CLEAR) | C17: 英国 | D17: 301848 (O) | E17: 1003920 (303570) | F17: 13095.AC0.005L | G17: 13095 | H17: 医药箱 | I17: 600 | J17: 3 | K17: =I17/J17 -> 200 | L17: 46113 | M17: =L17-7 -> 46106 | N17: N | O17: 46108 | Q17: PASS | R17: ok | T17: Y | U17: 5L | V17: HSXXXXX | Y17: 3.671 | Z17: =I17*Y17 -> 2202.6 | AA17: =Z17*7.75 -> 17070.15 | AB17: FE64205 | AC17: 已入系统 | AD17: A
A18: 46057 | B18: TJX UK (FOB-CLEAR) | C18: 英国 | D18: 301839 (O) | E18: 1003911 (303561) | F18: 13095.AC0.005L | G18: 13095 | H18: 医药箱 | I18: 801 | J18: 3 | K18: =I18/J18 -> 267 | L18: 46113 | M18: =L18-7 -> 46106 | N18: N | O18: 46108 | Q18: PASS | R18: ok | T18: Y | U18: 5L | V18: HSXXXXX | Y18: 3.671 | Z18: =I18*Y18 -> 2940.47 | AA18: =Z18*7.75 -> 22788.64 | AB18: FE64206 | AC18: 已入系统 | AD18: A
A19: 46057 | B19: TJX UK (FOB-CLEAR) | C19: 英国 | D19: 301840 (O) | E19: 1003912 (303562) | F19: 13095.AC0.005L | G19: 13095 | H19: 医药箱 | I19: 402 | J19: 3 | K19: =I19/J19 -> 134 | L19: 46113 | M19: =L19-7 -> 46106 | N19: N | O19: 46108 | Q19: PASS | R19: ok | T19: Y | U19: 5L | V19: HSXXXXX | Y19: 3.671 | Z19: =I19*Y19 -> 1475.74 | AA19: =Z19*7.75 -> 11436.99 | AB19: FE64207 | AC19: 已入系统 | AD19: A
A20: 46057 | B20: TJX UK (FOB-CLEAR) | C20: 英国 | D20: 301841 (O) | E20: 1003913 (303563) | F20: 13095.AC0.005L | G20: 13095 | H20: 医药箱 | I20: 600 | J20: 3 | K20: =I20/J20 -> 200 | L20: 46113 | M20: =L20-7 -> 46106 | N20: N | O20: 46108 | Q20: PASS | R20: ok | T20: Y | U20: 5L | V20: HSXXXXX | Y20: 3.671 | Z20: =I20*Y20 -> 2202.6 | AA20: =Z20*7.75 -> 17070.15 | AB20: FE64208 | AC20: 已入系统 | AD20: A
A21: 46057 | B21: TJX UK (FOB-CLEAR) | C21: 英国 | D21: 301842 (O) | E21: 1003914 (303564) | F21: 13095.AC0.005L | G21: 13095 | H21: 医药箱 | I21: 402 | J21: 3 | K21: =I21/J21 -> 134 | L21: 46113 | M21: =L21-7 -> 46106 | N21: N | O21: 46108 | Q21: PASS | R21: ok | T21: Y | U21: 5L | V21: HSXXXXX | Y21: 3.671 | Z21: =I21*Y21 -> 1475.74 | AA21: =Z21*7.75 -> 11436.99 | AB21: FE64209 | AC21: 已入系统 | AD21: A
A22: 46057 | B22: TJX UK (FOB-CLEAR) | C22: 英国 | D22: 301843 (O) | E22: 1003915 (303565) | F22: 13095.AC0.005L | G22: 13095 | H22: 医药箱 | I22: 600 | J22: 3 | K22: =I22/J22 -> 200 | L22: 46113 | M22: =L22-7 -> 46106 | N22: N | O22: 46108 | Q22: PASS | R22: ok | T22: Y | U22: 5L | V22: HSXXXXX | Y22: 3.671 | Z22: =I22*Y22 -> 2202.6 | AA22: =Z22*7.75 -> 17070.15 | AB22: FE64210 | AC22: 已入系统 | AD22: A
A23: 46029 | B23: KMART AUSTRALIA LIMITED - FOB C | C23: 澳大利亚 | D23: 300096 (O) | E23: 999896 (300643) | F23: 17552.AB0.005L | G23: 17552 | H23: 玩具商场 | I23: 4400 | J23: 2 | K23: =I23/J23 -> 2200 | L23: 46122 | M23: =L23-7 -> 46115 | N23: N | O23: 46119 | Q23: PASS | R23: ok | T23: Y | U23: 5L | V23: HSXXXXX | Y23: 13.059 | Z23: =I23*Y23 -> 57459.6 | AA23: =Z23*7.75 -> 445311.9 | AB23: FE64211 | AC23: 已入系统 | AD23: A | AE23: 已下半成品
A24: 46092 | B24: AMAZON.COM FOB | C24: 亚马逊 | D24: 306420 (O) | E24: 1017910 (308293) | F24: 13095.AC0.0000 | G24: 13095 | H24: 医药箱 | I24: 102 | J24: 3 | K24: =I24/J24 -> 34 | L24: 46154 | M24: =L24-7 -> 46147 | N24: N | O24: 46150 | Q24: PASS | R24: ok | T24: Y | U24: MOOSE | V24: HSXXXXX | W24: OJ 306890 | X24: 4/10收到贴纸 | Y24: 3.641 | Z24: =I24*Y24 -> 371.38 | AA24: =Z24*7.75 -> 2878.2 | AB24: FE64212 | AC24: 已入系统 | AD24: A
A25: 46092 | B25: AMAZON.COM FOB | C25: 亚马逊 | D25: 306421 (O) | E25: 1017911 (308294) | F25: 13095.AC0.0000 | G25: 13095 | H25: 医药箱 | I25: 270 | J25: 3 | K25: =I25/J25 -> 90 | L25: 46154 | M25: =L25-7 -> 46147 | N25: N | O25: 46150 | Q25: PASS | R25: ok | T25: Y | U25: MOOSE | V25: HSXXXXX | W25: OJ 306890 | X25: 4/10收到贴纸 | Y25: 3.641 | Z25: =I25*Y25 -> 983.07 | AA25: =Z25*7.75 -> 7618.79 | AB25: FE64213 | AC25: 已入系统 | AD25: A
A26: 46092 | B26: AMAZON.COM FOB | C26: 亚马逊 | D26: 306422 (O) | E26: 1017912 (308295) | F26: 13095.AC0.0000 | G26: 13095 | H26: 医药箱 | I26: 486 | J26: 3 | K26: =I26/J26 -> 162 | L26: 46154 | M26: =L26-7 -> 46147 | N26: N | O26: 46150 | Q26: PASS | R26: ok | T26: Y | U26: MOOSE | V26: HSXXXXX | W26: OJ 306890 | X26: 4/10收到贴纸 | Y26: 3.641 | Z26: =I26*Y26 -> 1769.53 | AA26: =Z26*7.75 -> 13713.86 | AB26: FE64214 | AC26: 已入系统 | AD26: A
A27: 46100 | B27: SUCKOT S.A.C. | C27: 秘鲁 | D27: 308285 (O) | E27: 1020855 (309910) | F27: 13095.AC0.0000 | G27: 13095 | H27: 医药箱 | I27: 1200 | J27: 3 | K27: =I27/J27 -> 400 | L27: 46164 | M27: =L27-7 -> 46157 | N27: N | O27: 46157 | R27: ok | T27: Y | U27: MOOSE | V27: HSXXXXX | W27: OJ 306890 | X27: 4/20收到贴纸 | Y27: 3.641 | Z27: =I27*Y27 -> 4369.2 | AA27: =Z27*7.75 -> 33861.3 | AB27: FE64215 | AC27: 已入系统 | AD27: A
A28: 46122 | B28: AMAZON.COM FOB | C28: 美国 | D28: 314412 (O) | E28: 1028658 (315378) | F28: 13095.AC0.0000 | G28: 13095 | H28: 医药箱 | I28: 48 | J28: 3 | K28: =I28/J28 -> 16 | L28: 46195 | M28: =L28-7 -> 46188 | N28: N | O28: 46189 | Q28: pass | R28: ok | T28: Y | U28: MOOSE | V28: HSXXXXX | W28: OJ 306890 | X28: 5/14收到贴纸 | Y28: 3.641 | Z28: =I28*Y28 -> 174.77 | AA28: =Z28*7.75 -> 1354.47 | AB28: FE64216 | AC28: 已入系统 | AD28: A
A29: 46122 | B29: AMAZON.COM FOB | C29: 美国 | D29: 314414 (O) | E29: 1028660 (315381) | F29: 13095.AC0.0000 | G29: 13095 | H29: 医药箱 | I29: 90 | J29: 3 | K29: =I29/J29 -> 30 | L29: 46195 | M29: =L29-7 -> 46188 | N29: N | O29: 46189 | Q29: pass | R29: ok | T29: Y | U29: MOOSE | V29: HSXXXXX | W29: OJ 306890 | X29: 5/14收到贴纸 | Y29: 3.641 | Z29: =I29*Y29 -> 327.69 | AA29: =Z29*7.75 -> 2539.6 | AB29: FE64217 | AC29: 已入系统 | AD29: A
A30: 46122 | B30: AMAZON.COM FOB | C30: 美国 | D30: 314415 (O) | E30: 1028661 (315382) | F30: 13095.AC0.0000 | G30: 13095 | H30: 医药箱 | I30: 63 | J30: 3 | K30: =I30/J30 -> 21 | L30: 46195 | M30: =L30-7 -> 46188 | N30: N | O30: 46189 | Q30: pass | R30: ok | T30: Y | U30: MOOSE | V30: HSXXXXX | W30: OJ 306890 | X30: 5/14收到贴纸 | Y30: 3.641 | Z30: =I30*Y30 -> 229.38 | AA30: =Z30*7.75 -> 1777.7 | AB30: FE64218 | AC30: 已入系统 | AD30: A
A31: 46122 | B31: AMAZON.COM FOB | C31: 美国 | D31: 314416 (O) | E31: 1028662 (315383) | F31: 13095.AC0.0000 | G31: 13095 | H31: 医药箱 | I31: 72 | J31: 3 | K31: =I31/J31 -> 24 | L31: 46195 | M31: =L31-7 -> 46188 | N31: N | O31: 46189 | Q31: pass | R31: ok | T31: Y | U31: MOOSE | V31: HSXXXXX | W31: OJ 306890 | X31: 5/14收到贴纸 | Y31: 3.641 | Z31: =I31*Y31 -> 262.15 | AA31: =Z31*7.75 -> 2031.66 | AB31: FE64219 | AC31: 已入系统 | AD31: A
A32: 46122 | B32: AMAZON.COM FOB | C32: 美国 | D32: 314413 (O) | E32: 1028659 (315380) | F32: 13095.AC0.0000 | G32: 13095 | H32: 医药箱 | I32: 105 | J32: 3 | K32: =I32/J32 -> 35 | L32: 46230 | M32: =L32-7 -> 46223 | N32: N | O32: 46227 | Q32: PASS | R32: ok | T32: Y | U32: MOOSE | V32: HSXXXXX | W32: OJ 306890 | X32: 6/10收到贴纸 | Y32: 3.641 | Z32: =I32*Y32 -> 382.31 | AA32: =Z32*7.75 -> 2962.9 | AB32: FE64220 | AC32: 已入系统 | AD32: A
A33: 46150 | B33: Moose Toys Distribution MX | C33: 墨西哥 | D33: 323923 (O) | E33: 1040096 (325618) | F33: 13095.AC0.005L | G33: 13095 | H33: 医药箱 | I33: 1203 | J33: 3 | K33: =I33/J33 -> 401 | L33: 46219 | M33: =L33-7 -> 46212 | N33: N | O33: 46213 | Q33: PASS | R33: ok | T33: Y | U33: 5L | V33: HSXXXXX | W33: OJ 325393 | X33: 6/9收到贴纸 | Y33: 3.671 | Z33: =I33*Y33 -> 4416.21 | AA33: =Z33*7.75 -> 34225.63 | AB33: FE64221 | AC33: 已入系统 | AD33: A
A34: 46150 | B34: Moose Toys Distribution MX | C34: 墨西哥 | D34: 323940 (O) | E34: 1040103 (325620) | F34: 13095.AC0.005L | G34: 13095 | H34: 医药箱 | I34: 162 | J34: 3 | K34: =I34/J34 -> 54 | L34: 46219 | M34: =L34-7 -> 46212 | N34: N | O34: 46213 | Q34: PASS | R34: ok | T34: Y | U34: 5L | V34: HSXXXXX | W34: OJ 325393 | X34: 6/9收到贴纸 | Y34: 3.671 | Z34: =I34*Y34 -> 594.7 | AA34: =Z34*7.75 -> 4608.93 | AB34: FE64222 | AC34: 已入系统 | AD34: A
I37: =SUM(I2:I36) -> 26640 | Z37: =SUM(Z2:Z36) -> 149839.71 | AA37: =SUM(AA2:AA36) -> 1161257.8
M38: .

Sheet MA
A1: 接单期 | B1: 国家/客名 | C1: Customer | D1: PO号 | E1: ItemCode | F1: 货号 | G1: 数量 | H1: 装箱数 | I1: 总箱数 | J1: 客PO期 | K1: 计划验货期 | L1: 第三方验货 | M1: 验货时间 | N1: SI日期 | O1: 验货 结果 | P1: 箱唛 资料 | Q1: 外箱 贴纸 | R1: 客贴纸 | S1: 包装版本 | T1: 日期码 | U1: 是否扣FGMA | V1: 备注 | W1: 单价 | X1: 金额USD | Y1: 金额HKD | Z1: 发票号 | AA1: 是否 入系统 | AB1: 车间 | AC1: 下单明细 | AD1: 送回数量 | AE1: 欠数 | AF1: 贴纸 | AG1: 外箱 | AH1: SY回复
A2: 45287 | C2: MA单可抵扣实单 | D2: MAR23-0563 | E2: 17389.AB0.0000 | F2: =TEXT(MID(E2,1,5),"00000") -> 17389 | G2: 1278 | H2: 2 | I2: =G2/H2 -> 639 | J2: 45402 | K2: =J2-7 -> 45395 | S2: MOOSE | T2: HSXXXXX | V2: 扣960pcs到PO:808565 (179840)； 扣40pcs到PO:808568 (179839) 扣14pcs到PO：876446（232723） | W2: 0 | X2: 0 | Y2: =X2*7.75 -> 0 | Z2: =Y2*7.75 -> 0 | AB2: =VLOOKUP(F2,☆!B:C,2,0) -> B
A3: 46023 | C3: MA单可抵扣实单 | D3: OJ 263825 | E3: 13095.AC0.0000 | F3: 13095 | G3: 0 | H3: 3 | I3: =G3/H3 -> 0 | J3: 46065 | K3: =J3-7 -> 46058 | S3: MOOSE | T3: HSXXXXX | W3: 0 | X3: 0 | Y3: =X3*7.75 -> 0
A4: 46084 | C4: MA单可抵扣实单 | D4: OJ 306890 | E4: 13095.AC0.0000 | F4: 13095 | G4: =3000-(102+270+486+1200+48+105+90+63+72+564) -> 0 | H4: 3 | I4: =G4/H4 -> 0 | J4: 46093 | K4: =J4-7 -> 46086 | S4: MOOSE | T4: HSXXXXX | V4: 扣120pcs到PO:1017910 (308293) 扣270pcs到PO:1017911 (308294) 扣486pcs到PO：1017912 (308295) 扣90pcsPO:876502(232722) 扣14pcs到PO:876520(232721) 扣40pcs到PO：876463（232720） 扣80pcs到PO：876492（232727） 扣98pcs到PO:876448(232726) 扣26pcs到PO:876483(232725) 扣36pcs到PO:876442(232724) 扣564pcs到po：336018 OF | W4: 0 | X4: =W4*G4 -> 0 | Y4: =X4*7.75 -> 0 | AB4: A
A5: 46150 | C5: MA单可抵扣实单 | D5: OJ 325393 | E5: 13095.AC0.005L | F5: 13095 | G5: =3000-(1203+162) -> 1635 | H5: 3 | I5: =G5/H5 -> 545 | J5: 46209 | K5: =J5-7 -> 46202 | S5: MOOSE | T5: HSXXXXX | V5: 扣1203pcs到PO1040096 (325618) 扣162pcs到PO1040103 (325620) | W5: 0 | X5: 0 | Y5: =X5*7.75 -> 0 | AB5: A
G10: =SUM(G1:G9) -> 2913 | X10: =SUM(X2:X9) -> 0 | Y10: =SUM(Y2:Y9) -> 0

Sheet 取消单
A1: 接单期 | B1: 国家/客名 | C1: 国家 | D1: Customer | E1: PO号 | F1: ItemCode | G1: 货号 | H1: 名称 | I1: 数量 | J1: 装箱数 | K1: 总箱数 | L1: 客PO期 | M1: 计划验货期 | N1: 第三方验货 | O1: 验货时间 | P1: SI日期 | Q1: 验货 结果 | R1: 箱唛 资料 | S1: 外箱 贴纸 | T1: 客贴纸 | U1: 包装版本 | V1: 日期码 | W1: 是否扣FGMA | X1: 备注 | Y1: 单价 | Z1: 金额USD | AA1: 金额HKD | AC1: 是否 入系统 | AD1: 车间 | AE1: 下单明细 | AF1: 送回数量 | AG1: 欠数 | AH1: 贴纸 | AI1: 外箱 | AJ1: SY回复 | AK1: 备注
A2: 46177 | B2: ROSS PROCUREMENT FOB | C2: 美国 | D2: 60308543 | E2: 1048839 (332168) | F2: 18060.AB0.0000 | G2: 18060 | H2: 车子+公仔 | I2: 6000 | J2: 2 | K2: =I2/J2 -> 3000 | L2: 46290 | M2: =L2-7 -> 46283 | N2: N | R2: ok | T2: Y | U2: MOOSE | V2: HS 25126 | X2: 翻单 | Y2: 3.842 | Z2: =I2*Y2 -> 23052 | AA2: =Z2*7.75 -> 178653 | AC2: 已入系统 | AD2: A
A3: 46177 | B3: ROSS PROCUREMENT FOB | C3: 美国 | D3: 60299555 | E3: 1048844 (332169) | F3: 18060.AB0.0000 | G3: 18060 | H3: 车子+公仔 | I3: 5400 | J3: 2 | K3: =I3/J3 -> 2700 | L3: 46324 | M3: =L3-7 -> 46317 | N3: N | R3: ok | T3: Y | U3: MOOSE | V3: HS 28826 | X3: 翻单 | Y3: 3.842 | Z3: =I3*Y3 -> 20746.8 | AA3: =Z3*7.75 -> 160787.7 | AC3: 已入系统 | AD3: A
A4: 46177 | B4: ROSS PROCUREMENT FOB | C4: 美国 | D4: 60299523 | E4: 1048815 (332167) | F4: 18060.AB0.0000 | G4: 18060 | H4: 车子+公仔 | I4: 2000 | J4: 2 | K4: =I4/J4 -> 1000 | L4: 46324 | M4: =L4-7 -> 46317 | N4: N | R4: ok | T4: Y | U4: MOOSE | V4: HS 28826 | X4: 翻单 | Y4: 3.842 | Z4: =I4*Y4 -> 7684 | AA4: =Z4*7.75 -> 59551 | AC4: 已入系统 | AD4: A
A5: 46177 | B5: ROSS PROCUREMENT FOB | C5: 美国 | D5: 60299490 | E5: 1048793 (332166) | F5: 18060.AB0.0000 | G5: 18060 | H5: 车子+公仔 | I5: 5800 | J5: 2 | K5: =I5/J5 -> 2900 | L5: 46248 | M5: =L5-7 -> 46241 | N5: N | R5: ok | T5: Y | U5: MOOSE | V5: HS 21526 | X5: 翻单 | Y5: 3.842 | Z5: =I5*Y5 -> 22283.6 | AA5: =Z5*7.75 -> 172697.9 | AC5: 已入系统 | AD5: A
A6: 46196 | B6: ROSS PROCUREMENT FOB | C6: 美国 | D6: 60308545 | E6: 1053033 (335281) | F6: 18060.AB0.0000 | G6: 18060 | H6: 车子+公仔 | I6: 5400 | J6: 2 | K6: =I6/J6 -> 2700 | L6: 46318 | M6: =L6-7 -> 46311 | N6: N | R6: ok | T6: Y | U6: MOOSE | V6: HS 28826 | X6: 翻单,替换PO 1048844(332169)，更改cust。PO号从60299555到60308545 | Y6: 3.842 | Z6: =I6*Y6 -> 20746.8 | AA6: =Z6*7.75 -> 160787.7 | AC6: 已入系统 | AD6: A | AE6: 系统出单

Sheet 惠州浩华
A1: 接单期 | B1: 国家/客名 | C1: PO号 | D1: ItemCode | E1: 名称 | F1: 数量 | G1: 客PO期 | H1: 计划验货期 | I1: 备注 | J1: 单价 | K1: 金额RMB | L1: 金额HKD | M1: 发票号 | N1: 是否入系统 | O1: 车间
A2: 46058 | B2: 惠州浩华 | C2: HH260203 | D2: 91039 | E2: 4件胶件公仔 | F2: 10000 | G2: 46113 | H2: =G2-7 -> 46106 | J2: 5.04 | K2: =F2*J2 -> 50400 | L2: =K2*1.22 -> 61488
A3: 46140 | B3: 惠州浩华 | C3: HH260428 | D3: 91039 | E3: 大宾果 | F3: 12000 | G3: 46199 | H3: =G3-7 -> 46192 | J3: 1.51 | K3: =F3*J3 -> 18120 | L3: =K3*1.22 -> 22106.4
A4: 46140 | B4: 惠州浩华 | C4: HH260428 | D4: 91039 | E4: 大布鲁 | F4: 8000 | G4: 46199 | H4: =G4-7 -> 46192 | J4: 1.51 | K4: =F4*J4 -> 12080 | L4: =K4*1.22 -> 14737.6
F10: =SUM(F2:F9) -> 30000 | K10: =SUM(K2:K9) -> 80600 | L10: =SUM(L2:L9) -> 98332

Sheet 配比图
B1: 50074两个装 | J1: 50074六个装

Sheet MA 表
A1: 接单期 | B1: PO号 | C1: 货号 | D1: 名称 | E1: 客人放MA数量 | F1: 已接实单 | G1: 剩余MA数量 | H1: 客PO期 | I1: 出货期
A2: 46084 | B2: OJ 306890 | C2: 13095 | D2: 医药箱 | E2: 3000 | F2: =102+270+486+1200+48+105+90+63+72+564 -> 3000 | G2: =E2-F2 -> 0 | H2: 46093 | I2: 46086
A3: 46150 | B3: OJ 325393 | C3: 13095 | D3: 医药箱 | E3: 3000 | F3: 801 | G3: =E3-F3 -> 2199 | H3: 46179 | I3: 46179

Sheet ☆
A1: ItemCode | B1: 车间 | C1: 车间 | D1: 名称
A2: 13095.AC0.00WR | B2: 13095 | C2: C | D2: 医药箱
A3: 14312.AF0.106L | B3: 14312 | C3: B | D3: 灯公仔
A4: 14345.AF0.106L | B4: 14345 | C4: B | D4: 灯公仔
A5: 17344.AD0.005L | B5: 17344 | C5: A | D5: 布鲁公仔一代
A6: 17345.AB0.00WR | B6: 17345 | C6: A | D6: 校巴
A7: 17529.AB0.00WR | B7: 17529 | C7: C | D7: 大树
A8: 17552.AB0.00WR | B8: 17552 | C8: A-C | D8: 玩具商场
A9: 17563.AB0.0000 | B9: 17563 | C9: A | D9: 校巴邮购盒装
A10: 17588.AA0.005L | B10: 17588 | C10: C | D10: 玩具商场+车仔
A11: 17644.AA0.0000 | B11: 17644 | C11: A-C | D11: 大树
A12: 13095.AC0.0000 | B12: =TEXT(MID(A12,1,5),"00000") -> 13095 | C12: C | D12: 医药箱
A13: 13095.AC0.00KL | B13: =TEXT(MID(A13,1,5),"00000") -> 13095 | C13: C | D13: 医药箱
A14: 13095.AC0.00SS | B14: =TEXT(MID(A14,1,5),"00000") -> 13095 | C14: C | D14: 医药箱
A15: 13095.AC0.00WR | B15: =TEXT(MID(A15,1,5),"00000") -> 13095 | C15: C | D15: 医药箱
A16: 14300.AF0.106L | B16: =TEXT(MID(A16,1,5),"00000") -> 14300 | C16: B | D16: 灯公仔
A17: 14303.AF0.106L | B17: =TEXT(MID(A17,1,5),"00000") -> 14303 | C17: B
A18: 14305.AF0.106L | B18: =TEXT(MID(A18,1,5),"00000") -> 14305 | C18: B
A19: 14311.AB0.0000 | B19: =TEXT(MID(A19,1,5),"00000") -> 14311 | C19: B | D19: 灯公仔
A20: 14311.AB0.00SS | B20: =TEXT(MID(A20,1,5),"00000") -> 14311 | C20: B | D20: 灯公仔
A21: 14312.AB0.0000 | B21: =TEXT(MID(A21,1,5),"00000") -> 14312 | C21: B | D21: 灯公仔
A22: 14312.AB0.00SS | B22: =TEXT(MID(A22,1,5),"00000") -> 14312 | C22: B | D22: 灯公仔
A23: 14312.AF0.0000 | B23: =TEXT(MID(A23,1,5),"00000") -> 14312 | C23: B | D23: 灯公仔
A24: 14312.AF0.106L | B24: =TEXT(MID(A24,1,5),"00000") -> 14312 | C24: B | D24: 灯公仔
A25: 14317.AF0.106L | B25: =TEXT(MID(A25,1,5),"00000") -> 14317 | C25: B
A26: 14344.AF0.106L | B26: =TEXT(MID(A26,1,5),"00000") -> 14344 | C26: B
A27: 14345.AF0.0000 | B27: =TEXT(MID(A27,1,5),"00000") -> 14345 | C27: B | D27: 灯公仔
A28: 14345.AF0.106L | B28: =TEXT(MID(A28,1,5),"00000") -> 14345 | C28: B | D28: 灯公仔
A29: 14347.AG0.CT00 | B29: =TEXT(MID(A29,1,5),"00000") -> 14347 | C29: B | D29: 灯公仔
A30: 14349.AF0.0000 | B30: =TEXT(MID(A30,1,5),"00000") -> 14349 | C30: B
A31: 14764.AF0.106L | B31: =TEXT(MID(A31,1,5),"00000") -> 14764 | C31: B | D31: 灯公仔
A32: 14765.AG0.CT00 | B32: =TEXT(MID(A32,1,5),"00000") -> 14765 | C32: B | D32: 灯公仔
A33: 14766.AG0.CT00 | B33: =TEXT(MID(A33,1,5),"00000") -> 14766 | C33: B | D33: 灯公仔
A34: 14766.AG0.CT02 | B34: 14766 | C34: B | D34: 灯公仔
A35: 14766.AG0.CT04 | B35: 14766 | C35: B | D35: 灯公仔
A36: 14767.AG0.CT03 | B36: 14767 | C36: B | D36: 灯公仔
A37: 14768.AG0.CT05 | B37: 14768 | C37: B | D37: 灯公仔
A38: 14769.AG0.CT06 | B38: 14769 | C38: B | D38: 灯公仔
A39: 17337.AB0.0000 | B39: =TEXT(MID(A39,1,5),"00000") -> 17337 | C39: B | D39: 学校
A40: 17337.AB0.005L | B40: =TEXT(MID(A40,1,5),"00000") -> 17337 | C40: B | D40: 学校
...

Sheet Sheet1
A1: 国家/客名 | C1: 国家
A2: BAN KEE TRADING INCORPORATED | C2: 菲律宾
A3: L.E. INTERNATIONAL CORP. | C3: 台湾
A4: TJX UK FREIGHT FORWARDER | C4: 英国
A5: TJX DE FREIGHT FORWARDER | C5: 德国
A6: SPECTRON BV | C6: 荷兰
A7: SUCKOT S.A.C. | C7: 秘鲁
A8: MOOSE AU WAREHOUSE | C8: 澳洲
A9: ALDI STORES (IRELAND) LTD M'TOWN FOBCC E(FOBCC - Euro) | C9: 爱尔兰
A10: ALDI STORES (A'STONE) FOBCC (FOBCC - Sterling) | C10: 英国
A11: MOOSE REGAL WAREHOUSE | C11: 美国
A12: SHENG TAI TOYS PTE LTD | C12: 新加坡
