Workbook

Sheet 总接单
A1: 产品名称 | H1: 确认走货期 | J1: 单价USD | K1: 金额USD | L1: HK金额 | M1: 发票号 | N1: 备注
A2: 接单期 | B2: 国家/客名 | C2: PO号 | D2: ItemCode | E2: 货号 | F2: 名称 | G2: 数量 | I2: 14312
A3: 46184 | B3: Character World LTD | C3: PO000652 | D3: 14312.AF0.106L | E3: 14312 | F3: 公仔夜灯 | G3: 2004 | H3: 46247 | I3: =G3 -> 2004 | J3: 2.75 | K3: =J3*G3 -> 5511 | L3: =K3*7.75 -> 42710.25
E8: 合计： | G8: =SUM(G3:G7) -> 2004 | H8: =排期!G6+已走货!H7+MA!G9 -> 2004 | K8: =SUM(K3:K7) -> 5511 | L8: =SUM(L3:L7) -> 42710.25
G9: =G8=SUM(I9:I9) -> TRUE | H9: =G8=H8 -> TRUE | I9: =SUM(I3:I8) -> 2004 | K9: =K8=排期!Y6+已走货!Z7 -> TRUE | L9: =L8=排期!Z6+已走货!AA7 -> TRUE
A12: 25年库存金额： | B12: 0
A14: 2026年总接单： | B14: =L8 -> 42710.25 | C14: =B14-B15-B16 -> 0
A15: 排期： | B15: =排期!Z6 -> 42710.25
A16: 已走货： | B16: =已走货!AA7 -> 0
A24: 以下标注内容区分识别备注：
A25: 类型
A26: 黄色填充
A27: 绿色填充
A28: 蓝色字体
A29: 粉色字体
A30: 红色字体

Sheet 排期
A1: 接单期 | B1: 国家/客名 | C1: PO号 | D1: ItemCode | E1: 货号 | F1: 名称 | G1: 数量 | H1: 装箱数 | I1: 总箱数 | J1: 客PO期 | K1: 计划验货期 | L1: 第三方验货 | M1: 产品描述 | N1: 验货时间 | O1: SI日期 | P1: 验货 结果 | Q1: 箱唛 资料 | R1: 外箱 贴纸 | S1: 客贴纸 | T1: 包装版本 | U1: 日期码 | V1: 是否扣FGMA | W1: 备注 | X1: 单价 | Y1: 金额USD | Z1: 金额HKD | AA1: 是否 入系统 | AB1: 车间 | AC1: 下单明细 | AD1: 送回数量 | AE1: 欠数 | AF1: 贴纸 | AG1: 外箱 | AH1: SY回复
A2: 46184 | B2: Character World LTD | C2: PO000652 | D2: 14312.AF0.106L | E2: 14312 | F2: 公仔夜灯 | G2: 2004 | H2: 6 | I2: =G2/H2 -> 334 | J2: 46247 | K2: 46245 | L2: 46245 | M2: Bluey Blue GoGlow Buddy | N2: 46241 | P2: PASS | T2: CW版本 | U2: HS22026 | W2: 有一套销售办 | X2: 2.75 | Y2: =X2*G2 -> 5511 | Z2: =Y2*7.75 -> 42710.25 | AA2: 已入系统 | AB2: B | AC2: 已下半成品
G6: =SUM(G1:G5) -> 2004 | Y6: =SUM(Y1:Y5) -> 5511 | Z6: =SUM(Z1:Z5) -> 42710.25

Sheet 已走货
A1: 接单期 | B1: 国家/客名 | C1: Customer | D1: PO号 | E1: ItemCode | F1: 货号 | G1: 名称 | H1: 数量 | I1: 装箱数 | J1: 总箱数 | K1: 客PO期 | L1: 计划验货期 | M1: 第三方验货 | N1: 产品描述 | O1: 验货时间 | P1: SI日期 | Q1: 验货 结果 | R1: 箱唛 资料 | S1: 外箱 贴纸 | T1: 客贴纸 | U1: 包装版本 | V1: 日期码 | W1: 是否扣FGMA | X1: 备注 | Y1: 单价 | Z1: 金额USD | AA1: 金额HKD | AB1: 是否 入系统 | AC1: 车间 | AD1: 下单明细 | AE1: 送回数量 | AF1: 欠数 | AG1: 贴纸 | AH1: 外箱 | AI1: SY回复 | AJ1: 发票号 | AK1: 发票日期 | AL1: 出货方式
H7: =SUM(H2:H6) -> 0 | Z7: =SUM(Z2:Z6) -> 0 | AA7: =SUM(AA2:AA6) -> 0

Sheet MA
A1: 接单期 | B1: 国家/客名 | C1: Customer | D1: PO号 | E1: ItemCode | F1: 货号 | G1: 数量 | H1: 装箱数 | I1: 总箱数 | J1: 客PO期 | K1: 计划验货期 | L1: 第三方验货 | M1: 验货时间 | N1: SI日期 | O1: 验货 结果 | P1: 箱唛 资料 | Q1: 外箱 贴纸 | R1: 客贴纸 | S1: 包装版本 | T1: 日期码 | U1: 是否扣FGMA | V1: 备注 | W1: 单价 | X1: 金额USD | Y1: 金额HKD | Z1: 发票号 | AA1: 是否 入系统 | AB1: 车间 | AC1: 下单明细 | AD1: 送回数量 | AE1: 欠数 | AF1: 贴纸 | AG1: 外箱 | AH1: SY回复
G9: =SUM(G1:G8) -> 0 | X9: =SUM(X2:X8) -> 0 | Y9: =SUM(Y2:Y8) -> 0

Sheet 取消单
A1: 接单期 | B1: 国家/客名 | C1: Customer | D1: PO号 | E1: ItemCode | F1: 货号 | G1: 名称 | H1: 数量 | I1: 装箱数 | J1: 总箱数 | K1: 客PO期 | L1: 计划验货期 | M1: 第三方验货 | N1: 产品描述 | O1: 验货时间 | P1: SI日期 | Q1: 验货 结果 | R1: 箱唛 资料 | S1: 外箱 贴纸 | T1: 客贴纸 | U1: 包装版本 | V1: 日期码 | W1: 是否扣FGMA | X1: 备注 | Y1: 单价 | Z1: 金额USD | AA1: 金额HKD | AB1: 是否 入系统 | AC1: 车间 | AD1: 下单明细 | AE1: 送回数量 | AF1: 欠数 | AG1: 贴纸 | AH1: 外箱 | AI1: SY回复
H6: =SUM(H1:H5) -> 0 | Z6: =SUM(Z1:Z5) -> 0 | AA6: =SUM(AA1:AA5) -> 0

Sheet 配比图
B1: 50074两个装 | J1: 50074六个装

Sheet ☆
A1: ItemCode | B1: 车间 | C1: 车间 | D1: 名称
A2: 13095.AC0.00WR | B2: 13095 | C2: C | D2: 医药箱
A3: 14312.AF0.106L | B3: 14312 | C3: B | D3: 灯公仔
A4: 14345.AF0.106L | B4: 14345 | C4: B | D4: 灯公仔
A5: 17344.AD0.005L | B5: 17344 | C5: A | D5: 布鲁公仔一代
A6: 17345.AB0.00WR | B6: 17345 | C6: A | D6: 校巴
A7: 17529.AB0.00WR | B7: 17529 | C7: C | D7: 大树
A8: 17552.AB0.00WR | B8: 17552 | C8: A-C | D8: 玩具商场
A9: 17563.AB0.0000 | B9: 17563 | C9: A | D9: 校巴邮购盒装
A10: 17588.AA0.005L | B10: 17588 | C10: C | D10: 玩具商场+车仔
A11: 17644.AA0.0000 | B11: 17644 | C11: A-C | D11: 大树
A12: 13095.AC0.0000 | B12: =TEXT(MID(A12,1,5),"00000") -> 13095 | C12: C | D12: 医药箱
A13: 13095.AC0.00KL | B13: =TEXT(MID(A13,1,5),"00000") -> 13095 | C13: C | D13: 医药箱
A14: 13095.AC0.00SS | B14: =TEXT(MID(A14,1,5),"00000") -> 13095 | C14: C | D14: 医药箱
A15: 13095.AC0.00WR | B15: =TEXT(MID(A15,1,5),"00000") -> 13095 | C15: C | D15: 医药箱
A16: 14300.AF0.106L | B16: =TEXT(MID(A16,1,5),"00000") -> 14300 | C16: B | D16: 灯公仔
A17: 14303.AF0.106L | B17: =TEXT(MID(A17,1,5),"00000") -> 14303 | C17: B
A18: 14305.AF0.106L | B18: =TEXT(MID(A18,1,5),"00000") -> 14305 | C18: B
A19: 14311.AB0.0000 | B19: =TEXT(MID(A19,1,5),"00000") -> 14311 | C19: B | D19: 灯公仔
A20: 14311.AB0.00SS | B20: =TEXT(MID(A20,1,5),"00000") -> 14311 | C20: B | D20: 灯公仔
A21: 14312.AB0.0000 | B21: =TEXT(MID(A21,1,5),"00000") -> 14312 | C21: B | D21: 灯公仔
A22: 14312.AB0.00SS | B22: =TEXT(MID(A22,1,5),"00000") -> 14312 | C22: B | D22: 灯公仔
A23: 14312.AF0.0000 | B23: =TEXT(MID(A23,1,5),"00000") -> 14312 | C23: B | D23: 灯公仔
A24: 14312.AF0.106L | B24: =TEXT(MID(A24,1,5),"00000") -> 14312 | C24: B | D24: 灯公仔
A25: 14317.AF0.106L | B25: =TEXT(MID(A25,1,5),"00000") -> 14317 | C25: B
A26: 14344.AF0.106L | B26: =TEXT(MID(A26,1,5),"00000") -> 14344 | C26: B
A27: 14345.AF0.0000 | B27: =TEXT(MID(A27,1,5),"00000") -> 14345 | C27: B | D27: 灯公仔
A28: 14345.AF0.106L | B28: =TEXT(MID(A28,1,5),"00000") -> 14345 | C28: B | D28: 灯公仔
A29: 14347.AG0.CT00 | B29: =TEXT(MID(A29,1,5),"00000") -> 14347 | C29: B | D29: 灯公仔
A30: 14349.AF0.0000 | B30: =TEXT(MID(A30,1,5),"00000") -> 14349 | C30: B
A31: 14764.AF0.106L | B31: =TEXT(MID(A31,1,5),"00000") -> 14764 | C31: B | D31: 灯公仔
A32: 14765.AG0.CT00 | B32: =TEXT(MID(A32,1,5),"00000") -> 14765 | C32: B | D32: 灯公仔
A33: 14766.AG0.CT00 | B33: =TEXT(MID(A33,1,5),"00000") -> 14766 | C33: B | D33: 灯公仔
A34: 14766.AG0.CT02 | B34: 14766 | C34: B | D34: 灯公仔
A35: 14766.AG0.CT04 | B35: 14766 | C35: B | D35: 灯公仔
A36: 14767.AG0.CT03 | B36: 14767 | C36: B | D36: 灯公仔
A37: 14768.AG0.CT05 | B37: 14768 | C37: B | D37: 灯公仔
A38: 14769.AG0.CT06 | B38: 14769 | C38: B | D38: 灯公仔
A39: 17337.AB0.0000 | B39: =TEXT(MID(A39,1,5),"00000") -> 17337 | C39: B | D39: 学校
A40: 17337.AB0.005L | B40: =TEXT(MID(A40,1,5),"00000") -> 17337 | C40: B | D40: 学校
...
